Workbook
Name b_ener: BASE_ALIMENTOS!$E$8:$E$649
Name b_fib: BASE_ALIMENTOS!$I$8:$I$649
Name b_hc: BASE_ALIMENTOS!$G$8:$G$649
Name b_key: BASE_ALIMENTOS!$N$8:$N$649
Name b_lip: BASE_ALIMENTOS!$H$8:$H$649
Name b_porcg: BASE_ALIMENTOS!$K$8:$K$649
Name b_prot: BASE_ALIMENTOS!$F$8:$F$649
Name fg_01: BASE_ALIMENTOS!$N$8:$N$60
Name fg_02: BASE_ALIMENTOS!$N$61:$N$65
Name fg_03: BASE_ALIMENTOS!$N$66:$N$149
Name fg_04: BASE_ALIMENTOS!$N$150:$N$197
Name fg_05: BASE_ALIMENTOS!$N$198:$N$215
Name fg_06: BASE_ALIMENTOS!$N$216:$N$235
Name fg_07: BASE_ALIMENTOS!$N$236:$N$309
Name fg_08: BASE_ALIMENTOS!$N$310:$N$313
Name fg_09: BASE_ALIMENTOS!$N$314:$N$338
Name fg_10: BASE_ALIMENTOS!$N$339:$N$393
Name fg_11: BASE_ALIMENTOS!$N$394:$N$437
Name fg_12: BASE_ALIMENTOS!$N$438:$N$445
Name fg_13: BASE_ALIMENTOS!$N$446:$N$476
Name fg_14: BASE_ALIMENTOS!$N$477:$N$482
Name fg_15: BASE_ALIMENTOS!$N$483:$N$496
Name fg_16: BASE_ALIMENTOS!$N$497:$N$500
Name fg_17: BASE_ALIMENTOS!$N$501:$N$510
Name fg_18: BASE_ALIMENTOS!$N$511:$N$523
Name fg_19: BASE_ALIMENTOS!$N$524:$N$526
Name fg_20: BASE_ALIMENTOS!$N$527:$N$534
Name fg_21: BASE_ALIMENTOS!$N$535:$N$574
Name fg_22: BASE_ALIMENTOS!$N$575:$N$578
Name fg_23: BASE_ALIMENTOS!$N$579:$N$595
Name fg_24: BASE_ALIMENTOS!$N$596:$N$649
Name fg_all: BASE_ALIMENTOS!$N$8:$N$649
Name grp_map: BASE_ALIMENTOS!$P$8:$Q$31
Name k_cho: CONFIG!$C$8
Name k_lip: CONFIG!$C$9
Name k_prot: CONFIG!$C$7
Name k_tol: CONFIG!$C$13
Name lst_eq: CONFIG!$A$17:$A$29
Name lst_grupos_base: BASE_ALIMENTOS!$P$8:$P$31
Name lst_tiempos: CONFIG!$A$34:$A$39
Name rng_eq: CONFIG!$A$17:$E$29
Name rng_macro: DATOS!$A$22:$D$24
Name rng_meta_dia: DATOS!$B$34:$H$34
Name rng_tiempos: CONFIG!$A$34:$B$39
Name u_inf: CONFIG!$C$10
Name u_rep: CONFIG!$C$12
Name u_sup: CONFIG!$C$11
Name v_meta: DATOS!$B$18

Sheet INICIO
A1: NUTRIMETRÍA · NMX-02 · TABLA DIETOSINTÉTICA SEMANAL
A2: Fase 4 · Dietas y platillos · versión 1.0 · uso propio · 19-07-2026
A3: INICIO | B3: DATOS | C3: DIETOSINTESIS | D3: DISTRIBUCION | E3: MENU_SEMANAL | F3: SEMANA | G3: RESULTADOS | H3: FUENTES | I3: PRUEBAS | J3: CONFIG | K3: CHANGELOG
A5: FICHA TÉCNICA DEL INSTRUMENTO
A6: Código del producto | D6: NMX-02
A7: Versión | D7: 1.0
A8: Fecha | D8: 2026-07-19
A9: Método | D9: Tabla dietosintética semanal
A10: Finalidad | D10: Fase 4 · Dietas y platillos
A11: Formato | D11: .xlsx sin macros
A13: QUÉ HACE ESTE LIBRO
A14: Traduce una prescripción numérica en una estructura alimentaria concreta. Usted define la meta energética y la distribución de macronutrientes; asigna equivalentes por grupo hasta ajustar el patrón; reparte esos equivalentes en los tiempos de comida con control de cuadratura; y despliega el resultado en una tabla semanal de siete días con su adecuación día por día.
A19: CÓMO USARLO
A20: 1 | B20: En DATOS: escriba la meta energética y los porcentajes de macronutrientes. El libro calcula las metas en gramos.
A21: 2 | B21: En DIETOSÍNTESIS: asigne equivalentes por grupo y observe el bloque de ajuste. Modifique hasta que la adecuación quede dentro del rango.
A22: 3 | B22: En DISTRIBUCIÓN: reparta esos mismos equivalentes entre los tiempos de comida. La columna de control avisa si faltan o sobran.
A23: 4 | B23: En SEMANA: los siete días parten enlazados al patrón base. Si escribe un número distinto, ese día queda como variación.
A24: 5 | B24: En RESULTADOS: revise los cinco controles de consistencia antes de dar por cerrada la tabla.
A25: 6 | B25: En CONFIG: ajuste la composición por equivalente y los porcentajes orientativos por tiempo de comida.
A27: CÓDIGO DE COLORES
A28: Arena | C28: Celdas que usted completa
A29: Gris claro | C29: Celdas calculadas (no escribir)
A30: Lila | C30: Información derivada de otra hoja
A31: Verde | C31: Resultado principal del ajuste
A32: Durazno | C32: Controles, advertencias y límites de uso
A34: AVISOS · Esta tabla define la ESTRUCTURA de la alimentación, no el menú: los alimentos concretos, las preparaciones y las medidas caseras se construyen en la etapa de platillos. La composición por equivalente precargada corresponde al tipo listas de intercambio y es EDITABLE: confirme que coincide con el sistema que usted utiliza. Los porcentajes orientativos por tiempo de comida son una referencia de trabajo, no una norma. El patrón nunca reproduce la meta con exactitud: se evalúa por adecuación dentro de un rango. Repetir el mismo patrón siete días es correcto en el cálculo pero empobrece la variedad, que se construye variando los alimentos dentro de cada grupo. Este libro no tiene respaldo de ninguna sociedad científica, no está validado clínicamente y no reemplaza el juicio profesional: la prescripción dietética, su indicación y su seguimiento son responsabilidad de quien la firma.

Sheet DATOS
A1: DATOS · PRESCRIPCIÓN DIETÉTICA
A2: Complete solo las celdas de color arena. Las grises se calculan solas.
A3: INICIO | B3: DATOS | C3: DIETOSINTESIS | D3: DISTRIBUCION | E3: MENU_SEMANAL | F3: SEMANA | G3: RESULTADOS | H3: FUENTES | I3: PRUEBAS | J3: CONFIG | K3: CHANGELOG
A5: IDENTIFICACIÓN
A6: Nombre o identificador | B6: Caso de ejemplo
A7: Edad (años) | B7: 34
A8: Sexo | B8: Femenino
A9: Peso (kg) | B9: 62
A10: Talla (m) | B10: 1.6
A11: Fecha de la prescripción | B11: 2026-07-18
A12: Profesional responsable | B12: —
A14: META ENERGÉTICA
A15: Forma de definir la meta | B15: Valor directo
A16: Energía indicada (kcal/día) | B16: 2000
A17: Energía por kilo (kcal/kg/día) | B17: —
A18: META ENERGÉTICA APLICADA | B18: =IF($B$15="Valor directo",IF(NOT(ISNUMBER($B$16)),"ND: falta la energía indicada",$B$16),IF(OR(NOT(ISNUMBER($B$17)),NOT(ISNUMBER($B$9))),"ND: faltan kcal/kg o peso",$B$17*$B$9)) -> 2000 | D18: kcal/día
A20: DISTRIBUCIÓN DE MACRONUTRIENTES
A21: Macronutriente | B21: % de la energía | C21: kcal | D21: Meta en gramos | E21: kcal por gramo
A22: Proteínas | B22: 0.15 | C22: =IF(NOT(ISNUMBER($B$18)),"ND",$B$18*B22) -> 300 | D22: =IF(OR(NOT(ISNUMBER(C22)),E22=0),"ND",C22/E22) -> 75 | E22: =k_prot -> 4
A23: H de C disponibles | B23: 0.55 | C23: =IF(NOT(ISNUMBER($B$18)),"ND",$B$18*B23) -> 1100 | D23: =IF(OR(NOT(ISNUMBER(C23)),E23=0),"ND",C23/E23) -> 275 | E23: =k_cho -> 4
A24: Lípidos | B24: 0.3 | C24: =IF(NOT(ISNUMBER($B$18)),"ND",$B$18*B24) -> 600 | D24: =IF(OR(NOT(ISNUMBER(C24)),E24=0),"ND",C24/E24) -> 66.666667 | E24: =k_lip -> 9
A25: Suma de porcentajes | B25: =SUM(B22:B24) -> 1 | C25: =IF(ABS(B25-1)>0.0001,"REVISAR: la suma debe ser 100%","OK") -> OK
A27: Estas metas en gramos son el objetivo que debe alcanzar el patrón de equivalentes que usted diseñe en la hoja DIETOSÍNTESIS. La coincidencia nunca será exacta: los equivalentes se asignan en números manejables y el ajuste se evalúa por adecuación porcentual.
A30: MODO DE META SEMANAL
A31: Modo de meta semanal | B31: Misma meta para todos los días
A32: Día | B32: Lunes | C32: Martes | D32: Miércoles | E32: Jueves | F32: Viernes | G32: Sábado | H32: Domingo
A33: Meta indicada por día (kcal/día)
A34: Meta aplicada por día (kcal/día) | B34: =IF($B$31="Misma meta para todos los días",v_meta,IF(ISNUMBER(B33),B33,v_meta)) -> 2000 | C34: =IF($B$31="Misma meta para todos los días",v_meta,IF(ISNUMBER(C33),C33,v_meta)) -> 2000 | D34: =IF($B$31="Misma meta para todos los días",v_meta,IF(ISNUMBER(D33),D33,v_meta)) -> 2000 | E34: =IF($B$31="Misma meta para todos los días",v_meta,IF(ISNUMBER(E33),E33,v_meta)) -> 2000 | F34: =IF($B$31="Misma meta para todos los días",v_meta,IF(ISNUMBER(F33),F33,v_meta)) -> 2000 | G34: =IF($B$31="Misma meta para todos los días",v_meta,IF(ISNUMBER(G33),G33,v_meta)) -> 2000 | H34: =IF($B$31="Misma meta para todos los días",v_meta,IF(ISNUMBER(H33),H33,v_meta)) -> 2000
A36: La meta aplicada usa la meta general salvo que elija "Meta diferente por día".

Sheet DIETOSINTESIS
A1: DIETOSÍNTESIS · PATRÓN DIARIO DE EQUIVALENTES
A2: Asigne los equivalentes de cada grupo y observe cómo se acerca el aporte a la meta. Es un proceso iterativo: modifique y vuelva a mirar la adecuación.
A3: INICIO | B3: DATOS | C3: DIETOSINTESIS | D3: DISTRIBUCION | E3: MENU_SEMANAL | F3: SEMANA | G3: RESULTADOS | H3: FUENTES | I3: PRUEBAS | J3: CONFIG | K3: CHANGELOG
A5: PATRÓN DE EQUIVALENTES POR DÍA
A6: Grupo de equivalencia | B6: Equivalentes/día | C6: H de C (g) | D6: Proteínas (g) | E6: Lípidos (g) | F6: Energía (kcal) | G6: % de la energía
A7: =INDEX(rng_eq,1,1) -> Lácteos descremados | B7: 1 | C7: =IF(NOT(ISNUMBER($B7)),"ND",$B7*INDEX(rng_eq,1,2)) -> 10 | D7: =IF(NOT(ISNUMBER($B7)),"ND",$B7*INDEX(rng_eq,1,3)) -> 7 | E7: =IF(NOT(ISNUMBER($B7)),"ND",$B7*INDEX(rng_eq,1,4)) -> 0 | F7: =IF(NOT(ISNUMBER($B7)),"ND",$B7*INDEX(rng_eq,1,5)) -> 70 | G7: =IF(OR(NOT(ISNUMBER(F7)),$F$20=0),"ND",F7/$F$20) -> 0.035
A8: =INDEX(rng_eq,2,1) -> Lácteos semidescremados | B8: 1 | C8: =IF(NOT(ISNUMBER($B8)),"ND",$B8*INDEX(rng_eq,2,2)) -> 9 | D8: =IF(NOT(ISNUMBER($B8)),"ND",$B8*INDEX(rng_eq,2,3)) -> 5 | E8: =IF(NOT(ISNUMBER($B8)),"ND",$B8*INDEX(rng_eq,2,4)) -> 3 | F8: =IF(NOT(ISNUMBER($B8)),"ND",$B8*INDEX(rng_eq,2,5)) -> 85 | G8: =IF(OR(NOT(ISNUMBER(F8)),$F$20=0),"ND",F8/$F$20) -> 0.0425
A9: =INDEX(rng_eq,3,1) -> Lácteos enteros | B9: 0 | C9: =IF(NOT(ISNUMBER($B9)),"ND",$B9*INDEX(rng_eq,3,2)) -> 0 | D9: =IF(NOT(ISNUMBER($B9)),"ND",$B9*INDEX(rng_eq,3,3)) -> 0 | E9: =IF(NOT(ISNUMBER($B9)),"ND",$B9*INDEX(rng_eq,3,4)) -> 0 | F9: =IF(NOT(ISNUMBER($B9)),"ND",$B9*INDEX(rng_eq,3,5)) -> 0 | G9: =IF(OR(NOT(ISNUMBER(F9)),$F$20=0),"ND",F9/$F$20) -> 0
A10: =INDEX(rng_eq,4,1) -> Verduras de consumo general | B10: 4 | C10: =IF(NOT(ISNUMBER($B10)),"ND",$B10*INDEX(rng_eq,4,2)) -> 20 | D10: =IF(NOT(ISNUMBER($B10)),"ND",$B10*INDEX(rng_eq,4,3)) -> 8 | E10: =IF(NOT(ISNUMBER($B10)),"ND",$B10*INDEX(rng_eq,4,4)) -> 0 | F10: =IF(NOT(ISNUMBER($B10)),"ND",$B10*INDEX(rng_eq,4,5)) -> 120 | G10: =IF(OR(NOT(ISNUMBER(F10)),$F$20=0),"ND",F10/$F$20) -> 0.06
A11: =INDEX(rng_eq,5,1) -> Verduras de libre consumo | B11: 3 | C11: =IF(NOT(ISNUMBER($B11)),"ND",$B11*INDEX(rng_eq,5,2)) -> 7.5 | D11: =IF(NOT(ISNUMBER($B11)),"ND",$B11*INDEX(rng_eq,5,3)) -> 0 | E11: =IF(NOT(ISNUMBER($B11)),"ND",$B11*INDEX(rng_eq,5,4)) -> 0 | F11: =IF(NOT(ISNUMBER($B11)),"ND",$B11*INDEX(rng_eq,5,5)) -> 30 | G11: =IF(OR(NOT(ISNUMBER(F11)),$F$20=0),"ND",F11/$F$20) -> 0.015
A12: =INDEX(rng_eq,6,1) -> Frutas | B12: 4 | C12: =IF(NOT(ISNUMBER($B12)),"ND",$B12*INDEX(rng_eq,6,2)) -> 60 | D12: =IF(NOT(ISNUMBER($B12)),"ND",$B12*INDEX(rng_eq,6,3)) -> 0 | E12: =IF(NOT(ISNUMBER($B12)),"ND",$B12*INDEX(rng_eq,6,4)) -> 0 | F12: =IF(NOT(ISNUMBER($B12)),"ND",$B12*INDEX(rng_eq,6,5)) -> 240 | G12: =IF(OR(NOT(ISNUMBER(F12)),$F$20=0),"ND",F12/$F$20) -> 0.12
A13: =INDEX(rng_eq,7,1) -> Panes, cereales, legumbres frescas y tubérculos | B13: 4 | C13: =IF(NOT(ISNUMBER($B13)),"ND",$B13*INDEX(rng_eq,7,2)) -> 120 | D13: =IF(NOT(ISNUMBER($B13)),"ND",$B13*INDEX(rng_eq,7,3)) -> 12 | E13: =IF(NOT(ISNUMBER($B13)),"ND",$B13*INDEX(rng_eq,7,4)) -> 4 | F13: =IF(NOT(ISNUMBER($B13)),"ND",$B13*INDEX(rng_eq,7,5)) -> 560 | G13: =IF(OR(NOT(ISNUMBER(F13)),$F$20=0),"ND",F13/$F$20) -> 0.28
A14: =INDEX(rng_eq,8,1) -> Legumbres secas | B14: 1 | C14: =IF(NOT(ISNUMBER($B14)),"ND",$B14*INDEX(rng_eq,8,2)) -> 30 | D14: =IF(NOT(ISNUMBER($B14)),"ND",$B14*INDEX(rng_eq,8,3)) -> 11 | E14: =IF(NOT(ISNUMBER($B14)),"ND",$B14*INDEX(rng_eq,8,4)) -> 1 | F14: =IF(NOT(ISNUMBER($B14)),"ND",$B14*INDEX(rng_eq,8,5)) -> 170 | G14: =IF(OR(NOT(ISNUMBER(F14)),$F$20=0),"ND",F14/$F$20) -> 0.085
A15: =INDEX(rng_eq,9,1) -> Carnes bajas en grasa | B15: 2 | C15: =IF(NOT(ISNUMBER($B15)),"ND",$B15*INDEX(rng_eq,9,2)) -> 2 | D15: =IF(NOT(ISNUMBER($B15)),"ND",$B15*INDEX(rng_eq,9,3)) -> 22 | E15: =IF(NOT(ISNUMBER($B15)),"ND",$B15*INDEX(rng_eq,9,4)) -> 4 | F15: =IF(NOT(ISNUMBER($B15)),"ND",$B15*INDEX(rng_eq,9,5)) -> 130 | G15: =IF(OR(NOT(ISNUMBER(F15)),$F$20=0),"ND",F15/$F$20) -> 0.065
A16: =INDEX(rng_eq,10,1) -> Carnes altas en grasa | B16: 0 | C16: =IF(NOT(ISNUMBER($B16)),"ND",$B16*INDEX(rng_eq,10,2)) -> 0 | D16: =IF(NOT(ISNUMBER($B16)),"ND",$B16*INDEX(rng_eq,10,3)) -> 0 | E16: =IF(NOT(ISNUMBER($B16)),"ND",$B16*INDEX(rng_eq,10,4)) -> 0 | F16: =IF(NOT(ISNUMBER($B16)),"ND",$B16*INDEX(rng_eq,10,5)) -> 0 | G16: =IF(OR(NOT(ISNUMBER(F16)),$F$20=0),"ND",F16/$F$20) -> 0
A17: =INDEX(rng_eq,11,1) -> Aceites, grasas y semillas | B17: 5 | C17: =IF(NOT(ISNUMBER($B17)),"ND",$B17*INDEX(rng_eq,11,2)) -> 0 | D17: =IF(NOT(ISNUMBER($B17)),"ND",$B17*INDEX(rng_eq,11,3)) -> 0 | E17: =IF(NOT(ISNUMBER($B17)),"ND",$B17*INDEX(rng_eq,11,4)) -> 25 | F17: =IF(NOT(ISNUMBER($B17)),"ND",$B17*INDEX(rng_eq,11,5)) -> 225 | G17: =IF(OR(NOT(ISNUMBER(F17)),$F$20=0),"ND",F17/$F$20) -> 0.1125
A18: =INDEX(rng_eq,12,1) -> Alimentos ricos en lípidos | B18: 2 | C18: =IF(NOT(ISNUMBER($B18)),"ND",$B18*INDEX(rng_eq,12,2)) -> 10 | D18: =IF(NOT(ISNUMBER($B18)),"ND",$B18*INDEX(rng_eq,12,3)) -> 10 | E18: =IF(NOT(ISNUMBER($B18)),"ND",$B18*INDEX(rng_eq,12,4)) -> 30 | F18: =IF(NOT(ISNUMBER($B18)),"ND",$B18*INDEX(rng_eq,12,5)) -> 350 | G18: =IF(OR(NOT(ISNUMBER(F18)),$F$20=0),"ND",F18/$F$20) -> 0.175
A19: =INDEX(rng_eq,13,1) -> Azúcares | B19: 1 | C19: =IF(NOT(ISNUMBER($B19)),"ND",$B19*INDEX(rng_eq,13,2)) -> 5 | D19: =IF(NOT(ISNUMBER($B19)),"ND",$B19*INDEX(rng_eq,13,3)) -> 0 | E19: =IF(NOT(ISNUMBER($B19)),"ND",$B19*INDEX(rng_eq,13,4)) -> 0 | F19: =IF(NOT(ISNUMBER($B19)),"ND",$B19*INDEX(rng_eq,13,5)) -> 20 | G19: =IF(OR(NOT(ISNUMBER(F19)),$F$20=0),"ND",F19/$F$20) -> 0.01
A20: TOTAL DEL DÍA | B20: =SUM(B7:B19) -> 28 | C20: =SUM(C7:C19) -> 273.5 | D20: =SUM(D7:D19) -> 75 | E20: =SUM(E7:E19) -> 67 | F20: =SUM(F7:F19) -> 2000 | G20: =SUM(G7:G19) -> 1
A22: AJUSTE FRENTE A LA PRESCRIPCIÓN
A23: Componente | B23: Aporta el patrón | C23: Meta prescrita | D23: Diferencia | E23: % de adecuación | F23: Evaluación
A24: Energía (kcal) | B24: =F20 -> 2000 | C24: =v_meta -> 2000 | D24: =IF(OR(NOT(ISNUMBER(B24)),NOT(ISNUMBER(C24))),"ND",B24-C24) -> 0 | E24: =IF(OR(NOT(ISNUMBER(B24)),NOT(ISNUMBER(C24)),C24=0),"ND",B24/C24) -> 1 | F24: =IF(NOT(ISNUMBER(E24)),"ND",IF(E24<u_inf,"Bajo la meta: agregue equivalentes",IF(E24<=u_sup,"Ajustado","Sobre la meta: reduzca equivalentes"))) -> Ajustado
A25: H de C disponibles (g) | B25: =C20 -> 273.5 | C25: =INDEX(rng_macro,2,4) -> 275 | D25: =IF(OR(NOT(ISNUMBER(B25)),NOT(ISNUMBER(C25))),"ND",B25-C25) -> -1.5 | E25: =IF(OR(NOT(ISNUMBER(B25)),NOT(ISNUMBER(C25)),C25=0),"ND",B25/C25) -> 0.99454545 | F25: =IF(NOT(ISNUMBER(E25)),"ND",IF(E25<u_inf,"Bajo la meta: agregue equivalentes",IF(E25<=u_sup,"Ajustado","Sobre la meta: reduzca equivalentes"))) -> Ajustado
A26: Proteínas (g) | B26: =D20 -> 75 | C26: =INDEX(rng_macro,1,4) -> 75 | D26: =IF(OR(NOT(ISNUMBER(B26)),NOT(ISNUMBER(C26))),"ND",B26-C26) -> 0 | E26: =IF(OR(NOT(ISNUMBER(B26)),NOT(ISNUMBER(C26)),C26=0),"ND",B26/C26) -> 1 | F26: =IF(NOT(ISNUMBER(E26)),"ND",IF(E26<u_inf,"Bajo la meta: agregue equivalentes",IF(E26<=u_sup,"Ajustado","Sobre la meta: reduzca equivalentes"))) -> Ajustado
A27: Lípidos (g) | B27: =E20 -> 67 | C27: =INDEX(rng_macro,3,4) -> 66.666667 | D27: =IF(OR(NOT(ISNUMBER(B27)),NOT(ISNUMBER(C27))),"ND",B27-C27) -> 0.33333333 | E27: =IF(OR(NOT(ISNUMBER(B27)),NOT(ISNUMBER(C27)),C27=0),"ND",B27/C27) -> 1.005 | F27: =IF(NOT(ISNUMBER(E27)),"ND",IF(E27<u_inf,"Bajo la meta: agregue equivalentes",IF(E27<=u_sup,"Ajustado","Sobre la meta: reduzca equivalentes"))) -> Ajustado
A29: DISTRIBUCIÓN PORCENTUAL LOGRADA
A30: Macronutriente | B30: % del patrón | C30: % prescrito | D30: Diferencia
A31: Proteínas | B31: =IF(OR(NOT(ISNUMBER(D20)),$F$20=0),"ND",D20*k_prot/$F$20) -> 0.15 | C31: =DATOS!B22 -> 0.15 | D31: =IF(OR(NOT(ISNUMBER(B31)),NOT(ISNUMBER(C31))),"ND",B31-C31) -> 0
A32: H de C disponibles | B32: =IF(OR(NOT(ISNUMBER(C20)),$F$20=0),"ND",C20*k_cho/$F$20) -> 0.547 | C32: =DATOS!B23 -> 0.55 | D32: =IF(OR(NOT(ISNUMBER(B32)),NOT(ISNUMBER(C32))),"ND",B32-C32) -> -0.003
A33: Lípidos | B33: =IF(OR(NOT(ISNUMBER(E20)),$F$20=0),"ND",E20*k_lip/$F$20) -> 0.3015 | C33: =DATOS!B24 -> 0.3 | D33: =IF(OR(NOT(ISNUMBER(B33)),NOT(ISNUMBER(C33))),"ND",B33-C33) -> 0.0015
A35: El patrón de equivalentes nunca reproduce la meta con exactitud: los equivalentes se asignan en cantidades manejables para construir menús reales. Busque adecuación dentro del rango, no coincidencia perfecta.

Sheet DISTRIBUCION
A1: DISTRIBUCIÓN DEL PATRÓN EN LOS TIEMPOS DE COMIDA
A2: Reparta los equivalentes de cada grupo entre los tiempos de comida. La columna de control avisa si el reparto no cuadra con el patrón diario.
A3: INICIO | B3: DATOS | C3: DIETOSINTESIS | D3: DISTRIBUCION | E3: MENU_SEMANAL | F3: SEMANA | G3: RESULTADOS | H3: FUENTES | I3: PRUEBAS | J3: CONFIG | K3: CHANGELOG
A5: REPARTO DE EQUIVALENTES
A6: Grupo de equivalencia | B6: =INDEX(rng_tiempos,1,1) -> Desayuno | C6: =INDEX(rng_tiempos,2,1) -> Colación AM | D6: =INDEX(rng_tiempos,3,1) -> Almuerzo | E6: =INDEX(rng_tiempos,4,1) -> Once | F6: =INDEX(rng_tiempos,5,1) -> Cena | G6: =INDEX(rng_tiempos,6,1) -> Colación nocturna | H6: Repartido | I6: Del patrón | J6: Control
A7: =INDEX(rng_eq,1,1) -> Lácteos descremados | E7: 1 | H7: =SUM(B7:G7) -> 1 | I7: =DIETOSINTESIS!B7 -> 1 | J7: =IF(NOT(ISNUMBER(I7)),"ND",IF(ABS(H7-I7)<=u_rep,"OK",IF(H7<I7,"FALTAN "&TEXT(I7-H7,"0,0")&" equivalentes","SOBRAN "&TEXT(H7-I7,"0,0")&" equivalentes"))) -> OK
A8: =INDEX(rng_eq,2,1) -> Lácteos semidescremados | B8: 1 | H8: =SUM(B8:G8) -> 1 | I8: =DIETOSINTESIS!B8 -> 1 | J8: =IF(NOT(ISNUMBER(I8)),"ND",IF(ABS(H8-I8)<=u_rep,"OK",IF(H8<I8,"FALTAN "&TEXT(I8-H8,"0,0")&" equivalentes","SOBRAN "&TEXT(H8-I8,"0,0")&" equivalentes"))) -> OK
A9: =INDEX(rng_eq,3,1) -> Lácteos enteros | H9: =SUM(B9:G9) -> 0 | I9: =DIETOSINTESIS!B9 -> 0 | J9: =IF(NOT(ISNUMBER(I9)),"ND",IF(ABS(H9-I9)<=u_rep,"OK",IF(H9<I9,"FALTAN "&TEXT(I9-H9,"0,0")&" equivalentes","SOBRAN "&TEXT(H9-I9,"0,0")&" equivalentes"))) -> OK
A10: =INDEX(rng_eq,4,1) -> Verduras de consumo general | D10: 2 | F10: 2 | H10: =SUM(B10:G10) -> 4 | I10: =DIETOSINTESIS!B10 -> 4 | J10: =IF(NOT(ISNUMBER(I10)),"ND",IF(ABS(H10-I10)<=u_rep,"OK",IF(H10<I10,"FALTAN "&TEXT(I10-H10,"0,0")&" equivalentes","SOBRAN "&TEXT(H10-I10,"0,0")&" equivalentes"))) -> OK
A11: =INDEX(rng_eq,5,1) -> Verduras de libre consumo | D11: 1 | E11: 1 | F11: 1 | H11: =SUM(B11:G11) -> 3 | I11: =DIETOSINTESIS!B11 -> 3 | J11: =IF(NOT(ISNUMBER(I11)),"ND",IF(ABS(H11-I11)<=u_rep,"OK",IF(H11<I11,"FALTAN "&TEXT(I11-H11,"0,0")&" equivalentes","SOBRAN "&TEXT(H11-I11,"0,0")&" equivalentes"))) -> OK
A12: =INDEX(rng_eq,6,1) -> Frutas | B12: 1 | C12: 1 | E12: 1 | G12: 1 | H12: =SUM(B12:G12) -> 4 | I12: =DIETOSINTESIS!B12 -> 4 | J12: =IF(NOT(ISNUMBER(I12)),"ND",IF(ABS(H12-I12)<=u_rep,"OK",IF(H12<I12,"FALTAN "&TEXT(I12-H12,"0,0")&" equivalentes","SOBRAN "&TEXT(H12-I12,"0,0")&" equivalentes"))) -> OK
A13: =INDEX(rng_eq,7,1) -> Panes, cereales, legumbres frescas y tubérculos | B13: 1 | D13: 1 | E13: 1 | F13: 1 | H13: =SUM(B13:G13) -> 4 | I13: =DIETOSINTESIS!B13 -> 4 | J13: =IF(NOT(ISNUMBER(I13)),"ND",IF(ABS(H13-I13)<=u_rep,"OK",IF(H13<I13,"FALTAN "&TEXT(I13-H13,"0,0")&" equivalentes","SOBRAN "&TEXT(H13-I13,"0,0")&" equivalentes"))) -> OK
A14: =INDEX(rng_eq,8,1) -> Legumbres secas | D14: 1 | H14: =SUM(B14:G14) -> 1 | I14: =DIETOSINTESIS!B14 -> 1 | J14: =IF(NOT(ISNUMBER(I14)),"ND",IF(ABS(H14-I14)<=u_rep,"OK",IF(H14<I14,"FALTAN "&TEXT(I14-H14,"0,0")&" equivalentes","SOBRAN "&TEXT(H14-I14,"0,0")&" equivalentes"))) -> OK
A15: =INDEX(rng_eq,9,1) -> Carnes bajas en grasa | D15: 1 | F15: 1 | H15: =SUM(B15:G15) -> 2 | I15: =DIETOSINTESIS!B15 -> 2 | J15: =IF(NOT(ISNUMBER(I15)),"ND",IF(ABS(H15-I15)<=u_rep,"OK",IF(H15<I15,"FALTAN "&TEXT(I15-H15,"0,0")&" equivalentes","SOBRAN "&TEXT(H15-I15,"0,0")&" equivalentes"))) -> OK
A16: =INDEX(rng_eq,10,1) -> Carnes altas en grasa | H16: =SUM(B16:G16) -> 0 | I16: =DIETOSINTESIS!B16 -> 0 | J16: =IF(NOT(ISNUMBER(I16)),"ND",IF(ABS(H16-I16)<=u_rep,"OK",IF(H16<I16,"FALTAN "&TEXT(I16-H16,"0,0")&" equivalentes","SOBRAN "&TEXT(H16-I16,"0,0")&" equivalentes"))) -> OK
A17: =INDEX(rng_eq,11,1) -> Aceites, grasas y semillas | B17: 1 | D17: 2 | F17: 2 | H17: =SUM(B17:G17) -> 5 | I17: =DIETOSINTESIS!B17 -> 5 | J17: =IF(NOT(ISNUMBER(I17)),"ND",IF(ABS(H17-I17)<=u_rep,"OK",IF(H17<I17,"FALTAN "&TEXT(I17-H17,"0,0")&" equivalentes","SOBRAN "&TEXT(H17-I17,"0,0")&" equivalentes"))) -> OK
A18: =INDEX(rng_eq,12,1) -> Alimentos ricos en lípidos | E18: 1 | F18: 1 | H18: =SUM(B18:G18) -> 2 | I18: =DIETOSINTESIS!B18 -> 2 | J18: =IF(NOT(ISNUMBER(I18)),"ND",IF(ABS(H18-I18)<=u_rep,"OK",IF(H18<I18,"FALTAN "&TEXT(I18-H18,"0,0")&" equivalentes","SOBRAN "&TEXT(H18-I18,"0,0")&" equivalentes"))) -> OK
A19: =INDEX(rng_eq,13,1) -> Azúcares | B19: 1 | H19: =SUM(B19:G19) -> 1 | I19: =DIETOSINTESIS!B19 -> 1 | J19: =IF(NOT(ISNUMBER(I19)),"ND",IF(ABS(H19-I19)<=u_rep,"OK",IF(H19<I19,"FALTAN "&TEXT(I19-H19,"0,0")&" equivalentes","SOBRAN "&TEXT(H19-I19,"0,0")&" equivalentes"))) -> OK
A20: TOTAL DE EQUIVALENTES | B20: =SUM(B7:B19) -> 5 | C20: =SUM(C7:C19) -> 1 | D20: =SUM(D7:D19) -> 8 | E20: =SUM(E7:E19) -> 5 | F20: =SUM(F7:F19) -> 8 | G20: =SUM(G7:G19) -> 1 | H20: =SUM(H7:H19) -> 28 | I20: =SUM(I7:I19) -> 28
A21: ENERGÍA (kcal) | B21: =SUMPRODUCT(B7:B19,CONFIG!$E$17:$E$29) -> 350 | C21: =SUMPRODUCT(C7:C19,CONFIG!$E$17:$E$29) -> 60 | D21: =SUMPRODUCT(D7:D19,CONFIG!$E$17:$E$29) -> 535 | E21: =SUMPRODUCT(E7:E19,CONFIG!$E$17:$E$29) -> 455 | F21: =SUMPRODUCT(F7:F19,CONFIG!$E$17:$E$29) -> 540 | G21: =SUMPRODUCT(G7:G19,CONFIG!$E$17:$E$29) -> 60 | H21: =SUM(B21:G21) -> 2000
A22: % DE LA ENERGÍA DEL DÍA | B22: =IF(H$21=0,"ND",B21/$H$21) -> 0.175 | C22: =IF(H$21=0,"ND",C21/$H$21) -> 0.03 | D22: =IF(H$21=0,"ND",D21/$H$21) -> 0.2675 | E22: =IF(H$21=0,"ND",E21/$H$21) -> 0.2275 | F22: =IF(H$21=0,"ND",F21/$H$21) -> 0.27 | G22: =IF(H$21=0,"ND",G21/$H$21) -> 0.03
A23: % orientativo de referencia | B23: =INDEX(rng_tiempos,1,2) -> 0.2 | C23: =INDEX(rng_tiempos,2,2) -> 0.05 | D23: =INDEX(rng_tiempos,3,2) -> 0.3 | E23: =INDEX(rng_tiempos,4,2) -> 0.2 | F23: =INDEX(rng_tiempos,5,2) -> 0.2 | G23: =INDEX(rng_tiempos,6,2) -> 0.05
A25: Un reparto correcto NO significa un menú adecuado: la aceptabilidad, los horarios reales, la cultura alimentaria y el presupuesto se definen al construir los platillos.

Sheet SEMANA
A1: TABLA DIETOSINTÉTICA SEMANAL
A2: Cada día muestra el APORTE REAL calculado desde MENU_SEMANAL. El patrón de equivalentes de abajo es solo referencia estructural.
A3: INICIO | B3: DATOS | C3: DIETOSINTESIS | D3: DISTRIBUCION | E3: MENU_SEMANAL | F3: SEMANA | G3: RESULTADOS | H3: FUENTES | I3: PRUEBAS | J3: CONFIG | K3: CHANGELOG
A4: PATRÓN PRESCRITO DE EQUIVALENTES (referencia estructural · igual para todos los días)
A6: Grupo de equivalencia | B6: Lunes | C6: Martes | D6: Miércoles | E6: Jueves | F6: Viernes | G6: Sábado | H6: Domingo | I6: Total semanal | J6: Promedio diario | K6: Patrón base | L6: Variación
A7: =INDEX(rng_eq,1,1) -> Lácteos descremados | B7: =DIETOSINTESIS!$B$7 -> 1 | C7: =DIETOSINTESIS!$B$7 -> 1 | D7: =DIETOSINTESIS!$B$7 -> 1 | E7: =DIETOSINTESIS!$B$7 -> 1 | F7: =DIETOSINTESIS!$B$7 -> 1 | G7: =DIETOSINTESIS!$B$7 -> 1 | H7: =DIETOSINTESIS!$B$7 -> 1 | I7: =SUM(B7:H7) -> 7 | J7: =AVERAGE(B7:H7) -> 1 | K7: =DIETOSINTESIS!$B$7 -> 1 | L7: =IF(NOT(ISNUMBER(K7)),"ND",IF(COUNTIF(B7:H7,K7)=7,"Sin variación","Varía en "&(7-COUNTIF(B7:H7,K7))&" día(s)")) -> Sin variación
A8: =INDEX(rng_eq,2,1) -> Lácteos semidescremados | B8: =DIETOSINTESIS!$B$8 -> 1 | C8: =DIETOSINTESIS!$B$8 -> 1 | D8: =DIETOSINTESIS!$B$8 -> 1 | E8: =DIETOSINTESIS!$B$8 -> 1 | F8: =DIETOSINTESIS!$B$8 -> 1 | G8: =DIETOSINTESIS!$B$8 -> 1 | H8: =DIETOSINTESIS!$B$8 -> 1 | I8: =SUM(B8:H8) -> 7 | J8: =AVERAGE(B8:H8) -> 1 | K8: =DIETOSINTESIS!$B$8 -> 1 | L8: =IF(NOT(ISNUMBER(K8)),"ND",IF(COUNTIF(B8:H8,K8)=7,"Sin variación","Varía en "&(7-COUNTIF(B8:H8,K8))&" día(s)")) -> Sin variación
A9: =INDEX(rng_eq,3,1) -> Lácteos enteros | B9: =DIETOSINTESIS!$B$9 -> 0 | C9: =DIETOSINTESIS!$B$9 -> 0 | D9: =DIETOSINTESIS!$B$9 -> 0 | E9: =DIETOSINTESIS!$B$9 -> 0 | F9: =DIETOSINTESIS!$B$9 -> 0 | G9: =DIETOSINTESIS!$B$9 -> 0 | H9: =DIETOSINTESIS!$B$9 -> 0 | I9: =SUM(B9:H9) -> 0 | J9: =AVERAGE(B9:H9) -> 0 | K9: =DIETOSINTESIS!$B$9 -> 0 | L9: =IF(NOT(ISNUMBER(K9)),"ND",IF(COUNTIF(B9:H9,K9)=7,"Sin variación","Varía en "&(7-COUNTIF(B9:H9,K9))&" día(s)")) -> Sin variación
A10: =INDEX(rng_eq,4,1) -> Verduras de consumo general | B10: =DIETOSINTESIS!$B$10 -> 4 | C10: =DIETOSINTESIS!$B$10 -> 4 | D10: =DIETOSINTESIS!$B$10 -> 4 | E10: =DIETOSINTESIS!$B$10 -> 4 | F10: =DIETOSINTESIS!$B$10 -> 4 | G10: =DIETOSINTESIS!$B$10 -> 4 | H10: =DIETOSINTESIS!$B$10 -> 4 | I10: =SUM(B10:H10) -> 28 | J10: =AVERAGE(B10:H10) -> 4 | K10: =DIETOSINTESIS!$B$10 -> 4 | L10: =IF(NOT(ISNUMBER(K10)),"ND",IF(COUNTIF(B10:H10,K10)=7,"Sin variación","Varía en "&(7-COUNTIF(B10:H10,K10))&" día(s)")) -> Sin variación
A11: =INDEX(rng_eq,5,1) -> Verduras de libre consumo | B11: =DIETOSINTESIS!$B$11 -> 3 | C11: =DIETOSINTESIS!$B$11 -> 3 | D11: =DIETOSINTESIS!$B$11 -> 3 | E11: =DIETOSINTESIS!$B$11 -> 3 | F11: =DIETOSINTESIS!$B$11 -> 3 | G11: =DIETOSINTESIS!$B$11 -> 3 | H11: =DIETOSINTESIS!$B$11 -> 3 | I11: =SUM(B11:H11) -> 21 | J11: =AVERAGE(B11:H11) -> 3 | K11: =DIETOSINTESIS!$B$11 -> 3 | L11: =IF(NOT(ISNUMBER(K11)),"ND",IF(COUNTIF(B11:H11,K11)=7,"Sin variación","Varía en "&(7-COUNTIF(B11:H11,K11))&" día(s)")) -> Sin variación
A12: =INDEX(rng_eq,6,1) -> Frutas | B12: =DIETOSINTESIS!$B$12 -> 4 | C12: =DIETOSINTESIS!$B$12 -> 4 | D12: =DIETOSINTESIS!$B$12 -> 4 | E12: =DIETOSINTESIS!$B$12 -> 4 | F12: =DIETOSINTESIS!$B$12 -> 4 | G12: =DIETOSINTESIS!$B$12 -> 4 | H12: =DIETOSINTESIS!$B$12 -> 4 | I12: =SUM(B12:H12) -> 28 | J12: =AVERAGE(B12:H12) -> 4 | K12: =DIETOSINTESIS!$B$12 -> 4 | L12: =IF(NOT(ISNUMBER(K12)),"ND",IF(COUNTIF(B12:H12,K12)=7,"Sin variación","Varía en "&(7-COUNTIF(B12:H12,K12))&" día(s)")) -> Sin variación
A13: =INDEX(rng_eq,7,1) -> Panes, cereales, legumbres frescas y tubérculos | B13: =DIETOSINTESIS!$B$13 -> 4 | C13: =DIETOSINTESIS!$B$13 -> 4 | D13: =DIETOSINTESIS!$B$13 -> 4 | E13: =DIETOSINTESIS!$B$13 -> 4 | F13: =DIETOSINTESIS!$B$13 -> 4 | G13: =DIETOSINTESIS!$B$13 -> 4 | H13: =DIETOSINTESIS!$B$13 -> 4 | I13: =SUM(B13:H13) -> 28 | J13: =AVERAGE(B13:H13) -> 4 | K13: =DIETOSINTESIS!$B$13 -> 4 | L13: =IF(NOT(ISNUMBER(K13)),"ND",IF(COUNTIF(B13:H13,K13)=7,"Sin variación","Varía en "&(7-COUNTIF(B13:H13,K13))&" día(s)")) -> Sin variación
A14: =INDEX(rng_eq,8,1) -> Legumbres secas | B14: =DIETOSINTESIS!$B$14 -> 1 | C14: =DIETOSINTESIS!$B$14 -> 1 | D14: =DIETOSINTESIS!$B$14 -> 1 | E14: =DIETOSINTESIS!$B$14 -> 1 | F14: =DIETOSINTESIS!$B$14 -> 1 | G14: =DIETOSINTESIS!$B$14 -> 1 | H14: =DIETOSINTESIS!$B$14 -> 1 | I14: =SUM(B14:H14) -> 7 | J14: =AVERAGE(B14:H14) -> 1 | K14: =DIETOSINTESIS!$B$14 -> 1 | L14: =IF(NOT(ISNUMBER(K14)),"ND",IF(COUNTIF(B14:H14,K14)=7,"Sin variación","Varía en "&(7-COUNTIF(B14:H14,K14))&" día(s)")) -> Sin variación
A15: =INDEX(rng_eq,9,1) -> Carnes bajas en grasa | B15: =DIETOSINTESIS!$B$15 -> 2 | C15: =DIETOSINTESIS!$B$15 -> 2 | D15: =DIETOSINTESIS!$B$15 -> 2 | E15: =DIETOSINTESIS!$B$15 -> 2 | F15: =DIETOSINTESIS!$B$15 -> 2 | G15: =DIETOSINTESIS!$B$15 -> 2 | H15: =DIETOSINTESIS!$B$15 -> 2 | I15: =SUM(B15:H15) -> 14 | J15: =AVERAGE(B15:H15) -> 2 | K15: =DIETOSINTESIS!$B$15 -> 2 | L15: =IF(NOT(ISNUMBER(K15)),"ND",IF(COUNTIF(B15:H15,K15)=7,"Sin variación","Varía en "&(7-COUNTIF(B15:H15,K15))&" día(s)")) -> Sin variación
A16: =INDEX(rng_eq,10,1) -> Carnes altas en grasa | B16: =DIETOSINTESIS!$B$16 -> 0 | C16: =DIETOSINTESIS!$B$16 -> 0 | D16: =DIETOSINTESIS!$B$16 -> 0 | E16: =DIETOSINTESIS!$B$16 -> 0 | F16: =DIETOSINTESIS!$B$16 -> 0 | G16: =DIETOSINTESIS!$B$16 -> 0 | H16: =DIETOSINTESIS!$B$16 -> 0 | I16: =SUM(B16:H16) -> 0 | J16: =AVERAGE(B16:H16) -> 0 | K16: =DIETOSINTESIS!$B$16 -> 0 | L16: =IF(NOT(ISNUMBER(K16)),"ND",IF(COUNTIF(B16:H16,K16)=7,"Sin variación","Varía en "&(7-COUNTIF(B16:H16,K16))&" día(s)")) -> Sin variación
A17: =INDEX(rng_eq,11,1) -> Aceites, grasas y semillas | B17: =DIETOSINTESIS!$B$17 -> 5 | C17: =DIETOSINTESIS!$B$17 -> 5 | D17: =DIETOSINTESIS!$B$17 -> 5 | E17: =DIETOSINTESIS!$B$17 -> 5 | F17: =DIETOSINTESIS!$B$17 -> 5 | G17: =DIETOSINTESIS!$B$17 -> 5 | H17: =DIETOSINTESIS!$B$17 -> 5 | I17: =SUM(B17:H17) -> 35 | J17: =AVERAGE(B17:H17) -> 5 | K17: =DIETOSINTESIS!$B$17 -> 5 | L17: =IF(NOT(ISNUMBER(K17)),"ND",IF(COUNTIF(B17:H17,K17)=7,"Sin variación","Varía en "&(7-COUNTIF(B17:H17,K17))&" día(s)")) -> Sin variación
A18: =INDEX(rng_eq,12,1) -> Alimentos ricos en lípidos | B18: =DIETOSINTESIS!$B$18 -> 2 | C18: =DIETOSINTESIS!$B$18 -> 2 | D18: =DIETOSINTESIS!$B$18 -> 2 | E18: =DIETOSINTESIS!$B$18 -> 2 | F18: =DIETOSINTESIS!$B$18 -> 2 | G18: =DIETOSINTESIS!$B$18 -> 2 | H18: =DIETOSINTESIS!$B$18 -> 2 | I18: =SUM(B18:H18) -> 14 | J18: =AVERAGE(B18:H18) -> 2 | K18: =DIETOSINTESIS!$B$18 -> 2 | L18: =IF(NOT(ISNUMBER(K18)),"ND",IF(COUNTIF(B18:H18,K18)=7,"Sin variación","Varía en "&(7-COUNTIF(B18:H18,K18))&" día(s)")) -> Sin variación
A19: =INDEX(rng_eq,13,1) -> Azúcares | B19: =DIETOSINTESIS!$B$19 -> 1 | C19: =DIETOSINTESIS!$B$19 -> 1 | D19: =DIETOSINTESIS!$B$19 -> 1 | E19: =DIETOSINTESIS!$B$19 -> 1 | F19: =DIETOSINTESIS!$B$19 -> 1 | G19: =DIETOSINTESIS!$B$19 -> 1 | H19: =DIETOSINTESIS!$B$19 -> 1 | I19: =SUM(B19:H19) -> 7 | J19: =AVERAGE(B19:H19) -> 1 | K19: =DIETOSINTESIS!$B$19 -> 1 | L19: =IF(NOT(ISNUMBER(K19)),"ND",IF(COUNTIF(B19:H19,K19)=7,"Sin variación","Varía en "&(7-COUNTIF(B19:H19,K19))&" día(s)")) -> Sin variación
A20: TOTAL DE EQUIVALENTES | B20: =SUM(B7:B19) -> 28 | C20: =SUM(C7:C19) -> 28 | D20: =SUM(D7:D19) -> 28 | E20: =SUM(E7:E19) -> 28 | F20: =SUM(F7:F19) -> 28 | G20: =SUM(G7:G19) -> 28 | H20: =SUM(H7:H19) -> 28 | I20: =SUM(I7:I19) -> 196 | J20: =SUM(J7:J19) -> 28
A21: ENERGÍA REAL DEL DÍA (kcal · desde MENU_SEMANAL) | B21: =SUMIFS(MENU_SEMANAL!$M$9:$M$218,MENU_SEMANAL!$A$9:$A$218,B$6) -> 2108.2 | C21: =SUMIFS(MENU_SEMANAL!$M$9:$M$218,MENU_SEMANAL!$A$9:$A$218,C$6) -> 1647.4 | D21: =SUMIFS(MENU_SEMANAL!$M$9:$M$218,MENU_SEMANAL!$A$9:$A$218,D$6) -> 1924.1 | E21: =SUMIFS(MENU_SEMANAL!$M$9:$M$218,MENU_SEMANAL!$A$9:$A$218,E$6) -> 2264 | F21: =SUMIFS(MENU_SEMANAL!$M$9:$M$218,MENU_SEMANAL!$A$9:$A$218,F$6) -> 2018.7 | G21: =SUMIFS(MENU_SEMANAL!$M$9:$M$218,MENU_SEMANAL!$A$9:$A$218,G$6) -> 1387.4 | H21: =SUMIFS(MENU_SEMANAL!$M$9:$M$218,MENU_SEMANAL!$A$9:$A$218,H$6) -> 1994.3 | I21: =SUM(B21:H21) -> 13344.1 | J21: =AVERAGE(B21:H21) -> 1906.3
A22: ADECUACIÓN FRENTE A LA META | B22: =IF(OR(NOT(ISNUMBER(DATOS!B$34)),DATOS!B$34=0),"ND",B21/DATOS!B$34) -> 1.0541 | C22: =IF(OR(NOT(ISNUMBER(DATOS!C$34)),DATOS!C$34=0),"ND",C21/DATOS!C$34) -> 0.8237 | D22: =IF(OR(NOT(ISNUMBER(DATOS!D$34)),DATOS!D$34=0),"ND",D21/DATOS!D$34) -> 0.96205 | E22: =IF(OR(NOT(ISNUMBER(DATOS!E$34)),DATOS!E$34=0),"ND",E21/DATOS!E$34) -> 1.132 | F22: =IF(OR(NOT(ISNUMBER(DATOS!F$34)),DATOS!F$34=0),"ND",F21/DATOS!F$34) -> 1.00935 | G22: =IF(OR(NOT(ISNUMBER(DATOS!G$34)),DATOS!G$34=0),"ND",G21/DATOS!G$34) -> 0.6937 | H22: =IF(OR(NOT(ISNUMBER(DATOS!H$34)),DATOS!H$34=0),"ND",H21/DATOS!H$34) -> 0.99715 | J22: =IF(OR(NOT(ISNUMBER(J21)),AVERAGE(DATOS!$B$34:$H$34)=0),"ND",J21/AVERAGE(DATOS!$B$34:$H$34)) -> 0.95315
A23: CONTROL DEL DÍA | B23: =IF(NOT(ISNUMBER(B22)),"ND",IF(B22<u_inf,"Bajo",IF(B22<=u_sup,"Ajustado","Sobre"))) -> Sobre | C23: =IF(NOT(ISNUMBER(C22)),"ND",IF(C22<u_inf,"Bajo",IF(C22<=u_sup,"Ajustado","Sobre"))) -> Bajo | D23: =IF(NOT(ISNUMBER(D22)),"ND",IF(D22<u_inf,"Bajo",IF(D22<=u_sup,"Ajustado","Sobre"))) -> Ajustado | E23: =IF(NOT(ISNUMBER(E22)),"ND",IF(E22<u_inf,"Bajo",IF(E22<=u_sup,"Ajustado","Sobre"))) -> Sobre | F23: =IF(NOT(ISNUMBER(F22)),"ND",IF(F22<u_inf,"Bajo",IF(F22<=u_sup,"Ajustado","Sobre"))) -> Ajustado | G23: =IF(NOT(ISNUMBER(G22)),"ND",IF(G22<u_inf,"Bajo",IF(G22<=u_sup,"Ajustado","Sobre"))) -> Bajo | H23: =IF(NOT(ISNUMBER(H22)),"ND",IF(H22<u_inf,"Bajo",IF(H22<=u_sup,"Ajustado","Sobre"))) -> Ajustado
A24: Repetir el mismo patrón siete días es correcto desde el cálculo, pero empobrece la variedad. La variación semanal se construye cambiando los ALIMENTOS dentro de cada grupo, no necesariamente el número de equivalentes.
A27: APORTE REAL POR DÍA (desde MENU_SEMANAL)
A28: Indicador | B28: Lunes | C28: Martes | D28: Miércoles | E28: Jueves | F28: Viernes | G28: Sábado | H28: Domingo | I28: Total semanal | K28: Promedio
A29: Energía real (kcal) | B29: =B21 -> 2108.2 | C29: =C21 -> 1647.4 | D29: =D21 -> 1924.1 | E29: =E21 -> 2264 | F29: =F21 -> 2018.7 | G29: =G21 -> 1387.4 | H29: =H21 -> 1994.3 | I29: =SUM(B29:H29) -> 13344.1 | K29: =AVERAGE(B29:H29) -> 1906.3
A30: Proteínas (g) | B30: =SUMIFS(MENU_SEMANAL!$N$9:$N$218,MENU_SEMANAL!$A$9:$A$218,SEMANA!B$6) -> 166.1 | C30: =SUMIFS(MENU_SEMANAL!$N$9:$N$218,MENU_SEMANAL!$A$9:$A$218,SEMANA!C$6) -> 200.57 | D30: =SUMIFS(MENU_SEMANAL!$N$9:$N$218,MENU_SEMANAL!$A$9:$A$218,SEMANA!D$6) -> 93 | E30: =SUMIFS(MENU_SEMANAL!$N$9:$N$218,MENU_SEMANAL!$A$9:$A$218,SEMANA!E$6) -> 104.52 | F30: =SUMIFS(MENU_SEMANAL!$N$9:$N$218,MENU_SEMANAL!$A$9:$A$218,SEMANA!F$6) -> 105.04 | G30: =SUMIFS(MENU_SEMANAL!$N$9:$N$218,MENU_SEMANAL!$A$9:$A$218,SEMANA!G$6) -> 70.3 | H30: =SUMIFS(MENU_SEMANAL!$N$9:$N$218,MENU_SEMANAL!$A$9:$A$218,SEMANA!H$6) -> 63.28 | I30: =SUM(B30:H30) -> 802.81 | K30: =AVERAGE(B30:H30) -> 114.68714
A31: H de C disp. (g) | B31: =SUMIFS(MENU_SEMANAL!$O$9:$O$218,MENU_SEMANAL!$A$9:$A$218,SEMANA!B$6) -> 68.94 | C31: =SUMIFS(MENU_SEMANAL!$O$9:$O$218,MENU_SEMANAL!$A$9:$A$218,SEMANA!C$6) -> 35.95 | D31: =SUMIFS(MENU_SEMANAL!$O$9:$O$218,MENU_SEMANAL!$A$9:$A$218,SEMANA!D$6) -> 101.08 | E31: =SUMIFS(MENU_SEMANAL!$O$9:$O$218,MENU_SEMANAL!$A$9:$A$218,SEMANA!E$6) -> 268.4 | F31: =SUMIFS(MENU_SEMANAL!$O$9:$O$218,MENU_SEMANAL!$A$9:$A$218,SEMANA!F$6) -> 107.71 | G31: =SUMIFS(MENU_SEMANAL!$O$9:$O$218,MENU_SEMANAL!$A$9:$A$218,SEMANA!G$6) -> 130.36 | H31: =SUMIFS(MENU_SEMANAL!$O$9:$O$218,MENU_SEMANAL!$A$9:$A$218,SEMANA!H$6) -> 393.36 | I31: =SUM(B31:H31) -> 1105.8 | K31: =AVERAGE(B31:H31) -> 157.97143
A32: Lípidos (g) | B32: =SUMIFS(MENU_SEMANAL!$P$9:$P$218,MENU_SEMANAL!$A$9:$A$218,SEMANA!B$6) -> 114.72 | C32: =SUMIFS(MENU_SEMANAL!$P$9:$P$218,MENU_SEMANAL!$A$9:$A$218,SEMANA!C$6) -> 73.53 | D32: =SUMIFS(MENU_SEMANAL!$P$9:$P$218,MENU_SEMANAL!$A$9:$A$218,SEMANA!D$6) -> 118.49 | E32: =SUMIFS(MENU_SEMANAL!$P$9:$P$218,MENU_SEMANAL!$A$9:$A$218,SEMANA!E$6) -> 65.95 | F32: =SUMIFS(MENU_SEMANAL!$P$9:$P$218,MENU_SEMANAL!$A$9:$A$218,SEMANA!F$6) -> 121.2 | G32: =SUMIFS(MENU_SEMANAL!$P$9:$P$218,MENU_SEMANAL!$A$9:$A$218,SEMANA!G$6) -> 55.08 | H32: =SUMIFS(MENU_SEMANAL!$P$9:$P$218,MENU_SEMANAL!$A$9:$A$218,SEMANA!H$6) -> 11.99 | I32: =SUM(B32:H32) -> 560.96 | K32: =AVERAGE(B32:H32) -> 80.137143
A33: Fibra (g) | B33: =SUMIFS(MENU_SEMANAL!$Q$9:$Q$218,MENU_SEMANAL!$A$9:$A$218,SEMANA!B$6) -> 118.38 | C33: =SUMIFS(MENU_SEMANAL!$Q$9:$Q$218,MENU_SEMANAL!$A$9:$A$218,SEMANA!C$6) -> 2.45 | D33: =SUMIFS(MENU_SEMANAL!$Q$9:$Q$218,MENU_SEMANAL!$A$9:$A$218,SEMANA!D$6) -> 17.81 | E33: =SUMIFS(MENU_SEMANAL!$Q$9:$Q$218,MENU_SEMANAL!$A$9:$A$218,SEMANA!E$6) -> 119.52 | F33: =SUMIFS(MENU_SEMANAL!$Q$9:$Q$218,MENU_SEMANAL!$A$9:$A$218,SEMANA!F$6) -> 44.45 | G33: =SUMIFS(MENU_SEMANAL!$Q$9:$Q$218,MENU_SEMANAL!$A$9:$A$218,SEMANA!G$6) -> 32.43 | H33: =SUMIFS(MENU_SEMANAL!$Q$9:$Q$218,MENU_SEMANAL!$A$9:$A$218,SEMANA!H$6) -> 34.56 | I33: =SUM(B33:H33) -> 369.6 | K33: =AVERAGE(B33:H33) -> 52.8
A34: N° de alimentos | B34: =COUNTIFS(MENU_SEMANAL!$A$9:$A$218,B$6,MENU_SEMANAL!$D$9:$D$218,"<>") -> 5 | C34: =COUNTIFS(MENU_SEMANAL!$A$9:$A$218,C$6,MENU_SEMANAL!$D$9:$D$218,"<>") -> 5 | D34: =COUNTIFS(MENU_SEMANAL!$A$9:$A$218,D$6,MENU_SEMANAL!$D$9:$D$218,"<>") -> 5 | E34: =COUNTIFS(MENU_SEMANAL!$A$9:$A$218,E$6,MENU_SEMANAL!$D$9:$D$218,"<>") -> 5 | F34: =COUNTIFS(MENU_SEMANAL!$A$9:$A$218,F$6,MENU_SEMANAL!$D$9:$D$218,"<>") -> 5 | G34: =COUNTIFS(MENU_SEMANAL!$A$9:$A$218,G$6,MENU_SEMANAL!$D$9:$D$218,"<>") -> 5 | H34: =COUNTIFS(MENU_SEMANAL!$A$9:$A$218,H$6,MENU_SEMANAL!$D$9:$D$218,"<>") -> 5 | I34: =SUM(B34:H34) -> 35
A35: N° con datos ND | B35: =COUNTIFS(MENU_SEMANAL!$A$9:$A$218,B$6,MENU_SEMANAL!$R$9:$R$218,"*incompleto*") -> 0 | C35: =COUNTIFS(MENU_SEMANAL!$A$9:$A$218,C$6,MENU_SEMANAL!$R$9:$R$218,"*incompleto*") -> 0 | D35: =COUNTIFS(MENU_SEMANAL!$A$9:$A$218,D$6,MENU_SEMANAL!$R$9:$R$218,"*incompleto*") -> 0 | E35: =COUNTIFS(MENU_SEMANAL!$A$9:$A$218,E$6,MENU_SEMANAL!$R$9:$R$218,"*incompleto*") -> 0 | F35: =COUNTIFS(MENU_SEMANAL!$A$9:$A$218,F$6,MENU_SEMANAL!$R$9:$R$218,"*incompleto*") -> 0 | G35: =COUNTIFS(MENU_SEMANAL!$A$9:$A$218,G$6,MENU_SEMANAL!$R$9:$R$218,"*incompleto*") -> 0 | H35: =COUNTIFS(MENU_SEMANAL!$A$9:$A$218,H$6,MENU_SEMANAL!$R$9:$R$218,"*incompleto*") -> 0 | I35: =SUM(B35:H35) -> 0
A36: Adecuación energética | B36: =B22 -> 1.0541 | C36: =C22 -> 0.8237 | D36: =D22 -> 0.96205 | E36: =E22 -> 1.132 | F36: =F22 -> 1.00935 | G36: =G22 -> 0.6937 | H36: =H22 -> 0.99715 | K36: =IF(OR(NOT(ISNUMBER(J21)),AVERAGE(DATOS!$B$34:$H$34)=0),"ND",J21/AVERAGE(DATOS!$B$34:$H$34)) -> 0.95315
A37: Control del día | B37: =B23 -> Sobre | C37: =C23 -> Bajo | D37: =D23 -> Ajustado | E37: =E23 -> Sobre | F37: =F23 -> Ajustado | G37: =G23 -> Bajo | H37: =H23 -> Ajustado

Sheet RESULTADOS
A1: RESULTADOS · VERIFICACIÓN DE LA TABLA SEMANAL
A3: INICIO | B3: DATOS | C3: DIETOSINTESIS | D3: DISTRIBUCION | E3: MENU_SEMANAL | F3: SEMANA | G3: RESULTADOS | H3: FUENTES | I3: PRUEBAS | J3: CONFIG | K3: CHANGELOG
A5: SÍNTESIS DE LA PRESCRIPCIÓN
A6: Meta energética prescrita | B6: =v_meta -> 2000 | C6: kcal/día
A7: Energía del patrón diario | B7: =DIETOSINTESIS!F20 -> 2000 | C7: kcal/día
A8: Adecuación del patrón | B8: =DIETOSINTESIS!E24 -> 1
A9: Energía promedio de la semana | B9: =SEMANA!J21 -> 1906.3 | C9: kcal/día
A10: Energía total de la semana | B10: =SEMANA!I21 -> 13344.1 | C10: kcal
A11: Total de equivalentes por día | B11: =DIETOSINTESIS!B20 -> 28 | C11: equivalentes
A13: CONTROLES DE CONSISTENCIA
A14: ¿Los porcentajes de macronutrientes suman 100%? | C14: =IF(ABS(SUM(DATOS!B22:B24)-1)>0.0001,"REVISAR: la suma no es 100%","OK") -> OK
A15: ¿El patrón queda dentro del rango de adecuación? | C15: =IF(NOT(ISNUMBER(DIETOSINTESIS!E24)),"ND",IF(AND(DIETOSINTESIS!E24>=u_inf,DIETOSINTESIS!E24<=u_sup),"OK: patrón ajustado a la meta","REVISAR: ajuste el número de equivalentes")) -> OK: patrón ajustado a la meta
A16: ¿El reparto por tiempos de comida cuadra con el patrón? | C16: =IF(COUNTIF(DISTRIBUCION!$J$7:$J$19,"OK")=13,"OK: los 13 grupos cuadran","REVISAR: "&(13-COUNTIF(DISTRIBUCION!$J$7:$J$19,"OK"))&" grupo(s) sin cuadrar") -> OK: los 13 grupos cuadran
A17: ¿Todos los días de la semana quedan ajustados? | C17: =IF(COUNTIF(SEMANA!$B$23:$H$23,"Ajustado")=7,"OK: los 7 días ajustados","REVISAR: "&(7-COUNTIF(SEMANA!$B$23:$H$23,"Ajustado"))&" día(s) fuera de rango") -> REVISAR: 4 día(s) fuera de rango
A18: ¿La suma de los porcentajes por tiempo de comida es 100%? | C18: =IF(ABS(SUM(CONFIG!$B$34:$B$39)-1)>0.0001,"REVISAR la referencia de CONFIG","OK") -> OK
A20: ESTRUCTURA DIARIA POR TIEMPO DE COMIDA
A21: Tiempo de comida | B21: Energía (kcal) | C21: % del día | D21: % orientativo | E21: Diferencia
A22: =INDEX(rng_tiempos,1,1) -> Desayuno | B22: =DISTRIBUCION!B21 -> 350 | C22: =DISTRIBUCION!B22 -> 0.175 | D22: =INDEX(rng_tiempos,1,2) -> 0.2 | E22: =IF(OR(NOT(ISNUMBER(C22)),NOT(ISNUMBER(D22))),"ND",C22-D22) -> -0.025
A23: =INDEX(rng_tiempos,2,1) -> Colación AM | B23: =DISTRIBUCION!C21 -> 60 | C23: =DISTRIBUCION!C22 -> 0.03 | D23: =INDEX(rng_tiempos,2,2) -> 0.05 | E23: =IF(OR(NOT(ISNUMBER(C23)),NOT(ISNUMBER(D23))),"ND",C23-D23) -> -0.02
A24: =INDEX(rng_tiempos,3,1) -> Almuerzo | B24: =DISTRIBUCION!D21 -> 535 | C24: =DISTRIBUCION!D22 -> 0.2675 | D24: =INDEX(rng_tiempos,3,2) -> 0.3 | E24: =IF(OR(NOT(ISNUMBER(C24)),NOT(ISNUMBER(D24))),"ND",C24-D24) -> -0.0325
A25: =INDEX(rng_tiempos,4,1) -> Once | B25: =DISTRIBUCION!E21 -> 455 | C25: =DISTRIBUCION!E22 -> 0.2275 | D25: =INDEX(rng_tiempos,4,2) -> 0.2 | E25: =IF(OR(NOT(ISNUMBER(C25)),NOT(ISNUMBER(D25))),"ND",C25-D25) -> 0.0275
A26: =INDEX(rng_tiempos,5,1) -> Cena | B26: =DISTRIBUCION!F21 -> 540 | C26: =DISTRIBUCION!F22 -> 0.27 | D26: =INDEX(rng_tiempos,5,2) -> 0.2 | E26: =IF(OR(NOT(ISNUMBER(C26)),NOT(ISNUMBER(D26))),"ND",C26-D26) -> 0.07
A27: =INDEX(rng_tiempos,6,1) -> Colación nocturna | B27: =DISTRIBUCION!G21 -> 60 | C27: =DISTRIBUCION!G22 -> 0.03 | D27: =INDEX(rng_tiempos,6,2) -> 0.05 | E27: =IF(OR(NOT(ISNUMBER(C27)),NOT(ISNUMBER(D27))),"ND",C27-D27) -> -0.02
A28: TOTAL | B28: =SUM(B22:B27) -> 2000 | C28: =SUM(C22:C27) -> 1
A30: ALCANCE DE ESTA TABLA · La tabla dietosintética define la ESTRUCTURA de la alimentación: cuántos equivalentes de cada grupo, repartidos en qué tiempos de comida. No define el menú: los alimentos concretos, las preparaciones, las porciones en medidas caseras y la aceptabilidad se construyen en la etapa de platillos. Dos personas con la misma tabla pueden comer de manera completamente distinta.
A35: EXACTITUD MATEMÁTICA ≠ VALIDACIÓN CLÍNICA. Herramienta de apoyo al cálculo y a la planificación. La prescripción dietética, su indicación y su seguimiento son responsabilidad del profesional.
A38: RESUMEN ENERGÉTICO SEMANAL (MENÚ REAL)
A39: Meta promedio diaria (kcal/día) | D39: =AVERAGE(DATOS!$B$34:$H$34) -> 2000
A40: Energía total de la semana (kcal) | D40: =SEMANA!I21 -> 13344.1
A41: Energía promedio diaria (kcal) | D41: =SEMANA!J21 -> 1906.3
A42: Día de mayor energía | D42: =INDEX(SEMANA!$B$6:$H$6,MATCH(MAX(SEMANA!$B$21:$H$21),SEMANA!$B$21:$H$21,0)) -> Jueves
A43: Día de menor energía | D43: =INDEX(SEMANA!$B$6:$H$6,MATCH(MIN(SEMANA!$B$21:$H$21),SEMANA!$B$21:$H$21,0)) -> Sábado
A44: Diferencia máxima entre días (kcal) | D44: =MAX(SEMANA!$B$21:$H$21)-MIN(SEMANA!$B$21:$H$21) -> 876.6
A45: Días ajustados | D45: =COUNTIF(SEMANA!$B$37:$H$37,"Ajustado") -> 3
A46: Días bajo la meta | D46: =COUNTIF(SEMANA!$B$37:$H$37,"Bajo") -> 2
A47: Días sobre la meta | D47: =COUNTIF(SEMANA!$B$37:$H$37,"Sobre") -> 2
A48: ENERGÍA POR DÍA (kcal)
A49: Día | B49: Lunes | C49: Martes | D49: Miércoles | E49: Jueves | F49: Viernes | G49: Sábado | H49: Domingo
A50: Energía | B50: =SEMANA!B21 -> 2108.2 | C50: =SEMANA!C21 -> 1647.4 | D50: =SEMANA!D21 -> 1924.1 | E50: =SEMANA!E21 -> 2264 | F50: =SEMANA!F21 -> 2018.7 | G50: =SEMANA!G21 -> 1387.4 | H50: =SEMANA!H21 -> 1994.3
A52: MACRONUTRIENTES · PROMEDIO DIARIO (g)
...

Sheet FUENTES
A1: FUENTES Y TRAZABILIDAD
A3: INICIO | B3: DATOS | C3: DIETOSINTESIS | D3: DISTRIBUCION | E3: MENU_SEMANAL | F3: SEMANA | G3: RESULTADOS | H3: FUENTES | I3: PRUEBAS | J3: CONFIG | K3: CHANGELOG
A4: MÉTODO Y REFERENCIAS
A6: Elemento | B6: Alcance y origen
A7: Qué es una tabla dietosintética | B7: Es el paso que traduce una prescripción numérica (energía y distribución de macronutrientes) en una estructura alimentaria manejable: número de equivalentes de cada grupo por día y su reparto en los tiempos de comida. Constituye el puente entre el cálculo y el menú.
A8: Sistema de equivalentes | B8: La composición por equivalente precargada corresponde al SISTEMA CHILENO del Manual de Porciones de Intercambio para Chile, 2ª edición 2021 (Ratner y cols., Universidad del Desarrollo), sobre antecedentes del sistema de Jury, Urteaga y Taibo (INTA–Universidad de Chile, 1999). Son 13 grupos, incluidas verduras de libre consumo y alimentos ricos en lípidos. Los valores continúan siendo EDITABLES en CONFIG y su aplicación debe responder al criterio profesional.
A9: Energía por equivalente | B9: La columna de energía muestra la ENERGÍA PUBLICADA por el manual UDD 2021. Puede diferir levemente de la energía Atwater (proteínas e H de C 4 kcal/g; lípidos 9 kcal/g) por redondeo y metodología; esa comprobación se realiza de forma independiente en la hoja PRUEBAS.
A10: Distribución por tiempos de comida | B10: Los porcentajes orientativos de CONFIG son una referencia de trabajo editable, NO una norma. La distribución real debe responder a los horarios, la jornada laboral, la cultura alimentaria y las preferencias de la persona.
A11: Criterio de ajuste | B11: El patrón de equivalentes no reproduce la meta con exactitud, porque los equivalentes se asignan en cantidades manejables para construir menús reales. El libro evalúa la adecuación porcentual dentro de un rango editable (por omisión 95% a 105%).
A12: Relación con otros módulos | B12: El sistema de equivalentes y su composición son los mismos que utiliza NMX-17. La composición química de los alimentos concretos proviene de la Tabla INTA 2018 y se aplica en los módulos que trabajan a nivel de alimento.
A13: Qué NO resuelve esta tabla | B13: No define alimentos, preparaciones ni medidas caseras; no considera aceptabilidad, presupuesto ni disponibilidad; no reemplaza la evaluación nutricional previa que fundamenta la prescripción.
A14: Respaldo institucional | B14: Este libro no cuenta con respaldo ni aval de INTA, de la Universidad de Chile ni de ninguna sociedad científica, y no está validado clínicamente.
A16: REFERENCIAS
A17: Ratner R, Aicardi V, Madrid J, Allende J, Riesco MV. | B17: Manual de Porciones de Intercambio para Chile. 2ª edición. Nutrición y Dietética, Facultad de Medicina, Universidad del Desarrollo; 2021.
A18: Jury G, Urteaga C, Taibo M. | B18: Porciones de intercambio y composición química de los alimentos de la pirámide alimentaria chilena. INTA, Universidad de Chile; 1999.
A19: Universidad del Desarrollo. | B19: Nutrición y Dietética UDD presenta nueva versión de Manual de Porciones de Intercambio para Chile. 27/09/2021. https://www.udd.cl/noticias/2021/09/27/nutricion-y-dietetica-udd-presenta-nueva-version-de-manual-de-porciones-de-intercambio-para-chile/
A20: Peña-D'Ardaillon F et al. | B20: Recomendaciones prácticas para el manejo nutricional de la enfermedad renal crónica en etapas 3 a 5 con y sin diálisis para adultos y personas mayores en Chile. Rev Chil Nutr. 2025;52(1):63-82. https://www.scielo.cl/pdf/rchnut/v52n1/0717-7518-rchnut-52-01-0063.pdf

Sheet PRUEBAS
A1: PRUEBAS DE CONTROL DE CALIDAD
A3: INICIO | B3: DATOS | C3: DIETOSINTESIS | D3: DISTRIBUCION | E3: MENU_SEMANAL | F3: SEMANA | G3: RESULTADOS | H3: FUENTES | I3: PRUEBAS | J3: CONFIG | K3: CHANGELOG
A4: Los valores esperados se calcularon de forma independiente del motor del libro (verificación externa).
A7: Bloque | B7: Descripción de la prueba | C7: Obtenido | D7: Esperado | E7: Estado
A8: A | B8: Energía publicada · Lácteos descremados | C8: =CONFIG!E17 -> 70 | D8: 70 | E8: =IF(AND(ISNUMBER(C8),ISNUMBER(D8)),IF(ABS(C8-D8)<=k_tol,"APROBADO","REVISAR"),IF(EXACT(C8&"",D8&""),"APROBADO","REVISAR")) -> APROBADO
A9: A | B9: Energía publicada · Lácteos semidescremados | C9: =CONFIG!E18 -> 85 | D9: 85 | E9: =IF(AND(ISNUMBER(C9),ISNUMBER(D9)),IF(ABS(C9-D9)<=k_tol,"APROBADO","REVISAR"),IF(EXACT(C9&"",D9&""),"APROBADO","REVISAR")) -> APROBADO
A10: A | B10: Energía publicada · Verduras de consumo general | C10: =CONFIG!E20 -> 30 | D10: 30 | E10: =IF(AND(ISNUMBER(C10),ISNUMBER(D10)),IF(ABS(C10-D10)<=k_tol,"APROBADO","REVISAR"),IF(EXACT(C10&"",D10&""),"APROBADO","REVISAR")) -> APROBADO
A11: A | B11: Energía publicada · Panes, cereales, legumbres frescas y tubérculos | C11: =CONFIG!E23 -> 140 | D11: 140 | E11: =IF(AND(ISNUMBER(C11),ISNUMBER(D11)),IF(ABS(C11-D11)<=k_tol,"APROBADO","REVISAR"),IF(EXACT(C11&"",D11&""),"APROBADO","REVISAR")) -> APROBADO
A12: A | B12: Energía publicada · Aceites, grasas y semillas | C12: =CONFIG!E27 -> 45 | D12: 45 | E12: =IF(AND(ISNUMBER(C12),ISNUMBER(D12)),IF(ABS(C12-D12)<=k_tol,"APROBADO","REVISAR"),IF(EXACT(C12&"",D12&""),"APROBADO","REVISAR")) -> APROBADO
A13: A | B13: Energía publicada · Alimentos ricos en lípidos | C13: =CONFIG!E28 -> 175 | D13: 175 | E13: =IF(AND(ISNUMBER(C13),ISNUMBER(D13)),IF(ABS(C13-D13)<=k_tol,"APROBADO","REVISAR"),IF(EXACT(C13&"",D13&""),"APROBADO","REVISAR")) -> APROBADO
A14: A | B14: Energía publicada · Azúcares | C14: =CONFIG!E29 -> 20 | D14: 20 | E14: =IF(AND(ISNUMBER(C14),ISNUMBER(D14)),IF(ABS(C14-D14)<=k_tol,"APROBADO","REVISAR"),IF(EXACT(C14&"",D14&""),"APROBADO","REVISAR")) -> APROBADO
A15: A2 | B15: Atwater independiente (HC×4+PROT×4+LIP×9) · Lácteos descremados | C15: =CONFIG!B17*k_cho+CONFIG!C17*k_prot+CONFIG!D17*k_lip -> 68 | D15: 68 | E15: =IF(AND(ISNUMBER(C15),ISNUMBER(D15)),IF(ABS(C15-D15)<=k_tol,"APROBADO","REVISAR"),IF(EXACT(C15&"",D15&""),"APROBADO","REVISAR")) -> APROBADO
A16: A2 | B16: Atwater independiente (HC×4+PROT×4+LIP×9) · Lácteos semidescremados | C16: =CONFIG!B18*k_cho+CONFIG!C18*k_prot+CONFIG!D18*k_lip -> 83 | D16: 83 | E16: =IF(AND(ISNUMBER(C16),ISNUMBER(D16)),IF(ABS(C16-D16)<=k_tol,"APROBADO","REVISAR"),IF(EXACT(C16&"",D16&""),"APROBADO","REVISAR")) -> APROBADO
A17: A2 | B17: Atwater independiente (HC×4+PROT×4+LIP×9) · Lácteos enteros | C17: =CONFIG!B19*k_cho+CONFIG!C19*k_prot+CONFIG!D19*k_lip -> 110 | D17: 110 | E17: =IF(AND(ISNUMBER(C17),ISNUMBER(D17)),IF(ABS(C17-D17)<=k_tol,"APROBADO","REVISAR"),IF(EXACT(C17&"",D17&""),"APROBADO","REVISAR")) -> APROBADO
A18: A2 | B18: Atwater independiente (HC×4+PROT×4+LIP×9) · Verduras de consumo general | C18: =CONFIG!B20*k_cho+CONFIG!C20*k_prot+CONFIG!D20*k_lip -> 28 | D18: 28 | E18: =IF(AND(ISNUMBER(C18),ISNUMBER(D18)),IF(ABS(C18-D18)<=k_tol,"APROBADO","REVISAR"),IF(EXACT(C18&"",D18&""),"APROBADO","REVISAR")) -> APROBADO
A19: A2 | B19: Atwater independiente (HC×4+PROT×4+LIP×9) · Verduras de libre consumo | C19: =CONFIG!B21*k_cho+CONFIG!C21*k_prot+CONFIG!D21*k_lip -> 10 | D19: 10 | E19: =IF(AND(ISNUMBER(C19),ISNUMBER(D19)),IF(ABS(C19-D19)<=k_tol,"APROBADO","REVISAR"),IF(EXACT(C19&"",D19&""),"APROBADO","REVISAR")) -> APROBADO
A20: A2 | B20: Atwater independiente (HC×4+PROT×4+LIP×9) · Frutas | C20: =CONFIG!B22*k_cho+CONFIG!C22*k_prot+CONFIG!D22*k_lip -> 60 | D20: 60 | E20: =IF(AND(ISNUMBER(C20),ISNUMBER(D20)),IF(ABS(C20-D20)<=k_tol,"APROBADO","REVISAR"),IF(EXACT(C20&"",D20&""),"APROBADO","REVISAR")) -> APROBADO
A21: A2 | B21: Atwater independiente (HC×4+PROT×4+LIP×9) · Panes, cereales, legumbres frescas y tubérculos | C21: =CONFIG!B23*k_cho+CONFIG!C23*k_prot+CONFIG!D23*k_lip -> 141 | D21: 141 | E21: =IF(AND(ISNUMBER(C21),ISNUMBER(D21)),IF(ABS(C21-D21)<=k_tol,"APROBADO","REVISAR"),IF(EXACT(C21&"",D21&""),"APROBADO","REVISAR")) -> APROBADO
A22: A2 | B22: Atwater independiente (HC×4+PROT×4+LIP×9) · Legumbres secas | C22: =CONFIG!B24*k_cho+CONFIG!C24*k_prot+CONFIG!D24*k_lip -> 173 | D22: 173 | E22: =IF(AND(ISNUMBER(C22),ISNUMBER(D22)),IF(ABS(C22-D22)<=k_tol,"APROBADO","REVISAR"),IF(EXACT(C22&"",D22&""),"APROBADO","REVISAR")) -> APROBADO
A23: A2 | B23: Atwater independiente (HC×4+PROT×4+LIP×9) · Carnes bajas en grasa | C23: =CONFIG!B25*k_cho+CONFIG!C25*k_prot+CONFIG!D25*k_lip -> 66 | D23: 66 | E23: =IF(AND(ISNUMBER(C23),ISNUMBER(D23)),IF(ABS(C23-D23)<=k_tol,"APROBADO","REVISAR"),IF(EXACT(C23&"",D23&""),"APROBADO","REVISAR")) -> APROBADO
A24: A2 | B24: Atwater independiente (HC×4+PROT×4+LIP×9) · Carnes altas en grasa | C24: =CONFIG!B26*k_cho+CONFIG!C26*k_prot+CONFIG!D26*k_lip -> 120 | D24: 120 | E24: =IF(AND(ISNUMBER(C24),ISNUMBER(D24)),IF(ABS(C24-D24)<=k_tol,"APROBADO","REVISAR"),IF(EXACT(C24&"",D24&""),"APROBADO","REVISAR")) -> APROBADO
A25: A2 | B25: Atwater independiente (HC×4+PROT×4+LIP×9) · Aceites, grasas y semillas | C25: =CONFIG!B27*k_cho+CONFIG!C27*k_prot+CONFIG!D27*k_lip -> 45 | D25: 45 | E25: =IF(AND(ISNUMBER(C25),ISNUMBER(D25)),IF(ABS(C25-D25)<=k_tol,"APROBADO","REVISAR"),IF(EXACT(C25&"",D25&""),"APROBADO","REVISAR")) -> APROBADO
A26: A2 | B26: Atwater independiente (HC×4+PROT×4+LIP×9) · Alimentos ricos en lípidos | C26: =CONFIG!B28*k_cho+CONFIG!C28*k_prot+CONFIG!D28*k_lip -> 175 | D26: 175 | E26: =IF(AND(ISNUMBER(C26),ISNUMBER(D26)),IF(ABS(C26-D26)<=k_tol,"APROBADO","REVISAR"),IF(EXACT(C26&"",D26&""),"APROBADO","REVISAR")) -> APROBADO
A27: A2 | B27: Atwater independiente (HC×4+PROT×4+LIP×9) · Azúcares | C27: =CONFIG!B29*k_cho+CONFIG!C29*k_prot+CONFIG!D29*k_lip -> 20 | D27: 20 | E27: =IF(AND(ISNUMBER(C27),ISNUMBER(D27)),IF(ABS(C27-D27)<=k_tol,"APROBADO","REVISAR"),IF(EXACT(C27&"",D27&""),"APROBADO","REVISAR")) -> APROBADO
A28: B | B28: Meta energética aplicada (kcal) | C28: =DATOS!B18 -> 2000 | D28: 2000 | E28: =IF(AND(ISNUMBER(C28),ISNUMBER(D28)),IF(ABS(C28-D28)<=k_tol,"APROBADO","REVISAR"),IF(EXACT(C28&"",D28&""),"APROBADO","REVISAR")) -> APROBADO
A29: B | B29: Meta de proteínas (g) = 15% × 2000 ÷ 4 | C29: =DATOS!D22 -> 75 | D29: 75 | E29: =IF(AND(ISNUMBER(C29),ISNUMBER(D29)),IF(ABS(C29-D29)<=k_tol,"APROBADO","REVISAR"),IF(EXACT(C29&"",D29&""),"APROBADO","REVISAR")) -> APROBADO
A30: B | B30: Meta de H de C (g) = 55% × 2000 ÷ 4 | C30: =DATOS!D23 -> 275 | D30: 275 | E30: =IF(AND(ISNUMBER(C30),ISNUMBER(D30)),IF(ABS(C30-D30)<=k_tol,"APROBADO","REVISAR"),IF(EXACT(C30&"",D30&""),"APROBADO","REVISAR")) -> APROBADO
A31: B | B31: Meta de lípidos (g) = 30% × 2000 ÷ 9 | C31: =DATOS!D24 -> 66.666667 | D31: 66.666667 | E31: =IF(AND(ISNUMBER(C31),ISNUMBER(D31)),IF(ABS(C31-D31)<=k_tol,"APROBADO","REVISAR"),IF(EXACT(C31&"",D31&""),"APROBADO","REVISAR")) -> APROBADO
A32: C | B32: H de C aportados por el patrón (g) | C32: =DIETOSINTESIS!C20 -> 273.5 | D32: 273.5 | E32: =IF(AND(ISNUMBER(C32),ISNUMBER(D32)),IF(ABS(C32-D32)<=k_tol,"APROBADO","REVISAR"),IF(EXACT(C32&"",D32&""),"APROBADO","REVISAR")) -> APROBADO
A33: C | B33: Proteínas aportadas por el patrón (g) | C33: =DIETOSINTESIS!D20 -> 75 | D33: 75 | E33: =IF(AND(ISNUMBER(C33),ISNUMBER(D33)),IF(ABS(C33-D33)<=k_tol,"APROBADO","REVISAR"),IF(EXACT(C33&"",D33&""),"APROBADO","REVISAR")) -> APROBADO
A34: C | B34: Lípidos aportados por el patrón (g) | C34: =DIETOSINTESIS!E20 -> 67 | D34: 67 | E34: =IF(AND(ISNUMBER(C34),ISNUMBER(D34)),IF(ABS(C34-D34)<=k_tol,"APROBADO","REVISAR"),IF(EXACT(C34&"",D34&""),"APROBADO","REVISAR")) -> APROBADO
A35: C | B35: Energía del patrón · energía publicada (kcal) | C35: =DIETOSINTESIS!F20 -> 2000 | D35: 2000 | E35: =IF(AND(ISNUMBER(C35),ISNUMBER(D35)),IF(ABS(C35-D35)<=k_tol,"APROBADO","REVISAR"),IF(EXACT(C35&"",D35&""),"APROBADO","REVISAR")) -> APROBADO
A36: C | B36: Total de equivalentes del patrón | C36: =DIETOSINTESIS!B20 -> 28 | D36: 28 | E36: =IF(AND(ISNUMBER(C36),ISNUMBER(D36)),IF(ABS(C36-D36)<=k_tol,"APROBADO","REVISAR"),IF(EXACT(C36&"",D36&""),"APROBADO","REVISAR")) -> APROBADO
A37: D | B37: Adecuación energética del patrón | C37: =DIETOSINTESIS!E24 -> 1 | D37: 1 | E37: =IF(AND(ISNUMBER(C37),ISNUMBER(D37)),IF(ABS(C37-D37)<=k_tol,"APROBADO","REVISAR"),IF(EXACT(C37&"",D37&""),"APROBADO","REVISAR")) -> APROBADO
A38: D | B38: El patrón queda evaluado como | C38: =DIETOSINTESIS!F24 -> Ajustado | D38: Ajustado | E38: =IF(AND(ISNUMBER(C38),ISNUMBER(D38)),IF(ABS(C38-D38)<=k_tol,"APROBADO","REVISAR"),IF(EXACT(C38&"",D38&""),"APROBADO","REVISAR")) -> APROBADO
A39: D | B39: Porcentaje de proteínas logrado | C39: =DIETOSINTESIS!B31 -> 0.15 | D39: 0.15 | E39: =IF(AND(ISNUMBER(C39),ISNUMBER(D39)),IF(ABS(C39-D39)<=k_tol,"APROBADO","REVISAR"),IF(EXACT(C39&"",D39&""),"APROBADO","REVISAR")) -> APROBADO
A40: D | B40: Porcentaje de H de C logrado | C40: =DIETOSINTESIS!B32 -> 0.547 | D40: 0.547 | E40: =IF(AND(ISNUMBER(C40),ISNUMBER(D40)),IF(ABS(C40-D40)<=k_tol,"APROBADO","REVISAR"),IF(EXACT(C40&"",D40&""),"APROBADO","REVISAR")) -> APROBADO
A41: E | B41: Energía asignada al desayuno (kcal) | C41: =DISTRIBUCION!B21 -> 350 | D41: 350 | E41: =IF(AND(ISNUMBER(C41),ISNUMBER(D41)),IF(ABS(C41-D41)<=k_tol,"APROBADO","REVISAR"),IF(EXACT(C41&"",D41&""),"APROBADO","REVISAR")) -> APROBADO
A42: E | B42: Energía asignada al almuerzo (kcal) | C42: =DISTRIBUCION!D21 -> 535 | D42: 535 | E42: =IF(AND(ISNUMBER(C42),ISNUMBER(D42)),IF(ABS(C42-D42)<=k_tol,"APROBADO","REVISAR"),IF(EXACT(C42&"",D42&""),"APROBADO","REVISAR")) -> APROBADO
A43: E | B43: Energía asignada a la once (kcal) | C43: =DISTRIBUCION!E21 -> 455 | D43: 455 | E43: =IF(AND(ISNUMBER(C43),ISNUMBER(D43)),IF(ABS(C43-D43)<=k_tol,"APROBADO","REVISAR"),IF(EXACT(C43&"",D43&""),"APROBADO","REVISAR")) -> APROBADO
...

Sheet CONFIG
A1: CONFIGURACIÓN · EQUIVALENTES Y CONSTANTES
A3: INICIO | B3: DATOS | C3: DIETOSINTESIS | D3: DISTRIBUCION | E3: MENU_SEMANAL | F3: SEMANA | G3: RESULTADOS | H3: FUENTES | I3: PRUEBAS | J3: CONFIG | K3: CHANGELOG
A5: FACTORES ENERGÉTICOS Y UMBRALES
A6: Parámetro | B6: Unidad | C6: Valor
A7: Energía por gramo de proteína | B7: kcal/g | C7: 4
A8: Energía por gramo de H de C | B8: kcal/g | C8: 4
A9: Energía por gramo de lípidos | B9: kcal/g | C9: 9
A10: Adecuación aceptable: límite inferior | B10: % | C10: 0.95
A11: Adecuación aceptable: límite superior | B11: % | C11: 1.05
A12: Tolerancia del reparto por tiempo de comida | B12: equivalentes | C12: 0.01
A13: Tolerancia de las pruebas | B13: ± | C13: 0.0001
A15: COMPOSICIÓN POR EQUIVALENTE · Sistema chileno · Manual de Porciones de Intercambio para Chile, UDD 2ª ed. 2021 (editable · confirme el sistema que usted utiliza)
A16: Grupo de equivalencia | B16: H de C (g) | C16: Proteínas (g) | D16: Lípidos (g) | E16: Energía (kcal)
A17: Lácteos descremados | B17: 10 | C17: 7 | D17: 0 | E17: 70
A18: Lácteos semidescremados | B18: 9 | C18: 5 | D18: 3 | E18: 85
A19: Lácteos enteros | B19: 9 | C19: 5 | D19: 6 | E19: 110
A20: Verduras de consumo general | B20: 5 | C20: 2 | D20: 0 | E20: 30
A21: Verduras de libre consumo | B21: 2.5 | C21: 0 | D21: 0 | E21: 10
A22: Frutas | B22: 15 | C22: 0 | D22: 0 | E22: 60
A23: Panes, cereales, legumbres frescas y tubérculos | B23: 30 | C23: 3 | D23: 1 | E23: 140
A24: Legumbres secas | B24: 30 | C24: 11 | D24: 1 | E24: 170
A25: Carnes bajas en grasa | B25: 1 | C25: 11 | D25: 2 | E25: 65
A26: Carnes altas en grasa | B26: 1 | C26: 11 | D26: 8 | E26: 120
A27: Aceites, grasas y semillas | B27: 0 | C27: 0 | D27: 5 | E27: 45
A28: Alimentos ricos en lípidos | B28: 5 | C28: 5 | D28: 15 | E28: 175
A29: Azúcares | B29: 5 | C29: 0 | D29: 0 | E29: 20
A30: La energía mostrada es la ENERGÍA PUBLICADA por el Manual de Porciones de Intercambio para Chile (Ratner y cols., UDD, 2ª ed. 2021). Puede diferir levemente de la energía Atwater (H de C×4 + proteínas×4 + lípidos×9) por redondeo y metodología del manual; la comprobación Atwater es independiente y se realiza en la hoja PRUEBAS. Los valores son EDITABLES.
A32: TIEMPOS DE COMIDA Y DISTRIBUCIÓN ENERGÉTICA ORIENTATIVA
A33: Tiempo de comida | B33: % orientativo de la energía
A34: Desayuno | B34: 0.2
A35: Colación AM | B35: 0.05
A36: Almuerzo | B36: 0.3
A37: Once | B37: 0.2
A38: Cena | B38: 0.2
A39: Colación nocturna | B39: 0.05
A40: Suma | B40: =SUM(B34:B39) -> 1
A41: Estos porcentajes son una referencia para comparar el reparto que usted diseñe. No son una norma: ajústelos a los horarios reales, la cultura alimentaria y la situación de la persona.

Sheet CHANGELOG
A1: CHANGELOG
A3: INICIO | B3: DATOS | C3: DIETOSINTESIS | D3: DISTRIBUCION | E3: MENU_SEMANAL | F3: SEMANA | G3: RESULTADOS | H3: FUENTES | I3: PRUEBAS | J3: CONFIG | K3: CHANGELOG
A5: Versión | B5: Fecha | C5: Cambio | E5: Motivo
A6: 1.0 | B6: 2026-07-19 | C6: Versión inicial de NMX-02: tabla dietosintética con patrón diario de equivalentes, ajuste iterativo frente a la prescripción, reparto por tiempos de comida y despliegue semanal. | E6: Inicio de la Fase 4 · Dietas y platillos.
A7: 1.0 | B7: 2026-07-19 | C7: Control de cuadratura del reparto: avisa por grupo si faltan o sobran equivalentes. | E7: Es el error más frecuente al repartir un patrón entre los tiempos de comida.
A8: 1.0 | B8: 2026-07-19 | C8: La tabla semanal parte enlazada al patrón base y detecta las variaciones por día. | E8: Permite construir semanas homogéneas o con variaciones sin perder el control del cálculo.
A9: 1.0 | B9: 2026-07-19 | C9: Composición por equivalente editable, compartida con el criterio de NMX-17. | E9: Coherencia entre el módulo de evaluación por equivalentes y el de planificación.
A10: v1.1.0 | B10: 2026-07-19 | C10: Menú semanal variable por alimentos (base INTA 2018): hojas BASE_ALIMENTOS y MENU_SEMANAL; energía y macros reales por día; meta por día; gráfico dinámico; 10 pruebas.
A11: 2.1.0 | B11: 2026-07-31 | C11: Se restablece el grupo 'Verduras y hortalizas' (31 alimentos, INTA-0332..INTA-0362) mal etiquetados como 'aceites y grasas' en BASE_ALIMENTOS. | E11: Corrección de integridad de datos. No se alteran valores, fórmulas, rangos ni validaciones.
