Workbook
Name k_cobMin: CONFIG!$E$21
Name k_nAlt: CONFIG!$E$22
Name k_tol: CONFIG!$E$23
Name lst_alimentos: ALIMENTOS!$B$9:$B$626
Name lst_prioridad: CONFIG!$K$30:$K$33
Name lst_si: CONFIG!$A$30:$A$31
Name lst_situacion: CONFIG!$F$30:$F$34
Name rng_clave: ALIMENTOS!$T$9:$T$626
Name rng_estado: ALIMENTOS!$S$9:$S$626
Name rng_grupo: ALIMENTOS!$C$9:$C$626
Name rng_K: ALIMENTOS!$H$9:$H$626
Name rng_kcal: ALIMENTOS!$F$9:$F$626
Name rng_Na: ALIMENTOS!$J$9:$J$626
Name rng_orden: ALIMENTOS!$U$9:$U$626
Name rng_P: ALIMENTOS!$I$9:$I$626
Name rng_pp: ALIMENTOS!$Q$9:$Q$626
Name rng_prot: ALIMENTOS!$G$9:$G$626
Name rng_umbrales: CONFIG!$A$13:$E$15
Name u_ppAcep: CONFIG!$E$19
Name u_ppDes: CONFIG!$E$18
Name u_protMin: CONFIG!$E$20
Name v_bloqueo: LICENCIA!$C$14
Name v_limK: DATOS!$C$15
Name v_limNa: DATOS!$C$17
Name v_limP: DATOS!$C$16
Name v_prioridad: DATOS!$C$22
Name v_revision: LICENCIA!$C$41

Sheet INICIO
A1: NUTRIMETRÍA · NMX-42
A2: Explorador renal de alimentos y equivalentes · versión 1.0 · Fase 7 · sujeto a licencia y revisión clínica
A4: Navegación — use las pestañas inferiores del libro
A5: =HYPERLINK("#LICENCIA!A1","▶ LICENCIA") -> ▶ LICENCIA | C5: =HYPERLINK("#DATOS!A1","▶ DATOS") -> ▶ DATOS | E5: =HYPERLINK("#ALIMENTOS!A1","▶ ALIMENTOS") -> ▶ ALIMENTOS | G5: =HYPERLINK("#EXPLORADOR!A1","▶ EXPLORADOR") -> ▶ EXPLORADOR | I5: =HYPERLINK("#SUSTITUCION!A1","▶ SUSTITUCION") -> ▶ SUSTITUCION | K5: =HYPERLINK("#EQUIVALENTES!A1","▶ EQUIVALENTES") -> ▶ EQUIVALENTES | M5: =HYPERLINK("#FUENTES!A1","▶ FUENTES") -> ▶ FUENTES | O5: =HYPERLINK("#PRUEBAS!A1","▶ PRUEBAS") -> ▶ PRUEBAS
A6: Bloqueo y cobertura | C6: Paciente y límites | E6: Base clasificada | G6: Buscar y filtrar | I6: Cambiar por otro | K6: Intercambios renales | M6: Referencias y advertencias | O6: Control de calidad
A7: =HYPERLINK("#CONFIG!A1","▶ CONFIG") -> ▶ CONFIG | C7: =HYPERLINK("#CHANGELOG!A1","▶ CHANGELOG") -> ▶ CHANGELOG
A8: Constantes | C8: Historial
A10: Código del producto | C10: NMX-42
A11: Versión | C11: 1.0
A12: Fecha | C12: 2026-07-24
A13: Fuente de composición | C13: INTA, Universidad de Chile, edición 2018 · LICENCIA
A14: Estado | C14: Sujeto a licencia y a revisión clínica · vea la hoja LICENCIA antes de usar
A15: Formato | C15: .xlsx sin macros · Microsoft 365 (Windows) y Excel 2021 · sin funciones matriciales
A16: Responsable | C16: Equipo Nutrimetría (completar por el titular)
A18: DOS CONDICIONES ANTES DE USAR ESTE ARCHIVO
A19: LICENCIA · La base proviene del INTA de la Universidad de Chile
A20: REVISIÓN CLÍNICA · La hoja LICENCIA incluye una lista de cinco puntos que parte marcada en No. Mientras no la complete, el libro se declara a sí mismo no apto para orientar a un paciente. Es deliberado.
A22: QUÉ HACE ESTE EXPLORADOR
A23: Clasifica cada alimento de la base según su contenido de potasio, fósforo y sodio, y calcula la razón fósforo sobre proteína en las fuentes proteicas: el criterio para cubrir el requerimiento de proteína con la menor carga fosfórica.
A24: Permite consultar y comparar alimentos escalando a la porción real, y muestra qué proporción del límite diario del paciente aporta la selección.
A25: Propone sustituciones dentro del mismo grupo, ordenadas por el nutriente que usted priorice.
A26: De los 618 alimentos de la base, solo 376 tienen los cinco nutrientes críticos completos. Los 242 restantes quedan EXCLUIDOS y marcados: no porque sean inadecuados, sino porque se desconoce su contenido.
A28: AVISO DE ALCANCE
A29: EXACTITUD MATEMÁTICA ≠ VALIDACIÓN CLÍNICA. No está validado clínicamente y no constituye diagnóstico ni prescripción.
A30: Este libro NO define los límites diarios del paciente: los define el equipo tratante a partir del laboratorio y de la situación clínica. Aquí solo se registran para ordenar los alimentos.
A31: Los umbrales de contenido bajo, medio y alto son convenciones de trabajo editables, no categorías normadas.
... A37: FLUJO DE USO
A38: 1 | C38: Lea LICENCIA y complete la lista de revisión clínica. Sin eso, el libro se declara no apto.
A39: 2 | C39: En DATOS registre al paciente y los límites diarios INDICADOS por el equipo tratante, y elija qué nutriente quiere reducir.
A40: 3 | C40: En EXPLORADOR consulte alimentos y porciones: verá el contenido, el nivel de cada nutriente y qué proporción del límite diario aporta la selección.
A41: 4 | C41: En SUSTITUCIÓN indique un alimento a reemplazar y revise las alternativas del mismo grupo con menor carga.
A42: 5 | C42: En EQUIVALENTES revise cómo se distribuyen los alimentos utilizables entre los grupos renales.
A43: 6 | C43: En CONFIG ajuste los umbrales de clasificación al criterio que usted aplica.
A44: 7 | C44: Para registrar la ingesta del paciente use NMX-22 o NMX-29: este módulo selecciona alimentos, no evalúa consumo.

Sheet LICENCIA
A1: NUTRIMETRÍA · NMX-42
A2: Bloqueo de licencia y cobertura de datos · leer antes de usar
A4: =HYPERLINK("#INICIO!A1","▶ VOLVER A INICIO") -> ▶ VOLVER A INICIO
A6: SITUACIÓN DE LA LICENCIA
A7: BLOQUEO ACTIVO. La base de composición proviene de la Tabla de Composición de Alimentos del INTA de la Universidad de Chile, edición 2018. No se encontró dentro del material entregado ninguna autorización de redistribución comercial.
A8: En consecuencia: este archivo es de USO PERSONAL del titular. No lo redistribuya, no lo comercialice y no lo incorpore a un producto de pago mientras no exista autorización documentada.
A9: No se declara que estos datos sean de dominio público, porque no hay evidencia de ello.
A10: Nutrimetría NO cuenta con respaldo ni aval del INTA ni de la Universidad de Chile. Nada en este archivo debe presentarse como avalado por esas instituciones.
A11: Para levantar el bloqueo se requiere autorización escrita, o bien reemplazar la fuente por otra con licencia compatible. El motor de este libro permite ese reemplazo sin reescribir las hojas de trabajo.
A12: Esta revisión no sustituye asesoría jurídica.
A14: ¿Existe autorización documentada de la fuente? | C14: No
A15: Estado del bloqueo | C15: =IF(C14="Sí","Autorización registrada: documente el respaldo y consérvelo junto a este archivo.","BLOQUEO ACTIVO · uso personal exclusivamente. No redistribuir ni comercializar.") -> BLOQUEO ACTIVO · uso personal exclusivamente. No redistribuir ni comercializar.
A17: COBERTURA DE DATOS · LA LIMITACIÓN OPERATIVA MÁS IMPORTANTE
A18: En contexto renal, un dato ausente NO es un dato en cero. Un alimento sin dato de potasio o de fósforo no puede recomendarse como bajo en esos nutrientes: simplemente no se sabe cuánto aporta. Este libro marca esos alimentos como NO UTILIZABLES y los excluye del explorador y del sustituidor.
A23: Nutriente | B23: Alimentos con dato | C23: Total | D23: Cobertura | E23: Alimentos sin dato
A24: Potasio | B24: =COUNT(ALIMENTOS!H$9:H$626) -> 403 | C24: =COUNTA(ALIMENTOS!$B$9:$B$626) -> 618 | D24: =IF(C24=0,"ND",B24/C24) -> 0.65210356 | E24: =C24-B24 -> 215
A25: Fósforo | B25: =COUNT(ALIMENTOS!I$9:I$626) -> 428 | C25: =COUNTA(ALIMENTOS!$B$9:$B$626) -> 618 | D25: =IF(C25=0,"ND",B25/C25) -> 0.69255663 | E25: =C25-B25 -> 190
A26: Sodio | B26: =COUNT(ALIMENTOS!J$9:J$626) -> 567 | C26: =COUNTA(ALIMENTOS!$B$9:$B$626) -> 618 | D26: =IF(C26=0,"ND",B26/C26) -> 0.91747573 | E26: =C26-B26 -> 51
A27: Proteínas | B27: =COUNT(ALIMENTOS!K$9:K$626) -> 604 | C27: =COUNTA(ALIMENTOS!$B$9:$B$626) -> 618 | D27: =IF(C27=0,"ND",B27/C27) -> 0.97734628 | E27: =C27-B27 -> 14
A28: Energía | B28: =COUNT(ALIMENTOS!L$9:L$626) -> 612 | C28: =COUNTA(ALIMENTOS!$B$9:$B$626) -> 618 | D28: =IF(C28=0,"ND",B28/C28) -> 0.99029126 | E28: =C28-B28 -> 6
A30: Alimentos UTILIZABLES en contexto renal | C30: =COUNTIF(ALIMENTOS!$S$9:$S$626,"Utilizable") -> 376 | L30: Con los cinco nutrientes presentes
A31: Alimentos NO utilizables por datos ausentes | C31: =COUNTIF(ALIMENTOS!$S$9:$S$626,"No utilizable") -> 242
A32: Proporción utilizable | C32: =IF(C30+C31=0,"ND",C30/(C30+C31)) -> 0.60841424
A33: Lectura
A35: REVISIÓN CLÍNICA OBLIGATORIA ANTES DE USAR CON UN PACIENTE
A36: ¿Un profesional revisó los umbrales de clasificación de CONFIG? | C36: No
A37: ¿Los límites del paciente provienen de su indicación clínica y no de este libro? | C37: No
A38: ¿Se verificó el laboratorio reciente del paciente? | C38: No
A39: ¿Se consideró el fósforo de aditivos, que la tabla no captura? | C39: No
A40: ¿Se coordinó con el equipo tratante de nefrología? | C40: No
A41: Estado de la revisión clínica | C41: =IF(COUNTIF(C36:C40,"Sí")=5,"Revisión clínica completa: el explorador puede usarse como apoyo.","REVISIÓN PENDIENTE · faltan "&(5-COUNTIF(C36:C40,"Sí"))&" punto(s). Este explorador NO debe usarse para orientar a un paciente mientras la revisión no esté completa.") -> REVISIÓN PENDIENTE · faltan 5 punto(s). Este explorador NO debe usarse para orientar a un paciente mientras la revisión no esté completa.
A43: El ejemplo viene con las cinco casillas en No, de modo que el libro se declara a sí mismo no apto para uso clínico hasta que usted complete la revisión. Es deliberado: un explorador de alimentos renales mal usado puede llevar a restricciones innecesarias o a pasar por alto una carga relevante.

Sheet DATOS
A1: NUTRIMETRÍA · NMX-42
A2: Paciente y límites indicados
A4: =HYPERLINK("#INICIO!A1","▶ VOLVER A INICIO") -> ▶ VOLVER A INICIO
A6: IDENTIFICACIÓN
A7: Nombre o identificador | C7: Caso de ejemplo
A8: Edad (años) | C8: 58
A9: Situación renal | C9: Trasplante
A10: Peso de cálculo (kg) | C10: 68
A11: Fecha | C11: 2026-07-24
A12: Profesional responsable | C12: —
A13: Diabetes (confirmación clínica) | C13: ND
A14: LÍMITES DIARIOS INDICADOS POR EL EQUIPO TRATANTE
A15: Meta clínica de potasio (mg/día) | C15: 2500 | L15: Debe provenir de la indicación clínica, no de este libro
A16: Meta clínica de fósforo (mg/día) | C16: 900 | L16: Ajustar según fosfemia
A17: Meta clínica de sodio (mg/día) | C17: 2000 | L17: Límite máximo
A18: Meta clínica de proteínas (g/día) | C18: ND | L18: 1,2 g/kg en diálisis
A19: Meta clínica de energía (kcal/día) | C19: 2040 | L19: 30 kcal/kg
A20: Estas metas son registradas por el profesional y no se derivan de una tabla universal. Potasio, fósforo y sodio dependen del contexto clínico; proteína debe diferenciar no diálisis, hemodiálisis, diálisis peritoneal, diabetes y trasplante. En el ejemplo postrasplante, proteína queda ND.
A21: PRIORIDAD DE ESTA CONSULTA
A22: Nutriente que se quiere reducir | C22: Potasio | L22: Determina el orden en que el sustituidor propone alternativas
A23: Laboratorio reciente · potasio sérico (mEq/L) | C23: 5.8
A24: Laboratorio reciente · fósforo sérico (mg/dL) | C24: 5.4
A25: Observaciones clínicas | C25: Hiperkalemia persistente pese a la restricción declarada.
A27: Los límites diarios NO los define este libro: los define el equipo tratante a partir del laboratorio y de la situación del paciente. Aquí solo se registran para que el explorador ordene los alimentos según esa indicación.
A28: TRAZABILIDAD DE METAS CLÍNICAS
A29: Componente | B29: Estado | E29: Fuente | H29: Limitación
A30: Potasio | B30: =IF(ISNUMBER(C15),"NUMERICO_INGRESADO",IF(C15="ND","ND","ND")) -> NUMERICO_INGRESADO | E30: Equipo tratante | H30: No existe cifra universal. Integrar kalemia, fármacos, acidosis, diálisis, tránsito intestinal y sustitutos de sal.
A31: Fósforo | B31: =IF(ISNUMBER(C16),"NUMERICO_INGRESADO",IF(C16="ND","ND","ND")) -> NUMERICO_INGRESADO | E31: Equipo tratante | H31: No existe cifra universal. INTA no captura bien aditivos fosfatados ni absorción; integrar fosfemia, quelantes y diálisis.
A32: Sodio | B32: =IF(ISNUMBER(C17),"NUMERICO_INGRESADO",IF(C17="ND","ND","ND")) -> NUMERICO_INGRESADO | E32: Equipo tratante / KDOQI 2020 | H32: KDOQI orienta <2300 mg/día en ERC 3–5, 5D o postrasplante; individualizar por presión, volumen y pérdidas.
A33: Proteínas | B33: =IF(ISNUMBER(C18),"NUMERICO_INGRESADO",IF(C18="ND","ND","ND")) -> ND | E33: Equipo tratante / KDOQI 2020 | H33: No usar una cifra para todas las poblaciones. Trasplante requiere evaluación clínica y no recibe meta automática.
A34: Energía | B34: =IF(ISNUMBER(C19),"NUMERICO_INGRESADO",IF(C19="ND","ND","ND")) -> NUMERICO_INGRESADO | E34: Equipo tratante / KDOQI 2020 | H34: 25–35 kcal/kg/día es un rango orientador sujeto a edad, actividad, composición corporal, inflamación y objetivo clínico.
A35: NUMERICO_INGRESADO indica una meta clínica documentada. ND indica ausencia de un dato utilizable; ND nunca equivale a cero y no permite declarar un alimento seguro.

Sheet ALIMENTOS
A1: NUTRIMETRÍA · NMX-42
A2: Base de alimentos clasificada según criterios renales
A4: =HYPERLINK("#INICIO!A1","▶ VOLVER A INICIO") -> ▶ VOLVER A INICIO
A6: Hoja de consulta: no modifique sus valores. 's/i' indica que la fuente no informa ese nutriente y NO equivale a cero. Los alimentos marcados como no utilizables quedan fuera del explorador.
A8: ID | B8: Alimento | C8: Grupo | D8: Código | E8: Origen del grupo | F8: Energía (kcal) | G8: Proteínas (g) | H8: Potasio (mg) | I8: Fósforo (mg) | J8: Sodio (mg) | K8: Energía | L8: Proteína | M8: Calcio (mg) | N8: Nivel de potasio | O8: Nivel de fósforo | P8: Nivel de sodio | Q8: Razón P/proteína | R8: Nivel de la razón | S8: Estado del dato | T8: Clave de orden | U8: Valor de orden (auxiliar)
A9: INTA-0001 | B9: Leche materna | C9: Leche y derivados | D9: 2.1 | E9: declarado en la fuente | F9: 70 | G9: 1 | H9: 51 | I9: 14 | J9: 17 | K9: 70 | L9: 1 | M9: 32 | N9: =IF(NOT(ISNUMBER(H9)),"Sin dato",IF(H9<=INDEX(rng_umbrales,1,2),"Bajo",IF(H9<=INDEX(rng_umbrales,1,3),"Medio",IF(H9<=INDEX(rng_umbrales,1,4),"Alto","Muy alto")))) -> Bajo | O9: =IF(NOT(ISNUMBER(I9)),"Sin dato",IF(I9<=INDEX(rng_umbrales,2,2),"Bajo",IF(I9<=INDEX(rng_umbrales,2,3),"Medio",IF(I9<=INDEX(rng_umbrales,2,4),"Alto","Muy alto")))) -> Bajo | P9: =IF(NOT(ISNUMBER(J9)),"Sin dato",IF(J9<=INDEX(rng_umbrales,3,2),"Bajo",IF(J9<=INDEX(rng_umbrales,3,3),"Medio",IF(J9<=INDEX(rng_umbrales,3,4),"Alto","Muy alto")))) -> Bajo | Q9: =IF(OR(NOT(ISNUMBER(G9)),NOT(ISNUMBER(I9))),"N/C",IF(G9<u_protMin,"N/C: no es fuente proteica",I9/G9)) -> N/C: no es fuente proteica | R9: =IF(NOT(ISNUMBER(Q9)),"N/C",IF(Q9<=u_ppDes,"Deseable",IF(Q9<=u_ppAcep,"Aceptable","Alta"))) -> N/C | S9: =IF(COUNT(F9:J9)=k_cobMin,"Utilizable","No utilizable") -> Utilizable | T9: =IF(S9<>"Utilizable","",C9&"|"&TEXT(IF(v_prioridad="Potasio",H9,IF(v_prioridad="Fósforo",I9,IF(v_prioridad="Sodio",J9,IF(ISNUMBER(Q9),Q9,99999)))),"000000.00")) -> Leche y derivados|00.000.051 | U9: =IF(OR($S9<>"Utilizable",$C9<>SUSTITUCION!$C$13),999999,IF(v_prioridad="Potasio",$H9,IF(v_prioridad="Fósforo",$I9,IF(v_prioridad="Sodio",$J9,IF(ISNUMBER($Q9),$Q9,999999))))) -> 999999
A10: INTA-0002 | B10: Leche de Burra | C10: Leche y derivados | D10: 2.1 | E10: declarado en la fuente | F10: 41 | G10: 1.6 | H10: s/i | I10: 60 | J10: s/i | K10: 41 | L10: 1.6 | M10: 138 | N10: =IF(NOT(ISNUMBER(H10)),"Sin dato",IF(H10<=INDEX(rng_umbrales,1,2),"Bajo",IF(H10<=INDEX(rng_umbrales,1,3),"Medio",IF(H10<=INDEX(rng_umbrales,1,4),"Alto","Muy alto")))) -> Sin dato | O10: =IF(NOT(ISNUMBER(I10)),"Sin dato",IF(I10<=INDEX(rng_umbrales,2,2),"Bajo",IF(I10<=INDEX(rng_umbrales,2,3),"Medio",IF(I10<=INDEX(rng_umbrales,2,4),"Alto","Muy alto")))) -> Medio | P10: =IF(NOT(ISNUMBER(J10)),"Sin dato",IF(J10<=INDEX(rng_umbrales,3,2),"Bajo",IF(J10<=INDEX(rng_umbrales,3,3),"Medio",IF(J10<=INDEX(rng_umbrales,3,4),"Alto","Muy alto")))) -> Sin dato | Q10: =IF(OR(NOT(ISNUMBER(G10)),NOT(ISNUMBER(I10))),"N/C",IF(G10<u_protMin,"N/C: no es fuente proteica",I10/G10)) -> N/C: no es fuente proteica | R10: =IF(NOT(ISNUMBER(Q10)),"N/C",IF(Q10<=u_ppDes,"Deseable",IF(Q10<=u_ppAcep,"Aceptable","Alta"))) -> N/C | S10: =IF(COUNT(F10:J10)=k_cobMin,"Utilizable","No utilizable") -> No utilizable | T10: =IF(S10<>"Utilizable","",C10&"|"&TEXT(IF(v_prioridad="Potasio",H10,IF(v_prioridad="Fósforo",I10,IF(v_prioridad="Sodio",J10,IF(ISNUMBER(Q10),Q10,99999)))),"000000.00")) | U10: =IF(OR($S10<>"Utilizable",$C10<>SUSTITUCION!$C$13),999999,IF(v_prioridad="Potasio",$H10,IF(v_prioridad="Fósforo",$I10,IF(v_prioridad="Sodio",$J10,IF(ISNUMBER($Q10),$Q10,999999))))) -> 999999
A11: INTA-0003 | B11: Leche de cabra con Vit. D | C11: Leche y derivados | D11: 2.1 | E11: declarado en la fuente | F11: 69 | G11: 3.6 | H11: 204 | I11: 111 | J11: 50 | K11: 69 | L11: 3.6 | M11: 134 | N11: =IF(NOT(ISNUMBER(H11)),"Sin dato",IF(H11<=INDEX(rng_umbrales,1,2),"Bajo",IF(H11<=INDEX(rng_umbrales,1,3),"Medio",IF(H11<=INDEX(rng_umbrales,1,4),"Alto","Muy alto")))) -> Alto | O11: =IF(NOT(ISNUMBER(I11)),"Sin dato",IF(I11<=INDEX(rng_umbrales,2,2),"Bajo",IF(I11<=INDEX(rng_umbrales,2,3),"Medio",IF(I11<=INDEX(rng_umbrales,2,4),"Alto","Muy alto")))) -> Alto | P11: =IF(NOT(ISNUMBER(J11)),"Sin dato",IF(J11<=INDEX(rng_umbrales,3,2),"Bajo",IF(J11<=INDEX(rng_umbrales,3,3),"Medio",IF(J11<=INDEX(rng_umbrales,3,4),"Alto","Muy alto")))) -> Medio | Q11: =IF(OR(NOT(ISNUMBER(G11)),NOT(ISNUMBER(I11))),"N/C",IF(G11<u_protMin,"N/C: no es fuente proteica",I11/G11)) -> N/C: no es fuente proteica | R11: =IF(NOT(ISNUMBER(Q11)),"N/C",IF(Q11<=u_ppDes,"Deseable",IF(Q11<=u_ppAcep,"Aceptable","Alta"))) -> N/C | S11: =IF(COUNT(F11:J11)=k_cobMin,"Utilizable","No utilizable") -> Utilizable | T11: =IF(S11<>"Utilizable","",C11&"|"&TEXT(IF(v_prioridad="Potasio",H11,IF(v_prioridad="Fósforo",I11,IF(v_prioridad="Sodio",J11,IF(ISNUMBER(Q11),Q11,99999)))),"000000.00")) -> Leche y derivados|00.000.204 | U11: =IF(OR($S11<>"Utilizable",$C11<>SUSTITUCION!$C$13),999999,IF(v_prioridad="Potasio",$H11,IF(v_prioridad="Fósforo",$I11,IF(v_prioridad="Sodio",$J11,IF(ISNUMBER($Q11),$Q11,999999))))) -> 999999
A12: INTA-0004 | B12: Leche fluida entera | C12: Leche y derivados | D12: 2.1 | E12: declarado en la fuente | F12: 64 | G12: 3.3 | H12: 151 | I12: 93 | J12: 49 | K12: 64 | L12: 3.3 | M12: 119 | N12: =IF(NOT(ISNUMBER(H12)),"Sin dato",IF(H12<=INDEX(rng_umbrales,1,2),"Bajo",IF(H12<=INDEX(rng_umbrales,1,3),"Medio",IF(H12<=INDEX(rng_umbrales,1,4),"Alto","Muy alto")))) -> Medio | O12: =IF(NOT(ISNUMBER(I12)),"Sin dato",IF(I12<=INDEX(rng_umbrales,2,2),"Bajo",IF(I12<=INDEX(rng_umbrales,2,3),"Medio",IF(I12<=INDEX(rng_umbrales,2,4),"Alto","Muy alto")))) -> Medio | P12: =IF(NOT(ISNUMBER(J12)),"Sin dato",IF(J12<=INDEX(rng_umbrales,3,2),"Bajo",IF(J12<=INDEX(rng_umbrales,3,3),"Medio",IF(J12<=INDEX(rng_umbrales,3,4),"Alto","Muy alto")))) -> Medio | Q12: =IF(OR(NOT(ISNUMBER(G12)),NOT(ISNUMBER(I12))),"N/C",IF(G12<u_protMin,"N/C: no es fuente proteica",I12/G12)) -> N/C: no es fuente proteica | R12: =IF(NOT(ISNUMBER(Q12)),"N/C",IF(Q12<=u_ppDes,"Deseable",IF(Q12<=u_ppAcep,"Aceptable","Alta"))) -> N/C | S12: =IF(COUNT(F12:J12)=k_cobMin,"Utilizable","No utilizable") -> Utilizable | T12: =IF(S12<>"Utilizable","",C12&"|"&TEXT(IF(v_prioridad="Potasio",H12,IF(v_prioridad="Fósforo",I12,IF(v_prioridad="Sodio",J12,IF(ISNUMBER(Q12),Q12,99999)))),"000000.00")) -> Leche y derivados|00.000.151 | U12: =IF(OR($S12<>"Utilizable",$C12<>SUSTITUCION!$C$13),999999,IF(v_prioridad="Potasio",$H12,IF(v_prioridad="Fósforo",$I12,IF(v_prioridad="Sodio",$J12,IF(ISNUMBER($Q12),$Q12,999999))))) -> 999999
A13: INTA-0005 | B13: Leche fluida entera 2 | C13: Leche y derivados | D13: 2.1 | E13: declarado en la fuente | F13: 58 | G13: 3.2 | H13: 141.8 | I13: 95 | J13: 59.7 | K13: 58 | L13: 3.2 | M13: 123 | N13: =IF(NOT(ISNUMBER(H13)),"Sin dato",IF(H13<=INDEX(rng_umbrales,1,2),"Bajo",IF(H13<=INDEX(rng_umbrales,1,3),"Medio",IF(H13<=INDEX(rng_umbrales,1,4),"Alto","Muy alto")))) -> Medio | O13: =IF(NOT(ISNUMBER(I13)),"Sin dato",IF(I13<=INDEX(rng_umbrales,2,2),"Bajo",IF(I13<=INDEX(rng_umbrales,2,3),"Medio",IF(I13<=INDEX(rng_umbrales,2,4),"Alto","Muy alto")))) -> Medio | P13: =IF(NOT(ISNUMBER(J13)),"Sin dato",IF(J13<=INDEX(rng_umbrales,3,2),"Bajo",IF(J13<=INDEX(rng_umbrales,3,3),"Medio",IF(J13<=INDEX(rng_umbrales,3,4),"Alto","Muy alto")))) -> Medio | Q13: =IF(OR(NOT(ISNUMBER(G13)),NOT(ISNUMBER(I13))),"N/C",IF(G13<u_protMin,"N/C: no es fuente proteica",I13/G13)) -> N/C: no es fuente proteica | R13: =IF(NOT(ISNUMBER(Q13)),"N/C",IF(Q13<=u_ppDes,"Deseable",IF(Q13<=u_ppAcep,"Aceptable","Alta"))) -> N/C | S13: =IF(COUNT(F13:J13)=k_cobMin,"Utilizable","No utilizable") -> Utilizable | T13: =IF(S13<>"Utilizable","",C13&"|"&TEXT(IF(v_prioridad="Potasio",H13,IF(v_prioridad="Fósforo",I13,IF(v_prioridad="Sodio",J13,IF(ISNUMBER(Q13),Q13,99999)))),"000000.00")) -> Leche y derivados|00.000.142 | U13: =IF(OR($S13<>"Utilizable",$C13<>SUSTITUCION!$C$13),999999,IF(v_prioridad="Potasio",$H13,IF(v_prioridad="Fósforo",$I13,IF(v_prioridad="Sodio",$J13,IF(ISNUMBER($Q13),$Q13,999999))))) -> 999999
A14: INTA-0006 | B14: Leche entera con sabor | C14: Leche y derivados | D14: 2.1 | E14: declarado en la fuente | F14: 80 | G14: 2.4 | H14: 167 | I14: 100 | J14: 59.6 | K14: 80 | L14: 2.4 | M14: 112 | N14: =IF(NOT(ISNUMBER(H14)),"Sin dato",IF(H14<=INDEX(rng_umbrales,1,2),"Bajo",IF(H14<=INDEX(rng_umbrales,1,3),"Medio",IF(H14<=INDEX(rng_umbrales,1,4),"Alto","Muy alto")))) -> Medio | O14: =IF(NOT(ISNUMBER(I14)),"Sin dato",IF(I14<=INDEX(rng_umbrales,2,2),"Bajo",IF(I14<=INDEX(rng_umbrales,2,3),"Medio",IF(I14<=INDEX(rng_umbrales,2,4),"Alto","Muy alto")))) -> Medio | P14: =IF(NOT(ISNUMBER(J14)),"Sin dato",IF(J14<=INDEX(rng_umbrales,3,2),"Bajo",IF(J14<=INDEX(rng_umbrales,3,3),"Medio",IF(J14<=INDEX(rng_umbrales,3,4),"Alto","Muy alto")))) -> Medio | Q14: =IF(OR(NOT(ISNUMBER(G14)),NOT(ISNUMBER(I14))),"N/C",IF(G14<u_protMin,"N/C: no es fuente proteica",I14/G14)) -> N/C: no es fuente proteica | R14: =IF(NOT(ISNUMBER(Q14)),"N/C",IF(Q14<=u_ppDes,"Deseable",IF(Q14<=u_ppAcep,"Aceptable","Alta"))) -> N/C | S14: =IF(COUNT(F14:J14)=k_cobMin,"Utilizable","No utilizable") -> Utilizable | T14: =IF(S14<>"Utilizable","",C14&"|"&TEXT(IF(v_prioridad="Potasio",H14,IF(v_prioridad="Fósforo",I14,IF(v_prioridad="Sodio",J14,IF(ISNUMBER(Q14),Q14,99999)))),"000000.00")) -> Leche y derivados|00.000.167 | U14: =IF(OR($S14<>"Utilizable",$C14<>SUSTITUCION!$C$13),999999,IF(v_prioridad="Potasio",$H14,IF(v_prioridad="Fósforo",$I14,IF(v_prioridad="Sodio",$J14,IF(ISNUMBER($Q14),$Q14,999999))))) -> 999999
A15: INTA-0007 | B15: Leche semidescremada | C15: Leche y derivados | D15: 2.1 | E15: declarado en la fuente | F15: 42 | G15: 2.6 | H15: s/i | I15: s/i | J15: s/i | K15: 42 | L15: 2.6 | M15: s/i | N15: =IF(NOT(ISNUMBER(H15)),"Sin dato",IF(H15<=INDEX(rng_umbrales,1,2),"Bajo",IF(H15<=INDEX(rng_umbrales,1,3),"Medio",IF(H15<=INDEX(rng_umbrales,1,4),"Alto","Muy alto")))) -> Sin dato | O15: =IF(NOT(ISNUMBER(I15)),"Sin dato",IF(I15<=INDEX(rng_umbrales,2,2),"Bajo",IF(I15<=INDEX(rng_umbrales,2,3),"Medio",IF(I15<=INDEX(rng_umbrales,2,4),"Alto","Muy alto")))) -> Sin dato | P15: =IF(NOT(ISNUMBER(J15)),"Sin dato",IF(J15<=INDEX(rng_umbrales,3,2),"Bajo",IF(J15<=INDEX(rng_umbrales,3,3),"Medio",IF(J15<=INDEX(rng_umbrales,3,4),"Alto","Muy alto")))) -> Sin dato | Q15: =IF(OR(NOT(ISNUMBER(G15)),NOT(ISNUMBER(I15))),"N/C",IF(G15<u_protMin,"N/C: no es fuente proteica",I15/G15)) -> N/C | R15: =IF(NOT(ISNUMBER(Q15)),"N/C",IF(Q15<=u_ppDes,"Deseable",IF(Q15<=u_ppAcep,"Aceptable","Alta"))) -> N/C | S15: =IF(COUNT(F15:J15)=k_cobMin,"Utilizable","No utilizable") -> No utilizable | T15: =IF(S15<>"Utilizable","",C15&"|"&TEXT(IF(v_prioridad="Potasio",H15,IF(v_prioridad="Fósforo",I15,IF(v_prioridad="Sodio",J15,IF(ISNUMBER(Q15),Q15,99999)))),"000000.00")) | U15: =IF(OR($S15<>"Utilizable",$C15<>SUSTITUCION!$C$13),999999,IF(v_prioridad="Potasio",$H15,IF(v_prioridad="Fósforo",$I15,IF(v_prioridad="Sodio",$J15,IF(ISNUMBER($Q15),$Q15,999999))))) -> 999999
A16: INTA-0008 | B16: Leche semidescremada con sabor | C16: Leche y derivados | D16: 2.1 | E16: declarado en la fuente | F16: 76 | G16: 3 | H16: 169 | I16: 102 | J16: 66 | K16: 76 | L16: 3 | M16: 109 | N16: =IF(NOT(ISNUMBER(H16)),"Sin dato",IF(H16<=INDEX(rng_umbrales,1,2),"Bajo",IF(H16<=INDEX(rng_umbrales,1,3),"Medio",IF(H16<=INDEX(rng_umbrales,1,4),"Alto","Muy alto")))) -> Medio | O16: =IF(NOT(ISNUMBER(I16)),"Sin dato",IF(I16<=INDEX(rng_umbrales,2,2),"Bajo",IF(I16<=INDEX(rng_umbrales,2,3),"Medio",IF(I16<=INDEX(rng_umbrales,2,4),"Alto","Muy alto")))) -> Alto | P16: =IF(NOT(ISNUMBER(J16)),"Sin dato",IF(J16<=INDEX(rng_umbrales,3,2),"Bajo",IF(J16<=INDEX(rng_umbrales,3,3),"Medio",IF(J16<=INDEX(rng_umbrales,3,4),"Alto","Muy alto")))) -> Medio | Q16: =IF(OR(NOT(ISNUMBER(G16)),NOT(ISNUMBER(I16))),"N/C",IF(G16<u_protMin,"N/C: no es fuente proteica",I16/G16)) -> N/C: no es fuente proteica | R16: =IF(NOT(ISNUMBER(Q16)),"N/C",IF(Q16<=u_ppDes,"Deseable",IF(Q16<=u_ppAcep,"Aceptable","Alta"))) -> N/C | S16: =IF(COUNT(F16:J16)=k_cobMin,"Utilizable","No utilizable") -> Utilizable | T16: =IF(S16<>"Utilizable","",C16&"|"&TEXT(IF(v_prioridad="Potasio",H16,IF(v_prioridad="Fósforo",I16,IF(v_prioridad="Sodio",J16,IF(ISNUMBER(Q16),Q16,99999)))),"000000.00")) -> Leche y derivados|00.000.169 | U16: =IF(OR($S16<>"Utilizable",$C16<>SUSTITUCION!$C$13),999999,IF(v_prioridad="Potasio",$H16,IF(v_prioridad="Fósforo",$I16,IF(v_prioridad="Sodio",$J16,IF(ISNUMBER($Q16),$Q16,999999))))) -> 999999
A17: INTA-0009 | B17: Leche semidescremada con sabor chocolate | C17: Leche y derivados | D17: 2.1 | E17: declarado en la fuente | F17: 52 | G17: 3.2 | H17: s/i | I17: 84 | J17: 70 | K17: 52 | L17: 3.2 | M17: 93 | N17: =IF(NOT(ISNUMBER(H17)),"Sin dato",IF(H17<=INDEX(rng_umbrales,1,2),"Bajo",IF(H17<=INDEX(rng_umbrales,1,3),"Medio",IF(H17<=INDEX(rng_umbrales,1,4),"Alto","Muy alto")))) -> Sin dato | O17: =IF(NOT(ISNUMBER(I17)),"Sin dato",IF(I17<=INDEX(rng_umbrales,2,2),"Bajo",IF(I17<=INDEX(rng_umbrales,2,3),"Medio",IF(I17<=INDEX(rng_umbrales,2,4),"Alto","Muy alto")))) -> Medio | P17: =IF(NOT(ISNUMBER(J17)),"Sin dato",IF(J17<=INDEX(rng_umbrales,3,2),"Bajo",IF(J17<=INDEX(rng_umbrales,3,3),"Medio",IF(J17<=INDEX(rng_umbrales,3,4),"Alto","Muy alto")))) -> Medio | Q17: =IF(OR(NOT(ISNUMBER(G17)),NOT(ISNUMBER(I17))),"N/C",IF(G17<u_protMin,"N/C: no es fuente proteica",I17/G17)) -> N/C: no es fuente proteica | R17: =IF(NOT(ISNUMBER(Q17)),"N/C",IF(Q17<=u_ppDes,"Deseable",IF(Q17<=u_ppAcep,"Aceptable","Alta"))) -> N/C | S17: =IF(COUNT(F17:J17)=k_cobMin,"Utilizable","No utilizable") -> No utilizable | T17: =IF(S17<>"Utilizable","",C17&"|"&TEXT(IF(v_prioridad="Potasio",H17,IF(v_prioridad="Fósforo",I17,IF(v_prioridad="Sodio",J17,IF(ISNUMBER(Q17),Q17,99999)))),"000000.00")) | U17: =IF(OR($S17<>"Utilizable",$C17<>SUSTITUCION!$C$13),999999,IF(v_prioridad="Potasio",$H17,IF(v_prioridad="Fósforo",$I17,IF(v_prioridad="Sodio",$J17,IF(ISNUMBER($Q17),$Q17,999999))))) -> 999999
A18: INTA-0010 | B18: Leche semidescremada con sabor frutilla | C18: Leche y derivados | D18: 2.1 | E18: declarado en la fuente | F18: 54 | G18: 3.1 | H18: s/i | I18: 84 | J18: 60 | K18: 54 | L18: 3.1 | M18: 104 | N18: =IF(NOT(ISNUMBER(H18)),"Sin dato",IF(H18<=INDEX(rng_umbrales,1,2),"Bajo",IF(H18<=INDEX(rng_umbrales,1,3),"Medio",IF(H18<=INDEX(rng_umbrales,1,4),"Alto","Muy alto")))) -> Sin dato | O18: =IF(NOT(ISNUMBER(I18)),"Sin dato",IF(I18<=INDEX(rng_umbrales,2,2),"Bajo",IF(I18<=INDEX(rng_umbrales,2,3),"Medio",IF(I18<=INDEX(rng_umbrales,2,4),"Alto","Muy alto")))) -> Medio | P18: =IF(NOT(ISNUMBER(J18)),"Sin dato",IF(J18<=INDEX(rng_umbrales,3,2),"Bajo",IF(J18<=INDEX(rng_umbrales,3,3),"Medio",IF(J18<=INDEX(rng_umbrales,3,4),"Alto","Muy alto")))) -> Medio | Q18: =IF(OR(NOT(ISNUMBER(G18)),NOT(ISNUMBER(I18))),"N/C",IF(G18<u_protMin,"N/C: no es fuente proteica",I18/G18)) -> N/C: no es fuente proteica | R18: =IF(NOT(ISNUMBER(Q18)),"N/C",IF(Q18<=u_ppDes,"Deseable",IF(Q18<=u_ppAcep,"Aceptable","Alta"))) -> N/C | S18: =IF(COUNT(F18:J18)=k_cobMin,"Utilizable","No utilizable") -> No utilizable | T18: =IF(S18<>"Utilizable","",C18&"|"&TEXT(IF(v_prioridad="Potasio",H18,IF(v_prioridad="Fósforo",I18,IF(v_prioridad="Sodio",J18,IF(ISNUMBER(Q18),Q18,99999)))),"000000.00")) | U18: =IF(OR($S18<>"Utilizable",$C18<>SUSTITUCION!$C$13),999999,IF(v_prioridad="Potasio",$H18,IF(v_prioridad="Fósforo",$I18,IF(v_prioridad="Sodio",$J18,IF(ISNUMBER($Q18),$Q18,999999))))) -> 999999
A19: INTA-0011 | B19: Leche semidescremada sin lactosa | C19: Leche y derivados | D19: 2.1 | E19: declarado en la fuente | F19: 44 | G19: 3.1 | H19: s/i | I19: s/i | J19: 60 | K19: 44 | L19: 3.1 | M19: 101 | N19: =IF(NOT(ISNUMBER(H19)),"Sin dato",IF(H19<=INDEX(rng_umbrales,1,2),"Bajo",IF(H19<=INDEX(rng_umbrales,1,3),"Medio",IF(H19<=INDEX(rng_umbrales,1,4),"Alto","Muy alto")))) -> Sin dato | O19: =IF(NOT(ISNUMBER(I19)),"Sin dato",IF(I19<=INDEX(rng_umbrales,2,2),"Bajo",IF(I19<=INDEX(rng_umbrales,2,3),"Medio",IF(I19<=INDEX(rng_umbrales,2,4),"Alto","Muy alto")))) -> Sin dato | P19: =IF(NOT(ISNUMBER(J19)),"Sin dato",IF(J19<=INDEX(rng_umbrales,3,2),"Bajo",IF(J19<=INDEX(rng_umbrales,3,3),"Medio",IF(J19<=INDEX(rng_umbrales,3,4),"Alto","Muy alto")))) -> Medio | Q19: =IF(OR(NOT(ISNUMBER(G19)),NOT(ISNUMBER(I19))),"N/C",IF(G19<u_protMin,"N/C: no es fuente proteica",I19/G19)) -> N/C | R19: =IF(NOT(ISNUMBER(Q19)),"N/C",IF(Q19<=u_ppDes,"Deseable",IF(Q19<=u_ppAcep,"Aceptable","Alta"))) -> N/C | S19: =IF(COUNT(F19:J19)=k_cobMin,"Utilizable","No utilizable") -> No utilizable | T19: =IF(S19<>"Utilizable","",C19&"|"&TEXT(IF(v_prioridad="Potasio",H19,IF(v_prioridad="Fósforo",I19,IF(v_prioridad="Sodio",J19,IF(ISNUMBER(Q19),Q19,99999)))),"000000.00")) | U19: =IF(OR($S19<>"Utilizable",$C19<>SUSTITUCION!$C$13),999999,IF(v_prioridad="Potasio",$H19,IF(v_prioridad="Fósforo",$I19,IF(v_prioridad="Sodio",$J19,IF(ISNUMBER($Q19),$Q19,999999))))) -> 999999
A20: INTA-0012 | B20: Leche descremada | C20: Leche y derivados | D20: 2.1 | E20: declarado en la fuente | F20: 32 | G20: 3.3 | H20: s/i | I20: 90 | J20: 32 | K20: 32 | L20: 3.3 | M20: 115 | N20: =IF(NOT(ISNUMBER(H20)),"Sin dato",IF(H20<=INDEX(rng_umbrales,1,2),"Bajo",IF(H20<=INDEX(rng_umbrales,1,3),"Medio",IF(H20<=INDEX(rng_umbrales,1,4),"Alto","Muy alto")))) -> Sin dato | O20: =IF(NOT(ISNUMBER(I20)),"Sin dato",IF(I20<=INDEX(rng_umbrales,2,2),"Bajo",IF(I20<=INDEX(rng_umbrales,2,3),"Medio",IF(I20<=INDEX(rng_umbrales,2,4),"Alto","Muy alto")))) -> Medio | P20: =IF(NOT(ISNUMBER(J20)),"Sin dato",IF(J20<=INDEX(rng_umbrales,3,2),"Bajo",IF(J20<=INDEX(rng_umbrales,3,3),"Medio",IF(J20<=INDEX(rng_umbrales,3,4),"Alto","Muy alto")))) -> Bajo | Q20: =IF(OR(NOT(ISNUMBER(G20)),NOT(ISNUMBER(I20))),"N/C",IF(G20<u_protMin,"N/C: no es fuente proteica",I20/G20)) -> N/C: no es fuente proteica | R20: =IF(NOT(ISNUMBER(Q20)),"N/C",IF(Q20<=u_ppDes,"Deseable",IF(Q20<=u_ppAcep,"Aceptable","Alta"))) -> N/C | S20: =IF(COUNT(F20:J20)=k_cobMin,"Utilizable","No utilizable") -> No utilizable | T20: =IF(S20<>"Utilizable","",C20&"|"&TEXT(IF(v_prioridad="Potasio",H20,IF(v_prioridad="Fósforo",I20,IF(v_prioridad="Sodio",J20,IF(ISNUMBER(Q20),Q20,99999)))),"000000.00")) | U20: =IF(OR($S20<>"Utilizable",$C20<>SUSTITUCION!$C$13),999999,IF(v_prioridad="Potasio",$H20,IF(v_prioridad="Fósforo",$I20,IF(v_prioridad="Sodio",$J20,IF(ISNUMBER($Q20),$Q20,999999))))) -> 999999
A21: INTA-0013 | B21: Leche descremada 2 | C21: Leche y derivados | D21: 2.1 | E21: declarado en la fuente | F21: 42 | G21: 3.4 | H21: 150 | I21: 95 | J21: 44 | K21: 42 | L21: 3.4 | M21: 125 | N21: =IF(NOT(ISNUMBER(H21)),"Sin dato",IF(H21<=INDEX(rng_umbrales,1,2),"Bajo",IF(H21<=INDEX(rng_umbrales,1,3),"Medio",IF(H21<=INDEX(rng_umbrales,1,4),"Alto","Muy alto")))) -> Medio | O21: =IF(NOT(ISNUMBER(I21)),"Sin dato",IF(I21<=INDEX(rng_umbrales,2,2),"Bajo",IF(I21<=INDEX(rng_umbrales,2,3),"Medio",IF(I21<=INDEX(rng_umbrales,2,4),"Alto","Muy alto")))) -> Medio | P21: =IF(NOT(ISNUMBER(J21)),"Sin dato",IF(J21<=INDEX(rng_umbrales,3,2),"Bajo",IF(J21<=INDEX(rng_umbrales,3,3),"Medio",IF(J21<=INDEX(rng_umbrales,3,4),"Alto","Muy alto")))) -> Medio | Q21: =IF(OR(NOT(ISNUMBER(G21)),NOT(ISNUMBER(I21))),"N/C",IF(G21<u_protMin,"N/C: no es fuente proteica",I21/G21)) -> N/C: no es fuente proteica | R21: =IF(NOT(ISNUMBER(Q21)),"N/C",IF(Q21<=u_ppDes,"Deseable",IF(Q21<=u_ppAcep,"Aceptable","Alta"))) -> N/C | S21: =IF(COUNT(F21:J21)=k_cobMin,"Utilizable","No utilizable") -> Utilizable | T21: =IF(S21<>"Utilizable","",C21&"|"&TEXT(IF(v_prioridad="Potasio",H21,IF(v_prioridad="Fósforo",I21,IF(v_prioridad="Sodio",J21,IF(ISNUMBER(Q21),Q21,99999)))),"000000.00")) -> Leche y derivados|00.000.150 | U21: =IF(OR($S21<>"Utilizable",$C21<>SUSTITUCION!$C$13),999999,IF(v_prioridad="Potasio",$H21,IF(v_prioridad="Fósforo",$I21,IF(v_prioridad="Sodio",$J21,IF(ISNUMBER($Q21),$Q21,999999))))) -> 999999
A22: INTA-0014 | B22: Leche en polvo 26% MG | C22: Leche y derivados | D22: 2.1 | E22: declarado en la fuente | F22: 489 | G22: 28.6 | H22: 1307 | I22: 775 | J22: 394.6 | K22: 489 | L22: 28.6 | M22: 912.5 | N22: =IF(NOT(ISNUMBER(H22)),"Sin dato",IF(H22<=INDEX(rng_umbrales,1,2),"Bajo",IF(H22<=INDEX(rng_umbrales,1,3),"Medio",IF(H22<=INDEX(rng_umbrales,1,4),"Alto","Muy alto")))) -> Muy alto | O22: =IF(NOT(ISNUMBER(I22)),"Sin dato",IF(I22<=INDEX(rng_umbrales,2,2),"Bajo",IF(I22<=INDEX(rng_umbrales,2,3),"Medio",IF(I22<=INDEX(rng_umbrales,2,4),"Alto","Muy alto")))) -> Muy alto | P22: =IF(NOT(ISNUMBER(J22)),"Sin dato",IF(J22<=INDEX(rng_umbrales,3,2),"Bajo",IF(J22<=INDEX(rng_umbrales,3,3),"Medio",IF(J22<=INDEX(rng_umbrales,3,4),"Alto","Muy alto")))) -> Alto | Q22: =IF(OR(NOT(ISNUMBER(G22)),NOT(ISNUMBER(I22))),"N/C",IF(G22<u_protMin,"N/C: no es fuente proteica",I22/G22)) -> 27.097902 | R22: =IF(NOT(ISNUMBER(Q22)),"N/C",IF(Q22<=u_ppDes,"Deseable",IF(Q22<=u_ppAcep,"Aceptable","Alta"))) -> Alta | S22: =IF(COUNT(F22:J22)=k_cobMin,"Utilizable","No utilizable") -> Utilizable | T22: =IF(S22<>"Utilizable","",C22&"|"&TEXT(IF(v_prioridad="Potasio",H22,IF(v_prioridad="Fósforo",I22,IF(v_prioridad="Sodio",J22,IF(ISNUMBER(Q22),Q22,99999)))),"000000.00")) -> Leche y derivados|00.001.307 | U22: =IF(OR($S22<>"Utilizable",$C22<>SUSTITUCION!$C$13),999999,IF(v_prioridad="Potasio",$H22,IF(v_prioridad="Fósforo",$I22,IF(v_prioridad="Sodio",$J22,IF(ISNUMBER($Q22),$Q22,999999))))) -> 999999
A23: INTA-0015 | B23: Leche en polvo 26% MG con Vit. D | C23: Leche y derivados | D23: 2.1 | E23: declarado en la fuente | F23: 496 | G23: 26.3 | H23: 1330 | I23: 776 | J23: 371 | K23: 496 | L23: 26.3 | M23: 912 | N23: =IF(NOT(ISNUMBER(H23)),"Sin dato",IF(H23<=INDEX(rng_umbrales,1,2),"Bajo",IF(H23<=INDEX(rng_umbrales,1,3),"Medio",IF(H23<=INDEX(rng_umbrales,1,4),"Alto","Muy alto")))) -> Muy alto | O23: =IF(NOT(ISNUMBER(I23)),"Sin dato",IF(I23<=INDEX(rng_umbrales,2,2),"Bajo",IF(I23<=INDEX(rng_umbrales,2,3),"Medio",IF(I23<=INDEX(rng_umbrales,2,4),"Alto","Muy alto")))) -> Muy alto | P23: =IF(NOT(ISNUMBER(J23)),"Sin dato",IF(J23<=INDEX(rng_umbrales,3,2),"Bajo",IF(J23<=INDEX(rng_umbrales,3,3),"Medio",IF(J23<=INDEX(rng_umbrales,3,4),"Alto","Muy alto")))) -> Alto | Q23: =IF(OR(NOT(ISNUMBER(G23)),NOT(ISNUMBER(I23))),"N/C",IF(G23<u_protMin,"N/C: no es fuente proteica",I23/G23)) -> 29.505703 | R23: =IF(NOT(ISNUMBER(Q23)),"N/C",IF(Q23<=u_ppDes,"Deseable",IF(Q23<=u_ppAcep,"Aceptable","Alta"))) -> Alta | S23: =IF(COUNT(F23:J23)=k_cobMin,"Utilizable","No utilizable") -> Utilizable | T23: =IF(S23<>"Utilizable","",C23&"|"&TEXT(IF(v_prioridad="Potasio",H23,IF(v_prioridad="Fósforo",I23,IF(v_prioridad="Sodio",J23,IF(ISNUMBER(Q23),Q23,99999)))),"000000.00")) -> Leche y derivados|00.001.330 | U23: =IF(OR($S23<>"Utilizable",$C23<>SUSTITUCION!$C$13),999999,IF(v_prioridad="Potasio",$H23,IF(v_prioridad="Fósforo",$I23,IF(v_prioridad="Sodio",$J23,IF(ISNUMBER($Q23),$Q23,999999))))) -> 999999
A24: INTA-0016 | B24: Leche en polvo 18% MG extra calcio | C24: Leche y derivados | D24: 2.1 | E24: declarado en la fuente | F24: 454 | G24: 29.1 | H24: s/i | I24: 865 | J24: s/i | K24: 454 | L24: 29.1 | M24: 1610 | N24: =IF(NOT(ISNUMBER(H24)),"Sin dato",IF(H24<=INDEX(rng_umbrales,1,2),"Bajo",IF(H24<=INDEX(rng_umbrales,1,3),"Medio",IF(H24<=INDEX(rng_umbrales,1,4),"Alto","Muy alto")))) -> Sin dato | O24: =IF(NOT(ISNUMBER(I24)),"Sin dato",IF(I24<=INDEX(rng_umbrales,2,2),"Bajo",IF(I24<=INDEX(rng_umbrales,2,3),"Medio",IF(I24<=INDEX(rng_umbrales,2,4),"Alto","Muy alto")))) -> Muy alto | P24: =IF(NOT(ISNUMBER(J24)),"Sin dato",IF(J24<=INDEX(rng_umbrales,3,2),"Bajo",IF(J24<=INDEX(rng_umbrales,3,3),"Medio",IF(J24<=INDEX(rng_umbrales,3,4),"Alto","Muy alto")))) -> Sin dato | Q24: =IF(OR(NOT(ISNUMBER(G24)),NOT(ISNUMBER(I24))),"N/C",IF(G24<u_protMin,"N/C: no es fuente proteica",I24/G24)) -> 29.725086 | R24: =IF(NOT(ISNUMBER(Q24)),"N/C",IF(Q24<=u_ppDes,"Deseable",IF(Q24<=u_ppAcep,"Aceptable","Alta"))) -> Alta | S24: =IF(COUNT(F24:J24)=k_cobMin,"Utilizable","No utilizable") -> No utilizable | T24: =IF(S24<>"Utilizable","",C24&"|"&TEXT(IF(v_prioridad="Potasio",H24,IF(v_prioridad="Fósforo",I24,IF(v_prioridad="Sodio",J24,IF(ISNUMBER(Q24),Q24,99999)))),"000000.00")) | U24: =IF(OR($S24<>"Utilizable",$C24<>SUSTITUCION!$C$13),999999,IF(v_prioridad="Potasio",$H24,IF(v_prioridad="Fósforo",$I24,IF(v_prioridad="Sodio",$J24,IF(ISNUMBER($Q24),$Q24,999999))))) -> 999999
A25: INTA-0017 | B25: Leche en polvo 12% MG | C25: Leche y derivados | D25: 2.1 | E25: declarado en la fuente | F25: 406 | G25: 34.6 | H25: 1521.6 | I25: 946 | J25: 534.9 | K25: 406 | L25: 34.6 | M25: s/i | N25: =IF(NOT(ISNUMBER(H25)),"Sin dato",IF(H25<=INDEX(rng_umbrales,1,2),"Bajo",IF(H25<=INDEX(rng_umbrales,1,3),"Medio",IF(H25<=INDEX(rng_umbrales,1,4),"Alto","Muy alto")))) -> Muy alto | O25: =IF(NOT(ISNUMBER(I25)),"Sin dato",IF(I25<=INDEX(rng_umbrales,2,2),"Bajo",IF(I25<=INDEX(rng_umbrales,2,3),"Medio",IF(I25<=INDEX(rng_umbrales,2,4),"Alto","Muy alto")))) -> Muy alto | P25: =IF(NOT(ISNUMBER(J25)),"Sin dato",IF(J25<=INDEX(rng_umbrales,3,2),"Bajo",IF(J25<=INDEX(rng_umbrales,3,3),"Medio",IF(J25<=INDEX(rng_umbrales,3,4),"Alto","Muy alto")))) -> Muy alto | Q25: =IF(OR(NOT(ISNUMBER(G25)),NOT(ISNUMBER(I25))),"N/C",IF(G25<u_protMin,"N/C: no es fuente proteica",I25/G25)) -> 27.34104 | R25: =IF(NOT(ISNUMBER(Q25)),"N/C",IF(Q25<=u_ppDes,"Deseable",IF(Q25<=u_ppAcep,"Aceptable","Alta"))) -> Alta | S25: =IF(COUNT(F25:J25)=k_cobMin,"Utilizable","No utilizable") -> Utilizable | T25: =IF(S25<>"Utilizable","",C25&"|"&TEXT(IF(v_prioridad="Potasio",H25,IF(v_prioridad="Fósforo",I25,IF(v_prioridad="Sodio",J25,IF(ISNUMBER(Q25),Q25,99999)))),"000000.00")) -> Leche y derivados|00.001.522 | U25: =IF(OR($S25<>"Utilizable",$C25<>SUSTITUCION!$C$13),999999,IF(v_prioridad="Potasio",$H25,IF(v_prioridad="Fósforo",$I25,IF(v_prioridad="Sodio",$J25,IF(ISNUMBER($Q25),$Q25,999999))))) -> 999999
A26: INTA-0018 | B26: Leche en polvo descremada | C26: Leche y derivados | D26: 2.1 | E26: declarado en la fuente | F26: 358 | G26: 35.1 | H26: 1705 | I26: 985 | J26: 549 | K26: 358 | L26: 35.1 | M26: 1231 | N26: =IF(NOT(ISNUMBER(H26)),"Sin dato",IF(H26<=INDEX(rng_umbrales,1,2),"Bajo",IF(H26<=INDEX(rng_umbrales,1,3),"Medio",IF(H26<=INDEX(rng_umbrales,1,4),"Alto","Muy alto")))) -> Muy alto | O26: =IF(NOT(ISNUMBER(I26)),"Sin dato",IF(I26<=INDEX(rng_umbrales,2,2),"Bajo",IF(I26<=INDEX(rng_umbrales,2,3),"Medio",IF(I26<=INDEX(rng_umbrales,2,4),"Alto","Muy alto")))) -> Muy alto | P26: =IF(NOT(ISNUMBER(J26)),"Sin dato",IF(J26<=INDEX(rng_umbrales,3,2),"Bajo",IF(J26<=INDEX(rng_umbrales,3,3),"Medio",IF(J26<=INDEX(rng_umbrales,3,4),"Alto","Muy alto")))) -> Muy alto | Q26: =IF(OR(NOT(ISNUMBER(G26)),NOT(ISNUMBER(I26))),"N/C",IF(G26<u_protMin,"N/C: no es fuente proteica",I26/G26)) -> 28.062678 | R26: =IF(NOT(ISNUMBER(Q26)),"N/C",IF(Q26<=u_ppDes,"Deseable",IF(Q26<=u_ppAcep,"Aceptable","Alta"))) -> Alta | S26: =IF(COUNT(F26:J26)=k_cobMin,"Utilizable","No utilizable") -> Utilizable | T26: =IF(S26<>"Utilizable","",C26&"|"&TEXT(IF(v_prioridad="Potasio",H26,IF(v_prioridad="Fósforo",I26,IF(v_prioridad="Sodio",J26,IF(ISNUMBER(Q26),Q26,99999)))),"000000.00")) -> Leche y derivados|00.001.705 | U26: =IF(OR($S26<>"Utilizable",$C26<>SUSTITUCION!$C$13),999999,IF(v_prioridad="Potasio",$H26,IF(v_prioridad="Fósforo",$I26,IF(v_prioridad="Sodio",$J26,IF(ISNUMBER($Q26),$Q26,999999))))) -> 999999
A27: INTA-0019 | B27: Leche en polvo descremada extra calcio | C27: Leche y derivados | D27: 2.1 | E27: declarado en la fuente | F27: 349 | G27: 31 | H27: s/i | I27: 900 | J27: 450 | K27: 349 | L27: 31 | M27: 2000 | N27: =IF(NOT(ISNUMBER(H27)),"Sin dato",IF(H27<=INDEX(rng_umbrales,1,2),"Bajo",IF(H27<=INDEX(rng_umbrales,1,3),"Medio",IF(H27<=INDEX(rng_umbrales,1,4),"Alto","Muy alto")))) -> Sin dato | O27: =IF(NOT(ISNUMBER(I27)),"Sin dato",IF(I27<=INDEX(rng_umbrales,2,2),"Bajo",IF(I27<=INDEX(rng_umbrales,2,3),"Medio",IF(I27<=INDEX(rng_umbrales,2,4),"Alto","Muy alto")))) -> Muy alto | P27: =IF(NOT(ISNUMBER(J27)),"Sin dato",IF(J27<=INDEX(rng_umbrales,3,2),"Bajo",IF(J27<=INDEX(rng_umbrales,3,3),"Medio",IF(J27<=INDEX(rng_umbrales,3,4),"Alto","Muy alto")))) -> Muy alto | Q27: =IF(OR(NOT(ISNUMBER(G27)),NOT(ISNUMBER(I27))),"N/C",IF(G27<u_protMin,"N/C: no es fuente proteica",I27/G27)) -> 29.032258 | R27: =IF(NOT(ISNUMBER(Q27)),"N/C",IF(Q27<=u_ppDes,"Deseable",IF(Q27<=u_ppAcep,"Aceptable","Alta"))) -> Alta | S27: =IF(COUNT(F27:J27)=k_cobMin,"Utilizable","No utilizable") -> No utilizable | T27: =IF(S27<>"Utilizable","",C27&"|"&TEXT(IF(v_prioridad="Potasio",H27,IF(v_prioridad="Fósforo",I27,IF(v_prioridad="Sodio",J27,IF(ISNUMBER(Q27),Q27,99999)))),"000000.00")) | U27: =IF(OR($S27<>"Utilizable",$C27<>SUSTITUCION!$C$13),999999,IF(v_prioridad="Potasio",$H27,IF(v_prioridad="Fósforo",$I27,IF(v_prioridad="Sodio",$J27,IF(ISNUMBER($Q27),$Q27,999999))))) -> 999999
A28: INTA-0020 | B28: Leche en polvo purita cereal | C28: Leche y derivados | D28: 2.1 | E28: declarado en la fuente | F28: 454 | G28: 19.4 | H28: s/i | I28: 644 | J28: 207 | K28: 454 | L28: 19.4 | M28: 1066 | N28: =IF(NOT(ISNUMBER(H28)),"Sin dato",IF(H28<=INDEX(rng_umbrales,1,2),"Bajo",IF(H28<=INDEX(rng_umbrales,1,3),"Medio",IF(H28<=INDEX(rng_umbrales,1,4),"Alto","Muy alto")))) -> Sin dato | O28: =IF(NOT(ISNUMBER(I28)),"Sin dato",IF(I28<=INDEX(rng_umbrales,2,2),"Bajo",IF(I28<=INDEX(rng_umbrales,2,3),"Medio",IF(I28<=INDEX(rng_umbrales,2,4),"Alto","Muy alto")))) -> Muy alto | P28: =IF(NOT(ISNUMBER(J28)),"Sin dato",IF(J28<=INDEX(rng_umbrales,3,2),"Bajo",IF(J28<=INDEX(rng_umbrales,3,3),"Medio",IF(J28<=INDEX(rng_umbrales,3,4),"Alto","Muy alto")))) -> Alto | Q28: =IF(OR(NOT(ISNUMBER(G28)),NOT(ISNUMBER(I28))),"N/C",IF(G28<u_protMin,"N/C: no es fuente proteica",I28/G28)) -> 33.195876 | R28: =IF(NOT(ISNUMBER(Q28)),"N/C",IF(Q28<=u_ppDes,"Deseable",IF(Q28<=u_ppAcep,"Aceptable","Alta"))) -> Alta | S28: =IF(COUNT(F28:J28)=k_cobMin,"Utilizable","No utilizable") -> No utilizable | T28: =IF(S28<>"Utilizable","",C28&"|"&TEXT(IF(v_prioridad="Potasio",H28,IF(v_prioridad="Fósforo",I28,IF(v_prioridad="Sodio",J28,IF(ISNUMBER(Q28),Q28,99999)))),"000000.00")) | U28: =IF(OR($S28<>"Utilizable",$C28<>SUSTITUCION!$C$13),999999,IF(v_prioridad="Potasio",$H28,IF(v_prioridad="Fósforo",$I28,IF(v_prioridad="Sodio",$J28,IF(ISNUMBER($Q28),$Q28,999999))))) -> 999999
A29: INTA-0021 | B29: Leche condensada | C29: Leche y derivados | D29: 2.1 | E29: declarado en la fuente | F29: 321 | G29: 7.9 | H29: 371 | I29: 253 | J29: 127 | K29: 321 | L29: 7.9 | M29: 284 | N29: =IF(NOT(ISNUMBER(H29)),"Sin dato",IF(H29<=INDEX(rng_umbrales,1,2),"Bajo",IF(H29<=INDEX(rng_umbrales,1,3),"Medio",IF(H29<=INDEX(rng_umbrales,1,4),"Alto","Muy alto")))) -> Muy alto | O29: =IF(NOT(ISNUMBER(I29)),"Sin dato",IF(I29<=INDEX(rng_umbrales,2,2),"Bajo",IF(I29<=INDEX(rng_umbrales,2,3),"Medio",IF(I29<=INDEX(rng_umbrales,2,4),"Alto","Muy alto")))) -> Muy alto | P29: =IF(NOT(ISNUMBER(J29)),"Sin dato",IF(J29<=INDEX(rng_umbrales,3,2),"Bajo",IF(J29<=INDEX(rng_umbrales,3,3),"Medio",IF(J29<=INDEX(rng_umbrales,3,4),"Alto","Muy alto")))) -> Alto | Q29: =IF(OR(NOT(ISNUMBER(G29)),NOT(ISNUMBER(I29))),"N/C",IF(G29<u_protMin,"N/C: no es fuente proteica",I29/G29)) -> N/C: no es fuente proteica | R29: =IF(NOT(ISNUMBER(Q29)),"N/C",IF(Q29<=u_ppDes,"Deseable",IF(Q29<=u_ppAcep,"Aceptable","Alta"))) -> N/C | S29: =IF(COUNT(F29:J29)=k_cobMin,"Utilizable","No utilizable") -> Utilizable | T29: =IF(S29<>"Utilizable","",C29&"|"&TEXT(IF(v_prioridad="Potasio",H29,IF(v_prioridad="Fósforo",I29,IF(v_prioridad="Sodio",J29,IF(ISNUMBER(Q29),Q29,99999)))),"000000.00")) -> Leche y derivados|00.000.371 | U29: =IF(OR($S29<>"Utilizable",$C29<>SUSTITUCION!$C$13),999999,IF(v_prioridad="Potasio",$H29,IF(v_prioridad="Fósforo",$I29,IF(v_prioridad="Sodio",$J29,IF(ISNUMBER($Q29),$Q29,999999))))) -> 999999
A30: INTA-0022 | B30: Leche evaporada | C30: Leche y derivados | D30: 2.1 | E30: declarado en la fuente | F30: 134 | G30: 6.8 | H30: 303 | I30: 203 | J30: 106 | K30: 134 | L30: 6.8 | M30: 261 | N30: =IF(NOT(ISNUMBER(H30)),"Sin dato",IF(H30<=INDEX(rng_umbrales,1,2),"Bajo",IF(H30<=INDEX(rng_umbrales,1,3),"Medio",IF(H30<=INDEX(rng_umbrales,1,4),"Alto","Muy alto")))) -> Muy alto | O30: =IF(NOT(ISNUMBER(I30)),"Sin dato",IF(I30<=INDEX(rng_umbrales,2,2),"Bajo",IF(I30<=INDEX(rng_umbrales,2,3),"Medio",IF(I30<=INDEX(rng_umbrales,2,4),"Alto","Muy alto")))) -> Muy alto | P30: =IF(NOT(ISNUMBER(J30)),"Sin dato",IF(J30<=INDEX(rng_umbrales,3,2),"Bajo",IF(J30<=INDEX(rng_umbrales,3,3),"Medio",IF(J30<=INDEX(rng_umbrales,3,4),"Alto","Muy alto")))) -> Medio | Q30: =IF(OR(NOT(ISNUMBER(G30)),NOT(ISNUMBER(I30))),"N/C",IF(G30<u_protMin,"N/C: no es fuente proteica",I30/G30)) -> N/C: no es fuente proteica | R30: =IF(NOT(ISNUMBER(Q30)),"N/C",IF(Q30<=u_ppDes,"Deseable",IF(Q30<=u_ppAcep,"Aceptable","Alta"))) -> N/C | S30: =IF(COUNT(F30:J30)=k_cobMin,"Utilizable","No utilizable") -> Utilizable | T30: =IF(S30<>"Utilizable","",C30&"|"&TEXT(IF(v_prioridad="Potasio",H30,IF(v_prioridad="Fósforo",I30,IF(v_prioridad="Sodio",J30,IF(ISNUMBER(Q30),Q30,99999)))),"000000.00")) -> Leche y derivados|00.000.303 | U30: =IF(OR($S30<>"Utilizable",$C30<>SUSTITUCION!$C$13),999999,IF(v_prioridad="Potasio",$H30,IF(v_prioridad="Fósforo",$I30,IF(v_prioridad="Sodio",$J30,IF(ISNUMBER($Q30),$Q30,999999))))) -> 999999
A31: INTA-0023 | B31: Quesillo | C31: Leche y derivados | D31: 2.1 | E31: declarado en la fuente | F31: 103 | G31: 12.5 | H31: 84.3 | I31: 131 | J31: 405 | K31: 103 | L31: 12.5 | M31: 60 | N31: =IF(NOT(ISNUMBER(H31)),"Sin dato",IF(H31<=INDEX(rng_umbrales,1,2),"Bajo",IF(H31<=INDEX(rng_umbrales,1,3),"Medio",IF(H31<=INDEX(rng_umbrales,1,4),"Alto","Muy alto")))) -> Bajo | O31: =IF(NOT(ISNUMBER(I31)),"Sin dato",IF(I31<=INDEX(rng_umbrales,2,2),"Bajo",IF(I31<=INDEX(rng_umbrales,2,3),"Medio",IF(I31<=INDEX(rng_umbrales,2,4),"Alto","Muy alto")))) -> Alto | P31: =IF(NOT(ISNUMBER(J31)),"Sin dato",IF(J31<=INDEX(rng_umbrales,3,2),"Bajo",IF(J31<=INDEX(rng_umbrales,3,3),"Medio",IF(J31<=INDEX(rng_umbrales,3,4),"Alto","Muy alto")))) -> Muy alto | Q31: =IF(OR(NOT(ISNUMBER(G31)),NOT(ISNUMBER(I31))),"N/C",IF(G31<u_protMin,"N/C: no es fuente proteica",I31/G31)) -> 10.48 | R31: =IF(NOT(ISNUMBER(Q31)),"N/C",IF(Q31<=u_ppDes,"Deseable",IF(Q31<=u_ppAcep,"Aceptable","Alta"))) -> Deseable | S31: =IF(COUNT(F31:J31)=k_cobMin,"Utilizable","No utilizable") -> Utilizable | T31: =IF(S31<>"Utilizable","",C31&"|"&TEXT(IF(v_prioridad="Potasio",H31,IF(v_prioridad="Fósforo",I31,IF(v_prioridad="Sodio",J31,IF(ISNUMBER(Q31),Q31,99999)))),"000000.00")) -> Leche y derivados|00.000.084 | U31: =IF(OR($S31<>"Utilizable",$C31<>SUSTITUCION!$C$13),999999,IF(v_prioridad="Potasio",$H31,IF(v_prioridad="Fósforo",$I31,IF(v_prioridad="Sodio",$J31,IF(ISNUMBER($Q31),$Q31,999999))))) -> 999999
A32: INTA-0024 | B32: Quesillo 0% MG | C32: Leche y derivados | D32: 2.1 | E32: declarado en la fuente | F32: 85 | G32: 13.9 | H32: s/i | I32: s/i | J32: 260 | K32: 85 | L32: 13.9 | M32: 434 | N32: =IF(NOT(ISNUMBER(H32)),"Sin dato",IF(H32<=INDEX(rng_umbrales,1,2),"Bajo",IF(H32<=INDEX(rng_umbrales,1,3),"Medio",IF(H32<=INDEX(rng_umbrales,1,4),"Alto","Muy alto")))) -> Sin dato | O32: =IF(NOT(ISNUMBER(I32)),"Sin dato",IF(I32<=INDEX(rng_umbrales,2,2),"Bajo",IF(I32<=INDEX(rng_umbrales,2,3),"Medio",IF(I32<=INDEX(rng_umbrales,2,4),"Alto","Muy alto")))) -> Sin dato | P32: =IF(NOT(ISNUMBER(J32)),"Sin dato",IF(J32<=INDEX(rng_umbrales,3,2),"Bajo",IF(J32<=INDEX(rng_umbrales,3,3),"Medio",IF(J32<=INDEX(rng_umbrales,3,4),"Alto","Muy alto")))) -> Alto | Q32: =IF(OR(NOT(ISNUMBER(G32)),NOT(ISNUMBER(I32))),"N/C",IF(G32<u_protMin,"N/C: no es fuente proteica",I32/G32)) -> N/C | R32: =IF(NOT(ISNUMBER(Q32)),"N/C",IF(Q32<=u_ppDes,"Deseable",IF(Q32<=u_ppAcep,"Aceptable","Alta"))) -> N/C | S32: =IF(COUNT(F32:J32)=k_cobMin,"Utilizable","No utilizable") -> No utilizable | T32: =IF(S32<>"Utilizable","",C32&"|"&TEXT(IF(v_prioridad="Potasio",H32,IF(v_prioridad="Fósforo",I32,IF(v_prioridad="Sodio",J32,IF(ISNUMBER(Q32),Q32,99999)))),"000000.00")) | U32: =IF(OR($S32<>"Utilizable",$C32<>SUSTITUCION!$C$13),999999,IF(v_prioridad="Potasio",$H32,IF(v_prioridad="Fósforo",$I32,IF(v_prioridad="Sodio",$J32,IF(ISNUMBER($Q32),$Q32,999999))))) -> 999999
A33: INTA-0025 | B33: Quesillo sin sal | C33: Leche y derivados | D33: 2.1 | E33: declarado en la fuente | F33: 151 | G33: 13 | H33: s/i | I33: s/i | J33: 51 | K33: 151 | L33: 13 | M33: 420 | N33: =IF(NOT(ISNUMBER(H33)),"Sin dato",IF(H33<=INDEX(rng_umbrales,1,2),"Bajo",IF(H33<=INDEX(rng_umbrales,1,3),"Medio",IF(H33<=INDEX(rng_umbrales,1,4),"Alto","Muy alto")))) -> Sin dato | O33: =IF(NOT(ISNUMBER(I33)),"Sin dato",IF(I33<=INDEX(rng_umbrales,2,2),"Bajo",IF(I33<=INDEX(rng_umbrales,2,3),"Medio",IF(I33<=INDEX(rng_umbrales,2,4),"Alto","Muy alto")))) -> Sin dato | P33: =IF(NOT(ISNUMBER(J33)),"Sin dato",IF(J33<=INDEX(rng_umbrales,3,2),"Bajo",IF(J33<=INDEX(rng_umbrales,3,3),"Medio",IF(J33<=INDEX(rng_umbrales,3,4),"Alto","Muy alto")))) -> Medio | Q33: =IF(OR(NOT(ISNUMBER(G33)),NOT(ISNUMBER(I33))),"N/C",IF(G33<u_protMin,"N/C: no es fuente proteica",I33/G33)) -> N/C | R33: =IF(NOT(ISNUMBER(Q33)),"N/C",IF(Q33<=u_ppDes,"Deseable",IF(Q33<=u_ppAcep,"Aceptable","Alta"))) -> N/C | S33: =IF(COUNT(F33:J33)=k_cobMin,"Utilizable","No utilizable") -> No utilizable | T33: =IF(S33<>"Utilizable","",C33&"|"&TEXT(IF(v_prioridad="Potasio",H33,IF(v_prioridad="Fósforo",I33,IF(v_prioridad="Sodio",J33,IF(ISNUMBER(Q33),Q33,99999)))),"000000.00")) | U33: =IF(OR($S33<>"Utilizable",$C33<>SUSTITUCION!$C$13),999999,IF(v_prioridad="Potasio",$H33,IF(v_prioridad="Fósforo",$I33,IF(v_prioridad="Sodio",$J33,IF(ISNUMBER($Q33),$Q33,999999))))) -> 999999
A34: INTA-0026 | B34: Queso cabra | C34: Leche y derivados | D34: 2.1 | E34: declarado en la fuente | F34: 364 | G34: 21.6 | H34: 158 | I34: 375 | J34: 415 | K34: 364 | L34: 21.6 | M34: 298 | N34: =IF(NOT(ISNUMBER(H34)),"Sin dato",IF(H34<=INDEX(rng_umbrales,1,2),"Bajo",IF(H34<=INDEX(rng_umbrales,1,3),"Medio",IF(H34<=INDEX(rng_umbrales,1,4),"Alto","Muy alto")))) -> Medio | O34: =IF(NOT(ISNUMBER(I34)),"Sin dato",IF(I34<=INDEX(rng_umbrales,2,2),"Bajo",IF(I34<=INDEX(rng_umbrales,2,3),"Medio",IF(I34<=INDEX(rng_umbrales,2,4),"Alto","Muy alto")))) -> Muy alto | P34: =IF(NOT(ISNUMBER(J34)),"Sin dato",IF(J34<=INDEX(rng_umbrales,3,2),"Bajo",IF(J34<=INDEX(rng_umbrales,3,3),"Medio",IF(J34<=INDEX(rng_umbrales,3,4),"Alto","Muy alto")))) -> Muy alto | Q34: =IF(OR(NOT(ISNUMBER(G34)),NOT(ISNUMBER(I34))),"N/C",IF(G34<u_protMin,"N/C: no es fuente proteica",I34/G34)) -> 17.361111 | R34: =IF(NOT(ISNUMBER(Q34)),"N/C",IF(Q34<=u_ppDes,"Deseable",IF(Q34<=u_ppAcep,"Aceptable","Alta"))) -> Alta | S34: =IF(COUNT(F34:J34)=k_cobMin,"Utilizable","No utilizable") -> Utilizable | T34: =IF(S34<>"Utilizable","",C34&"|"&TEXT(IF(v_prioridad="Potasio",H34,IF(v_prioridad="Fósforo",I34,IF(v_prioridad="Sodio",J34,IF(ISNUMBER(Q34),Q34,99999)))),"000000.00")) -> Leche y derivados|00.000.158 | U34: =IF(OR($S34<>"Utilizable",$C34<>SUSTITUCION!$C$13),999999,IF(v_prioridad="Potasio",$H34,IF(v_prioridad="Fósforo",$I34,IF(v_prioridad="Sodio",$J34,IF(ISNUMBER($Q34),$Q34,999999))))) -> 999999
A35: INTA-0027 | B35: Queso chanco | C35: Leche y derivados | D35: 2.1 | E35: declarado en la fuente | F35: 356 | G35: 20.8 | H35: s/i | I35: s/i | J35: 536 | K35: 356 | L35: 20.8 | M35: 822 | N35: =IF(NOT(ISNUMBER(H35)),"Sin dato",IF(H35<=INDEX(rng_umbrales,1,2),"Bajo",IF(H35<=INDEX(rng_umbrales,1,3),"Medio",IF(H35<=INDEX(rng_umbrales,1,4),"Alto","Muy alto")))) -> Sin dato | O35: =IF(NOT(ISNUMBER(I35)),"Sin dato",IF(I35<=INDEX(rng_umbrales,2,2),"Bajo",IF(I35<=INDEX(rng_umbrales,2,3),"Medio",IF(I35<=INDEX(rng_umbrales,2,4),"Alto","Muy alto")))) -> Sin dato | P35: =IF(NOT(ISNUMBER(J35)),"Sin dato",IF(J35<=INDEX(rng_umbrales,3,2),"Bajo",IF(J35<=INDEX(rng_umbrales,3,3),"Medio",IF(J35<=INDEX(rng_umbrales,3,4),"Alto","Muy alto")))) -> Muy alto | Q35: =IF(OR(NOT(ISNUMBER(G35)),NOT(ISNUMBER(I35))),"N/C",IF(G35<u_protMin,"N/C: no es fuente proteica",I35/G35)) -> N/C | R35: =IF(NOT(ISNUMBER(Q35)),"N/C",IF(Q35<=u_ppDes,"Deseable",IF(Q35<=u_ppAcep,"Aceptable","Alta"))) -> N/C | S35: =IF(COUNT(F35:J35)=k_cobMin,"Utilizable","No utilizable") -> No utilizable | T35: =IF(S35<>"Utilizable","",C35&"|"&TEXT(IF(v_prioridad="Potasio",H35,IF(v_prioridad="Fósforo",I35,IF(v_prioridad="Sodio",J35,IF(ISNUMBER(Q35),Q35,99999)))),"000000.00")) | U35: =IF(OR($S35<>"Utilizable",$C35<>SUSTITUCION!$C$13),999999,IF(v_prioridad="Potasio",$H35,IF(v_prioridad="Fósforo",$I35,IF(v_prioridad="Sodio",$J35,IF(ISNUMBER($Q35),$Q35,999999))))) -> 999999
A36: INTA-0028 | B36: Queso cheddar | C36: Leche y derivados | D36: 2.1 | E36: declarado en la fuente | F36: 404 | G36: 22.9 | H36: 76 | I36: 455 | J36: 653 | K36: 404 | L36: 22.9 | M36: 710 | N36: =IF(NOT(ISNUMBER(H36)),"Sin dato",IF(H36<=INDEX(rng_umbrales,1,2),"Bajo",IF(H36<=INDEX(rng_umbrales,1,3),"Medio",IF(H36<=INDEX(rng_umbrales,1,4),"Alto","Muy alto")))) -> Bajo | O36: =IF(NOT(ISNUMBER(I36)),"Sin dato",IF(I36<=INDEX(rng_umbrales,2,2),"Bajo",IF(I36<=INDEX(rng_umbrales,2,3),"Medio",IF(I36<=INDEX(rng_umbrales,2,4),"Alto","Muy alto")))) -> Muy alto | P36: =IF(NOT(ISNUMBER(J36)),"Sin dato",IF(J36<=INDEX(rng_umbrales,3,2),"Bajo",IF(J36<=INDEX(rng_umbrales,3,3),"Medio",IF(J36<=INDEX(rng_umbrales,3,4),"Alto","Muy alto")))) -> Muy alto | Q36: =IF(OR(NOT(ISNUMBER(G36)),NOT(ISNUMBER(I36))),"N/C",IF(G36<u_protMin,"N/C: no es fuente proteica",I36/G36)) -> 19.868996 | R36: =IF(NOT(ISNUMBER(Q36)),"N/C",IF(Q36<=u_ppDes,"Deseable",IF(Q36<=u_ppAcep,"Aceptable","Alta"))) -> Alta | S36: =IF(COUNT(F36:J36)=k_cobMin,"Utilizable","No utilizable") -> Utilizable | T36: =IF(S36<>"Utilizable","",C36&"|"&TEXT(IF(v_prioridad="Potasio",H36,IF(v_prioridad="Fósforo",I36,IF(v_prioridad="Sodio",J36,IF(ISNUMBER(Q36),Q36,99999)))),"000000.00")) -> Leche y derivados|00.000.076 | U36: =IF(OR($S36<>"Utilizable",$C36<>SUSTITUCION!$C$13),999999,IF(v_prioridad="Potasio",$H36,IF(v_prioridad="Fósforo",$I36,IF(v_prioridad="Sodio",$J36,IF(ISNUMBER($Q36),$Q36,999999))))) -> 999999
A37: INTA-0029 | B37: Queso crema | C37: Leche y derivados | D37: 2.1 | E37: declarado en la fuente | F37: 350 | G37: 6.2 | H37: 132 | I37: 107 | J37: 314 | K37: 350 | L37: 6.2 | M37: 97 | N37: =IF(NOT(ISNUMBER(H37)),"Sin dato",IF(H37<=INDEX(rng_umbrales,1,2),"Bajo",IF(H37<=INDEX(rng_umbrales,1,3),"Medio",IF(H37<=INDEX(rng_umbrales,1,4),"Alto","Muy alto")))) -> Medio | O37: =IF(NOT(ISNUMBER(I37)),"Sin dato",IF(I37<=INDEX(rng_umbrales,2,2),"Bajo",IF(I37<=INDEX(rng_umbrales,2,3),"Medio",IF(I37<=INDEX(rng_umbrales,2,4),"Alto","Muy alto")))) -> Alto | P37: =IF(NOT(ISNUMBER(J37)),"Sin dato",IF(J37<=INDEX(rng_umbrales,3,2),"Bajo",IF(J37<=INDEX(rng_umbrales,3,3),"Medio",IF(J37<=INDEX(rng_umbrales,3,4),"Alto","Muy alto")))) -> Alto | Q37: =IF(OR(NOT(ISNUMBER(G37)),NOT(ISNUMBER(I37))),"N/C",IF(G37<u_protMin,"N/C: no es fuente proteica",I37/G37)) -> N/C: no es fuente proteica | R37: =IF(NOT(ISNUMBER(Q37)),"N/C",IF(Q37<=u_ppDes,"Deseable",IF(Q37<=u_ppAcep,"Aceptable","Alta"))) -> N/C | S37: =IF(COUNT(F37:J37)=k_cobMin,"Utilizable","No utilizable") -> Utilizable | T37: =IF(S37<>"Utilizable","",C37&"|"&TEXT(IF(v_prioridad="Potasio",H37,IF(v_prioridad="Fósforo",I37,IF(v_prioridad="Sodio",J37,IF(ISNUMBER(Q37),Q37,99999)))),"000000.00")) -> Leche y derivados|00.000.132 | U37: =IF(OR($S37<>"Utilizable",$C37<>SUSTITUCION!$C$13),999999,IF(v_prioridad="Potasio",$H37,IF(v_prioridad="Fósforo",$I37,IF(v_prioridad="Sodio",$J37,IF(ISNUMBER($Q37),$Q37,999999))))) -> 999999
A38: INTA-0030 | B38: Queso crema 2 | C38: Leche y derivados | D38: 2.1 | E38: declarado en la fuente | F38: 218 | G38: 12 | H38: s/i | I38: s/i | J38: 763 | K38: 218 | L38: 12 | M38: 430 | N38: =IF(NOT(ISNUMBER(H38)),"Sin dato",IF(H38<=INDEX(rng_umbrales,1,2),"Bajo",IF(H38<=INDEX(rng_umbrales,1,3),"Medio",IF(H38<=INDEX(rng_umbrales,1,4),"Alto","Muy alto")))) -> Sin dato | O38: =IF(NOT(ISNUMBER(I38)),"Sin dato",IF(I38<=INDEX(rng_umbrales,2,2),"Bajo",IF(I38<=INDEX(rng_umbrales,2,3),"Medio",IF(I38<=INDEX(rng_umbrales,2,4),"Alto","Muy alto")))) -> Sin dato | P38: =IF(NOT(ISNUMBER(J38)),"Sin dato",IF(J38<=INDEX(rng_umbrales,3,2),"Bajo",IF(J38<=INDEX(rng_umbrales,3,3),"Medio",IF(J38<=INDEX(rng_umbrales,3,4),"Alto","Muy alto")))) -> Muy alto | Q38: =IF(OR(NOT(ISNUMBER(G38)),NOT(ISNUMBER(I38))),"N/C",IF(G38<u_protMin,"N/C: no es fuente proteica",I38/G38)) -> N/C | R38: =IF(NOT(ISNUMBER(Q38)),"N/C",IF(Q38<=u_ppDes,"Deseable",IF(Q38<=u_ppAcep,"Aceptable","Alta"))) -> N/C | S38: =IF(COUNT(F38:J38)=k_cobMin,"Utilizable","No utilizable") -> No utilizable | T38: =IF(S38<>"Utilizable","",C38&"|"&TEXT(IF(v_prioridad="Potasio",H38,IF(v_prioridad="Fósforo",I38,IF(v_prioridad="Sodio",J38,IF(ISNUMBER(Q38),Q38,99999)))),"000000.00")) | U38: =IF(OR($S38<>"Utilizable",$C38<>SUSTITUCION!$C$13),999999,IF(v_prioridad="Potasio",$H38,IF(v_prioridad="Fósforo",$I38,IF(v_prioridad="Sodio",$J38,IF(ISNUMBER($Q38),$Q38,999999))))) -> 999999
A39: INTA-0031 | B39: Queso fresco | C39: Leche y derivados | D39: 2.1 | E39: declarado en la fuente | F39: 228 | G39: 16.9 | H39: s/i | I39: s/i | J39: 401 | K39: 228 | L39: 16.9 | M39: s/i | N39: =IF(NOT(ISNUMBER(H39)),"Sin dato",IF(H39<=INDEX(rng_umbrales,1,2),"Bajo",IF(H39<=INDEX(rng_umbrales,1,3),"Medio",IF(H39<=INDEX(rng_umbrales,1,4),"Alto","Muy alto")))) -> Sin dato | O39: =IF(NOT(ISNUMBER(I39)),"Sin dato",IF(I39<=INDEX(rng_umbrales,2,2),"Bajo",IF(I39<=INDEX(rng_umbrales,2,3),"Medio",IF(I39<=INDEX(rng_umbrales,2,4),"Alto","Muy alto")))) -> Sin dato | P39: =IF(NOT(ISNUMBER(J39)),"Sin dato",IF(J39<=INDEX(rng_umbrales,3,2),"Bajo",IF(J39<=INDEX(rng_umbrales,3,3),"Medio",IF(J39<=INDEX(rng_umbrales,3,4),"Alto","Muy alto")))) -> Muy alto | Q39: =IF(OR(NOT(ISNUMBER(G39)),NOT(ISNUMBER(I39))),"N/C",IF(G39<u_protMin,"N/C: no es fuente proteica",I39/G39)) -> N/C | R39: =IF(NOT(ISNUMBER(Q39)),"N/C",IF(Q39<=u_ppDes,"Deseable",IF(Q39<=u_ppAcep,"Aceptable","Alta"))) -> N/C | S39: =IF(COUNT(F39:J39)=k_cobMin,"Utilizable","No utilizable") -> No utilizable | T39: =IF(S39<>"Utilizable","",C39&"|"&TEXT(IF(v_prioridad="Potasio",H39,IF(v_prioridad="Fósforo",I39,IF(v_prioridad="Sodio",J39,IF(ISNUMBER(Q39),Q39,99999)))),"000000.00")) | U39: =IF(OR($S39<>"Utilizable",$C39<>SUSTITUCION!$C$13),999999,IF(v_prioridad="Potasio",$H39,IF(v_prioridad="Fósforo",$I39,IF(v_prioridad="Sodio",$J39,IF(ISNUMBER($Q39),$Q39,999999))))) -> 999999
A40: INTA-0032 | B40: Queso fresco 2 | C40: Leche y derivados | D40: 2.1 | E40: declarado en la fuente | F40: 177 | G40: 12.6 | H40: s/i | I40: s/i | J40: 254 | K40: 177 | L40: 12.6 | M40: 383 | N40: =IF(NOT(ISNUMBER(H40)),"Sin dato",IF(H40<=INDEX(rng_umbrales,1,2),"Bajo",IF(H40<=INDEX(rng_umbrales,1,3),"Medio",IF(H40<=INDEX(rng_umbrales,1,4),"Alto","Muy alto")))) -> Sin dato | O40: =IF(NOT(ISNUMBER(I40)),"Sin dato",IF(I40<=INDEX(rng_umbrales,2,2),"Bajo",IF(I40<=INDEX(rng_umbrales,2,3),"Medio",IF(I40<=INDEX(rng_umbrales,2,4),"Alto","Muy alto")))) -> Sin dato | P40: =IF(NOT(ISNUMBER(J40)),"Sin dato",IF(J40<=INDEX(rng_umbrales,3,2),"Bajo",IF(J40<=INDEX(rng_umbrales,3,3),"Medio",IF(J40<=INDEX(rng_umbrales,3,4),"Alto","Muy alto")))) -> Alto | Q40: =IF(OR(NOT(ISNUMBER(G40)),NOT(ISNUMBER(I40))),"N/C",IF(G40<u_protMin,"N/C: no es fuente proteica",I40/G40)) -> N/C | R40: =IF(NOT(ISNUMBER(Q40)),"N/C",IF(Q40<=u_ppDes,"Deseable",IF(Q40<=u_ppAcep,"Aceptable","Alta"))) -> N/C | S40: =IF(COUNT(F40:J40)=k_cobMin,"Utilizable","No utilizable") -> No utilizable | T40: =IF(S40<>"Utilizable","",C40&"|"&TEXT(IF(v_prioridad="Potasio",H40,IF(v_prioridad="Fósforo",I40,IF(v_prioridad="Sodio",J40,IF(ISNUMBER(Q40),Q40,99999)))),"000000.00")) | U40: =IF(OR($S40<>"Utilizable",$C40<>SUSTITUCION!$C$13),999999,IF(v_prioridad="Potasio",$H40,IF(v_prioridad="Fósforo",$I40,IF(v_prioridad="Sodio",$J40,IF(ISNUMBER($Q40),$Q40,999999))))) -> 999999
