Workbook
Name a_k: PLIEGUES!$C$17
Name a_MediaG: PLIEGUES!$C$20
Name a_Sd2: PLIEGUES!$C$18
Name a_Sum8: PLIEGUES!$C$24
Name a_TEMabs: PLIEGUES!$C$19
Name a_TEMrel: PLIEGUES!$C$21
Name a_TEMver: PLIEGUES!$C$22
Name BRO_A: CONFIG!$B$28
Name BRO_B: CONFIG!$B$29
Name c_ampl: CALCULOS!$B$36
Name c_BDdw: CALCULOS!$B$25
Name c_BDjp3: CALCULOS!$B$21
Name c_BDjp7: CALCULOS!$B$19
Name c_ClaseGrasa: CALCULOS!$B$46
Name c_DWc: CALCULOS!$B$23
Name c_DWm: CALCULOS!$B$24
Name c_estado: CALCULOS!$B$37
Name c_Gate: CALCULOS!$B$16
Name c_GrDW: CALCULOS!$B$26
Name c_GrFaulk: CALCULOS!$B$27
Name c_GrJP3: CALCULOS!$B$22
Name c_GrJP7: CALCULOS!$B$20
Name c_GrRep: CALCULOS!$B$30
Name c_IMC: CALCULOS!$B$9
Name c_IMG: CALCULOS!$B$42
Name c_IMLG: CALCULOS!$B$43
Name c_max: CALCULOS!$B$34
Name c_MG: CALCULOS!$B$40
Name c_min: CALCULOS!$B$33
Name c_MLG: CALCULOS!$B$41
Name c_n: CALCULOS!$B$31
Name c_prom: CALCULOS!$B$32
Name c_rango: CALCULOS!$B$35
Name c_Sum7: CALCULOS!$B$10
Name c_SumDW: CALCULOS!$B$12
Name c_SumFaulk: CALCULOS!$B$13
Name c_SumJP3: CALCULOS!$B$11
Name c_TallaM: CALCULOS!$B$8
Name DISP_MAX: CONFIG!$B$20
Name EDAD_MAX: CONFIG!$B$11
Name EDAD_MIN: CONFIG!$B$10
Name EST_MAX: CONFIG!$B$15
Name EST_MIN: CONFIG!$B$14
Name FAULK_A: CONFIG!$B$30
Name FAULK_B: CONFIG!$B$31
Name GRASA_MAX: CONFIG!$B$19
Name GRASA_MIN: CONFIG!$B$18
Name in_Conv: DATOS!$B$15
Name in_Ecu: DATOS!$B$14
Name in_Edad: DATOS!$B$11
Name in_Est: DATOS!$B$13
Name in_Eval: DATOS!$B$16
Name in_Fecha: DATOS!$B$8
Name in_ID: DATOS!$B$7
Name in_Obs: DATOS!$B$17
Name in_Pac: DATOS!$B$9
Name in_Peso: DATOS!$B$12
Name in_Sexo: DATOS!$B$10
Name JP3_HA: CONFIG!$B$40
Name JP3_HB1: CONFIG!$B$41

Sheet INICIO
A1: NUTRIMETRÍA · NMX-36
A2: Calculadora especializada de plicometría · versión 1.0
A4: Navegación — use las pestañas inferiores del libro
A5: =HYPERLINK("#DATOS!A1","▶ DATOS") -> ▶ DATOS | B5: =HYPERLINK("#PLIEGUES!A1","▶ PLIEGUES") -> ▶ PLIEGUES | D5: =HYPERLINK("#CALCULOS!A1","▶ CALCULOS") -> ▶ CALCULOS | F5: =HYPERLINK("#RESULTADOS!A1","▶ RESULTADOS") -> ▶ RESULTADOS | H5: =HYPERLINK("#FUENTES!A1","▶ FUENTES") -> ▶ FUENTES | J5: =HYPERLINK("#PRUEBAS!A1","▶ PRUEBAS") -> ▶ PRUEBAS | L5: =HYPERLINK("#CONFIG!A1","▶ CONFIG") -> ▶ CONFIG | N5: =HYPERLINK("#CHANGELOG!A1","▶ CHANGELOG") -> ▶ CHANGELOG
A6: Ingresar datos | B6: Evaluación de pliegues | D6: Auditar operaciones | F6: Ver resumen | H6: Trazabilidad | J6: Control de calidad | L6: Constantes | N6: Historial
A7: Código del producto | C7: NMX-36
A8: Versión | C8: 1.0
A9: Fecha | C9: 2026-07-14
A10: Formato | C10: .xlsx sin macros · Microsoft 365 y Excel 2021
A11: Responsable | C11: Equipo Nutrimetría (completar por el titular)
A12: AVISO DE ALCANCE — LÉALO ANTES DE USAR
A13: EXACTITUD MATEMÁTICA ≠ VALIDACIÓN CLÍNICA. Este archivo NO está validado clínicamente.
A14: APLICA A: personas ADULTAS (≥18 años) en condición estable.
A15: NO APLICA A: embarazo · lactancia · menores de edad · pacientes críticos.
A16: Los pliegues ESTIMAN; la referencia son DEXA o pesaje hidrostático.
A17: Las cuatro ecuaciones NO son intercambiables: elija UNA validada para su población y úsela siempre.
A18: Para seguimiento, la Σ de pliegues (mm) es más robusta que el % de grasa: mismo evaluador, mismo plicómetro.
A19: La calidad depende de la técnica: si el ETM supera 7,5 %, repita las mediciones.
A20: PROPÓSITO Y ALCANCE
A21: Propósito | C21: Proveer una herramienta automatizada que facilite la evaluación y el análisis de la composición corporal en población adulta, permitiendo calcular el porcentaje de grasa corporal a través de cuatro ecuaciones estandarizadas basadas en pliegues cutáneos.
A22: Población | C22: Personas adultas (≥18 años) en condición estable. No aplica a embarazo, lactancia, menores de edad ni pacientes críticos.
A23: Uso | C23: Los pliegues ESTIMAN; la referencia son DEXA o pesaje hidrostático.
A24: Compatibilidad | C24: .xlsx sin macros · Microsoft 365 y Excel 2021
A25: Privacidad | C25: Los datos permanecen en el archivo local. El libro no transmite información.
A26: CÓMO SE MODELA
A27: Cada sitio se mide 2 veces; el valor usado es la media y la diferencia alimenta el ETM.
A28: JP7 y JP3: densidad cuadrática por sexo → % grasa por Siri (495/D−450) o Brožek (457/D−414).
A29: Durnin–Womersley: densidad = c − m·log10(Σ4) por sexo y banda etaria → Siri/Brožek.
A30: Faulkner: % grasa = 0,153·Σ4 + 5,783 (directo, sin densidad).
A31: Composición: MG = %grasa×peso · MLG = peso − MG · IMG = MG/talla² · IMLG = MLG/talla².

Sheet DATOS
A1: NUTRIMETRÍA · NMX-36
A2: Datos de entrada · identificación y selección de ecuación
A3: =HYPERLINK("#INICIO!A1","◀ INICIO") -> ◀ INICIO | B3: PLIEGUES | C3: =HYPERLINK("#CALCULOS!A1","▶ CALCULOS") -> ▶ CALCULOS | E3: =HYPERLINK("#RESULTADOS!A1","▶ RESULTADOS") -> ▶ RESULTADOS
A4: LEYENDA · Celdas ARENA con texto AZUL = editables. Grises = calculadas. (opcional) = puede quedar vacía.
A5: ► Los pliegues se ingresan en la hoja PLIEGUES. Aquí van la identificación y la ecuación a reportar.
A6: Campo | B6: Valor | C6: Unidad | D6: Validación | E6: Ayuda
A7: Identificador de la evaluación | B7: NMX-2026-0036 | C7: — | D7: Texto libre | E7: Código interno.
A8: Fecha | B8: 46217 | C8: fecha | D8: Fecha | E8: dd/mm/aaaa.
A9: Nombre o código del paciente | B9: PAC-0071 | C9: — | D9: Texto libre | E9: Prefiera un CÓDIGO si comparte el archivo.
A10: Sexo biológico | B10: Hombre | C10: — | D10: Lista: Hombre / Mujer | E10: Las ecuaciones se derivaron por sexo.
A11: Edad | B11: 34 | C11: años | D11: ≥18 y ≤120 | E11: Solo adultos.
A12: Peso | B12: 78.5 | C12: kg | D12: Entre 25 y 350 | E12: Para masa grasa y magra.
A13: Estatura | B13: 176 | C13: cm | D13: Entre 120 y 230 | E13: Para IMG / IMLG.
A14: Ecuación a reportar | B14: 7 sitios · Jackson–Pollock | C14: — | D14: Lista (CONFIG C3) | E14: Las cuatro se calculan; esta se destaca.
A15: Conversión densidad→grasa | B15: Siri (1961) | C15: — | D15: Lista (CONFIG C4) | E15: Aplica a JP y Durnin–Womersley.
A16: Evaluador | B16: EVAL-01 | C16: — | D16: Texto libre | E16: Para trazar el error técnico de medición.
A17: Observaciones | C17: — | D17: Texto libre | E17: Calibración del plicómetro, condiciones, etc.

Sheet PLIEGUES
A1: NUTRIMETRÍA · NMX-36
A2: Panel de pliegues · doble medición y error técnico de medición (ETM)
A3: Cada sitio se mide DOS veces (M1 y M2). El valor usado es la MEDIA. La diferencia |M1−M2| alimenta el error técnico de medición (ETM) intraevaluador de abajo, según el estándar ISAK. Marque los puntos anatómicos del lado derecho antes de medir. Los sitios no exigidos por su ecuación pueden quedar vacíos.
A4: =HYPERLINK("#DATOS!A1","◀ DATOS") -> ◀ DATOS | C4: =HYPERLINK("#CALCULOS!A1","▶ CALCULOS") -> ▶ CALCULOS | F4: =HYPERLINK("#RESULTADOS!A1","▶ RESULTADOS") -> ▶ RESULTADOS
A6: Nº | B6: Sitio (lado derecho) | C6: M1 (mm) | D6: M2 (mm) | E6: Media | F6: |M1−M2| | G6: Referencia anatómica / técnica
A7: 1 | B7: Pectoral (pecho) | C7: 12 | D7: 12 | E7: =IF(AND(ISNUMBER(C7),ISNUMBER(D7)),(C7+D7)/2,IF(ISNUMBER(C7),C7,"")) -> 12 | F7: =IF(AND(ISNUMBER(C7),ISNUMBER(D7)),ABS(C7-D7),"") -> 0 | G7: Diagonal, entre axila y pezón (½ en H, ⅓ en M).
A8: 2 | B8: Axilar medio | C8: 14 | D8: 14 | E8: =IF(AND(ISNUMBER(C8),ISNUMBER(D8)),(C8+D8)/2,IF(ISNUMBER(C8),C8,"")) -> 14 | F8: =IF(AND(ISNUMBER(C8),ISNUMBER(D8)),ABS(C8-D8),"") -> 0 | G8: Línea axilar media, a la altura del apéndice xifoides.
A9: 3 | B9: Tríceps | C9: 13 | D9: 11 | E9: =IF(AND(ISNUMBER(C9),ISNUMBER(D9)),(C9+D9)/2,IF(ISNUMBER(C9),C9,"")) -> 12 | F9: =IF(AND(ISNUMBER(C9),ISNUMBER(D9)),ABS(C9-D9),"") -> 2 | G9: Vertical, cara posterior del brazo, punto medio.
A10: 4 | B10: Subescapular | C10: 16 | D10: 16 | E10: =IF(AND(ISNUMBER(C10),ISNUMBER(D10)),(C10+D10)/2,IF(ISNUMBER(C10),C10,"")) -> 16 | F10: =IF(AND(ISNUMBER(C10),ISNUMBER(D10)),ABS(C10-D10),"") -> 0 | G10: Oblicuo, 2 cm bajo el ángulo inferior de la escápula.
A11: 5 | B11: Bíceps | C11: 7 | D11: 7 | E11: =IF(AND(ISNUMBER(C11),ISNUMBER(D11)),(C11+D11)/2,IF(ISNUMBER(C11),C11,"")) -> 7 | F11: =IF(AND(ISNUMBER(C11),ISNUMBER(D11)),ABS(C11-D11),"") -> 0 | G11: Vertical, cara anterior del brazo, punto medio.
A12: 6 | B12: Suprailíaco (cresta ilíaca) | C12: 17 | D12: 15 | E12: =IF(AND(ISNUMBER(C12),ISNUMBER(D12)),(C12+D12)/2,IF(ISNUMBER(C12),C12,"")) -> 16 | F12: =IF(AND(ISNUMBER(C12),ISNUMBER(D12)),ABS(C12-D12),"") -> 2 | G12: Oblicuo, sobre la cresta ilíaca, línea axilar media.
A13: 7 | B13: Abdominal | C13: 23 | D13: 21 | E13: =IF(AND(ISNUMBER(C13),ISNUMBER(D13)),(C13+D13)/2,IF(ISNUMBER(C13),C13,"")) -> 22 | F13: =IF(AND(ISNUMBER(C13),ISNUMBER(D13)),ABS(C13-D13),"") -> 2 | G13: Vertical, 2 cm a la derecha del ombligo.
A14: 8 | B14: Muslo anterior | C14: 16 | D14: 16 | E14: =IF(AND(ISNUMBER(C14),ISNUMBER(D14)),(C14+D14)/2,IF(ISNUMBER(C14),C14,"")) -> 16 | F14: =IF(AND(ISNUMBER(C14),ISNUMBER(D14)),ABS(C14-D14),"") -> 0 | G14: Vertical, cara anterior, punto medio inguinal–rótula.
A16: ERROR TÉCNICO DE MEDICIÓN (ETM) INTRAEVALUADOR · estándar ISAK
A17: Sitios medidos por duplicado (k) | C17: =SUMPRODUCT((ISNUMBER(C7:C14))*(ISNUMBER(D7:D14))) -> 8 | E17: sitios | F17: Solo cuentan los sitios con M1 y M2.
A18: Σ de las diferencias al cuadrado | C18: =SUMPRODUCT((ISNUMBER(C7:C14))*(ISNUMBER(D7:D14))*(C7:C14-D7:D14)^2) -> 12 | E18: mm² | F18: Σ(M1−M2)² sobre los sitios duplicados.
A19: ETM absoluto | C19: =IF(a_k>0,SQRT(a_Sd2/(2*a_k)),"ND") -> 0.8660254 | E19: mm | F19: √(Σd² / 2k). Error típico de una medición.
A20: Media global de las mediciones | C20: =IF((COUNT(C7:C14)+COUNT(D7:D14))>0,(SUM(C7:C14)+SUM(D7:D14))/(COUNT(C7:C14)+COUNT(D7:D14)),"ND") -> 14.375 | E20: mm | F20: Promedio de todos los M1 y M2.
A21: ETM relativo (%) | C21: =IF(AND(ISNUMBER(a_TEMabs),ISNUMBER(a_MediaG),a_MediaG>0),a_TEMabs/a_MediaG,"ND") -> 0.060245245 | E21: — | F21: ETM absoluto / media global.
A22: Veredicto ISAK | C22: =IF(ISNUMBER(a_TEMrel),IF(a_TEMrel<=TEM_OK,"OK (≤5%)",IF(a_TEMrel<=TEM_ACC,"Aceptable (5–7,5%)","Revisar técnica (>7,5%)")),"ND") -> Aceptable (5–7,5%) | E22: — | F22: ≤5% experto · 5–7,5% aceptable · >7,5% revisar.
A24: Σ de los 8 pliegues (seguimiento) | C24: =IF(COUNT(E7:E14)>0,SUM(E7:E14),"ND") -> 115 | E24: mm | F24: Suma bruta para MONITOREAR cambios en el tiempo; independiente de toda ecuación.
A26: La suma de pliegues es la métrica de seguimiento más robusta: no depende de ninguna ecuación ni de la conversión densidad→grasa. Para comparar en el tiempo, use SIEMPRE el mismo evaluador, el mismo plicómetro y los mismos sitios.

Sheet CALCULOS
A1: NUTRIMETRÍA · NMX-36
A2: Motor · cuatro ecuaciones de pliegues, reconciliación y composición
A3: =HYPERLINK("#DATOS!A1","◀ DATOS") -> ◀ DATOS | B3: =HYPERLINK("#'PLIEGUES'!A1", "◀ PLIEGUES") -> ◀ PLIEGUES | D3: =HYPERLINK("#RESULTADOS!A1","▶ RESULTADOS") -> ▶ RESULTADOS | E3: =HYPERLINK("#FUENTES!A1","▶ FUENTES") -> ▶ FUENTES
A4: Cada celda declara su fórmula. Las guardas devuelven texto 'ND: …' en vez de errores de Excel; un sitio ausente no rompe la cadena, solo deja ND la ecuación que lo necesitaba.
A6: BLOQUE 0 · BASE Y SUMATORIAS POR ECUACIÓN
A7: Variable | B7: Valor | C7: Unidad | D7: Fórmula / cómo se obtiene
A8: Estatura en metros | B8: =IF(ISNUMBER(in_Est),in_Est/100,"ND: estatura") -> 1.76 | C8: m | D8: in_Est/100
A9: IMC | B9: =IF(AND(ISNUMBER(in_Peso),ISNUMBER(in_Est),in_Est>0),in_Peso/(in_Est/100)^2,"ND") -> 25.3422 | C9: kg/m² | D9: peso/estatura²
A10: Σ Jackson–Pollock 7 sitios | B10: =IF(AND(ISNUMBER(p_Pect),ISNUMBER(p_Axil),ISNUMBER(p_Tri),ISNUMBER(p_Sub),ISNUMBER(p_Abd),ISNUMBER(p_Supra),ISNUMBER(p_Muslo)),p_Pect+p_Axil+p_Tri+p_Sub+p_Abd+p_Supra+p_Muslo,"ND: faltan sitios") -> 108 | C10: mm | D10: pectoral+axilar+tríceps+subescapular+abdominal+suprailíaco+muslo
A11: Σ Jackson–Pollock 3 sitios | B11: =IF(in_Sexo="Hombre",IF(AND(ISNUMBER(p_Pect),ISNUMBER(p_Abd),ISNUMBER(p_Muslo)),p_Pect+p_Abd+p_Muslo,"ND: faltan sitios"),IF(AND(ISNUMBER(p_Tri),ISNUMBER(p_Supra),ISNUMBER(p_Muslo)),p_Tri+p_Supra+p_Muslo,"ND: faltan sitios")) -> 50 | C11: mm | D11: H: pectoral+abdominal+muslo · M: tríceps+suprailíaco+muslo
A12: Σ Durnin–Womersley 4 | B12: =IF(AND(ISNUMBER(p_Bic),ISNUMBER(p_Tri),ISNUMBER(p_Sub),ISNUMBER(p_Supra)),p_Bic+p_Tri+p_Sub+p_Supra,"ND: faltan sitios") -> 51 | C12: mm | D12: bíceps+tríceps+subescapular+suprailíaco
A13: Σ Faulkner 4 | B13: =IF(AND(ISNUMBER(p_Tri),ISNUMBER(p_Sub),ISNUMBER(p_Supra),ISNUMBER(p_Abd)),p_Tri+p_Sub+p_Supra+p_Abd,"ND: faltan sitios") -> 66 | C13: mm | D13: tríceps+subescapular+suprailíaco+abdominal
A14: BLOQUE 1 · COMPUERTA DE DATOS IMPOSIBLES
A15: Variable | B15: Valor | C15: Unidad | D15: Fórmula / cómo se obtiene
A16: ¿Cálculo habilitado? | B16: =IF(AND(COUNTIF(SEXOS,in_Sexo)>0,ISNUMBER(in_Edad),in_Edad>=EDAD_MIN,in_Edad<=EDAD_MAX,ISNUMBER(in_Peso),in_Peso>=PESO_MIN,in_Peso<=PESO_MAX,ISNUMBER(in_Est),in_Est>=EST_MIN,in_Est<=EST_MAX),"SÍ","NO") -> SÍ | C16: — | D16: Exige sexo, edad adulta, peso y estatura válidos
A17: BLOQUE 2 · DENSIDAD Y % DE GRASA POR CADA ECUACIÓN (fracción)
A18: Variable | B18: Valor | C18: Unidad | D18: Fórmula / cómo se obtiene
A19: Densidad · JP7 | B19: =IF(AND(c_Gate="SÍ",ISNUMBER(c_Sum7)),IF(in_Sexo="Hombre",JP7_HA-JP7_HB1*c_Sum7+JP7_HB2*c_Sum7^2-JP7_HB3*in_Edad,JP7_MA-JP7_MB1*c_Sum7+JP7_MB2*c_Sum7^2-JP7_MB3*in_Edad),"ND") -> 1.0616354 | C19: g/mL | D19: Cuadrática por sexo
A20: % grasa · JP7 | B20: =IF(ISNUMBER(c_BDjp7),IF(in_Conv="Brožek (1963)",(BRO_A/c_BDjp7-BRO_B)/100,(SIRI_A/c_BDjp7-SIRI_B)/100),"ND") -> 0.16261752 | C20: % | D20: Siri o Brožek
A21: Densidad · JP3 | B21: =IF(AND(c_Gate="SÍ",ISNUMBER(c_SumJP3)),IF(in_Sexo="Hombre",JP3_HA-JP3_HB1*c_SumJP3+JP3_HB2*c_SumJP3^2-JP3_HB3*in_Edad,JP3_MA-JP3_MB1*c_SumJP3+JP3_MB2*c_SumJP3^2-JP3_MB3*in_Edad),"ND") -> 1.0632934 | C21: g/mL | D21: Cuadrática por sexo
A22: % grasa · JP3 | B22: =IF(ISNUMBER(c_BDjp3),IF(in_Conv="Brožek (1963)",(BRO_A/c_BDjp3-BRO_B)/100,(SIRI_A/c_BDjp3-SIRI_B)/100),"ND") -> 0.15534724 | C22: % | D22: Siri o Brožek
A23: Durnin–Womersley · c | B23: =IF(AND(c_Gate="SÍ",ISNUMBER(c_SumDW)),SUMPRODUCT((CONFIG!$A$72:$A$81=in_Sexo)*(CONFIG!$B$72:$B$81<=in_Edad)*(CONFIG!$C$72:$C$81>in_Edad)*CONFIG!$D$72:$D$81),"ND") -> 1.1422 | C23: — | D23: Coef. c por sexo y banda
A24: Durnin–Womersley · m | B24: =IF(AND(c_Gate="SÍ",ISNUMBER(c_SumDW)),SUMPRODUCT((CONFIG!$A$72:$A$81=in_Sexo)*(CONFIG!$B$72:$B$81<=in_Edad)*(CONFIG!$C$72:$C$81>in_Edad)*CONFIG!$E$72:$E$81),"ND") -> 0.0544 | C24: — | D24: Coef. m por sexo y banda
A25: Densidad · DW4 | B25: =IF(AND(ISNUMBER(c_DWc),ISNUMBER(c_DWm),ISNUMBER(c_SumDW)),c_DWc-c_DWm*LOG10(c_SumDW),"ND") -> 1.0493082 | C25: g/mL | D25: c − m·log10(Σ4)
A26: % grasa · DW4 | B26: =IF(ISNUMBER(c_BDdw),IF(in_Conv="Brožek (1963)",(BRO_A/c_BDdw-BRO_B)/100,(SIRI_A/c_BDdw-SIRI_B)/100),"ND") -> 0.21739388 | C26: % | D26: Siri o Brožek
A27: % grasa · Faulkner | B27: =IF(AND(c_Gate="SÍ",ISNUMBER(c_SumFaulk)),(FAULK_A*c_SumFaulk+FAULK_B)/100,"ND") -> 0.15881 | C27: % | D27: 0,153·Σ4 + 5,783 (directo)
A28: BLOQUE 3 · RECONCILIACIÓN DE LAS ECUACIONES
A29: Variable | B29: Valor | C29: Unidad | D29: Fórmula / cómo se obtiene
A30: % grasa REPORTADO | B30: =CHOOSE(MATCH(in_Ecu,LISTA_ECU,0),c_GrJP7,c_GrJP3,c_GrDW,c_GrFaulk) -> 0.16261752 | C30: % | D30: Ecuación elegida en DATOS
A31: Ecuaciones con dato (n) | B31: =COUNT(c_GrJP7,c_GrJP3,c_GrDW,c_GrFaulk) -> 4 | C31: — | D31: Cuántas entregaron número
A32: Promedio | B32: =IF(c_n>0,AVERAGE(c_GrJP7,c_GrJP3,c_GrDW,c_GrFaulk),"ND") -> 0.17354216 | C32: % | D32: AVERAGE ignora los ND
A33: Mínimo | B33: =IF(c_n>0,MIN(c_GrJP7,c_GrJP3,c_GrDW,c_GrFaulk),"ND") -> 0.15534724 | C33: %
A34: Máximo | B34: =IF(c_n>0,MAX(c_GrJP7,c_GrJP3,c_GrDW,c_GrFaulk),"ND") -> 0.21739388 | C34: %
A35: Rango (máx − mín) | B35: =IF(AND(ISNUMBER(c_min),ISNUMBER(c_max)),c_max-c_min,"ND") -> 0.062046637 | C35: p.p. | D35: Dispersión en puntos porcentuales
A36: Amplitud relativa | B36: =IF(AND(ISNUMBER(c_rango),ISNUMBER(c_prom),c_prom>0),c_rango/c_prom,"ND") -> 0.35753062 | C36: — | D36: rango/promedio (informativo)
A37: Estado de concordancia | B37: =IF(ISNUMBER(c_rango),IF(c_rango<=DISP_MAX,"OK: las ecuaciones concuerdan dentro del umbral.","ATENCIÓN: las ecuaciones de pliegues no son intercambiables; elija UNA y sígala en el tiempo."),"ND") -> OK: las ecuaciones concuerdan dentro del umbral. | C37: — | D37: Compara el rango con DISP_MAX
A38: BLOQUE 4 · COMPOSICIÓN CORPORAL (según la ecuación reportada)
A39: Variable | B39: Valor | C39: Unidad | D39: Fórmula / cómo se obtiene
A40: Masa grasa (MG) | B40: =IF(AND(ISNUMBER(c_GrRep),ISNUMBER(in_Peso)),c_GrRep*in_Peso,"ND") -> 12.765475 | C40: kg | D40: % grasa × peso
A41: Masa libre de grasa (MLG) | B41: =IF(AND(ISNUMBER(c_MG),ISNUMBER(in_Peso)),in_Peso-c_MG,"ND") -> 65.734525 | C41: kg | D41: peso − MG
...

Sheet RESULTADOS
A1: NUTRIMETRÍA · NMX-36
A2: Informe de plicometría y composición corporal
A3: =HYPERLINK("#DATOS!A1","◀ DATOS") -> ◀ DATOS | B3: =HYPERLINK("#'PLIEGUES'!A1", "◀ PLIEGUES") -> ◀ PLIEGUES | C3: =HYPERLINK("#CALCULOS!A1","◀ CALCULOS") -> ◀ CALCULOS | E3: =HYPERLINK("#FUENTES!A1","▶ FUENTES") -> ▶ FUENTES
A5: IDENTIFICACIÓN
A6: Identificador | B6: =in_ID -> NMX-2026-0036
A7: Fecha | B7: =in_Fecha -> 46217
A8: Paciente | B8: =in_Pac -> PAC-0071
A9: Evaluador | B9: =in_Eval -> EVAL-01
A10: Sexo · edad | B10: =in_Sexo&" · "&IF(ISNUMBER(in_Edad),in_Edad&" años","(edad no válida)") -> Hombre · 34 años
A11: Peso · estatura | B11: =IF(ISNUMBER(in_Peso),ROUND(in_Peso,1)&" kg","(?)")&" · "&IF(ISNUMBER(in_Est),ROUND(in_Est,1)&" cm","(?)") -> 78,5 kg · 176 cm
A12: Ecuación reportada | B12: =in_Ecu -> 7 sitios · Jackson–Pollock
A13: Estado del cálculo | B13: =IF(c_Gate="SÍ","HABILITADO","BLOQUEADO — corrija los datos imposibles") -> HABILITADO
A15: CALIDAD DE LA MEDICIÓN (ETM intraevaluador · ISAK)
A16: Sitios medidos por duplicado (k) | B16: =a_k -> 8
A17: ETM absoluto | B17: =a_TEMabs -> 0.8660254 | C17: mm
A18: ETM relativo | B18: =a_TEMrel -> 0.060245245
A19: Veredicto ISAK | B19: =a_TEMver -> Aceptable (5–7,5%)
A20: Σ de los 8 pliegues (seguimiento) | B20: =a_Sum8 -> 115 | C20: mm
A22: % DE GRASA POR LAS CUATRO ECUACIONES
A23: Ecuación | B23: % de grasa | C23: ¿Disponible? | D23: Fuente
A24: 7 sitios · Jackson–Pollock | B24: =c_GrJP7 -> 0.16261752 | C24: =IF(ISNUMBER(c_GrJP7),"Sí","No") -> Sí | D24: Jackson & Pollock 1978/1980
A25: 3 sitios · Jackson–Pollock | B25: =c_GrJP3 -> 0.15534724 | C25: =IF(ISNUMBER(c_GrJP3),"Sí","No") -> Sí | D25: Jackson & Pollock 1978/1980
A26: 4 pliegues · Durnin–Womersley | B26: =c_GrDW -> 0.21739388 | C26: =IF(ISNUMBER(c_GrDW),"Sí","No") -> Sí | D26: Durnin & Womersley 1974
A27: 4 pliegues · Faulkner | B27: =c_GrFaulk -> 0.15881 | C27: =IF(ISNUMBER(c_GrFaulk),"Sí","No") -> Sí | D27: Faulkner 1968
A28: ECUACIÓN REPORTADA | B28: =c_GrRep -> 0.16261752 | C28: =in_Ecu -> 7 sitios · Jackson–Pollock
A30: CONCORDANCIA ENTRE ECUACIONES
A31: Promedio | B31: =c_prom -> 0.17354216
A32: Rango (máx − mín) | B32: =c_rango -> 0.062046637
A33: Amplitud relativa | B33: =c_ampl -> 0.35753062
A34: =c_estado -> OK: las ecuaciones concuerdan dentro del umbral.
A36: COMPOSICIÓN CORPORAL (según la ecuación reportada)
A37: % de grasa reportado | B37: =c_GrRep -> 0.16261752
A38: Masa grasa (MG) | B38: =c_MG -> 12.765475 | C38: kg
A39: Masa libre de grasa (MLG) | B39: =c_MLG -> 65.734525 | C39: kg
A40: Índice de masa grasa (IMG) | B40: =c_IMG -> 4.1210857 | C40: kg/m²
A41: Índice de masa libre de grasa (IMLG) | B41: =c_IMLG -> 21.221115 | C41: kg/m²
A42: Clasificación por % grasa (ACE, referencial) | B42: =c_ClaseGrasa -> En forma
A44: DATOS DE APOYO PARA LOS GRÁFICOS
A45: Ecuación | B45: % de grasa
A46: JP7 | B46: =IF(ISNUMBER(c_GrJP7),c_GrJP7,0) -> 0.16261752
...

Sheet FUENTES
A1: NUTRIMETRÍA · NMX-36
A2: Trazabilidad de ecuaciones de plicometría y verificación
A3: NIVEL A = publicación primaria / estándar oficial · B = resumen primario o corroboración por pares · C = fuente secundaria (atribución propagada por manuales). Solo se usan ECUACIONES y COEFICIENTES (hechos no protegibles). EXACTITUD BIBLIOGRÁFICA ≠ VALIDACIÓN CLÍNICA. Las ecuaciones de pliegues NO son intercambiables.
A4: =HYPERLINK("#INICIO!A1","◀ INICIO") -> ◀ INICIO | B4: =HYPERLINK("#DATOS!A1","◀ DATOS") -> ◀ DATOS | C4: =HYPERLINK("#CALCULOS!A1","◀ CALCULOS") -> ◀ CALCULOS
A5: Ecuación o dato | B5: Autor u organización | C5: Año | D5: Población de derivación | E5: Fórmula / valor | F5: Unidades | G5: Limitaciones | H5: DOI o fuente | I5: Fecha cotejo | J5: Licencia / condiciones | K5: Nivel
A6: Densidad · JP 7 sitios (hombres) | B6: Jackson AS, Pollock ML — Br J Nutr 40:497-504 | C6: 1978 | D6: 308 hombres, 18–61 años; pesaje hidrostático | E6: BD = 1,112 − 0,00043499·Σ7 + 0,00000055·Σ7² − 0,00028826·edad | F6: g/mL; mm; años | G6: Muestra mayoritariamente caucásica no atleta; error ~3,5 %grasa. | H6: Br J Nutr 1978;40:497-504 | I6: 2026-07-16 | J6: Artículo con derechos de autor; solo se usan los coeficientes. | K6: B
A7: Densidad · JP 7 y 3 sitios (mujeres) | B7: Jackson AS, Pollock ML, Ward A — Med Sci Sports Exerc 12:175-182 | C7: 1980 | D7: 249 mujeres, 18–55 años; pesaje hidrostático | E7: BD = 1,097 − 0,00046971·Σ7 + 0,00000056·Σ7² − 0,00012828·edad | F7: g/mL; mm; años | G7: Precaución en mujeres mayores de 40 años. | H7: Med Sci Sports Exerc 1980;12:175-182 | I7: 2026-07-16 | J7: Artículo con derechos de autor; solo se usan los coeficientes. | K7: B
A8: Densidad · JP 3 sitios (hombres) | B8: Jackson AS, Pollock ML — Br J Nutr 40:497-504 | C8: 1978 | D8: Sitios: pectoral, abdominal, muslo | E8: BD = 1,10938 − 0,0008267·Σ3 + 0,0000016·Σ3² − 0,0002574·edad | F8: g/mL; mm; años | G8: Versión abreviada; algo menos precisa que la de 7 sitios. | H8: Br J Nutr 1978;40:497-504 | I8: 2026-07-16 | J8: Artículo con derechos de autor; solo se usan los coeficientes. | K8: B
A9: Densidad · Durnin–Womersley 4 | B9: Durnin JVGA, Womersley J — Br J Nutr 32:77-97 | C9: 1974 | D9: 481 personas, 16–72 años; pesaje hidrostático | E9: D = c − m·log10(Σ4); Σ4 = bíceps+tríceps+subescapular+suprailíaco | F9: g/mL; mm | G9: Ecuación general británica; depende de la técnica del evaluador. | H9: 10.1079/bjn19740060 | I9: 2026-07-16 | J9: Artículo con derechos de autor; solo se usan los coeficientes. | K9: B
A10: % grasa · Faulkner (4 pliegues) | B10: Faulkner JA (derivada de Yuhasz) | C10: 1968 | D10: Uso extendido en el ámbito deportivo | E10: %grasa = 0,153·(tríceps+subescapular+suprailíaco+abdominal) + 5,783 | F10: %; mm | G10: ATRIBUCIÓN SECUNDARIA: la primaria (tesis 1968) no se inspeccionó. Verifíquela antes de un uso formal. | H10: Manuales de cineantropometría | I10: 2026-07-16 | J10: Fórmula divulgada; se cita como referencia. | K10: C
A11: Densidad → % grasa · Siri | B11: Siri WE — NAS-NRC | C11: 1961 | D11: Modelo de dos compartimentos | E11: %grasa = 495/D − 450 | F11: %; D g/mL | G11: Densidades fijas de los compartimentos; menos válida en extremos. | H11: Siri 1961 (NAS-NRC) | I11: 2026-07-16 | J11: Obra clásica; solo se usa la ecuación. | K11: B
A12: Densidad → % grasa · Brožek | B12: Brožek J et al. — Ann N Y Acad Sci 110:113-140 | C12: 1963 | D12: Cuerpo de referencia | E12: %grasa = 457/D − 414 | F12: %; D g/mL | G12: Alternativa a Siri; difiere en los extremos. | H12: 10.1111/j.1749-6632.1963.tb17079.x | I12: 2026-07-16 | J12: Artículo con derechos de autor; solo se usa la ecuación. | K12: B
A13: Error técnico de medición (ETM) | B13: ISAK — International Standards for Anthropometric Assessment | C13: 2001/vigente | D13: Estándar internacional de cineantropometría | E13: ETM = √(Σd²/2k); ETM% = ETM/media · límites 5 % / 7,5 % | F13: mm; % | G13: El ETM mide reproducibilidad, no exactitud: un ETM bajo no valida la ecuación. | H13: ISAK · normas de acreditación | I13: 2026-07-16 | J13: Estándar de la sociedad ISAK; se usa la definición (hecho no protegible). | K13: A
A14: Rangos referenciales de % de grasa | B14: American Council on Exercise (ACE) | C14: referencial | D14: Rangos divulgados por categoría y sexo | E14: H: esencial 2–5, atlético 6–13, en forma 14–17, aceptable 18–24, obesidad ≥25 % | F14: % | G14: REFERENCIALES; no son un estándar oficial ni un diagnóstico. | H14: ACE (rangos divulgados) | I14: 2026-07-16 | J14: Rangos de uso general; se citan como referencia. | K14: C
A16: PENDIENTES DE VERIFICACIÓN PRIMARIA: las ecuaciones de Jackson–Pollock, Durnin–Womersley, Siri y Brožek disponen de resumen primario o corroboración por pares, pero no se inspeccionó cada PDF completo. La fórmula de Faulkner es de atribución secundaria (nivel C): confirme la fuente primaria antes de un uso formal.

Sheet PRUEBAS
A1: NUTRIMETRÍA · NMX-36
A2: Banco de verificación · el recuento se calcula solo en el RESUMEN
A3: REGLA: el valor ESPERADO nunca lee el CONFIG que usa el motor. O es un literal calculado a partir de la fuente publicada, o se reconstruye con los coeficientes publicados escritos de forma explícita. Si alguien corrompe un coeficiente de CONFIG, estas pruebas FALLAN.
A4: =HYPERLINK("#INICIO!A1","◀ INICIO") -> ◀ INICIO
A6: BLOQUE A · EXACTITUD JACKSON–POLLOCK 7 SITIOS → densidad → % grasa (Siri)
A7: ID | B7: Descripción | C7: Sexo | D7: Σ7 | E7: Edad | F7: Obtenido | G7: Esperado | H7: Dif. | I7: Estado
A8: A01 | B8: Hombre Σ108 | C8: Hombre | D8: 108 | E8: 34 | F8: =IF(C8="Hombre",(495/(1.112-0.00043499*D8+0.00000055*D8^2-0.00028826*E8)-450)/100,(495/(1.097-0.00046971*D8+0.00000056*D8^2-0.00012828*E8)-450)/100) -> 0.16261752 | G8: 0.162618 | H8: =F8-G8 -> -4.8225775e-07 | I8: =IF(ABS(H8)<=TOL_FRAC,"APROBADO","FALLIDO") -> APROBADO
A9: A02 | B9: Mujer Σ120 | C9: Mujer | D9: 120 | E9: 30 | F9: =IF(C9="Hombre",(495/(1.112-0.00043499*D9+0.00000055*D9^2-0.00028826*E9)-450)/100,(495/(1.097-0.00046971*D9+0.00000056*D9^2-0.00012828*E9)-450)/100) -> 0.23752032 | G9: 0.23752 | H9: =F9-G9 -> 3.1869826e-07 | I9: =IF(ABS(H9)<=TOL_FRAC,"APROBADO","FALLIDO") -> APROBADO
A10: A03 | B10: Hombre Σ80 | C10: Hombre | D10: 80 | E10: 25 | F10: =IF(C10="Hombre",(495/(1.112-0.00043499*D10+0.00000055*D10^2-0.00028826*E10)-450)/100,(495/(1.097-0.00046971*D10+0.00000056*D10^2-0.00012828*E10)-450)/100) -> 0.11102381 | G10: 0.111024 | H10: =F10-G10 -> -1.8783467e-07 | I10: =IF(ABS(H10)<=TOL_FRAC,"APROBADO","FALLIDO") -> APROBADO
A11: A04 | B11: Mujer Σ150 | C11: Mujer | D11: 150 | E11: 45 | F11: =IF(C11="Hombre",(495/(1.112-0.00043499*D11+0.00000055*D11^2-0.00028826*E11)-450)/100,(495/(1.097-0.00046971*D11+0.00000056*D11^2-0.00012828*E11)-450)/100) -> 0.29014844 | G11: 0.290148 | H11: =F11-G11 -> 4.3557139e-07 | I11: =IF(ABS(H11)<=TOL_FRAC,"APROBADO","FALLIDO") -> APROBADO
A12: A05 | B12: Hombre Σ200 | C12: Hombre | D12: 200 | E12: 55 | F12: =IF(C12="Hombre",(495/(1.112-0.00043499*D12+0.00000055*D12^2-0.00028826*E12)-450)/100,(495/(1.097-0.00046971*D12+0.00000056*D12^2-0.00012828*E12)-450)/100) -> 0.30047621 | G12: 0.300476 | H12: =F12-G12 -> 2.0723976e-07 | I12: =IF(ABS(H12)<=TOL_FRAC,"APROBADO","FALLIDO") -> APROBADO
A13: A06 | B13: Mujer Σ90 | C13: Mujer | D13: 90 | E13: 22 | F13: =IF(C13="Hombre",(495/(1.112-0.00043499*D13+0.00000055*D13^2-0.00028826*E13)-450)/100,(495/(1.097-0.00046971*D13+0.00000056*D13^2-0.00012828*E13)-450)/100) -> 0.18554795 | G13: 0.185548 | H13: =F13-G13 -> -4.5423424e-08 | I13: =IF(ABS(H13)<=TOL_FRAC,"APROBADO","FALLIDO") -> APROBADO
A15: BLOQUE B · EXACTITUD JACKSON–POLLOCK 3 SITIOS → densidad → % grasa (Siri)
A16: ID | B16: Descripción | C16: Sexo | D16: Σ3 | E16: Edad | F16: Obtenido | G16: Esperado | H16: Dif. | I16: Estado
A17: B01 | B17: Hombre Σ50 | C17: Hombre | D17: 50 | E17: 34 | F17: =IF(C17="Hombre",(495/(1.10938-0.0008267*D17+0.0000016*D17^2-0.0002574*E17)-450)/100,(495/(1.0994921-0.0009929*D17+0.0000023*D17^2-0.0001392*E17)-450)/100) -> 0.15534724 | G17: 0.155347 | H17: =F17-G17 -> 2.4470217e-07 | I17: =IF(ABS(H17)<=TOL_FRAC,"APROBADO","FALLIDO") -> APROBADO
A18: B02 | B18: Mujer Σ60 | C18: Mujer | D18: 60 | E18: 30 | F18: =IF(C18="Hombre",(495/(1.10938-0.0008267*D18+0.0000016*D18^2-0.0002574*E18)-450)/100,(495/(1.0994921-0.0009929*D18+0.0000023*D18^2-0.0001392*E18)-450)/100) -> 0.24127894 | G18: 0.241279 | H18: =F18-G18 -> -5.5809068e-08 | I18: =IF(ABS(H18)<=TOL_FRAC,"APROBADO","FALLIDO") -> APROBADO
A19: B03 | B19: Hombre Σ35 | C19: Hombre | D19: 35 | E19: 25 | F19: =IF(C19="Hombre",(495/(1.10938-0.0008267*D19+0.0000016*D19^2-0.0002574*E19)-450)/100,(495/(1.0994921-0.0009929*D19+0.0000023*D19^2-0.0001392*E19)-450)/100) -> 0.10049788 | G19: 0.100498 | H19: =F19-G19 -> -1.2389652e-07 | I19: =IF(ABS(H19)<=TOL_FRAC,"APROBADO","FALLIDO") -> APROBADO
A20: B04 | B20: Mujer Σ80 | C20: Mujer | D20: 80 | E20: 45 | F20: =IF(C20="Hombre",(495/(1.10938-0.0008267*D20+0.0000016*D20^2-0.0002574*E20)-450)/100,(495/(1.0994921-0.0009929*D20+0.0000023*D20^2-0.0001392*E20)-450)/100) -> 0.31275889 | G20: 0.312759 | H20: =F20-G20 -> -1.1367824e-07 | I20: =IF(ABS(H20)<=TOL_FRAC,"APROBADO","FALLIDO") -> APROBADO
A21: B05 | B21: Hombre Σ90 | C21: Hombre | D21: 90 | E21: 55 | F21: =IF(C21="Hombre",(495/(1.10938-0.0008267*D21+0.0000016*D21^2-0.0002574*E21)-450)/100,(495/(1.0994921-0.0009929*D21+0.0000023*D21^2-0.0001392*E21)-450)/100) -> 0.28825282 | G21: 0.288253 | H21: =F21-G21 -> -1.8025112e-07 | I21: =IF(ABS(H21)<=TOL_FRAC,"APROBADO","FALLIDO") -> APROBADO
A22: B06 | B22: Mujer Σ45 | C22: Mujer | D22: 45 | E22: 22 | F22: =IF(C22="Hombre",(495/(1.10938-0.0008267*D22+0.0000016*D22^2-0.0002574*E22)-450)/100,(495/(1.0994921-0.0009929*D22+0.0000023*D22^2-0.0001392*E22)-450)/100) -> 0.18569539 | G22: 0.185695 | H22: =F22-G22 -> 3.8606675e-07 | I22: =IF(ABS(H22)<=TOL_FRAC,"APROBADO","FALLIDO") -> APROBADO
A24: BLOQUE C · DURNIN–WOMERSLEY (Siri) Y FAULKNER (directo)
A25: ID | B25: Descripción | C25: Método | D25: c/A | E25: m/B | F25: Σ4 | G25: Obtenido | H25: Esperado | I25: Dif. | J25: Estado
A26: C01 | B26: DW H 30–40 | C26: DW | D26: 1.1422 | E26: 0.0544 | F26: 51 | G26: =(495/(D26-E26*LOG10(F26))-450)/100 -> 0.21739388 | H26: 0.217394 | I26: =G26-H26 -> -1.1807808e-07 | J26: =IF(ABS(I26)<=TOL_FRAC,"APROBADO","FALLIDO") -> APROBADO
A27: C02 | B27: DW M 20–30 | C27: DW | D27: 1.1599 | E27: 0.0717 | F27: 60 | G27: =(495/(D27-E27*LOG10(F27))-450)/100 -> 0.29462279 | H27: 0.294623 | I27: =G27-H27 -> -2.088517e-07 | J27: =IF(ABS(I27)<=TOL_FRAC,"APROBADO","FALLIDO") -> APROBADO
A28: C03 | B28: DW H 40–50 | C28: DW | D28: 1.162 | E28: 0.07 | F28: 45 | G28: =(495/(D28-E28*LOG10(F28))-450)/100 -> 0.23106919 | H28: 0.231069 | I28: =G28-H28 -> 1.8656988e-07 | J28: =IF(ABS(I28)<=TOL_FRAC,"APROBADO","FALLIDO") -> APROBADO
A29: C04 | B29: Faulkner | C29: FA | D29: 0.153 | E29: 5.783 | F29: 66 | G29: =(D29*F29+E29)/100 -> 0.15881 | H29: 0.15881 | I29: =G29-H29 -> 0 | J29: =IF(ABS(I29)<=TOL_FRAC,"APROBADO","FALLIDO") -> APROBADO
A30: C05 | B30: Faulkner | C30: FA | D30: 0.153 | E30: 5.783 | F30: 40 | G30: =(D30*F30+E30)/100 -> 0.11903 | H30: 0.11903 | I30: =G30-H30 -> 0 | J30: =IF(ABS(I30)<=TOL_FRAC,"APROBADO","FALLIDO") -> APROBADO
A31: C06 | B31: Faulkner | C31: FA | D31: 0.153 | E31: 5.783 | F31: 100 | G31: =(D31*F31+E31)/100 -> 0.21083 | H31: 0.21083 | I31: =G31-H31 -> 0 | J31: =IF(ABS(I31)<=TOL_FRAC,"APROBADO","FALLIDO") -> APROBADO
A33: BLOQUE D · ERROR TÉCNICO DE MEDICIÓN (ETM) · ±0,05 mm
A34: ID | B34: Descripción | C34: Σd² | D34: k | E34: Media | F34: ETMabs obt | G34: ETMabs esp | H34: Est.abs | I34: ETMrel obt | J34: ETMrel esp | K34: Est.rel
A35: D01 | B35: Caso tipo | C35: 12 | D35: 8 | E35: 14.375 | F35: =SQRT(C35/(2*D35)) -> 0.8660254 | G35: 0.866025 | H35: =IF(ABS(F35-G35)<=TOL_MM,"APROBADO","FALLIDO") -> APROBADO | I35: =F35/E35 -> 0.060245245 | J35: 0.060245 | K35: =IF(ABS(I35-J35)<=TOL_FRAC,"APROBADO","FALLIDO") -> APROBADO
A36: D02 | B36: Sin error | C36: 0 | D36: 6 | E36: 15 | F36: =SQRT(C36/(2*D36)) -> 0 | G36: 0 | H36: =IF(ABS(F36-G36)<=TOL_MM,"APROBADO","FALLIDO") -> APROBADO | I36: =F36/E36 -> 0 | J36: 0 | K36: =IF(ABS(I36-J36)<=TOL_FRAC,"APROBADO","FALLIDO") -> APROBADO
A37: D03 | B37: Alto error | C37: 50 | D37: 8 | E37: 16 | F37: =SQRT(C37/(2*D37)) -> 1.767767 | G37: 1.767767 | H37: =IF(ABS(F37-G37)<=TOL_MM,"APROBADO","FALLIDO") -> APROBADO | I37: =F37/E37 -> 0.11048543 | J37: 0.110485 | K37: =IF(ABS(I37-J37)<=TOL_FRAC,"APROBADO","FALLIDO") -> APROBADO
A39: BLOQUE E · COMPOSICIÓN (MG, MLG, IMLG) · ±0,05
A40: ID | B40: % grasa | C40: Peso | D40: Talla m | E40: MG obt | F40: MG esp | G40: Est.MG | H40: IMLG obt | I40: IMLG esp | J40: Est.IMLG
A41: E01 | B41: 0.16262 | C41: 78.5 | D41: 1.76 | E41: =B41*C41 -> 12.76567 | F41: 12.7657 | G41: =IF(ABS(E41-F41)<=TOL_KG,"APROBADO","FALLIDO") -> APROBADO | H41: =(C41-B41*C41)/D41^2 -> 21.221052 | I41: 21.2211 | J41: =IF(ABS(H41-I41)<=TOL_KG,"APROBADO","FALLIDO") -> APROBADO
A42: E02 | B42: 0.3 | C42: 60 | D42: 1.6 | E42: =B42*C42 -> 18 | F42: 18 | G42: =IF(ABS(E42-F42)<=TOL_KG,"APROBADO","FALLIDO") -> APROBADO | H42: =(C42-B42*C42)/D42^2 -> 16.40625 | I42: 16.4062 | J42: =IF(ABS(H42-I42)<=TOL_KG,"APROBADO","FALLIDO") -> APROBADO
A43: E03 | B43: 0.12 | C43: 90 | D43: 1.85 | E43: =B43*C43 -> 10.8 | F43: 10.8 | G43: =IF(ABS(E43-F43)<=TOL_KG,"APROBADO","FALLIDO") -> APROBADO | H43: =(C43-B43*C43)/D43^2 -> 23.140979 | I43: 23.141 | J43: =IF(ABS(H43-I43)<=TOL_KG,"APROBADO","FALLIDO") -> APROBADO
A45: BLOQUE F · VALIDACIONES: vacíos, texto, negativos, imposibles
A46: ID | B46: Escenario | C46: Entrada | D46: Comportamiento esperado | E46: Comportamiento obtenido | F46: Estado
...

Sheet CONFIG
A1: NUTRIMETRÍA · NMX-36
A2: Parámetros, coeficientes y catálogos · versión 1.0
A3: =HYPERLINK("#INICIO!A1","◀ INICIO") -> ◀ INICIO
A4: Toda constante del modelo vive aquí; ninguna fórmula del libro contiene un coeficiente escrito a mano. Las celdas arena son editables. Cambiar un valor aquí propaga a todo el libro y hace FALLAR las pruebas que cotejan contra la fuente publicada.
A6: C1 · PARÁMETROS, LÍMITES Y COEFICIENTES
A7: Parámetro | B7: Valor | C7: Unidad | D7: Tipo | E7: Nota / fuente
A8: Idioma | B8: Español (es-CL) | C8: — | D8: — | E8: Interfaz
A9: Versión de las fuentes | B9: 2026-07 · v1.0 | C9: — | D9: — | E9: Ver hoja FUENTES
A10: Edad mínima (adulto) | B10: 18 | C10: años | D10: IMPOSIBLE | E10: Alcance: solo adultos
A11: Edad máxima plausible | B11: 120 | C11: años | D11: IMPOSIBLE | E11: Límite operativo
A12: Peso mínimo posible | B12: 25 | C12: kg | D12: IMPOSIBLE
A13: Peso máximo posible | B13: 350 | C13: kg | D13: IMPOSIBLE
A14: Estatura mínima posible | B14: 120 | C14: cm | D14: IMPOSIBLE
A15: Estatura máxima posible | B15: 230 | C15: cm | D15: IMPOSIBLE
A16: Pliegue mínimo por sitio | B16: 1 | C16: mm | D16: IMPOSIBLE | E16: Guarda de cada pliegue
A17: Pliegue máximo por sitio | B17: 80 | C17: mm | D17: IMPOSIBLE | E17: Guarda de cada pliegue
A18: % de grasa mínimo plausible | B18: 0.03 | C18: % | D18: IMPOSIBLE | E18: Grasa esencial
A19: % de grasa máximo plausible | B19: 0.75 | C19: % | D19: IMPOSIBLE
A20: Rango máximo aceptado entre métodos | B20: 0.08 | C20: p.p. | D20: Umbral | E20: Rango (máx−mín) del % de grasa, en puntos porcentuales
A21: ETM relativo · límite OK (ISAK) | B21: 0.05 | C21: % | D21: Umbral | E21: ≤5 % intraevaluador experimentado
A22: ETM relativo · límite aceptable | B22: 0.075 | C22: % | D22: Umbral | E22: 5–7,5 % aceptable; >7,5 % revisar técnica
A23: Tolerancia de pruebas · fracción | B23: 0.0005 | C23: — | D23: Umbral | E23: % de grasa (fracción)
A24: Tolerancia de pruebas · kg | B24: 0.05 | C24: kg | D24: Umbral | E24: Masa (kg)
A25: Tolerancia de pruebas · mm | B25: 0.05 | C25: mm | D25: Umbral | E25: Pliegues y ETM
A26: Siri (1961) · numerador | B26: 495 | C26: — | D26: Coef. | E26: %grasa = 495/D − 450
A27: Siri (1961) · término | B27: 450 | C27: — | D27: Coef.
A28: Brožek (1963) · numerador | B28: 457 | C28: — | D28: Coef. | E28: %grasa = 457/D − 414
A29: Brožek (1963) · término | B29: 414 | C29: — | D29: Coef.
A30: Faulkner (1968) · pendiente | B30: 0.153 | C30: — | D30: Coef. | E30: %grasa = 0,153·Σ4 + 5,783
A31: Faulkner (1968) · intersección | B31: 5.783 | C31: — | D31: Coef.
A32: Jackson–Pollock 7 · hombre · a | B32: 1.112 | C32: — | D32: Coef. | E32: BD = a − b1·Σ + b2·Σ² − b3·edad
A33: Jackson–Pollock 7 · hombre · b1 | B33: 0.00043499 | C33: — | D33: Coef.
A34: Jackson–Pollock 7 · hombre · b2 | B34: 5.5e-07 | C34: — | D34: Coef.
A35: Jackson–Pollock 7 · hombre · b3 | B35: 0.00028826 | C35: — | D35: Coef.
A36: Jackson–Pollock 7 · mujer · a | B36: 1.097 | C36: — | D36: Coef.
A37: Jackson–Pollock 7 · mujer · b1 | B37: 0.00046971 | C37: — | D37: Coef.
A38: Jackson–Pollock 7 · mujer · b2 | B38: 5.6e-07 | C38: — | D38: Coef.
A39: Jackson–Pollock 7 · mujer · b3 | B39: 0.00012828 | C39: — | D39: Coef.
A40: Jackson–Pollock 3 · hombre · a | B40: 1.10938 | C40: — | D40: Coef. | E40: Sitios H: pectoral, abdominal, muslo
A41: Jackson–Pollock 3 · hombre · b1 | B41: 0.0008267 | C41: — | D41: Coef.
...

Sheet CHANGELOG
A1: NUTRIMETRÍA · NMX-36
A2: Historial de versiones
A3: =HYPERLINK("#INICIO!A1","◀ INICIO") -> ◀ INICIO
A5: Versión | B5: Fecha | C5: Cambio | D5: Motivo | E5: Responsable
A6: 1.0 | B6: 2026-07-14 | C6: Versión inicial. Panel ISAK de 8 sitios con doble medición y error técnico de medición (ETM) intraevaluador; cuatro ecuaciones (Jackson–Pollock 7 y 3 sitios, Durnin–Womersley, Faulkner) con reconciliación y Σ de pliegues para seguimiento. | D6: Primera entrega del producto 36. | E6: Equipo Nutrimetría
A7: 1.0 | B7: 2026-07-14 | C7: Banco de pruebas con exactitud de las cuatro ecuaciones, ETM, composición, validaciones e integridad, con valores esperados independientes del CONFIG. | D7: Control de calidad. | E7: Equipo Nutrimetría
