Workbook
Name BIV_MAX: CONFIG!$B$20
Name BIV_MIN: CONFIG!$B$19
Name c_Clase: CALCULOS!$B$28
Name c_Gate: CALCULOS!$B$15
Name c_InTab: CALCULOS!$B$9
Name c_Key: CALCULOS!$B$8
Name c_L: CALCULOS!$B$10
Name c_M: CALCULOS!$B$11
Name c_pct: CALCULOS!$B$26
Name c_pctTxt: CALCULOS!$B$27
Name c_S: CALCULOS!$B$12
Name c_SD2n: CALCULOS!$B$21
Name c_SD2p: CALCULOS!$B$19
Name c_SD3n: CALCULOS!$B$22
Name c_SD3p: CALCULOS!$B$20
Name c_z: CALCULOS!$B$23
Name c_zraw: CALCULOS!$B$18
Name General: CONFIG!$B$9
Name in_EdadMeses: DATOS!$B$12
Name in_Eval: DATOS!$B$14
Name in_Fecha: DATOS!$B$8
Name in_ID: DATOS!$B$7
Name in_Indicador: DATOS!$B$11
Name in_Medida: DATOS!$B$13
Name in_Obs: DATOS!$B$15
Name in_Pac: DATOS!$B$9
Name in_Sexo: DATOS!$B$10
Name LISTA_IND: CONFIG!$A$31:$A$31
Name LMS_KEY: CONFIG!$G$39:$G$160
Name LMS_L: CONFIG!$D$39:$D$160
Name LMS_M: CONFIG!$E$39:$E$160
Name LMS_S: CONFIG!$F$39:$F$160
Name MED_MAX: CONFIG!$B$13
Name MED_MIN: CONFIG!$B$12
Name MES_MAX: CONFIG!$B$11
Name MES_MIN: CONFIG!$B$10
Name SEXOS: CONFIG!$A$26:$A$27
Name SINO: CONFIG!$A$34:$A$35
Name TOL_KG: CONFIG!$B$22
Name TOL_Z: CONFIG!$B$21
Name Z_DEF: CONFIG!$B$15
Name Z_LIM: CONFIG!$B$18
Name Z_SEV: CONFIG!$B$14
Name Z_SUP1: CONFIG!$B$16
Name Z_SUP2: CONFIG!$B$17

Sheet INICIO
A1: NUTRIMETRÍA · NMX-9
A2: Calculadora de percentiles OMS · versión 1.0
A3: Navegación — use las pestañas inferiores del libro
A4: =HYPERLINK("#DATOS!A1","▶ DATOS") -> ▶ DATOS | B4: =HYPERLINK("#CALCULOS!A1","▶ CALCULOS") -> ▶ CALCULOS | D4: =HYPERLINK("#RESULTADOS!A1","▶ RESULTADOS") -> ▶ RESULTADOS | F4: =HYPERLINK("#PRUEBAS!A1","▶ PRUEBAS") -> ▶ PRUEBAS | H4: =HYPERLINK("#FUENTES!A1","▶ FUENTES") -> ▶ FUENTES | J4: =HYPERLINK("#PRUEBAS!A1","▶ PRUEBAS") -> ▶ PRUEBAS | L4: =HYPERLINK("#CONFIG!A1","▶ CONFIG") -> ▶ CONFIG | N4: =HYPERLINK("#CHANGELOG!A1","▶ CHANGELOG") -> ▶ CHANGELOG
A5: Ingresar datos | B5: Auditar operaciones | D5: Ver resumen | F5: Control de calidad | H5: Consultar evidencia | J5: Ver QA | L5: Ajustes y límites | N5: Registro de versiones y cambios
A6: Código del producto | B6: NMX-9
A7: Versión | B7: 1.0
A8: Fecha | B8: 2026-07-14
A9: Método | B9: LMS · WHO Child Growth Standards
A10: Indicador incluido | B10: Peso para la edad (0–60 meses)
A11: Formato | B11: .xlsx sin macros · Microsoft 365 y Excel 2021
A12: Responsable | B12: Equipo Nutrimetría (completar por el titular)
A13: AVISO DE ALCANCE — LÉALO ANTES DE USAR
A14: • | B14: EXACTITUD MATEMÁTICA ≠ VALIDACIÓN CLÍNICA. Este archivo NO reemplaza la evaluación pediátrica.
A15: • | B15: APLICA A: niñas y niños de 0 a 60 meses (peso para la edad).
A16: • | B16: La edad se ingresa en MESES CUMPLIDOS (entero). Si no está en la tabla, el cálculo se bloquea.
A17: • | B17: Un percentil es una foto puntual; lo relevante es el SEGUIMIENTO del canal de crecimiento.
A18: • | B18: El peso para la edad no distingue exceso de grasa: para exceso, use peso/talla e IMC para la edad.
A19: • | B19: Los percentiles solo se definen para |z| ≤ 3; fuera de ese rango se informa el z-score.
A20: PROPÓSITO Y ALCANCE
A21: Propósito principal | B21: Automatizar el cálculo exacto del Z-score y percentiles de crecimiento, eliminando el error humano en la lectura visual de las gráficas de la OMS.
A22: Alcance poblacional | B22: Evaluación transversal del indicador "Peso para la edad" exclusivamente para pacientes pediátricos de 0 a 60 meses cumplidos.
A23: Restricciones de uso | B23: Es una herramienta de apoyo analítico. El diagnóstico requiere evaluar la velocidad de crecimiento en el tiempo y no solo un percentil aislado.
A24: FLUJO DE USO
A25: 1. Ingreso de datos | B25: Diríjase a la hoja DATOS e ingrese el sexo, la edad (estrictamente en meses enteros) y el peso (kg) en las celdas de color arena con texto azul.
A26: 2. Motor y validación | B26: De forma automática, en la hoja CÁLCULOS, el sistema buscará los coeficientes LMS y verificará que los datos ingresados no sean biológicamente imposibles.
A27: 3. Auditoría interna | B27: Vaya a la hoja CÁLCULOS y revise que la compuerta indique "Cálculo habilitado: SÍ", comprobando que no existan advertencias de datos extremos u omisiones.
A28: 4. Emisión de informe | B28: Finalmente, en la hoja RESULTADOS, consulte el puntaje Z ajustado, el percentil exacto (si aplica) y la clasificación nutricional oficial asignada al paciente.
A29: CÓMO SE CALCULA
A30: ▸ | B30: Se buscan L, M y S en la tabla OMS según sexo y mes cumplido.
A31: ▸ | B31: z = ((X/M)^L − 1)/(L·S) si L≠0 · z = ln(X/M)/S si L=0.
A32: ▸ | B32: Para |z|>3, la OMS fija la desviación a la distancia entre ±2 y ±3 SD.
A33: ▸ | B33: Percentil = Φ(z) (función normal estándar).
A34: ▸ | B34: Clasificación por cortes de z: muy bajo / bajo / adecuado / elevado / muy elevado.

Sheet DATOS
A1: NUTRIMETRÍA · NMX-9
A2: Datos de entrada · un niño o niña por evaluación
A3: =HYPERLINK("#INICIO!A1","◀ INICIO") -> ◀ INICIO | B3: =HYPERLINK("#CALCULOS!A1","▶ CALCULOS") -> ▶ CALCULOS | D3: =HYPERLINK("#RESULTADOS!A1","▶ RESULTADOS") -> ▶ RESULTADOS
A4: LEYENDA · Celdas ARENA con texto AZUL = editables. Grises = calculadas. La edad va en MESES CUMPLIDOS (entero, 0 a 60).
A5: ► Indicador incluido: peso para la edad (0–60 meses). Otros indicadores se pueden añadir en CONFIG.
A6: Campo | B6: Valor | C6: Unidad | D6: Validación | E6: Ayuda
A7: Identificador de la evaluación | B7: NMX-2026-0009 | C7: — | D7: Texto libre | E7: Código interno.
A8: Fecha | B8: 46217 | C8: fecha | D8: Fecha | E8: dd/mm/aaaa.
A9: Nombre o código del paciente | B9: PAC-0091 | C9: — | D9: Texto libre | E9: Prefiera un CÓDIGO si comparte el archivo.
A10: Sexo | B10: Niña | C10: — | D10: Lista: Niño / Niña | E10: Tablas OMS separadas por sexo.
A11: Indicador | B11: Peso para la edad | C11: — | D11: Lista (CONFIG C3) | E11: Por ahora, peso para la edad 0–60 meses.
A12: Edad | B12: 6 | C12: meses | D12: Entero 0 a 60 | E12: Meses CUMPLIDOS.
A13: Medida (peso) | B13: 7.6 | C13: kg | D13: Entre 0,5 y 60 | E13: Balanza calibrada, sin ropa.
A14: Evaluador | B14: EVAL-01 | C14: — | D14: Texto libre | E14: Para trazabilidad.
A15: Observaciones | C15: — | D15: Texto libre | E15: Contexto, condición del niño, etc.

Sheet CALCULOS
A1: NUTRIMETRÍA · NMX-9
A2: Motor · método LMS de la OMS con ajuste para |z| > 3
A3: =HYPERLINK("#DATOS!A1","◀ DATOS") -> ◀ DATOS | B3: =HYPERLINK("#RESULTADOS!A1","▶ RESULTADOS") -> ▶ RESULTADOS
A4: z = ((X/M)^L − 1)/(L·S) si L≠0 · z = ln(X/M)/S si L=0. Percentil = Φ(z). Para |z|>3 la OMS fija la desviación a la distancia entre ±2 y ±3 SD (los percentiles solo se definen para |z| ≤ 3).
A6: BLOQUE 0 · BÚSQUEDA DE COEFICIENTES LMS
A7: Variable | B7: Valor | C7: Unidad | D7: Fórmula / cómo se obtiene
A8: Clave de búsqueda | B8: =IF(AND(COUNTIF(SEXOS,in_Sexo)>0,ISNUMBER(in_EdadMeses)),in_Sexo&"-"&INT(in_EdadMeses),"ND") -> Niña-6 | C8: — | D8: sexo & "-" & mes
A9: ¿Edad en la tabla? | B9: =IF(c_Key="ND","NO",IF(COUNTIF(LMS_KEY,c_Key)>0,"SÍ","NO")) -> SÍ | C9: — | D9: Verifica que exista la fila oficial
A10: L (lambda) | B10: =IF(c_InTab="SÍ",INDEX(LMS_L,MATCH(c_Key,LMS_KEY,0)),"ND") -> -0.0756 | C10: — | D10: Potencia de Box-Cox
A11: M (mediana) | B11: =IF(c_InTab="SÍ",INDEX(LMS_M,MATCH(c_Key,LMS_KEY,0)),"ND") -> 7.297 | C11: kg | D11: Mediana de referencia
A12: S (coef. variación) | B12: =IF(c_InTab="SÍ",INDEX(LMS_S,MATCH(c_Key,LMS_KEY,0)),"ND") -> 0.12204 | C12: — | D12: Coeficiente de variación
A13: BLOQUE 1 · COMPUERTA
A14: Variable | B14: Valor | C14: Unidad | D14: Fórmula / cómo se obtiene
A15: ¿Cálculo habilitado? | B15: =IF(AND(c_InTab="SÍ",ISNUMBER(in_Medida),in_Medida>=MED_MIN,in_Medida<=MED_MAX,in_EdadMeses=INT(in_EdadMeses)),"SÍ","NO") -> SÍ | C15: — | D15: Exige fila en la tabla, medida válida y edad entera
A16: BLOQUE 2 · Z-SCORE Y LÍNEAS DE REFERENCIA
A17: Variable | B17: Valor | C17: Unidad | D17: Fórmula / cómo se obtiene
A18: z sin ajustar | B18: =IF(c_Gate="SÍ",IF(c_L=0,LN(in_Medida/c_M)/c_S,((in_Medida/c_M)^c_L-1)/(c_L*c_S)),"ND") -> 0.33286167 | C18: z | D18: Fórmula LMS
A19: +2 SD (peso) | B19: =IF(c_Gate="SÍ",IF(c_L=0,c_M*EXP(c_S*2),c_M*(1+c_L*c_S*2)^(1/c_L)),"ND") -> 9.3354906 | C19: kg | D19: M(1+L·S·2)^(1/L)
A20: +3 SD (peso) | B20: =IF(c_Gate="SÍ",IF(c_L=0,c_M*EXP(c_S*3),c_M*(1+c_L*c_S*3)^(1/c_L)),"ND") -> 10.577675 | C20: kg | D20: M(1+L·S·3)^(1/L)
A21: −2 SD (peso) | B21: =IF(c_Gate="SÍ",IF(c_L=0,c_M*EXP(c_S*-2),c_M*(1+c_L*c_S*-2)^(1/c_L)),"ND") -> 5.7293834 | C21: kg | D21: M(1+L·S·(−2))^(1/L)
A22: −3 SD (peso) | B22: =IF(c_Gate="SÍ",IF(c_L=0,c_M*EXP(c_S*-3),c_M*(1+c_L*c_S*-3)^(1/c_L)),"ND") -> 5.0851197 | C22: kg | D22: M(1+L·S·(−3))^(1/L)
A23: z (ajustado OMS) | B23: =IF(ISNUMBER(c_zraw),IF(c_zraw>3,3+(in_Medida-c_SD3p)/(c_SD3p-c_SD2p),IF(c_zraw<-3,-3+(in_Medida-c_SD3n)/(c_SD2n-c_SD3n),c_zraw)),"ND") -> 0.33286167 | C23: z | D23: Fuera de ±3 SD, desviación fija
A24: BLOQUE 3 · PERCENTIL Y CLASIFICACIÓN
A25: Variable | B25: Valor | C25: Unidad | D25: Fórmula / cómo se obtiene
A26: Percentil | B26: =IF(ISNUMBER(c_z),NORMSDIST(c_z),"ND") -> 0.63038065 | C26: — | D26: Φ(z) · solo válido para |z| ≤ 3
A27: Percentil (texto) | B27: =IF(ISNUMBER(c_z),IF(c_z>Z_LIM,"> 99,9 (fuera de rango)",IF(c_z<-Z_LIM,"< 0,1 (fuera de rango)",TEXT(c_pct,"0.0%"))),"ND") -> 63% | C27: — | D27: La OMS restringe el percentil a |z| ≤ 3
A28: Clasificación (peso/edad) | B28: =IF(ISNUMBER(c_z),IF(c_z<Z_SEV,"Muy bajo peso para la edad",IF(c_z<Z_DEF,"Bajo peso para la edad",IF(c_z<=Z_SUP1,"Peso adecuado para la edad",IF(c_z<=Z_SUP2,"Peso elevado — evaluar peso/talla e IMC","Peso muy elevado — evaluar peso/talla e IMC")))),"ND") -> Peso adecuado para la edad | C28: — | D28: Cortes OMS/MINSAL para peso/edad
A29: BLOQUE 4 · ADVERTENCIAS
A30: Variable | B30: Valor | C30: Unidad | D30: Fórmula / cómo se obtiene
A31: Edad no está en la tabla | B31: =IF(c_InTab="SÍ","—","La edad en meses no está en la tabla LMS incrustada (0–60). Pegue la fila oficial en CONFIG o corrija la edad.") -> —
A32: Cálculo bloqueado | B32: =IF(OR(c_Gate="SÍ",c_InTab="NO"),"—","Revise la medida o la edad: el cálculo está bloqueado.") -> —
A33: Valor biológicamente implausible | B33: =IF(ISNUMBER(c_z),IF(OR(c_z<BIV_MIN,c_z>BIV_MAX),"z fuera del rango plausible de la OMS (BIV): verifique la medición y la edad.","—"),"—") -> —
A34: Percentil fuera de rango OMS | B34: =IF(ISNUMBER(c_z),IF(ABS(c_z)>Z_LIM,"El percentil no se define para |z|>3; use el z-score y las líneas de ±SD para interpretar.","—"),"—") -> —
A35: Peso elevado: usar otro indicador | B35: =IF(ISNUMBER(c_z),IF(c_z>Z_SUP1,"El peso para la edad no distingue exceso de grasa: confirme con peso/talla e IMC para la edad.","—"),"—") -> —
A36: Recordatorio metodológico | B36: ="Exactitud matemática ≠ validación clínica. El percentil describe la posición en la referencia OMS; no reemplaza la evaluación pediátrica ni el seguimiento del canal de crecimiento." -> Exactitud matemática ≠ validación clínica. El percentil describe la posición en la referencia OMS; no reemplaza la evaluación pediátrica ni el seguimiento del canal de crecimiento.

Sheet RESULTADOS
A1: NUTRIMETRÍA · NMX-9
A2: Informe de percentil OMS · peso para la edad
A3: =HYPERLINK("#DATOS!A1","◀ DATOS") -> ◀ DATOS | B3: =HYPERLINK("#CALCULOS!A1","▶ CALCULOS") -> ▶ CALCULOS | E3: =HYPERLINK("#FUENTES!A1","▶ FUENTES") -> ▶ FUENTES
A5: IDENTIFICACIÓN
A6: Identificador | B6: =in_ID -> NMX-2026-0009
A7: Fecha | B7: =in_Fecha -> 46217
A8: Paciente | B8: =in_Pac -> PAC-0091
A9: Evaluador | B9: =in_Eval -> EVAL-01
A10: Sexo | B10: =in_Sexo -> Niña
A11: Indicador | B11: =in_Indicador -> Peso para la edad
A12: Edad · medida | B12: =IF(ISNUMBER(in_EdadMeses),in_EdadMeses&" meses","(?)")&" · "&IF(ISNUMBER(in_Medida),ROUND(in_Medida,2)&" kg","(?)") -> 6 meses · 7,6 kg
A13: Estado del cálculo | B13: =IF(c_Gate="SÍ","HABILITADO","BLOQUEADO — revise edad/medida") -> HABILITADO
A15: RESULTADO
A16: Puntuación z | B16: =c_z -> 0.33286167
A17: Percentil | B17: =c_pctTxt -> 63%
A18: Clasificación | B18: =c_Clase -> Peso adecuado para la edad
A19: Mediana de referencia (M) | B19: =c_M -> 7.297 | C19: kg
A20: L / S | B20: =IF(ISNUMBER(c_L),TEXT(c_L,"0.0000")&" / "&TEXT(c_S,"0.00000"),"ND") -> 00.000 / 000.000
A22: PESO FRENTE A LAS LÍNEAS DE REFERENCIA DE LA OMS
A23: Línea | B23: Peso (kg)
A24: −3 SD | B24: =IF(ISNUMBER(c_SD3n),c_SD3n,0) -> 5.0851197
A25: −2 SD | B25: =IF(ISNUMBER(c_SD2n),c_SD2n,0) -> 5.7293834
A26: −1 SD | B26: =IF(c_Gate="SÍ",c_M*(1+c_L*c_S*-1)^(1/c_L),0) -> 6.4622842
A27: Mediana | B27: =IF(ISNUMBER(c_M),c_M,0) -> 7.297
A28: +1 SD | B28: =IF(c_Gate="SÍ",c_M*(1+c_L*c_S*1)^(1/c_L),0) -> 8.2488168
A29: +2 SD | B29: =IF(ISNUMBER(c_SD2p),c_SD2p,0) -> 9.3354906
A30: +3 SD | B30: =IF(ISNUMBER(c_SD3p),c_SD3p,0) -> 10.577675
A31: Este niño/a | B31: =IF(ISNUMBER(in_Medida),in_Medida,0) -> 7.6
A33: ADVERTENCIAS
A34: Edad fuera de la tabla | B34: =CALCULOS!B31 -> —
A35: Cálculo bloqueado | B35: =CALCULOS!B32 -> —
A36: Valor implausible (BIV) | B36: =CALCULOS!B33 -> —
A37: Percentil fuera de rango | B37: =CALCULOS!B34 -> —
A38: Usar otro indicador | B38: =CALCULOS!B35 -> —
A39: Recordatorio | B39: =CALCULOS!B36 -> Exactitud matemática ≠ validación clínica. El percentil describe la posición en la referencia OMS; no reemplaza la evaluación pediátrica ni el seguimiento del canal de crecimiento.
A41: EXACTITUD MATEMÁTICA ≠ VALIDACIÓN CLÍNICA. Los coeficientes LMS son los oficiales de la OMS, pero este archivo NO reemplaza la evaluación pediátrica. Un percentil es una foto; lo que importa clínicamente es el SEGUIMIENTO del canal de crecimiento en el tiempo. El peso para la edad no distingue exceso de grasa de mayor masa.

Sheet FUENTES
A1: NUTRIMETRÍA · NMX-9
A2: Trazabilidad · estándares de crecimiento de la OMS y método LMS
A3: NIVEL A = documento/tabla oficial de la OMS · B = publicación primaria del método · C = fuente secundaria. Los coeficientes LMS son datos oficiales de la OMS (hechos publicados). EXACTITUD ≠ VALIDACIÓN CLÍNICA.
A4: =HYPERLINK("#INICIO!A1","◀ INICIO") -> ◀ INICIO
A5: Ecuación o dato | B5: Autor u organización | C5: Año | D5: Población / base | E5: Fórmula / valor | F5: Unidades | G5: Limitaciones | H5: DOI o fuente | I5: Fecha cotejo | J5: Licencia / condiciones | K5: Nivel
A6: Tablas LMS · peso para la edad | B6: OMS — WHO Child Growth Standards | C6: 2006 | D6: Estudio Multicéntrico (MGRS): 8440 niños de 6 países, alimentados según recomendaciones | E6: Coeficientes L, M, S por sexo y mes (0–60) | F6: kg; adimensional | G6: Estándar 0–5 años; para 5–19 usar la referencia 2007 (no incluida en esta versión). | H6: who.int · child-growth-standards (WFA) | I6: 2026-07-16 | J6: Tablas oficiales de la OMS de acceso público (uso con atribución). | K6: A
A7: Método LMS | B7: Cole TJ, Green PJ — Statistics in Medicine 11:1305-1319 | C7: 1992 | D7: Método de suavizado de curvas de centiles | E7: z = ((X/M)^L − 1)/(L·S) ; L=0: z = ln(X/M)/S | F7: adimensional | G7: Asume distribución Box-Cox normal; se restringe a |z|≤3 en los indicadores de la OMS. | H7: 10.1002/sim.4780111005 | I7: 2026-07-16 | J7: Artículo con derechos de autor; solo se usa la ecuación. | K7: B
A8: Restricción y ajuste más allá de ±3 SD | B8: OMS — Computation of centiles and z-scores | C8: 2006/2007 | D8: Documentación técnica de la OMS | E8: Fuera de ±3 SD, la desviación se fija a la distancia entre ±2 y ±3 SD | F8: kg; z | G8: Los percentiles solo se definen para |z|≤3 (0,135 a 99,865). | H8: who.int · computation.pdf | I8: 2026-07-16 | J8: Documento oficial de la OMS de acceso público. | K8: A
A9: Percentil desde z | B9: Función de distribución normal estándar Φ | C9: clásico | D9: Estadística estándar | E9: percentil = Φ(z) ; p.ej. z=1,645 → percentil 95 | F9: — | G9: Válido dentro del rango de la referencia (|z|≤3). | H9: Normal estándar | I9: 2026-07-16 | J9: Dominio público. | K9: A
A10: Cortes de clasificación (peso/edad) | B10: OMS / MINSAL (Chile) | C10: vigente | D10: Puntos de corte de z para tamizaje nutricional | E10: <−3 muy bajo · −3 a <−2 bajo · −2 a +1 adecuado · +1 a +2 elevado · >+2 muy elevado | F10: z | G10: El peso para la edad no distingue exceso de grasa; confirmar con peso/talla e IMC. | H10: OMS/MINSAL | I10: 2026-07-16 | J10: Criterios oficiales de acceso público. | K10: A
A12: EXTENSIBILIDAD: esta versión incrusta la tabla de PESO PARA LA EDAD (0–60 meses). Para añadir talla/edad, IMC/edad o peso/talla, descargue las tablas LMS oficiales de la OMS y péguelas en CONFIG (C5) respetando las columnas indicador · sexo · mes · L · M · S · clave.

Sheet PRUEBAS
A1: NUTRIMETRÍA · NMX-9
A2: Banco de verificación · el recuento se calcula solo en el RESUMEN
A3: REGLA: el valor ESPERADO no lee el CONFIG que usa el motor; se reconstruye con la fórmula LMS y con los L,M,S publicados escritos de forma explícita, o son valores publicados por la OMS (líneas de ±SD). Si alguien corrompe un coeficiente, estas pruebas FALLAN.
A4: =HYPERLINK("#INICIO!A1","◀ INICIO") -> ◀ INICIO
A6: BLOQUE A · EXACTITUD DEL Z-SCORE (fórmula LMS con L,M,S publicados) · ±0,001
A7: ID | B7: Descripción | C7: L | D7: M | E7: S | F7: Peso | G7: Obtenido | H7: Esperado | I7: Dif. | J7: Estado
A8: A01 | B8: Niña 6m · mediana | C8: -0.0756 | D8: 7.297 | E8: 0.12204 | F8: 7.297 | G8: =IF(C8=0,LN(F8/D8)/E8,((F8/D8)^C8-1)/(C8*E8)) -> 0 | H8: 0 | I8: =G8-H8 -> 0 | J8: =IF(ABS(I8)<=TOL_Z,"APROBADO","FALLIDO") -> APROBADO
A9: A02 | B9: Niña 6m · 7,6 kg | C9: -0.0756 | D9: 7.297 | E9: 0.12204 | F9: 7.6 | G9: =IF(C9=0,LN(F9/D9)/E9,((F9/D9)^C9-1)/(C9*E9)) -> 0.33286167 | H9: 0.332862 | I9: =G9-H9 -> -3.3489709e-07 | J9: =IF(ABS(I9)<=TOL_Z,"APROBADO","FALLIDO") -> APROBADO
A10: A03 | B10: Niño 0m · 3,3464 | C10: 0.3487 | D10: 3.3464 | E10: 0.14602 | F10: 3.3464 | G10: =IF(C10=0,LN(F10/D10)/E10,((F10/D10)^C10-1)/(C10*E10)) -> 0 | H10: 0 | I10: =G10-H10 -> 0 | J10: =IF(ABS(I10)<=TOL_Z,"APROBADO","FALLIDO") -> APROBADO
A11: A04 | B11: Niño 12m · 10 kg | C11: 0.0644 | D11: 9.6479 | E11: 0.10925 | F11: 10 | G11: =IF(C11=0,LN(F11/D11)/E11,((F11/D11)^C11-1)/(C11*E11)) -> 0.328478 | H11: 0.328478 | I11: =G11-H11 -> 4.207202e-09 | J11: =IF(ABS(I11)<=TOL_Z,"APROBADO","FALLIDO") -> APROBADO
A12: A05 | B12: Niña 24m · 11 kg | C12: -0.2941 | D12: 11.4775 | E12: 0.1239 | F12: 11 | G12: =IF(C12=0,LN(F12/D12)/E12,((F12/D12)^C12-1)/(C12*E12)) -> -0.3451167 | H12: -0.345117 | I12: =G12-H12 -> 2.9659105e-07 | J12: =IF(ABS(I12)<=TOL_Z,"APROBADO","FALLIDO") -> APROBADO
A13: A06 | B13: Niño 60m · 20 kg | C13: -0.1506 | D13: 18.3366 | E13: 0.13517 | F13: 20 | G13: =IF(C13=0,LN(F13/D13)/E13,((F13/D13)^C13-1)/(C13*E13)) -> 0.63821791 | H13: 0.638218 | I13: =G13-H13 -> -8.6456803e-08 | J13: =IF(ABS(I13)<=TOL_Z,"APROBADO","FALLIDO") -> APROBADO
A15: BLOQUE B · LÍNEAS ±SD RECONSTRUIDAS vs VALOR PUBLICADO POR LA OMS (±0,05 kg)
A16: ID | B16: Descripción | C16: L | D16: M | E16: S | F16: k(SD) | G16: Obtenido | H16: OMS publicado | I16: Dif. | J16: Estado
A17: B01 | B17: Niño 0m −2SD | C17: 0.3487 | D17: 3.3464 | E17: 0.14602 | F17: -2 | G17: =IF(C17=0,D17*EXP(E17*F17),D17*(1+C17*E17*F17)^(1/C17)) -> 2.4593124 | H17: 2.5 | I17: =G17-H17 -> -0.040687561 | J17: =IF(ABS(I17)<=TOL_KG,"APROBADO","FALLIDO") -> APROBADO
A18: B02 | B18: Niño 0m +2SD | C18: 0.3487 | D18: 3.3464 | E18: 0.14602 | F18: 2 | G18: =IF(C18=0,D18*EXP(E18*F18),D18*(1+C18*E18*F18)^(1/C18)) -> 4.4193538 | H18: 4.4 | I18: =G18-H18 -> 0.019353801 | J18: =IF(ABS(I18)<=TOL_KG,"APROBADO","FALLIDO") -> APROBADO
A19: B03 | B19: Niña 6m +1SD | C19: -0.0756 | D19: 7.297 | E19: 0.12204 | F19: 1 | G19: =IF(C19=0,D19*EXP(E19*F19),D19*(1+C19*E19*F19)^(1/C19)) -> 8.2488168 | H19: 8.2 | I19: =G19-H19 -> 0.048816833 | J19: =IF(ABS(I19)<=TOL_KG,"APROBADO","FALLIDO") -> APROBADO
A20: B04 | B20: Niña 6m −2SD | C20: -0.0756 | D20: 7.297 | E20: 0.12204 | F20: -2 | G20: =IF(C20=0,D20*EXP(E20*F20),D20*(1+C20*E20*F20)^(1/C20)) -> 5.7293834 | H20: 5.7 | I20: =G20-H20 -> 0.029383406 | J20: =IF(ABS(I20)<=TOL_KG,"APROBADO","FALLIDO") -> APROBADO
A21: B05 | B21: Niño 24m +3SD | C21: -0.0137 | D21: 12.1515 | E21: 0.11426 | F21: 3 | G21: =IF(C21=0,D21*EXP(E21*F21),D21*(1+C21*E21*F21)^(1/C21)) -> 17.133575 | H21: 17.1 | I21: =G21-H21 -> 0.033575361 | J21: =IF(ABS(I21)<=TOL_KG,"APROBADO","FALLIDO") -> APROBADO
A22: B06 | B22: Niña 60m −3SD | C22: -0.3518 | D22: 18.2193 | E22: 0.14821 | F22: -3 | G22: =IF(C22=0,D22*EXP(E22*F22),D22*(1+C22*E22*F22)^(1/C22)) -> 12.053778 | H22: 12.1 | I22: =G22-H22 -> -0.046221806 | J22: =IF(ABS(I22)<=TOL_KG,"APROBADO","FALLIDO") -> APROBADO
A24: BLOQUE C · PERCENTIL DESDE Z (normal estándar) · ±0,001
A25: ID | B25: z | C25: Obtenido | D25: Esperado | E25: Dif. | F25: Estado
A26: C01 | B26: 0 | C26: =NORMSDIST(B26) -> 0.5 | D26: 0.5 | E26: =C26-D26 -> 0 | F26: =IF(ABS(E26)<=TOL_Z,"APROBADO","FALLIDO") -> APROBADO
A27: C02 | B27: 1.645 | C27: =NORMSDIST(B27) -> 0.95001509 | D27: 0.950015 | E27: =C27-D27 -> 9.4460879e-08 | F27: =IF(ABS(E27)<=TOL_Z,"APROBADO","FALLIDO") -> APROBADO
A28: C03 | B28: -1.881 | C28: =NORMSDIST(B28) -> 0.029985959 | D28: 0.029986 | E28: =C28-D28 -> -4.057873e-08 | F28: =IF(ABS(E28)<=TOL_Z,"APROBADO","FALLIDO") -> APROBADO
A29: C04 | B29: 1.036 | C29: =NORMSDIST(B29) -> 0.84989893 | D29: 0.849899 | E29: =C29-D29 -> -7.1258277e-08 | F29: =IF(ABS(E29)<=TOL_Z,"APROBADO","FALLIDO") -> APROBADO
A30: C05 | B30: -2 | C30: =NORMSDIST(B30) -> 0.022750132 | D30: 0.02275 | E30: =C30-D30 -> 1.3194818e-07 | F30: =IF(ABS(E30)<=TOL_Z,"APROBADO","FALLIDO") -> APROBADO
A31: C06 | B31: 0.33286 | C31: =NORMSDIST(B31) -> 0.63038002 | D31: 0.63038 | E31: =C31-D31 -> 1.7671289e-08 | F31: =IF(ABS(E31)<=TOL_Z,"APROBADO","FALLIDO") -> APROBADO
A33: BLOQUE D · CLASIFICACIÓN POR CORTES DE Z
A34: ID | B34: z | C34: Esperado | D34: Obtenido | E34: Estado
A35: D01 | B35: -3.5 | C35: Muy bajo peso para la edad | D35: =IF(B35<-3,"Muy bajo peso para la edad",IF(B35<-2,"Bajo peso para la edad",IF(B35<=1,"Peso adecuado para la edad",IF(B35<=2,"Peso elevado — evaluar peso/talla e IMC","Peso muy elevado — evaluar peso/talla e IMC")))) -> Muy bajo peso para la edad | E35: =IF(D35=C35,"APROBADO","FALLIDO") -> APROBADO
A36: D02 | B36: -2.5 | C36: Bajo peso para la edad | D36: =IF(B36<-3,"Muy bajo peso para la edad",IF(B36<-2,"Bajo peso para la edad",IF(B36<=1,"Peso adecuado para la edad",IF(B36<=2,"Peso elevado — evaluar peso/talla e IMC","Peso muy elevado — evaluar peso/talla e IMC")))) -> Bajo peso para la edad | E36: =IF(D36=C36,"APROBADO","FALLIDO") -> APROBADO
A37: D03 | B37: 0.33 | C37: Peso adecuado para la edad | D37: =IF(B37<-3,"Muy bajo peso para la edad",IF(B37<-2,"Bajo peso para la edad",IF(B37<=1,"Peso adecuado para la edad",IF(B37<=2,"Peso elevado — evaluar peso/talla e IMC","Peso muy elevado — evaluar peso/talla e IMC")))) -> Peso adecuado para la edad | E37: =IF(D37=C37,"APROBADO","FALLIDO") -> APROBADO
A38: D04 | B38: 1.5 | C38: Peso elevado — evaluar peso/talla e IMC | D38: =IF(B38<-3,"Muy bajo peso para la edad",IF(B38<-2,"Bajo peso para la edad",IF(B38<=1,"Peso adecuado para la edad",IF(B38<=2,"Peso elevado — evaluar peso/talla e IMC","Peso muy elevado — evaluar peso/talla e IMC")))) -> Peso elevado — evaluar peso/talla e IMC | E38: =IF(D38=C38,"APROBADO","FALLIDO") -> APROBADO
A39: D05 | B39: 2.5 | C39: Peso muy elevado — evaluar peso/talla e IMC | D39: =IF(B39<-3,"Muy bajo peso para la edad",IF(B39<-2,"Bajo peso para la edad",IF(B39<=1,"Peso adecuado para la edad",IF(B39<=2,"Peso elevado — evaluar peso/talla e IMC","Peso muy elevado — evaluar peso/talla e IMC")))) -> Peso muy elevado — evaluar peso/talla e IMC | E39: =IF(D39=C39,"APROBADO","FALLIDO") -> APROBADO
A40: D06 | B40: 1 | C40: Peso adecuado para la edad | D40: =IF(B40<-3,"Muy bajo peso para la edad",IF(B40<-2,"Bajo peso para la edad",IF(B40<=1,"Peso adecuado para la edad",IF(B40<=2,"Peso elevado — evaluar peso/talla e IMC","Peso muy elevado — evaluar peso/talla e IMC")))) -> Peso adecuado para la edad | E40: =IF(D40=C40,"APROBADO","FALLIDO") -> APROBADO
A42: BLOQUE E · AJUSTE OMS PARA |z|>3 · ±0,001
A43: ID | B43: Descripción | C43: L | D43: M | E43: S | F43: Peso | G43: z obt | H43: z esp | I43: Dif. | J43: Estado
A44: E01 | B44: Niño 0m 6 kg (>+3SD) | C44: 0.3487 | D44: 3.3464 | E44: 0.14602 | F44: 6 | G44: =IF(((F44/D44)^C44-1)/(C44*E44)>3,3+(F44-D44*(1+C44*E44*3)^(1/C44))/(D44*(1+C44*E44*3)^(1/C44)-D44*(1+C44*E44*2)^(1/C44)),IF(((F44/D44)^C44-1)/(C44*E44)<-3,-3+(F44-D44*(1+C44*E44*-3)^(1/C44))/(D44*(1+C44*E44*-2)^(1/C44)-D44*(1+C44*E44*-3)^(1/C44)),((F44/D44)^C44-1)/(C44*E44))) -> 4.5857743 | H44: 4.585774 | I44: =G44-H44 -> 2.8520711e-07 | J44: =IF(ABS(I44)<=TOL_Z,"APROBADO","FALLIDO") -> APROBADO
A45: E02 | B45: Niña 6m 4,5 kg (<−3SD) | C45: -0.0756 | D45: 7.297 | E45: 0.12204 | F45: 4.5 | G45: =IF(((F45/D45)^C45-1)/(C45*E45)>3,3+(F45-D45*(1+C45*E45*3)^(1/C45))/(D45*(1+C45*E45*3)^(1/C45)-D45*(1+C45*E45*2)^(1/C45)),IF(((F45/D45)^C45-1)/(C45*E45)<-3,-3+(F45-D45*(1+C45*E45*-3)^(1/C45))/(D45*(1+C45*E45*-2)^(1/C45)-D45*(1+C45*E45*-3)^(1/C45)),((F45/D45)^C45-1)/(C45*E45))) -> -3.908199 | H45: -3.908199 | I45: =G45-H45 -> -1.8067896e-08 | J45: =IF(ABS(I45)<=TOL_Z,"APROBADO","FALLIDO") -> APROBADO
...

Sheet CONFIG
A1: NUTRIMETRÍA · NMX-9
A2: Parámetros, cortes y tablas LMS oficiales de la OMS · versión 1.0
A3: =HYPERLINK("#INICIO!A1","◀ INICIO") -> ◀ INICIO
A4: Los coeficientes LMS provienen de las tablas oficiales de la OMS (peso para la edad, 0–60 meses). Están fijos y NO deben editarse: son datos publicados. Los cortes de clasificación sí son parámetros. Para añadir otros indicadores (talla/edad, IMC/edad), pegue las filas oficiales bajo la tabla, respetando las columnas.
A6: C1 · PARÁMETROS, LÍMITES Y CORTES DE CLASIFICACIÓN
A7: Parámetro | B7: Valor | C7: Unidad | D7: Tipo | E7: Nota / fuente
A8: Idioma | B8: Español (es-CL) | C8: — | D8: — | E8: Interfaz
A9: Versión de las fuentes | B9: 2026-07 · v1.0 | C9: — | D9: — | E9: OMS · Child Growth Standards
A10: Edad mínima (meses) | B10: 0 | C10: meses | D10: IMPOSIBLE | E10: Alcance de la tabla incrustada
A11: Edad máxima (meses) | B11: 60 | C11: meses | D11: IMPOSIBLE | E11: Peso/edad 0–60 meses (OMS 2006)
A12: Medida mínima plausible | B12: 0.5 | C12: kg | D12: IMPOSIBLE | E12: Guarda del peso
A13: Medida máxima plausible | B13: 60 | C13: kg | D13: IMPOSIBLE | E13: Guarda del peso
A14: Corte z · déficit severo | B14: -3 | C14: z | D14: Corte | E14: z < −3 → muy bajo peso
A15: Corte z · déficit | B15: -2 | C15: z | D15: Corte | E15: −3 ≤ z < −2 → bajo peso
A16: Corte z · superior 1 | B16: 1 | C16: z | D16: Corte | E16: +1 < z ≤ +2 → elevado
A17: Corte z · superior 2 | B17: 2 | C17: z | D17: Corte | E17: z > +2 → muy elevado
A18: Límite de percentil OMS | B18: 3 | C18: z | D18: Regla | E18: Los percentiles solo se definen para |z| ≤ 3
A19: BIV · z mínimo (peso/edad) | B19: -6 | C19: z | D19: Bandera | E19: Valor biológicamente implausible si z < −6
A20: BIV · z máximo (peso/edad) | B20: 5 | C20: z | D20: Bandera | E20: Valor biológicamente implausible si z > 5
A21: Tolerancia de pruebas · z | B21: 0.001 | C21: z | D21: Umbral | E21: Diferencia máxima de z en el banco de pruebas
A22: Tolerancia de pruebas · kg | B22: 0.05 | C22: kg | D22: Umbral | E22: Para las líneas de ±SD
A24: C2 · SEXOS
A25: Valor | B25: Nota
A26: Niño | B26: Tablas de la OMS para varones
A27: Niña | B27: Tablas de la OMS para mujeres
A29: C3 · INDICADORES DISPONIBLES
A30: Indicador | B30: Rango
A31: Peso para la edad | B31: 0–60 meses (OMS 2006)
A33: C4 · LISTA SÍ / NO
A34: Sí
A35: No
A37: C5 · TABLA LMS OFICIAL DE LA OMS · PESO PARA LA EDAD (0–60 meses) · NO EDITAR
A38: Indicador | B38: Sexo | C38: Mes | D38: L | E38: M | F38: S | G38: Clave
A39: Peso para la edad | B39: Niño | C39: 0 | D39: 0.3487 | E39: 3.3464 | F39: 0.14602 | G39: Niño-0
A40: Peso para la edad | B40: Niño | C40: 1 | D40: 0.2297 | E40: 4.4709 | F40: 0.13395 | G40: Niño-1
A41: Peso para la edad | B41: Niño | C41: 2 | D41: 0.197 | E41: 5.5675 | F41: 0.12385 | G41: Niño-2
A42: Peso para la edad | B42: Niño | C42: 3 | D42: 0.1738 | E42: 6.3762 | F42: 0.11727 | G42: Niño-3
A43: Peso para la edad | B43: Niño | C43: 4 | D43: 0.1553 | E43: 7.0023 | F43: 0.11316 | G43: Niño-4
A44: Peso para la edad | B44: Niño | C44: 5 | D44: 0.1395 | E44: 7.5105 | F44: 0.1108 | G44: Niño-5
A45: Peso para la edad | B45: Niño | C45: 6 | D45: 0.1257 | E45: 7.934 | F45: 0.10958 | G45: Niño-6
...

Sheet CHANGELOG
A1: NUTRIMETRÍA · NMX-9
A2: Historial de versiones
A3: =HYPERLINK("#INICIO!A1","◀ INICIO") -> ◀ INICIO
A5: Versión | B5: Fecha | C5: Cambio | D5: Motivo | E5: Responsable
A6: 1.0 | B6: 2026-07-14 | C6: Versión inicial. Motor LMS de la OMS con tablas oficiales de peso para la edad (0–60 meses, ambos sexos), ajuste para |z|>3, percentil, clasificación por cortes y gráfico frente a las líneas de ±SD. | D6: Primera entrega del producto 9. | E6: Equipo Nutrimetría
A7: 1.0 | B7: 2026-07-14 | C7: Banco de pruebas que coteja el z-score y las líneas de ±SD contra los valores publicados por la OMS, además de validaciones e integridad. Valores esperados independientes del CONFIG. | D7: Control de calidad. | E7: Equipo Nutrimetría
