Workbook

Sheet DATOS
A1: NUTRIMETRÍA · NMX-43 | DATOS
A3: Entradas principales del caso académico.
A5: =HYPERLINK("#'INICIO'!A1","INICIO") -> INICIO | B5: =HYPERLINK("#'DATOS'!A1","DATOS") -> DATOS | C5: =HYPERLINK("#'ENERGÍA'!A1","ENERGÍA") -> ENERGÍA | D5: =HYPERLINK("#'MACRONUTRIENTES'!A1","MACRONUTRIENTES") -> MACRONUTRIENTES | E5: =HYPERLINK("#'AGUA_FIBRA'!A1","AGUA/FIBRA") -> AGUA/FIBRA | F5: =HYPERLINK("#'FICHA_NUTRIENTE'!A1","FICHA/NUTRIENTE") -> FICHA/NUTRIENTE | G5: =HYPERLINK("#'RESULTADOS'!A1","RESULTADOS") -> RESULTADOS | H5: =HYPERLINK("#'DOCUMENTACIÓN'!A1","DOCUMENTACIÓN") -> DOCUMENTACIÓN | I5: =HYPERLINK("#'COBERTURA'!A1","COBERTURA") -> COBERTURA | J5: =HYPERLINK("#'AUDITORÍA_FINAL'!A1","AUDITORÍA") -> AUDITORÍA
A7: CASO ACADÉMICO · ENTRADAS EDITABLES
A8: Código del caso | B8: CASO-DEMO-01 | C8: Identificador interno | E8: RESUMEN AUTOMÁTICO
A9: Nombre opcional | B9: Caso demostrativo | C9: Texto | E9: Edad equivalente (años) | F9: =IF(B12="Meses",B11/12,B11) -> 25
A10: Fecha | B10: 46236 | C10: Fecha | E10: Edad equivalente (meses) | F10: =IF(B12="Meses",B11,B11*12) -> 300
A11: Edad | B11: 25 | C11: Años o meses | E11: IMC informativo | F11: =IF(OR(B14="",B15=""),"",B14/(B15/100)^2) -> 20.82094
A12: Unidad de edad | B12: Años | C12: Lista | E12: Suma de macros (%) | F12: =SUM(B27:B29) -> 100
A13: Sexo | B13: Femenino | C13: Lista | E13: Estado de entrada | F13: =IF(OR(B11="",B14="",B15=""),"INCOMPLETO",IF(ABS(F12-100)>CONFIG!$B$11,"REVISAR MACROS","LISTO")) -> LISTO
A14: Peso | B14: 56 | C14: kg | E14: Uso | F14: Académico; no diagnóstico
A15: Talla | B15: 164 | C15: cm
A16: Estado fisiológico | B16: Ninguno | C16: Lista | E16: Advertencia: los resultados son estimaciones poblacionales. El requerimiento energético individual debe contrastarse con evolución del peso, crecimiento, gestación o lactancia y con el contexto clínico.
A17: Actividad NASEM | B17: Poco activo | C17: Lista
A18: Actividad FAO 6–18 | B18: Ligera | C18: Lista
A19: Método energético | B19: Schofield × PAL | C19: Lista
A20: PAL manual Schofield | B20: 1.6 | C20: múltiplo BMR
A21: Semanas de gestación | B21: 20 | C21: 0–42
A22: IMC pregestacional | B22: Normal | C22: Lista
A23: Meses posparto | B23: 0 | C23: 0–12
A24: Tipo de lactancia | B24: No aplica | C24: Lista
A25: Modo de macronutrientes | B25: Porcentual | C25: Lista
A26: Proteína seleccionada | B26: 1 | C26: g/kg/día
A27: Proteína | B27: 15 | C27: % energía
A28: Lípidos | B28: 30 | C28: % energía
A29: Carbohidratos | B29: 55 | C29: % energía
A30: Agua consumida | B30: 2.5 | C30: L/día
A31: Fibra consumida | B31: 25 | C31: g/día
A32: Energía manual | B32: 2000 | C32: kcal/día

Sheet INICIO
A1: NUTRIMETRÍA · NMX-43 | INICIO
A3: Panel de control y navegación del portafolio académico.
A5: =HYPERLINK("#'INICIO'!A1","INICIO") -> INICIO | B5: =HYPERLINK("#'DATOS'!A1","DATOS") -> DATOS | C5: =HYPERLINK("#'ENERGÍA'!A1","ENERGÍA") -> ENERGÍA | D5: =HYPERLINK("#'MACRONUTRIENTES'!A1","MACRONUTRIENTES") -> MACRONUTRIENTES | E5: =HYPERLINK("#'AGUA_FIBRA'!A1","AGUA/FIBRA") -> AGUA/FIBRA | F5: =HYPERLINK("#'FICHA_NUTRIENTE'!A1","FICHA/NUTRIENTE") -> FICHA/NUTRIENTE | G5: =HYPERLINK("#'RESULTADOS'!A1","RESULTADOS") -> RESULTADOS | H5: =HYPERLINK("#'DOCUMENTACIÓN'!A1","DOCUMENTACIÓN") -> DOCUMENTACIÓN | I5: =HYPERLINK("#'COBERTURA'!A1","COBERTURA") -> COBERTURA | J5: =HYPERLINK("#'AUDITORÍA_FINAL'!A1","AUDITORÍA") -> AUDITORÍA
A7: NMX-43 · Portafolio de Bases de la Nutrición I y II
A9: NUTRIENTES 23 | E9: FASE ACTUAL 9 | I9: PRUEBAS APROBADAS 103 / 106 | M9: ESTADO 69 CASOS ACTIVOS
A15: FASE 9 · BIBLIOTECA UDD Y BANCO CLÍNICO-FORMATIVO El libro incluye 69 casos de micronutrientes: un caso básico, uno intermedio y uno avanzado para cada uno de los 23 micronutrientes. La hoja CASOS_CLÍNICOS permite seleccionar nutriente y nivel, y contiene una matriz de cobertura 69/69. Los casos son educativos: no representan diagnóstico, prescripción ni tratamiento automático.
A24: ACCESOS RÁPIDOS
A26: =HYPERLINK("#'DATOS'!A1","DATOS") -> DATOS | E26: =HYPERLINK("#'ENERGÍA'!A1","ENERGÍA") -> ENERGÍA | I26: =HYPERLINK("#'MACRONUTRIENTES'!A1","MACRONUTRIENTES") -> MACRONUTRIENTES | M26: =HYPERLINK("#'AGUA_FIBRA'!A1","AGUA / FIBRA") -> AGUA / FIBRA
A32: =HYPERLINK("#'ÍNDICE_CARGA_GLICÉMICA'!A1","ÍNDICE / CARGA") -> ÍNDICE / CARGA | E32: =HYPERLINK("#'RESULTADOS'!A1","RESULTADOS") -> RESULTADOS | I32: =HYPERLINK("#'FUENTES'!A1","FUENTES") -> FUENTES | M32: =HYPERLINK("#'PRUEBAS'!A1","PRUEBAS") -> PRUEBAS
A37: =HYPERLINK("#'FICHA_NUTRIENTE'!A1","FICHA NUTRIENTE") -> FICHA NUTRIENTE | E37: =HYPERLINK("#'REQUERIMIENTOS'!A1","REQUERIMIENTOS") -> REQUERIMIENTOS | I37: =HYPERLINK("#'DOCUMENTACIÓN'!A1","DOCUMENTACIÓN") -> DOCUMENTACIÓN | M37: =HYPERLINK("#'AUDITORÍA_FINAL'!A1","AUDITORÍA FINAL") -> AUDITORÍA FINAL

Sheet ENERGÍA
A1: NUTRIMETRÍA · NMX-43 | ENERGÍA
A3: Motores activos: Schofield 1985, FAO/WHO/UNU 2004, factorial de 24 horas y NASEM EER 2023.
A5: =HYPERLINK("#'INICIO'!A1","INICIO") -> INICIO | B5: =HYPERLINK("#'DATOS'!A1","DATOS") -> DATOS | C5: =HYPERLINK("#'ENERGÍA'!A1","ENERGÍA") -> ENERGÍA | D5: =HYPERLINK("#'MACRONUTRIENTES'!A1","MACRONUTRIENTES") -> MACRONUTRIENTES | E5: =HYPERLINK("#'AGUA_FIBRA'!A1","AGUA/FIBRA") -> AGUA/FIBRA | F5: =HYPERLINK("#'FICHA_NUTRIENTE'!A1","FICHA/NUTRIENTE") -> FICHA/NUTRIENTE | G5: =HYPERLINK("#'RESULTADOS'!A1","RESULTADOS") -> RESULTADOS | H5: =HYPERLINK("#'DOCUMENTACIÓN'!A1","DOCUMENTACIÓN") -> DOCUMENTACIÓN | I5: =HYPERLINK("#'COBERTURA'!A1","COBERTURA") -> COBERTURA | J5: =HYPERLINK("#'AUDITORÍA_FINAL'!A1","AUDITORÍA") -> AUDITORÍA
A7: DATOS DEL CASO
A8: Edad equivalente | B8: =CALCULOS_ENERGÍA!B2 -> 25 | C8: años | E8: BMR Schofield 1985 | F8: =CALCULOS_ENERGÍA!B15 -> 1316.408 | G8: kcal/d | I8: Indicador | K8: Resultado
A9: Sexo | B9: =CALCULOS_ENERGÍA!B4 -> Femenino | E9: GET Schofield × PAL | F9: =CALCULOS_ENERGÍA!B16 -> 2106.2528 | G9: kcal/d | I9: Diferencia NASEM vs Schofield (%) | K9: =CALCULOS_ENERGÍA!B25 -> 2.6828309
A10: Peso | B10: =CALCULOS_ENERGÍA!B5 -> 56 | C10: kg | E10: GET método factorial | F10: =CALCULOS_ENERGÍA!B18 -> 1974.612 | G10: kcal/d | I10: Alerta | K10: =CALCULOS_ENERGÍA!B26 -> OK CON LIMITACIONES
A11: Talla | B11: =CALCULOS_ENERGÍA!B6 -> 164 | C11: cm | E11: EER FAO 2004 (0–18) | F11: =CALCULOS_ENERGÍA!B19 -> ND | G11: kcal/d | I11: Uso de resultado | K11: Estimación educativa
A12: Estado fisiológico | B12: =CALCULOS_ENERGÍA!B7 -> Ninguno | E12: EER NASEM 2023 | F12: =CALCULOS_ENERGÍA!B21 -> 2162.76 | G12: kcal/d | I12: Criterio de control | K12: Monitorear peso/crecimiento
A13: Actividad NASEM | B13: =CALCULOS_ENERGÍA!B8 -> Poco activo | E13: Resultado seleccionado | F13: =CALCULOS_ENERGÍA!B23 -> 2106.2528 | G13: kcal/d
A14: Actividad FAO | B14: =CALCULOS_ENERGÍA!B9 -> Ligera | E14: Método seleccionado | F14: =CALCULOS_ENERGÍA!B22 -> Schofield × PAL | I14: Schofield estima metabolismo basal a partir de peso, edad y sexo. El método factorial combina BMR con horas y razones de actividad física (PAR). FAO pediátrico incorpora gasto y crecimiento. NASEM 2023 se presenta como comparador moderno y contempla embarazo/lactancia con entradas adicionales.
A15: PAL manual | B15: =CALCULOS_ENERGÍA!B10 -> 1.6 | E15: Método recomendado | F15: =CALCULOS_ENERGÍA!B24 -> Schofield × PAL y NASEM 2023 como comparación
I19: Instrucciones: 1) Asigne una actividad a cada fila. 2) Registre horas hasta completar 24. 3) El PAL se calcula como Σ(horas × PAR) / 24. 4) Si el total no es 24, el resultado queda ND. Los PAR son ejemplos de FAO/WHO/UNU y no sustituyen una medición individual.
A20: Seleccione una actividad en cualquiera de las 12 filas amarillas y registre sus horas. PAR, Horas × PAR, fuente y estado se completan automáticamente. El total debe ser 24 horas.
A21: MÉTODO FACTORIAL · 24 HORAS
A22: Actividad | B22: Horas/día | C22: PAR | D22: Horas × PAR | E22: Fuente/nota | F22: Estado
A23: Dormir | B23: 8 | C23: =IF(A23="","",IFERROR(INDEX(LISTAS!$L$2:$L$16,MATCH(A23,LISTAS!$K$2:$K$16,0)),"")) -> 1 | D23: =IF(A23="","",N(B23)*N(C23)) -> 8 | E23: =IF(A23="","",IFERROR(INDEX(LISTAS!$M$2:$M$16,MATCH(A23,LISTAS!$K$2:$K$16,0)),"Editable")) -> FAO tabla 5.1 | F23: =IF(A23="","",IF(B23<0,"ERROR",IF(B23>24,"REVISAR","OK"))) -> OK
A24: Cuidado personal | B24: 1 | C24: =IF(A24="","",IFERROR(INDEX(LISTAS!$L$2:$L$16,MATCH(A24,LISTAS!$K$2:$K$16,0)),"")) -> 2.3 | D24: =IF(A24="","",N(B24)*N(C24)) -> 2.3 | E24: =IF(A24="","",IFERROR(INDEX(LISTAS!$M$2:$M$16,MATCH(A24,LISTAS!$K$2:$K$16,0)),"Editable")) -> Vestirse, ducharse | F24: =IF(A24="","",IF(B24<0,"ERROR",IF(B24>24,"REVISAR","OK"))) -> OK
A25: Comer | B25: 1 | C25: =IF(A25="","",IFERROR(INDEX(LISTAS!$L$2:$L$16,MATCH(A25,LISTAS!$K$2:$K$16,0)),"")) -> 1.5 | D25: =IF(A25="","",N(B25)*N(C25)) -> 1.5 | E25: =IF(A25="","",IFERROR(INDEX(LISTAS!$M$2:$M$16,MATCH(A25,LISTAS!$K$2:$K$16,0)),"Editable")) -> Actividad alimentaria | F25: =IF(A25="","",IF(B25<0,"ERROR",IF(B25>24,"REVISAR","OK"))) -> OK
A26: Sentado / oficina | B26: 8 | C26: =IF(A26="","",IFERROR(INDEX(LISTAS!$L$2:$L$16,MATCH(A26,LISTAS!$K$2:$K$16,0)),"")) -> 1.5 | D26: =IF(A26="","",N(B26)*N(C26)) -> 12 | E26: =IF(A26="","",IFERROR(INDEX(LISTAS!$M$2:$M$16,MATCH(A26,LISTAS!$K$2:$K$16,0)),"Editable")) -> Trabajo sedentario | F26: =IF(A26="","",IF(B26<0,"ERROR",IF(B26>24,"REVISAR","OK"))) -> OK
A27: Trabajo doméstico general | B27: 1 | C27: =IF(A27="","",IFERROR(INDEX(LISTAS!$L$2:$L$16,MATCH(A27,LISTAS!$K$2:$K$16,0)),"")) -> 2.8 | D27: =IF(A27="","",N(B27)*N(C27)) -> 2.8 | E27: =IF(A27="","",IFERROR(INDEX(LISTAS!$M$2:$M$16,MATCH(A27,LISTAS!$K$2:$K$16,0)),"Editable")) -> Actividad doméstica | F27: =IF(A27="","",IF(B27<0,"ERROR",IF(B27>24,"REVISAR","OK"))) -> OK
A28: Conducir automóvil | B28: 1 | C28: =IF(A28="","",IFERROR(INDEX(LISTAS!$L$2:$L$16,MATCH(A28,LISTAS!$K$2:$K$16,0)),"")) -> 2 | D28: =IF(A28="","",N(B28)*N(C28)) -> 2 | E28: =IF(A28="","",IFERROR(INDEX(LISTAS!$M$2:$M$16,MATCH(A28,LISTAS!$K$2:$K$16,0)),"Editable")) -> Transporte | F28: =IF(A28="","",IF(B28<0,"ERROR",IF(B28>24,"REVISAR","OK"))) -> OK
A29: Caminar sin carga | B29: 1 | C29: =IF(A29="","",IFERROR(INDEX(LISTAS!$L$2:$L$16,MATCH(A29,LISTAS!$K$2:$K$16,0)),"")) -> 3.2 | D29: =IF(A29="","",N(B29)*N(C29)) -> 3.2 | E29: =IF(A29="","",IFERROR(INDEX(LISTAS!$M$2:$M$16,MATCH(A29,LISTAS!$K$2:$K$16,0)),"Editable")) -> Ritmos variables | F29: =IF(A29="","",IF(B29<0,"ERROR",IF(B29>24,"REVISAR","OK"))) -> OK
A30: Ocio ligero | B30: 3 | C30: =IF(A30="","",IFERROR(INDEX(LISTAS!$L$2:$L$16,MATCH(A30,LISTAS!$K$2:$K$16,0)),"")) -> 1.4 | D30: =IF(A30="","",N(B30)*N(C30)) -> 4.2 | E30: =IF(A30="","",IFERROR(INDEX(LISTAS!$M$2:$M$16,MATCH(A30,LISTAS!$K$2:$K$16,0)),"Editable")) -> TV, conversar | F30: =IF(A30="","",IF(B30<0,"ERROR",IF(B30>24,"REVISAR","OK"))) -> OK
A31: Viaje en bus | B31: 0 | C31: =IF(A31="","",IFERROR(INDEX(LISTAS!$L$2:$L$16,MATCH(A31,LISTAS!$K$2:$K$16,0)),"")) -> 1.2 | D31: =IF(A31="","",N(B31)*N(C31)) -> 0 | E31: =IF(A31="","",IFERROR(INDEX(LISTAS!$M$2:$M$16,MATCH(A31,LISTAS!$K$2:$K$16,0)),"Editable")) -> Transporte sentado | F31: =IF(A31="","",IF(B31<0,"ERROR",IF(B31>24,"REVISAR","OK"))) -> OK
B32: 0 | C32: =IF(A32="","",IFERROR(INDEX(LISTAS!$L$2:$L$16,MATCH(A32,LISTAS!$K$2:$K$16,0)),"")) | D32: =IF(A32="","",N(B32)*N(C32)) | E32: =IF(A32="","",IFERROR(INDEX(LISTAS!$M$2:$M$16,MATCH(A32,LISTAS!$K$2:$K$16,0)),"Editable")) | F32: =IF(A32="","",IF(B32<0,"ERROR",IF(B32>24,"REVISAR","OK")))
B33: 0 | C33: =IF(A33="","",IFERROR(INDEX(LISTAS!$L$2:$L$16,MATCH(A33,LISTAS!$K$2:$K$16,0)),"")) | D33: =IF(A33="","",N(B33)*N(C33)) | E33: =IF(A33="","",IFERROR(INDEX(LISTAS!$M$2:$M$16,MATCH(A33,LISTAS!$K$2:$K$16,0)),"Editable")) | F33: =IF(A33="","",IF(B33<0,"ERROR",IF(B33>24,"REVISAR","OK")))
B34: 0 | C34: =IF(A34="","",IFERROR(INDEX(LISTAS!$L$2:$L$16,MATCH(A34,LISTAS!$K$2:$K$16,0)),"")) | D34: =IF(A34="","",N(B34)*N(C34)) | E34: =IF(A34="","",IFERROR(INDEX(LISTAS!$M$2:$M$16,MATCH(A34,LISTAS!$K$2:$K$16,0)),"Editable")) | F34: =IF(A34="","",IF(B34<0,"ERROR",IF(B34>24,"REVISAR","OK")))
A35: Total horas | B35: =SUM(B23:B34) -> 24 | C35: Suma horas×PAR | E35: =SUM(D23:D34) -> 36 | F35: =IF(B35=24,"OK",IF(B35<24,"FALTAN "&TEXT(24-B35,"0.00")&" h","EXCEDEN "&TEXT(B35-24,"0.00")&" h")) -> OK
A36: PAL factorial | E36: =IF(B35=24,E35/24,"ND") -> 1.5
A37: GET factorial | C37: kcal/d | E37: =IF(ISNUMBER(E36),CALCULOS_ENERGÍA!B15*E36,"ND") -> 1974.612

Sheet MACRONUTRIENTES
A1: NUTRIMETRÍA · NMX-43 | MACRONUTRIENTES
A3: Distribución por porcentaje o proteína g/kg, conversión 4-9-4, DRI y AMDR.
A5: =HYPERLINK("#'INICIO'!A1","INICIO") -> INICIO | B5: =HYPERLINK("#'DATOS'!A1","DATOS") -> DATOS | C5: =HYPERLINK("#'ENERGÍA'!A1","ENERGÍA") -> ENERGÍA | D5: =HYPERLINK("#'MACRONUTRIENTES'!A1","MACRONUTRIENTES") -> MACRONUTRIENTES | E5: =HYPERLINK("#'AGUA_FIBRA'!A1","AGUA/FIBRA") -> AGUA/FIBRA | F5: =HYPERLINK("#'FICHA_NUTRIENTE'!A1","FICHA/NUTRIENTE") -> FICHA/NUTRIENTE | G5: =HYPERLINK("#'RESULTADOS'!A1","RESULTADOS") -> RESULTADOS | H5: =HYPERLINK("#'DOCUMENTACIÓN'!A1","DOCUMENTACIÓN") -> DOCUMENTACIÓN | I5: =HYPERLINK("#'COBERTURA'!A1","COBERTURA") -> COBERTURA | J5: =HYPERLINK("#'AUDITORÍA_FINAL'!A1","AUDITORÍA") -> AUDITORÍA
A7: ENTRADAS DE DISTRIBUCIÓN
A8: Energía seleccionada | B8: =CALCULOS_NUTRIENTES!B2 -> 2106.2528 | C8: kcal/d | E8: Componente | F8: g/día | G8: kcal/día | H8: % energía | I8: Referencia | J8: Adecuación
A9: Modo | B9: =CALCULOS_NUTRIENTES!B7 -> Porcentual | E9: Proteína | F9: =CALCULOS_NUTRIENTES!B12 -> 78.98448 | G9: =CALCULOS_NUTRIENTES!B13 -> 315.93792 | H9: =IF(ISNUMBER(G9),G9/CALCULOS_NUTRIENTES!B2*100,"ND") -> 15 | I9: =CALCULOS_NUTRIENTES!B21 -> 46 | J9: =CALCULOS_NUTRIENTES!B23 -> 171.70539
A10: Peso | B10: =CALCULOS_NUTRIENTES!B6 -> 56 | C10: kg | E10: Lípidos | F10: =CALCULOS_NUTRIENTES!B14 -> 70.208427 | G10: =CALCULOS_NUTRIENTES!B15 -> 631.87584 | H10: =IF(ISNUMBER(G10),G10/CALCULOS_NUTRIENTES!B2*100,"ND") -> 30 | I10: =CALCULOS_NUTRIENTES!B26 -> 20–35
A11: Proteína seleccionada | B11: =CALCULOS_NUTRIENTES!B8 -> 1 | C11: g/kg/d | E11: Carbohidratos | F11: =CALCULOS_NUTRIENTES!B16 -> 289.60976 | G11: =CALCULOS_NUTRIENTES!B17 -> 1158.439 | H11: =IF(ISNUMBER(G11),G11/CALCULOS_NUTRIENTES!B2*100,"ND") -> 55 | I11: =CALCULOS_NUTRIENTES!B22 -> 130 | J11: =CALCULOS_NUTRIENTES!B24 -> 222.77674
A12: Proteína | B12: =CALCULOS_NUTRIENTES!B9 -> 15 | C12: % | E12: TOTAL | G12: =CALCULOS_NUTRIENTES!B18 -> 2106.2528 | H12: =CALCULOS_NUTRIENTES!B19 -> 100
A13: Lípidos | B13: =CALCULOS_NUTRIENTES!B10 -> 30 | C13: %
A14: CHO | B14: =CALCULOS_NUTRIENTES!B11 -> 55 | C14: %
A17: REFERENCIAS Y CONTROL | E17: Interpretación académica: • RDA/AI y AMDR son referencias diferentes. • El modo porcentual convierte energía a gramos mediante factores 4-9-4. • El modo g/kg fija proteína, conserva el porcentaje de grasa y calcula CHO como residuo. • Un porcentaje de adecuación no sustituye la evaluación clínica ni implica seguridad por sobre la referencia.
A18: Indicador | B18: Resultado | C18: Interpretación
A19: RDA/AI proteína | B19: =CALCULOS_NUTRIENTES!B21 -> 46 | C19: g/día
A20: RDA/AI carbohidratos | B20: =CALCULOS_NUTRIENTES!B22 -> 130 | C20: g/día
A21: AMDR proteína | B21: =CALCULOS_NUTRIENTES!B25 -> 10–35 | C21: % energía
A22: AMDR lípidos | B22: =CALCULOS_NUTRIENTES!B26 -> 20–35 | C22: % energía
A23: AMDR CHO | B23: =CALCULOS_NUTRIENTES!B27 -> 45–65 | C23: % energía
A24: Cierre energético | B24: =CALCULOS_NUTRIENTES!B28 -> CIERRE CORRECTO | C24: Tolerancia configurable

Sheet ÍNDICE_CARGA_GLICÉMICA
A1: NUTRIMETRÍA · NMX-43 | ÍNDICE_CARGA_GLICÉMICA
A3: Cálculo por porción, clasificación y trazabilidad del valor publicado.
A5: =HYPERLINK("#'INICIO'!A1","INICIO") -> INICIO | B5: =HYPERLINK("#'DATOS'!A1","DATOS") -> DATOS | C5: =HYPERLINK("#'ENERGÍA'!A1","ENERGÍA") -> ENERGÍA | D5: =HYPERLINK("#'MACRONUTRIENTES'!A1","MACRONUTRIENTES") -> MACRONUTRIENTES | E5: =HYPERLINK("#'AGUA_FIBRA'!A1","AGUA/FIBRA") -> AGUA/FIBRA | F5: =HYPERLINK("#'FICHA_NUTRIENTE'!A1","FICHA/NUTRIENTE") -> FICHA/NUTRIENTE | G5: =HYPERLINK("#'RESULTADOS'!A1","RESULTADOS") -> RESULTADOS | H5: =HYPERLINK("#'DOCUMENTACIÓN'!A1","DOCUMENTACIÓN") -> DOCUMENTACIÓN | I5: =HYPERLINK("#'COBERTURA'!A1","COBERTURA") -> COBERTURA | J5: =HYPERLINK("#'AUDITORÍA_FINAL'!A1","AUDITORÍA") -> AUDITORÍA
A7: ÍNDICE Y CARGA GLICÉMICA · CÁLCULO EDUCATIVO
A9: Entrada | B9: Valor | C9: Unidad/estado | D9: Fuente o nota | F9: Resultado | G9: Valor | H9: Unidad | I9: Clasificación | J9: Fuente_ID | K9: Estado
A10: Alimento o categoría | B10: Productos lácteos (promedio de categoría) | D10: IG_BASE | F10: Índice glicémico | G10: =B13 -> 35 | I10: =IF(NOT(ISNUMBER(G10)),"NO EVALUABLE",IF(G10<=CONFIG!$B$13,"BAJO",IF(G10<=CONFIG!$B$14,"MEDIO","ALTO"))) -> BAJO | J10: =IF(ISNUMBER(B12),"USUARIO",INDEX(IG_BASE!$H$2:$H$8,MATCH(B10,IG_BASE!$B$2:$B$8,0))) -> SRC-GI-2021 | K10: =IF(ISNUMBER(B12),IF(B16="","FALTA FUENTE MANUAL","MANUAL CON FUENTE"),INDEX(IG_BASE!$J$2:$J$8,MATCH(B10,IG_BASE!$B$2:$B$8,0))) -> VERIFICADO_SECUNDARIO
A11: IG recuperado | B11: =IF(B10="","",INDEX(IG_BASE!$E$2:$E$8,MATCH(B10,IG_BASE!$B$2:$B$8,0))) -> 35 | C11: Glucosa=100 | D11: Automático | F11: Carga glicémica | G11: =IF(AND(ISNUMBER(B13),ISNUMBER(B14)),B13*B14/100,"ND") -> 10.5 | I11: =IF(NOT(ISNUMBER(G11)),"NO EVALUABLE",IF(G11<=CONFIG!$B$15,"BAJA",IF(G11<=CONFIG!$B$16,"MEDIA","ALTA"))) -> MEDIA | J11: =J10 -> SRC-GI-2021 | K11: =K10 -> VERIFICADO_SECUNDARIO
A12: IG manual (opcional) | C12: 0–100 | D12: Sobrescribe el recuperado | F12: Carbohidratos disponibles | G12: =B14 -> 30 | H12: g
A13: IG efectivo | B13: =IF(ISNUMBER(B12),B12,B11) -> 35 | C13: Glucosa=100 | D13: Usado en el cálculo | F13: Escala de IG | G13: Glucosa=100
A14: CHO disponibles por porción | B14: 30 | C14: g | D14: Entrada del usuario | F14: Advertencia | G14: =IF(OR(B10="",NOT(ISNUMBER(B13))),"Faltan datos","El IG puede variar por variedad, madurez, procesamiento, cocción, enfriamiento y composición de la comida.") -> El IG puede variar por variedad, madurez, procesamiento, cocción, enfriamiento y composición de la comida.
A15: Descripción de porción | B15: Porción con 30 g de CHO disponibles | C15: texto | D15: Opcional
A16: Fuente específica del valor manual | C16: texto/URL | D16: Obligatoria si se usa IG manual
A20: FÓRMULA, CLASIFICACIÓN Y USO CORRECTO
A21: Carga glicémica = índice glicémico × gramos de carbohidratos disponibles de la porción ÷ 100. Clasificación configurada: IG bajo ≤55, medio 56–69 y alto ≥70; carga glicémica baja ≤10, media 11–19 y alta ≥20. Los valores de categoría incluidos son promedios educativos y no deben asignarse automáticamente a un producto o preparación concreta. Para un caso real, utilice un valor publicado que coincida con el alimento, método y preparación, y registre la fuente.
A29: TRAZABILIDAD DEL REGISTRO SELECCIONADO
A30: ID | B30: Alimento publicado | C30: Preparación/alcance | D30: Ámbito | E30: IG | F30: Escala | G30: Año | H30: Fuente_ID | I30: Observaciones | J30: Estado
A31: =IF(B10="","",INDEX(IG_BASE!$A$2:$A$8,MATCH(B10,IG_BASE!$B$2:$B$8,0))) -> IG-DAIRY-CAT | B31: =IF(B10="","",INDEX(IG_BASE!$B$2:$B$8,MATCH(B10,IG_BASE!$B$2:$B$8,0))) -> Productos lácteos (promedio de categoría) | C31: =IF(B10="","",INDEX(IG_BASE!$C$2:$C$8,MATCH(B10,IG_BASE!$B$2:$B$8,0))) -> Promedio de múltiples productos | D31: =IF(B10="","",INDEX(IG_BASE!$D$2:$D$8,MATCH(B10,IG_BASE!$B$2:$B$8,0))) -> Internacional | E31: =IF(B10="","",INDEX(IG_BASE!$E$2:$E$8,MATCH(B10,IG_BASE!$B$2:$B$8,0))) -> 35 | F31: =IF(B10="","",INDEX(IG_BASE!$F$2:$F$8,MATCH(B10,IG_BASE!$B$2:$B$8,0))) -> Glucosa=100 | G31: =IF(B10="","",INDEX(IG_BASE!$G$2:$G$8,MATCH(B10,IG_BASE!$B$2:$B$8,0))) -> 2021 | H31: =IF(B10="","",INDEX(IG_BASE!$H$2:$H$8,MATCH(B10,IG_BASE!$B$2:$B$8,0))) -> SRC-GI-2021 | I31: =IF(B10="","",INDEX(IG_BASE!$I$2:$I$8,MATCH(B10,IG_BASE!$B$2:$B$8,0))) -> Promedio de categoría; composición y azúcares añadidos modifican el resultado. | J31: =IF(B10="","",INDEX(IG_BASE!$J$2:$J$8,MATCH(B10,IG_BASE!$B$2:$B$8,0))) -> VERIFICADO_SECUNDARIO

Sheet AGUA_FIBRA
A1: NUTRIMETRÍA · NMX-43 | AGUA_FIBRA
A3: AI de agua total y fibra según edad, sexo y estado fisiológico.
A5: =HYPERLINK("#'INICIO'!A1","INICIO") -> INICIO | B5: =HYPERLINK("#'DATOS'!A1","DATOS") -> DATOS | C5: =HYPERLINK("#'ENERGÍA'!A1","ENERGÍA") -> ENERGÍA | D5: =HYPERLINK("#'MACRONUTRIENTES'!A1","MACRONUTRIENTES") -> MACRONUTRIENTES | E5: =HYPERLINK("#'AGUA_FIBRA'!A1","AGUA/FIBRA") -> AGUA/FIBRA | F5: =HYPERLINK("#'FICHA_NUTRIENTE'!A1","FICHA/NUTRIENTE") -> FICHA/NUTRIENTE | G5: =HYPERLINK("#'RESULTADOS'!A1","RESULTADOS") -> RESULTADOS | H5: =HYPERLINK("#'DOCUMENTACIÓN'!A1","DOCUMENTACIÓN") -> DOCUMENTACIÓN | I5: =HYPERLINK("#'COBERTURA'!A1","COBERTURA") -> COBERTURA | J5: =HYPERLINK("#'AUDITORÍA_FINAL'!A1","AUDITORÍA") -> AUDITORÍA
A7: AGUA Y FIBRA · REFERENCIAS DRI Y ADECUACIÓN
A9: Entrada | B9: Valor | C9: Unidad | D9: Procedencia | F9: Indicador | G9: Referencia | H9: Unidad | I9: Ingesta | J9: Adecuación (%) | K9: Estado
A10: Agua total ingresada | B10: =DATOS!B30 -> 2.5 | C10: L/d | D10: DATOS | F10: Agua total | G10: =CALCULOS_ADECUACIÓN!B7 -> 2.7 | H10: L/d | I10: =CALCULOS_ADECUACIÓN!B5 -> 2.5 | J10: =CALCULOS_ADECUACIÓN!B9 -> 92.592593 | K10: =CALCULOS_ADECUACIÓN!B11 -> DENTRO DEL RANGO
A11: Fibra dietaria ingresada | B11: =DATOS!B31 -> 25 | C11: g/d | D11: DATOS | F11: Fibra dietaria | G11: =CALCULOS_ADECUACIÓN!B8 -> 25 | H11: g/d | I11: =CALCULOS_ADECUACIÓN!B6 -> 25 | J11: =CALCULOS_ADECUACIÓN!B10 -> 100 | K11: =CALCULOS_ADECUACIÓN!B12 -> DENTRO DEL RANGO
A15: INTERPRETACIÓN Y LÍMITES
A16: El valor de agua corresponde a agua total (bebidas + humedad de los alimentos) cuando se utiliza la AI de los DRI. La cifra no debe interpretarse como una prescripción universal de agua para beber. La fibra se muestra como AI y puede no estar establecida para lactantes menores de 1 año en esta matriz. Los semáforos usan límites técnicos configurables (90–110 %) y no reemplazan la evaluación clínica.
A24: DATOS DEL PERFIL
A25: Variable | B25: Valor | C25: Unidad
A26: Edad | B26: =CALCULOS_ADECUACIÓN!B2 -> 25 | C26: años
A27: Sexo | B27: =CALCULOS_ADECUACIÓN!B3 -> Femenino
A28: Estado fisiológico | B28: =CALCULOS_ADECUACIÓN!B4 -> Ninguno

Sheet NUTRIENTES
A1: NUTRIMETRÍA · NMX-43 | NUTRIENTES
A3: Estructura de NUTRIENTES preparada para el desarrollo por fases.
A5: =HYPERLINK("#'INICIO'!A1","INICIO") -> INICIO | B5: =HYPERLINK("#'DATOS'!A1","DATOS") -> DATOS | C5: =HYPERLINK("#'ENERGÍA'!A1","ENERGÍA") -> ENERGÍA | D5: =HYPERLINK("#'MACRONUTRIENTES'!A1","MACRONUTRIENTES") -> MACRONUTRIENTES | E5: =HYPERLINK("#'AGUA_FIBRA'!A1","AGUA/FIBRA") -> AGUA/FIBRA | F5: =HYPERLINK("#'FICHA_NUTRIENTE'!A1","FICHA/NUTRIENTE") -> FICHA/NUTRIENTE | G5: =HYPERLINK("#'RESULTADOS'!A1","RESULTADOS") -> RESULTADOS | H5: =HYPERLINK("#'DOCUMENTACIÓN'!A1","DOCUMENTACIÓN") -> DOCUMENTACIÓN | I5: =HYPERLINK("#'COBERTURA'!A1","COBERTURA") -> COBERTURA | J5: =HYPERLINK("#'AUDITORÍA_FINAL'!A1","AUDITORÍA") -> AUDITORÍA
A7: ID | B7: Nombre | C7: Símbolo | D7: Categoría | E7: Subcategoría | F7: Unidad principal | G7: Presente INTA | H7: DRI | I7: UL | J7: Estado ficha | K7: Última revisión
A8: MIN-FE | B8: Hierro | C8: Fe | D8: Mineral | E8: Oligoelemento | F8: mg | G8: Sí | H8: Sí | I8: Sí | J8: VERIFICADO_SECUNDARIO | K8: 46237
A9: MIN-ZN | B9: Zinc | C9: Zn | D9: Mineral | E9: Oligoelemento | F9: mg | G9: Sí | H9: Sí | I9: Sí | J9: VERIFICADO_SECUNDARIO | K9: 46237
A10: MIN-CU | B10: Cobre | C10: Cu | D10: Mineral | E10: Oligoelemento | F10: mg | G10: Sí | H10: Sí | I10: Sí | J10: VERIFICADO_SECUNDARIO | K10: 46237
A11: MIN-CA | B11: Calcio | C11: Ca | D11: Mineral | E11: Macromineral | F11: mg | G11: Sí | H11: Sí | I11: Sí | J11: VERIFICADO_SECUNDARIO | K11: 46237
A12: MIN-P | B12: Fósforo | C12: P | D12: Mineral | E12: Macromineral | F12: mg | G12: Sí | H12: Sí | I12: Sí | J12: VERIFICADO_SECUNDARIO | K12: 46237
A13: MIN-SE | B13: Selenio | C13: Se | D13: Mineral | E13: Oligoelemento | F13: µg | G13: Sí | H13: Sí | I13: Sí | J13: VERIFICADO_SECUNDARIO | K13: 46237
A14: MIN-K | B14: Potasio | C14: K | D14: Mineral | E14: Electrolito | F14: mg | G14: Sí | H14: Sí | I14: No establecido | J14: VERIFICADO_SECUNDARIO | K14: 46237
A15: MIN-MG | B15: Magnesio | C15: Mg | D15: Mineral | E15: Macromineral | F15: mg | G15: Sí | H15: Sí | I15: Sí | J15: VERIFICADO_SECUNDARIO | K15: 46237
A16: MIN-NA | B16: Sodio | C16: Na | D16: Mineral | E16: Electrolito | F16: mg | G16: Sí | H16: Sí | I16: Según sistema | J16: VERIFICADO_SECUNDARIO | K16: 46237
A17: MIN-CL | B17: Cloruro | C17: Cl⁻ | D17: Mineral | E17: Electrolito | F17: mg | G17: No | H17: Sí | I17: Sí | J17: VERIFICADO_SECUNDARIO | K17: 46237
A18: VIT-A | B18: Vitamina A | C18: RAE | D18: Vitamina liposoluble | E18: Liposoluble | F18: µg RAE | G18: Sí | H18: Sí | I18: Sí | J18: VERIFICADO_SECUNDARIO | K18: 46237
A19: VIT-D | B19: Vitamina D | C19: D | D19: Vitamina liposoluble | E19: Liposoluble | F19: µg | G19: Sí | H19: Sí | I19: Sí | J19: VERIFICADO_SECUNDARIO | K19: 46237
... A30: VIT-B12 | B30: Cobalamina | C30: B12 | D30: Vitamina hidrosoluble | E30: Complejo B | F30: µg | G30: Sí | H30: Sí | I30: No establecido | J30: VERIFICADO_SECUNDARIO | K30: 46237

Sheet FICHA_NUTRIENTE
A1: NUTRIMETRÍA · NMX-43 | FICHA DE NUTRIENTE
A3: Ficha automatizada de consulta rápida para 23 vitaminas y minerales.
A5: =HYPERLINK("#'INICIO'!A1","INICIO") -> INICIO | B5: =HYPERLINK("#'DATOS'!A1","DATOS") -> DATOS | C5: =HYPERLINK("#'ENERGÍA'!A1","ENERGÍA") -> ENERGÍA | D5: =HYPERLINK("#'MACRONUTRIENTES'!A1","MACRONUTRIENTES") -> MACRONUTRIENTES | E5: =HYPERLINK("#'AGUA_FIBRA'!A1","AGUA/FIBRA") -> AGUA/FIBRA | F5: =HYPERLINK("#'FICHA_NUTRIENTE'!A1","FICHA/NUTRIENTE") -> FICHA/NUTRIENTE | G5: =HYPERLINK("#'RESULTADOS'!A1","RESULTADOS") -> RESULTADOS | H5: =HYPERLINK("#'DOCUMENTACIÓN'!A1","DOCUMENTACIÓN") -> DOCUMENTACIÓN | I5: =HYPERLINK("#'COBERTURA'!A1","COBERTURA") -> COBERTURA | J5: =HYPERLINK("#'AUDITORÍA_FINAL'!A1","AUDITORÍA") -> AUDITORÍA
A7: NUTRIENTE | C7: Zinc | E7: ID | G7: =IFERROR(INDEX(NUTRIENTES!$A$8:$A$30,MATCH($C$7,NUTRIENTES!$B$8:$B$30,0)),"") -> MIN-ZN | I7: CLASE | K7: =IFERROR(INDEX(NUTRIENTES!$D$8:$D$30,MATCH($C$7,NUTRIENTES!$B$8:$B$30,0)),"") -> Mineral | M7: UNIDAD | N7: =IFERROR(INDEX(NUTRIENTES!$F$8:$F$30,MATCH($C$7,NUTRIENTES!$B$8:$B$30,0)),"") -> mg
A8: Use la flecha de la celda amarilla para seleccionar el nutriente. | C8: =IFERROR(INDEX(NUTRIENTES!$A$8:$A$30,MATCH($C$7,NUTRIENTES!$B$8:$B$30,0)),"") -> MIN-ZN
A10: 1. IDENTIFICACIÓN | E10: 2. FUNCIONES FISIOLÓGICAS | J10: 3. IMPORTANCIA CLÍNICA
A11: =IFERROR(INDEX(FICHAS_BASE!$D$2:$D$461,MATCH($C$8&"|IDENTIFICACION",FICHAS_BASE!$H$2:$H$461,0)),"") -> Zinc (Zn). Mineral traza presente en proteínas y enzimas; no posee un depósito corporal especializado de gran tamaño. | E11: =IFERROR(INDEX(FICHAS_BASE!$D$2:$D$461,MATCH($C$8&"|FUNCIONES",FICHAS_BASE!$H$2:$H$461,0)),"") -> • Actividad catalítica de numerosas enzimas. • Síntesis de ADN y proteínas. • Crecimiento, desarrollo y cicatrización. • Función inmunitaria y percepción del gusto. | J11: =IFERROR(INDEX(FICHAS_BASE!$D$2:$D$461,MATCH($C$8&"|ORGANOS_TEJIDOS",FICHAS_BASE!$H$2:$H$461,0)),"")&CHAR(10)&CHAR(10)&IFERROR(INDEX(FICHAS_BASE!$D$2:$D$461,MATCH($C$8&"|IMPORTANCIA_CLINICA",FICHAS_BASE!$H$2:$H$461,0)),"") -> Intestino, hígado, páncreas, piel, sistema inmunitario, músculo y hueso. La homeostasis depende de absorción intestinal y pérdidas. La deficiencia afecta crecimiento, inmunidad y cicatrización.
A17: 4. METABOLISMO RESUMIDO
A18: =IFERROR(INDEX(FICHAS_BASE!$D$2:$D$461,MATCH($C$8&"|METABOLISMO",FICHAS_BASE!$H$2:$H$461,0)),"") -> Ingesta → absorción en intestino delgado → transporte unido principalmente a albúmina → distribución tisular → intercambio rápido con reservas celulares → excreción sobre todo fecal.
A23: 5. ABSORCIÓN | E23: 6. TRANSPORTE Y ALMACENAMIENTO | J23: 7. EXCRECIÓN
A24: =IFERROR(INDEX(FICHAS_BASE!$D$2:$D$461,MATCH($C$8&"|ABSORCION",FICHAS_BASE!$H$2:$H$461,0)),"") -> La absorción ocurre en intestino delgado mediante transportadores regulados por el estado de zinc y la composición de la dieta. | E24: ="Transporte: "&IFERROR(INDEX(FICHAS_BASE!$D$2:$D$461,MATCH($C$8&"|TRANSPORTE",FICHAS_BASE!$H$2:$H$461,0)),"")&CHAR(10)&CHAR(10)&"Almacenamiento: "&IFERROR(INDEX(FICHAS_BASE!$D$2:$D$461,MATCH($C$8&"|ALMACENAMIENTO",FICHAS_BASE!$H$2:$H$461,0)),"") -> Transporte: Circula unido sobre todo a albúmina y otras proteínas; entra y sale de células mediante familias de transportadores ZIP y ZnT. Almacenamiento: No hay un órgano de depósito específico; músculo y hueso contienen gran parte del zinc corporal por su masa. | J24: =IFERROR(INDEX(FICHAS_BASE!$D$2:$D$461,MATCH($C$8&"|EXCRECION",FICHAS_BASE!$H$2:$H$461,0)),"") -> Principalmente por heces; también orina, sudor, semen, menstruación y descamación.
A30: 8. BIODISPONIBILIDAD | H30: 9. FUENTES ALIMENTARIAS
A31: ="Favorece: "&IFERROR(INDEX(FICHAS_BASE!$D$2:$D$461,MATCH($C$8&"|BIODISPONIBILIDAD_MEJORA",FICHAS_BASE!$H$2:$H$461,0)),"")&CHAR(10)&CHAR(10)&"Reduce: "&IFERROR(INDEX(FICHAS_BASE!$D$2:$D$461,MATCH($C$8&"|BIODISPONIBILIDAD_REDUCE",FICHAS_BASE!$H$2:$H$461,0)),"") -> Favorece: Proteínas animales y fermentación/germinación que reduzcan fitatos pueden mejorar la biodisponibilidad. Reduce: Fitatos reducen la absorción; dietas vegetales no planificadas pueden requerir atención a la biodisponibilidad. | H31: =IFERROR(INDEX(FICHAS_BASE!$D$2:$D$461,MATCH($C$8&"|FUENTES_ALIMENTARIAS",FICHAS_BASE!$H$2:$H$461,0)),"") -> Ostras y otros mariscos; carne bovina; aves; lácteos; legumbres, semillas y frutos secos.
A37: 10. DÉFICIT Y EXCESO | H37: 11. APLICACIÓN CLÍNICA
A38: ="Déficit: "&IFERROR(INDEX(FICHAS_BASE!$D$2:$D$461,MATCH($C$8&"|DEFICIT",FICHAS_BASE!$H$2:$H$461,0)),"")&CHAR(10)&CHAR(10)&"Exceso: "&IFERROR(INDEX(FICHAS_BASE!$D$2:$D$461,MATCH($C$8&"|EXCESO",FICHAS_BASE!$H$2:$H$461,0)),"") -> Déficit: Retraso del crecimiento, alopecia, dermatitis, diarrea, alteración del gusto, mala cicatrización e inmunidad deteriorada. Riesgo en malabsorción, cirugía bariátrica, alcoholismo y dietas muy altas en fitatos. Exceso: Dosis elevadas sostenidas pueden causar náuseas, reducir cobre, alterar perfil lipídico y deteriorar función inmunitaria. | H38: =IFERROR(INDEX(FICHAS_BASE!$D$2:$D$461,MATCH($C$8&"|APLICACION_CLINICA",FICHAS_BASE!$H$2:$H$461,0)),"") -> En diarrea crónica, malabsorción o cicatrización deficiente, revisar ingesta, pérdidas y contexto clínico antes de atribuir los síntomas al zinc.
A44: 12. INTERACCIONES DESTACADAS
A45: =IFERROR(INDEX(FICHAS_BASE!$D$2:$D$461,MATCH($C$8&"|INTERACCIONES_RESUMEN",FICHAS_BASE!$H$2:$H$461,0)),"") -> Cobre | Nutriente–nutriente | Dosis altas de zinc reducen cobre Vigilar suplementos crónicos de zinc. Quinolonas y tetraciclinas | Medicamento–nutriente | Reduce absorción de ambos Separación horaria solo según indicación farmacéutica/médica.
A51: 13. BIOMARCADORES | H51: 14. PERLAS CLÍNICAS
A52: =IFERROR(INDEX(FICHAS_BASE!$D$2:$D$461,MATCH($C$8&"|BIOMARCADORES_RESUMEN",FICHAS_BASE!$H$2:$H$461,0)),"") -> Zinc plasmático/sérico | Estado circulante de zinc Limitación: Sensibilidad limitada; cambia con ayuno, hora, inflamación y embarazo. | H52: =IFERROR(INDEX(FICHAS_BASE!$D$2:$D$461,MATCH($C$8&"|PERLAS",FICHAS_BASE!$H$2:$H$461,0)),"") -> • Zinc alto en suplementos puede inducir deficiencia de cobre. • El zinc plasmático cambia con inflamación y hora del día. • Fitatos importan tanto como la cantidad ingerida. • No usar zinc para todas las infecciones sin indicación.
A59: 15. REFERENCIAS Y ADVERTENCIA
A60: =IFERROR(INDEX(FICHAS_BASE!$D$2:$D$461,MATCH($C$8&"|REFERENCIAS",FICHAS_BASE!$H$2:$H$461,0)),"")&CHAR(10)&CHAR(10)&IFERROR(INDEX(FICHAS_BASE!$D$2:$D$461,MATCH($C$8&"|ADVERTENCIA",FICHAS_BASE!$H$2:$H$461,0)),"") -> 1) SRC-ODS-ZINC: fuente institucional principal para funciones, metabolismo, déficit, exceso e interacciones. 2) SRC-DRI-SUMMARY: referencia normativa o clínica complementaria para requerimientos e interpretación. Material educativo. No sustituye evaluación clínica, diagnóstico, tratamiento ni indicaciones farmacológicas.
A66: =HYPERLINK("#'FUENTES'!A1","VER FUENTES") -> VER FUENTES | E66: =HYPERLINK("#'INTERACCIONES'!A1","VER INTERACCIONES") -> VER INTERACCIONES | I66: =HYPERLINK("#'BIOMARCADORES'!A1","VER BIOMARCADORES") -> VER BIOMARCADORES | M66: =HYPERLINK("#'CASOS_CLÍNICOS'!A1","VER CASO") -> VER CASO

Sheet FUENTES_ALIMENTARIAS
A1: NUTRIMETRÍA · NMX-43 | FUENTES_ALIMENTARIAS
A3: Selección de alimentos INTA, cálculo por gramaje, porcentaje de referencia y ranking por 100 g.
A5: =HYPERLINK("#'INICIO'!A1","INICIO") -> INICIO | B5: =HYPERLINK("#'DATOS'!A1","DATOS") -> DATOS | C5: =HYPERLINK("#'ENERGÍA'!A1","ENERGÍA") -> ENERGÍA | D5: =HYPERLINK("#'MACRONUTRIENTES'!A1","MACRONUTRIENTES") -> MACRONUTRIENTES | E5: =HYPERLINK("#'AGUA_FIBRA'!A1","AGUA/FIBRA") -> AGUA/FIBRA | F5: =HYPERLINK("#'FICHA_NUTRIENTE'!A1","FICHA/NUTRIENTE") -> FICHA/NUTRIENTE | G5: =HYPERLINK("#'RESULTADOS'!A1","RESULTADOS") -> RESULTADOS | H5: =HYPERLINK("#'DOCUMENTACIÓN'!A1","DOCUMENTACIÓN") -> DOCUMENTACIÓN | I5: =HYPERLINK("#'COBERTURA'!A1","COBERTURA") -> COBERTURA | J5: =HYPERLINK("#'AUDITORÍA_FINAL'!A1","AUDITORÍA") -> AUDITORÍA
A7: NUTRIENTE | C7: Zinc | E7: ID | G7: =IFERROR(IFERROR(INDEX(NUTRIENTES!$A$8:$A$30,MATCH($C$7,NUTRIENTES!$B$8:$B$30,0)),""),"") -> MIN-ZN | I7: ENCABEZADO INTA | K7: =IFERROR(IFERROR(INDEX(LISTAS!$AH$2:$AH$24,MATCH($G$7,LISTAS!$AF$2:$AF$24,0)),""),"") -> Zinc (mg) | M7: UNIDAD | N7: =IFERROR(IFERROR(INDEX(LISTAS!$AI$2:$AI$24,MATCH($G$7,LISTAS!$AF$2:$AF$24,0)),""),"") -> mg
A8: Use la flecha de la celda amarilla para seleccionar el nutriente.
A9: OBJETIVO | E9: TIPO | I9: LÍMITE | M9: DISPONIBLE INTA
A10: =IFERROR(IFERROR(INDEX(DRI_BASE!$T$2:$T$469,MATCH(1,INDEX((DRI_BASE!$B$2:$B$469=$G$7)*(DRI_BASE!$D$2:$D$469<=DATOS!$F$9)*(DRI_BASE!$E$2:$E$469>DATOS!$F$9)*(((DRI_BASE!$C$2:$C$469=DATOS!$B$13)+(DRI_BASE!$C$2:$C$469="Ambos"))>0)*(DRI_BASE!$G$2:$G$469=DATOS!$B$16),0),0)),"ND"),"ND") -> 8 | E10: =IFERROR(IFERROR(INDEX(DRI_BASE!$R$2:$R$469,MATCH(1,INDEX((DRI_BASE!$B$2:$B$469=$G$7)*(DRI_BASE!$D$2:$D$469<=DATOS!$F$9)*(DRI_BASE!$E$2:$E$469>DATOS!$F$9)*(((DRI_BASE!$C$2:$C$469=DATOS!$B$13)+(DRI_BASE!$C$2:$C$469="Ambos"))>0)*(DRI_BASE!$G$2:$G$469=DATOS!$B$16),0),0)),"ND"),"ND") -> RDA | I10: =IFERROR(IFERROR(INDEX(DRI_BASE!$U$2:$U$469,MATCH(1,INDEX((DRI_BASE!$B$2:$B$469=$G$7)*(DRI_BASE!$D$2:$D$469<=DATOS!$F$9)*(DRI_BASE!$E$2:$E$469>DATOS!$F$9)*(((DRI_BASE!$C$2:$C$469=DATOS!$B$13)+(DRI_BASE!$C$2:$C$469="Ambos"))>0)*(DRI_BASE!$G$2:$G$469=DATOS!$B$16),0),0)),"ND"),"ND") -> 40 | M10: =IFERROR(IFERROR(INDEX(LISTAS!$AJ$2:$AJ$24,MATCH($G$7,LISTAS!$AF$2:$AF$24,0)),"No"),"No") -> Sí
A12: # | B12: Alimento | C12: Grupo | D12: Estado | E12: Porción doméstica | F12: Gramaje | G12: Valor/100 g | H12: Aporte | I12: Unidad | J12: % referencia | K12: ND | L12: Estado dato | M12: Fuente | N12: Observación
A13: 1 | B13: Mango | C13: =IF($B13="","",IFERROR(IFERROR(INDEX(ALIMENTOS_INTA!$F$8:$F$625,MATCH($B13,ALIMENTOS_INTA!$E$8:$E$625,0)),""),"")) -> Frutas | D13: =IF($B13="","",IFERROR(IFERROR(INDEX(ALIMENTOS_INTA!$G$8:$G$625,MATCH($B13,ALIMENTOS_INTA!$E$8:$E$625,0)),""),"")) -> sin documentar | E13: 1 taza aprox. | F13: 150 | G13: =IF($B13="","",IF($K$7="","ND",IF(ISNUMBER((INDEX(ALIMENTOS_INTA!$D$8:$AO$625,(MATCH($B13,ALIMENTOS_INTA!$E$8:$E$625,0)),(MATCH($K$7,ALIMENTOS_INTA!$D$7:$AO$7,0))))),(INDEX(ALIMENTOS_INTA!$D$8:$AO$625,(MATCH($B13,ALIMENTOS_INTA!$E$8:$E$625,0)),(MATCH($K$7,ALIMENTOS_INTA!$D$7:$AO$7,0)))),"ND"))) -> 0.1 | H13: =IF(AND(ISNUMBER($G13),ISNUMBER($F13),$F13>=0),$G13*$F13/100,IF($B13="","",IF($G13="ND","ND",""))) -> 0.15 | I13: =$N$7 -> mg | J13: =IF(AND(ISNUMBER($H13),ISNUMBER($A$10),$A$10>0),$H13/$A$10*100,"ND") -> 1.875 | K13: =IF($B13="","",IF($G13="ND",1,0)) -> 0 | L13: =IF($B13="","SIN ALIMENTO",IF($G13="ND","ND FUENTE",IF(NOT(ISNUMBER($F13)),"FALTA GRAMAJE","DISPONIBLE"))) -> DISPONIBLE | M13: =IF($B13="","","SRC-NMX21") -> SRC-NMX21 | N13: =IF($B13="","",IF($G13="ND","El nutriente no está informado para este alimento.","Aporte = valor por 100 g × gramaje / 100.")) -> Aporte = valor por 100 g × gramaje / 100.
A14: 2 | B14: Higado de vacuno cocido | C14: =IF($B14="","",IFERROR(IFERROR(INDEX(ALIMENTOS_INTA!$F$8:$F$625,MATCH($B14,ALIMENTOS_INTA!$E$8:$E$625,0)),""),"")) -> Carnes y Vísceras | D14: =IF($B14="","",IFERROR(IFERROR(INDEX(ALIMENTOS_INTA!$G$8:$G$625,MATCH($B14,ALIMENTOS_INTA!$E$8:$E$625,0)),""),"")) -> sin documentar | E14: 1 porción | F14: 100 | G14: =IF($B14="","",IF($K$7="","ND",IF(ISNUMBER((INDEX(ALIMENTOS_INTA!$D$8:$AO$625,(MATCH($B14,ALIMENTOS_INTA!$E$8:$E$625,0)),(MATCH($K$7,ALIMENTOS_INTA!$D$7:$AO$7,0))))),(INDEX(ALIMENTOS_INTA!$D$8:$AO$625,(MATCH($B14,ALIMENTOS_INTA!$E$8:$E$625,0)),(MATCH($K$7,ALIMENTOS_INTA!$D$7:$AO$7,0)))),"ND"))) -> 5.3 | H14: =IF(AND(ISNUMBER($G14),ISNUMBER($F14),$F14>=0),$G14*$F14/100,IF($B14="","",IF($G14="ND","ND",""))) -> 5.3 | I14: =$N$7 -> mg | J14: =IF(AND(ISNUMBER($H14),ISNUMBER($A$10),$A$10>0),$H14/$A$10*100,"ND") -> 66.25 | K14: =IF($B14="","",IF($G14="ND",1,0)) -> 0 | L14: =IF($B14="","SIN ALIMENTO",IF($G14="ND","ND FUENTE",IF(NOT(ISNUMBER($F14)),"FALTA GRAMAJE","DISPONIBLE"))) -> DISPONIBLE | M14: =IF($B14="","","SRC-NMX21") -> SRC-NMX21 | N14: =IF($B14="","",IF($G14="ND","El nutriente no está informado para este alimento.","Aporte = valor por 100 g × gramaje / 100.")) -> Aporte = valor por 100 g × gramaje / 100.
A15: 3 | B15: Espinaca cocida | C15: =IF($B15="","",IFERROR(IFERROR(INDEX(ALIMENTOS_INTA!$F$8:$F$625,MATCH($B15,ALIMENTOS_INTA!$E$8:$E$625,0)),""),"")) -> Verduras y hortalizas | D15: =IF($B15="","",IFERROR(IFERROR(INDEX(ALIMENTOS_INTA!$G$8:$G$625,MATCH($B15,ALIMENTOS_INTA!$E$8:$E$625,0)),""),"")) -> sin documentar | E15: 1 porción | F15: 100 | G15: =IF($B15="","",IF($K$7="","ND",IF(ISNUMBER((INDEX(ALIMENTOS_INTA!$D$8:$AO$625,(MATCH($B15,ALIMENTOS_INTA!$E$8:$E$625,0)),(MATCH($K$7,ALIMENTOS_INTA!$D$7:$AO$7,0))))),(INDEX(ALIMENTOS_INTA!$D$8:$AO$625,(MATCH($B15,ALIMENTOS_INTA!$E$8:$E$625,0)),(MATCH($K$7,ALIMENTOS_INTA!$D$7:$AO$7,0)))),"ND"))) -> 0.8 | H15: =IF(AND(ISNUMBER($G15),ISNUMBER($F15),$F15>=0),$G15*$F15/100,IF($B15="","",IF($G15="ND","ND",""))) -> 0.8 | I15: =$N$7 -> mg | J15: =IF(AND(ISNUMBER($H15),ISNUMBER($A$10),$A$10>0),$H15/$A$10*100,"ND") -> 10 | K15: =IF($B15="","",IF($G15="ND",1,0)) -> 0 | L15: =IF($B15="","SIN ALIMENTO",IF($G15="ND","ND FUENTE",IF(NOT(ISNUMBER($F15)),"FALTA GRAMAJE","DISPONIBLE"))) -> DISPONIBLE | M15: =IF($B15="","","SRC-NMX21") -> SRC-NMX21 | N15: =IF($B15="","",IF($G15="ND","El nutriente no está informado para este alimento.","Aporte = valor por 100 g × gramaje / 100.")) -> Aporte = valor por 100 g × gramaje / 100.
A16: 4 | B16: Huevo entero cocido | C16: =IF($B16="","",IFERROR(IFERROR(INDEX(ALIMENTOS_INTA!$F$8:$F$625,MATCH($B16,ALIMENTOS_INTA!$E$8:$E$625,0)),""),"")) -> HUEVOS | D16: =IF($B16="","",IFERROR(IFERROR(INDEX(ALIMENTOS_INTA!$G$8:$G$625,MATCH($B16,ALIMENTOS_INTA!$E$8:$E$625,0)),""),"")) -> sin documentar | E16: 1 unidad mediana | F16: 50 | G16: =IF($B16="","",IF($K$7="","ND",IF(ISNUMBER((INDEX(ALIMENTOS_INTA!$D$8:$AO$625,(MATCH($B16,ALIMENTOS_INTA!$E$8:$E$625,0)),(MATCH($K$7,ALIMENTOS_INTA!$D$7:$AO$7,0))))),(INDEX(ALIMENTOS_INTA!$D$8:$AO$625,(MATCH($B16,ALIMENTOS_INTA!$E$8:$E$625,0)),(MATCH($K$7,ALIMENTOS_INTA!$D$7:$AO$7,0)))),"ND"))) -> ND | H16: =IF(AND(ISNUMBER($G16),ISNUMBER($F16),$F16>=0),$G16*$F16/100,IF($B16="","",IF($G16="ND","ND",""))) -> ND | I16: =$N$7 -> mg | J16: =IF(AND(ISNUMBER($H16),ISNUMBER($A$10),$A$10>0),$H16/$A$10*100,"ND") -> ND | K16: =IF($B16="","",IF($G16="ND",1,0)) -> 1 | L16: =IF($B16="","SIN ALIMENTO",IF($G16="ND","ND FUENTE",IF(NOT(ISNUMBER($F16)),"FALTA GRAMAJE","DISPONIBLE"))) -> ND FUENTE | M16: =IF($B16="","","SRC-NMX21") -> SRC-NMX21 | N16: =IF($B16="","",IF($G16="ND","El nutriente no está informado para este alimento.","Aporte = valor por 100 g × gramaje / 100.")) -> El nutriente no está informado para este alimento.
A17: 5 | B17: Yogurt natural | C17: =IF($B17="","",IFERROR(IFERROR(INDEX(ALIMENTOS_INTA!$F$8:$F$625,MATCH($B17,ALIMENTOS_INTA!$E$8:$E$625,0)),""),"")) -> Leche y derivados | D17: =IF($B17="","",IFERROR(IFERROR(INDEX(ALIMENTOS_INTA!$G$8:$G$625,MATCH($B17,ALIMENTOS_INTA!$E$8:$E$625,0)),""),"")) -> sin documentar | E17: 1 envase | F17: 170 | G17: =IF($B17="","",IF($K$7="","ND",IF(ISNUMBER((INDEX(ALIMENTOS_INTA!$D$8:$AO$625,(MATCH($B17,ALIMENTOS_INTA!$E$8:$E$625,0)),(MATCH($K$7,ALIMENTOS_INTA!$D$7:$AO$7,0))))),(INDEX(ALIMENTOS_INTA!$D$8:$AO$625,(MATCH($B17,ALIMENTOS_INTA!$E$8:$E$625,0)),(MATCH($K$7,ALIMENTOS_INTA!$D$7:$AO$7,0)))),"ND"))) -> 0.6 | H17: =IF(AND(ISNUMBER($G17),ISNUMBER($F17),$F17>=0),$G17*$F17/100,IF($B17="","",IF($G17="ND","ND",""))) -> 1.02 | I17: =$N$7 -> mg | J17: =IF(AND(ISNUMBER($H17),ISNUMBER($A$10),$A$10>0),$H17/$A$10*100,"ND") -> 12.75 | K17: =IF($B17="","",IF($G17="ND",1,0)) -> 0 | L17: =IF($B17="","SIN ALIMENTO",IF($G17="ND","ND FUENTE",IF(NOT(ISNUMBER($F17)),"FALTA GRAMAJE","DISPONIBLE"))) -> DISPONIBLE | M17: =IF($B17="","","SRC-NMX21") -> SRC-NMX21 | N17: =IF($B17="","",IF($G17="ND","El nutriente no está informado para este alimento.","Aporte = valor por 100 g × gramaje / 100.")) -> Aporte = valor por 100 g × gramaje / 100.
A18: 6 | B18: Leche fluida entera | C18: =IF($B18="","",IFERROR(IFERROR(INDEX(ALIMENTOS_INTA!$F$8:$F$625,MATCH($B18,ALIMENTOS_INTA!$E$8:$E$625,0)),""),"")) -> Leche y derivados | D18: =IF($B18="","",IFERROR(IFERROR(INDEX(ALIMENTOS_INTA!$G$8:$G$625,MATCH($B18,ALIMENTOS_INTA!$E$8:$E$625,0)),""),"")) -> sin documentar | F18: 100 | G18: =IF($B18="","",IF($K$7="","ND",IF(ISNUMBER((INDEX(ALIMENTOS_INTA!$D$8:$AO$625,(MATCH($B18,ALIMENTOS_INTA!$E$8:$E$625,0)),(MATCH($K$7,ALIMENTOS_INTA!$D$7:$AO$7,0))))),(INDEX(ALIMENTOS_INTA!$D$8:$AO$625,(MATCH($B18,ALIMENTOS_INTA!$E$8:$E$625,0)),(MATCH($K$7,ALIMENTOS_INTA!$D$7:$AO$7,0)))),"ND"))) -> 0.4 | H18: =IF(AND(ISNUMBER($G18),ISNUMBER($F18),$F18>=0),$G18*$F18/100,IF($B18="","",IF($G18="ND","ND",""))) -> 0.4 | I18: =$N$7 -> mg | J18: =IF(AND(ISNUMBER($H18),ISNUMBER($A$10),$A$10>0),$H18/$A$10*100,"ND") -> 5 | K18: =IF($B18="","",IF($G18="ND",1,0)) -> 0 | L18: =IF($B18="","SIN ALIMENTO",IF($G18="ND","ND FUENTE",IF(NOT(ISNUMBER($F18)),"FALTA GRAMAJE","DISPONIBLE"))) -> DISPONIBLE | M18: =IF($B18="","","SRC-NMX21") -> SRC-NMX21 | N18: =IF($B18="","",IF($G18="ND","El nutriente no está informado para este alimento.","Aporte = valor por 100 g × gramaje / 100.")) -> Aporte = valor por 100 g × gramaje / 100.
A19: 7 | B19: Leche de Burra | C19: =IF($B19="","",IFERROR(IFERROR(INDEX(ALIMENTOS_INTA!$F$8:$F$625,MATCH($B19,ALIMENTOS_INTA!$E$8:$E$625,0)),""),"")) -> Leche y derivados | D19: =IF($B19="","",IFERROR(IFERROR(INDEX(ALIMENTOS_INTA!$G$8:$G$625,MATCH($B19,ALIMENTOS_INTA!$E$8:$E$625,0)),""),"")) -> sin documentar | F19: 100 | G19: =IF($B19="","",IF($K$7="","ND",IF(ISNUMBER((INDEX(ALIMENTOS_INTA!$D$8:$AO$625,(MATCH($B19,ALIMENTOS_INTA!$E$8:$E$625,0)),(MATCH($K$7,ALIMENTOS_INTA!$D$7:$AO$7,0))))),(INDEX(ALIMENTOS_INTA!$D$8:$AO$625,(MATCH($B19,ALIMENTOS_INTA!$E$8:$E$625,0)),(MATCH($K$7,ALIMENTOS_INTA!$D$7:$AO$7,0)))),"ND"))) -> ND | H19: =IF(AND(ISNUMBER($G19),ISNUMBER($F19),$F19>=0),$G19*$F19/100,IF($B19="","",IF($G19="ND","ND",""))) -> ND | I19: =$N$7 -> mg | J19: =IF(AND(ISNUMBER($H19),ISNUMBER($A$10),$A$10>0),$H19/$A$10*100,"ND") -> ND | K19: =IF($B19="","",IF($G19="ND",1,0)) -> 1 | L19: =IF($B19="","SIN ALIMENTO",IF($G19="ND","ND FUENTE",IF(NOT(ISNUMBER($F19)),"FALTA GRAMAJE","DISPONIBLE"))) -> ND FUENTE | M19: =IF($B19="","","SRC-NMX21") -> SRC-NMX21 | N19: =IF($B19="","",IF($G19="ND","El nutriente no está informado para este alimento.","Aporte = valor por 100 g × gramaje / 100.")) -> El nutriente no está informado para este alimento.
A20: 8 | B20: Semillas de hinojo | C20: =IF($B20="","",IFERROR(IFERROR(INDEX(ALIMENTOS_INTA!$F$8:$F$625,MATCH($B20,ALIMENTOS_INTA!$E$8:$E$625,0)),""),"")) -> Especias | D20: =IF($B20="","",IFERROR(IFERROR(INDEX(ALIMENTOS_INTA!$G$8:$G$625,MATCH($B20,ALIMENTOS_INTA!$E$8:$E$625,0)),""),"")) -> sin documentar | F20: 100 | G20: =IF($B20="","",IF($K$7="","ND",IF(ISNUMBER((INDEX(ALIMENTOS_INTA!$D$8:$AO$625,(MATCH($B20,ALIMENTOS_INTA!$E$8:$E$625,0)),(MATCH($K$7,ALIMENTOS_INTA!$D$7:$AO$7,0))))),(INDEX(ALIMENTOS_INTA!$D$8:$AO$625,(MATCH($B20,ALIMENTOS_INTA!$E$8:$E$625,0)),(MATCH($K$7,ALIMENTOS_INTA!$D$7:$AO$7,0)))),"ND"))) -> 3.7 | H20: =IF(AND(ISNUMBER($G20),ISNUMBER($F20),$F20>=0),$G20*$F20/100,IF($B20="","",IF($G20="ND","ND",""))) -> 3.7 | I20: =$N$7 -> mg | J20: =IF(AND(ISNUMBER($H20),ISNUMBER($A$10),$A$10>0),$H20/$A$10*100,"ND") -> 46.25 | K20: =IF($B20="","",IF($G20="ND",1,0)) -> 0 | L20: =IF($B20="","SIN ALIMENTO",IF($G20="ND","ND FUENTE",IF(NOT(ISNUMBER($F20)),"FALTA GRAMAJE","DISPONIBLE"))) -> DISPONIBLE | M20: =IF($B20="","","SRC-NMX21") -> SRC-NMX21 | N20: =IF($B20="","",IF($G20="ND","El nutriente no está informado para este alimento.","Aporte = valor por 100 g × gramaje / 100.")) -> Aporte = valor por 100 g × gramaje / 100.
A21: 9 | B21: Leche evaporada | C21: =IF($B21="","",IFERROR(IFERROR(INDEX(ALIMENTOS_INTA!$F$8:$F$625,MATCH($B21,ALIMENTOS_INTA!$E$8:$E$625,0)),""),"")) -> Leche y derivados | D21: =IF($B21="","",IFERROR(IFERROR(INDEX(ALIMENTOS_INTA!$G$8:$G$625,MATCH($B21,ALIMENTOS_INTA!$E$8:$E$625,0)),""),"")) -> sin documentar | F21: 100 | G21: =IF($B21="","",IF($K$7="","ND",IF(ISNUMBER((INDEX(ALIMENTOS_INTA!$D$8:$AO$625,(MATCH($B21,ALIMENTOS_INTA!$E$8:$E$625,0)),(MATCH($K$7,ALIMENTOS_INTA!$D$7:$AO$7,0))))),(INDEX(ALIMENTOS_INTA!$D$8:$AO$625,(MATCH($B21,ALIMENTOS_INTA!$E$8:$E$625,0)),(MATCH($K$7,ALIMENTOS_INTA!$D$7:$AO$7,0)))),"ND"))) -> 0.8 | H21: =IF(AND(ISNUMBER($G21),ISNUMBER($F21),$F21>=0),$G21*$F21/100,IF($B21="","",IF($G21="ND","ND",""))) -> 0.8 | I21: =$N$7 -> mg | J21: =IF(AND(ISNUMBER($H21),ISNUMBER($A$10),$A$10>0),$H21/$A$10*100,"ND") -> 10 | K21: =IF($B21="","",IF($G21="ND",1,0)) -> 0 | L21: =IF($B21="","SIN ALIMENTO",IF($G21="ND","ND FUENTE",IF(NOT(ISNUMBER($F21)),"FALTA GRAMAJE","DISPONIBLE"))) -> DISPONIBLE | M21: =IF($B21="","","SRC-NMX21") -> SRC-NMX21 | N21: =IF($B21="","",IF($G21="ND","El nutriente no está informado para este alimento.","Aporte = valor por 100 g × gramaje / 100.")) -> Aporte = valor por 100 g × gramaje / 100.
A22: 10 | B22: Pan trigo | C22: =IF($B22="","",IFERROR(IFERROR(INDEX(ALIMENTOS_INTA!$F$8:$F$625,MATCH($B22,ALIMENTOS_INTA!$E$8:$E$625,0)),""),"")) -> cereales y derivados | D22: =IF($B22="","",IFERROR(IFERROR(INDEX(ALIMENTOS_INTA!$G$8:$G$625,MATCH($B22,ALIMENTOS_INTA!$E$8:$E$625,0)),""),"")) -> sin documentar | F22: 100 | G22: =IF($B22="","",IF($K$7="","ND",IF(ISNUMBER((INDEX(ALIMENTOS_INTA!$D$8:$AO$625,(MATCH($B22,ALIMENTOS_INTA!$E$8:$E$625,0)),(MATCH($K$7,ALIMENTOS_INTA!$D$7:$AO$7,0))))),(INDEX(ALIMENTOS_INTA!$D$8:$AO$625,(MATCH($B22,ALIMENTOS_INTA!$E$8:$E$625,0)),(MATCH($K$7,ALIMENTOS_INTA!$D$7:$AO$7,0)))),"ND"))) -> 1.2 | H22: =IF(AND(ISNUMBER($G22),ISNUMBER($F22),$F22>=0),$G22*$F22/100,IF($B22="","",IF($G22="ND","ND",""))) -> 1.2 | I22: =$N$7 -> mg | J22: =IF(AND(ISNUMBER($H22),ISNUMBER($A$10),$A$10>0),$H22/$A$10*100,"ND") -> 15 | K22: =IF($B22="","",IF($G22="ND",1,0)) -> 0 | L22: =IF($B22="","SIN ALIMENTO",IF($G22="ND","ND FUENTE",IF(NOT(ISNUMBER($F22)),"FALTA GRAMAJE","DISPONIBLE"))) -> DISPONIBLE | M22: =IF($B22="","","SRC-NMX21") -> SRC-NMX21 | N22: =IF($B22="","",IF($G22="ND","El nutriente no está informado para este alimento.","Aporte = valor por 100 g × gramaje / 100.")) -> Aporte = valor por 100 g × gramaje / 100.
A23: TOTAL | H23: =IF(COUNTA($B$13:$B$22)=0,"",SUM(H13:H22)) -> 13.37 | I23: =$N$7 -> mg | J23: =IF(AND(ISNUMBER(H23),ISNUMBER(A10),A10>0),H23/A10*100,"ND") -> 167.125 | K23: =SUM(K13:K22) -> 2 | L23: =IF(COUNTA($B$13:$B$22)=0,"SIN ALIMENTOS",IF(K23>0,"PARCIAL · "&K23&" ND","COMPLETO")) -> PARCIAL · 2 ND | M23: SRC-NMX21 | N23: El total conocido no convierte los datos s/i en cero.
A26: Rango | B26: Alimento | C26: Grupo | D26: Estado | E26: Valor/100 g | F26: Unidad
A27: 1 | B27: =IFERROR(IFERROR(INDEX(CALCULOS_NUTRIENTES!$AL$2:$AL$211,MATCH(1,INDEX((CALCULOS_NUTRIENTES!$AJ$2:$AJ$211=$G$7)*(CALCULOS_NUTRIENTES!$AK$2:$AK$211=$A27),0),0)),""),"") -> Tyrex 1 | C27: =IFERROR(IFERROR(INDEX(CALCULOS_NUTRIENTES!$AM$2:$AM$211,MATCH(1,INDEX((CALCULOS_NUTRIENTES!$AJ$2:$AJ$211=$G$7)*(CALCULOS_NUTRIENTES!$AK$2:$AK$211=$A27),0),0)),""),"") -> Alimentos con formulaciones Especiales | D27: =IFERROR(IFERROR(INDEX(CALCULOS_NUTRIENTES!$AN$2:$AN$211,MATCH(1,INDEX((CALCULOS_NUTRIENTES!$AJ$2:$AJ$211=$G$7)*(CALCULOS_NUTRIENTES!$AK$2:$AK$211=$A27),0),0)),""),"") -> sin documentar | E27: =IFERROR(IFERROR(INDEX(CALCULOS_NUTRIENTES!$AO$2:$AO$211,MATCH(1,INDEX((CALCULOS_NUTRIENTES!$AJ$2:$AJ$211=$G$7)*(CALCULOS_NUTRIENTES!$AK$2:$AK$211=$A27),0),0)),""),"") -> 85.4 | F27: =IFERROR(IFERROR(INDEX(CALCULOS_NUTRIENTES!$AP$2:$AP$211,MATCH(1,INDEX((CALCULOS_NUTRIENTES!$AJ$2:$AJ$211=$G$7)*(CALCULOS_NUTRIENTES!$AK$2:$AK$211=$A27),0),0)),""),"") -> mg
A28: 2 | B28: =IFERROR(IFERROR(INDEX(CALCULOS_NUTRIENTES!$AL$2:$AL$211,MATCH(1,INDEX((CALCULOS_NUTRIENTES!$AJ$2:$AJ$211=$G$7)*(CALCULOS_NUTRIENTES!$AK$2:$AK$211=$A28),0),0)),""),"") -> PKU2 Nutri Concentrated | C28: =IFERROR(IFERROR(INDEX(CALCULOS_NUTRIENTES!$AM$2:$AM$211,MATCH(1,INDEX((CALCULOS_NUTRIENTES!$AJ$2:$AJ$211=$G$7)*(CALCULOS_NUTRIENTES!$AK$2:$AK$211=$A28),0),0)),""),"") -> Alimentos con formulaciones Especiales | D28: =IFERROR(IFERROR(INDEX(CALCULOS_NUTRIENTES!$AN$2:$AN$211,MATCH(1,INDEX((CALCULOS_NUTRIENTES!$AJ$2:$AJ$211=$G$7)*(CALCULOS_NUTRIENTES!$AK$2:$AK$211=$A28),0),0)),""),"") -> sin documentar | E28: =IFERROR(IFERROR(INDEX(CALCULOS_NUTRIENTES!$AO$2:$AO$211,MATCH(1,INDEX((CALCULOS_NUTRIENTES!$AJ$2:$AJ$211=$G$7)*(CALCULOS_NUTRIENTES!$AK$2:$AK$211=$A28),0),0)),""),"") -> 30 | F28: =IFERROR(IFERROR(INDEX(CALCULOS_NUTRIENTES!$AP$2:$AP$211,MATCH(1,INDEX((CALCULOS_NUTRIENTES!$AJ$2:$AJ$211=$G$7)*(CALCULOS_NUTRIENTES!$AK$2:$AK$211=$A28),0),0)),""),"") -> mg
A29: 3 | B29: =IFERROR(IFERROR(INDEX(CALCULOS_NUTRIENTES!$AL$2:$AL$211,MATCH(1,INDEX((CALCULOS_NUTRIENTES!$AJ$2:$AJ$211=$G$7)*(CALCULOS_NUTRIENTES!$AK$2:$AK$211=$A29),0),0)),""),"") -> MSUD Med A Plus | C29: =IFERROR(IFERROR(INDEX(CALCULOS_NUTRIENTES!$AM$2:$AM$211,MATCH(1,INDEX((CALCULOS_NUTRIENTES!$AJ$2:$AJ$211=$G$7)*(CALCULOS_NUTRIENTES!$AK$2:$AK$211=$A29),0),0)),""),"") -> Alimentos con formulaciones Especiales | D29: =IFERROR(IFERROR(INDEX(CALCULOS_NUTRIENTES!$AN$2:$AN$211,MATCH(1,INDEX((CALCULOS_NUTRIENTES!$AJ$2:$AJ$211=$G$7)*(CALCULOS_NUTRIENTES!$AK$2:$AK$211=$A29),0),0)),""),"") -> sin documentar | E29: =IFERROR(IFERROR(INDEX(CALCULOS_NUTRIENTES!$AO$2:$AO$211,MATCH(1,INDEX((CALCULOS_NUTRIENTES!$AJ$2:$AJ$211=$G$7)*(CALCULOS_NUTRIENTES!$AK$2:$AK$211=$A29),0),0)),""),"") -> 25 | F29: =IFERROR(IFERROR(INDEX(CALCULOS_NUTRIENTES!$AP$2:$AP$211,MATCH(1,INDEX((CALCULOS_NUTRIENTES!$AJ$2:$AJ$211=$G$7)*(CALCULOS_NUTRIENTES!$AK$2:$AK$211=$A29),0),0)),""),"") -> mg
A30: 4 | B30: =IFERROR(IFERROR(INDEX(CALCULOS_NUTRIENTES!$AL$2:$AL$211,MATCH(1,INDEX((CALCULOS_NUTRIENTES!$AJ$2:$AJ$211=$G$7)*(CALCULOS_NUTRIENTES!$AK$2:$AK$211=$A30),0),0)),""),"") -> Ketonex 2 | C30: =IFERROR(IFERROR(INDEX(CALCULOS_NUTRIENTES!$AM$2:$AM$211,MATCH(1,INDEX((CALCULOS_NUTRIENTES!$AJ$2:$AJ$211=$G$7)*(CALCULOS_NUTRIENTES!$AK$2:$AK$211=$A30),0),0)),""),"") -> Alimentos con formulaciones Especiales | D30: =IFERROR(IFERROR(INDEX(CALCULOS_NUTRIENTES!$AN$2:$AN$211,MATCH(1,INDEX((CALCULOS_NUTRIENTES!$AJ$2:$AJ$211=$G$7)*(CALCULOS_NUTRIENTES!$AK$2:$AK$211=$A30),0),0)),""),"") -> sin documentar | E30: =IFERROR(IFERROR(INDEX(CALCULOS_NUTRIENTES!$AO$2:$AO$211,MATCH(1,INDEX((CALCULOS_NUTRIENTES!$AJ$2:$AJ$211=$G$7)*(CALCULOS_NUTRIENTES!$AK$2:$AK$211=$A30),0),0)),""),"") -> 23 | F30: =IFERROR(IFERROR(INDEX(CALCULOS_NUTRIENTES!$AP$2:$AP$211,MATCH(1,INDEX((CALCULOS_NUTRIENTES!$AJ$2:$AJ$211=$G$7)*(CALCULOS_NUTRIENTES!$AK$2:$AK$211=$A30),0),0)),""),"") -> mg
A31: 5 | B31: =IFERROR(IFERROR(INDEX(CALCULOS_NUTRIENTES!$AL$2:$AL$211,MATCH(1,INDEX((CALCULOS_NUTRIENTES!$AJ$2:$AJ$211=$G$7)*(CALCULOS_NUTRIENTES!$AK$2:$AK$211=$A31),0),0)),""),"") -> P-AM2 | C31: =IFERROR(IFERROR(INDEX(CALCULOS_NUTRIENTES!$AM$2:$AM$211,MATCH(1,INDEX((CALCULOS_NUTRIENTES!$AJ$2:$AJ$211=$G$7)*(CALCULOS_NUTRIENTES!$AK$2:$AK$211=$A31),0),0)),""),"") -> Alimentos con formulaciones Especiales | D31: =IFERROR(IFERROR(INDEX(CALCULOS_NUTRIENTES!$AN$2:$AN$211,MATCH(1,INDEX((CALCULOS_NUTRIENTES!$AJ$2:$AJ$211=$G$7)*(CALCULOS_NUTRIENTES!$AK$2:$AK$211=$A31),0),0)),""),"") -> sin documentar | E31: =IFERROR(IFERROR(INDEX(CALCULOS_NUTRIENTES!$AO$2:$AO$211,MATCH(1,INDEX((CALCULOS_NUTRIENTES!$AJ$2:$AJ$211=$G$7)*(CALCULOS_NUTRIENTES!$AK$2:$AK$211=$A31),0),0)),""),"") -> 21 | F31: =IFERROR(IFERROR(INDEX(CALCULOS_NUTRIENTES!$AP$2:$AP$211,MATCH(1,INDEX((CALCULOS_NUTRIENTES!$AJ$2:$AJ$211=$G$7)*(CALCULOS_NUTRIENTES!$AK$2:$AK$211=$A31),0),0)),""),"") -> mg
A32: 6 | B32: =IFERROR(IFERROR(INDEX(CALCULOS_NUTRIENTES!$AL$2:$AL$211,MATCH(1,INDEX((CALCULOS_NUTRIENTES!$AJ$2:$AJ$211=$G$7)*(CALCULOS_NUTRIENTES!$AK$2:$AK$211=$A32),0),0)),""),"") -> MSUD Med B Plus | C32: =IFERROR(IFERROR(INDEX(CALCULOS_NUTRIENTES!$AM$2:$AM$211,MATCH(1,INDEX((CALCULOS_NUTRIENTES!$AJ$2:$AJ$211=$G$7)*(CALCULOS_NUTRIENTES!$AK$2:$AK$211=$A32),0),0)),""),"") -> Alimentos con formulaciones Especiales | D32: =IFERROR(IFERROR(INDEX(CALCULOS_NUTRIENTES!$AN$2:$AN$211,MATCH(1,INDEX((CALCULOS_NUTRIENTES!$AJ$2:$AJ$211=$G$7)*(CALCULOS_NUTRIENTES!$AK$2:$AK$211=$A32),0),0)),""),"") -> sin documentar | E32: =IFERROR(IFERROR(INDEX(CALCULOS_NUTRIENTES!$AO$2:$AO$211,MATCH(1,INDEX((CALCULOS_NUTRIENTES!$AJ$2:$AJ$211=$G$7)*(CALCULOS_NUTRIENTES!$AK$2:$AK$211=$A32),0),0)),""),"") -> 19 | F32: =IFERROR(IFERROR(INDEX(CALCULOS_NUTRIENTES!$AP$2:$AP$211,MATCH(1,INDEX((CALCULOS_NUTRIENTES!$AJ$2:$AJ$211=$G$7)*(CALCULOS_NUTRIENTES!$AK$2:$AK$211=$A32),0),0)),""),"") -> mg
A33: 7 | B33: =IFERROR(IFERROR(INDEX(CALCULOS_NUTRIENTES!$AL$2:$AL$211,MATCH(1,INDEX((CALCULOS_NUTRIENTES!$AJ$2:$AJ$211=$G$7)*(CALCULOS_NUTRIENTES!$AK$2:$AK$211=$A33),0),0)),""),"") -> MSUD OAcMedB Plus | C33: =IFERROR(IFERROR(INDEX(CALCULOS_NUTRIENTES!$AM$2:$AM$211,MATCH(1,INDEX((CALCULOS_NUTRIENTES!$AJ$2:$AJ$211=$G$7)*(CALCULOS_NUTRIENTES!$AK$2:$AK$211=$A33),0),0)),""),"") -> Alimentos con formulaciones Especiales | D33: =IFERROR(IFERROR(INDEX(CALCULOS_NUTRIENTES!$AN$2:$AN$211,MATCH(1,INDEX((CALCULOS_NUTRIENTES!$AJ$2:$AJ$211=$G$7)*(CALCULOS_NUTRIENTES!$AK$2:$AK$211=$A33),0),0)),""),"") -> sin documentar | E33: =IFERROR(IFERROR(INDEX(CALCULOS_NUTRIENTES!$AO$2:$AO$211,MATCH(1,INDEX((CALCULOS_NUTRIENTES!$AJ$2:$AJ$211=$G$7)*(CALCULOS_NUTRIENTES!$AK$2:$AK$211=$A33),0),0)),""),"") -> 19 | F33: =IFERROR(IFERROR(INDEX(CALCULOS_NUTRIENTES!$AP$2:$AP$211,MATCH(1,INDEX((CALCULOS_NUTRIENTES!$AJ$2:$AJ$211=$G$7)*(CALCULOS_NUTRIENTES!$AK$2:$AK$211=$A33),0),0)),""),"") -> mg
A34: 8 | B34: =IFERROR(IFERROR(INDEX(CALCULOS_NUTRIENTES!$AL$2:$AL$211,MATCH(1,INDEX((CALCULOS_NUTRIENTES!$AJ$2:$AJ$211=$G$7)*(CALCULOS_NUTRIENTES!$AK$2:$AK$211=$A34),0),0)),""),"") -> Phenex 2 | C34: =IFERROR(IFERROR(INDEX(CALCULOS_NUTRIENTES!$AM$2:$AM$211,MATCH(1,INDEX((CALCULOS_NUTRIENTES!$AJ$2:$AJ$211=$G$7)*(CALCULOS_NUTRIENTES!$AK$2:$AK$211=$A34),0),0)),""),"") -> Alimentos con formulaciones Especiales | D34: =IFERROR(IFERROR(INDEX(CALCULOS_NUTRIENTES!$AN$2:$AN$211,MATCH(1,INDEX((CALCULOS_NUTRIENTES!$AJ$2:$AJ$211=$G$7)*(CALCULOS_NUTRIENTES!$AK$2:$AK$211=$A34),0),0)),""),"") -> sin documentar | E34: =IFERROR(IFERROR(INDEX(CALCULOS_NUTRIENTES!$AO$2:$AO$211,MATCH(1,INDEX((CALCULOS_NUTRIENTES!$AJ$2:$AJ$211=$G$7)*(CALCULOS_NUTRIENTES!$AK$2:$AK$211=$A34),0),0)),""),"") -> 19 | F34: =IFERROR(IFERROR(INDEX(CALCULOS_NUTRIENTES!$AP$2:$AP$211,MATCH(1,INDEX((CALCULOS_NUTRIENTES!$AJ$2:$AJ$211=$G$7)*(CALCULOS_NUTRIENTES!$AK$2:$AK$211=$A34),0),0)),""),"") -> mg
A35: 9 | B35: =IFERROR(IFERROR(INDEX(CALCULOS_NUTRIENTES!$AL$2:$AL$211,MATCH(1,INDEX((CALCULOS_NUTRIENTES!$AJ$2:$AJ$211=$G$7)*(CALCULOS_NUTRIENTES!$AK$2:$AK$211=$A35),0),0)),""),"") -> PKU Med B Plus | C35: =IFERROR(IFERROR(INDEX(CALCULOS_NUTRIENTES!$AM$2:$AM$211,MATCH(1,INDEX((CALCULOS_NUTRIENTES!$AJ$2:$AJ$211=$G$7)*(CALCULOS_NUTRIENTES!$AK$2:$AK$211=$A35),0),0)),""),"") -> Alimentos con formulaciones Especiales | D35: =IFERROR(IFERROR(INDEX(CALCULOS_NUTRIENTES!$AN$2:$AN$211,MATCH(1,INDEX((CALCULOS_NUTRIENTES!$AJ$2:$AJ$211=$G$7)*(CALCULOS_NUTRIENTES!$AK$2:$AK$211=$A35),0),0)),""),"") -> sin documentar | E35: =IFERROR(IFERROR(INDEX(CALCULOS_NUTRIENTES!$AO$2:$AO$211,MATCH(1,INDEX((CALCULOS_NUTRIENTES!$AJ$2:$AJ$211=$G$7)*(CALCULOS_NUTRIENTES!$AK$2:$AK$211=$A35),0),0)),""),"") -> 19 | F35: =IFERROR(IFERROR(INDEX(CALCULOS_NUTRIENTES!$AP$2:$AP$211,MATCH(1,INDEX((CALCULOS_NUTRIENTES!$AJ$2:$AJ$211=$G$7)*(CALCULOS_NUTRIENTES!$AK$2:$AK$211=$A35),0),0)),""),"") -> mg
A36: 10 | B36: =IFERROR(IFERROR(INDEX(CALCULOS_NUTRIENTES!$AL$2:$AL$211,MATCH(1,INDEX((CALCULOS_NUTRIENTES!$AJ$2:$AJ$211=$G$7)*(CALCULOS_NUTRIENTES!$AK$2:$AK$211=$A36),0),0)),""),"") -> Propimex 2 | C36: =IFERROR(IFERROR(INDEX(CALCULOS_NUTRIENTES!$AM$2:$AM$211,MATCH(1,INDEX((CALCULOS_NUTRIENTES!$AJ$2:$AJ$211=$G$7)*(CALCULOS_NUTRIENTES!$AK$2:$AK$211=$A36),0),0)),""),"") -> Alimentos con formulaciones Especiales | D36: =IFERROR(IFERROR(INDEX(CALCULOS_NUTRIENTES!$AN$2:$AN$211,MATCH(1,INDEX((CALCULOS_NUTRIENTES!$AJ$2:$AJ$211=$G$7)*(CALCULOS_NUTRIENTES!$AK$2:$AK$211=$A36),0),0)),""),"") -> sin documentar | E36: =IFERROR(IFERROR(INDEX(CALCULOS_NUTRIENTES!$AO$2:$AO$211,MATCH(1,INDEX((CALCULOS_NUTRIENTES!$AJ$2:$AJ$211=$G$7)*(CALCULOS_NUTRIENTES!$AK$2:$AK$211=$A36),0),0)),""),"") -> 18 | F36: =IFERROR(IFERROR(INDEX(CALCULOS_NUTRIENTES!$AP$2:$AP$211,MATCH(1,INDEX((CALCULOS_NUTRIENTES!$AJ$2:$AJ$211=$G$7)*(CALCULOS_NUTRIENTES!$AK$2:$AK$211=$A36),0),0)),""),"") -> mg
A39: El ranking se expresa por 100 g de porción comestible y no representa una porción recomendada. Las medidas domésticas son textos editables y no provienen de la tabla INTA. Cloruro y biotina permanecen como ND porque no están disponibles en la base alimentaria incorporada.

Sheet REQUERIMIENTOS
A1: NUTRIMETRÍA · NMX-43 | REQUERIMIENTOS
A3: Consulta automática de RDA/AI y UL/CDRR por edad, sexo y estado fisiológico.
A5: =HYPERLINK("#'INICIO'!A1","INICIO") -> INICIO | B5: =HYPERLINK("#'DATOS'!A1","DATOS") -> DATOS | C5: =HYPERLINK("#'ENERGÍA'!A1","ENERGÍA") -> ENERGÍA | D5: =HYPERLINK("#'MACRONUTRIENTES'!A1","MACRONUTRIENTES") -> MACRONUTRIENTES | E5: =HYPERLINK("#'AGUA_FIBRA'!A1","AGUA/FIBRA") -> AGUA/FIBRA | F5: =HYPERLINK("#'FICHA_NUTRIENTE'!A1","FICHA/NUTRIENTE") -> FICHA/NUTRIENTE | G5: =HYPERLINK("#'RESULTADOS'!A1","RESULTADOS") -> RESULTADOS | H5: =HYPERLINK("#'DOCUMENTACIÓN'!A1","DOCUMENTACIÓN") -> DOCUMENTACIÓN | I5: =HYPERLINK("#'COBERTURA'!A1","COBERTURA") -> COBERTURA | J5: =HYPERLINK("#'AUDITORÍA_FINAL'!A1","AUDITORÍA") -> AUDITORÍA
A7: NUTRIENTE | C7: Zinc | E7: ID | G7: =IFERROR(IFERROR(INDEX(NUTRIENTES!$A$8:$A$30,MATCH($C$7,NUTRIENTES!$B$8:$B$30,0)),""),"") -> MIN-ZN
A8: Use la flecha de la celda amarilla para seleccionar el nutriente.
A9: EDAD | C9: SEXO | E9: ESTADO | G9: GRUPO RESUELTO
A10: =DATOS!F9 -> 25 | C10: =DATOS!B13 -> Femenino | E10: =DATOS!B16 -> Ninguno | G10: =IFERROR(IFERROR(INDEX(DRI_BASE!$C$2:$C$469&" · "&DRI_BASE!$D$2:$D$469&"–"&DRI_BASE!$E$2:$E$469&" años",MATCH(1,INDEX((DRI_BASE!$B$2:$B$469=$G$7)*(DRI_BASE!$D$2:$D$469<=DATOS!$F$9)*(DRI_BASE!$E$2:$E$469>DATOS!$F$9)*(((DRI_BASE!$C$2:$C$469=DATOS!$B$13)+(DRI_BASE!$C$2:$C$469="Ambos"))>0)*(DRI_BASE!$G$2:$G$469=DATOS!$B$16),0),0)),"ND"),"ND") -> Femenino · 19–31 años
A12: OBJETIVO | C12: TIPO | E12: LÍMITE | G12: TIPO LÍMITE | I12: UNIDAD | K12: FUENTE
