Workbook
Name AM_C1: CONFIG!$B$49
Name AM_C2: CONFIG!$B$50
Name AM_C3: CONFIG!$B$51
Name BRO_A: CONFIG!$B$31
Name BRO_B: CONFIG!$B$32
Name c_ampl: CALCULOS!$B$30
Name c_ClaseGrasa: CALCULOS!$B$48
Name c_ClaseIMC: CALCULOS!$B$47
Name c_Dens: CALCULOS!$B$18
Name c_DWc: CALCULOS!$B$16
Name c_DWm: CALCULOS!$B$17
Name c_estado: CALCULOS!$B$31
Name c_Gate: CALCULOS!$B$13
Name c_GrDeu: CALCULOS!$B$21
Name c_GrNavy: CALCULOS!$B$20
Name c_GrPli: CALCULOS!$B$19
Name c_GrRep: CALCULOS!$B$24
Name c_ICC: CALCULOS!$B$40
Name c_ICE: CALCULOS!$B$41
Name c_IMC: CALCULOS!$B$9
Name c_IMG: CALCULOS!$B$36
Name c_IMLG: CALCULOS!$B$37
Name c_max: CALCULOS!$B$28
Name c_MG: CALCULOS!$B$34
Name c_min: CALCULOS!$B$27
Name c_MLG: CALCULOS!$B$35
Name c_n: CALCULOS!$B$25
Name c_prom: CALCULOS!$B$26
Name c_rango: CALCULOS!$B$29
Name c_RiesgoCint: CALCULOS!$B$42
Name c_RiesgoICC: CALCULOS!$B$43
Name c_RiesgoICE: CALCULOS!$B$44
Name c_SumPli: CALCULOS!$B$10
Name c_TallaM: CALCULOS!$B$8
Name CAD_MAX: CONFIG!$B$23
Name CAD_MIN: CONFIG!$B$22
Name CIN_MAX: CONFIG!$B$21
Name CIN_MIN: CONFIG!$B$20
Name CINT_H: CONFIG!$B$52
Name CINT_M: CONFIG!$B$53
Name CUE_MAX: CONFIG!$B$19
Name CUE_MIN: CONFIG!$B$18
Name DEU_CONST: CONFIG!$B$42
Name DEU_EDAD: CONFIG!$B$40
Name DEU_IMC: CONFIG!$B$39
Name DEU_SEXO: CONFIG!$B$41
Name DISP_MAX: CONFIG!$B$26
Name EDAD_AM: CONFIG!$B$48
Name EDAD_MAX: CONFIG!$B$11
Name EDAD_MIN: CONFIG!$B$10
Name EST_MAX: CONFIG!$B$15
Name EST_MIN: CONFIG!$B$14
Name GRASA_MAX: CONFIG!$B$25
Name GRASA_MIN: CONFIG!$B$24
Name ICC_H: CONFIG!$B$54
Name ICC_M: CONFIG!$B$55
Name ICE_R: CONFIG!$B$56
Name IMC_C1: CONFIG!$B$43
Name IMC_C2: CONFIG!$B$44
Name IMC_C3: CONFIG!$B$45

Sheet INICIO
A1: NUTRIMETRÍA · NMX-12
A2: Calculadora de grasa y composición corporal · versión 1.0
A4: Navegación — use las pestañas inferiores del libro
A5: =HYPERLINK("#DATOS!A1","▶ DATOS") -> ▶ DATOS | B5: =HYPERLINK("#CALCULOS!A1","▶ CALCULOS") -> ▶ CALCULOS | D5: =HYPERLINK("#RESULTADOS!A1","▶ RESULTADOS") -> ▶ RESULTADOS | F5: =HYPERLINK("#FUENTES!A1","▶ FUENTES") -> ▶ FUENTES | H5: =HYPERLINK("#PRUEBAS!A1","▶ PRUEBAS") -> ▶ PRUEBAS | J5: =HYPERLINK("#CONFIG!A1","▶ CONFIG") -> ▶ CONFIG | L5: =HYPERLINK("#CHANGELOG!A1","▶ CHANGELOG") -> ▶ CHANGELOG
A6: Ingresar datos | B6: Auditar operaciones | D6: Ver resumen | F6: Trazabilidad | H6: Control de calidad | J6: Constantes | L6: Historial
A7: Código del producto | C7: NMX-12
A8: Versión | C8: 1.0
A9: Fecha | C9: 2026-07-14
A10: Localización | C10: Chile (es-CL) · clasificación anclada a MINSAL y OMS
A11: Formato | C11: .xlsx sin macros · Microsoft 365 y Excel 2021
A12: Responsable | C12: Equipo Nutrimetría (completar por el titular)
A13: AVISO DE ALCANCE — LÉALO ANTES DE USAR
A14: EXACTITUD MATEMÁTICA ≠ VALIDACIÓN CLÍNICA. Este archivo NO está validado clínicamente.
A15: APLICA A: personas ADULTAS (≥18 años) en condición estable.
A16: NO APLICA A: embarazo · lactancia · menores de edad · pacientes críticos · atletas de élite (subestima/sobrestima).
A17: Los métodos ESTIMAN la composición; la referencia son DEXA o pesaje hidrostático.
A18: La clasificación de IMC y cintura usa cortes del MINSAL/OMS. Los rangos de % de grasa (ACE) son REFERENCIALES.
A19: La antropometría depende de la técnica del evaluador: pliegues y circunferencias mal tomados invalidan el resultado.
A20: PROPÓSITO Y ALCANCE
A21: Propósito | C21: Proveer una herramienta de cálculo automatizado que permita estimar la composición corporal (porcentaje de grasa y masa libre de grasa) a partir de mediciones de pliegues cutáneos y circunferencias, sirviendo como apoyo práctico para el diagnóstico y la planificación alimentaria.
A22: Población | C22: Personas adultas (≥18 años) en condición estable. No aplica a embarazo, lactancia, menores de edad, pacientes críticos ni atletas de élite.
A23: Uso | C23: Los métodos ESTIMAN la composición corporal; la referencia son DEXA o pesaje hidrostático.
A24: Compatibilidad | C24: .xlsx sin macros · Microsoft 365 y Excel 2021
A25: Privacidad | C25: Los datos permanecen en el archivo local. El libro no transmite información.
A26: CÓMO SE MODELA
A27: Método 1 (pliegues): densidad = c − m·log10(Σ4 pliegues) → % grasa por Siri (495/D−450) o Brožek (457/D−414).
A28: Método 2 (circunferencias): fórmula US Navy con cuello, cintura, estatura (y cadera en mujeres).
A29: Método 3 (IMC): Deurenberg = 1,20·IMC + 0,23·edad − 10,8·sexo − 5,4.
A30: Composición: MG = %grasa×peso · MLG = peso − MG · IMG = MG/talla² · IMLG = MLG/talla².
A31: Distribución: ICC = cintura/cadera · ICE = cintura/estatura, con cortes de riesgo MINSAL/OMS.

Sheet DATOS
A1: NUTRIMETRÍA · NMX-12
A2: Datos de entrada · variables ingresadas por el usuario
A3: =HYPERLINK("#INICIO!A1","◀ INICIO") -> ◀ INICIO | B3: =HYPERLINK("#CALCULOS!A1","▶ CALCULOS") -> ▶ CALCULOS | D3: =HYPERLINK("#RESULTADOS!A1","▶ RESULTADOS") -> ▶ RESULTADOS
A4: LEYENDA · Celdas ARENA con texto AZUL = editables. Grises = calculadas. (opcional) = puede quedar vacía.
A5: ► Viene cargado un CASO DE EJEMPLO realista. Reemplace los valores por los de su paciente.
A6: Campo | B6: Valor | C6: Unidad | D6: Validación | E6: Ayuda
A7: Identificador de la evaluación | B7: NMX-2026-0012 | C7: — | D7: Texto libre | E7: Código interno de la evaluación.
A8: Fecha | B8: 46217 | C8: fecha | D8: Fecha | E8: dd/mm/aaaa.
A9: Nombre o código del paciente | B9: PAC-0058 | C9: — | D9: Texto libre | E9: Prefiera un CÓDIGO si va a compartir el archivo.
A10: Sexo biológico | B10: Hombre | C10: — | D10: Lista: Hombre / Mujer | E10: Las ecuaciones se derivaron por sexo biológico.
A11: Edad | B11: 34 | C11: años | D11: ≥18 y ≤120 | E11: Solo adultos.
A12: Peso | B12: 80 | C12: kg | D12: Entre 25 y 350 | E12: Balanza calibrada, ropa ligera.
A13: Estatura | B13: 180 | C13: cm | D13: Entre 120 y 230 | E13: De pie, sin zapatos.
A14: Método de % de grasa a reportar | B14: 1 · Pliegues (Durnin–Womersley 1974) | C14: — | D14: Lista (CONFIG C3) | E14: Los tres métodos se calculan; este define cuál se destaca.
A15: Conversión densidad→grasa | B15: Siri (1961) | C15: — | D15: Lista (CONFIG C4) | E15: Solo afecta al método de pliegues.
A16: Pliegue bíceps | B16: 6 | C16: mm | D16: Entre 1 y 80 | E16: Pliegue vertical, cara anterior del brazo.
A17: Pliegue tríceps | B17: 10 | C17: mm | D17: Entre 1 y 80 | E17: Pliegue vertical, cara posterior del brazo.
A18: Pliegue subescapular | B18: 14 | C18: mm | D18: Entre 1 y 80 | E18: Pliegue oblicuo bajo el ángulo de la escápula.
A19: Pliegue suprailíaco | B19: 16 | C19: mm | D19: Entre 1 y 80 | E19: Pliegue sobre la cresta ilíaca.
A20: Circunferencia de cuello | B20: 38 | C20: cm | D20: Entre 20 y 70 | E20: Bajo la laringe. Necesaria para el método de circunferencias.
A21: Circunferencia de cintura | B21: 88 | C21: cm | D21: Entre 40 y 200 | E21: En el punto medio entre última costilla y cresta ilíaca.
A22: Circunferencia de cadera | B22: 100 | C22: cm | D22: Entre 50 y 200 | E22: En la máxima prominencia glútea. Necesaria en mujeres (Navy) e ICC.
A23: Observaciones | C23: — | D23: Texto libre | E23: Contexto clínico, criterios, calidad de la medición.
A25: ► Los tres métodos se comparan en RESULTADOS. Si discrepan mucho, el libro lo advierte.

Sheet CALCULOS
A1: NUTRIMETRÍA · NMX-12
A2: Motor de cálculo · densidad, % de grasa por tres métodos y composición
A3: ◀ DATOS | C3: ▶ RESULTADOS
A4: Cada celda calculada declara su fórmula. Las guardas devuelven texto 'ND: …' en vez de errores de Excel, de modo que un dato ausente no rompe la cadena.
A6: BLOQUE 0 · BASE
A7: Variable | B7: Valor | C7: Unidad | D7: Fórmula / cómo se obtiene
A8: Estatura en metros | B8: =IF(ISNUMBER(in_Est),in_Est/100,"ND: estatura") -> 1.8 | C8: m | D8: in_Est/100
A9: IMC | B9: =IF(AND(ISNUMBER(in_Peso),ISNUMBER(in_Est),in_Est>0),in_Peso/(in_Est/100)^2,"ND: faltan peso o estatura") -> 24.691358 | C9: kg/m² | D9: peso/estatura²
A10: Σ de los 4 pliegues | B10: =IF(AND(ISNUMBER(in_PliBi),ISNUMBER(in_PliTri),ISNUMBER(in_PliSub),ISNUMBER(in_PliSupra),in_PliBi>0,in_PliTri>0,in_PliSub>0,in_PliSupra>0),in_PliBi+in_PliTri+in_PliSub+in_PliSupra,"ND: faltan pliegues") -> 46 | C10: mm | D10: bíceps+tríceps+subescapular+suprailíaco
A11: BLOQUE 1 · COMPUERTA DE DATOS IMPOSIBLES
A12: Variable | B12: Valor | C12: Unidad | D12: Fórmula / cómo se obtiene
A13: ¿Cálculo habilitado? | B13: =IF(AND(COUNTIF(SEXOS,in_Sexo)>0,ISNUMBER(in_Edad),in_Edad>=EDAD_MIN,in_Edad<=EDAD_MAX,ISNUMBER(in_Peso),in_Peso>=PESO_MIN,in_Peso<=PESO_MAX,ISNUMBER(in_Est),in_Est>=EST_MIN,in_Est<=EST_MAX),"SÍ","NO") -> SÍ | C13: — | D13: Exige sexo, edad adulta, peso y estatura válidos
A14: BLOQUE 2 · % DE GRASA POR TRES MÉTODOS (fracción)
A15: Variable | B15: Valor | C15: Unidad | D15: Fórmula / cómo se obtiene
A16: Durnin–Womersley · c | B16: =IF(AND(c_Gate="SÍ",ISNUMBER(c_SumPli)),SUMPRODUCT((CONFIG!$A$80:$A$89=in_Sexo)*(CONFIG!$B$80:$B$89<=in_Edad)*(CONFIG!$C$80:$C$89>in_Edad)*CONFIG!$D$80:$D$89),"ND") -> 1.1422 | C16: — | D16: Coeficiente c por sexo y banda etaria
A17: Durnin–Womersley · m | B17: =IF(AND(c_Gate="SÍ",ISNUMBER(c_SumPli)),SUMPRODUCT((CONFIG!$A$80:$A$89=in_Sexo)*(CONFIG!$B$80:$B$89<=in_Edad)*(CONFIG!$C$80:$C$89>in_Edad)*CONFIG!$E$80:$E$89),"ND") -> 0.0544 | C17: — | D17: Coeficiente m por sexo y banda etaria
A18: Densidad corporal (pliegues) | B18: =IF(AND(ISNUMBER(c_DWc),ISNUMBER(c_DWm),ISNUMBER(c_SumPli)),c_DWc-c_DWm*LOG10(c_SumPli),"ND") -> 1.051746 | C18: g/mL | D18: c − m·log10(Σ4)
A19: Método 1 · % grasa (pliegues) | B19: =IF(ISNUMBER(c_Dens),IF(in_Conv="Brožek (1963)",(BRO_A/c_Dens-BRO_B)/100,(SIRI_A/c_Dens-SIRI_B)/100),"ND") -> 0.20645966 | C19: % | D19: Siri o Brožek sobre la densidad
A20: Método 2 · % grasa (US Navy) | B20: =IF(AND(c_Gate="SÍ",ISNUMBER(in_Cuello),ISNUMBER(in_Cintura),IF(in_Sexo="Mujer",ISNUMBER(in_Cadera),TRUE())),IF(in_Sexo="Hombre",IF((in_Cintura-in_Cuello)>0,(SIRI_A/(NAVY_H0-NAVY_H1*LOG10(in_Cintura-in_Cuello)+NAVY_H2*LOG10(in_Est))-SIRI_B)/100,"ND: cintura≤cuello"),IF((in_Cintura+in_Cadera-in_Cuello)>0,(SIRI_A/(NAVY_M0-NAVY_M1*LOG10(in_Cintura+in_Cadera-in_Cuello)+NAVY_M2*LOG10(in_Est))-SIRI_B)/100,"ND")),"ND: faltan circunferencias") -> 0.18367495 | C20: % | D20: Circunferencias (cm) con log10
A21: Método 3 · % grasa (Deurenberg) | B21: =IF(AND(c_Gate="SÍ",ISNUMBER(c_IMC)),(DEU_IMC*c_IMC+DEU_EDAD*in_Edad-DEU_SEXO*IF(in_Sexo="Hombre",1,0)-DEU_CONST)/100,"ND") -> 0.2124963 | C21: % | D21: 1,20·IMC+0,23·edad−10,8·sexo−5,4
A22: BLOQUE 3 · RECONCILIACIÓN DE LOS MÉTODOS
A23: Variable | B23: Valor | C23: Unidad | D23: Fórmula / cómo se obtiene
A24: % grasa REPORTADO | B24: =CHOOSE(MATCH(in_Metodo,LISTA_MET,0),c_GrPli,c_GrNavy,c_GrDeu) -> 0.20645966 | C24: % | D24: Método elegido en DATOS
A25: Métodos con dato (n) | B25: =COUNT(c_GrPli,c_GrNavy,c_GrDeu) -> 3 | C25: — | D25: Cuántos métodos entregaron número
A26: Promedio de los métodos | B26: =IF(c_n>0,AVERAGE(c_GrPli,c_GrNavy,c_GrDeu),"ND") -> 0.20087697 | C26: % | D26: AVERAGE ignora los ND
A27: Mínimo | B27: =IF(c_n>0,MIN(c_GrPli,c_GrNavy,c_GrDeu),"ND") -> 0.18367495 | C27: %
A28: Máximo | B28: =IF(c_n>0,MAX(c_GrPli,c_GrNavy,c_GrDeu),"ND") -> 0.2124963 | C28: %
A29: Rango (máx − mín) | B29: =IF(AND(ISNUMBER(c_min),ISNUMBER(c_max)),c_max-c_min,"ND") -> 0.028821345 | C29: %
A30: Amplitud relativa | B30: =IF(AND(ISNUMBER(c_rango),ISNUMBER(c_prom),c_prom>0),c_rango/c_prom,"ND") -> 0.1434776 | C30: — | D30: rango/promedio
A31: Estado de concordancia | B31: =IF(ISNUMBER(c_ampl),IF(c_ampl<=DISP_MAX,"OK: los métodos disponibles concuerdan dentro del umbral.","ATENCIÓN: los métodos discrepan más que el umbral configurado."),"ND") -> OK: los métodos disponibles concuerdan dentro del umbral. | C31: — | D31: Compara la amplitud con DISP_MAX
A32: BLOQUE 4 · COMPOSICIÓN CORPORAL (según el método reportado)
A33: Variable | B33: Valor | C33: Unidad | D33: Fórmula / cómo se obtiene
A34: Masa grasa (MG) | B34: =IF(AND(ISNUMBER(c_GrRep),ISNUMBER(in_Peso)),c_GrRep*in_Peso,"ND") -> 16.516773 | C34: kg | D34: % grasa × peso
A35: Masa libre de grasa (MLG) | B35: =IF(AND(ISNUMBER(c_MG),ISNUMBER(in_Peso)),in_Peso-c_MG,"ND") -> 63.483227 | C35: kg | D35: peso − MG
A36: Índice de masa grasa (IMG) | B36: =IF(AND(ISNUMBER(c_MG),ISNUMBER(c_TallaM),c_TallaM>0),c_MG/c_TallaM^2,"ND") -> 5.0977694 | C36: kg/m² | D36: MG / estatura²
A37: Índice de masa libre de grasa (IMLG) | B37: =IF(AND(ISNUMBER(c_MLG),ISNUMBER(c_TallaM),c_TallaM>0),c_MLG/c_TallaM^2,"ND") -> 19.593589 | C37: kg/m² | D37: MLG / estatura²
A38: BLOQUE 5 · DISTRIBUCIÓN Y RIESGO CARDIOMETABÓLICO
A39: Variable | B39: Valor | C39: Unidad | D39: Fórmula / cómo se obtiene
A40: Índice cintura/cadera (ICC) | B40: =IF(AND(ISNUMBER(in_Cintura),ISNUMBER(in_Cadera),in_Cadera>0),in_Cintura/in_Cadera,"ND") -> 0.88 | C40: — | D40: cintura/cadera
A41: Índice cintura/estatura (ICE) | B41: =IF(AND(ISNUMBER(in_Cintura),ISNUMBER(in_Est),in_Est>0),in_Cintura/in_Est,"ND") -> 0.48888889 | C41: — | D41: cintura/estatura
...

Sheet RESULTADOS
A1: NUTRIMETRÍA · NMX-12
A2: Informe de grasa y composición corporal
A3: =HYPERLINK("#DATOS!A1","◀ DATOS") -> ◀ DATOS | B3: =HYPERLINK("#CALCULOS!A1","◀ CALCULOS") -> ◀ CALCULOS | E3: =HYPERLINK("#FUENTES!A1","▶ FUENTES") -> ▶ FUENTES
A4: IDENTIFICACIÓN
A6: Identificador | B6: =in_ID -> NMX-2026-0012
A7: Fecha | B7: =in_Fecha -> 46217
A8: Paciente | B8: =in_Pac -> PAC-0058
A9: Sexo · edad | B9: =in_Sexo&" · "&IF(ISNUMBER(in_Edad),in_Edad&" años","(edad no válida)") -> Hombre · 34 años
A10: Peso · estatura | B10: =IF(ISNUMBER(in_Peso),ROUND(in_Peso,1)&" kg","(?)")&" · "&IF(ISNUMBER(in_Est),ROUND(in_Est,1)&" cm","(?)") -> 80 kg · 180 cm
A11: Método reportado | B11: =in_Metodo -> 1 · Pliegues (Durnin–Womersley 1974)
A12: Estado del cálculo | B12: =IF(c_Gate="SÍ","HABILITADO","BLOQUEADO — corrija los datos imposibles") -> HABILITADO
A13: Observaciones | B13: =IF(in_Obs="","—",in_Obs) -> —
A14: % DE GRASA POR LOS TRES MÉTODOS
A16: Método | B16: % de grasa | C16: ¿Disponible? | D16: Fuente
A17: 1 · Pliegues (Durnin–Womersley → Siri/Brožek) | B17: =c_GrPli -> 0.20645966 | C17: =IF(ISNUMBER(c_GrPli),"Sí","No") -> Sí | D17: Durnin–Womersley 1974
A18: 2 · Circunferencias (US Navy) | B18: =c_GrNavy -> 0.18367495 | C18: =IF(ISNUMBER(c_GrNavy),"Sí","No") -> Sí | D18: Hodgdon–Beckett 1984
A19: 3 · IMC (Deurenberg) | B19: =c_GrDeu -> 0.2124963 | C19: =IF(ISNUMBER(c_GrDeu),"Sí","No") -> Sí | D19: Deurenberg 1991
A20: MÉTODO REPORTADO | B20: =c_GrRep -> 0.20645966 | C20: =in_Metodo -> 1 · Pliegues (Durnin–Womersley 1974)
A21: CONCORDANCIA ENTRE MÉTODOS
A23: Promedio | B23: =c_prom -> 0.20087697
A24: Rango (máx − mín) | B24: =c_rango -> 0.028821345
A25: Amplitud relativa | B25: =c_ampl -> 0.1434776
A26: =c_estado -> OK: los métodos disponibles concuerdan dentro del umbral.
A27: COMPOSICIÓN CORPORAL (según el método reportado)
A29: % de grasa reportado | B29: =c_GrRep -> 0.20645966
A30: Masa grasa (MG) | B30: =c_MG -> 16.516773 | C30: kg
A31: Masa libre de grasa (MLG) | B31: =c_MLG -> 63.483227 | C31: kg
A32: Índice de masa grasa (IMG) | B32: =c_IMG -> 5.0977694 | C32: kg/m²
A33: Índice de masa libre de grasa (IMLG) | B33: =c_IMLG -> 19.593589 | C33: kg/m²
A34: IMC | B34: =c_IMC -> 24.691358 | C34: kg/m²
A35: Clasificación por IMC | B35: =c_ClaseIMC -> Normal (OMS)
A36: Clasificación por % grasa (ACE, referencial) | B36: =c_ClaseGrasa -> Aceptable
A37: DISTRIBUCIÓN Y RIESGO CARDIOMETABÓLICO
A39: Indicador | B39: Valor | C39: Clasificación | D39: Corte aplicado
A40: Circunferencia de cintura | B40: =IF(ISNUMBER(in_Cintura),in_Cintura,"ND") -> 88 | C40: =c_RiesgoCint -> Sin riesgo aumentado | E40: =IF(in_Sexo="Hombre","≥102 cm (H)","≥88 cm (M)") -> ≥102 cm (H)
A41: Índice cintura/cadera (ICC) | B41: =c_ICC -> 0.88 | C41: =c_RiesgoICC -> Sin riesgo aumentado | E41: =IF(in_Sexo="Hombre","≥0,90 (H)","≥0,85 (M)") -> ≥0,90 (H)
A42: Índice cintura/estatura (ICE) | B42: =c_ICE -> 0.48888889 | C42: =c_RiesgoICE -> Sin riesgo aumentado | E42: ≥0,50
A43: DATOS DE APOYO PARA LOS GRÁFICOS
A45: Método | B45: % de grasa
A46: 1 · Pliegues | B46: =IF(ISNUMBER(c_GrPli),c_GrPli,0) -> 0.20645966
...

Sheet FUENTES
A1: NUTRIMETRÍA · NMX-12
A2: Trazabilidad · anclaje regional a Chile (INTA U. de Chile y MINSAL)
A3: LOCALIZACIÓN: por indicación, se ELIMINARON las fuentes de USDA (FoodData Central) y del Instituto Nacional de Salud del Perú. El anclaje poblacional y de clasificación es EXCLUSIVAMENTE chileno: INTA (Universidad de Chile) y MINSAL, con la OMS como referencia adoptada por el propio MINSAL. NIVEL A = documento oficial o publicación primaria · B = resumen primario / corroboración por pares · C = fuente secundaria. EXACTITUD ≠ VALIDACIÓN CLÍNICA.
A4: =HYPERLINK("#INICIO!A1","◀ INICIO") -> ◀ INICIO | B4: =HYPERLINK("#DATOS!A1","◀ DATOS") -> ◀ DATOS | C4: =HYPERLINK("#CALCULOS!A1","◀ CALCULOS") -> ◀ CALCULOS
A5: Ecuación o dato | B5: Autor u organización | C5: Año | D5: Población de derivación | E5: Fórmula / valor | F5: Unidades | G5: Limitaciones | H5: DOI o fuente | I5: Fecha cotejo | J5: Licencia / condiciones | K5: Nivel
A6: Densidad por 4 pliegues | B6: Durnin JVGA, Womersley J — Br J Nutr 32(1):77-97 | C6: 1974 | D6: 481 personas (209 H, 272 M), 16–72 años; pesaje hidrostático | E6: D = c − m·log10(Σ bíceps+tríceps+subescapular+suprailíaco) | F6: g/mL; pliegues mm | G6: Muestra británica; ecuación general. Depende de la técnica del evaluador. | H6: 10.1079/bjn19740060 | I6: 2026-07-16 | J6: Artículo con derechos de autor; solo se usan los coeficientes (hecho no protegible). | K6: B
A7: Densidad → % grasa · Siri | B7: Siri WE — en Techniques for Measuring Body Composition (NAS-NRC) | C7: 1961 | D7: Modelo de dos compartimentos (grasa / libre de grasa) | E7: %grasa = 495/D − 450 | F7: % ; D g/mL | G7: Asume densidades fijas de los compartimentos; menos válida en extremos de composición. | H7: Siri 1961 (NAS-NRC) | I7: 2026-07-16 | J7: Obra clásica; solo se usa la ecuación. | K7: B
A8: Densidad → % grasa · Brožek | B8: Brožek J et al. — Ann N Y Acad Sci 110:113-140 | C8: 1963 | D8: Modelo del cuerpo de referencia | E8: %grasa = 457/D − 414 | F8: % ; D g/mL | G8: Alternativa a Siri; difiere levemente en los extremos. | H8: 10.1111/j.1749-6632.1963.tb17079.x | I8: 2026-07-16 | J8: Artículo con derechos de autor; solo se usa la ecuación. | K8: B
A9: % grasa por circunferencias | B9: Hodgdon JA, Beckett MB — Naval Health Research Center (US Navy) | C9: 1984 | D9: Personal de la Marina de EE. UU. | E9: H: 495/(1,0324−0,19077·log10(cint−cuello)+0,15456·log10(talla))−450 · M usa (cint+cadera−cuello) | F9: cm; % | G9: Derivada en población militar; sensible a la técnica de medición. | H9: NHRC Reports 84-11 / 84-29 | I9: 2026-07-16 | J9: Informe técnico del gobierno de EE. UU.: dominio público. | K9: B
A10: % grasa por IMC · Deurenberg | B10: Deurenberg P, Weststrate JA, Seidell JC — Br J Nutr 65(2):105-114 | C10: 1991 | D10: 1229 sujetos, amplio rango de edad e IMC | E10: %grasa = 1,20·IMC + 0,23·edad − 10,8·sexo − 5,4 (H=1, M=0) | F10: % ; IMC kg/m² | G10: Estimación poblacional; menos precisa en el individuo, deportistas y ancianos. | H10: 10.1079/bjn19910073 | I10: 2026-07-16 | J10: Artículo con derechos de autor; solo se usa la ecuación. Citada en material técnico chileno (MINSAL). | K10: A
A11: Modelo de composición · MG y MLG | B11: INTA, Universidad de Chile — Salazar G. et al. (Lab. de Metabolismo Energético e Isótopos Estables) | C11: 2003 | D11: Población chilena; antropometría contrastada con dilución de deuterio | E11: Modelo de dos compartimentos: peso = MG + MLG; MG = %grasa·peso | F11: kg | G11: El anclaje regional del marco composicional es chileno; la exactitud sigue dependiendo del método antropométrico. | H11: Rev Chil Pediatr 2003;74:37-45 (INTA U. de Chile) | I11: 2026-07-16 | J11: Artículo con derechos de autor; se usa el marco conceptual (hecho no protegible). Fuente institucional del INTA. | K11: B
A12: Clasificación por IMC · adulto y adulto mayor | B12: MINSAL (Chile) — Norma técnica de evaluación nutricional | C12: vigente | D12: Adopta cortes OMS para el adulto; cortes propios para ≥65 años | E12: Adulto (OMS): 18,5 / 25 / 30 / 35 / 40 · Adulto mayor (MINSAL): 23 / 28 / 32 | F12: kg/m² | G12: Cortes poblacionales; el IMC no distingue masa grasa de masa magra. | H12: MINSAL · Norma de evaluación nutricional | I12: 2026-07-16 | J12: Documento oficial del Estado de Chile: acceso público. | K12: A
A13: Circunferencia de cintura e índices de distribución | B13: MINSAL (Chile) / OMS — cortes de riesgo cardiometabólico | C13: vigente | D13: Consensos OMS/NIH adoptados por el MINSAL | E13: Cintura: H≥102, M≥88 cm · ICC: H≥0,90, M≥0,85 · ICE ≥0,50 | F13: cm; adimensional | G13: Cortes de tamizaje, no diagnósticos por sí solos. | H13: MINSAL / OMS (Waist circumference and WHR, 2008) | I13: 2026-07-16 | J13: Documentos oficiales de acceso público. | K13: A
A14: Rangos referenciales de % de grasa | B14: American Council on Exercise (ACE) | C14: referencial | D14: Rangos divulgados por categoría y sexo | E14: H: esencial 2–5, atlético 6–13, en forma 14–17, aceptable 18–24, obesidad ≥25 % · M: +8 aprox. | F14: % | G14: REFERENCIALES, NO son un estándar chileno oficial. Para diagnóstico priman IMC y cintura (MINSAL). | H14: ACE (rangos divulgados) | I14: 2026-07-16 | J14: Rangos de uso general; se citan como referencia, no como norma. | K14: C
A16: PENDIENTES DE VERIFICACIÓN PRIMARIA (nivel B): Durnin–Womersley, Siri, Brožek y US Navy disponen de resumen primario o corroboración por pares, pero no se inspeccionó cada PDF completo. La versión y el año exactos de la norma MINSAL vigente deben confirmarse en el sitio oficial del Ministerio de Salud antes de un uso formal.

Sheet PRUEBAS
A1: NUTRIMETRÍA · NMX-12
A2: Banco de verificación · el recuento se calcula solo en el RESUMEN
A3: REGLA: el valor ESPERADO nunca lee el CONFIG que usa el motor. O es un literal calculado a partir de la fuente publicada, o se reconstruye con los coeficientes publicados escritos de forma explícita. Si alguien corrompe un coeficiente de CONFIG, estas pruebas FALLAN.
A4: =HYPERLINK("#INICIO!A1","◀ INICIO") -> ◀ INICIO
A6: BLOQUE A · EXACTITUD PLIEGUES → DENSIDAD → % GRASA (Durnin–Womersley + Siri/Brožek)
A7: ID | B7: Descripción | C7: Sexo | D7: Edad | E7: c | F7: m | G7: Σ4 | H7: Conv. | I7: Obtenido | J7: Esperado | K7: Dif. | L7: Estado
A8: A01 | B8: H 30–40 · Siri | C8: Hombre | D8: 34 | E8: 1.1422 | F8: 0.0544 | G8: 46 | H8: Siri | I8: =IF(H8="Brožek",(457/(E8-F8*LOG10(G8))-414)/100,(495/(E8-F8*LOG10(G8))-450)/100) -> 0.20645966 | J8: 0.20646 | K8: =I8-J8 -> -3.3904329e-07 | L8: =IF(ABS(K8)<=TOL_FRAC,"APROBADO","FALLIDO") -> APROBADO
A9: A02 | B9: M 20–30 · Siri | C9: Mujer | D9: 25 | E9: 1.1599 | F9: 0.0717 | G9: 60 | H9: Siri | I9: =IF(H9="Brožek",(457/(E9-F9*LOG10(G9))-414)/100,(495/(E9-F9*LOG10(G9))-450)/100) -> 0.29462279 | J9: 0.294623 | K9: =I9-J9 -> -2.088517e-07 | L9: =IF(ABS(K9)<=TOL_FRAC,"APROBADO","FALLIDO") -> APROBADO
A10: A03 | B10: H 20–30 · Siri | C10: Hombre | D10: 22 | E10: 1.1631 | F10: 0.0632 | G10: 40 | H10: Siri | I10: =IF(H10="Brožek",(457/(E10-F10*LOG10(G10))-414)/100,(495/(E10-F10*LOG10(G10))-450)/100) -> 0.16167622 | J10: 0.161676 | K10: =I10-J10 -> 2.1838009e-07 | L10: =IF(ABS(K10)<=TOL_FRAC,"APROBADO","FALLIDO") -> APROBADO
A11: A04 | B11: M 50+ · Siri | C11: Mujer | D11: 55 | E11: 1.1339 | F11: 0.0645 | G11: 70 | H11: Siri | I11: =IF(H11="Brožek",(457/(E11-F11*LOG10(G11))-414)/100,(495/(E11-F11*LOG10(G11))-450)/100) -> 0.37737022 | J11: 0.37737 | K11: =I11-J11 -> 2.1959879e-07 | L11: =IF(ABS(K11)<=TOL_FRAC,"APROBADO","FALLIDO") -> APROBADO
A12: A05 | B12: H 40–50 · Brožek | C12: Hombre | D12: 45 | E12: 1.162 | F12: 0.07 | G12: 55 | H12: Brožek | I12: =IF(H12="Brožek",(457/(E12-F12*LOG10(G12))-414)/100,(495/(E12-F12*LOG10(G12))-450)/100) -> 0.25349312 | J12: 0.253493 | K12: =I12-J12 -> 1.1975181e-07 | L12: =IF(ABS(K12)<=TOL_FRAC,"APROBADO","FALLIDO") -> APROBADO
A13: A06 | B13: M 30–40 · Brožek | C13: Mujer | D13: 34 | E13: 1.1423 | F13: 0.0632 | G13: 50 | H13: Brožek | I13: =IF(H13="Brožek",(457/(E13-F13*LOG10(G13))-414)/100,(495/(E13-F13*LOG10(G13))-450)/100) -> 0.27577851 | J13: 0.275779 | K13: =I13-J13 -> -4.8726203e-07 | L13: =IF(ABS(K13)<=TOL_FRAC,"APROBADO","FALLIDO") -> APROBADO
A15: BLOQUE B · EXACTITUD % GRASA POR CIRCUNFERENCIAS (US Navy 1984)
A16: ID | B16: Descripción | C16: Sexo | D16: Cuello | E16: Cintura | F16: Cadera | G16: Estatura | H16: Obtenido | I16: Esperado | J16: Dif. | K16: Estado
A17: B01 | B17: Hombre típico | C17: Hombre | D17: 38 | E17: 88 | F17: 100 | G17: 176 | H17: =IF(C17="Hombre",(495/(1.0324-0.19077*LOG10(E17-D17)+0.15456*LOG10(G17))-450)/100,(495/(1.29579-0.35004*LOG10(E17+F17-D17)+0.221*LOG10(G17))-450)/100) -> 0.19036961 | I17: 0.19037 | J17: =H17-I17 -> -3.9194423e-07 | K17: =IF(ABS(J17)<=TOL_FRAC,"APROBADO","FALLIDO") -> APROBADO
A18: B02 | B18: Hombre atlético | C18: Hombre | D18: 40 | E18: 82 | F18: 96 | G18: 180 | H18: =IF(C18="Hombre",(495/(1.0324-0.19077*LOG10(E18-D18)+0.15456*LOG10(G18))-450)/100,(495/(1.29579-0.35004*LOG10(E18+F18-D18)+0.221*LOG10(G18))-450)/100) -> 0.12052147 | I18: 0.120521 | J18: =H18-I18 -> 4.6662089e-07 | K18: =IF(ABS(J18)<=TOL_FRAC,"APROBADO","FALLIDO") -> APROBADO
A19: B03 | B19: Hombre obesidad | C19: Hombre | D19: 44 | E19: 112 | F19: 110 | G19: 170 | H19: =IF(C19="Hombre",(495/(1.0324-0.19077*LOG10(E19-D19)+0.15456*LOG10(G19))-450)/100,(495/(1.29579-0.35004*LOG10(E19+F19-D19)+0.221*LOG10(G19))-450)/100) -> 0.31728167 | I19: 0.317282 | J19: =H19-I19 -> -3.2611922e-07 | K19: =IF(ABS(J19)<=TOL_FRAC,"APROBADO","FALLIDO") -> APROBADO
A20: B04 | B20: Mujer típica | C20: Mujer | D20: 32 | E20: 74 | F20: 100 | G20: 164 | H20: =IF(C20="Hombre",(495/(1.0324-0.19077*LOG10(E20-D20)+0.15456*LOG10(G20))-450)/100,(495/(1.29579-0.35004*LOG10(E20+F20-D20)+0.221*LOG10(G20))-450)/100) -> 0.29705326 | I20: 0.297053 | J20: =H20-I20 -> 2.563539e-07 | K20: =IF(ABS(J20)<=TOL_FRAC,"APROBADO","FALLIDO") -> APROBADO
A21: B05 | B21: Mujer atlética | C21: Mujer | D21: 30 | E21: 68 | F21: 92 | G21: 170 | H21: =IF(C21="Hombre",(495/(1.0324-0.19077*LOG10(E21-D21)+0.15456*LOG10(G21))-450)/100,(495/(1.29579-0.35004*LOG10(E21+F21-D21)+0.221*LOG10(G21))-450)/100) -> 0.21988448 | I21: 0.219884 | J21: =H21-I21 -> 4.8359026e-07 | K21: =IF(ABS(J21)<=TOL_FRAC,"APROBADO","FALLIDO") -> APROBADO
A22: B06 | B22: Mujer obesidad | C22: Mujer | D22: 36 | E22: 96 | F22: 118 | G22: 160 | H22: =IF(C22="Hombre",(495/(1.0324-0.19077*LOG10(E22-D22)+0.15456*LOG10(G22))-450)/100,(495/(1.29579-0.35004*LOG10(E22+F22-D22)+0.221*LOG10(G22))-450)/100) -> 0.47405703 | I22: 0.474057 | J22: =H22-I22 -> 3.4013848e-08 | K22: =IF(ABS(J22)<=TOL_FRAC,"APROBADO","FALLIDO") -> APROBADO
A24: BLOQUE C · EXACTITUD % GRASA POR IMC (Deurenberg 1991)
A25: ID | B25: Descripción | C25: Sexo | D25: IMC | E25: Edad | F25: Obtenido | G25: Esperado | H25: Dif. | I25: Estado
A26: C01 | B26: Hombre normal | C26: Hombre | D26: 25.3422 | E26: 34 | F26: =(1.2*D26+0.23*E26-10.8*IF(C26="Hombre",1,0)-5.4)/100 -> 0.2203064 | G26: 0.220306 | H26: =F26-G26 -> 4e-07 | I26: =IF(ABS(H26)<=TOL_FRAC,"APROBADO","FALLIDO") -> APROBADO
A27: C02 | B27: Mujer normal | C27: Mujer | D27: 23 | E27: 45 | F27: =(1.2*D27+0.23*E27-10.8*IF(C27="Hombre",1,0)-5.4)/100 -> 0.3255 | G27: 0.3255 | H27: =F27-G27 -> 0 | I27: =IF(ABS(H27)<=TOL_FRAC,"APROBADO","FALLIDO") -> APROBADO
A28: C03 | B28: Hombre obesidad | C28: Hombre | D28: 33 | E28: 55 | F28: =(1.2*D28+0.23*E28-10.8*IF(C28="Hombre",1,0)-5.4)/100 -> 0.3605 | G28: 0.3605 | H28: =F28-G28 -> 0 | I28: =IF(ABS(H28)<=TOL_FRAC,"APROBADO","FALLIDO") -> APROBADO
A29: C04 | B29: Mujer obesidad | C29: Mujer | D29: 31 | E29: 60 | F29: =(1.2*D29+0.23*E29-10.8*IF(C29="Hombre",1,0)-5.4)/100 -> 0.456 | G29: 0.456 | H29: =F29-G29 -> 0 | I29: =IF(ABS(H29)<=TOL_FRAC,"APROBADO","FALLIDO") -> APROBADO
A30: C05 | B30: Hombre joven | C30: Hombre | D30: 22 | E30: 20 | F30: =(1.2*D30+0.23*E30-10.8*IF(C30="Hombre",1,0)-5.4)/100 -> 0.148 | G30: 0.148 | H30: =F30-G30 -> 0 | I30: =IF(ABS(H30)<=TOL_FRAC,"APROBADO","FALLIDO") -> APROBADO
A31: C06 | B31: Mujer mayor | C31: Mujer | D31: 27.5 | E31: 70 | F31: =(1.2*D31+0.23*E31-10.8*IF(C31="Hombre",1,0)-5.4)/100 -> 0.437 | G31: 0.437 | H31: =F31-G31 -> 0 | I31: =IF(ABS(H31)<=TOL_FRAC,"APROBADO","FALLIDO") -> APROBADO
A33: BLOQUE D · COMPOSICIÓN CORPORAL (MG, MLG, IMLG) · tolerancia ±0,05 kg / kg·m⁻²
A34: ID | B34: % grasa | C34: Peso | D34: Talla m | E34: MG obt | F34: MG esp | G34: Est.MG | H34: IMLG obt | I34: IMLG esp | J34: Est.IMLG
A35: D01 | B35: 0.20646 | C35: 78.5 | D35: 1.76 | E35: =B35*C35 -> 16.20711 | F35: 16.2071 | G35: =IF(ABS(E35-F35)<=TOL_KG,"APROBADO","FALLIDO") -> APROBADO | H35: =(C35-B35*C35)/D35^2 -> 20.11005 | I35: 20.11 | J35: =IF(ABS(H35-I35)<=TOL_KG,"APROBADO","FALLIDO") -> APROBADO
A36: D02 | B36: 0.3 | C36: 60 | D36: 1.6 | E36: =B36*C36 -> 18 | F36: 18 | G36: =IF(ABS(E36-F36)<=TOL_KG,"APROBADO","FALLIDO") -> APROBADO | H36: =(C36-B36*C36)/D36^2 -> 16.40625 | I36: 16.4062 | J36: =IF(ABS(H36-I36)<=TOL_KG,"APROBADO","FALLIDO") -> APROBADO
A37: D03 | B37: 0.12 | C37: 90 | D37: 1.85 | E37: =B37*C37 -> 10.8 | F37: 10.8 | G37: =IF(ABS(E37-F37)<=TOL_KG,"APROBADO","FALLIDO") -> APROBADO | H37: =(C37-B37*C37)/D37^2 -> 23.140979 | I37: 23.141 | J37: =IF(ABS(H37-I37)<=TOL_KG,"APROBADO","FALLIDO") -> APROBADO
A38: D04 | B38: 0.25 | C38: 72 | D38: 1.7 | E38: =B38*C38 -> 18 | F38: 18 | G38: =IF(ABS(E38-F38)<=TOL_KG,"APROBADO","FALLIDO") -> APROBADO | H38: =(C38-B38*C38)/D38^2 -> 18.685121 | I38: 18.6851 | J38: =IF(ABS(H38-I38)<=TOL_KG,"APROBADO","FALLIDO") -> APROBADO
A40: BLOQUE E · ÍNDICES DE DISTRIBUCIÓN Y CLASIFICACIÓN
A41: ID | B41: Escenario | C41: Entrada | D41: Comportamiento esperado | E41: Comportamiento obtenido | F41: Estado
A42: E01 | B42: ICC hombre bajo umbral (0,88) | C42: 88/100 | D42: Sin riesgo aumentado | E42: =IF(88/100>=0.9,"Riesgo aumentado","Sin riesgo aumentado") -> Sin riesgo aumentado | F42: =IF(E42=D42,"APROBADO","FALLIDO") -> APROBADO
A43: E02 | B43: Cintura hombre en riesgo (105) | C43: 105 | D43: Riesgo aumentado | E43: =IF(105>=102,"Riesgo aumentado","Sin riesgo aumentado") -> Riesgo aumentado | F43: =IF(E43=D43,"APROBADO","FALLIDO") -> APROBADO
A44: E03 | B44: ICE en el umbral (0,50) | C44: 88/176 | D44: Riesgo aumentado | E44: =IF(88/176>=0.5,"Riesgo aumentado","Sin riesgo aumentado") -> Riesgo aumentado | F44: =IF(E44=D44,"APROBADO","FALLIDO") -> APROBADO
A45: E04 | B45: IMC 25,34 adulto → OMS | C45: 25.3422 | D45: Sobrepeso (OMS) | E45: =IF(25.3422<18.5,"Bajo peso (OMS)",IF(25.3422<25,"Normal (OMS)",IF(25.3422<30,"Sobrepeso (OMS)","Obesidad (OMS)"))) -> Sobrepeso (OMS) | F45: =IF(E45=D45,"APROBADO","FALLIDO") -> APROBADO
...

Sheet CONFIG
A1: NUTRIMETRÍA · NMX-12
A2: Parámetros, coeficientes y catálogos · versión 1.0
A3: =HYPERLINK("#INICIO!A1","◀ INICIO") -> ◀ INICIO
A4: Toda constante del modelo vive aquí; ninguna fórmula del libro contiene un coeficiente escrito a mano. Las celdas arena son editables. Cambiar un valor aquí propaga a todo el libro y hace FALLAR las pruebas que cotejan contra la fuente publicada.
A6: C1 · PARÁMETROS, LÍMITES Y COEFICIENTES
A7: Parámetro | B7: Valor | C7: Unidad | D7: Tipo | E7: Nota / fuente
A8: Idioma | B8: Español (es-CL) | C8: — | D8: — | E8: Interfaz
A9: Versión de las fuentes | B9: 2026-07 · v1.0 | C9: — | D9: — | E9: Ver hoja FUENTES
A10: Edad mínima (adulto) | B10: 18 | C10: años | D10: IMPOSIBLE | E10: Alcance del producto: solo adultos
A11: Edad máxima plausible | B11: 120 | C11: años | D11: IMPOSIBLE | E11: Límite operativo
A12: Peso mínimo posible | B12: 25 | C12: kg | D12: IMPOSIBLE | E12: Bajo este valor se considera imposible en un adulto
A13: Peso máximo posible | B13: 350 | C13: kg | D13: IMPOSIBLE | E13: Límite operativo
A14: Estatura mínima posible | B14: 120 | C14: cm | D14: IMPOSIBLE | E14: Límite operativo
A15: Estatura máxima posible | B15: 230 | C15: cm | D15: IMPOSIBLE | E15: Límite operativo
A16: Pliegue mínimo por sitio | B16: 1 | C16: mm | D16: IMPOSIBLE | E16: Guarda de cada pliegue
A17: Pliegue máximo por sitio | B17: 80 | C17: mm | D17: IMPOSIBLE | E17: Guarda de cada pliegue
A18: Cuello mínimo | B18: 20 | C18: cm | D18: IMPOSIBLE | E18: Guarda del método de circunferencias
A19: Cuello máximo | B19: 70 | C19: cm | D19: IMPOSIBLE | E19: Guarda del método de circunferencias
A20: Cintura mínima | B20: 40 | C20: cm | D20: IMPOSIBLE | E20: Guarda de circunferencia
A21: Cintura máxima | B21: 200 | C21: cm | D21: IMPOSIBLE | E21: Guarda de circunferencia
... A56: Índice cintura/estatura · riesgo | B56: 0.5 | C56: — | D56: Corte | E56: Umbral general ≥0,5
A58: C2 · SEXOS
A59: Valor | B59: Nota
A60: Hombre | B60: Ecuaciones derivadas en varones
A61: Mujer | B61: Ecuaciones derivadas en mujeres
A63: C3 · MÉTODO DE % DE GRASA A REPORTAR
A64: Método (lista) | B64: Variables indispensables
A65: 1 · Pliegues (Durnin–Womersley 1974) | B65: 4 pliegues, sexo, edad
A66: 2 · Circunferencias (US Navy 1984) | B66: cuello, cintura, estatura (y cadera en mujeres)
A67: 3 · IMC (Deurenberg 1991) | B67: peso, estatura, edad, sexo
A69: C4 · CONVERSIÓN DE DENSIDAD A % DE GRASA (solo método de pliegues)
A70: Fórmula (lista) | B70: Expresión
A71: Siri (1961) | B71: %grasa = 495/D − 450
A72: Brožek (1963) | B72: %grasa = 457/D − 414
A74: C5 · LISTA SÍ / NO
A75: Sí
A76: No
A78: C6 · DURNIN–WOMERSLEY (1974) · densidad = c − m·log10(Σ4 pliegues) · por sexo y banda etaria
A79: Sexo | B79: Edad desde (≥) | C79: Edad hasta (<) | D79: c | E79: m
A80: Hombre | B80: 17 | C80: 20 | D80: 1.162 | E80: 0.063
...

Sheet CHANGELOG
A1: NUTRIMETRÍA · NMX-12
A2: Historial de versiones
A3: =HYPERLINK("#INICIO!A1","◀ INICIO") -> ◀ INICIO
A5: Versión | B5: Fecha | C5: Cambio | D5: Motivo | E5: Responsable
A6: 1.0 | B6: 2026-07-14 | C6: Versión inicial. Tres métodos de % de grasa (Durnin–Womersley→Siri/Brožek, US Navy, Deurenberg), reconciliación con control de dispersión, composición (MG, MLG, IMG, IMLG) e índices de distribución (cintura, ICC, ICE). | D6: Primera entrega del producto 12. | E6: Equipo Nutrimetría
A7: 1.0 | B7: 2026-07-14 | C7: LOCALIZACIÓN A CHILE: se eliminaron las fuentes de USDA (FoodData Central) y del INS del Perú. El anclaje de clasificación queda en MINSAL y OMS; el marco de composición se referencia al INTA (Universidad de Chile). | D7: Indicación del titular; verificación de licencias. | E7: Equipo Nutrimetría
A8: 1.0 | B8: 2026-07-14 | C8: Banco de pruebas con casos de exactitud (las tres ecuaciones), composición, índices de distribución, validaciones e integridad, con valores esperados independientes del CONFIG. | D8: Control de calidad. | E8: Equipo Nutrimetría
