Workbook

Sheet INICIO
A1: NUTRIMETRÍA · EVALUACIÓN PEDIÁTRICA OMS / MINSAL + UDD · FUENTES RESUELTAS
A2: Versión 3.1 · fuentes primarias verificadas · 6 de agosto de 2026
A3: =HYPERLINK("#INICIO!A1","● INICIO") -> ● INICIO | B3: =HYPERLINK("#'Ingreso'!A1", "● Ir a Ingreso") -> ● Ir a Ingreso | C3: =HYPERLINK("#'Interpretación'!A1", " ● Ir a Interpretación") -> ● Ir a Interpretación | D3: =HYPERLINK("#'GRÁFICO'!A1", "● Ir a GRÁFICO") -> ● Ir a GRÁFICO | E3: =HYPERLINK("#'Informe'!A1", "● Ir a Informe") -> ● Ir a Informe | F3: =HYPERLINK("#'FUENTES'!A1", "● Ir a FUENTES") -> ● Ir a FUENTES | G3: =HYPERLINK("#'SITUACIONES_ESPECIALES'!A1", " ● Ir a Situaciones Especiales") -> ● Ir a Situaciones Especiales | H3: =HYPERLINK("#'CASOS'!A1", "● Ir a CASOS") -> ● Ir a CASOS
A4: Producto | B4: NMX-14 · Evaluación Nutricional Pediátrica
A5: Versión | B5: 3.1 FUENTES RESUELTAS
A6: Rango técnico | B6: 0–228 meses (0–19 años), según tabla aplicable
A7: NT MINSAL infantil | B7: Norma Técnica N.º 218, 2.ª edición 2021, Resolución Exenta N.º 55 — alcance 0–9 años
A8: Patrones clínicos | B8: MINSAL 2018 — nacimiento a 19 años; resolución no identificada en el documento revisado
A9: Compatibilidad | B9: Fórmulas universales; sin XLOOKUP, _xlfn ni _xludf
A11: SEPARACIÓN METODOLÓGICA
A12: 1. OMS 2006 · 0–60 meses: P/E, P/Longitud, P/Estatura, T/E y PCe según tabla disponible.
A13: 2. OMS Reference 2007 · 61–228 meses: IMC/E y T/E.
A14: 3. MINSAL 2018: clasificación clínica por indicador primario y cortes nacionales.
A15: 4. NT N.º 218/2021: prematuridad y situaciones especiales dentro de su alcance 0–9 años.
A16: 5. Poblaciones especiales: módulos separados; las curvas generales se bloquean cuando no corresponde.
A17: 6. Las fuentes especiales se identifican por documento, versión y dominio. Una fuente verificada puede permanecer sin motor automático por licencia o falta de datos tabulares.
A18: FLUJO DE USO
A19: 1. Complete Ingreso, incluyendo peso al nacer y EG exacta si existe prematuridad.
A20: 2. Revise Cálculos para edad efectiva, dominio y alertas.
A21: 3. Consulte Interpretación: diagnóstico nutricional de tamizaje, indicadores, fuentes, aplicabilidad y alertas clínicas.
A22: 4. Revise REGLAS_OFICIALES y SITUACIONES_ESPECIALES antes de uso clínico.
... A25: AVISO: herramienta de apoyo y tamizaje. La exactitud matemática no equivale a validación clínica. Debe interpretarse con trayectoria de crecimiento, antecedentes, examen y criterio profesional.

Sheet Ingreso
A1: NUTRIMETRÍA · DATOS DEL PACIENTE (Ingreso)
B2: Nombre | C2: PACIENTE-X01 | E2: Use un CÓDIGO si va a compartir el archivo.
B3: Sexo (Niño/Niña) | C3: Masculino | E3: Determina la tabla OMS a usar.
B4: Fecha Nacimiento | C4: 40179 | E4: dd/mm/aaaa.
B5: Fecha Evaluación | C5: 46023 | E5: dd/mm/aaaa (≥ nacimiento).
B6: Prematuro (Sí/No) | C6: No | E6: Corrige la edad si aplica.
B7: Semanas Gestación (Dejar en blanco si no es prematuro) | E7: Solo si es prematuro.
B8: Peso (kg) | C8: 62 | E8: Balanza calibrada.
B9: Talla (cm) | C9: 168 | E9: <2 años acostado; ≥2 de pie.
B10: Perímetro Cefálico (cm) | E10: Solo hasta 36 meses.
B11: Perímetro de Cintura (cm) | C11: 62 | E11: Solo desde 5 años.
B12: Días adicionales de gestación (0–6) | E12: Solo si es prematuro; se suma a las semanas completas.
B13: Peso al nacer (g) | E13: Obligatorio para aplicar la regla de prematuridad NT N.º 218.
B14: Síndrome de Down (Sí/No) | C14: No | E14: Las curvas generales quedan bloqueadas; requiere tablas específicas verificadas.
B15: Tipo de medición de talla | C15: Automático por edad | E15: <2 años: longitud; ≥2 años: estatura.
B16: Población seleccionada | C16: GENERAL | E16: Controla el enrutamiento. GENERAL y PREMATURIDAD usan el motor OMS/MINSAL; las demás poblaciones bloquean curvas generales.
B17: Estadio puberal registrado (I–V) | C17: NO_EVALUADO | E17: Dato ingresado por profesional. No se incorporan imágenes Tanner ni se calcula edad biológica automáticamente.
B18: GMFCS registrado (I–V) | C18: NO_REGISTRADO | E18: Registro auxiliar para parálisis cerebral; no activa curvas ni ecuaciones no verificadas.
B19: Celdas arena = editables. UDD se usa como fuente secundaria; OMS/MINSAL conservan prioridad.
B20: Percentil P/E Zemel 2015 (manual 0–100) | E20: Leer en la gráfica CDC/Zemel correspondiente a sexo y edad. Obligatorio <1 año si P/T OMS es <+1 DE.
B21: Percentil T/E Zemel 2015 (manual 0–100) | E21: Usado para calificación estatural específica de síndrome de Down.
B22: Percentil PCe/E Zemel 2015 (manual 0–100) | E22: Usado para PCe específico de síndrome de Down; medir al menos hasta 5 años.
B23: Edad biológica determinada por profesional (años) | E23: No se deriva automáticamente desde imágenes. Usar solo con evaluación profesional.
B24: Seguimiento NANEAS de PCe hasta 5 años | C24: No | E24: Activa tablas OMS PCe/E entre 37 y 60 meses para seguimiento NANEAS.

Sheet Cálculos
A1: Edad Exacta y Aproximación MINSAL (< 5 años)
A2: NUTRIMETRÍA · MOTOR DE CÁLCULO (patrones MINSAL — no editar) | F2: CORTES IMC/EDAD | I2: CORTES PESO/EDAD | L2: CORTES TALLA/EDAD
A3: MESES | B3: Edad Real en Meses): | C3: =IF(OR(Ingreso!C4="",Ingreso!C5="",Ingreso!C5<Ingreso!C4),"",DATEDIF(Ingreso!C4,Ingreso!C5,"m")) -> 192 | F3: (-3DE IMC): | G3: =IFERROR(C8*(1+C9*C10*-3)^(1/C9), "") -> 15.109257 | I3: (-3DE P/E): | J3: =IFERROR(C13*(1+C14*C15*-3)^(1/C14), "") | L3: (Corte -2DE Talla): | M3: =IF(OR(C57<>"SÍ",C6<0,C6>228),"",IF(Ingreso!C3="Femenino",IFERROR(INDEX(Tablas_OMS!$V$2:$V$230,MATCH(C6,Tablas_OMS!$U$2:$U$230,0)),""),IF(Ingreso!C3="Masculino",IFERROR(INDEX(Tablas_OMS!$AC$2:$AC$230,MATCH(C6,Tablas_OMS!$AB$2:$AB$230,0)),""),""))) -> 157.4 | P3: CÁLCULO DE PUNTAJE Z
B4: (Días sobrantes) | C4: =IF(OR(Ingreso!C4="",Ingreso!C5="",Ingreso!C5<Ingreso!C4),"",DATEDIF(Ingreso!C4,Ingreso!C5,"md")) -> 0 | F4: (-2DE IMC): | G4: =IFERROR(C8*(1+C9*C10*-2)^(1/C9), "") -> 16.504916 | I4: (-2DE P/E): | J4: =IFERROR(C13*(1+C14*C15*-2)^(1/C14), "") | L4: (Corte -1DE Talla): | M4: =IF(OR(C57<>"SÍ",C6<0,C6>228),"",IF(Ingreso!C3="Femenino",IFERROR(INDEX(Tablas_OMS!$W$2:$W$230,MATCH(C6,Tablas_OMS!$U$2:$U$230,0)),""),IF(Ingreso!C3="Masculino",IFERROR(INDEX(Tablas_OMS!$AD$2:$AD$230,MATCH(C6,Tablas_OMS!$AB$2:$AB$230,0)),""),""))) -> 165.1 | P4: zIMC = [(y∕M)L-1] (S×L)
B5: (Meses aproximados MINSAL): | C5: =IF(C3="","",IF(C3<60,IF(C4<=15,C3,C3+1),C3)) -> 192 | F5: (-1DE IMC): | G5: =IFERROR(C8*(1+C9*C10*-1)^(1/C9), "") -> 18.24738 | I5: (-1DE P/E): | J5: =IFERROR(C13*(1+C14*C15*-1)^(1/C14), "") | L5: (Corte Mediana Talla): | M5: =IF(OR(C57<>"SÍ",C6<0,C6>228),"",IF(Ingreso!C3="Femenino",IFERROR(INDEX(Tablas_OMS!$X$2:$X$230,MATCH(C6,Tablas_OMS!$U$2:$U$230,0)),""),IF(Ingreso!C3="Masculino",IFERROR(INDEX(Tablas_OMS!$AE$2:$AE$230,MATCH(C6,Tablas_OMS!$AB$2:$AB$230,0)),""),""))) -> 172.9
B6: (Edad efectiva para tablas): | C6: =C50 -> 192 | F6: (Mediana IMC): | G6: =C8 -> 20.4951 | I6: (Mediana P/E): | J6: =C13 | L6: (Corte +1DE Talla): | M6: =IF(OR(C57<>"SÍ",C6<0,C6>228),"",IF(Ingreso!C3="Femenino",IFERROR(INDEX(Tablas_OMS!$Y$2:$Y$230,MATCH(C6,Tablas_OMS!$U$2:$U$230,0)),""),IF(Ingreso!C3="Masculino",IFERROR(INDEX(Tablas_OMS!$AF$2:$AF$230,MATCH(C6,Tablas_OMS!$AB$2:$AB$230,0)),""),""))) -> 180.7
A7: IMC/E | B7: (IMC Real): | C7: =IF(OR(Ingreso!C8="",Ingreso!C9="",Ingreso!C8<=0,Ingreso!C9<=0),"",Ingreso!C8/((Ingreso!C9/100)^2)) -> 21.96712 | F7: (+1DE IMC): | G7: =IFERROR(C8*(1+C9*C10*1)^(1/C9), "") -> 23.525227 | I7: (+1DE P/E): | J7: =IFERROR(C13*(1+C14*C15*1)^(1/C14), "") | L7: (Corte +2DE Talla): | M7: =IF(OR(C57<>"SÍ",C6<0,C6>228),"",IF(Ingreso!C3="Femenino",IFERROR(INDEX(Tablas_OMS!$Z$2:$Z$230,MATCH(C6,Tablas_OMS!$U$2:$U$230,0)),""),IF(Ingreso!C3="Masculino",IFERROR(INDEX(Tablas_OMS!$AG$2:$AG$230,MATCH(C6,Tablas_OMS!$AB$2:$AB$230,0)),""),""))) -> 188.4
B8: (Mediana M del IMC): | C8: =IF(OR(C57<>"SÍ",C6<61,C6>228),"",IF(Ingreso!C3="Femenino",IFERROR(INDEX(Tablas_OMS!$C$2:$C$169,MATCH(C6,Tablas_OMS!$A$2:$A$169,0)),""),IF(Ingreso!C3="Masculino",IFERROR(INDEX(Tablas_OMS!$H$2:$H$169,MATCH(C6,Tablas_OMS!$F$2:$F$169,0)),""),""))) -> 20.4951 | F8: (+2DE IMC): | G8: =IFERROR(C8*(1+C9*C10*2)^(1/C9), "") -> 27.874756 | I8: (+2DE P/E): | J8: =IFERROR(C13*(1+C14*C15*2)^(1/C14), "") | P8: Donde: y = IMC real M = Mediana de IMC para edad y sexo L, S = Estas variables aparecen en las primeras columnas de estas tablas, siendo L: el indicador de simetría y S: el coeficiente de variación.
B9: (Factor L del IMC): | C9: =IF(OR(C57<>"SÍ",C6<61,C6>228),"",IF(Ingreso!C3="Femenino",IFERROR(INDEX(Tablas_OMS!$B$2:$B$169,MATCH(C6,Tablas_OMS!$A$2:$A$169,0)),""),IF(Ingreso!C3="Masculino",IFERROR(INDEX(Tablas_OMS!$G$2:$G$169,MATCH(C6,Tablas_OMS!$F$2:$F$169,0)),""),""))) -> -1.3529 | F9: (+3DE IMC): | G9: =IFERROR(C8*(1+C9*C10*3)^(1/C9), "") -> 34.753538 | I9: (+3DE P/E): | J9: =IFERROR(C13*(1+C14*C15*3)^(1/C14), "")
B10: (Factor S del IMC): | C10: =IF(OR(C57<>"SÍ",C6<61,C6>228),"",IF(Ingreso!C3="Femenino",IFERROR(INDEX(Tablas_OMS!$D$2:$D$169,MATCH(C6,Tablas_OMS!$A$2:$A$169,0)),""),IF(Ingreso!C3="Masculino",IFERROR(INDEX(Tablas_OMS!$I$2:$I$169,MATCH(C6,Tablas_OMS!$F$2:$F$169,0)),""),""))) -> 0.12579
B11: (Puntaje Z exacto del IMC): | C11: =IF(OR(C7="",C8="",C9="",C10=""),"",IF(C9=0,LN(C7/C8)/C10,(((C7/C8)^C9)-1)/(C10*C9))) -> 0.52632207
B12: Lactantes Menor (<1 año)
A13: Peso/Edad | B13: (Mediana M del P/E): | C13: =IF(OR(C57<>"SÍ",C6<0,C6>60),"",IF(Ingreso!C3="Femenino",IFERROR(INDEX(OMS_TABLAS_OFICIALES!$C$5:$C$65,MATCH(C6,OMS_TABLAS_OFICIALES!$A$5:$A$65,0)),""),IF(Ingreso!C3="Masculino",IFERROR(INDEX(OMS_TABLAS_OFICIALES!$H$5:$H$65,MATCH(C6,OMS_TABLAS_OFICIALES!$F$5:$F$65,0)),""),"")))
B14: (Factor L del P/E): | C14: =IF(OR(C57<>"SÍ",C6<0,C6>60),"",IF(Ingreso!C3="Femenino",IFERROR(INDEX(OMS_TABLAS_OFICIALES!$B$5:$B$65,MATCH(C6,OMS_TABLAS_OFICIALES!$A$5:$A$65,0)),""),IF(Ingreso!C3="Masculino",IFERROR(INDEX(OMS_TABLAS_OFICIALES!$G$5:$G$65,MATCH(C6,OMS_TABLAS_OFICIALES!$F$5:$F$65,0)),""),"")))
B15: (Factor S del P/E): | C15: =IF(OR(C57<>"SÍ",C6<0,C6>60),"",IF(Ingreso!C3="Femenino",IFERROR(INDEX(OMS_TABLAS_OFICIALES!$D$5:$D$65,MATCH(C6,OMS_TABLAS_OFICIALES!$A$5:$A$65,0)),""),IF(Ingreso!C3="Masculino",IFERROR(INDEX(OMS_TABLAS_OFICIALES!$I$5:$I$65,MATCH(C6,OMS_TABLAS_OFICIALES!$F$5:$F$65,0)),""),"")))
B16: (Puntaje Z exacto del P/E): | C16: =IF(OR(Ingreso!C8="",C13="",C14="",C15=""),"",IF(C14=0,LN(Ingreso!C8/C13)/C15,(((Ingreso!C8/C13)^C14)-1)/(C15*C14)))
A18: Talla/Edad | B18: EXTRAS TALLA/EDAD
B19: (Factor L de T/E): | C19: =1 -> 1
B20: (Mediana M de T/E): | C20: =M5 -> 172.9
B21: (Factor S de T/E): | C21: =IFERROR((M6-M5)/M5, "") -> 0.045112782
B22: (Puntaje Z T/E interpolado): | C22: =IF(OR(M3="",M4="",M5="",M6="",M7="",Ingreso!C9=""),"",IF(Ingreso!C9<M4,-1+(Ingreso!C9-M4)/(M4-M3),IF(Ingreso!C9<M5,(Ingreso!C9-M5)/(M5-M4),IF(Ingreso!C9<M6,(Ingreso!C9-M5)/(M6-M5),1+(Ingreso!C9-M6)/(M7-M6))))) -> -0.62820513
A24: Perimetro encefalico | B24: (Corte -2DE PC): | C24: =IF(OR(C57<>"SÍ",C6<0,C6>60,AND(C6>36,Ingreso!C24<>"Sí")),"",IF(Ingreso!C3="Femenino",IFERROR(INDEX(OMS_PCE_0_60!$G$5:$G$65,MATCH(C6,OMS_PCE_0_60!$A$5:$A$65,0)),""),IF(Ingreso!C3="Masculino",IFERROR(INDEX(OMS_PCE_0_60!$T$5:$T$65,MATCH(C6,OMS_PCE_0_60!$N$5:$N$65,0)),""),"")))
B25: (Corte -1DE PC): | C25: =IF(OR(C57<>"SÍ",C6<0,C6>60,AND(C6>36,Ingreso!C24<>"Sí")),"",IF(Ingreso!C3="Femenino",IFERROR(INDEX(OMS_PCE_0_60!$H$5:$H$65,MATCH(C6,OMS_PCE_0_60!$A$5:$A$65,0)),""),IF(Ingreso!C3="Masculino",IFERROR(INDEX(OMS_PCE_0_60!$U$5:$U$65,MATCH(C6,OMS_PCE_0_60!$N$5:$N$65,0)),""),"")))
B26: (Corte Mediana PC): | C26: =IF(OR(C57<>"SÍ",C6<0,C6>60,AND(C6>36,Ingreso!C24<>"Sí")),"",IF(Ingreso!C3="Femenino",IFERROR(INDEX(OMS_PCE_0_60!$I$5:$I$65,MATCH(C6,OMS_PCE_0_60!$A$5:$A$65,0)),""),IF(Ingreso!C3="Masculino",IFERROR(INDEX(OMS_PCE_0_60!$V$5:$V$65,MATCH(C6,OMS_PCE_0_60!$N$5:$N$65,0)),""),"")))
B27: (Corte +1DE PC): | C27: =IF(OR(C57<>"SÍ",C6<0,C6>60,AND(C6>36,Ingreso!C24<>"Sí")),"",IF(Ingreso!C3="Femenino",IFERROR(INDEX(OMS_PCE_0_60!$J$5:$J$65,MATCH(C6,OMS_PCE_0_60!$A$5:$A$65,0)),""),IF(Ingreso!C3="Masculino",IFERROR(INDEX(OMS_PCE_0_60!$W$5:$W$65,MATCH(C6,OMS_PCE_0_60!$N$5:$N$65,0)),""),"")))
B28: (Corte +2DE PC): | C28: =IF(OR(C57<>"SÍ",C6<0,C6>60,AND(C6>36,Ingreso!C24<>"Sí")),"",IF(Ingreso!C3="Femenino",IFERROR(INDEX(OMS_PCE_0_60!$K$5:$K$65,MATCH(C6,OMS_PCE_0_60!$A$5:$A$65,0)),""),IF(Ingreso!C3="Masculino",IFERROR(INDEX(OMS_PCE_0_60!$X$5:$X$65,MATCH(C6,OMS_PCE_0_60!$N$5:$N$65,0)),""),"")))
B29: (Puntaje Z PCe interpolado): | C29: =IF(OR(C24="",C25="",C26="",C27="",C28="",Ingreso!C10=""),"",IF(Ingreso!C10<C25,-1+(Ingreso!C10-C25)/(C25-C24),IF(Ingreso!C10<C26,(Ingreso!C10-C26)/(C26-C25),IF(Ingreso!C10<C27,(Ingreso!C10-C26)/(C27-C26),1+(Ingreso!C10-C27)/(C28-C27)))))
A30: Peso/Talla | B30: (Mediana M de P/Longitud o P/Estatura): | C30: =IF(OR(C57<>"SÍ",C6<0,C6>60,C54=""),"",IF(C6<24,IF(Ingreso!C3="Femenino",IFERROR(INDEX(OMS_TABLAS_OFICIALES!$M$5:$M$135,MATCH(C54,OMS_TABLAS_OFICIALES!$K$5:$K$135,0)),""),IF(Ingreso!C3="Masculino",IFERROR(INDEX(OMS_TABLAS_OFICIALES!$R$5:$R$135,MATCH(C54,OMS_TABLAS_OFICIALES!$P$5:$P$135,0)),""),"")),IF(Ingreso!C3="Femenino",IFERROR(INDEX(OMS_TABLAS_OFICIALES!$W$5:$W$115,MATCH(C54,OMS_TABLAS_OFICIALES!$U$5:$U$115,0)),""),IF(Ingreso!C3="Masculino",IFERROR(INDEX(OMS_TABLAS_OFICIALES!$AB$5:$AB$115,MATCH(C54,OMS_TABLAS_OFICIALES!$Z$5:$Z$115,0)),""),""))))
B31: (Factor L de P/Longitud o P/Estatura): | C31: =IF(OR(C57<>"SÍ",C6<0,C6>60,C54=""),"",IF(C6<24,IF(Ingreso!C3="Femenino",IFERROR(INDEX(OMS_TABLAS_OFICIALES!$L$5:$L$135,MATCH(C54,OMS_TABLAS_OFICIALES!$K$5:$K$135,0)),""),IF(Ingreso!C3="Masculino",IFERROR(INDEX(OMS_TABLAS_OFICIALES!$Q$5:$Q$135,MATCH(C54,OMS_TABLAS_OFICIALES!$P$5:$P$135,0)),""),"")),IF(Ingreso!C3="Femenino",IFERROR(INDEX(OMS_TABLAS_OFICIALES!$V$5:$V$115,MATCH(C54,OMS_TABLAS_OFICIALES!$U$5:$U$115,0)),""),IF(Ingreso!C3="Masculino",IFERROR(INDEX(OMS_TABLAS_OFICIALES!$AA$5:$AA$115,MATCH(C54,OMS_TABLAS_OFICIALES!$Z$5:$Z$115,0)),""),""))))
B32: (Factor S de P/Longitud o P/Estatura): | C32: =IF(OR(C57<>"SÍ",C6<0,C6>60,C54=""),"",IF(C6<24,IF(Ingreso!C3="Femenino",IFERROR(INDEX(OMS_TABLAS_OFICIALES!$N$5:$N$135,MATCH(C54,OMS_TABLAS_OFICIALES!$K$5:$K$135,0)),""),IF(Ingreso!C3="Masculino",IFERROR(INDEX(OMS_TABLAS_OFICIALES!$S$5:$S$135,MATCH(C54,OMS_TABLAS_OFICIALES!$P$5:$P$135,0)),""),"")),IF(Ingreso!C3="Femenino",IFERROR(INDEX(OMS_TABLAS_OFICIALES!$X$5:$X$115,MATCH(C54,OMS_TABLAS_OFICIALES!$U$5:$U$115,0)),""),IF(Ingreso!C3="Masculino",IFERROR(INDEX(OMS_TABLAS_OFICIALES!$AC$5:$AC$115,MATCH(C54,OMS_TABLAS_OFICIALES!$Z$5:$Z$115,0)),""),""))))
B33: (Puntaje Z de P/Longitud o P/Estatura): | C33: =IF(OR(Ingreso!C8="",C30="",C31="",C32=""),"",IF(C31=0,LN(Ingreso!C8/C30)/C32,(((Ingreso!C8/C30)^C31)-1)/(C32*C31)))
A35: (Z-score Primario): | C35: =IF(OR(C57<>"SÍ",C6="",C6>228),"",IF(C6<12,IF(C33>=1,C33,C16),IF(C6<=60,C33,C11))) -> 0.52632207
A36: Perimetro de cintura | B36: (Edad en Años Exactos): | C36: =IF(OR(Ingreso!C4="",Ingreso!C5="",Ingreso!C5<Ingreso!C4),"",DATEDIF(Ingreso!C4,Ingreso!C5,"Y")) -> 16
B37: (Corte p75 Cintura): | C37: =IF(OR(C57<>"SÍ",C36<5,C36>18),"",IF(Ingreso!C3="Femenino",IFERROR(INDEX(Tablas_OMS!$BU$2:$BU$15,MATCH(C36,Tablas_OMS!$BQ$2:$BQ$15,0)),""),IF(Ingreso!C3="Masculino",IFERROR(INDEX(Tablas_OMS!$CB$2:$CB$15,MATCH(C36,Tablas_OMS!$BX$2:$BX$15,0)),""),""))) -> 84.5
B38: (Corte p90 Cintura): | C38: =IF(OR(C57<>"SÍ",C36<5,C36>18),"",IF(Ingreso!C3="Femenino",IFERROR(INDEX(Tablas_OMS!$BV$2:$BV$15,MATCH(C36,Tablas_OMS!$BQ$2:$BQ$15,0)),""),IF(Ingreso!C3="Masculino",IFERROR(INDEX(Tablas_OMS!$CC$2:$CC$15,MATCH(C36,Tablas_OMS!$BX$2:$BX$15,0)),""),""))) -> 98.4
A40: EDAD DOCUMENTADA, APLICABILIDAD Y ALERTAS
B41: Días cronológicos exactos | C41: =IF(OR(Ingreso!C4="",Ingreso!C5="",Ingreso!C5<Ingreso!C4),"",Ingreso!C5-Ingreso!C4) -> 5844 | D41: Fecha evaluación − fecha nacimiento
B42: Edad gestacional total (días) | C42: =IF(Ingreso!C7="","",Ingreso!C7*7+IF(Ingreso!C12="",0,Ingreso!C12)) | D42: Semanas×7 + días adicionales
B43: Corrección teórica (días) | C43: =IF(C42="","",MAX(0,280-C42)) | D43: 280 − edad gestacional total
B44: Clase de prematuridad NT N.º 218 | C44: =IF(Ingreso!C6<>"Sí","NO_APLICA",IF(OR(Ingreso!C7="",Ingreso!C13=""),"PENDIENTE_DATO",IF(OR(Ingreso!C7<20,Ingreso!C7>42,IF(Ingreso!C12="",0,Ingreso!C12)<0,IF(Ingreso!C12="",0,Ingreso!C12)>6,Ingreso!C13<300,Ingreso!C13>8000),"DATO_INVALIDO",IF(OR(C42<224,Ingreso!C13<1500),"RNMBP",IF(AND(C42>=224,C42<=237,Ingreso!C13>=1500),"PREMATURO_MODERADO",IF(AND(C42>=238,C42<=258,Ingreso!C13>=1500),"PREMATURO_TARDÍO","FUERA_CRITERIO_NT218")))))) -> NO_APLICA | D44: Usa EG y peso al nacer
...

Sheet Interpretación
A1: NUTRIMETRÍA · RESULTADOS SEPARADOS OMS / MINSAL
B2: Indicador | C2: Puntaje Z | D2: Clasificación OMS | E2: Clasificación clínica MINSAL | F2: Fuente identificada | G2: Aplicabilidad | H2: Estado / alerta
B3: IMC/Edad | C3: =Cálculos!C11 -> 0.52632207 | D3: =IF(C3="","",IF(C3<-3,"Delgadez severa",IF(C3<-2,"Delgadez",IF(C3<=1,"Normal",IF(C3<=2,"Sobrepeso","Obesidad"))))) -> Normal | E3: =IF(C3="","",IF(C3<=-2,"Desnutrición",IF(C3<=-1,"Riesgo de desnutrir",IF(C3<1,"Normal",IF(C3<2,"Sobrepeso",IF(C3<3,"Obesidad","Obesidad severa")))))) -> Normal | F3: OMS Reference 2007 (61–228 m); MINSAL 2018 p. 9 | G3: =IF(OR(Ingreso!C16="SINDROME_DOWN",Ingreso!C16="PARALISIS_CEREBRAL",Ingreso!C16="OTRA"),"REFERENCIA_NO_IMPLEMENTADA",IF(AND(Cálculos!C6>=61,Cálculos!C6<=228),IF(C3="","PENDIENTE_DATO","APLICA"),"FUERA_DE_DOMINIO")) -> APLICA | H3: =IF(OR(G3="APLICA",G3="NO_APLICA",G3="EDAD_CRONOLÓGICA",G3="CORRECCIÓN_FINALIZADA"),"OK",G3) -> OK
B4: Peso/Edad | C4: =Cálculos!C16 | D4: =IF(C4="","",IF(C4<-3,"Bajo peso severo",IF(C4<-2,"Bajo peso","Normal"))) | E4: =IF(C4="","",IF(C4<=-2,"Desnutrición",IF(C4<=-1,"Riesgo de desnutrir","Normal / eutrófico"))) | F4: OMS Child Growth Standards 2006 (0–60 m); MINSAL 2018 p. 9 | G4: =IF(OR(Ingreso!C16="SINDROME_DOWN",Ingreso!C16="PARALISIS_CEREBRAL",Ingreso!C16="OTRA"),"REFERENCIA_NO_IMPLEMENTADA",IF(AND(Cálculos!C6>=0,Cálculos!C6<=60),IF(C4="","PENDIENTE_DATO","APLICA"),"FUERA_DE_DOMINIO")) -> FUERA_DE_DOMINIO | H4: =IF(OR(G4="APLICA",G4="NO_APLICA",G4="EDAD_CRONOLÓGICA",G4="CORRECCIÓN_FINALIZADA"),"OK",G4) -> FUERA_DE_DOMINIO
B5: Talla/Edad | C5: =Cálculos!C22 -> -0.62820513 | D5: =IF(C5="","",IF(C5<-3,"Talla baja severa",IF(C5<-2,"Talla baja",IF(C5<=3,"Normal","Talla alta")))) -> Normal | E5: =IF(C5="","",IF(C5<=-2,"Talla baja",IF(C5<=-1,"Talla normal baja",IF(C5<1,"Normal",IF(C5<2,"Talla normal alta","Talla alta"))))) -> Normal | F5: OMS 2006/2007, líneas Z oficiales; puntaje Z interpolado entre líneas | G5: =IF(OR(Ingreso!C16="SINDROME_DOWN",Ingreso!C16="PARALISIS_CEREBRAL",Ingreso!C16="OTRA"),"REFERENCIA_NO_IMPLEMENTADA",IF(AND(Cálculos!C6>=0,Cálculos!C6<=228),IF(C5="","PENDIENTE_DATO","APLICA"),"FUERA_DE_DOMINIO")) -> APLICA | H5: =IF(G5="APLICA","OK_CON_LIMITACIÓN_Z_INTERPOLADO",IF(G5="NO_APLICA_SÍNDROME_DOWN",G5,IF(G5="FUERA_DE_DOMINIO",G5,G5))) -> OK_CON_LIMITACIÓN_Z_INTERPOLADO
B6: Perímetro cefálico/Edad | C6: =Cálculos!C29 | D6: =IF(C6="","","NO_CLASIFICACIÓN_OMS_IMPLEMENTADA") | E6: =IF(C6="","",IF(C6<=-2,"Microcefalia",IF(C6>=2,"Macrocefalia","Normal"))) | F6: OMS 2006 PCe/E 0–60 m; MINSAL NT N.º218, 2021, tabla II-35 p.132: normal >−2 y <+2 | G6: =IF(OR(Ingreso!C16="SINDROME_DOWN",Ingreso!C16="PARALISIS_CEREBRAL",Ingreso!C16="OTRA"),"REFERENCIA_ESPECÍFICA",IF(AND(Cálculos!C6>=0,Cálculos!C6<=60,OR(Cálculos!C6<=36,Ingreso!C24="Sí")),IF(Ingreso!C10="","NO_INGRESADO","APLICA"),"FUERA_DE_DOMINIO")) -> FUERA_DE_DOMINIO | H6: =IF(G6="APLICA","OK_CON_LIMITACIÓN_Z_INTERPOLADO",IF(G6="NO_APLICA_SÍNDROME_DOWN",G6,IF(G6="FUERA_DE_DOMINIO",G6,G6))) -> FUERA_DE_DOMINIO
B7: Peso/Longitud o Peso/Estatura | C7: =Cálculos!C33 | D7: =IF(C7="","",IF(C7<-3,"Emaciación severa",IF(C7<-2,"Emaciación",IF(C7<=1,"Normal",IF(C7<=2,"Posible riesgo de sobrepeso",IF(C7<=3,"Sobrepeso","Obesidad")))))) | E7: =IF(C7="","",IF(C7<=-2,"Desnutrición",IF(C7<=-1,"Riesgo de desnutrir",IF(C7<1,"Normal",IF(C7<2,"Sobrepeso","Obesidad"))))) | F7: OMS 2006 P/L <2 a y P/E 2–5 a; MINSAL 2018 p. 9 | G7: =IF(OR(Ingreso!C16="SINDROME_DOWN",Ingreso!C16="PARALISIS_CEREBRAL",Ingreso!C16="OTRA"),"REFERENCIA_NO_IMPLEMENTADA",IF(AND(Cálculos!C6>=0,Cálculos!C6<=60),IF(OR(Cálculos!C54<IF(Cálculos!C6<24,45,65),Cálculos!C54>IF(Cálculos!C6<24,110,120)),"FUERA_DE_DOMINIO_TALLA",IF(C7="","PENDIENTE_DATO","APLICA")),"FUERA_DE_DOMINIO")) -> FUERA_DE_DOMINIO | H7: =IF(OR(G7="APLICA",G7="NO_APLICA",G7="EDAD_CRONOLÓGICA",G7="CORRECCIÓN_FINALIZADA"),"OK",G7) -> FUERA_DE_DOMINIO
B8: Perímetro de cintura/Edad | C8: ="" | D8: ="NO_OMS · percentiles Fernández" -> NO_OMS · percentiles Fernández | E8: =IF(OR(Ingreso!C11="",Cálculos!C37=""),"",IF(Ingreso!C11<Cálculos!C37,"Normal",IF(Ingreso!C11<Cálculos!C38,"Riesgo de obesidad abdominal","Obesidad abdominal"))) -> Normal | F8: Fernández et al. 2004; incorporado por MINSAL 2018 p. 11 | G8: =IF(OR(Ingreso!C16="SINDROME_DOWN",Ingreso!C16="PARALISIS_CEREBRAL",Ingreso!C16="OTRA"),"REFERENCIA_NO_IMPLEMENTADA",IF(AND(Cálculos!C36>=5,Cálculos!C36<=18),IF(Ingreso!C11="","NO_INGRESADO","APLICA"),"FUERA_DE_DOMINIO_TABLA")) -> APLICA | H8: =IF(OR(G8="APLICA",G8="NO_APLICA",G8="EDAD_CRONOLÓGICA",G8="CORRECCIÓN_FINALIZADA"),"OK",G8) -> OK
B9: Clasificación nutricional integrada | C9: =Cálculos!C35 -> 0.52632207 | D9: ="NO_APLICA · clasificación clínica MINSAL" -> NO_APLICA · clasificación clínica MINSAL | E9: =IF(C9="","",IF(C9<=-2,"Desnutrición",IF(C9<=-1,"Riesgo de desnutrir",IF(C9<1,"Normal",IF(C9<2,"Sobrepeso",IF(AND(Cálculos!C6>=61,C9>=3),"Obesidad severa","Obesidad")))))) -> Normal | F9: MINSAL, Patrones de crecimiento 2018, p. 9 | G9: =IF(OR(Ingreso!C16="SINDROME_DOWN",Ingreso!C16="PARALISIS_CEREBRAL",Ingreso!C16="OTRA"),"REFERENCIA_NO_IMPLEMENTADA",IF(AND(Cálculos!C6>=0,Cálculos!C6<=228),IF(C9="","PENDIENTE_DATO","APLICA"),"FUERA_DE_DOMINIO")) -> APLICA | H9: =IF(OR(G9="APLICA",G9="NO_APLICA",G9="EDAD_CRONOLÓGICA",G9="CORRECCIÓN_FINALIZADA"),"OK",G9) -> OK
B10: Dominio etario | C10: ="" | D10: =Cálculos!C52 -> OMS 2007 · 61–228 meses | E10: =IF(Cálculos!C6="","PENDIENTE","NT N.º 218: 0–9 años; patrones MINSAL 2018: nacimiento–19 años") -> NT N.º 218: 0–9 años; patrones MINSAL 2018: nacimiento–19 años | F10: OMS 2006 + OMS Reference 2007; MINSAL 2018 | G10: =IF(Cálculos!C6="","PENDIENTE","APLICA") -> APLICA | H10: =IF(OR(G10="APLICA",G10="NO_APLICA",G10="EDAD_CRONOLÓGICA",G10="CORRECCIÓN_FINALIZADA"),"OK",G10) -> OK
B11: Prematuridad | C11: ="" | D11: ="NO_APLICA" -> NO_APLICA | E11: =Cálculos!C44 -> NO_APLICA | F11: MINSAL NT N.º 218, 2.ª ed. 2021, Resolución Exenta N.º 55, tabla III-12 p. 146 | G11: =IF(Ingreso!C6="Sí",Cálculos!C51,"NO_APLICA") -> NO_APLICA | H11: =IF(OR(G11="APLICA",G11="NO_APLICA",G11="EDAD_CRONOLÓGICA",G11="CORRECCIÓN_FINALIZADA"),"OK",G11) -> OK
B12: Síndrome de Down | C12: ="" | D12: =IF(Ingreso!C16="SINDROME_DOWN","MOTOR_DOWN_INTEGRADO_OMS_ZEMEL","NO_APLICA") -> NO_APLICA | E12: =IF(Ingreso!C16="SINDROME_DOWN",DOWN_INTEGRADO!B16,"NO_APLICA") -> NO_APLICA | F12: MINSAL NT N.º218, 2021, tablas III-21 a III-24 pp.161–162; OMS 2006/2007; Zemel 2015 | G12: =IF(Ingreso!C16="SINDROME_DOWN",DOWN_INTEGRADO!B20,"NO_APLICA") -> NO_APLICA | H12: =IF(OR(G12="APLICA",G12="NO_APLICA"),IF(OR(E12="PENDIENTE_PERCENTIL_P_E_ZEMEL",E12="PENDIENTE_DATO_OMS_P_T",E12="PENDIENTE_DATO_OMS_IMC_E"),E12,"OK"),G12) -> OK | I12: Z-Score Exacto: | J12: =IF(C9="","",C9) -> 0.52632207
B13: Población seleccionada | C13: ="" | D13: =Ingreso!C16 -> GENERAL | E13: =IF(Ingreso!C16="GENERAL","MOTOR_GENERAL_OMS_MINSAL",IF(Ingreso!C16="PREMATURIDAD","MOTOR_GENERAL_CON_EDAD_CORREGIDA",IF(Ingreso!C16="SINDROME_DOWN","MOTOR_DOWN_INTEGRADO_OMS_ZEMEL",IF(Ingreso!C16="PARALISIS_CEREBRAL","FUENTE_VERIFICADA_MOTOR_NO_AUTOMATIZADO",IF(Ingreso!C16="OTRA","FUENTE_ESPECÍFICA_REQUERIDA","POBLACIÓN_NO_SELECCIONADA"))))) -> MOTOR_GENERAL_OMS_MINSAL | F13: Selector de población + jerarquía OMS/MINSAL/UDD | G13: =IF(Ingreso!C16="GENERAL","APLICA",IF(Ingreso!C16="PREMATURIDAD",IF(Ingreso!C6="Sí","APLICA_CON_EDAD_CORREGIDA","PENDIENTE_DATO"),IF(Ingreso!C16="SINDROME_DOWN",DOWN_INTEGRADO!B20,IF(Ingreso!C16="PARALISIS_CEREBRAL","FUENTE_VERIFICADA_SIN_MOTOR",IF(Ingreso!C16="OTRA","FUENTE_ESPECÍFICA_REQUERIDA","PENDIENTE"))))) -> APLICA | H13: =IF(OR(G13="APLICA",G13="APLICA_CON_EDAD_CORREGIDA"),"OK",G13) -> OK
B14: DIAGNÓSTICO NUTRICIONAL DE TAMIZAJE
B15: =IF(Ingreso!C2="","",IF(Cálculos!C6="","Evaluación nutricional de "&Ingreso!C2&". "&"La edad efectiva está pendiente de resolución.",IF(Ingreso!C16="SINDROME_DOWN","Evaluación nutricional de "&Ingreso!C2&", "&IF(Ingreso!C3="Femenino","niña","niño")&" de "&IF(Cálculos!C6<12,TEXT(Cálculos!C6,"0")&" meses",TEXT(INT(Cálculos!C6/12),"0")&IF(INT(Cálculos!C6/12)=1," año"," años")&" y "&TEXT(Cálculos!C6-INT(Cálculos!C6/12)*12,"0")&" meses")&", con síndrome de Down.",IF(Ingreso!C16="PARALISIS_CEREBRAL","Evaluación nutricional de "&Ingreso!C2&", "&IF(Ingreso!C3="Femenino","niña","niño")&" de "&IF(Cálculos!C6<12,TEXT(Cálculos!C6,"0")&" meses",TEXT(INT(Cálculos!C6/12),"0")&IF(INT(Cálculos!C6/12)=1," año"," años")&" y "&TEXT(Cálculos!C6-INT(Cálculos!C6/12)*12,"0")&" meses")&", con parálisis cerebral.","Evaluación nutricional de "&Ingreso!C2&", "&IF(Ingreso!C3="Femenino","niña","niño")&" de "&IF(Cálculos!C6<12,TEXT(Cálculos!C6,"0")&" meses",TEXT(INT(Cálculos!C6/12),"0")&IF(INT(Cálculos!C6/12)=1," año"," años")&" y "&TEXT(Cálculos!C6-INT(Cálculos!C6/12)*12,"0")&" meses")&".")))) -> Evaluación nutricional de PACIENTE-X01, niño de 16 años y 0 meses.
B16: =IF(Ingreso!C2="","",IF(Cálculos!C6="","No fue posible emitir el diagnóstico nutricional. Revise las fechas, la condición de prematuridad, la edad gestacional y el peso al nacer.",IF(Ingreso!C16="SINDROME_DOWN","Diagnóstico nutricional de tamizaje: "&IF(DOWN_INTEGRADO!B16="PENDIENTE_PERCENTIL_P_E_ZEMEL","no concluyente por falta del percentil de peso/edad Zemel",IF(DOWN_INTEGRADO!B16="PENDIENTE_DATO_OMS_P_T","no concluyente por falta de datos para peso/longitud o peso/estatura",IF(DOWN_INTEGRADO!B16="PENDIENTE_DATO_OMS_IMC_E","no concluyente por falta de datos para IMC/edad",LOWER(SUBSTITUTE(DOWN_INTEGRADO!B16,"_"," ")))))&". "&"La valoración integró los indicadores OMS permitidos por MINSAL y los percentiles específicos Zemel.",IF(Ingreso!C16="PARALISIS_CEREBRAL","Conclusión de tamizaje: no es clínicamente válido emitir un diagnóstico antropométrico automático utilizando las curvas pediátricas generales.",IF(Ingreso!C16="OTRA","No es posible emitir un diagnóstico nutricional automático válido para la población OTRA, porque falta una referencia específica con versión, dominio y criterios documentados.","Diagnóstico nutricional de tamizaje: estado nutricional "&LOWER(IF(E9="","no concluyente por falta de datos",E9))&" según la clasificación clínica MINSAL aplicable a su edad."))))) -> Diagnóstico nutricional de tamizaje: estado nutricional normal según la clasificación clínica MINSAL aplicable a su edad.
B17: =IF(Ingreso!C2="","",IF(Cálculos!C6="","Los indicadores no pueden interpretarse hasta resolver la edad efectiva.",IF(Ingreso!C16="SINDROME_DOWN","Peso específico: "&LOWER(SUBSTITUTE(DOWN_INTEGRADO!B17,"_"," "))&". "&"Talla para la edad específica: "&LOWER(SUBSTITUTE(DOWN_INTEGRADO!B18,"_"," "))&". "&"Perímetro cefálico para la edad específico: "&LOWER(SUBSTITUTE(DOWN_INTEGRADO!B19,"_"," "))&".",IF(Ingreso!C16="PARALISIS_CEREBRAL",IF(Ingreso!C18="NO_REGISTRADO","El nivel GMFCS no está registrado. ","Nivel GMFCS registrado: "&Ingreso!C18&". ")&"La valoración debe integrar peso y talla directos o estimados, medidas segmentarias, evolución, función motora, vía de alimentación e ingesta.",IF(Ingreso!C16="OTRA","Seleccione la población correcta o incorpore la referencia clínica específica antes de interpretar los indicadores.",IF(Cálculos!C6<=60,"Peso para la longitud/estatura: "&LOWER(IF(E7="","no disponible",E7))&"."&IF(Cálculos!C6<12," "&"Peso para la edad: "&LOWER(IF(E4="","no disponible",E4))&".",""),"IMC para la edad: "&LOWER(IF(E3="","no disponible",E3))&".")&" "&"Talla para la edad: "&LOWER(IF(E5="","sin información suficiente",E5))&"."&IF(G6="APLICA"," "&"Perímetro cefálico para la edad: "&LOWER(E6)&".","")&IF(G8="APLICA"," "&"Perímetro de cintura: "&LOWER(E8)&".","")))))) -> IMC para la edad: normal. Talla para la edad: normal. Perímetro de cintura: normal.
B18: =IF(Ingreso!C2="","",IF(Cálculos!C6="","Corrija los datos de ingreso antes de utilizar el resultado para una decisión clínica.",IF(Ingreso!C16="SINDROME_DOWN","Confirme que los percentiles Zemel fueron leídos e ingresados por un profesional y valore la trayectoria individual. Las curvas generales no deben utilizarse como sustituto.",IF(Ingreso!C16="PARALISIS_CEREBRAL","Se recomienda completar la evaluación en el módulo antropométrico especializado y formular el diagnóstico nutricional con criterio clínico individual.",IF(Ingreso!C16="OTRA","No utilice las curvas generales como sustituto de una referencia que no ha sido verificada.",IF(OR(E9="Desnutrición",E9="Obesidad severa"),"El hallazgo requiere evaluación nutricional y clínica prioritaria, revisión de la velocidad de crecimiento y una conducta individualizada. ",IF(OR(E9="Riesgo de desnutrir",E9="Sobrepeso",E9="Obesidad"),"El hallazgo requiere evaluación nutricional completa y seguimiento cercano de la trayectoria de crecimiento, la alimentación y los factores clínicos y familiares. ",IF(E9="Normal","No se identifican alteraciones antropométricas en el indicador principal; se recomienda mantener seguimiento periódico de la trayectoria de crecimiento. ","La conclusión debe completarse cuando estén disponibles todos los datos requeridos. ")))&IF(Ingreso!C6="Sí","La interpretación utilizó "&LOWER(SUBSTITUTE(Cálculos!C51,"_"," "))&". ","")&"Este diagnóstico es orientador y debe integrarse con anamnesis alimentaria, examen físico, antecedentes clínicos y evolución longitudinal."))))) -> No se identifican alteraciones antropométricas en el indicador principal; se recomienda mantener seguimiento periódico de la trayectoria de crecimiento. Este diagnóstico es orientador y debe integrarse con anamnesis alimentaria, examen físico, antecedentes clínicos y evolución longitudinal.
B20: CONSIDERACIONES CLÍNICAS Y ALERTAS
B21: =IF(Ingreso!C2="","",IF(Cálculos!C53<>"OK","La interpretación presenta una limitación: "&LOWER(SUBSTITUTE(Cálculos!C53,"_"," "))&". "&"Revise los datos de ingreso, el dominio etario o la población seleccionada antes de utilizar el resultado.",IF(H9<>"OK","La clasificación integrada no pudo completarse: "&LOWER(SUBSTITUTE(H9,"_"," "))&".",IF(OR(E9="Desnutrición",E9="Obesidad severa"),"Hallazgo de mayor prioridad clínica. Se recomienda evaluación nutricional completa, revisión de la velocidad de crecimiento y derivación médica según el contexto.",IF(OR(E9="Riesgo de desnutrir",E9="Sobrepeso",E9="Obesidad"),"Hallazgo que requiere seguimiento nutricional, revisión de la trayectoria de crecimiento y evaluación de factores alimentarios, clínicos y familiares.","Sin alertas automáticas de dominio o coherencia. Mantener interpretación clínica y seguimiento periódico."))))) -> Sin alertas automáticas de dominio o coherencia. Mantener interpretación clínica y seguimiento periódico.

Sheet GRÁFICO
A1: NUTRIMETRÍA · NMX-14 · Perfil de puntajes z
A2: Posición del paciente frente a la referencia OMS/MINSAL (banda normal −2 a +2)
A5: Indicador | B5: Puntaje z | C5: Registro DE
A6: IMC / edad | B6: =IF(ISNUMBER(Cálculos!C11),Cálculos!C11,"") -> 0.52632207 | C6: =IF(Interpretación!E3="","—",Interpretación!E3) -> Normal
A7: Peso / edad | B7: =IF(ISNUMBER(Cálculos!C16),Cálculos!C16,"") | C7: =IF(Interpretación!E4="","—",Interpretación!E4) -> —
A8: Talla / edad | B8: =IF(ISNUMBER(Cálculos!C22),Cálculos!C22,"") -> -0.62820513 | C8: =IF(Interpretación!E5="","—",Interpretación!E5) -> Normal
A9: Peso / talla | B9: =IF(ISNUMBER(Cálculos!C33),Cálculos!C33,"") | C9: =IF(Interpretación!E7="","—",Interpretación!E7) -> —
A10: INTEGRADO (primario) | B10: =IF(ISNUMBER(Cálculos!C35),Cálculos!C35,"") -> 0.52632207 | C10: =IF(Interpretación!E9="","—",Interpretación!E9) -> Normal
A13: Serie (para el gráfico)
A14: Indicador | B14: z
A15: IMC / edad | B15: =IF(ISNUMBER(Cálculos!C11),Cálculos!C11,0) -> 0.52632207
A16: Peso / edad | B16: =IF(ISNUMBER(Cálculos!C16),Cálculos!C16,0) -> 0
A17: Talla / edad | B17: =IF(ISNUMBER(Cálculos!C22),Cálculos!C22,0) -> -0.62820513
A18: Peso / talla | B18: =IF(ISNUMBER(Cálculos!C33),Cálculos!C33,0) -> 0
A19: INTEGRADO (primario) | B19: =IF(ISNUMBER(Cálculos!C35),Cálculos!C35,0) -> 0.52632207
A21: La banda −2 a +2 DE es el rango normal. ≤ −2 sugiere déficit; ≥ +2 sugiere exceso. Interpretar junto al canal de crecimiento y la evaluación clínica.

Sheet Informe
A1: NUTRIMETRÍA · INFORME DE EVALUACIÓN NUTRICIONAL
B5: Nombre del Paciente: | C5: =Ingreso!C2 -> PACIENTE-X01
B6: Edad: | C6: =Cálculos!C6 & " meses" -> 192 meses
B8: DIAGNÓSTICO NUTRICIONAL: | C8: =Interpretación!B15 & CHAR(10) & CHAR(10) & Interpretación!B16 & CHAR(10) & CHAR(10) & Interpretación!B17 & CHAR(10) & CHAR(10) & Interpretación!B18 -> Evaluación nutricional de PACIENTE-X01, niño de 16 años y 0 meses. Diagnóstico nutricional de tamizaje: estado nutricional normal según la clasificación clínica MINSAL aplicable a su edad. IMC para la edad: normal. Talla para la edad: normal. Perímetro de cintura: normal. No se identifican alteraciones antropométricas en el indicador principal; se recomienda mantener seguimiento periódico de la trayectoria de crecimiento. Este diagnóstico es orientador y debe integrarse con anamnesis alimentaria, examen físico, antecedentes clínicos y evolución longitudinal.
B17: Z-Score | C17: =Cálculos!C35 -> 0.52632207
B34: El puntaje Z (Z-score) en los patrones de crecimiento del MINSAL (basados en los estándares de la OMS) sirve para comparar las medidas antropométricas de un niño con las de una población de referencia del mismo sexo y edad. Es la forma más precisa de evaluar el estado nutricional infantil.
A40: ¿Cómo se interpreta? Puntaje Z Interpretación 0 Exactamente en la mediana (valor esperado). +1 Una desviación estándar sobre la mediana. +2 Muy por encima de la mediana. +3 Extremadamente por encima de la mediana. -1 Una desviación estándar bajo la mediana. -2 Muy por debajo de la mediana. -3 Extremadamente por debajo de la mediana.
A48: Documento de apoyo. EXACTITUD MATEMÁTICA ≠ VALIDACIÓN CLÍNICA. No constituye diagnóstico médico automático.

Sheet FUENTES
A1: NUTRIMETRÍA · TRAZABILIDAD OMS / MINSAL / UDD
A2: OMS y MINSAL mantienen prioridad. El Manual UDD se registra únicamente como fuente secundaria de protocolos, inventario y contraste.
A4: Documento | B4: Organismo | C4: Año | D4: Resolución | E4: Población | F4: Páginas/Sección | G4: Uso en NMX-14 | H4: Estado documental
A5: Norma Técnica para la Supervisión de Salud Integral de Niños y Niñas de 0 a 9 años en APS, N.º 218, 2.ª edición | B5: MINSAL | C5: 2021 | D5: Resolución Exenta N.º 55, 18-10-2021 | E5: 0–9 años | F5: Cap. 3; pp. 146 y 160–162 | G5: Prematuridad y situaciones especiales | H5: VERIFICADO | I5: Fecha cotejo | J5: Licencia | K5: Nivel
A6: Patrones de crecimiento para la evaluación nutricional de niños, niñas y adolescentes, desde el nacimiento hasta los 19 años | B6: MINSAL | C6: 2018 | D6: No identificada en el documento revisado | E6: Nacimiento–19 años | F6: pp. 7–11 y tablas | G6: Clasificación MINSAL, edad, PCe y cintura | H6: VERIFICADO_CON_RESOLUCIÓN_NO_IDENTIFICADA | I6: 2026-07-17 | J6: Tablas oficiales OMS, uso público | K6: A
A7: WHO Child Growth Standards | B7: OMS | C7: 2006 | D7: No aplica | E7: 0–60 meses | F7: Web y tablas Excel oficiales | G7: LMS P/E, P/L, P/Estatura; curvas T/E y PCe | H7: VERIFICADO | I7: 2026-07-17 | J7: Tablas oficiales OMS, uso público | K7: A
A8: WHO Growth Reference 2007 | B8: OMS | C8: 2007 | D8: No aplica | E8: 61–228 meses | F8: Web oficial e indicadores | G8: IMC/E y T/E 5–19 años | H8: VERIFICADO | I8: 2026-07-17 | J8: Artículo con derechos; solo la ecuación | K8: B
A9: Child Growth Monitoring: A Technical Guide | B9: OMS/EMRO | C9: 2025 | D9: No aplica | E9: Menores de 5 años | F9: p. 33, tabla 3 | G9: Clasificación OMS y regla de límite exacto menos severo | H9: VERIFICADO | I9: 2026-07-17 | J9: Documento oficial, uso público | K9: A
A10: Manual de Evaluación Nutricional UDD | B10: Universidad del Desarrollo | C10: 2018 | D10: No aplica | E10: Curso de vida y poblaciones especiales | F10: pp. 47–68; 105–114 | G10: Protocolos y mapa de candidatos; no reemplaza reglas oficiales | H10: FUENTE_SECUNDARIA_CONTROLADA | I10: 2026-08-06 | J10: Documento académico; atribución | K10: C
A11: FUENTES WEB OFICIALES | I11: 2026-07-17 | J11: Documento oficial, uso público | K11: A
A12: Fuente | B12: URL oficial | C12: Contenido usado | D12: Fecha de consulta
A13: MINSAL — actualización NT N.º218 | B13: https://www.minsal.cl/ministerio-de-salud-presenta-actualizacion-de-norma-tecnica-para-la-supervision-de-salud-integral-de-ninos-y-ninas-de-0-a-9-anos-en-aps/ | C13: Identificación y contexto de actualización | D13: 05-08-2026
A14: MINSAL — Salud infantil | B14: https://www.minsal.cl/salud-infantil/ | C14: Acceso institucional a documentos infantiles | D14: 05-08-2026
A15: OMS — Child Growth Standards | B15: https://www.who.int/tools/child-growth-standards | C15: Dominio 0–60 meses y tablas oficiales | D15: 05-08-2026
A16: OMS — Growth Reference 5–19 | B16: https://www.who.int/tools/growth-reference-data-for-5to19-years | C16: Dominio 61–228 meses | D16: 05-08-2026
A17: OMS — BMI-for-age 5–19 | B17: https://www.who.int/tools/growth-reference-data-for-5to19-years/indicators/bmi-for-age | C17: Puntos de corte OMS | D17: 05-08-2026
A18: Amezquita y Hodgson. Estimación de talla en PC | B18: Rev Chil Pediatr | C18: 2014 | D18: No aplica | E18: Parálisis cerebral | F18: 85(1):22–30; DOI 10.4067/S0370-41062014000100003 | G18: Validación chilena; motor en NMX-28 | H18: VERIFICADO | I18: 2026-08-06 | J18: Artículo con derechos | K18: A/B
A19: Zemel et al. Growth Charts for Down Syndrome | B19: Pediatrics | C19: 2015 | D19: No aplica | E19: Síndrome de Down | F19: 136(5):e1204–e1211; DOI 10.1542/peds.2015-1652 | G19: Percentiles manuales CDC + MINSAL | H19: VERIFICADO_CON_ENTRADA_MANUAL | I19: 2026-08-06 | J19: No redistribuir gráficas | K19: A/B
A20: MINSAL NT N.º218 — edad biológica | B20: MINSAL | C20: 2021 | D20: Res. Ex. N.º55 | E20: Escolares/adolescentes | F20: Cap.2 p.129 | G20: Rangos, >1 año y excepción SD | H20: VERIFICADO | I20: 2026-08-06 | J20: Documento oficial | K20: A
A21: Brooks et al. Growth charts in cerebral palsy | B21: Pediatrics | C21: 2011 | D21: No aplica | E21: Parálisis cerebral | F21: 128:e299; DOI 10.1542/peds.2010-2801 | G21: Curvas por sexo/GMFCS | H21: VERIFICADO_NO_AUTOMATIZADO | I21: 2026-08-06 | J21: Gráficas con derechos | K21: A/B
A22: GMFCS Expanded & Revised | B22: CanChild | C22: 2007/actualizado | D22: No aplica | E22: Parálisis cerebral | F22: 5 niveles y bandas etarias | G22: Nivel informado; instrumento no incorporado | H22: VERIFICADO_CON_RESTRICCIÓN_DE_LICENCIA | I22: 2026-08-06 | J22: Licencia EHR/comercial | K22: A
A23: WHO Head circumference-for-age 0–5 | B23: OMS | C23: 2006 | D23: No aplica | E23: 0–60 meses | F23: Tablas Excel oficiales por sexo | G23: PCe/E y NANEAS | H23: VERIFICADO_E_IMPORTADO | I23: 2026-08-06 | J23: Tablas OMS | K23: A
A25: Fuente | B25: URL oficial | C25: Contenido | D25: Consulta
A26: MINSAL NT218 capítulo 2 | B26: https://www.medicinafamiliar.cl/mf/wordpress/wp-content/uploads/2021/12/capitulo-2.pdf | C26: PCe y edad biológica | D26: 06-08-2026
A27: MINSAL NT218 capítulo 3 | B27: https://www.minsal.cl/wp-content/uploads/2021/12/Capi%CC%81tulo-3-Web.pdf | C27: Prematuridad y Down | D27: 06-08-2026
A28: CDC Down charts | B28: https://www.cdc.gov/birth-defects/hcp/down-syndrome-growth-charts/index.html | C28: Gráficas Zemel | D28: 06-08-2026
A29: Zemel DOI | B29: https://doi.org/10.1542/peds.2015-1652 | C29: Artículo primario | D29: 06-08-2026
A30: Brooks PubMed | B30: https://pubmed.ncbi.nlm.nih.gov/21768315/ | C30: Curvas PC | D30: 06-08-2026
A31: CanChild GMFCS | B31: https://canchild.ca/resources/42-gmfcs-e-r/ | C31: GMFCS y licencia | D31: 06-08-2026
A32: Amezquita SciELO | B32: https://www.scielo.cl/scielo.php?pid=S0370-41062014000100003&script=sci_arttext | C32: Talla PC Chile | D32: 06-08-2026

Sheet Tablas_OMS
A1: Meses | B1: L_IMC | C1: M_IMC | D1: S_IMC | F1: Meses | G1: L_IMC_Niños | H1: M_IMC_Niños | I1: S_IMC_Niños | K1: Meses_PE_Niñas | L1: L_PE_Niñas | M1: M_PE_Niñas | N1: S_PE_Niñas | P1: Meses_PE_Niños | Q1: L_PE_Niños | R1: M_PE_Niños | S1: S_PE_Niños | U1: Meses_TE_Niñas | V1: TE_Menos2_Niñas | W1: TE_Menos1_Niñas | X1: TE_Mediana_Niñas | Y1: TE_Mas1_Niñas | Z1: TE_Mas2_Niñas | AB1: Meses_TE_Niños | AC1: TE_Menos2_Niños | AD1: TE_Menos1_Niños | AE1: TE_Mediana_Niños | AF1: TE_Mas1_Niños | AG1: TE_Mas2_Niños | AI1: Meses_PC_Niñas | AJ1: PC_Menos2_Niñas | AK1: PC_Menos1_Niñas | AL1: PC_Mediana_Niñas | AM1: PC_Mas1_Niñas | AN1: PC_Mas2_Niñas | AP1: Meses_PC_Niños | AQ1: PC_Menos2_Niños | AR1: PC_Menos1_Niños | AS1: PC_Mediana_Niños | AT1: PC_Mas1_Niños | AU1: PC_Mas2_Niños | AW1: Talla_cm_Niñas | AX1: L_PT_Niñas | AY1: M_PT_Niñas | AZ1: S_PT_Niñas | BA1: PT_Menos2_Niñas | BB1: PT_Menos1_Niñas | BC1: PT_Mediana_Niñas | BD1: PT_Mas1_Niñas | BE1: PT_Mas2_Niñas | BG1: Talla_cm_Niños | BH1: L_PT_Niños | BI1: M_PT_Niños | BJ1: S_PT_Niños | BK1: PT_Menos2_Niños | BL1: PT_Menos1_Niños | BM1: PT_Mediana_Niños | BN1: PT_Mas1_Niños | BO1: PT_Mas2_Niños | BQ1: Edad_Años_Niñas | BR1: p10_Niñas | BS1: p25_Niñas | BT1: p50_Niñas | BU1: p75_Niñas | BV1: p90_Niñas | BX1: Edad_Años_Niños | BY1: p10_Niños | BZ1: p25_Niños | CA1: p50_Niños | CB1: p75_Niños | CC1: p90_Niños
A2: 61 | B2: -0.8886 | C2: 15.2441 | D2: 0.09692 | F2: 61 | G2: -0.7387 | H2: 15.2641 | I2: 0.0839 | K2: 0 | L2: 0.3809 | M2: 3.2322 | N2: 0.14171 | P2: 0 | Q2: 0.3487 | R2: 3.3464 | S2: 0.14602 | U2: 0 | V2: 45.4 | W2: 47.3 | X2: 49.1 | Y2: 51 | Z2: 52.9 | AB2: 0 | AC2: 46.1 | AD2: 48 | AE2: 49.9 | AF2: 51.8 | AG2: 53.7 | AI2: 0 | AJ2: 31.5 | AK2: 32.7 | AL2: 33.9 | AM2: 35.1 | AN2: 36.2 | AP2: 0 | AQ2: 31.9 | AR2: 33.2 | AS2: 34.5 | AT2: 35.7 | AU2: 37 | AW2: 45 | AX2: -0.3833 | AY2: 2.4607 | AZ2: 0.09029 | BA2: 2.1 | BB2: 2.3 | BC2: 2.5 | BD2: 2.7 | BE2: 3 | BG2: 45 | BH2: -0.3521 | BI2: 2.441 | BJ2: 0.09182 | BK2: 2 | BL2: 2.2 | BM2: 2.4 | BN2: 2.7 | BO2: 3 | BQ2: 5 | BR2: 48.5 | BS2: 50.1 | BT2: 53 | BU2: 56.7 | BV2: 61.4 | BX2: 5 | BY2: 48.4 | BZ2: 50.6 | CA2: 53.2 | CB2: 56.4 | CC2: 61
A3: 62 | B3: -0.9068 | C3: 15.2434 | D3: 0.09738 | F3: 62 | G3: -0.7621 | H3: 15.2616 | I3: 0.08414 | K3: 1 | L3: 0.1714 | M3: 4.1873 | N3: 0.13724 | P3: 1 | Q3: 0.2297 | R3: 4.4709 | S3: 0.13395 | U3: 1 | V3: 49.8 | W3: 51.7 | X3: 53.7 | Y3: 55.6 | Z3: 57.6 | AB3: 1 | AC3: 50.8 | AD3: 52.8 | AE3: 54.7 | AF3: 56.7 | AG3: 58.6 | AI3: 1 | AJ3: 34.2 | AK3: 35.4 | AL3: 36.5 | AM3: 37.7 | AN3: 38.9 | AP3: 1 | AQ3: 34.9 | AR3: 36.1 | AS3: 37.3 | AT3: 38.4 | AU3: 39.6 | AW3: 45.5 | AX3: -0.3833 | AY3: 2.5457 | AZ3: 0.09033 | BA3: 2.1 | BB3: 2.3 | BC3: 2.5 | BD3: 2.8 | BE3: 3.1 | BG3: 45.5 | BH3: -0.3521 | BI3: 2.5244 | BJ3: 0.09153 | BK3: 2.1 | BL3: 2.3 | BM3: 2.5 | BN3: 2.8 | BO3: 3.1 | BQ3: 6 | BR3: 50.1 | BS3: 51.8 | BT3: 55 | BU3: 59.1 | BV3: 64.1 | BX3: 6 | BY3: 50.1 | BZ3: 52.4 | CA3: 55.2 | CB3: 59 | CC3: 64.4
A4: 63 | B4: -0.9248 | C4: 15.2433 | D4: 0.09783 | F4: 63 | G4: -0.7856 | H4: 15.2604 | I4: 0.08439 | K4: 2 | L4: 0.0962 | M4: 5.1282 | N4: 0.13 | P4: 2 | Q4: 0.197 | R4: 5.5675 | S4: 0.12385 | U4: 2 | V4: 53 | W4: 55 | X4: 57.1 | Y4: 59.1 | Z4: 61.1 | AB4: 2 | AC4: 54.4 | AD4: 56.4 | AE4: 58.4 | AF4: 60.4 | AG4: 62.4 | AI4: 2 | AJ4: 35.8 | AK4: 37 | AL4: 38.3 | AM4: 39.5 | AN4: 40.7 | AP4: 2 | AQ4: 36.8 | AR4: 38 | AS4: 39.1 | AT4: 40.3 | AU4: 41.5 | AW4: 46 | AX4: -0.3833 | AY4: 2.6306 | AZ4: 0.09037 | BA4: 2.2 | BB4: 2.4 | BC4: 2.6 | BD4: 2.9 | BE4: 3.2 | BG4: 46 | BH4: -0.3521 | BI4: 2.6077 | BJ4: 0.09124 | BK4: 2.2 | BL4: 2.4 | BM4: 2.6 | BN4: 2.9 | BO4: 3.1 | BQ4: 7 | BR4: 51.6 | BS4: 53.5 | BT4: 56.9 | BU4: 61.5 | BV4: 67.5 | BX4: 7 | BY4: 51.8 | BZ4: 54.3 | CA4: 57.2 | CB4: 61.5 | CC4: 67.8
A5: 64 | B5: -0.9427 | C5: 15.2438 | D5: 0.09829 | F5: 64 | G5: -0.8089 | H5: 15.2605 | I5: 0.08464 | K5: 3 | L5: 0.0402 | M5: 5.8458 | N5: 0.12619 | P5: 3 | Q5: 0.1738 | R5: 6.3762 | S5: 0.11727 | U5: 3 | V5: 55.6 | W5: 57.7 | X5: 59.8 | Y5: 61.9 | Z5: 64 | AB5: 3 | AC5: 57.3 | AD5: 59.4 | AE5: 61.4 | AF5: 63.5 | AG5: 65.5 | AI5: 3 | AJ5: 37.1 | AK5: 38.3 | AL5: 39.5 | AM5: 40.8 | AN5: 42 | AP5: 3 | AQ5: 38.1 | AR5: 39.3 | AS5: 40.5 | AT5: 41.7 | AU5: 42.9 | AW5: 46.5 | AX5: -0.3833 | AY5: 2.7155 | AZ5: 0.0904 | BA5: 2.3 | BB5: 2.5 | BC5: 2.7 | BD5: 3 | BE5: 3.3 | BG5: 46.5 | BH5: -0.3521 | BI5: 2.6913 | BJ5: 0.09094 | BK5: 2.3 | BL5: 2.5 | BM5: 2.7 | BN5: 3 | BO5: 3.2 | BQ5: 8 | BR5: 53.2 | BS5: 55.2 | BT5: 58.9 | BU5: 63.9 | BV5: 70.5 | BX5: 8 | BY5: 53.5 | BZ5: 56.1 | CA5: 59.3 | CB5: 64.1 | CC5: 71.2
A6: 65 | B6: -0.9605 | C6: 15.2448 | D6: 0.09875 | F6: 65 | G6: -0.8322 | H6: 15.2619 | I6: 0.0849 | K6: 4 | L6: -0.005 | M6: 6.4237 | N6: 0.12402 | P6: 4 | Q6: 0.1553 | R6: 7.0023 | S6: 0.11316 | U6: 4 | V6: 57.8 | W6: 59.9 | X6: 62.1 | Y6: 64.3 | Z6: 66.4 | AB6: 4 | AC6: 59.7 | AD6: 61.8 | AE6: 63.9 | AF6: 66 | AG6: 68 | AI6: 4 | AJ6: 38.1 | AK6: 39.3 | AL6: 40.6 | AM6: 41.8 | AN6: 43.1 | AP6: 4 | AQ6: 39.2 | AR6: 40.4 | AS6: 41.6 | AT6: 42.8 | AU6: 44 | AW6: 47 | AX6: -0.3833 | AY6: 2.8007 | AZ6: 0.09044 | BA6: 2.4 | BB6: 2.6 | BC6: 2.8 | BD6: 3.1 | BE6: 3.4 | BG6: 47 | BH6: -0.3521 | BI6: 2.7755 | BJ6: 0.09065 | BK6: 2.3 | BL6: 2.5 | BM6: 2.8 | BN6: 3 | BO6: 3.3 | BQ6: 9 | BR6: 54.8 | BS6: 56.9 | BT6: 60.8 | BU6: 66.3 | BV6: 73.6 | BX6: 9 | BY6: 55.3 | BZ6: 58 | CA6: 61.3 | CB6: 66.6 | CC6: 74.6
A7: 66 | B7: -0.978 | C7: 15.2464 | D7: 0.0992 | F7: 66 | G7: -0.8554 | H7: 15.2645 | I7: 0.08516 | K7: 5 | L7: -0.043 | M7: 6.8985 | N7: 0.12274 | P7: 5 | Q7: 0.1395 | R7: 7.5105 | S7: 0.1108 | U7: 5 | V7: 59.6 | W7: 61.8 | X7: 64 | Y7: 66.2 | Z7: 68.5 | AB7: 5 | AC7: 61.7 | AD7: 63.8 | AE7: 65.9 | AF7: 68 | AG7: 70.1 | AI7: 5 | AJ7: 38.9 | AK7: 40.2 | AL7: 41.5 | AM7: 42.7 | AN7: 44 | AP7: 5 | AQ7: 40.1 | AR7: 41.4 | AS7: 42.6 | AT7: 43.8 | AU7: 45 | AW7: 47.5 | AX7: -0.3833 | AY7: 2.8867 | AZ7: 0.09048 | BA7: 2.4 | BB7: 2.6 | BC7: 2.9 | BD7: 3.2 | BE7: 3.5 | BG7: 47.5 | BH7: -0.3521 | BI7: 2.8609 | BJ7: 0.09036 | BK7: 2.4 | BL7: 2.6 | BM7: 2.9 | BN7: 3.1 | BO7: 3.4 | BQ7: 10 | BR7: 56.3 | BS7: 58.6 | BT7: 62.8 | BU7: 68.7 | BV7: 76.6 | BX7: 10 | BY7: 57 | BZ7: 59.8 | CA7: 63.3 | CB7: 69.2 | CC7: 78
A8: 67 | B8: -0.9954 | C8: 15.2487 | D8: 0.09966 | F8: 67 | G8: -0.8785 | H8: 15.2684 | I8: 0.08543 | K8: 6 | L8: -0.0756 | M8: 7.297 | N8: 0.12204 | P8: 6 | Q8: 0.1257 | R8: 7.934 | S8: 0.10958 | U8: 6 | V8: 61.2 | W8: 63.5 | X8: 65.7 | Y8: 68 | Z8: 70.3 | AB8: 6 | AC8: 63.3 | AD8: 65.5 | AE8: 67.6 | AF8: 69.8 | AG8: 71.9 | AI8: 6 | AJ8: 39.6 | AK8: 40.9 | AL8: 42.2 | AM8: 43.5 | AN8: 44.8 | AP8: 6 | AQ8: 40.9 | AR8: 42.1 | AS8: 43.3 | AT8: 44.6 | AU8: 45.8 | AW8: 48 | AX8: -0.3833 | AY8: 2.9741 | AZ8: 0.09052 | BA8: 2.5 | BB8: 2.7 | BC8: 3 | BD8: 3.3 | BE8: 3.6 | BG8: 48 | BH8: -0.3521 | BI8: 2.948 | BJ8: 0.09007 | BK8: 2.5 | BL8: 2.7 | BM8: 2.9 | BN8: 3.2 | BO8: 3.6 | BQ8: 11 | BR8: 57.9 | BS8: 60.3 | BT8: 64.8 | BU8: 71.1 | BV8: 79.7 | BX8: 11 | BY8: 58.7 | BZ8: 61.7 | CA8: 65.4 | CB8: 71.7 | CC8: 81.4
A9: 68 | B9: -1.0126 | C9: 15.2516 | D9: 0.10012 | F9: 68 | G9: -0.9015 | H9: 15.2737 | I9: 0.0857 | K9: 7 | L9: -0.1039 | M9: 7.6422 | N9: 0.12178 | P9: 7 | Q9: 0.1134 | R9: 8.297 | S9: 0.10902 | U9: 7 | V9: 62.7 | W9: 65 | X9: 67.3 | Y9: 69.6 | Z9: 71.9 | AB9: 7 | AC9: 64.8 | AD9: 67 | AE9: 69.2 | AF9: 71.3 | AG9: 73.5 | AI9: 7 | AJ9: 40.2 | AK9: 41.5 | AL9: 42.8 | AM9: 44.1 | AN9: 45.5 | AP9: 7 | AQ9: 41.5 | AR9: 42.7 | AS9: 44 | AT9: 45.2 | AU9: 46.4 | AW9: 48.5 | AX9: -0.3833 | AY9: 3.0636 | AZ9: 0.09056 | BA9: 2.6 | BB9: 2.8 | BC9: 3.1 | BD9: 3.4 | BE9: 3.7 | BG9: 48.5 | BH9: -0.3521 | BI9: 3.0377 | BJ9: 0.08977 | BK9: 2.6 | BL9: 2.8 | BM9: 3 | BN9: 3.3 | BO9: 3.7 | BQ9: 12 | BR9: 59.5 | BS9: 62 | BT9: 66.7 | BU9: 73.5 | BV9: 82.7 | BX9: 12 | BY9: 60.5 | BZ9: 63.5 | CA9: 67.4 | CB9: 74.3 | CC9: 84.4
A10: 69 | B10: -1.0296 | C10: 15.2551 | D10: 0.10058 | F10: 69 | G10: -0.9243 | H10: 15.2801 | I10: 0.08597 | K10: 8 | L10: -0.1288 | M10: 7.9487 | N10: 0.12181 | P10: 8 | Q10: 0.1021 | R10: 8.6151 | S10: 0.10882 | U10: 8 | V10: 64 | W10: 66.4 | X10: 68.7 | Y10: 71.1 | Z10: 73.5 | AB10: 8 | AC10: 66.2 | AD10: 68.4 | AE10: 70.6 | AF10: 72.8 | AG10: 75 | AI10: 8 | AJ10: 40.7 | AK10: 42 | AL10: 43.4 | AM10: 44.7 | AN10: 46 | AP10: 8 | AQ10: 42 | AR10: 43.3 | AS10: 44.5 | AT10: 45.8 | AU10: 47 | AW10: 49 | AX10: -0.3833 | AY10: 3.156 | AZ10: 0.0906 | BA10: 2.6 | BB10: 2.9 | BC10: 3.2 | BD10: 3.5 | BE10: 3.8 | BG10: 49 | BH10: -0.3521 | BI10: 3.1308 | BJ10: 0.08948 | BK10: 2.6 | BL10: 2.9 | BM10: 3.1 | BN10: 3.4 | BO10: 3.8 | BQ10: 13 | BR10: 61 | BS10: 63.7 | BT10: 68.7 | BU10: 75.9 | BV10: 85.9 | BX10: 13 | BY10: 62.2 | BZ10: 65.4 | CA10: 69.5 | CB10: 76.8 | CC10: 88.2
A11: 70 | B11: -1.0464 | C11: 15.2592 | D11: 0.10104 | F11: 70 | G11: -0.9471 | H11: 15.2877 | I11: 0.08625 | K11: 9 | L11: -0.1507 | M11: 8.2254 | N11: 0.12199 | P11: 9 | Q11: 0.0917 | R11: 8.9014 | S11: 0.10881 | U11: 9 | V11: 65.3 | W11: 67.7 | X11: 70.1 | Y11: 72.6 | Z11: 75 | AB11: 9 | AC11: 67.5 | AD11: 69.7 | AE11: 72 | AF11: 74.2 | AG11: 76.5 | AI11: 9 | AJ11: 41.2 | AK11: 42.5 | AL11: 43.8 | AM11: 45.2 | AN11: 46.5 | AP11: 9 | AQ11: 42.5 | AR11: 43.7 | AS11: 45 | AT11: 46.3 | AU11: 47.5 | AW11: 49.5 | AX11: -0.3833 | AY11: 3.252 | AZ11: 0.09064 | BA11: 2.7 | BB11: 3 | BC11: 3.3 | BD11: 3.6 | BE11: 3.9 | BG11: 49.5 | BH11: -0.3521 | BI11: 3.2276 | BJ11: 0.08919 | BK11: 2.7 | BL11: 3 | BM11: 3.2 | BN11: 3.5 | BO11: 3.9 | BQ11: 14 | BR11: 62.6 | BS11: 65.4 | BT11: 70.6 | BU11: 78.3 | BV11: 88.8 | BX11: 14 | BY11: 63.9 | BZ11: 67.2 | CA11: 71.5 | CB11: 79.4 | CC11: 91.6
A12: 71 | B12: -1.063 | C12: 15.2641 | D12: 0.10149 | F12: 71 | G12: -0.9697 | H12: 15.2965 | I12: 0.08653 | K12: 10 | L12: -0.17 | M12: 8.48 | N12: 0.12223 | P12: 10 | Q12: 0.082 | R12: 9.1649 | S12: 0.10891 | U12: 10 | V12: 66.5 | W12: 69 | X12: 71.5 | Y12: 73.9 | Z12: 76.4 | AB12: 10 | AC12: 68.7 | AD12: 71 | AE12: 73.3 | AF12: 75.6 | AG12: 77.9 | AI12: 10 | AJ12: 41.5 | AK12: 42.9 | AL12: 44.2 | AM12: 45.6 | AN12: 46.9 | AP12: 10 | AQ12: 42.9 | AR12: 44.1 | AS12: 45.4 | AT12: 46.7 | AU12: 47.9 | AW12: 50 | AX12: -0.3833 | AY12: 3.3518 | AZ12: 0.09068 | BA12: 2.8 | BB12: 3.1 | BC12: 3.4 | BD12: 3.7 | BE12: 4 | BG12: 50 | BH12: -0.3521 | BI12: 3.3278 | BJ12: 0.0889 | BK12: 2.8 | BL12: 3 | BM12: 3.3 | BN12: 3.6 | BO12: 4 | BQ12: 15 | BR12: 64.2 | BS12: 67.1 | BT12: 72.6 | BU12: 80.7 | BV12: 91.9 | BX12: 15 | BY12: 65.6 | BZ12: 69.1 | CA12: 73.5 | CB12: 81.9 | CC12: 95
A13: 72 | B13: -1.0794 | C13: 15.2697 | D13: 0.10195 | F13: 72 | G13: -0.9921 | H13: 15.3062 | I13: 0.08682 | K13: 11 | L13: -0.1872 | M13: 8.7192 | N13: 0.12247 | P13: 11 | Q13: 0.073 | R13: 9.4122 | S13: 0.10906 | U13: 11 | V13: 67.7 | W13: 70.3 | X13: 72.8 | Y13: 75.3 | Z13: 77.8 | AB13: 11 | AC13: 69.9 | AD13: 72.2 | AE13: 74.5 | AF13: 76.9 | AG13: 79.2 | AI13: 11 | AJ13: 41.9 | AK13: 43.2 | AL13: 44.6 | AM13: 45.9 | AN13: 47.3 | AP13: 11 | AQ13: 43.2 | AR13: 44.5 | AS13: 45.8 | AT13: 47 | AU13: 48.3 | AW13: 50.5 | AX13: -0.3833 | AY13: 3.4557 | AZ13: 0.09072 | BA13: 2.9 | BB13: 3.2 | BC13: 3.5 | BD13: 3.8 | BE13: 4.2 | BG13: 50.5 | BH13: -0.3521 | BI13: 3.4311 | BJ13: 0.08861 | BK13: 2.9 | BL13: 3.1 | BM13: 3.4 | BN13: 3.8 | BO13: 4.1 | BQ13: 16 | BR13: 65.7 | BS13: 68.8 | BT13: 74.6 | BU13: 83.1 | BV13: 94.9 | BX13: 16 | BY13: 67.4 | BZ13: 70.9 | CA13: 75.6 | CB13: 84.5 | CC13: 98.4
A14: 73 | B14: -1.0956 | C14: 15.276 | D14: 0.10241 | F14: 73 | G14: -1.0144 | H14: 15.3169 | I14: 0.08711 | K14: 12 | L14: -0.2024 | M14: 8.9481 | N14: 0.12268 | P14: 12 | Q14: 0.0644 | R14: 9.6479 | S14: 0.10925 | U14: 12 | V14: 68.9 | W14: 71.4 | X14: 74 | Y14: 76.6 | Z14: 79.2 | AB14: 12 | AC14: 71 | AD14: 73.4 | AE14: 75.7 | AF14: 78.1 | AG14: 80.5 | AI14: 12 | AJ14: 42.2 | AK14: 43.5 | AL14: 44.9 | AM14: 46.3 | AN14: 47.6 | AP14: 12 | AQ14: 43.5 | AR14: 44.8 | AS14: 46.1 | AT14: 47.4 | AU14: 48.6 | AW14: 51 | AX14: -0.3833 | AY14: 3.5636 | AZ14: 0.09076 | BA14: 3 | BB14: 3.3 | BC14: 3.6 | BD14: 3.9 | BE14: 4.3 | BG14: 51 | BH14: -0.3521 | BI14: 3.5376 | BJ14: 0.08831 | BK14: 3 | BL14: 3.2 | BM14: 3.5 | BN14: 3.9 | BO14: 4.2 | BQ14: 17 | BR14: 67.3 | BS14: 70.5 | BT14: 76.5 | BU14: 85.5 | BV14: 98 | BX14: 17 | BY14: 69.1 | BZ14: 72.8 | CA14: 77.6 | CB14: 87 | CC14: 101.8
A15: 74 | B15: -1.1115 | C15: 15.2831 | D15: 0.10287 | F15: 74 | G15: -1.0365 | H15: 15.3285 | I15: 0.08741 | U15: 13 | V15: 70 | W15: 72.6 | X15: 75.2 | Y15: 77.8 | Z15: 80.5 | AB15: 13 | AC15: 72.1 | AD15: 74.5 | AE15: 76.9 | AF15: 79.3 | AG15: 81.8 | AI15: 13 | AJ15: 42.4 | AK15: 43.8 | AL15: 45.2 | AM15: 46.5 | AN15: 47.9 | AP15: 13 | AQ15: 43.8 | AR15: 45 | AS15: 46.3 | AT15: 47.6 | AU15: 48.9 | AW15: 51.5 | AX15: -0.3833 | AY15: 3.6754 | AZ15: 0.0908 | BA15: 3.1 | BB15: 3.4 | BC15: 3.7 | BD15: 4 | BE15: 4.4 | BG15: 51.5 | BH15: -0.3521 | BI15: 3.6477 | BJ15: 0.08801 | BK15: 3.1 | BL15: 3.3 | BM15: 3.6 | BN15: 4 | BO15: 4.4 | BQ15: 18 | BR15: 68.9 | BS15: 72.2 | BT15: 78.5 | BU15: 87.9 | BV15: 101 | BX15: 18 | BY15: 70.8 | BZ15: 74.6 | CA15: 79.6 | CB15: 89.6 | CC15: 105.2
A16: 75 | B16: -1.1272 | C16: 15.2911 | D16: 0.10333 | F16: 75 | G16: -1.0584 | H16: 15.3408 | I16: 0.08771 | U16: 14 | V16: 71 | W16: 73.7 | X16: 76.4 | Y16: 79.1 | Z16: 81.7 | AB16: 14 | AC16: 73.1 | AD16: 75.6 | AE16: 78 | AF16: 80.5 | AG16: 83 | AI16: 14 | AJ16: 42.7 | AK16: 44.1 | AL16: 45.4 | AM16: 46.8 | AN16: 48.2 | AP16: 14 | AQ16: 44 | AR16: 45.3 | AS16: 46.6 | AT16: 47.9 | AU16: 49.2 | AW16: 52 | AX16: -0.3833 | AY16: 3.7911 | AZ16: 0.09085 | BA16: 3.2 | BB16: 3.5 | BC16: 3.8 | BD16: 4.2 | BE16: 4.6 | BG16: 52 | BH16: -0.3521 | BI16: 3.762 | BJ16: 0.08771 | BK16: 3.2 | BL16: 3.5 | BM16: 3.8 | BN16: 4.1 | BO16: 4.5
A17: 76 | B17: -1.1427 | C17: 15.2998 | D17: 0.10379 | F17: 76 | G17: -1.0801 | H17: 15.354 | I17: 0.08802 | U17: 15 | V17: 72 | W17: 74.8 | X17: 77.5 | Y17: 80.2 | Z17: 83 | AB17: 15 | AC17: 74.1 | AD17: 76.6 | AE17: 79.1 | AF17: 81.7 | AG17: 84.2 | AI17: 15 | AJ17: 42.9 | AK17: 44.3 | AL17: 45.7 | AM17: 47 | AN17: 48.4 | AP17: 15 | AQ17: 44.2 | AR17: 45.5 | AS17: 46.8 | AT17: 48.1 | AU17: 49.4 | AW17: 52.5 | AX17: -0.3833 | AY17: 3.9105 | AZ17: 0.09089 | BA17: 3.3 | BB17: 3.6 | BC17: 3.9 | BD17: 4.3 | BE17: 4.7 | BG17: 52.5 | BH17: -0.3521 | BI17: 3.8814 | BJ17: 0.08741 | BK17: 3.3 | BL17: 3.6 | BM17: 3.9 | BN17: 4.2 | BO17: 4.6
A18: 77 | B18: -1.1579 | C18: 15.3095 | D18: 0.10425 | F18: 77 | G18: -1.1017 | H18: 15.3679 | I18: 0.08833 | U18: 16 | V18: 73 | W18: 75.8 | X18: 78.6 | Y18: 81.4 | Z18: 84.2 | AB18: 16 | AC18: 75 | AD18: 77.6 | AE18: 80.2 | AF18: 82.8 | AG18: 85.4 | AI18: 16 | AJ18: 43.1 | AK18: 44.5 | AL18: 45.9 | AM18: 47.2 | AN18: 48.6 | AP18: 16 | AQ18: 44.4 | AR18: 45.7 | AS18: 47 | AT18: 48.3 | AU18: 49.6 | AW18: 53 | AX18: -0.3833 | AY18: 4.0332 | AZ18: 0.09093 | BA18: 3.4 | BB18: 3.7 | BC18: 4 | BD18: 4.4 | BE18: 4.9 | BG18: 53 | BH18: -0.3521 | BI18: 4.006 | BJ18: 0.08711 | BK18: 3.4 | BL18: 3.7 | BM18: 4 | BN18: 4.4 | BO18: 4.8
A19: 78 | B19: -1.1728 | C19: 15.32 | D19: 0.10471 | F19: 78 | G19: -1.123 | H19: 15.3825 | I19: 0.08865 | U19: 17 | V19: 74 | W19: 76.8 | X19: 79.7 | Y19: 82.5 | Z19: 85.4 | AB19: 17 | AC19: 76 | AD19: 78.6 | AE19: 81.2 | AF19: 83.9 | AG19: 86.5 | AI19: 17 | AJ19: 43.3 | AK19: 44.7 | AL19: 46.1 | AM19: 47.4 | AN19: 48.8 | AP19: 17 | AQ19: 44.6 | AR19: 45.9 | AS19: 47.2 | AT19: 48.5 | AU19: 49.8 | AW19: 53.5 | AX19: -0.3833 | AY19: 4.1591 | AZ19: 0.09098 | BA19: 3.5 | BB19: 3.8 | BC19: 4.2 | BD19: 4.6 | BE19: 5 | BG19: 53.5 | BH19: -0.3521 | BI19: 4.1354 | BJ19: 0.08681 | BK19: 3.5 | BL19: 3.8 | BM19: 4.1 | BN19: 4.5 | BO19: 4.9
A20: 79 | B20: -1.1875 | C20: 15.3314 | D20: 0.10517 | F20: 79 | G20: -1.1441 | H20: 15.3978 | I20: 0.08898 | U20: 18 | V20: 74.9 | W20: 77.8 | X20: 80.7 | Y20: 83.6 | Z20: 86.5 | AB20: 18 | AC20: 76.9 | AD20: 79.6 | AE20: 82.3 | AF20: 85 | AG20: 87.7 | AI20: 18 | AJ20: 43.5 | AK20: 44.9 | AL20: 46.2 | AM20: 47.6 | AN20: 49 | AP20: 18 | AQ20: 44.7 | AR20: 46 | AS20: 47.4 | AT20: 48.7 | AU20: 50 | AW20: 54 | AX20: -0.3833 | AY20: 4.2875 | AZ20: 0.09102 | BA20: 3.6 | BB20: 3.9 | BC20: 4.3 | BD20: 4.7 | BE20: 5.2 | BG20: 54 | BH20: -0.3521 | BI20: 4.2693 | BJ20: 0.08651 | BK20: 3.6 | BL20: 3.9 | BM20: 4.3 | BN20: 4.7 | BO20: 5.1
A21: 80 | B21: -1.2019 | C21: 15.3439 | D21: 0.10562 | F21: 80 | G21: -1.1649 | H21: 15.4137 | I21: 0.08931 | U21: 19 | V21: 75.8 | W21: 78.8 | X21: 81.7 | Y21: 84.7 | Z21: 87.6 | AB21: 19 | AC21: 77.7 | AD21: 80.5 | AE21: 83.2 | AF21: 86 | AG21: 88.8 | AI21: 19 | AJ21: 43.6 | AK21: 45 | AL21: 46.4 | AM21: 47.8 | AN21: 49.2 | AP21: 19 | AQ21: 44.9 | AR21: 46.2 | AS21: 47.5 | AT21: 48.9 | AU21: 50.2 | AW21: 54.5 | AX21: -0.3833 | AY21: 4.4179 | AZ21: 0.09106 | BA21: 3.7 | BB21: 4 | BC21: 4.4 | BD21: 4.8 | BE21: 5.3 | BG21: 54.5 | BH21: -0.3521 | BI21: 4.4066 | BJ21: 0.08621 | BK21: 3.7 | BL21: 4 | BM21: 4.4 | BN21: 4.8 | BO21: 5.3
A22: 81 | B22: -1.216 | C22: 15.3572 | D22: 0.10608 | F22: 81 | G22: -1.1856 | H22: 15.4302 | I22: 0.08964 | U22: 20 | V22: 76.7 | W22: 79.7 | X22: 82.7 | Y22: 85.7 | Z22: 88.7 | AB22: 20 | AC22: 78.6 | AD22: 81.4 | AE22: 84.2 | AF22: 87 | AG22: 89.8 | AI22: 20 | AJ22: 43.8 | AK22: 45.2 | AL22: 46.6 | AM22: 48 | AN22: 49.4 | AP22: 20 | AQ22: 45 | AR22: 46.4 | AS22: 47.7 | AT22: 49 | AU22: 50.4 | AW22: 55 | AX22: -0.3833 | AY22: 4.5498 | AZ22: 0.0911 | BA22: 3.8 | BB22: 4.2 | BC22: 4.5 | BD22: 5 | BE22: 5.5 | BG22: 55 | BH22: -0.3521 | BI22: 4.5467 | BJ22: 0.08592 | BK22: 3.8 | BL22: 4.2 | BM22: 4.5 | BN22: 5 | BO22: 5.4
A23: 82 | B23: -1.2298 | C23: 15.3717 | D23: 0.10654 | F23: 82 | G23: -1.206 | H23: 15.4473 | I23: 0.08998 | U23: 21 | V23: 77.5 | W23: 80.6 | X23: 83.7 | Y23: 86.7 | Z23: 89.8 | AB23: 21 | AC23: 79.4 | AD23: 82.3 | AE23: 85.1 | AF23: 88 | AG23: 90.9 | AI23: 21 | AJ23: 44 | AK23: 45.3 | AL23: 46.7 | AM23: 48.1 | AN23: 49.5 | AP23: 21 | AQ23: 45.2 | AR23: 46.5 | AS23: 47.8 | AT23: 49.2 | AU23: 50.5 | AW23: 55.5 | AX23: -0.3833 | AY23: 4.6827 | AZ23: 0.09114 | BA23: 3.9 | BB23: 4.3 | BC23: 4.7 | BD23: 5.1 | BE23: 5.7 | BG23: 55.5 | BH23: -0.3521 | BI23: 4.6892 | BJ23: 0.08563 | BK23: 4 | BL23: 4.3 | BM23: 4.7 | BN23: 5.1 | BO23: 5.6
A24: 83 | B24: -1.2433 | C24: 15.3871 | D24: 0.107 | F24: 83 | G24: -1.2261 | H24: 15.465 | I24: 0.09033 | U24: 22 | V24: 78.4 | W24: 81.5 | X24: 84.6 | Y24: 87.7 | Z24: 90.8 | AB24: 22 | AC24: 80.2 | AD24: 83.1 | AE24: 86 | AF24: 89 | AG24: 91.9 | AI24: 22 | AJ24: 44.1 | AK24: 45.5 | AL24: 46.9 | AM24: 48.3 | AN24: 49.7 | AP24: 22 | AQ24: 45.3 | AR24: 46.6 | AS24: 48 | AT24: 49.3 | AU24: 50.7 | AW24: 56 | AX24: -0.3833 | AY24: 4.8162 | AZ24: 0.09118 | BA24: 4 | BB24: 4.4 | BC24: 4.8 | BD24: 5.3 | BE24: 5.8 | BG24: 56 | BH24: -0.3521 | BI24: 4.8338 | BJ24: 0.08535 | BK24: 4.1 | BL24: 4.4 | BM24: 4.8 | BN24: 5.3 | BO24: 5.8
A25: 84 | B25: -1.2565 | C25: 15.4036 | D25: 0.10746 | F25: 84 | G25: -1.246 | H25: 15.4832 | I25: 0.09068 | U25: 23 | V25: 79.2 | W25: 82.3 | X25: 85.5 | Y25: 88.7 | Z25: 91.9 | AB25: 23 | AC25: 81 | AD25: 83.9 | AE25: 86.9 | AF25: 89.9 | AG25: 92.9 | AI25: 23 | AJ25: 44.3 | AK25: 45.6 | AL25: 47 | AM25: 48.4 | AN25: 49.8 | AP25: 23 | AQ25: 45.4 | AR25: 46.8 | AS25: 48.1 | AT25: 49.5 | AU25: 50.8 | AW25: 56.5 | AX25: -0.3833 | AY25: 4.95 | AZ25: 0.09121 | BA25: 4.1 | BB25: 4.5 | BC25: 5 | BD25: 5.4 | BE25: 6 | BG25: 56.5 | BH25: -0.3521 | BI25: 4.9796 | BJ25: 0.08507 | BK25: 4.2 | BL25: 4.6 | BM25: 5 | BN25: 5.4 | BO25: 5.9
