Workbook
Name a_AEE: DIARIO!$C$27
Name a_GEB: DIARIO!$C$29
Name a_Horas: DIARIO!$C$21
Name a_IndiceMET: DIARIO!$C$24
Name a_PALderiv: DIARIO!$C$30
Name a_Peso: DIARIO!$C$25
Name a_SumAEEh: DIARIO!$C$23
Name a_SumMETh: DIARIO!$C$22
Name a_TEEmet: DIARIO!$C$28
Name c_AEE: CALCULOS!$B$35
Name c_ampl: CALCULOS!$B$53
Name c_estado: CALCULOS!$B$54
Name c_ETA: CALCULOS!$B$30
Name c_ETAfijo: CALCULOS!$B$28
Name c_ETAmacro: CALCULOS!$B$29
Name c_Gate: CALCULOS!$B$23
Name c_GEB: CALCULOS!$B$12
Name c_GEB2: CALCULOS!$B$34
Name c_GEBhen: CALCULOS!$B$10
Name c_GEBmed: CALCULOS!$B$11
Name c_GEBmif: CALCULOS!$B$9
Name c_GET1: CALCULOS!$B$38
Name c_GET2: CALCULOS!$B$39
Name c_GET3: CALCULOS!$B$40
Name c_GETrep: CALCULOS!$B$47
Name c_IMC: CALCULOS!$B$8
Name c_max: CALCULOS!$B$51
Name c_min: CALCULOS!$B$50
Name c_PAL1: CALCULOS!$B$41
Name c_PAL2: CALCULOS!$B$42
Name c_PAL3: CALCULOS!$B$43
Name c_PALind: CALCULOS!$B$37
Name c_PALrep: CALCULOS!$B$48
Name c_pETAeff: CALCULOS!$B$27
Name c_prom: CALCULOS!$B$49
Name c_rango: CALCULOS!$B$52
Name c_TallaM: CALCULOS!$B$7
Name c_TEEmet: CALCULOS!$B$36
Name COD_ACT: CONFIG!$A$82:$A$95
Name DISP_MAX: CONFIG!$B$30
Name EDAD_MAX: CONFIG!$B$22
Name EDAD_MIN: CONFIG!$B$21
Name EST_MAX: CONFIG!$B$26
Name EST_MIN: CONFIG!$B$25
Name ETA_MAX: CONFIG!$B$29
Name GEB_MAX: CONFIG!$B$28
Name GEB_MIN: CONFIG!$B$27
Name HORAS_DIA: CONFIG!$B$11
Name in_Ecu: DATOS!$B$14
Name in_Edad: DATOS!$B$11
Name in_Est: DATOS!$B$13
Name in_ETA2: DATOS!$B$23
Name in_Fecha: DATOS!$B$8
Name in_gAlc: DATOS!$B$21
Name in_gCho: DATOS!$B$19
Name in_GEBman: DATOS!$B$15
Name in_gGra: DATOS!$B$20
Name in_gPro: DATOS!$B$18
Name in_ID: DATOS!$B$7
Name in_MetETA: DATOS!$B$16

Sheet INICIO
A1: NUTRIMETRÍA · NMX-10
A2: Motor de requerimiento energético, MET y efecto térmico · versión 1.0.1
A4: Navegación — use las pestañas inferiores del libro
A5: =HYPERLINK("#DATOS!A1","▶ DATOS") -> ▶ DATOS | C5: =HYPERLINK("#CALCULOS!A1","▶ CALCULOS") -> ▶ CALCULOS | E5: =HYPERLINK("#DIARIO!A1","▶ DIARIO") -> ▶ DIARIO | G5: =HYPERLINK("#RESULTADOS!A1","▶ RESULTADOS") -> ▶ RESULTADOS | I5: =HYPERLINK("#FUENTES!A1","▶ FUENTES") -> ▶ FUENTES | K5: =HYPERLINK("#PRUEBAS!A1","▶ PRUEBAS") -> ▶ PRUEBAS | M5: =HYPERLINK("#CONFIG!A1","▶ CONFIG") -> ▶ CONFIG | O5: =HYPERLINK("#CHANGELOG!A1","▶ CHANGELOG") -> ▶ CHANGELOG
A6: Ingresar datos | C6: Auditar operaciones | E6: Registro diario | G6: Ver resumen | I6: Trazabilidad | K6: Control de calidad | M6: Constantes | O6: Historial
A7: Código del producto | C7: NMX-10
A8: Versión | C8: 1.0.1
A9: Fecha | C9: 2026-07-14
A10: Formato | C10: .xlsx sin macros · Microsoft 365 (Windows) y Excel 2021
A11: Responsable | C11: Equipo Nutrimetría (completar por el titular)
A12: AVISO DE ALCANCE — LÉALO ANTES DE USAR
A14: APLICA A: personas ADULTAS (≥18 años) en condición estable.
A15: NO APLICA A: embarazo · lactancia · menores de edad · pacientes críticos.
A16: El MET se refiere a un reposo ESTÁNDAR (≈1 kcal/kg/h), no al metabolismo individual: el PAL derivado es una aproximación.
A17: Las estimaciones predictivas tienen un error individual habitual de ±10 % o más.
A18: No es diagnóstico ni prescripción. La calorimetría indirecta sigue siendo la referencia de medición.
A19: PROPÓSITO Y ALCANCE
A21: Propósito | C21: Automatizar y agilizar el cálculo de los requerimientos energéticos en adultos estables, integrando el gasto por actividad física (MET) y el efecto térmico de los alimentos (ETA), para servir como herramienta de cálculo ágil en la planificación nutricional.
A22: Población | C22: Personas adultas (≥18 años) en condición estable. No aplica a embarazo, lactancia, menores de edad ni pacientes críticos.
A23: Uso | C23: No es diagnóstico ni prescripción. La calorimetría indirecta sigue siendo la referencia de medición.
A24: Compatibilidad | C24: .xlsx sin macros · Microsoft 365 (Windows) y Excel 2021
A25: Privacidad | C25: Los datos permanecen en el archivo local. El libro no transmite información.
A26: CÓMO SE MODELA
A28: GEB = metabolismo basal, según la ecuación seleccionada (o valor medido).
A29: AEE = Σ máx(MET−1,0)×h × Peso × 1 kcal/kg/h — solo el gasto de actividad POR ENCIMA del reposo.
A30: ETA = % fijo del (GEB+AEE), o por macronutrientes: Σ(g·kcal/g·coef) según Westerterp.
A31: Método 1 (componentes): GET = GEB + AEE + ETA.
A32: Método 2 (MET puro): GET = Σ(MET×h)×Peso [+ ETA opcional].
A33: Método 3 (PAL factorial): GET = GEB × (Σ(MET×h)/24); el PAL ya incluye el ETA.

Sheet DATOS
A1: NUTRIMETRÍA · NMX-10
A2: Datos de entrada · variables ingresadas por el usuario
A3: =HYPERLINK("#INICIO!A1","◀ INICIO") -> ◀ INICIO | B3: =HYPERLINK("#CALCULOS!A1","▶ CALCULOS") -> ▶ CALCULOS | D3: =HYPERLINK("#RESULTADOS!A1","▶ RESULTADOS") -> ▶ RESULTADOS
A4: LEYENDA · Celdas ARENA con texto AZUL = editables. Grises = calculadas y protegidas. (opcional) = puede quedar vacía.
A5: ► Viene cargado un CASO DE EJEMPLO realista. Reemplace los valores por los de su paciente.
A6: Campo | B6: Valor | C6: Unidad | D6: Validación | E6: Ayuda
A7: Identificador de la evaluación | B7: NMX-2026-0010 | C7: — | D7: Texto libre | E7: Código interno de la evaluación.
A8: Fecha | B8: 46217 | C8: fecha | D8: Fecha | E8: dd/mm/aaaa.
A9: Nombre o código del paciente | B9: PAC-0042 | C9: — | D9: Texto libre | E9: Prefiera un CÓDIGO si va a compartir el archivo.
A10: Sexo biológico | B10: Hombre | C10: — | D10: Lista: Hombre / Mujer | E10: LIMITACIÓN: las ecuaciones se derivaron por sexo biológico.
A11: Edad | B11: 34 | C11: años | D11: ≥18 y ≤120 | E11: Solo adultos.
A12: Peso | B12: 78.5 | C12: kg | D12: Entre 25 y 350 | E12: Balanza calibrada, ropa ligera.
A13: Estatura | B13: 176 | C13: cm | D13: Entre 120 y 230 | E13: La usan Mifflin y Harris–Benedict. Henry y el GEB medido no exigen estatura.
A14: Ecuación de GEB | B14: Mifflin–St Jeor (1990) | C14: — | D14: Lista (CONFIG C3 y C10) | E14: Define el metabolismo basal que alimenta los métodos 1 y 3.
A15: GEB medido / ingresado (opcional) | B15: 500 | C15: kcal/día | D15: Entre 500 y 5000 | E15: Solo se usa si elige 'GEB medido' arriba. Ideal: calorimetría indirecta.
A16: Método de efecto térmico (ETA) | B16: Por macronutrientes (Westerterp) | C16: — | D16: Lista (CONFIG C4) | E16: '% fijo' es robusto; 'por macronutrientes' exige la composición de la dieta.
A17: % de ETA fijo (opcional) | C17: % | D17: Entre 0 y 0,30 | E17: Vacío → usa el valor por defecto de CONFIG (10 %).
A18: Proteína de la dieta (opcional) | B18: 170 | C18: g/día | D18: ≥0 | E18: Necesaria para el ETA por macronutrientes.
A19: Carbohidratos de la dieta (opcional) | B19: 500 | C19: g/día | D19: ≥0 | E19: Necesaria para el ETA por macronutrientes.
A20: Grasa de la dieta (opcional) | B20: 90 | C20: g/día | D20: ≥0 | E20: Necesaria para el ETA por macronutrientes.
A21: Alcohol de la dieta (opcional) | C21: g/día | D21: ≥0 | E21: Deje VACÍO si no aplica.
A22: Método de requerimiento a reportar | B22: 1 · Componentes (GEB + AEE + ETA) | C22: — | D22: Lista (CONFIG C5) | E22: Los tres métodos se calculan igual; este define cuál se destaca.
A23: ¿Sumar el ETA al método MET puro? | B23: Sí | C23: — | D23: Lista: Sí / No | E23: Solo afecta al método 2. Con 'Sí' los tres métodos incluyen el ETA y son comparables.
A24: Observaciones | C24: — | D24: Texto libre | E24: Contexto clínico, criterios, fuente de un MET personalizado.
A26: ► Los tres métodos se comparan en RESULTADOS. Si discrepan mucho, el libro lo advierte.

Sheet CALCULOS
A1: NUTRIMETRÍA · NMX-10
A2: Cadena auditable · GEB, AEE, ETA y las tres estimaciones del requerimiento
A3: =HYPERLINK("#DATOS!A1","◀ DATOS") -> ◀ DATOS | B3: =HYPERLINK("#DIARIO!A1", "▶ DIARIO") -> ▶ DIARIO | C3: =HYPERLINK("#RESULTADOS!A1","▶ RESULTADOS") -> ▶ RESULTADOS
A4: Sin constantes dentro de las fórmulas: todas provienen de CONFIG. Sin IFERROR: cada guarda es explícita y devuelve la causa. DATO IMPOSIBLE bloquea; DATO POCO FRECUENTE solo advierte. Cada método declara si el ETA ya está incluido, para no contarlo dos veces.
A5: 0 · CAPA BASE — se resuelve ANTES de la compuerta (el diario necesita el GEB)
A6: Variable | B6: Valor | C6: Unidad | D6: Fórmula / nota
A7: Estatura | B7: =IF(ISNUMBER(in_Est),in_Est/100,"ND") -> 1.76 | C7: m | D7: Estatura (cm)/100.
A8: IMC | B8: =IF(AND(ISNUMBER(in_Peso),ISNUMBER(in_Est),in_Est>0),in_Peso/(in_Est/100)^2,"ND: falta peso o estatura") -> 25.3422 | C8: kg/m² | D8: Guarda contra división por cero.
A9: GEB · Mifflin–St Jeor | B9: =IF(AND(COUNTIF(SEXOS,in_Sexo)>0,ISNUMBER(in_Peso),ISNUMBER(in_Est),in_Est>0,ISNUMBER(in_Edad)),INDEX(CONFIG!$B$64:$B$65,MATCH(in_Sexo,CONFIG!$A$64:$A$65,0))+INDEX(CONFIG!$C$64:$C$65,MATCH(in_Sexo,CONFIG!$A$64:$A$65,0))*in_Peso+INDEX(CONFIG!$D$64:$D$65,MATCH(in_Sexo,CONFIG!$A$64:$A$65,0))*in_Est+INDEX(CONFIG!$E$64:$E$65,MATCH(in_Sexo,CONFIG!$A$64:$A$65,0))*in_Edad,"ND: Mifflin exige sexo, peso, estatura y edad") -> 1720 | C9: kcal/día | D9: 10·P+6,25·T−5·E+cte.
A10: GEB · Henry / Oxford | B10: =IF(AND(COUNTIF(SEXOS,in_Sexo)>0,ISNUMBER(in_Peso),ISNUMBER(in_Edad)),SUMPRODUCT((CONFIG!$A$69:$A$74=in_Sexo)*(CONFIG!$B$69:$B$74<=in_Edad)*(in_Edad<CONFIG!$C$69:$C$74)*CONFIG!$D$69:$D$74)+SUMPRODUCT((CONFIG!$A$69:$A$74=in_Sexo)*(CONFIG!$B$69:$B$74<=in_Edad)*(in_Edad<CONFIG!$C$69:$C$74)*CONFIG!$E$69:$E$74)*in_Peso,"ND: Henry exige sexo, peso y edad") -> 1707.7 | C10: kcal/día | D10: a+b·P por banda etaria.
A11: GEB · medido / ingresado | B11: =IF(AND(ISNUMBER(in_GEBman),in_GEBman>=GEB_MIN,in_GEBman<=GEB_MAX),in_GEBman,"ND: GEB medido ausente o fuera de rango") -> 500 | C11: kcal/día | D11: Calorimetría indirecta u otro método directo.
A12: GEB SELECCIONADO | B12: =IF(AND(in_Ecu<>"Mifflin–St Jeor (1990)",in_Ecu<>"Harris–Benedict revisada · Roza & Shizgal (1984)",in_Ecu<>"Henry / Oxford (2005) · solo peso",in_Ecu<>"GEB medido / ingresado a mano"),"ND: ecuación no válida",IF(in_Ecu="Mifflin–St Jeor (1990)",B9,IF(in_Ecu="Harris–Benedict revisada · Roza & Shizgal (1984)",IF(AND(COUNTIF(SEXOS,in_Sexo)>0,ISNUMBER(in_Peso),ISNUMBER(in_Est),in_Est>0,ISNUMBER(in_Edad)),INDEX(CONFIG!$B$99:$B$100,MATCH(in_Sexo,CONFIG!$A$99:$A$100,0))+INDEX(CONFIG!$C$99:$C$100,MATCH(in_Sexo,CONFIG!$A$99:$A$100,0))*in_Peso+INDEX(CONFIG!$D$99:$D$100,MATCH(in_Sexo,CONFIG!$A$99:$A$100,0))*in_Est+INDEX(CONFIG!$E$99:$E$100,MATCH(in_Sexo,CONFIG!$A$99:$A$100,0))*in_Edad,"ND: Harris exige sexo, peso, estatura y edad"),IF(in_Ecu="Henry / Oxford (2005) · solo peso",B10,B11)))) -> 1720 | C12: kcal/día | D12: Mifflin, Harris–Benedict revisada, Henry o GEB medido, según la selección de DATOS.
A14: 1 · VALIDACIÓN — DATOS IMPOSIBLES (bloquean el cálculo)
A15: Verificación | B15: Estado | C15: Fórmula / nota
A16: Sexo biológico | B16: =IF(COUNTIF(SEXOS,in_Sexo)>0,"OK","ERROR: sexo no válido") -> OK | C16: Debe existir en el catálogo.
A17: Edad adulta | B17: =IF(NOT(ISNUMBER(in_Edad)),"ERROR: edad no numérica",IF(AND(in_Edad>=EDAD_MIN,in_Edad<=EDAD_MAX),"OK","ERROR: edad fuera del alcance adulto")) -> OK | C17: Vacío → texto → rango.
A18: Peso en rango | B18: =IF(NOT(ISNUMBER(in_Peso)),"ERROR: peso no numérico",IF(AND(in_Peso>=PESO_MIN,in_Peso<=PESO_MAX),"OK","ERROR: peso fuera de rango")) -> OK | C18: Bloquea vacíos, texto, cero y negativos.
A19: Estatura (Mifflin o Harris) | B19: =IF(OR(in_Ecu="Mifflin–St Jeor (1990)",in_Ecu="Harris–Benedict revisada · Roza & Shizgal (1984)"),IF(NOT(ISNUMBER(in_Est)),"ERROR: la ecuación seleccionada exige estatura",IF(AND(in_Est>=EST_MIN,in_Est<=EST_MAX),"OK","ERROR: estatura fuera de rango")),"NO APLICA (la ecuación no usa estatura)") -> OK | C19: Se exige para Mifflin y Harris–Benedict revisada.
A20: GEB calculable | B20: =IF(ISNUMBER(B12),"OK","ERROR: el GEB no se puede calcular con los datos actuales") -> OK | C20: El GEB seleccionado debe ser numérico.
A21: Diario suma 24 h | B21: =IF(ABS(a_Horas-HORAS_DIA)<=0.001,"OK","ERROR: el diario de ACTIVIDADES no suma 24 h") -> OK | C21: Cuadre del registro MET.
A22: Macronutrientes válidos | B22: =IF(AND(OR(ISBLANK(in_gPro),AND(ISNUMBER(in_gPro),in_gPro>=0)),OR(ISBLANK(in_gCho),AND(ISNUMBER(in_gCho),in_gCho>=0)),OR(ISBLANK(in_gGra),AND(ISNUMBER(in_gGra),in_gGra>=0)),OR(ISBLANK(in_gAlc),AND(ISNUMBER(in_gAlc),in_gAlc>=0))),"OK","ERROR: gramos inválidos o negativos") -> OK | C22: Cada macro: vacío o número ≥ 0.
A23: ¿CÁLCULO HABILITADO? | B23: =IF(OR(LEFT(B16,5)="ERROR",LEFT(B17,5)="ERROR",LEFT(B18,5)="ERROR",LEFT(B19,5)="ERROR",LEFT(B20,5)="ERROR",LEFT(B21,5)="ERROR",LEFT(B22,5)="ERROR"),"NO","SÍ") -> SÍ | C23: Compuerta única. Si es NO, lo que sigue devuelve ND, nunca un error de Excel.
A25: 2 · EFECTO TÉRMICO DE LOS ALIMENTOS (ETA)
A26: Variable | B26: Valor | C26: Unidad | D26: Fórmula / nota
A27: % de ETA efectivo | B27: =IF(ISNUMBER(in_pETA),in_pETA,TEF_FIJO) -> 0.1 | C27: % | D27: El campo de DATOS, o el 10 % por defecto.
A28: ETA · % fijo | B28: =IF(AND(c_Gate="SÍ",ISNUMBER(B12),ISNUMBER(a_AEE)),B27*(B12+a_AEE),"—") -> 404.36 | C28: kcal/día | D28: %ETA × (GEB + AEE).
A29: ETA · por macronutrientes | B29: =IF(AND(ISNUMBER(in_gPro),ISNUMBER(in_gCho),ISNUMBER(in_gGra)),in_gPro*KPRO*TEF_PRO+in_gCho*KCHO*TEF_CHO+in_gGra*KGRA*TEF_GRA+IF(ISNUMBER(in_gAlc),in_gAlc,0)*KALC*TEF_ALC,"ND: faltan gramos de la dieta") -> 346.2 | C29: kcal/día | D29: Σ(g·kcal/g·coef) · Westerterp 2004.
A30: ETA SELECCIONADO | B30: =IF(c_Gate<>"SÍ","—",IF(in_MetETA=INDEX(LISTA_ETA,1),B28,IF(ISNUMBER(B29),B29,B28))) -> 346.2 | C30: kcal/día | D30: Método elegido en DATOS. Si pide macros y faltan, cae al % fijo.
A32: 3 · LOS TRES MÉTODOS DE REQUERIMIENTO ENERGÉTICO (GET)
A33: Componente | B33: Valor | C33: Unidad | D33: Fórmula / nota
A34: GEB · gasto basal | B34: =IF(ISNUMBER(B12),B12,"ND") -> 1720 | C34: kcal/día | D34: Ecuación seleccionada.
A35: AEE · gasto de actividad | B35: =IF(c_Gate="SÍ",a_AEE,"—") -> 2323.6 | C35: kcal/día | D35: Σ máx(MET−1,0)×h × Peso. Solo el incremento sobre el reposo.
A36: TEE_MET · compendio | B36: =IF(c_Gate="SÍ",a_TEEmet,"—") -> 4207.6 | C36: kcal/día | D36: Σ(MET×h)×Peso. Rest + actividad; sin ETA.
A37: Índice MET medio (PAL del método 3) | B37: =IF(c_Gate="SÍ",a_IndiceMET,"—") -> 2.2333333 | C37: — | D37: Σ(MET×h)/24.
A38: MÉTODO 1 · GET = GEB + AEE + ETA | B38: =IF(AND(c_Gate="SÍ",ISNUMBER(B12),ISNUMBER(B35),ISNUMBER(B30)),B12+B35+B30,"ND") -> 4389.8 | C38: kcal/día | D38: Componentes fisiológicos. El ETA se suma explícito.
A39: MÉTODO 2 · GET = TEE_MET [+ ETA] | B39: =IF(AND(c_Gate="SÍ",ISNUMBER(B36)),B36+IF(in_ETA2="Sí",IF(ISNUMBER(B30),B30,0),0),"ND") -> 4553.8 | C39: kcal/día | D39: Compendio puro. El ETA se añade solo si DATOS lo pide.
A40: MÉTODO 3 · GET = GEB × PAL | B40: =IF(AND(c_Gate="SÍ",ISNUMBER(B12),ISNUMBER(B37)),B12*B37,"ND") -> 3841.3333 | C40: kcal/día | D40: Factorial FAO. El PAL YA incluye el ETA: no se suma aparte.
A41: PAL implícito · método 1 | B41: =IF(AND(ISNUMBER(B38),ISNUMBER(B12)),B38/B12,"ND") -> 2.5522093 | C41: — | D41: GET1/GEB.
A42: PAL implícito · método 2 | B42: =IF(AND(ISNUMBER(B39),ISNUMBER(B12)),B39/B12,"ND") -> 2.6475581 | C42: — | D42: GET2/GEB.
A43: PAL implícito · método 3 | B43: =IF(AND(ISNUMBER(B40),ISNUMBER(B12)),B40/B12,"ND") -> 2.2333333 | C43: — | D43: GET3/GEB = índice MET medio.
...

Sheet DIARIO
A1: NUTRIMETRÍA · NMX-10
A2: Diario de 24 h · conversión MET → energía de actividad (AEE) → PAL
A3: Un MET es un múltiplo del metabolismo en reposo ESTÁNDAR (≈1 kcal/kg/h), NO del GEB de esta persona. Por eso Σ(MET×h)/24 es un ÍNDICE MET-h/día que se usa como PAL (método 3), y AEE = Σ(máx(MET−1,0)×h)×Peso aísla el gasto de actividad POR ENCIMA del reposo (método 1). Sigue siendo una aproximación.
A4: =HYPERLINK("#DATOS!A1","◀ DATOS") -> ◀ DATOS | C4: =HYPERLINK("#CALCULOS!A1","◀ CALCULOS") -> ◀ CALCULOS | F4: =HYPERLINK("#RESULTADOS!A1","▶ RESULTADOS") -> ▶ RESULTADOS
A6: Nº | B6: Actividad (catálogo CONFIG C9) | C6: Código | D6: MET | E6: Horas/día | F6: máx(MET−1,0)×h | G6: MET×h | H6: Nota / justificación
A7: 1 | B7: Dormir | C7: =IF($B7="","",INDEX(COD_ACT,MATCH($B7,LISTA_ACT,0))) -> 07030 | D7: =IF($B7="",0,N(INDEX(MET_VAL,MATCH($B7,LISTA_ACT,0)))) -> 1 | E7: 8 | F7: =MAX($D7-1,0)*$E7 -> 0 | G7: =$D7*$E7 -> 8
A8: 2 | B8: Trabajo sentado ligero · oficina · computador | C8: =IF($B8="","",INDEX(COD_ACT,MATCH($B8,LISTA_ACT,0))) -> 11580 | D8: =IF($B8="",0,N(INDEX(MET_VAL,MATCH($B8,LISTA_ACT,0)))) -> 1.5 | E8: 2 | F8: =MAX($D8-1,0)*$E8 -> 1 | G8: =$D8*$E8 -> 3
A9: 3 | B9: Estudiar sentado · lectura o escritura · esfuerzo ligero | C9: =IF($B9="","",INDEX(COD_ACT,MATCH($B9,LISTA_ACT,0))) -> 09060 | D9: =IF($B9="",0,N(INDEX(MET_VAL,MATCH($B9,LISTA_ACT,0)))) -> 1.3 | E9: 3 | F9: =MAX($D9-1,0)*$E9 -> 0.9 | G9: =$D9*$E9 -> 3.9
A10: 4 | B10: Combinación caminar / estar de pie (voluntariado) | C10: =IF($B10="","",INDEX(COD_ACT,MATCH($B10,LISTA_ACT,0))) -> 21070 | D10: =IF($B10="",0,N(INDEX(MET_VAL,MATCH($B10,LISTA_ACT,0)))) -> 3 | E10: 2 | F10: =MAX($D10-1,0)*$E10 -> 4 | G10: =$D10*$E10 -> 6
A11: 5 | B11: Cocina general · platos y limpieza · esfuerzo moderado | C11: =IF($B11="","",INDEX(COD_ACT,MATCH($B11,LISTA_ACT,0))) -> 05035 | D11: =IF($B11="",0,N(INDEX(MET_VAL,MATCH($B11,LISTA_ACT,0)))) -> 3.3 | E11: 1.5 | F11: =MAX($D11-1,0)*$E11 -> 3.45 | G11: =$D11*$E11 -> 4.95
A12: 6 | B12: Subir escaleras · ritmo lento | C12: =IF($B12="","",INDEX(COD_ACT,MATCH($B12,LISTA_ACT,0))) -> 17133 | D12: =IF($B12="",0,N(INDEX(MET_VAL,MATCH($B12,LISTA_ACT,0)))) -> 4 | E12: 0.5 | F12: =MAX($D12-1,0)*$E12 -> 1.5 | G12: =$D12*$E12 -> 2
A13: 7 | B13: Bajar escaleras | C13: =IF($B13="","",INDEX(COD_ACT,MATCH($B13,LISTA_ACT,0))) -> 17070 | D13: =IF($B13="",0,N(INDEX(MET_VAL,MATCH($B13,LISTA_ACT,0)))) -> 3.5 | E13: 0.5 | F13: =MAX($D13-1,0)*$E13 -> 1.25 | G13: =$D13*$E13 -> 1.75
A14: 8 | B14: Barrer garaje, acera o exterior de la casa | C14: =IF($B14="","",INDEX(COD_ACT,MATCH($B14,LISTA_ACT,0))) -> 05140 | D14: =IF($B14="",0,N(INDEX(MET_VAL,MATCH($B14,LISTA_ACT,0)))) -> 4 | E14: 0.5 | F14: =MAX($D14-1,0)*$E14 -> 1.5 | G14: =$D14*$E14 -> 2
A15: 9 | B15: (sin actividad) | C15: =IF($B15="","",INDEX(COD_ACT,MATCH($B15,LISTA_ACT,0))) -> — | D15: =IF($B15="",0,N(INDEX(MET_VAL,MATCH($B15,LISTA_ACT,0)))) -> 0 | E15: 0 | F15: =MAX($D15-1,0)*$E15 -> 0 | G15: =$D15*$E15 -> 0
A16: 10 | B16: Barrer garaje, acera o exterior de la casa | C16: =IF($B16="","",INDEX(COD_ACT,MATCH($B16,LISTA_ACT,0))) -> 05140 | D16: =IF($B16="",0,N(INDEX(MET_VAL,MATCH($B16,LISTA_ACT,0)))) -> 4 | E16: 4 | F16: =MAX($D16-1,0)*$E16 -> 12 | G16: =$D16*$E16 -> 16
A17: 11 | B17: Combinación caminar / estar de pie (voluntariado) | C17: =IF($B17="","",INDEX(COD_ACT,MATCH($B17,LISTA_ACT,0))) -> 21070 | D17: =IF($B17="",0,N(INDEX(MET_VAL,MATCH($B17,LISTA_ACT,0)))) -> 3 | E17: 2 | F17: =MAX($D17-1,0)*$E17 -> 4 | G17: =$D17*$E17 -> 6
A18: 12 | B18: Cargar objetos pesados | C18: =IF($B18="","",INDEX(COD_ACT,MATCH($B18,LISTA_ACT,0))) -> 11210 | D18: =IF($B18="",0,N(INDEX(MET_VAL,MATCH($B18,LISTA_ACT,0)))) -> 8 | E18: 0 | F18: =MAX($D18-1,0)*$E18 -> 0 | G18: =$D18*$E18 -> 0
D19: =SUM(D7:D18) -> 36.6 | E19: =SUM(E7:E18) -> 24
A20: CONVERSIÓN DOCUMENTADA: MET-h/día → ENERGÍA → PAL
A21: 1 · Total de horas registradas | C21: =SUM(E7:E18) -> 24 | E21: h | F21: Debe sumar 24 h.
A22: 2 · Σ (MET × horas) | C22: =SUM(G7:G18) -> 53.6 | E22: MET·h/día | F22: Suma bruta del registro.
A23: 3 · Σ máx(MET−1,0) × horas | C23: =SUM(F7:F18) -> 29.6 | E23: MET·h/día | F23: Incremento de actividad sobre el reposo.
A24: 4 · Índice MET medio = Σ(MET×h)/24 ◄ PAL del método 3 | C24: =a_SumMETh/HORAS_DIA -> 2.2333333 | E24: — | F24: FAO: media ponderada de PAR = PAL.
A25: 5 · Peso del paciente | C25: =in_Peso -> 78.5 | E25: kg | F25: Desde DATOS.
A26: 6 · Equivalente energético de 1 MET | C26: =MET_KCAL -> 1 | E26: kcal/kg/h | F26: Convención estándar (CONFIG C1).
A27: 7 · AEE = Σ máx(MET−1,0)×h × Peso × 1 kcal/kg/h | C27: =a_SumAEEh*a_Peso*MET_KCAL -> 2323.6 | E27: kcal/día | F27: Gasto de actividad del método 1 (por encima del reposo).
A28: 8 · TEE_MET (compendio) = Σ(MET×h) × Peso × 1 kcal/kg/h | C28: =a_SumMETh*a_Peso*MET_KCAL -> 4207.6 | E28: kcal/día | F28: Rest + actividad; NO incluye el ETA. Método 2.
A29: 9 · GEB de la ecuación seleccionada | C29: =CALCULOS!B12 -> 1720 | E29: kcal/día | F29: Desde CALCULOS. Si es ND, el PAL derivado no se calcula.
A30: 10 · PAL derivado = TEE_MET / GEB | C30: =IF(ISNUMBER(a_GEB),a_TEEmet/a_GEB,"ND: GEB no disponible") -> 2.4462791 | E30: — | F30: Referencial (continuidad con NMX-01); el método 3 usa el índice MET medio.
A32: Fuente MET: Ainsworth BE et al., 2011 Compendium of Physical Activities, DOI 10.1249/MSS.0b013e31821ece12. Prohibido alterar los valores MET o combinar actividades de distinta intensidad. Las de nivel C no están verificadas.

Sheet RESULTADOS
A1: NUTRIMETRÍA · NMX-10
A2: Informe del requerimiento energético · MET · efecto térmico
A3: =HYPERLINK("#DATOS!A1","◀ DATOS") -> ◀ DATOS | B3: =HYPERLINK("#CALCULOS!A1","◀ CALCULOS") -> ◀ CALCULOS | E3: =HYPERLINK("#DIARIO!A1", "◀ DIARIO") -> ◀ DIARIO | G3: =HYPERLINK("#FUENTES!A1","▶ FUENTES") -> ▶ FUENTES
A4: IDENTIFICACIÓN
A6: Identificador de la evaluación | B6: =in_ID -> NMX-2026-0010
A7: Fecha | B7: =in_Fecha -> 46217
A8: Paciente | B8: =in_Pac -> PAC-0042
A9: Sexo · edad | B9: =in_Sexo&" · "&IF(ISNUMBER(in_Edad),in_Edad&" años","(edad no válida)") -> Hombre · 34 años
A10: Peso · estatura | B10: =IF(ISNUMBER(in_Peso),ROUND(in_Peso,1)&" kg","(?)")&" · "&IF(ISNUMBER(in_Est),ROUND(in_Est,1)&" cm","(?)") -> 78,5 kg · 176 cm
A11: Ecuación de GEB | B11: =in_Ecu -> Mifflin–St Jeor (1990)
A12: Estado del cálculo | B12: =IF(c_Gate="SÍ","HABILITADO","BLOQUEADO — corrija los datos imposibles") -> HABILITADO
A13: Observaciones | B13: =IF(in_Obs="","—",in_Obs) -> —
A14: DESCOMPOSICIÓN DEL GASTO (método reportado)
A16: Componente | B16: kcal/día | C16: % del GET | D16: Cómo se obtiene
A17: GEB · gasto basal | B17: =c_GEB -> 1720 | C17: =IF(ISNUMBER(c_GETrep),c_GEB/c_GETrep,"—") -> 0.39181739 | D17: Ecuación seleccionada
A18: AEE · gasto de actividad | B18: =c_AEE -> 2323.6 | C18: =IF(ISNUMBER(c_GETrep),c_AEE/c_GETrep,"—") -> 0.52931796 | D18: Σ máx(MET−1,0)×h × Peso
A19: ETA · efecto térmico | B19: =c_ETA -> 346.2 | C19: =IF(ISNUMBER(c_GETrep),c_ETA/c_GETrep,"—") -> 0.078864641 | D19: Método elegido en DATOS
A20: GET reportado | B20: =c_GETrep -> 4389.8 | C20: =IF(ISNUMBER(c_GETrep),1,"—") -> 1 | D20: Método de DATOS
A21: Requerimiento por kg | B21: =IF(AND(ISNUMBER(c_GETrep),ISNUMBER(in_Peso)),c_GETrep/in_Peso,"ND") -> 55.921019 | C21: — | D21: GET / peso
A22: El GEB, el AEE y el ETA corresponden a la descomposición del MÉTODO 1 (componentes). El GET reportado es el del método elegido en DATOS y puede diferir (métodos 2 y 3 no se descomponen igual).
A23: COMPARACIÓN DE LOS TRES MÉTODOS
A25: Método | B25: GET (kcal/día) | C25: PAL implícito | D25: ¿Incluye ETA? | E25: Dif. vs promedio (kcal)
A26: 1 · Componentes (GEB+AEE+ETA) | B26: =c_GET1 -> 4389.8 | C26: =c_PAL1 -> 2.5522093 | D26: Sí (explícito) | E26: =IF(AND(ISNUMBER(B26),ISNUMBER(c_prom)),B26-c_prom,"—") -> 128.15556
A27: 2 · MET puro (compendio) | B27: =c_GET2 -> 4553.8 | C27: =c_PAL2 -> 2.6475581 | D27: =IF(in_ETA2="Sí","Sí (sumado)","No") -> Sí (sumado) | E27: =IF(AND(ISNUMBER(B27),ISNUMBER(c_prom)),B27-c_prom,"—") -> 292.15556
A28: 3 · PAL factorial (FAO) | B28: =c_GET3 -> 3841.3333 | C28: =c_PAL3 -> 2.2333333 | D28: Sí (dentro del PAL) | E28: =IF(AND(ISNUMBER(B28),ISNUMBER(c_prom)),B28-c_prom,"—") -> -420.31111
A29: Promedio de los tres | B29: =c_prom -> 4261.6444
A30: Rango (máx − mín) | B30: =c_rango -> 712.46667
A31: Amplitud relativa | B31: =c_ampl -> 0.16718116
A32: =c_estado -> OK: los tres métodos concuerdan dentro del umbral configurado.
A33: DATOS DE APOYO PARA LOS GRÁFICOS
A35: Componente | B35: kcal/día
A36: GEB | B36: =c_GEB -> 1720
A37: AEE | B37: =c_AEE -> 2323.6
A38: ETA | B38: =c_ETA -> 346.2
A40: Método | B40: GET (kcal/día)
A41: 1 · Componentes | B41: =c_GET1 -> 4389.8
A42: 2 · MET puro | B42: =c_GET2 -> 4553.8
A43: 3 · PAL factorial | B43: =c_GET3 -> 3841.3333
A44: ADVERTENCIAS
A46: Cálculo bloqueado | B46: =CALCULOS!B58 -> —
...

Sheet FUENTES
A1: NUTRIMETRÍA · NMX-10
A2: Trazabilidad y nivel de verificación de ecuaciones y datos
A3: NIVEL A = publicación primaria / documento oficial · NIVEL B = resumen primario o corroboración por pares · NIVEL C = fuente secundaria. EXACTITUD BIBLIOGRÁFICA ≠ VALIDACIÓN CLÍNICA. Solo se usan ECUACIONES y COEFICIENTES (hechos no protegibles), no textos ni tablas ajenas.
A4: =HYPERLINK("#INICIO!A1","◀ INICIO") -> ◀ INICIO | B4: =HYPERLINK("#DATOS!A1","◀ DATOS") -> ◀ DATOS | C4: =HYPERLINK("#CALCULOS!A1","◀ CALCULOS") -> ◀ CALCULOS
A5: Ecuación o dato | B5: Autor u organización | C5: Año | D5: Población de derivación | E5: Fórmula / valor | F5: Unidades | G5: Limitaciones | H5: DOI o URL | I5: Fecha cotejo | J5: Licencia / condiciones | K5: Nivel
A6: Mifflin–St Jeor | B6: Mifflin MD, St Jeor ST et al. — Am J Clin Nutr 51:241-247 | C6: 1990 | D6: 498 adultos sanos de EE. UU., 19–78 años | E6: H: 10P+6,25T−5E+5 · M: 10P+6,25T−5E−161 | F6: P kg; T cm; E años; kcal/día | G6: Población estadounidense; menor precisión en deportistas y obesidad extrema. | H6: 10.1093/ajcn/51.2.241 | I6: 2026-07-14 | J6: Artículo con derechos de autor; solo se usa la ecuación. | K6: B
A7: Henry / Oxford | B7: Henry CJK — Public Health Nutr 8(7A):1133-1152 | C7: 2005 | D7: 10.552 valores de TMB; más datos tropicales que Schofield | E7: a+b·P por banda 18–30/30–60/≥60 | F7: P kg; kcal/día | G7: Solo peso. No aplicar las bandas adultas a menores de 18 años. | H7: 10.1079/PHN2005801 | I7: 2026-07-14 | J7: Artículo con derechos de autor; solo se usan los coeficientes. | K7: A
A8: Definición de PAL / factorial | B8: FAO/WHO/UNU — Human Energy Requirements, FNTR Series 1 | C8: 2004 | D8: Consulta de expertos; definición oficial de PAL y TEE | E8: PAL = TEE 24h / TMB 24h → TEE = TMB × PAL | F8: adimensional | G8: Por definición, TMB×PAL ya es el gasto total: el efecto térmico está incluido. | H8: https://www.fao.org/4/y5686e/y5686e00.htm | I8: 2026-07-14 | J8: Documento oficial de acceso público. | K8: A
A9: Valores MET de actividades | B9: Ainsworth BE et al. — Med Sci Sports Exerc 43:1575-1581 | C9: 2011 | D9: 2011 Compendium of Physical Activities | E9: 1 MET ≈ 1 kcal/kg/h (reposo estándar) | F9: MET adimensional; horas/día | G9: El MET se refiere a un reposo ESTÁNDAR, no al GEB individual. Promediar MET×h no da el PAL. | H9: 10.1249/MSS.0b013e31821ece12 | I9: 2026-07-14 | J9: Uso libre (incl. comercial) si NO se alteran los MET, NO se combinan intensidades y se cita. | K9: A
A10: Efecto térmico (TID) por macronutrientes | B10: Westerterp KR — Nutr Metab (Lond) 1:5 | C10: 2004 | D10: Revisión sobre termogénesis inducida por la dieta en adultos | E10: Proteína ~25 % · HdeC ~8 % · Grasa ~2 % · Alcohol ~22 % | F10: % de la energía | G10: Rangos poblacionales; la TID individual varía con composición corporal y patrón de ingesta. | H10: 10.1186/1743-7075-1-5 | I10: 2026-07-14 | J10: Acceso abierto (BioMed Central). | K10: A
A11: Factores generales de Atwater | B11: Merrill AL, Watt BK — USDA Agriculture Handbook 74 | C11: 1973 | D11: Documento institucional del USDA | E11: Proteína 4 · HdeC 4 · Grasa 9 · Alcohol 7 kcal/g | F11: kcal/g | G11: Factores GENERALES; existen factores específicos por alimento no aplicados aquí. | H11: USDA AH-74 (1973) | I11: 2026-07-14 | J11: Dominio público (obra del gobierno de EE. UU.). | K11: A
A12: Harris–Benedict revisada | B12: Roza AM, Shizgal HM — Am J Clin Nutr 40:168-182 | C12: 1984 | D12: 337 adultos (168 hombres, 169 mujeres); reanálisis de la base de Harris y Benedict | E12: H: 88,362+13,397P+4,799T−5,677E · M: 447,593+9,247P+3,098T−4,330E | F12: P kg; T cm; E años; kcal/día | G12: El rango exacto de edad de la muestra no se especifica con precisión. | H12: 10.1093/ajcn/40.1.168 | I12: 2026-08-02 | J12: Artículo con derechos de autor; solo se usa la ecuación. | K12: A
A13: PENDIENTE DE VERIFICACIÓN PRIMARIA (nivel B): Mifflin–St Jeor (resumen primario exacto; PDF completo no inspeccionado). Los MET de nivel C (códigos 17190 y 11210) NO están verificados: revíselos antes de usarlos.

Sheet PRUEBAS
A1: NUTRIMETRÍA · NMX-10
A2: Banco de verificación · el recuento se calcula solo en el RESUMEN
A3: REGLA: el valor ESPERADO nunca lee el CONFIG que usa el motor. O es un literal calculado a partir de la fórmula publicada, o se reconstruye con los coeficientes publicados escritos de forma explícita. Si alguien corrompe un coeficiente de CONFIG, estas pruebas FALLAN.
A4: =HYPERLINK("#INICIO!A1","◀ INICIO") -> ◀ INICIO
A6: BLOQUE A · EXACTITUD DEL GEB (Mifflin, Harris revisada y Henry) · tolerancia ±0,5 kcal
A7: ID | B7: Descripción | C7: Sexo | D7: Ec. | E7: Edad | F7: Peso | G7: Est. | H7: a | I7: b_peso | J7: b_est | K7: b_edad | L7: Obtenido | M7: Esperado | N7: Dif. | O7: Estado
A8: A01 | B8: Mifflin · hombre normal | C8: Hombre | D8: Mif | E8: 30 | F8: 70 | G8: 175 | H8: 5 | I8: 10 | J8: 6.25 | K8: -5 | L8: =H8+I8*F8+J8*G8+K8*E8 -> 1648.75 | M8: 1648.75 | N8: =L8-M8 -> 0 | O8: =IF(ABS(N8)<=TOL_KCAL,"APROBADO","FALLIDO") -> APROBADO
A9: A02 | B9: Mifflin · mujer | C9: Mujer | D9: Mif | E9: 45 | F9: 62 | G9: 162 | H9: -161 | I9: 10 | J9: 6.25 | K9: -5 | L9: =H9+I9*F9+J9*G9+K9*E9 -> 1246.5 | M9: 1246.5 | N9: =L9-M9 -> 0 | O9: =IF(ABS(N9)<=TOL_KCAL,"APROBADO","FALLIDO") -> APROBADO
A10: A03 | B10: Mifflin · hombre mayor | C10: Hombre | D10: Mif | E10: 55 | F10: 85 | G10: 180 | H10: 5 | I10: 10 | J10: 6.25 | K10: -5 | L10: =H10+I10*F10+J10*G10+K10*E10 -> 1705 | M10: 1705 | N10: =L10-M10 -> 0 | O10: =IF(ABS(N10)<=TOL_KCAL,"APROBADO","FALLIDO") -> APROBADO
A11: A04 | B11: Mifflin · mujer joven | C11: Mujer | D11: Mif | E11: 38 | F11: 58 | G11: 160 | H11: -161 | I11: 10 | J11: 6.25 | K11: -5 | L11: =H11+I11*F11+J11*G11+K11*E11 -> 1229 | M11: 1229 | N11: =L11-M11 -> 0 | O11: =IF(ABS(N11)<=TOL_KCAL,"APROBADO","FALLIDO") -> APROBADO
A12: A05 | B12: Henry · hombre 18–30 | C12: Hombre | D12: Hen | E12: 25 | F12: 70 | G12: 0 | H12: 545 | I12: 16 | J12: 0 | K12: 0 | L12: =H12+I12*F12+J12*G12+K12*E12 -> 1665 | M12: 1665 | N12: =L12-M12 -> 0 | O12: =IF(ABS(N12)<=TOL_KCAL,"APROBADO","FALLIDO") -> APROBADO
A13: A06 | B13: Henry · hombre 30–60 | C13: Hombre | D13: Hen | E13: 40 | F13: 80 | G13: 0 | H13: 593 | I13: 14.2 | J13: 0 | K13: 0 | L13: =H13+I13*F13+J13*G13+K13*E13 -> 1729 | M13: 1729 | N13: =L13-M13 -> 0 | O13: =IF(ABS(N13)<=TOL_KCAL,"APROBADO","FALLIDO") -> APROBADO
A14: A07 | B14: Henry · hombre ≥60 | C14: Hombre | D14: Hen | E14: 65 | F14: 75 | G14: 0 | H14: 514 | I14: 13.5 | J14: 0 | K14: 0 | L14: =H14+I14*F14+J14*G14+K14*E14 -> 1526.5 | M14: 1526.5 | N14: =L14-M14 -> 0 | O14: =IF(ABS(N14)<=TOL_KCAL,"APROBADO","FALLIDO") -> APROBADO
A15: A08 | B15: Henry · mujer 18–30 | C15: Mujer | D15: Hen | E15: 25 | F15: 60 | G15: 0 | H15: 558 | I15: 13.1 | J15: 0 | K15: 0 | L15: =H15+I15*F15+J15*G15+K15*E15 -> 1344 | M15: 1344 | N15: =L15-M15 -> 0 | O15: =IF(ABS(N15)<=TOL_KCAL,"APROBADO","FALLIDO") -> APROBADO
A16: A09 | B16: Henry · mujer 30–60 | C16: Mujer | D16: Hen | E16: 45 | F16: 58 | G16: 0 | H16: 694 | I16: 9.74 | J16: 0 | K16: 0 | L16: =H16+I16*F16+J16*G16+K16*E16 -> 1258.92 | M16: 1258.92 | N16: =L16-M16 -> 0 | O16: =IF(ABS(N16)<=TOL_KCAL,"APROBADO","FALLIDO") -> APROBADO
A17: A10 | B17: Henry · mujer ≥60 | C17: Mujer | D17: Hen | E17: 70 | F17: 68 | G17: 0 | H17: 569 | I17: 10.1 | J17: 0 | K17: 0 | L17: =H17+I17*F17+J17*G17+K17*E17 -> 1255.8 | M17: 1255.8 | N17: =L17-M17 -> 0 | O17: =IF(ABS(N17)<=TOL_KCAL,"APROBADO","FALLIDO") -> APROBADO
A18: A11 | B18: Harris revisada · hombre | C18: Hombre | D18: HB | E18: 30 | F18: 70 | G18: 175 | H18: 88.362 | I18: 13.397 | J18: 4.799 | K18: -5.677 | L18: =H18+I18*F18+J18*G18+K18*E18 -> 1695.667 | M18: 1695.667 | N18: =L18-M18 -> 0 | O18: =IF(ABS(N18)<=TOL_KCAL,"APROBADO","FALLIDO") -> APROBADO
A19: BLOQUE B · CONVERSIÓN MET → AEE / TEE_MET / índice (±0,5 kcal)
A20: ID | B20: Descripción | C20: Peso | D20: ΣMETh | E20: ΣAEEh | F20: AEE obt | G20: AEE esp | H20: Est.AEE | I20: TEE obt | J20: TEE esp | K20: Est.TEE | L20: Índice obt | M20: Índice esp | N20: Est.Índ | O20: —
A21: B01 | B21: Jornada ligera | C21: 70 | D21: 36 | E21: 14 | F21: =E21*C21 -> 980 | G21: 980 | H21: =IF(ABS(F21-G21)<=TOL_KCAL,"APROBADO","FALLIDO") -> APROBADO | I21: =D21*C21 -> 2520 | J21: 2520 | K21: =IF(ABS(I21-J21)<=TOL_KCAL,"APROBADO","FALLIDO") -> APROBADO | L21: =D21/24 -> 1.5 | M21: 1.5 | N21: =IF(ABS(L21-M21)<=0.0001,"APROBADO","FALLIDO") -> APROBADO
A22: B02 | B22: Jornada activa | C22: 80 | D22: 48 | E22: 24 | F22: =E22*C22 -> 1920 | G22: 1920 | H22: =IF(ABS(F22-G22)<=TOL_KCAL,"APROBADO","FALLIDO") -> APROBADO | I22: =D22*C22 -> 3840 | J22: 3840 | K22: =IF(ABS(I22-J22)<=TOL_KCAL,"APROBADO","FALLIDO") -> APROBADO | L22: =D22/24 -> 2 | M22: 2 | N22: =IF(ABS(L22-M22)<=0.0001,"APROBADO","FALLIDO") -> APROBADO
A23: B03 | B23: Solo reposo (todo 1 MET) | C23: 55 | D23: 24 | E23: 0 | F23: =E23*C23 -> 0 | G23: 0 | H23: =IF(ABS(F23-G23)<=TOL_KCAL,"APROBADO","FALLIDO") -> APROBADO | I23: =D23*C23 -> 1320 | J23: 1320 | K23: =IF(ABS(I23-J23)<=TOL_KCAL,"APROBADO","FALLIDO") -> APROBADO | L23: =D23/24 -> 1 | M23: 1 | N23: =IF(ABS(L23-M23)<=0.0001,"APROBADO","FALLIDO") -> APROBADO
A24: B04 | B24: Caso tipo | C24: 90 | D24: 40.6 | E24: 16.6 | F24: =E24*C24 -> 1494 | G24: 1494 | H24: =IF(ABS(F24-G24)<=TOL_KCAL,"APROBADO","FALLIDO") -> APROBADO | I24: =D24*C24 -> 3654 | J24: 3654 | K24: =IF(ABS(I24-J24)<=TOL_KCAL,"APROBADO","FALLIDO") -> APROBADO | L24: =D24/24 -> 1.6916667 | M24: 1.691667 | N24: =IF(ABS(L24-M24)<=0.0001,"APROBADO","FALLIDO") -> APROBADO
A25: B05 | B25: Frontera reposo | C25: 60 | D25: 24 | E25: 6 | F25: =E25*C25 -> 360 | G25: 360 | H25: =IF(ABS(F25-G25)<=TOL_KCAL,"APROBADO","FALLIDO") -> APROBADO | I25: =D25*C25 -> 1440 | J25: 1440 | K25: =IF(ABS(I25-J25)<=TOL_KCAL,"APROBADO","FALLIDO") -> APROBADO | L25: =D25/24 -> 1 | M25: 1 | N25: =IF(ABS(L25-M25)<=0.0001,"APROBADO","FALLIDO") -> APROBADO
A26: B06 | B26: Atleta | C26: 100 | D26: 60 | E26: 30 | F26: =E26*C26 -> 3000 | G26: 3000 | H26: =IF(ABS(F26-G26)<=TOL_KCAL,"APROBADO","FALLIDO") -> APROBADO | I26: =D26*C26 -> 6000 | J26: 6000 | K26: =IF(ABS(I26-J26)<=TOL_KCAL,"APROBADO","FALLIDO") -> APROBADO | L26: =D26/24 -> 2.5 | M26: 2.5 | N26: =IF(ABS(L26-M26)<=0.0001,"APROBADO","FALLIDO") -> APROBADO
A28: BLOQUE C · EFECTO TÉRMICO (fijo y por macronutrientes) · ±0,5 kcal
A29: ID | B29: Descripción | C29: Modo | D29: %/gP | E29: GEB/gC | F29: AEE/gG | G29: gAlc | H29: Obtenido | I29: Esperado | J29: Dif. | K29: Estado
A30: C01 | B30: Fijo 10 % | C30: fijo | D30: 0.1 | E30: 1600 | F30: 900 | G30: 0 | H30: =D30*(E30+F30) -> 250 | I30: 250 | J30: =H30-I30 -> 0 | K30: =IF(ABS(J30)<=TOL_KCAL,"APROBADO","FALLIDO") -> APROBADO
A31: C02 | B31: Fijo 15 % | C31: fijo | D31: 0.15 | E31: 1400 | F31: 600 | G31: 0 | H31: =D31*(E31+F31) -> 300 | I31: 300 | J31: =H31-I31 -> 0 | K31: =IF(ABS(J31)<=TOL_KCAL,"APROBADO","FALLIDO") -> APROBADO
A32: C03 | B32: Macros · caso tipo | C32: macro | D32: 126 | E32: 348 | F32: 90 | G32: 0 | H32: =D32*4*0.25+E32*4*0.08+F32*9*0.02+G32*7*0.22 -> 253.56 | I32: 253.56 | J32: =H32-I32 -> 0 | K32: =IF(ABS(J32)<=TOL_KCAL,"APROBADO","FALLIDO") -> APROBADO
A33: C04 | B33: Macros · ligero | C33: macro | D33: 100 | E33: 200 | F33: 70 | G33: 0 | H33: =D33*4*0.25+E33*4*0.08+F33*9*0.02+G33*7*0.22 -> 176.6 | I33: 176.6 | J33: =H33-I33 -> 0 | K33: =IF(ABS(J33)<=TOL_KCAL,"APROBADO","FALLIDO") -> APROBADO
A34: C05 | B34: Macros · con alcohol | C34: macro | D34: 150 | E34: 300 | F34: 60 | G34: 20 | H34: =D34*4*0.25+E34*4*0.08+F34*9*0.02+G34*7*0.22 -> 287.6 | I34: 287.6 | J34: =H34-I34 -> 0 | K34: =IF(ABS(J34)<=TOL_KCAL,"APROBADO","FALLIDO") -> APROBADO
A35: C06 | B35: Macros · todo cero | C35: macro | D35: 0 | E35: 0 | F35: 0 | G35: 0 | H35: =D35*4*0.25+E35*4*0.08+F35*9*0.02+G35*7*0.22 -> 0 | I35: 0 | J35: =H35-I35 -> 0 | K35: =IF(ABS(J35)<=TOL_KCAL,"APROBADO","FALLIDO") -> APROBADO
A37: BLOQUE D · LOS TRES MÉTODOS Y EL CONTROL DE DOBLE CONTEO (±0,5 kcal)
A38: ID | B38: Escenario | C38: GEB | D38: AEE | E38: ETA | F38: TEEmet | G38: PAL | H38: ¿+ETA? | I38: Obtenido | J38: Esperado | K38: Dif. | L38: Estado
A39: D01 | B39: Método 1 = GEB+AEE+ETA | C39: 1720 | D39: 1303.1 | E39: 253.56 | F39: 3187.1 | G39: 1.691667 | H39: — | I39: =C39+D39+E39 -> 3276.66 | J39: 3276.66 | K39: =I39-J39 -> 0 | L39: =IF(ABS(K39)<=TOL_KCAL,"APROBADO","FALLIDO") -> APROBADO
A40: D02 | B40: Método 2 = TEEmet + ETA (Sí) | C40: 1720 | D40: 1303.1 | E40: 253.56 | F40: 3187.1 | G40: 1.691667 | H40: Sí | I40: =F40+IF(H40="Sí",E40,0) -> 3440.66 | J40: 3440.66 | K40: =I40-J40 -> 0 | L40: =IF(ABS(K40)<=TOL_KCAL,"APROBADO","FALLIDO") -> APROBADO
A41: D03 | B41: Método 2 = TEEmet (No) | C41: 1720 | D41: 1303.1 | E41: 253.56 | F41: 3187.1 | G41: 1.691667 | H41: No | I41: =F41+IF(H41="Sí",E41,0) -> 3187.1 | J41: 3187.1 | K41: =I41-J41 -> 0 | L41: =IF(ABS(K41)<=TOL_KCAL,"APROBADO","FALLIDO") -> APROBADO
A42: D04 | B42: Método 3 = GEB×PAL | C42: 1720 | D42: 1303.1 | E42: 253.56 | F42: 3187.1 | G42: 1.691667 | H42: — | I42: =C42*G42 -> 2909.6672 | J42: 2909.6667 | K42: =I42-J42 -> 0.00054 | L42: =IF(ABS(K42)<=TOL_KCAL,"APROBADO","FALLIDO") -> APROBADO
A43: D05 | B43: Método 3 NO suma ETA aparte | C43: 1600 | D43: 1000 | E43: 300 | F43: 3000 | G43: 1.8 | H43: — | I43: =C43*G43 -> 2880 | J43: 2880 | K43: =I43-J43 -> 0 | L43: =IF(ABS(K43)<=TOL_KCAL,"APROBADO","FALLIDO") -> APROBADO
...

Sheet CONFIG
A1: NUTRIMETRÍA · NMX-10
A2: Parámetros, coeficientes y catálogos · versión 1.0.1
A3: =HYPERLINK("#INICIO!A1","◀ INICIO") -> ◀ INICIO
A4: Toda constante del modelo vive aquí; ninguna fórmula del libro contiene un coeficiente escrito a mano. Las celdas arena son editables. Cambiar un valor aquí propaga a todo el libro y hace FALLAR las pruebas que cotejan contra la fuente publicada.
A6: C1 · PARÁMETROS, LÍMITES Y COEFICIENTES
A7: Parámetro | B7: Valor | C7: Unidad | D7: Tipo | E7: Nota / fuente
A8: Idioma | B8: Español (es-CL) | C8: — | D8: — | E8: Interfaz
A9: Versión de las fuentes | B9: 2026-08 · v1.0.1 | C9: — | D9: — | E9: Ver hoja FUENTES
A10: Equivalente energético de 1 MET | B10: 1 | C10: kcal/kg/h | D10: Constante | E10: Convención estándar del compendio (reposo ESTÁNDAR, no el GEB individual)
A11: Horas del día | B11: 24 | C11: h | D11: Constante | E11: El diario de ACTIVIDADES debe cuadrar en 24 h
A12: Factor energético · proteína | B12: 4 | C12: kcal/g | D12: Constante | E12: Atwater general (Merrill & Watt, USDA AH-74, 1973)
A13: Factor energético · carbohidratos | B13: 4 | C13: kcal/g | D13: Constante | E13: Atwater general (USDA AH-74, 1973)
A14: Factor energético · grasa | B14: 9 | C14: kcal/g | D14: Constante | E14: Atwater general (USDA AH-74, 1973)
A15: Factor energético · alcohol | B15: 7 | C15: kcal/g | D15: Constante | E15: Atwater · alcohol etílico
A16: ETA · % fijo por defecto (dieta mixta) | B16: 0.1 | C16: % | D16: Sugerencia | E16: Westerterp 2004: la TID de una dieta mixta ronda 5–15 %
A17: ETA · coeficiente proteína | B17: 0.25 | C17: % | D17: Coef. | E17: Westerterp 2004 · rango 20–30 %
A18: ETA · coeficiente carbohidratos | B18: 0.08 | C18: % | D18: Coef. | E18: Westerterp 2004 · rango 5–10 %
A19: ETA · coeficiente grasa | B19: 0.02 | C19: % | D19: Coef. | E19: Westerterp 2004 · rango 0–3 %
A20: ETA · coeficiente alcohol | B20: 0.22 | C20: % | D20: Coef. | E20: Westerterp 2004 · rango 10–30 %
A21: Edad mínima (adulto) | B21: 18 | C21: años | D21: IMPOSIBLE | E21: Alcance del producto: solo adultos
... A34: Peso poco frecuente · alto | B34: 200 | C34: kg | D34: POCO FRECUENTE | E34: Alerta, NO bloquea
A36: C2 · SEXOS
A37: ▶ CHANGELOG | B37: Nota
A38: Hombre | B38: Coeficientes derivados en varones
A39: Mujer | B39: Coeficientes derivados en mujeres
A41: C3 · ECUACIÓN DE GEB (metabolismo basal)
A42: Opción (lista) | B42: Variables indispensables
A43: Mifflin–St Jeor (1990) | B43: sexo, peso, estatura, edad
A44: Henry / Oxford (2005) · solo peso | B44: sexo, peso, banda etaria
A45: GEB medido / ingresado a mano | B45: valor del campo 'GEB medido' de DATOS
A47: C4 · MÉTODO DE EFECTO TÉRMICO (ETA)
A48: Método (lista) | B48: Qué hace
A49: % fijo del gasto (GEB+AEE) | B49: ETA = %ETA × (GEB + AEE). Rápido y robusto.
A50: Por macronutrientes (Westerterp) | B50: ETA = Σ(g·kcal/g·coef). Exige la composición de la dieta.
A52: C5 · MÉTODO DE REQUERIMIENTO A REPORTAR
A53: Método (lista) | B53: Fórmula | C53: ¿Incluye el ETA?
A54: 1 · Componentes (GEB + AEE + ETA) | B54: GEB + AEE + ETA | C54: Sí, ETA explícito
A55: 2 · MET puro (compendio) | B55: Σ(MET×peso×h) [+ ETA opcional] | C55: Opcional (campo de DATOS)
A56: 3 · PAL factorial (FAO) | B56: GEB × (Σ(MET×h)/24) | C56: Sí, el PAL ya lo contiene
A58: C5b · LISTA SÍ / NO
...

Sheet CHANGELOG
A1: NUTRIMETRÍA · NMX-10
A2: Historial de versiones
A3: =HYPERLINK("#INICIO!A1","◀ INICIO") -> ◀ INICIO
A5: Versión | B5: Fecha | C5: Cambio | D5: Motivo | E5: Responsable
A6: 1.0 | B6: 2026-07-14 | C6: Versión inicial. Motor de requerimiento por componentes (GEB+AEE+ETA), diario MET con AEE = Σ máx(MET−1,0)×h, ETA por % fijo y por macronutrientes (Westerterp), y comparación con los métodos MET puro y PAL factorial (FAO), con control de doble conteo. | D6: Primera entrega del producto 10. | E6: Equipo Nutrimetría
A7: 1.0 | B7: 2026-07-14 | C7: Banco de pruebas con 40+ casos (exactitud GEB, AEE/MET, ETA, los 3 métodos, validaciones, integridad y cotejo manual con la publicación). | D7: Control de calidad previo a la entrega. | E7: Equipo Nutrimetría
A8: 1.0.1 | B8: 2026-08-02 | C8: Se incorpora Harris–Benedict revisada (Roza & Shizgal, 1984) al selector de GEB, con coeficientes auditables, validación de estatura, fuente y prueba independiente. | D8: Integrar al NMX-10 una ecuación de GEB disponible en el NMX-01 sin modificar el diseño visual. | E8: Equipo Nutrimetría
