Workbook
Name c_CAG: CALCULOS!$B$11
Name c_CCG: CALCULOS!$B$12
Name c_Clase: CALCULOS!$B$30
Name c_Ecto: CALCULOS!$B$21
Name c_Endo: CALCULOS!$B$19
Name c_Gate: CALCULOS!$B$16
Name c_HWR: CALCULOS!$B$13
Name c_Meso: CALCULOS!$B$20
Name c_mid: CALCULOS!$B$29
Name c_mn: CALCULOS!$B$28
Name c_mx: CALCULOS!$B$27
Name c_Soma: CALCULOS!$B$22
Name c_Sum3: CALCULOS!$B$9
Name c_SX: CALCULOS!$B$25
Name c_SY: CALCULOS!$B$26
Name c_TallaM: CALCULOS!$B$8
Name c_Xcorr: CALCULOS!$B$10
Name DIA_MAX: CONFIG!$B$19
Name DIA_MIN: CONFIG!$B$18
Name ECTO_A1: CONFIG!$B$37
Name ECTO_A2: CONFIG!$B$39
Name ECTO_B1: CONFIG!$B$38
Name ECTO_B2: CONFIG!$B$40
Name ECTO_T1: CONFIG!$B$35
Name ECTO_T2: CONFIG!$B$36
Name EDAD_MAX: CONFIG!$B$11
Name EDAD_MIN: CONFIG!$B$10
Name ENDO_C0: CONFIG!$B$24
Name ENDO_C1: CONFIG!$B$25
Name ENDO_C2: CONFIG!$B$26
Name ENDO_C3: CONFIG!$B$27
Name ENDO_HREF: CONFIG!$B$28
Name EST_MAX: CONFIG!$B$15
Name EST_MIN: CONFIG!$B$14
Name in_Edad: DATOS!$B$11
Name in_Est: DATOS!$B$13
Name in_Eval: DATOS!$B$14
Name in_Fecha: DATOS!$B$8
Name in_ID: DATOS!$B$7
Name in_Obs: DATOS!$B$15
Name in_Pac: DATOS!$B$9
Name in_Peso: DATOS!$B$12
Name in_Sexo: DATOS!$B$10
Name m_ArmG: MEDIDAS!$C$16
Name m_Calf: MEDIDAS!$C$11
Name m_CalfG: MEDIDAS!$C$17
Name m_Fem: MEDIDAS!$C$14
Name m_Hum: MEDIDAS!$C$13
Name m_Sub: MEDIDAS!$C$9
Name m_Sup: MEDIDAS!$C$10
Name m_Tri: MEDIDAS!$C$8
Name MESO_CAG: CONFIG!$B$31
Name MESO_CCG: CONFIG!$B$32
Name MESO_FB: CONFIG!$B$30
Name MESO_H: CONFIG!$B$33
Name MESO_HB: CONFIG!$B$29
Name MESO_K: CONFIG!$B$34
Name MIN_COMP: CONFIG!$B$22
Name PER_MAX: CONFIG!$B$21
Name PER_MIN: CONFIG!$B$20

Sheet DATOS
A1: NUTRIMETRÍA · NMX-16
A2: Datos de entrada · identificación y datos básicos
A3: =HYPERLINK("#INICIO!A1","◀ INICIO") -> ◀ INICIO | B3: =HYPERLINK("#CALCULOS!A1","▶ CALCULOS") -> ▶ CALCULOS | D3: =HYPERLINK("#RESULTADOS!A1","▶ RESULTADOS") -> ▶ RESULTADOS
A4: LEYENDA · Celdas ARENA con texto AZUL = editables. Grises = calculadas. (opcional) = puede quedar vacía.
A5: ► Las mediciones antropométricas se ingresan en la hoja MEDIDAS.
A6: Campo | B6: Valor | C6: Unidad | D6: Validación | E6: Ayuda
A7: Identificador de la evaluación | B7: NMX-2026-0016 | C7: — | D7: Texto libre | E7: Código interno.
A8: Fecha | B8: 46217 | C8: fecha | D8: Fecha | E8: dd/mm/aaaa.
A9: Nombre o código del paciente | B9: PAC-0083 | C9: — | D9: Texto libre | E9: Prefiera un CÓDIGO si comparte el archivo.
A10: Sexo biológico | B10: Hombre | C10: — | D10: Lista: Hombre / Mujer | E10: Referencia; las ecuaciones HC no dependen del sexo.
A11: Edad | B11: 34 | C11: años | D11: ≥18 y ≤120 | E11: Solo adultos.
A12: Peso | B12: 78.5 | C12: kg | D12: Entre 25 y 350 | E12: Necesario para la ectomorfia.
A13: Estatura | B13: 176 | C13: cm | D13: Entre 120 y 230 | E13: Necesaria para las tres componentes.
A14: Evaluador | B14: EVAL-01 | C14: — | D14: Texto libre | E14: Para trazabilidad.
A15: Observaciones | C15: — | D15: Texto libre | E15: Contexto, calibración, condiciones.

Sheet INICIO
A1: NUTRIMETRÍA · NMX-16
A2: Calculadora de somatotipo y somatocarta · versión 1.0
A4: Navegación — use las pestañas inferiores del libro
A5: =HYPERLINK("#DATOS!A1","▶ DATOS") -> ▶ DATOS | B5: =HYPERLINK("#MEDIDAS!A1","▶ MEDIDAS") -> ▶ MEDIDAS | D5: =HYPERLINK("#CALCULOS!A1","▶ CALCULOS") -> ▶ CALCULOS | F5: =HYPERLINK("#RESULTADOS!A1","▶ RESULTADOS") -> ▶ RESULTADOS | H5: =HYPERLINK("#FUENTES!A1","▶ FUENTES") -> ▶ FUENTES | J5: =HYPERLINK("#PRUEBAS!A1","▶ PRUEBAS") -> ▶ PRUEBAS | L5: =HYPERLINK("#CONFIG!A1","▶ CONFIG") -> ▶ CONFIG | N5: =HYPERLINK("#CHANGELOG!A1","▶ CHANGELOG") -> ▶ CHANGELOG
A6: Ingresar datos | B6: Medidas corporales | D6: Auditar operaciones | F6: Ver resumen | H6: Trazabilidad | J6: Control de calidad | L6: Constantes | N6: Historial
A7: Código del producto | D7: NMX-16
A8: Versión | D8: 1.0
A9: Fecha | D9: 2026-07-14
A10: Método | D10: Antropométrico de Heath–Carter
A11: Formato | D11: .xlsx sin macros · Microsoft 365 y Excel 2021
A12: Responsable | D12: Equipo Nutrimetría (completar por el titular)
A13: AVISO DE ALCANCE — LÉALO ANTES DE USAR
A14: EXACTITUD MATEMÁTICA ≠ VALIDACIÓN CLÍNICA. Este archivo NO está validado clínicamente.
A15: APLICA A: personas ADULTAS (≥18 años).
A16: El somatotipo describe la FORMA corporal; NO mide composición ni diagnostica por sí solo.
A17: La precisión depende de la técnica de medición (estándar ISAK): puntos anatómicos y plicómetro calibrado.
A18: Los tres componentes deben interpretarse en conjunto, no de forma aislada.
A19: Un componente cuyo cálculo sea ≤0 se fija en 0,1 por definición del método.
A20: PROPÓSITO Y ALCANCE
A21: Propósito | D21: Proveer una herramienta automatizada para determinar los componentes de endomorfia, mesomorfia y ectomorfia según el método antropométrico de Heath-Carter, permitiendo visualizar la distribución morfológica en la somatocarta como complemento a la evaluación física.
A22: Población | D22: Personas adultas (≥18 años).
A23: Uso | D23: El somatotipo describe la FORMA corporal; NO mide composición ni diagnostica por sí solo.
A24: Compatibilidad | D24: .xlsx sin macros · Microsoft 365 y Excel 2021
A25: Privacidad | D25: Los datos permanecen en el archivo local. El libro no transmite información.
A26: CÓMO SE MODELA
A27: Endomorfia: polinomio sobre Σ(tríceps+subescapular+supraespinal) corregida por talla (×170,18/estatura).
A28: Mesomorfia: diámetros de húmero y fémur + perímetros de brazo y pantorrilla corregidos − 0,131·talla + 4,5.
A29: Ectomorfia: según el índice talla/peso^(1/3) (HWR), en tres tramos.
A30: Somatocarta: X = ecto − endo · Y = 2·meso − (endo+ecto).
A31: Clasificación en 13 categorías según qué componente domina y sus diferencias.

Sheet MEDIDAS
A1: NUTRIMETRÍA · NMX-16
A2: Panel antropométrico · Heath–Carter (lado derecho del cuerpo)
A3: Marque los puntos anatómicos antes de medir. Los pliegues van en mm; los diámetros óseos y perímetros, en cm. Endomorfia: tríceps + subescapular + supraespinal. Mesomorfia: húmero, fémur, brazo y pantorrilla (perímetros corregidos con sus pliegues). Ectomorfia: peso y estatura (hoja DATOS).
A4: =HYPERLINK("#DATOS!A1","◀ DATOS") -> ◀ DATOS | C4: =HYPERLINK("#CALCULOS!A1","◀ CALCULOS") -> ◀ CALCULOS
A6: Nº | B6: Medida | C6: Valor | D6: Unidad | E6: Referencia anatómica / técnica
A7: Pliegues cutáneos (mm)
A8: 1 | B8: Tríceps | C8: 10 | D8: mm | E8: Vertical, cara posterior del brazo, punto medio.
A9: 2 | B9: Subescapular | C9: 12 | D9: mm | E9: Oblicuo, 2 cm bajo el ángulo inferior de la escápula.
A10: 3 | B10: Supraespinal (cresta ilíaca ant.) | C10: 8 | D10: mm | E10: Oblicuo, sobre la espina ilíaca anterosuperior.
A11: 4 | B11: Pantorrilla medial | C11: 8 | D11: mm | E11: Vertical, cara medial, máximo perímetro.
A12: Diámetros óseos (cm)
A13: 5 | B13: Húmero (biepicondíleo) | C13: 7 | D13: cm | E13: Entre epicóndilo y epitróclea, codo a 90°.
A14: 6 | B14: Fémur (biepicondíleo) | C14: 9.6 | D14: cm | E14: Entre cóndilos femorales, sentado, rodilla a 90°.
A15: Perímetros (cm)
A16: 7 | B16: Brazo flexionado en tensión | C16: 33 | D16: cm | E16: Máximo, con el brazo contraído.
A17: 8 | B17: Pantorrilla (máximo) | C17: 37 | D17: cm | E17: Máximo perímetro de la pantorrilla.
A18: ► El brazo y la pantorrilla se corrigen automáticamente restando su pliegue: brazo − tríceps/10 y pantorrilla − pliegue de pantorrilla/10.

Sheet CALCULOS
A1: NUTRIMETRÍA · NMX-16
A2: Motor · endomorfia, mesomorfia, ectomorfia y somatocarta
A3: =HYPERLINK("#DATOS!A1","◀ DATOS") -> ◀ DATOS | B3: =HYPERLINK("#'MEDIDAS'!A1", "◀ MEDIDAS") -> ◀ MEDIDAS | C3: =HYPERLINK("#RESULTADOS!A1","▶ RESULTADOS") -> ▶ RESULTADOS
A4: Cada celda declara su fórmula. Las guardas devuelven 'ND: …' en vez de errores. Un componente cuyo cálculo sea ≤0 se fija en 0,1 por definición (Carter).
A6: BLOQUE 0 · MEDIDAS DERIVADAS
A7: Variable | B7: Valor | C7: Unidad | D7: Fórmula / cómo se obtiene
A8: Estatura en metros | B8: =IF(ISNUMBER(in_Est),in_Est/100,"ND") -> 1.76 | C8: m | D8: in_Est/100
A9: Σ 3 pliegues (endomorfia) | B9: =IF(AND(ISNUMBER(m_Tri),ISNUMBER(m_Sub),ISNUMBER(m_Sup)),m_Tri+m_Sub+m_Sup,"ND: faltan pliegues") -> 30 | C9: mm | D9: tríceps+subescapular+supraespinal
A10: Σ corregida por talla (X) | B10: =IF(AND(ISNUMBER(c_Sum3),ISNUMBER(in_Est),in_Est>0),c_Sum3*(ENDO_HREF/in_Est),"ND") -> 29.007955 | C10: mm | D10: Σ3 × (170,18 / estatura)
A11: Perímetro de brazo corregido | B11: =IF(AND(ISNUMBER(m_ArmG),ISNUMBER(m_Tri)),m_ArmG-m_Tri/10,"ND") -> 32 | C11: cm | D11: brazo − tríceps/10
A12: Perímetro de pantorrilla corregido | B12: =IF(AND(ISNUMBER(m_CalfG),ISNUMBER(m_Calf)),m_CalfG-m_Calf/10,"ND") -> 36.2 | C12: cm | D12: pantorrilla − pliegue/10
A13: Índice talla/peso (HWR) | B13: =IF(AND(ISNUMBER(in_Est),ISNUMBER(in_Peso),in_Peso>0),in_Est/(in_Peso^(1/3)),"ND") -> 41.104507 | C13: — | D13: estatura / peso^(1/3)
A14: BLOQUE 1 · COMPUERTA DE DATOS IMPOSIBLES
A15: Variable | B15: Valor | C15: Unidad | D15: Fórmula / cómo se obtiene
A16: ¿Cálculo habilitado? | B16: =IF(AND(ISNUMBER(in_Edad),in_Edad>=EDAD_MIN,in_Edad<=EDAD_MAX,ISNUMBER(in_Peso),in_Peso>=PESO_MIN,in_Peso<=PESO_MAX,ISNUMBER(in_Est),in_Est>=EST_MIN,in_Est<=EST_MAX),"SÍ","NO") -> SÍ | C16: — | D16: Exige edad adulta, peso y estatura válidos
A17: BLOQUE 2 · COMPONENTES DEL SOMATOTIPO
A18: Variable | B18: Valor | C18: Unidad | D18: Fórmula / cómo se obtiene
A19: Endomorfia | B19: =IF(AND(c_Gate="SÍ",ISNUMBER(c_Xcorr)),MAX(MIN_COMP,ENDO_C0+ENDO_C1*c_Xcorr-ENDO_C2*c_Xcorr^2+ENDO_C3*c_Xcorr^3),"ND") -> 2.9528331 | C19: — | D19: Polinomio de 3er grado sobre X
A20: Mesomorfia | B20: =IF(AND(c_Gate="SÍ",ISNUMBER(m_Hum),ISNUMBER(m_Fem),ISNUMBER(c_CAG),ISNUMBER(c_CCG),ISNUMBER(in_Est)),MAX(MIN_COMP,MESO_HB*m_Hum+MESO_FB*m_Fem+MESO_CAG*c_CAG+MESO_CCG*c_CCG-MESO_H*in_Est+MESO_K),"ND") -> 5.0638 | C20: — | D20: Diámetros y perímetros corregidos − 0,131·talla + 4,5
A21: Ectomorfia | B21: =IF(AND(c_Gate="SÍ",ISNUMBER(c_HWR)),MAX(MIN_COMP,IF(c_HWR>=ECTO_T1,ECTO_A1*c_HWR-ECTO_B1,IF(c_HWR>ECTO_T2,ECTO_A2*c_HWR-ECTO_B2,MIN_COMP))),"ND") -> 1.5084995 | C21: — | D21: Según el tramo del HWR
A22: Somatotipo | B22: =IF(AND(ISNUMBER(c_Endo),ISNUMBER(c_Meso),ISNUMBER(c_Ecto)),TEXT(c_Endo,"0.0")&" - "&TEXT(c_Meso,"0.0")&" - "&TEXT(c_Ecto,"0.0"),"ND") -> 03 - 05 - 02 | C22: — | D22: endo − meso − ecto
A23: BLOQUE 3 · SOMATOCARTA Y CLASIFICACIÓN
A24: Variable | B24: Valor | C24: Unidad | D24: Fórmula / cómo se obtiene
A25: Coordenada X | B25: =IF(AND(ISNUMBER(c_Endo),ISNUMBER(c_Ecto)),c_Ecto-c_Endo,"ND") -> -1.4443337 | C25: — | D25: ecto − endo
A26: Coordenada Y | B26: =IF(AND(ISNUMBER(c_Endo),ISNUMBER(c_Meso),ISNUMBER(c_Ecto)),2*c_Meso-(c_Endo+c_Ecto),"ND") -> 5.6662674 | C26: — | D26: 2·meso − (endo+ecto)
A27: Máximo componente | B27: =IF(ISNUMBER(c_Endo),MAX(c_Endo,c_Meso,c_Ecto),"ND") -> 5.0638 | C27: —
A28: Mínimo componente | B28: =IF(ISNUMBER(c_Endo),MIN(c_Endo,c_Meso,c_Ecto),"ND") -> 1.5084995 | C28: —
A29: Componente medio | B29: =IF(ISNUMBER(c_Endo),c_Endo+c_Meso+c_Ecto-c_mx-c_mn,"ND") -> 2.9528331 | C29: —
A30: Clasificación (13 categorías) | B30: =IF(AND(ISNUMBER(c_Endo),ISNUMBER(c_Meso),ISNUMBER(c_Ecto)),IF((c_mx-c_mn)<=1,"Central",IF((c_mx-c_mid)<=0.5,IF(c_mn=c_Ecto,"Endomorfo-mesomorfo",IF(c_mn=c_Endo,"Mesomorfo-ectomorfo","Endomorfo-ectomorfo")),IF((c_mid-c_mn)<=0.5,IF(c_mx=c_Meso,"Mesomorfo",IF(c_mx=c_Endo,"Endomorfo","Ectomorfo"))&" balanceado",IF(c_mx=c_Meso,"Mesomorfo",IF(c_mx=c_Endo,"Endomorfo","Ectomorfo"))&" "&IF(c_mid=c_Endo,"endomórfico",IF(c_mid=c_Meso,"mesomórfico","ectomórfico"))))),"ND") -> Mesomorfo endomórfico | C30: — | D30: Regla de Carter & Heath según dominancia
A31: BLOQUE 4 · ADVERTENCIAS
A32: Variable | B32: Valor | C32: Unidad | D32: Fórmula / cómo se obtiene
A33: Cálculo bloqueado | B33: =IF(c_Gate="NO","Corrija los datos imposibles (edad, peso o estatura) antes de interpretar.","—") -> —
A34: Endomorfia sin datos | B34: =IF(ISNUMBER(c_Endo),"—","Faltan pliegues (tríceps, subescapular o supraespinal) para la endomorfia.") -> —
A35: Mesomorfia sin datos | B35: =IF(ISNUMBER(c_Meso),"—","Faltan diámetros o perímetros para la mesomorfia.") -> —
A36: Ectomorfia sin datos | B36: =IF(ISNUMBER(c_Ecto),"—","Falta peso o estatura para la ectomorfia.") -> —
A37: Componente en su piso (0,1) | B37: =IF(OR(AND(ISNUMBER(c_Endo),c_Endo<=MIN_COMP),AND(ISNUMBER(c_Meso),c_Meso<=MIN_COMP),AND(ISNUMBER(c_Ecto),c_Ecto<=MIN_COMP)),"Algún componente quedó en su valor mínimo (0,1): revise las mediciones extremas.","—") -> —
A38: Medida fuera de rango habitual | B38: =IF(OR(AND(ISNUMBER(m_Hum),OR(m_Hum<DIA_MIN,m_Hum>DIA_MAX)),AND(ISNUMBER(m_Fem),OR(m_Fem<DIA_MIN,m_Fem>DIA_MAX)),AND(ISNUMBER(m_ArmG),OR(m_ArmG<PER_MIN,m_ArmG>PER_MAX)),AND(ISNUMBER(m_CalfG),OR(m_CalfG<PER_MIN,m_CalfG>PER_MAX))),"Algún diámetro o perímetro está fuera del rango habitual: verifique la medición.","—") -> —
A39: Recordatorio metodológico | B39: ="Exactitud matemática ≠ validación clínica. El somatotipo describe la FORMA corporal, no diagnostica ni mide composición por sí solo." -> Exactitud matemática ≠ validación clínica. El somatotipo describe la FORMA corporal, no diagnostica ni mide composición por sí solo.

Sheet RESULTADOS
A1: NUTRIMETRÍA · NMX-16
A2: Informe de somatotipo y somatocarta
A3: =HYPERLINK("#DATOS!A1","◀ DATOS") -> ◀ DATOS | B3: =HYPERLINK("#'MEDIDAS'!A1", "◀ MEDIDAS") -> ◀ MEDIDAS | D3: =HYPERLINK("#CALCULOS!A1","◀ CALCULOS") -> ◀ CALCULOS | G3: =HYPERLINK("#FUENTES!A1","▶ FUENTES") -> ▶ FUENTES
A5: IDENTIFICACIÓN
A6: Identificador | B6: =in_ID -> NMX-2026-0016
A7: Fecha | B7: =in_Fecha -> 46217
A8: Paciente | B8: =in_Pac -> PAC-0083
A9: Evaluador | B9: =in_Eval -> EVAL-01
A10: Sexo · edad | B10: =in_Sexo&" · "&IF(ISNUMBER(in_Edad),in_Edad&" años","(edad no válida)") -> Hombre · 34 años
A11: Peso · estatura | B11: =IF(ISNUMBER(in_Peso),ROUND(in_Peso,1)&" kg","(?)")&" · "&IF(ISNUMBER(in_Est),ROUND(in_Est,1)&" cm","(?)") -> 78,5 kg · 176 cm
A12: Estado del cálculo | B12: =IF(c_Gate="SÍ","HABILITADO","BLOQUEADO — corrija los datos imposibles") -> HABILITADO
A14: SOMATOTIPO
A15: Endomorfia (relativa adiposidad) | B15: =c_Endo -> 2.9528331
A16: Mesomorfia (robustez musculoesquelética) | B16: =c_Meso -> 5.0638
A17: Ectomorfia (linealidad) | B17: =c_Ecto -> 1.5084995
A18: Somatotipo | B18: =c_Soma -> 03 - 05 - 02
A19: Clasificación | B19: =c_Clase -> Mesomorfo endomórfico
A21: SOMATOCARTA
A22: Coordenada X (ecto − endo) | B22: =c_SX -> -1.4443337
A23: Coordenada Y (2·meso − (endo+ecto)) | B23: =c_SY -> 5.6662674
A25: Serie | B25: X | C25: Y
A26: =CONFIG!A53 -> Endomorfia (7-1-1) | B26: =CONFIG!B53 -> -6 | C26: =CONFIG!C53 -> -6
A27: =CONFIG!A54 -> Mesomorfia (1-7-1) | B27: =CONFIG!B54 -> 0 | C27: =CONFIG!C54 -> 12
A28: =CONFIG!A55 -> Ectomorfia (1-1-7) | B28: =CONFIG!B55 -> 6 | C28: =CONFIG!C55 -> -6
A29: =CONFIG!A56 -> cierre | B29: =CONFIG!B56 -> -6 | C29: =CONFIG!C56 -> -6
A30: Sujeto | B30: =c_SX -> -1.4443337 | C30: =c_SY -> 5.6662674
A32: DATOS DE APOYO (gráfico de componentes)
A33: Componente | B33: Valor
A34: Endomorfia | B34: =IF(ISNUMBER(c_Endo),c_Endo,0) -> 2.9528331
A35: Mesomorfia | B35: =IF(ISNUMBER(c_Meso),c_Meso,0) -> 5.0638
A36: Ectomorfia | B36: =IF(ISNUMBER(c_Ecto),c_Ecto,0) -> 1.5084995
A38: ADVERTENCIAS
A39: Cálculo bloqueado | B39: =CALCULOS!B33 -> —
A40: Endomorfia sin datos | B40: =CALCULOS!B34 -> —
A41: Mesomorfia sin datos | B41: =CALCULOS!B35 -> —
A42: Ectomorfia sin datos | B42: =CALCULOS!B36 -> —
A43: Componente en su piso | B43: =CALCULOS!B37 -> —
A44: Medida fuera de rango | B44: =CALCULOS!B38 -> —
A45: Recordatorio metodológico | B45: =CALCULOS!B39 -> Exactitud matemática ≠ validación clínica. El somatotipo describe la FORMA corporal, no diagnostica ni mide composición por sí solo.
A46: EXACTITUD MATEMÁTICA ≠ VALIDACIÓN CLÍNICA. Los coeficientes se cotejaron contra el manual de Heath–Carter, pero este archivo NO está validado clínicamente. El somatotipo describe la FORMA corporal; no mide composición por sí solo ni constituye diagnóstico. La precisión depende de la técnica de medición (ISAK).

Sheet FUENTES
A1: NUTRIMETRÍA · NMX-16
A2: Trazabilidad del método antropométrico de Heath–Carter
A3: NIVEL A = manual/publicación oficial del método · B = corroboración por pares · C = fuente secundaria. Solo se usan ECUACIONES y COEFICIENTES (hechos no protegibles). EXACTITUD BIBLIOGRÁFICA ≠ VALIDACIÓN CLÍNICA.
A4: =HYPERLINK("#INICIO!A1","◀ INICIO") -> ◀ INICIO | B4: =HYPERLINK("#DATOS!A1","◀ DATOS") -> ◀ DATOS | C4: =HYPERLINK("#CALCULOS!A1","◀ CALCULOS") -> ◀ CALCULOS
A5: Ecuación o dato | B5: Autor u organización | C5: Año | D5: Población / base | E5: Fórmula / valor | F5: Unidades | G5: Limitaciones | H5: DOI o fuente | I5: Fecha cotejo | J5: Licencia / condiciones | K5: Nivel
A6: Método antropométrico de somatotipo | B6: Carter JEL — The Heath-Carter Anthropometric Somatotype, Instruction Manual | C6: 1990/2002 | D6: Basado en Heath & Carter (1967); San Diego State University | E6: Tres componentes: endomorfia, mesomorfia, ectomorfia | F6: unidades adimensionales | G6: Describe la FORMA, no la composición; depende de la técnica de medición. | H6: somatotype.org · Instruction Manual | I6: 2026-07-16 | J6: Manual reproducible para uso docente sin permiso específico (según el propio manual); se usan las ecuaciones. | K6: A
A7: Endomorfia (corregida por talla) | B7: Carter & Heath | C7: 1990 | D7: Polinomio de 3er grado | E7: Endo = −0,7182 + 0,1451·X − 0,00068·X² + 0,0000014·X³ ; X = Σ3·(170,18/talla) | F7: mm; adimensional | G7: Σ3 = tríceps+subescapular+supraespinal; sensible a la calidad de los pliegues. | H7: Heath-Carter Manual | I7: 2026-07-16 | J7: Se usa la ecuación (hecho no protegible). | K7: A
A8: Mesomorfia | B8: Carter & Heath | C8: 1990 | D8: Diámetros óseos y perímetros corregidos | E8: Meso = 0,858·húmero + 0,601·fémur + 0,188·brazoC + 0,161·pantorrillaC − 0,131·talla + 4,5 | F8: cm; adimensional | G8: Perímetros corregidos por el pliegue respectivo (÷10 para pasar mm→cm). | H8: Heath-Carter Manual | I8: 2026-07-16 | J8: Se usa la ecuación (hecho no protegible). | K8: A
A9: Ectomorfia (por HWR) | B9: Carter & Heath | C9: 1990 | D9: Índice talla/peso HWR = talla / peso^(1/3) | E9: HWR≥40,75: 0,732·HWR−28,58 · 38,25<HWR<40,75: 0,463·HWR−17,63 · HWR≤38,25: 0,1 | F9: adimensional | G9: Tres tramos; un componente ≤0 se fija en 0,1. | H9: Heath-Carter Manual | I9: 2026-07-16 | J9: Se usa la ecuación (hecho no protegible). | K9: A
A10: Clasificación en 13 categorías | B10: Carter & Heath — Somatotyping: development and applications | C10: 1990 | D10: Regla de dominancia de componentes | E10: Central / balanceado / ‘-’ / adjetivado según dominancia y diferencias | F10: — | G10: Categoría cualitativa; los valores numéricos son la información primaria. | H10: Cambridge University Press, 1990 | I10: 2026-07-16 | J10: Obra con derechos de autor; se usa el criterio de clasificación (hecho no protegible). | K10: B
A11: Estandarización de la medición | B11: ISAK — International Standards for Anthropometric Assessment | C11: 2001/vigente | D11: Estándar internacional de cineantropometría | E11: Puntos anatómicos y técnica de pliegues, diámetros y perímetros | F11: mm; cm | G11: La reproducibilidad depende de la acreditación del evaluador. | H11: ISAK · normas | I11: 2026-07-16 | J11: Estándar de la sociedad ISAK; se usa la definición técnica. | K11: A
A13: VERIFICADO (2026-07-23): el umbral bajo del HWR usado en el motor es 38,25, confirmado contra múltiples fuentes revisadas por pares que aplican el método Heath–Carter (p. ej. Frontiers in Physiology, 2025; PMC). La cifra de 38,35 que circula en algunas copias secundarias (diapositivas) es la errata; no se usa aquí. Aun así, se recomienda cotejar contra la edición física del manual de Carter (1990/2002) antes de un uso clínico o docente formal.
A15: NOTA EDITORIAL AÑADIDA (2026-07-23): los límites de "impossible data" para pliegues cutáneos en CONFIG (2 mm a 60 mm) son una cota práctica de plicometría/ISAK definida por el equipo del producto, no un valor tomado del manual Heath–Carter. El titular puede ajustarlos en CONFIG!B16:B17 según su propio protocolo.

Sheet PRUEBAS
A1: NUTRIMETRÍA · NMX-16
A2: Banco de verificación · el recuento se calcula solo en el RESUMEN
A3: REGLA: el valor ESPERADO nunca lee el CONFIG que usa el motor. O es un literal calculado a partir del manual de Heath–Carter, o se reconstruye con los coeficientes publicados escritos de forma explícita. Si alguien corrompe un coeficiente de CONFIG, estas pruebas FALLAN.
A4: =HYPERLINK("#INICIO!A1","◀ INICIO") -> ◀ INICIO
A6: BLOQUE A · EXACTITUD ENDOMORFIA (polinomio corregido por talla)
A7: ID | B7: Descripción | C7: Σ3 | D7: Talla | E7: Obtenido | F7: Esperado | G7: Dif. | H7: Estado
A8: A01 | B8: Σ30 H176 | C8: 30 | D8: 176 | E8: =MAX(0.1,-0.7182+0.1451*(C8*(170.18/D8))-0.00068*(C8*(170.18/D8))^2+0.0000014*(C8*(170.18/D8))^3) -> 2.9528331 | F8: 2.952833 | G8: =E8-F8 -> 1.389989e-07 | H8: =IF(ABS(G8)<=TOL_U,"APROBADO","FALLIDO") -> APROBADO
A9: A02 | B9: Σ45 H165 | C9: 45 | D9: 165 | E9: =MAX(0.1,-0.7182+0.1451*(C9*(170.18/D9))-0.00068*(C9*(170.18/D9))^2+0.0000014*(C9*(170.18/D9))^3) -> 4.6914421 | F9: 4.691442 | G9: =E9-F9 -> 7.3974192e-08 | H9: =IF(ABS(G9)<=TOL_U,"APROBADO","FALLIDO") -> APROBADO
A10: A03 | B10: Σ60 H180 | C10: 60 | D10: 180 | E10: =MAX(0.1,-0.7182+0.1451*(C10*(170.18/D10))-0.00068*(C10*(170.18/D10))^2+0.0000014*(C10*(170.18/D10))^3) -> 5.5802155 | F10: 5.580216 | G10: =E10-F10 -> -4.6497167e-07 | H10: =IF(ABS(G10)<=TOL_U,"APROBADO","FALLIDO") -> APROBADO
A11: A04 | B11: Σ20 H170 | C11: 20 | D11: 170 | E11: =MAX(0.1,-0.7182+0.1451*(C11*(170.18/D11))-0.00068*(C11*(170.18/D11))^2+0.0000014*(C11*(170.18/D11))^3) -> 1.925532 | F11: 1.925532 | G11: =E11-F11 -> 1.5094264e-08 | H11: =IF(ABS(G11)<=TOL_U,"APROBADO","FALLIDO") -> APROBADO
A12: A05 | B12: Σ90 H160 | C12: 90 | D12: 160 | E12: =MAX(0.1,-0.7182+0.1451*(C12*(170.18/D12))-0.00068*(C12*(170.18/D12))^2+0.0000014*(C12*(170.18/D12))^3) -> 8.1685532 | F12: 8.168553 | G12: =E12-F12 -> 2.071471e-07 | H12: =IF(ABS(G12)<=TOL_U,"APROBADO","FALLIDO") -> APROBADO
A13: A06 | B13: Σ15 H190 | C13: 15 | D13: 190 | E13: =MAX(0.1,-0.7182+0.1451*(C13*(170.18/D13))-0.00068*(C13*(170.18/D13))^2+0.0000014*(C13*(170.18/D13))^3) -> 1.1119076 | F13: 1.111908 | G13: =E13-F13 -> -3.8772628e-07 | H13: =IF(ABS(G13)<=TOL_U,"APROBADO","FALLIDO") -> APROBADO
A15: BLOQUE B · EXACTITUD MESOMORFIA
A16: ID | B16: Húmero | C16: Fémur | D16: BrazoC | E16: PantC | F16: Talla | G16: Obtenido | H16: Esperado | I16: Dif. | J16: Estado
A17: B01 | B17: 7 | C17: 9.6 | D17: 32 | E17: 36.2 | F17: 176 | G17: =MAX(0.1,0.858*B17+0.601*C17+0.188*D17+0.161*E17-0.131*F17+4.5) -> 5.0638 | H17: 5.0638 | I17: =G17-H17 -> 0 | J17: =IF(ABS(I17)<=TOL_U,"APROBADO","FALLIDO") -> APROBADO
A18: B02 | B18: 6.5 | C18: 9 | D18: 28 | E18: 34 | F18: 165 | G18: =MAX(0.1,0.858*B18+0.601*C18+0.188*D18+0.161*E18-0.131*F18+4.5) -> 4.609 | H18: 4.609 | I18: =G18-H18 -> 0 | J18: =IF(ABS(I18)<=TOL_U,"APROBADO","FALLIDO") -> APROBADO
A19: B03 | B19: 7.5 | C19: 10.2 | D19: 36 | E19: 39 | F19: 182 | G19: =MAX(0.1,0.858*B19+0.601*C19+0.188*D19+0.161*E19-0.131*F19+4.5) -> 6.2702 | H19: 6.2702 | I19: =G19-H19 -> 0 | J19: =IF(ABS(I19)<=TOL_U,"APROBADO","FALLIDO") -> APROBADO
A20: B04 | B20: 6 | C20: 8.5 | D20: 26 | E20: 32 | F20: 158 | G20: =MAX(0.1,0.858*B20+0.601*C20+0.188*D20+0.161*E20-0.131*F20+4.5) -> 4.0985 | H20: 4.0985 | I20: =G20-H20 -> 0 | J20: =IF(ABS(I20)<=TOL_U,"APROBADO","FALLIDO") -> APROBADO
A21: B05 | B21: 8 | C21: 10.5 | D21: 40 | E21: 41 | F21: 190 | G21: =MAX(0.1,0.858*B21+0.601*C21+0.188*D21+0.161*E21-0.131*F21+4.5) -> 6.9055 | H21: 6.9055 | I21: =G21-H21 -> 0 | J21: =IF(ABS(I21)<=TOL_U,"APROBADO","FALLIDO") -> APROBADO
A23: BLOQUE C · EXACTITUD ECTOMORFIA · los tres tramos del HWR
A24: ID | B24: Descripción | C24: Talla | D24: Peso | E24: Obtenido | F24: Esperado | G24: Dif. | H24: Estado
A25: C01 | B25: Tramo alto | C25: 176 | D25: 78.5 | E25: =MAX(0.1,IF(C25/(D25^(1/3))>=40.75,0.732*(C25/(D25^(1/3)))-28.58,IF(C25/(D25^(1/3))>38.25,0.463*(C25/(D25^(1/3)))-17.63,0.1))) -> 1.5084995 | F25: 1.508499 | G25: =E25-F25 -> 4.8259255e-07 | H25: =IF(ABS(G25)<=TOL_U,"APROBADO","FALLIDO") -> APROBADO
A26: C02 | B26: Tramo alto delgado | C26: 180 | D26: 60 | E26: =MAX(0.1,IF(C26/(D26^(1/3))>=40.75,0.732*(C26/(D26^(1/3)))-28.58,IF(C26/(D26^(1/3))>38.25,0.463*(C26/(D26^(1/3)))-17.63,0.1))) -> 5.0763103 | F26: 5.07631 | G26: =E26-F26 -> 2.7072485e-07 | H26: =IF(ABS(G26)<=TOL_U,"APROBADO","FALLIDO") -> APROBADO
A27: C03 | B27: Tramo medio | C27: 170 | D27: 72 | E27: =MAX(0.1,IF(C27/(D27^(1/3))>=40.75,0.732*(C27/(D27^(1/3)))-28.58,IF(C27/(D27^(1/3))>38.25,0.463*(C27/(D27^(1/3)))-17.63,0.1))) -> 1.3322561 | F27: 1.332256 | G27: =E27-F27 -> 8.8175658e-08 | H27: =IF(ABS(G27)<=TOL_U,"APROBADO","FALLIDO") -> APROBADO
A28: C04 | B28: Tramo bajo (piso 0,1) | C28: 160 | D28: 85 | E28: =MAX(0.1,IF(C28/(D28^(1/3))>=40.75,0.732*(C28/(D28^(1/3)))-28.58,IF(C28/(D28^(1/3))>38.25,0.463*(C28/(D28^(1/3)))-17.63,0.1))) -> 0.1 | F28: 0.1 | G28: =E28-F28 -> 0 | H28: =IF(ABS(G28)<=TOL_U,"APROBADO","FALLIDO") -> APROBADO
A29: C05 | B29: Muy delgado | C29: 190 | D29: 62 | E29: =MAX(0.1,IF(C29/(D29^(1/3))>=40.75,0.732*(C29/(D29^(1/3)))-28.58,IF(C29/(D29^(1/3))>38.25,0.463*(C29/(D29^(1/3)))-17.63,0.1))) -> 6.5599214 | F29: 6.559921 | G29: =E29-F29 -> 3.8133124e-07 | H29: =IF(ABS(G29)<=TOL_U,"APROBADO","FALLIDO") -> APROBADO
A30: C06 | B30: Robusto bajo | C30: 165 | D30: 90 | E30: =MAX(0.1,IF(C30/(D30^(1/3))>=40.75,0.732*(C30/(D30^(1/3)))-28.58,IF(C30/(D30^(1/3))>38.25,0.463*(C30/(D30^(1/3)))-17.63,0.1))) -> 0.1 | F30: 0.1 | G30: =E30-F30 -> 0 | H30: =IF(ABS(G30)<=TOL_U,"APROBADO","FALLIDO") -> APROBADO
A32: BLOQUE D · COORDENADAS DE LA SOMATOCARTA
A33: ID | B33: Endo | C33: Meso | D33: Ecto | E33: X obt | F33: X esp | G33: Est.X | H33: Y obt | I33: Y esp | J33: Est.Y
A34: D01 | B34: 2.95 | C34: 5.06 | D34: 1.51 | E34: =D34-B34 -> -1.44 | F34: -1.44 | G34: =IF(ABS(E34-F34)<=TOL_U,"APROBADO","FALLIDO") -> APROBADO | H34: =2*C34-(B34+D34) -> 5.66 | I34: 5.66 | J34: =IF(ABS(H34-I34)<=TOL_U,"APROBADO","FALLIDO") -> APROBADO
A35: D02 | B35: 4 | C35: 4 | D35: 2 | E35: =D35-B35 -> -2 | F35: -2 | G35: =IF(ABS(E35-F35)<=TOL_U,"APROBADO","FALLIDO") -> APROBADO | H35: =2*C35-(B35+D35) -> 2 | I35: 2 | J35: =IF(ABS(H35-I35)<=TOL_U,"APROBADO","FALLIDO") -> APROBADO
A36: D03 | B36: 1.5 | C36: 2 | D36: 5.5 | E36: =D36-B36 -> 4 | F36: 4 | G36: =IF(ABS(E36-F36)<=TOL_U,"APROBADO","FALLIDO") -> APROBADO | H36: =2*C36-(B36+D36) -> -3 | I36: -3 | J36: =IF(ABS(H36-I36)<=TOL_U,"APROBADO","FALLIDO") -> APROBADO
A37: D04 | B37: 3 | C37: 3 | D37: 3 | E37: =D37-B37 -> 0 | F37: 0 | G37: =IF(ABS(E37-F37)<=TOL_U,"APROBADO","FALLIDO") -> APROBADO | H37: =2*C37-(B37+D37) -> 0 | I37: 0 | J37: =IF(ABS(H37-I37)<=TOL_U,"APROBADO","FALLIDO") -> APROBADO
A39: BLOQUE E · CLASIFICACIÓN EN 13 CATEGORÍAS
A40: ID | B40: Endo·Meso·Ecto | C40: Esperado | D40: Obtenido | E40: Estado
A41: E01 | B41: 2.95·5.06·1.51 | C41: Mesomorfo endomórfico | D41: =IF((5.06-1.51)<=1,"Central",IF((5.06-2.95)<=0.5,IF(1.51=1.51,"Endomorfo-mesomorfo",IF(1.51=2.95,"Mesomorfo-ectomorfo","Endomorfo-ectomorfo")),IF((2.95-1.51)<=0.5,IF(5.06=5.06,"Mesomorfo",IF(5.06=2.95,"Endomorfo","Ectomorfo"))&" balanceado",IF(5.06=5.06,"Mesomorfo",IF(5.06=2.95,"Endomorfo","Ectomorfo"))&" "&IF(2.95=2.95,"endomórfico",IF(2.95=5.06,"mesomórfico","ectomórfico"))))) -> Mesomorfo endomórfico | E41: =IF(D41=C41,"APROBADO","FALLIDO") -> APROBADO
A42: E02 | B42: 3.0·3.5·3.2 | C42: Central | D42: =IF((3.5-3)<=1,"Central",IF((3.5-3.2)<=0.5,IF(3=3.2,"Endomorfo-mesomorfo",IF(3=3,"Mesomorfo-ectomorfo","Endomorfo-ectomorfo")),IF((3.2-3)<=0.5,IF(3.5=3.5,"Mesomorfo",IF(3.5=3,"Endomorfo","Ectomorfo"))&" balanceado",IF(3.5=3.5,"Mesomorfo",IF(3.5=3,"Endomorfo","Ectomorfo"))&" "&IF(3.2=3,"endomórfico",IF(3.2=3.5,"mesomórfico","ectomórfico"))))) -> Central | E42: =IF(D42=C42,"APROBADO","FALLIDO") -> APROBADO
A43: E03 | B43: 5.0·2.0·2.0 | C43: Endomorfo balanceado | D43: =IF((5-2)<=1,"Central",IF((5-2)<=0.5,IF(2=2,"Endomorfo-mesomorfo",IF(2=5,"Mesomorfo-ectomorfo","Endomorfo-ectomorfo")),IF((2-2)<=0.5,IF(5=2,"Mesomorfo",IF(5=5,"Endomorfo","Ectomorfo"))&" balanceado",IF(5=2,"Mesomorfo",IF(5=5,"Endomorfo","Ectomorfo"))&" "&IF(2=5,"endomórfico",IF(2=2,"mesomórfico","ectomórfico"))))) -> Endomorfo balanceado | E43: =IF(D43=C43,"APROBADO","FALLIDO") -> APROBADO
A44: E04 | B44: 2.0·5.0·2.2 | C44: Mesomorfo balanceado | D44: =IF((5-2)<=1,"Central",IF((5-2.2)<=0.5,IF(2=2.2,"Endomorfo-mesomorfo",IF(2=2,"Mesomorfo-ectomorfo","Endomorfo-ectomorfo")),IF((2.2-2)<=0.5,IF(5=5,"Mesomorfo",IF(5=2,"Endomorfo","Ectomorfo"))&" balanceado",IF(5=5,"Mesomorfo",IF(5=2,"Endomorfo","Ectomorfo"))&" "&IF(2.2=2,"endomórfico",IF(2.2=5,"mesomórfico","ectomórfico"))))) -> Mesomorfo balanceado | E44: =IF(D44=C44,"APROBADO","FALLIDO") -> APROBADO
A45: E05 | B45: 2.0·2.2·6.0 | C45: Ectomorfo balanceado | D45: =IF((6-2)<=1,"Central",IF((6-2.2)<=0.5,IF(2=6,"Endomorfo-mesomorfo",IF(2=2,"Mesomorfo-ectomorfo","Endomorfo-ectomorfo")),IF((2.2-2)<=0.5,IF(6=2.2,"Mesomorfo",IF(6=2,"Endomorfo","Ectomorfo"))&" balanceado",IF(6=2.2,"Mesomorfo",IF(6=2,"Endomorfo","Ectomorfo"))&" "&IF(2.2=2,"endomórfico",IF(2.2=2.2,"mesomórfico","ectomórfico"))))) -> Ectomorfo balanceado | E45: =IF(D45=C45,"APROBADO","FALLIDO") -> APROBADO
...

Sheet CONFIG
A1: NUTRIMETRÍA · NMX-16
A2: Parámetros, coeficientes y catálogos · versión 1.0
A3: =HYPERLINK("#INICIO!A1","◀ INICIO") -> ◀ INICIO
A4: Toda constante del modelo vive aquí; ninguna fórmula del libro contiene un coeficiente escrito a mano. Las celdas arena son editables. Cambiar un valor aquí propaga a todo el libro y hace FALLAR las pruebas que cotejan contra la fuente publicada.
A6: C1 · PARÁMETROS, LÍMITES Y COEFICIENTES DE HEATH–CARTER
A7: Parámetro | B7: Valor | C7: Unidad | D7: Prueba | E7: Nota/Fuente
A8: Idioma | B8: Español (es-CL)
A9: Versión de las fuentes | B9: 2026-07 · v1.0
A10: Edad mínima (adulto) | B10: 18
A11: Edad máxima plausible | B11: 120
A12: Peso mínimo posible | B12: 25
A13: Peso máximo posible | B13: 350 | C13: kg | D13: IMPOSIBLE | E13: Cota de seguridad para datos imposibles; ver DATOS!D12 y PRUEBAS!F03.
A14: Estatura mínima posible | B14: 120 | C14: cm | D14: IMPOSIBLE | E14: Cota de seguridad para datos imposibles; ver DATOS!D13 y PRUEBAS!F04.
A15: Estatura máxima posible | B15: 230 | C15: cm | D15: IMPOSIBLE | E15: Cota de seguridad para datos imposibles; ver DATOS!D13 y PRUEBAS!F04.
A16: Pliegue mínimo por sitio | B16: 2 | C16: mm | D16: IMPOSIBLE | E16: Valor editorial (rango práctico de plicometría/ISAK); el manual Heath-Carter no fija este límite. Ajustable por el titular.
A17: Pliegue máximo por sitio | B17: 60 | C17: mm | D17: IMPOSIBLE | E17: Valor editorial (rango práctico de plicometría/ISAK); el manual Heath-Carter no fija este límite. Ajustable por el titular.
A18: Diámetro óseo mínimo | B18: 3 | C18: cm | D18: IMPOSIBLE | E18: Cota de seguridad para datos imposibles; ver PRUEBAS!F05.
A19: Diámetro óseo máximo | B19: 15 | C19: cm | D19: IMPOSIBLE | E19: Cota de seguridad para datos imposibles; ver PRUEBAS!F05.
A20: Perímetro mínimo | B20: 15 | C20: cm | D20: IMPOSIBLE | E20: Brazo / pantorrilla
A21: Perímetro máximo | B21: 80 | C21: cm | D21: IMPOSIBLE
A22: Componente mínimo (piso) | B22: 0.1 | C22: — | D22: Regla | E22: Un componente ≤0 se fija en 0,1 (Carter)
A23: Tolerancia de pruebas · unidad | B23: 0.01 | C23: — | D23: Umbral | E23: Diferencia máxima en unidades de somatotipo
A24: Endomorfia · término independiente | B24: -0.7182 | C24: — | D24: Coef. | E24: Endo = c0 + c1·X − c2·X² + c3·X³
A25: Endomorfia · coef. lineal | B25: 0.1451 | C25: — | D25: Coef.
A26: Endomorfia · coef. cuadrático | B26: 0.00068 | C26: — | D26: Coef. | E26: (se resta)
A27: Endomorfia · coef. cúbico | B27: 1.4e-06 | C27: — | D27: Coef.
A28: Endomorfia · estatura de referencia | B28: 170.18 | C28: cm | D28: Coef. | E28: Corrección por talla: Σ3·(170,18/H)
A29: Mesomorfia · coef. húmero | B29: 0.858 | C29: — | D29: Coef. | E29: × diámetro biepicondíleo húmero
A30: Mesomorfia · coef. fémur | B30: 0.601 | C30: — | D30: Coef. | E30: × diámetro biepicondíleo fémur
A31: Mesomorfia · coef. perímetro de brazo | B31: 0.188 | C31: — | D31: Coef. | E31: × brazo corregido
A32: Mesomorfia · coef. perímetro de pantorrilla | B32: 0.161 | C32: — | D32: Coef. | E32: × pantorrilla corregida
A33: Mesomorfia · coef. estatura | B33: 0.131 | C33: — | D33: Coef. | E33: (se resta) × estatura
A34: Mesomorfia · constante | B34: 4.5 | C34: — | D34: Coef. | E34: Término independiente
A35: Ectomorfia · umbral alto (HWR) | B35: 40.75 | C35: — | D35: Corte | E35: HWR ≥ 40,75 usa el tramo 1
A36: Ectomorfia · umbral bajo (HWR) | B36: 38.25 | C36: — | D36: Corte | E36: HWR ≤ 38,25 → 0,1
A37: Ectomorfia · pendiente tramo 1 | B37: 0.732 | C37: — | D37: Coef. | E37: 0,732·HWR − 28,58
A38: Ectomorfia · término tramo 1 | B38: 28.58 | C38: — | D38: Coef.
A39: Ectomorfia · pendiente tramo 2 | B39: 0.463 | C39: — | D39: Coef. | E39: 0,463·HWR − 17,63
A40: Ectomorfia · término tramo 2 | B40: 17.63 | C40: — | D40: Coef.
A42: C2 · SEXOS
...

Sheet CHANGELOG
A1: NUTRIMETRÍA · NMX-16
A2: Historial de versiones
A3: =HYPERLINK("#INICIO!A1","◀ INICIO") -> ◀ INICIO
A5: Versión | B5: Fecha | C5: Cambio | D5: Motivo | E5: Responsable
A6: 1.0 | B6: 2026-07-14 | C6: Versión inicial. Somatotipo antropométrico de Heath–Carter (endomorfia, mesomorfia, ectomorfia), clasificación en 13 categorías y somatocarta (gráfico de dispersión con el punto del sujeto). | D6: Primera entrega del producto 16. | E6: Equipo Nutrimetría
A7: 1.0 | B7: 2026-07-14 | C7: Banco de pruebas con exactitud de las tres ecuaciones (incluidos los tres tramos de ectomorfia), clasificación, coordenadas de la somatocarta, validaciones e integridad; valores esperados independientes del CONFIG. | D7: Control de calidad. | E7: Equipo Nutrimetría
