Workbook
Name c_anios: CALCULOS!$B$14
Name c_choReq: CALCULOS!$B$53
Name c_ci75: CALCULOS!$B$42
Name c_ci90: CALCULOS!$B$43
Name C_CINT: CONFIG!$B$19
Name c_diaSob: CALCULOS!$B$10
Name c_Gate: CALCULOS!$B$17
Name c_GET: CALCULOS!$B$48
Name c_iL: CALCULOS!$B$22
Name c_iM: CALCULOS!$B$23
Name C_IMC: CONFIG!$B$17
Name c_imcVal: CALCULOS!$B$18
Name c_iS: CALCULOS!$B$24
Name C_LACT: CONFIG!$B$16
Name c_lipPct: CALCULOS!$B$51
Name c_lipReq: CALCULOS!$B$52
Name c_mes: CALCULOS!$B$13
Name c_mesAprox: CALCULOS!$B$11
Name c_mesCorr: CALCULOS!$B$12
Name c_mesReal: CALCULOS!$B$9
Name C_PCE: CONFIG!$B$18
Name c_pcM2: CALCULOS!$B$40
Name c_pcP2: CALCULOS!$B$41
Name c_peL: CALCULOS!$B$25
Name c_peM: CALCULOS!$B$26
Name c_peS: CALCULOS!$B$27
Name c_proGk: CALCULOS!$B$49
Name c_proReq: CALCULOS!$B$50
Name c_ptL: CALCULOS!$B$28
Name c_ptM: CALCULOS!$B$29
Name c_ptS: CALCULOS!$B$30
Name c_sexoCod: CALCULOS!$B$8
Name c_teM1: CALCULOS!$B$36
Name c_teMed: CALCULOS!$B$37
Name c_teP1: CALCULOS!$B$38
Name c_tKey: CALCULOS!$B$19
Name c_TMB: CALCULOS!$B$47
Name c_zIMC: CALCULOS!$B$33
Name c_zPE: CALCULOS!$B$34
Name c_zPrim: CALCULOS!$B$44
Name c_zPT: CALCULOS!$B$35
Name c_zTE: CALCULOS!$B$39
Name FA: CONFIG!$B$27
Name in_Cintura: DATOS!$B$17
Name in_Eval: DATOS!$B$20
Name in_Fecha: DATOS!$B$11
Name in_FNac: DATOS!$B$10
Name in_ID: DATOS!$B$7
Name in_kcalIng: DATOS!$B$18
Name in_Obs: DATOS!$B$21
Name in_Pac: DATOS!$B$8
Name in_PCe: DATOS!$B$16
Name in_Peso: DATOS!$B$14
Name in_Prem: DATOS!$B$12
Name in_proIng: DATOS!$B$19
Name in_SemGest: DATOS!$B$13
Name in_Sexo: DATOS!$B$9
Name in_Talla: DATOS!$B$15
Name MES_MAX: CONFIG!$B$14
Name PESO_MAX: CONFIG!$B$11

Sheet INICIO
A1: NUTRIMETRÍA · NMX-14
A2: Evaluación nutricional pediátrica integral · versión 2.0.1
A3: =HYPERLINK("#INICIO!A1","● INICIO") -> ● INICIO | B3: =HYPERLINK("#DATOS!A1","▶ DATOS") -> ▶ DATOS | C3: =HYPERLINK("#SEGUIMIENTO!A1","▶ SEGUIMIENTO") -> ▶ SEGUIMIENTO | D3: =HYPERLINK("#CALCULOS!A1","▶ CALCULOS") -> ▶ CALCULOS | E3: =HYPERLINK("#RESULTADOS!A1","▶ RESULTADOS") -> ▶ RESULTADOS | F3: =HYPERLINK("#CURVAS!A1","▶ CURVAS") -> ▶ CURVAS | G3: =HYPERLINK("#FUENTES!A1","▶ FUENTES") -> ▶ FUENTES | H3: =HYPERLINK("#PRUEBAS!A1","▶ PRUEBAS") -> ▶ PRUEBAS | I3: =HYPERLINK("#CONFIG!A1","▶ CONFIG") -> ▶ CONFIG | J3: =HYPERLINK("#TABLAS!A1","▶ TABLAS") -> ▶ TABLAS | K3: =HYPERLINK("#CHANGELOG!A1","▶ CHANGELOG") -> ▶ CHANGELOG
A5: Código del producto | B5: NMX-14
A6: Versión | B6: 2.0.1
A7: Fecha | B7: 2026-08-06
A8: Método | B8: Antropometría OMS (LMS/DE) + MINSAL 2018
A9: Rango | B9: 0 a 19 años (228 meses)
A10: Formato | B10: .xlsx sin macros · Microsoft 365 y Excel 2021
A11: Responsable | B11: Equipo Nutrimetría (completar por el titular)
A12: PROPÓSITO
A13: Proporcionar una evaluación antropométrica integral, automatizada y estandarizada del estado nutricional y crecimiento en población infantojuvenil de 0 a 19 años (0 a 228 meses). Integra el cálculo exacto de puntuaciones Z y percentiles según el método LMS/DE de la OMS y los criterios de clasificación diagnóstica de la Norma Técnica MINSAL (Chile), permitiendo determinar el Diagnóstico Nutricional Integrado (DNI) y realizar el seguimiento longitudinal del canal de crecimiento estaturo-ponderal.
A15: AVISO DE ALCANCE — LÉALO ANTES DE USAR
A16: • | B16: EXACTITUD MATEMÁTICA ≠ VALIDACIÓN CLÍNICA. NO es un diagnóstico médico automático.
A17: • | B17: APLICA A: 0 a 19 años. Cada indicador tiene su propio rango de edad/talla.
A18: • | B18: El indicador primario depende de la edad: P/E o P/T (<12 m), P/T (12–60 m), IMC/edad (≥61 m).
A19: • | B19: Un valor puntual es una foto; lo relevante es el SEGUIMIENTO del canal de crecimiento.
A20: • | B20: En prematuros se corrige la edad hasta 24 m (<32 sem) o 12 m (≥32 sem).
A21: • | B21: Los cortes de tamizaje no reemplazan la evaluación clínica ni el juicio del profesional.
A23: NAVEGACIÓN
A24: =HYPERLINK("#DATOS!A1","▶ DATOS") -> ▶ DATOS
A25: =HYPERLINK("#SEGUIMIENTO!A1","▶ SEGUIMIENTO") -> ▶ SEGUIMIENTO
A26: =HYPERLINK("#CALCULOS!A1","▶ CALCULOS") -> ▶ CALCULOS
A27: =HYPERLINK("#RESULTADOS!A1","▶ RESULTADOS") -> ▶ RESULTADOS
A28: =HYPERLINK("#CURVAS!A1","▶ CURVAS") -> ▶ CURVAS
A29: =HYPERLINK("#FUENTES!A1","▶ FUENTES") -> ▶ FUENTES
A30: =HYPERLINK("#PRUEBAS!A1","▶ PRUEBAS") -> ▶ PRUEBAS
A31: =HYPERLINK("#CONFIG!A1","▶ CONFIG") -> ▶ CONFIG
A32: =HYPERLINK("#TABLAS!A1","▶ TABLAS") -> ▶ TABLAS
A33: =HYPERLINK("#CHANGELOG!A1","▶ CHANGELOG") -> ▶ CHANGELOG
A34: =HYPERLINK("#QA_REAL!A1","▶ QA_REAL · ROBUSTEZ") -> ▶ QA_REAL · ROBUSTEZ

Sheet DATOS
A1: NUTRIMETRÍA · NMX-14
A2: Datos de entrada · un paciente por evaluación
A3: =HYPERLINK("#INICIO!A1","▶ INICIO") -> ▶ INICIO | B3: =HYPERLINK("#DATOS!A1","● DATOS") -> ● DATOS | C3: =HYPERLINK("#SEGUIMIENTO!A1","▶ SEGUIMIENTO") -> ▶ SEGUIMIENTO | D3: =HYPERLINK("#CALCULOS!A1","▶ CALCULOS") -> ▶ CALCULOS | E3: =HYPERLINK("#RESULTADOS!A1","▶ RESULTADOS") -> ▶ RESULTADOS | F3: =HYPERLINK("#CURVAS!A1","▶ CURVAS") -> ▶ CURVAS | G3: =HYPERLINK("#FUENTES!A1","▶ FUENTES") -> ▶ FUENTES | H3: =HYPERLINK("#PRUEBAS!A1","▶ PRUEBAS") -> ▶ PRUEBAS | I3: =HYPERLINK("#CONFIG!A1","▶ CONFIG") -> ▶ CONFIG | J3: =HYPERLINK("#TABLAS!A1","▶ TABLAS") -> ▶ TABLAS | K3: =HYPERLINK("#CHANGELOG!A1","▶ CHANGELOG") -> ▶ CHANGELOG
A4: LEYENDA · Celdas ARENA con texto AZUL = editables. Grises = calculadas. (opcional) = puede quedar vacía. Prefiera un CÓDIGO en vez del nombre si va a compartir el archivo.
A6: Campo | B6: Valor | C6: Unidad | D6: Validación | E6: Ayuda
A7: Identificador de la evaluación | B7: NMX-2026-0014 | C7: — | D7: Texto libre | E7: Código interno.
A8: Nombre o código del paciente | B8: PAC-0102 | C8: — | D8: Texto libre | E8: Use un código si va a compartir.
A9: Sexo | B9: Niño | C9: — | D9: Lista: Niño / Niña | E9: Tablas OMS separadas por sexo.
A10: Fecha de nacimiento | B10: 44743 | C10: fecha | D10: Fecha | E10: dd/mm/aaaa.
A11: Fecha de evaluación | B11: 46204 | C11: fecha | D11: Fecha ≥ nacimiento | E11: dd/mm/aaaa.
A12: ¿Prematuro? | B12: No | C12: — | D12: Lista: Sí / No | E12: Corrige la edad hasta cierto límite.
A13: Semanas de gestación | C13: sem | D13: 24 a 42 (si prematuro) | E13: Solo si es prematuro.
A14: Peso | B14: 16.5 | C14: kg | D14: Entre 1 y 150 | E14: Balanza calibrada.
A15: Talla / longitud | B15: 103 | C15: cm | D15: Entre 40 y 210 | E15: <2 años acostado; ≥2 de pie.
A16: Perímetro cefálico | C16: cm | D16: (opcional, 0–36 m) | E16: Solo hasta 36 meses.
A17: Perímetro de cintura | C17: cm | D17: (opcional, ≥5 años) | E17: Solo desde 5 años.
A18: Energía ingerida | B18: 1250 | C18: kcal | D18: (opcional) | E18: Para el % de adecuación energética.
A19: Proteína ingerida | B19: 30 | C19: g | D19: (opcional) | E19: Para el % de adecuación proteica.
A20: Evaluador | B20: EVAL-01 | C20: — | D20: Texto libre | E20: Para trazabilidad.
A21: Observaciones | C21: — | D21: Texto libre | E21: Contexto clínico.

Sheet SEGUIMIENTO
A1: NUTRIMETRÍA · NMX-14
A2: Seguimiento longitudinal · una fila por evaluación (la tabla se expande al escribir)
A3: =HYPERLINK("#INICIO!A1","▶ INICIO") -> ▶ INICIO | B3: =HYPERLINK("#DATOS!A1","▶ DATOS") -> ▶ DATOS | C3: =HYPERLINK("#SEGUIMIENTO!A1","● SEGUIMIENTO") -> ● SEGUIMIENTO | D3: =HYPERLINK("#CALCULOS!A1","▶ CALCULOS") -> ▶ CALCULOS | E3: =HYPERLINK("#RESULTADOS!A1","▶ RESULTADOS") -> ▶ RESULTADOS | F3: =HYPERLINK("#CURVAS!A1","▶ CURVAS") -> ▶ CURVAS | G3: =HYPERLINK("#FUENTES!A1","▶ FUENTES") -> ▶ FUENTES | H3: =HYPERLINK("#PRUEBAS!A1","▶ PRUEBAS") -> ▶ PRUEBAS | I3: =HYPERLINK("#CONFIG!A1","▶ CONFIG") -> ▶ CONFIG | J3: =HYPERLINK("#TABLAS!A1","▶ TABLAS") -> ▶ TABLAS | K3: =HYPERLINK("#CHANGELOG!A1","▶ CHANGELOG") -> ▶ CHANGELOG
A4: LEYENDA · Escriba una fila por evaluación. IMC se calcula solo. Las columnas de z se copian desde CALCULOS tras cada evaluación (vacío -> 'ND'). Use CÓDIGOS de paciente.
A6: EvalID | B6: PacID | C6: Fecha | D6: EdadReal_m | E6: EdadCorr_m | F6: Peso_kg | G6: TallaLong_cm | H6: IMC | I6: PCe_cm | J6: Cintura_cm | K6: z_primario | L6: z_PT | M6: z_IMC | N6: z_PE | O6: z_TE | P6: z_PCe | Q6: Clasificacion | R6: Evaluador | S6: Observaciones
A7: NMX-2026-0014 | B7: PAC-0102 | C7: 2026-07-01 | D7: 48 | E7: 48 | F7: 16.5 | G7: 103 | H7: =IF(NOT(ISNUMBER(F7)),"ND",IF(F7<=0,"ND",IF(NOT(ISNUMBER(G7)),"ND",IF(G7<=0,"ND",F7/(G7/100)^2)))) -> 15.552833 | K7: 0.196 | L7: 0.196 | M7: ND | N7: ND | O7: -0.071 | Q7: Eutrófico (P/T) | R7: EVAL-01 | S7: Fila de ejemplo — reemplácela
H8: =IF(AND(ISNUMBER(F8),ISNUMBER(G8),G8>0),F8/(G8/100)^2,"")
H9: =IF(AND(ISNUMBER(F9),ISNUMBER(G9),G9>0),F9/(G9/100)^2,"")
H10: =IF(AND(ISNUMBER(F10),ISNUMBER(G10),G10>0),F10/(G10/100)^2,"")
H11: =IF(AND(ISNUMBER(F11),ISNUMBER(G11),G11>0),F11/(G11/100)^2,"")
H12: =IF(AND(ISNUMBER(F12),ISNUMBER(G12),G12>0),F12/(G12/100)^2,"")
H13: =IF(AND(ISNUMBER(F13),ISNUMBER(G13),G13>0),F13/(G13/100)^2,"")
H14: =IF(AND(ISNUMBER(F14),ISNUMBER(G14),G14>0),F14/(G14/100)^2,"")
H15: =IF(AND(ISNUMBER(F15),ISNUMBER(G15),G15>0),F15/(G15/100)^2,"")
H16: =IF(AND(ISNUMBER(F16),ISNUMBER(G16),G16>0),F16/(G16/100)^2,"")
H17: =IF(AND(ISNUMBER(F17),ISNUMBER(G17),G17>0),F17/(G17/100)^2,"")
H18: =IF(AND(ISNUMBER(F18),ISNUMBER(G18),G18>0),F18/(G18/100)^2,"")
H19: =IF(AND(ISNUMBER(F19),ISNUMBER(G19),G19>0),F19/(G19/100)^2,"")
... H45: =IF(AND(ISNUMBER(F45),ISNUMBER(G45),G45>0),F45/(G45/100)^2,"")

Sheet CALCULOS
A1: NUTRIMETRÍA · NMX-14
A2: Motor · edad corregida, z-scores OMS (INDICE/COINCIDIR) y requerimientos
A3: =HYPERLINK("#INICIO!A1","▶ INICIO") -> ▶ INICIO | B3: =HYPERLINK("#DATOS!A1","▶ DATOS") -> ▶ DATOS | C3: =HYPERLINK("#SEGUIMIENTO!A1","▶ SEGUIMIENTO") -> ▶ SEGUIMIENTO | D3: =HYPERLINK("#CALCULOS!A1","● CALCULOS") -> ● CALCULOS | E3: =HYPERLINK("#RESULTADOS!A1","▶ RESULTADOS") -> ▶ RESULTADOS | F3: =HYPERLINK("#CURVAS!A1","▶ CURVAS") -> ▶ CURVAS | G3: =HYPERLINK("#FUENTES!A1","▶ FUENTES") -> ▶ FUENTES | H3: =HYPERLINK("#PRUEBAS!A1","▶ PRUEBAS") -> ▶ PRUEBAS | I3: =HYPERLINK("#CONFIG!A1","▶ CONFIG") -> ▶ CONFIG | J3: =HYPERLINK("#TABLAS!A1","▶ TABLAS") -> ▶ TABLAS | K3: =HYPERLINK("#CHANGELOG!A1","▶ CHANGELOG") -> ▶ CHANGELOG
A4: Sin XLOOKUP ni IFERROR: la búsqueda usa COINCIDIR/INDICE y las guardas devuelven texto 'ND: …' explicando el motivo. Todo coeficiente vive en CONFIG o TABLAS; aquí no hay constantes escritas a mano.
A6: BLOQUE 0 · EDAD
A7: Variable | B7: Valor | C7: Unidad | D7: Fórmula / cómo se obtiene
A8: Código de sexo | B8: =IF(COUNTIF(SEXOS,in_Sexo)>0,INDEX(SEXOS_COD,MATCH(in_Sexo,SEXOS,0)),"ND") -> M | C8: — | D8: M/F
A9: Edad real (meses) | B9: =IF(AND(ISNUMBER(in_FNac),ISNUMBER(in_Fecha),in_Fecha>in_FNac),(YEAR(in_Fecha)-YEAR(in_FNac))*12+MONTH(in_Fecha)-MONTH(in_FNac)-IF(DAY(in_Fecha)<DAY(in_FNac),1,0),"ND") -> 48 | C9: meses | D9: DATEDIF(nac;eval)
A10: Días sobrantes | B10: =IF(ISNUMBER(c_mesReal),in_Fecha-DATE(YEAR(in_FNac),MONTH(in_FNac)+c_mesReal,DAY(in_FNac)),"ND") -> 0 | C10: días
A11: Edad aproximada MINSAL | B11: =IF(ISNUMBER(c_mesReal),IF(c_mesReal<60,IF(c_diaSob<=15,c_mesReal,c_mesReal+1),c_mesReal),"ND") -> 48 | C11: meses | D11: <5 a: redondeo por 15 días
A12: Edad corregida (prematuro) | B12: =IF(NOT(ISNUMBER(c_mesAprox)),"ND",IF(OR(in_Prem="No",in_Prem=""),c_mesAprox,IF(NOT(ISNUMBER(in_SemGest)),"ND",IF(OR(in_SemGest<24,in_SemGest>42),"ND",IF(OR(AND(in_SemGest<32,c_mesAprox>24),AND(in_SemGest>=32,c_mesAprox>12)),c_mesAprox,MAX(0,c_mesAprox-(SEM_TERM-in_SemGest)*7/30.44)))))) -> 48 | C12: meses | D12: Corrige hasta 24 m (<32 sem) o 12 m
A13: Edad para tablas (meses) | B13: =IF(ISNUMBER(c_mesCorr),ROUND(c_mesCorr,0),"ND") -> 48 | C13: meses | D13: Entero para la búsqueda
A14: Edad (años exactos) | B14: =IF(ISNUMBER(c_mesCorr),c_mesCorr/12,"ND") -> 4 | C14: años | D14: Para TMB y proteína
A15: BLOQUE 1 · COMPUERTA Y ANTROPOMETRÍA
A16: Variable | B16: Valor | C16: Unidad | D16: Fórmula / cómo se obtiene
A17: ¿Cálculo habilitado? | B17: =IF(c_sexoCod="ND","NO",IF(NOT(ISNUMBER(c_mes)),"NO",IF(OR(c_mes<0,c_mes>MES_MAX),"NO",IF(NOT(ISNUMBER(in_Peso)),"NO",IF(OR(in_Peso<PESO_MIN,in_Peso>PESO_MAX),"NO",IF(NOT(ISNUMBER(in_Talla)),"NO",IF(OR(in_Talla<TALLA_MIN,in_Talla>TALLA_MAX),"NO",IF(OR(in_Prem="No",in_Prem=""),"SÍ",IF(in_Prem<>"Sí","NO",IF(NOT(ISNUMBER(in_SemGest)),"NO",IF(OR(in_SemGest<24,in_SemGest>42),"NO","SÍ"))))))))))) -> SÍ | C17: — | D17: Exige sexo, fechas, peso y talla válidos
A18: IMC | B18: =IF(c_Gate="SÍ",in_Peso/(in_Talla/100)^2,"ND") -> 15.552833 | C18: kg/m² | D18: peso/talla²
A19: Talla para P/T (0,5 cm) | B19: =IF(c_Gate="SÍ",ROUND(in_Talla*2,0)/2,"ND") -> 103 | C19: cm | D19: Redondeo a 0,5 cm para P/T
A20: BLOQUE 2 · COEFICIENTES OMS (COINCIDIR/INDICE)
A21: Variable | B21: Valor | C21: Unidad | D21: Fórmula / cómo se obtiene
A22: IMC/E · L | B22: =IF(AND(c_Gate="SÍ",c_mes>=C_IMC),IF(COUNTIF(T_KEY,("IMC-"&c_sexoCod&"-"&c_mes))>0,INDEX(T_V1,MATCH(("IMC-"&c_sexoCod&"-"&c_mes),T_KEY,0)),"ND"),"ND") -> ND | C22: —
A23: IMC/E · M | B23: =IF(AND(c_Gate="SÍ",c_mes>=C_IMC),IF(COUNTIF(T_KEY,("IMC-"&c_sexoCod&"-"&c_mes))>0,INDEX(T_V2,MATCH(("IMC-"&c_sexoCod&"-"&c_mes),T_KEY,0)),"ND"),"ND") -> ND | C23: kg/m²
A24: IMC/E · S | B24: =IF(AND(c_Gate="SÍ",c_mes>=C_IMC),IF(COUNTIF(T_KEY,("IMC-"&c_sexoCod&"-"&c_mes))>0,INDEX(T_V3,MATCH(("IMC-"&c_sexoCod&"-"&c_mes),T_KEY,0)),"ND"),"ND") -> ND | C24: —
A25: P/E · L | B25: =IF(AND(c_Gate="SÍ",c_mes<=12),IF(COUNTIF(T_KEY,("PE-"&c_sexoCod&"-"&c_mes))>0,INDEX(T_V1,MATCH(("PE-"&c_sexoCod&"-"&c_mes),T_KEY,0)),"ND"),"ND") -> ND | C25: —
A26: P/E · M | B26: =IF(AND(c_Gate="SÍ",c_mes<=12),IF(COUNTIF(T_KEY,("PE-"&c_sexoCod&"-"&c_mes))>0,INDEX(T_V2,MATCH(("PE-"&c_sexoCod&"-"&c_mes),T_KEY,0)),"ND"),"ND") -> ND | C26: kg
A27: P/E · S | B27: =IF(AND(c_Gate="SÍ",c_mes<=12),IF(COUNTIF(T_KEY,("PE-"&c_sexoCod&"-"&c_mes))>0,INDEX(T_V3,MATCH(("PE-"&c_sexoCod&"-"&c_mes),T_KEY,0)),"ND"),"ND") -> ND | C27: —
A28: P/T · L | B28: =IF(AND(c_Gate="SÍ",c_tKey>=45,c_tKey<=120),IF(COUNTIF(T_KEY,("PT-"&c_sexoCod&"-"&c_tKey))>0,INDEX(T_V1,MATCH(("PT-"&c_sexoCod&"-"&c_tKey),T_KEY,0)),"ND"),"ND") -> -0.3521 | C28: —
A29: P/T · M | B29: =IF(AND(c_Gate="SÍ",c_tKey>=45,c_tKey<=120),IF(COUNTIF(T_KEY,("PT-"&c_sexoCod&"-"&c_tKey))>0,INDEX(T_V2,MATCH(("PT-"&c_sexoCod&"-"&c_tKey),T_KEY,0)),"ND"),"ND") -> 16.2298 | C29: kg
A30: P/T · S | B30: =IF(AND(c_Gate="SÍ",c_tKey>=45,c_tKey<=120),IF(COUNTIF(T_KEY,("PT-"&c_sexoCod&"-"&c_tKey))>0,INDEX(T_V3,MATCH(("PT-"&c_sexoCod&"-"&c_tKey),T_KEY,0)),"ND"),"ND") -> 0.08381 | C30: —
A31: BLOQUE 3 · PUNTAJES Z
A32: Variable | B32: Valor | C32: Unidad | D32: Fórmula / cómo se obtiene
A33: z · IMC/edad | B33: =IF(c_Gate<>"SÍ","ND: no aplica",IF(NOT(ISNUMBER(c_imcVal)),"ND: no aplica",IF(NOT(ISNUMBER(c_iL)),"ND: no aplica",IF(NOT(ISNUMBER(c_iM)),"ND: no aplica",IF(c_iM<=0,"ND: no aplica",IF(NOT(ISNUMBER(c_iS)),"ND: no aplica",IF(c_iS<=0,"ND: no aplica",IF(c_iL=0,LN(c_imcVal/c_iM)/c_iS,((c_imcVal/c_iM)^c_iL-1)/(c_iS*c_iL))))))))) -> ND: no aplica | C33: z | D33: LMS · ≥61 meses
A34: z · peso/edad | B34: =IF(c_Gate<>"SÍ","ND: no aplica",IF(NOT(ISNUMBER(in_Peso)),"ND: no aplica",IF(OR(in_Peso<PESO_MIN,in_Peso>PESO_MAX),"ND: no aplica",IF(NOT(ISNUMBER(c_peL)),"ND: no aplica",IF(NOT(ISNUMBER(c_peM)),"ND: no aplica",IF(c_peM<=0,"ND: no aplica",IF(NOT(ISNUMBER(c_peS)),"ND: no aplica",IF(c_peS<=0,"ND: no aplica",IF(c_peL=0,LN(in_Peso/c_peM)/c_peS,((in_Peso/c_peM)^c_peL-1)/(c_peS*c_peL)))))))))) -> ND: no aplica | C34: z | D34: LMS · 0–12 meses
A35: z · peso/talla | B35: =IF(c_Gate<>"SÍ","ND: no aplica",IF(NOT(ISNUMBER(in_Peso)),"ND: no aplica",IF(OR(in_Peso<PESO_MIN,in_Peso>PESO_MAX),"ND: no aplica",IF(NOT(ISNUMBER(c_ptL)),"ND: no aplica",IF(NOT(ISNUMBER(c_ptM)),"ND: no aplica",IF(c_ptM<=0,"ND: no aplica",IF(NOT(ISNUMBER(c_ptS)),"ND: no aplica",IF(c_ptS<=0,"ND: no aplica",IF(c_ptL=0,LN(in_Peso/c_ptM)/c_ptS,((in_Peso/c_ptM)^c_ptL-1)/(c_ptS*c_ptL)))))))))) -> 0.19643742 | C35: z | D35: LMS · talla 45–120 cm
A36: T/E · −1 DE | B36: =IF(c_Gate="SÍ",IF(COUNTIF(T_KEY,("TE-"&c_sexoCod&"-"&c_mes))>0,INDEX(T_V2,MATCH(("TE-"&c_sexoCod&"-"&c_mes),T_KEY,0)),"ND"),"ND") -> 99.1 | C36: cm
A37: T/E · mediana | B37: =IF(c_Gate="SÍ",IF(COUNTIF(T_KEY,("TE-"&c_sexoCod&"-"&c_mes))>0,INDEX(T_V3,MATCH(("TE-"&c_sexoCod&"-"&c_mes),T_KEY,0)),"ND"),"ND") -> 103.3 | C37: cm
A38: T/E · +1 DE | B38: =IF(c_Gate="SÍ",IF(COUNTIF(T_KEY,("TE-"&c_sexoCod&"-"&c_mes))>0,INDEX(T_V4,MATCH(("TE-"&c_sexoCod&"-"&c_mes),T_KEY,0)),"ND"),"ND") -> 107.5 | C38: cm
A39: z · talla/edad | B39: =IF(AND(c_Gate="SÍ",ISNUMBER(c_teM1),ISNUMBER(c_teMed),ISNUMBER(c_teP1),ISNUMBER(in_Talla),c_teP1>c_teMed,c_teMed>c_teM1),IF(in_Talla>=c_teMed,(in_Talla-c_teMed)/(c_teP1-c_teMed),(in_Talla-c_teMed)/(c_teMed-c_teM1)),"ND") -> -0.071428571 | C39: z | D39: Interpolación entre líneas DE
A40: PCe · −2 DE | B40: =IF(c_Gate<>"SÍ","ND",IF(c_mes>C_PCE,"ND",IF(NOT(ISNUMBER(in_PCe)),"ND",IF(in_PCe<=0,"ND",IF(COUNTIF(T_KEY,("PC-"&c_sexoCod&"-"&c_mes))>0,INDEX(T_V1,MATCH(("PC-"&c_sexoCod&"-"&c_mes),T_KEY,0)),"ND"))))) -> ND | C40: cm
A41: PCe · +2 DE | B41: =IF(c_Gate<>"SÍ","ND",IF(c_mes>C_PCE,"ND",IF(NOT(ISNUMBER(in_PCe)),"ND",IF(in_PCe<=0,"ND",IF(COUNTIF(T_KEY,("PC-"&c_sexoCod&"-"&c_mes))>0,INDEX(T_V5,MATCH(("PC-"&c_sexoCod&"-"&c_mes),T_KEY,0)),"ND"))))) -> ND | C41: cm
...

Sheet RESULTADOS
A1: NUTRIMETRÍA · NMX-14
A2: Informe de evaluación nutricional pediátrica
A3: =HYPERLINK("#INICIO!A1","▶ INICIO") -> ▶ INICIO | B3: =HYPERLINK("#DATOS!A1","▶ DATOS") -> ▶ DATOS | C3: =HYPERLINK("#SEGUIMIENTO!A1","▶ SEGUIMIENTO") -> ▶ SEGUIMIENTO | D3: =HYPERLINK("#CALCULOS!A1","▶ CALCULOS") -> ▶ CALCULOS | E3: =HYPERLINK("#RESULTADOS!A1","● RESULTADOS") -> ● RESULTADOS | F3: =HYPERLINK("#CURVAS!A1","▶ CURVAS") -> ▶ CURVAS | G3: =HYPERLINK("#FUENTES!A1","▶ FUENTES") -> ▶ FUENTES | H3: =HYPERLINK("#PRUEBAS!A1","▶ PRUEBAS") -> ▶ PRUEBAS | I3: =HYPERLINK("#CONFIG!A1","▶ CONFIG") -> ▶ CONFIG | J3: =HYPERLINK("#TABLAS!A1","▶ TABLAS") -> ▶ TABLAS | K3: =HYPERLINK("#CHANGELOG!A1","▶ CHANGELOG") -> ▶ CHANGELOG
A5: IDENTIFICACIÓN
A6: Identificador | B6: =in_ID -> NMX-2026-0014
A7: Paciente | B7: =in_Pac -> PAC-0102
A8: Evaluador | B8: =in_Eval -> EVAL-01
A9: Sexo · edad | B9: =in_Sexo&IF(ISNUMBER(c_mes)," · "&c_mes&" meses ("&TEXT(c_anios,"0.0")&" a)"," · (edad ND)") -> Niño · 48 meses (04 a)
A10: Peso · talla | B10: =IF(NOT(ISNUMBER(in_Peso)),"(peso inválido)",IF(OR(in_Peso<PESO_MIN,in_Peso>PESO_MAX),"(peso inválido)",ROUND(in_Peso,1)&" kg"))&" · "&IF(NOT(ISNUMBER(in_Talla)),"(talla inválida)",IF(OR(in_Talla<TALLA_MIN,in_Talla>TALLA_MAX),"(talla inválida)",ROUND(in_Talla,1)&" cm")) -> 16,5 kg · 103 cm
A11: IMC | B11: =IF(ISNUMBER(c_imcVal),TEXT(c_imcVal,"0.0")&" kg/m²","ND") -> 16 kg/m²
A12: Edad corregida por prematurez | B12: =IF(OR(in_Prem="No",in_Prem=""),"No aplica",IF(ISNUMBER(c_mesCorr),"Sí · "&TEXT(c_mesCorr,"0.0")&" meses","ND")) -> No aplica
A13: Estado del cálculo | B13: =IF(c_Gate="SÍ","HABILITADO",IF(NOT(ISNUMBER(in_FNac)),"DATO_INVALIDO · fechas",IF(NOT(ISNUMBER(in_Fecha)),"DATO_INVALIDO · fechas",IF(in_Fecha<=in_FNac,"DATO_INVALIDO · fechas",IF(COUNTIF(SEXOS,in_Sexo)=0,"DATO_INVALIDO · sexo",IF(NOT(ISNUMBER(in_Peso)),"DATO_INVALIDO · peso",IF(OR(in_Peso<PESO_MIN,in_Peso>PESO_MAX),"DATO_INVALIDO · peso",IF(NOT(ISNUMBER(in_Talla)),"DATO_INVALIDO · talla",IF(OR(in_Talla<TALLA_MIN,in_Talla>TALLA_MAX),"DATO_INVALIDO · talla",IF(in_Prem="Sí",IF(NOT(ISNUMBER(in_SemGest)),"DATO_INVALIDO · edad gestacional",IF(OR(in_SemGest<24,in_SemGest>42),"DATO_INVALIDO · edad gestacional",IF(AND(ISNUMBER(c_mes),c_mes>MES_MAX),"FUERA_DE_APLICABILIDAD","BLOQUEADO — revise datos"))),IF(AND(ISNUMBER(c_mes),c_mes>MES_MAX),"FUERA_DE_APLICABILIDAD","BLOQUEADO — revise datos"))))))))))) -> HABILITADO
A15: DIAGNÓSTICO POR INDICADOR
A16: Indicador | B16: Puntaje z / valor | C16: Clasificación | D16: Registro DE | E16: Aplica | F16: Norma
A17: Peso / edad (P/E) | B17: =IF(ISNUMBER(c_zPE),TEXT(c_zPE,"0.00"),"—") -> — | C17: =IF(ISNUMBER(c_zPE),IF(c_zPE<=Z_DES,"Desnutrición",IF(c_zPE<=Z_RIE,"Riesgo de desnutrir",IF(c_zPE<Z_SOB,"Normal",IF(c_zPE<Z_OBE,"Sobrepeso",IF(c_zPE<Z_SEV,"Obesidad","Obesidad severa"))))),"No aplica") -> No aplica | D17: =IF(ISNUMBER(c_zPE),IF(c_zPE<=-3,"≤ −3 DE",IF(c_zPE<=-2,"−2 DE",IF(c_zPE<=-1,"−1 DE",IF(c_zPE<1,"Mediana",IF(c_zPE<2,"+1 DE",IF(c_zPE<3,"+2 DE","+3 DE")))))),"—") -> — | E17: =IF(ISNUMBER(c_zPE),"0–12 m","") | F17: OMS/MINSAL
A18: Peso / talla (P/T) | B18: =IF(ISNUMBER(c_zPT),TEXT(c_zPT,"0.00"),"—") -> 000 | C18: =IF(ISNUMBER(c_zPT),IF(c_zPT<=Z_DES,"Desnutrición",IF(c_zPT<=Z_RIE,"Riesgo de desnutrir",IF(c_zPT<Z_SOB,"Normal",IF(c_zPT<Z_OBE,"Sobrepeso",IF(c_zPT<Z_SEV,"Obesidad","Obesidad severa"))))),"No aplica") -> Normal | D18: =IF(ISNUMBER(c_zPT),IF(c_zPT<=-3,"≤ −3 DE",IF(c_zPT<=-2,"−2 DE",IF(c_zPT<=-1,"−1 DE",IF(c_zPT<1,"Mediana",IF(c_zPT<2,"+1 DE",IF(c_zPT<3,"+2 DE","+3 DE")))))),"—") -> Mediana | E18: =IF(ISNUMBER(c_zPT),"45–120 cm","") -> 45–120 cm | F18: OMS/MINSAL
A19: IMC / edad (IMC/E) | B19: =IF(ISNUMBER(c_zIMC),TEXT(c_zIMC,"0.00"),"—") -> — | C19: =IF(ISNUMBER(c_zIMC),IF(c_zIMC<=Z_DES,"Desnutrición",IF(c_zIMC<=Z_RIE,"Riesgo de desnutrir",IF(c_zIMC<Z_SOB,"Normal",IF(c_zIMC<Z_OBE,"Sobrepeso",IF(c_zIMC<Z_SEV,"Obesidad","Obesidad severa"))))),"No aplica") -> No aplica | D19: =IF(ISNUMBER(c_zIMC),IF(c_zIMC<=-3,"≤ −3 DE",IF(c_zIMC<=-2,"−2 DE",IF(c_zIMC<=-1,"−1 DE",IF(c_zIMC<1,"Mediana",IF(c_zIMC<2,"+1 DE",IF(c_zIMC<3,"+2 DE","+3 DE")))))),"—") -> — | E19: =IF(ISNUMBER(c_zIMC),"≥61 m","") | F19: OMS 2007
A20: Talla / edad (T/E) | B20: =IF(ISNUMBER(c_zTE),TEXT(c_zTE,"0.00"),"—") -> 000 | C20: =IF(ISNUMBER(c_zTE),IF(c_zTE<=-2,"Talla baja",IF(c_zTE<=-1,"Talla normal-baja",IF(c_zTE<2,"Talla normal","Talla alta"))),"No aplica") -> Talla normal | D20: =IF(ISNUMBER(c_zTE),IF(c_zTE<=-3,"≤ −3 DE",IF(c_zTE<=-2,"−2 DE",IF(c_zTE<=-1,"−1 DE",IF(c_zTE<1,"Mediana",IF(c_zTE<2,"+1 DE",IF(c_zTE<3,"+2 DE","+3 DE")))))),"—") -> Mediana | E20: =IF(ISNUMBER(c_zTE),"0–228 m","") -> 0–228 m | F20: OMS/MINSAL
A21: Perímetro cefálico (PCe) | B21: =IF(NOT(ISNUMBER(in_PCe)),"—",IF(in_PCe>0,TEXT(in_PCe,"0.0")&" cm","Dato inválido")) -> — | C21: =IF(AND(ISNUMBER(in_PCe),ISNUMBER(c_pcM2)),IF(in_PCe<=c_pcM2,"Microcefalia",IF(in_PCe>=c_pcP2,"Macrocefalia","Normal")),"No aplica") -> No aplica | D21: =IF(AND(ISNUMBER(in_PCe),ISNUMBER(c_pcM2)),IF(in_PCe<=c_pcM2,"≤ −2 DE",IF(in_PCe>=c_pcP2,"≥ +2 DE","Normal")),"—") -> — | E21: =IF(ISNUMBER(c_pcM2),"0–36 m","") | F21: OMS
A22: Perímetro de cintura | B22: =IF(NOT(ISNUMBER(in_Cintura)),"—",IF(in_Cintura>0,TEXT(in_Cintura,"0.0")&" cm","Dato inválido")) -> — | C22: =IF(AND(ISNUMBER(in_Cintura),ISNUMBER(c_ci75)),IF(in_Cintura<c_ci75,"Normal",IF(in_Cintura<c_ci90,"Riesgo obesidad abdominal","Obesidad abdominal")),"No aplica") -> No aplica | D22: =IF(AND(ISNUMBER(in_Cintura),ISNUMBER(c_ci75)),IF(in_Cintura<c_ci75,"< p75",IF(in_Cintura<c_ci90,"p75–p90","≥ p90")),"—") -> — | E22: =IF(ISNUMBER(c_ci75),"≥5 años","") | F22: MINSAL
A24: DIAGNÓSTICO NUTRICIONAL INTEGRADO
A25: Indicador primario | B25: =IF(c_Gate<>"SÍ","ND",IF(c_mes<C_LACT,"P/E o P/T",IF(c_mes<C_IMC,"P/T","IMC/E"))) -> P/T | D25: =IF(ISNUMBER(c_zPrim),"z = "&TEXT(c_zPrim,"0.00"),"ND") -> z = 000
A26: Estado nutricional | B26: =IF(ISNUMBER(c_zPrim),IF(c_zPrim<=Z_DES,"Desnutrición",IF(c_zPrim<=Z_RIE,"Riesgo de desnutrir",IF(c_zPrim<Z_SOB,"Normal",IF(c_zPrim<Z_OBE,"Sobrepeso",IF(c_zPrim<Z_SEV,"Obesidad","Obesidad severa"))))),"ND") -> Normal
A27: Talla para la edad | B27: =IF(ISNUMBER(c_zTE),IF(c_zTE<=-2,"Talla baja",IF(c_zTE<=-1,"Talla normal-baja",IF(c_zTE<2,"Talla normal","Talla alta"))),"ND") -> Talla normal
A28: Síntesis | B28: =IF(c_Gate<>"SÍ","No fue posible calcular los indicadores: "&LOWER(B13)&". Revise los datos y sus unidades.",IF(c_mes<C_LACT,"Lactante menor",IF(c_mes<24,"Lactante mayor",IF(c_mes<72,"Preescolar",IF(c_mes<144,"Escolar","Adolescente"))))&" de sexo "&LOWER(in_Sexo)&", con estado nutricional de "&LOWER(IF(c_zPrim<=Z_DES,"Desnutrición",IF(c_zPrim<=Z_RIE,"Riesgo de desnutrir",IF(c_zPrim<Z_SOB,"Normal",IF(c_zPrim<Z_OBE,"Sobrepeso",IF(c_zPrim<Z_SEV,"Obesidad","Obesidad severa"))))))&" y "&LOWER(IF(c_zTE<=-2,"talla baja",IF(c_zTE<=-1,"talla normal-baja",IF(c_zTE<2,"talla normal","talla alta"))))&", según patrones OMS/MINSAL. Interpretar junto al canal de crecimiento y la evaluación clínica.") -> Preescolar de sexo niño, con estado nutricional de normal y talla normal, según patrones OMS/MINSAL. Interpretar junto al canal de crecimiento y la evaluación clínica.
A29: Señal de alerta | B29: =IF(c_Gate<>"SÍ","No se emitió una alerta clínica porque el cálculo está bloqueado.",IF(OR(c_zPrim<=Z_DES,c_zPrim>=Z_SEV),"⚠ ALERTA: evaluar derivación a médico o equipo según flujograma MINSAL.",IF(c_zPrim<=Z_RIE,"Atención: riesgo. Reforzar control nutricional.","Sin riesgo inminente en esta evaluación."))) -> Sin riesgo inminente en esta evaluación.
A31: REQUERIMIENTOS ESTIMADOS
A32: Tasa metabólica basal (TMB) | B32: =c_TMB -> 878.949 | C32: kcal/día | D32: Schofield · FAO/OMS/UNU 1985
A33: Gasto energético total (GET) | B33: =c_GET -> 1230.5286 | C33: kcal/día | D33: TMB × factor de actividad
A34: Proteínas | B34: =c_proReq -> 15.18 | C34: g/día | D34: WHO/FAO/UNU 2007
A35: Lípidos | B35: =c_lipReq -> 41.01762 | C35: g/día | D35: FAO 2010 (punto medio %VCT)
A36: Carbohidratos | B36: =c_choReq -> 200.16251 | C36: g/día | D36: Por diferencia
A38: ADECUACIÓN (opcional)
A39: Nutriente | B39: Requerido | C39: Ingerido | D39: % Adecuación | E39: Diagnóstico
A40: Energía | B40: =IF(ISNUMBER(c_GET),c_GET,"ND") -> 1230.5286 | C40: =IF(ISNUMBER(in_kcalIng),in_kcalIng,"—") -> 1250 | D40: =IF(AND(ISNUMBER(B40),ISNUMBER(C40),B40>0),C40/B40,"—") -> 1.0158236 | E40: =IF(NOT(ISNUMBER(D40)),"—",IF(D40<0.9,"Déficit",IF(D40<=1.1,"Adecuado","Exceso"))) -> Adecuado
A41: Proteínas | B41: =IF(ISNUMBER(c_proReq),c_proReq,"ND") -> 15.18 | C41: =IF(ISNUMBER(in_proIng),in_proIng,"—") -> 30 | D41: =IF(AND(ISNUMBER(B41),ISNUMBER(C41),B41>0),C41/B41,"—") -> 1.9762846 | E41: =IF(NOT(ISNUMBER(D41)),"—",IF(D41<0.9,"Déficit",IF(D41<=1.1,"Adecuado","Exceso"))) -> Exceso
A43: PERFIL DE PUNTAJES Z (banda normal −2 a +2)
A44: Indicador | B44: z
A45: P/E | B45: =IF(ISNUMBER(c_zPE),c_zPE,"")
A46: P/T | B46: =IF(ISNUMBER(c_zPT),c_zPT,"") -> 0.19643742
...

Sheet CURVAS
A1: NUTRIMETRÍA · NMX-14
A2: Curvas de evolución · se actualizan al agregar filas en SEGUIMIENTO
A3: =HYPERLINK("#INICIO!A1","▶ INICIO") -> ▶ INICIO | B3: =HYPERLINK("#DATOS!A1","▶ DATOS") -> ▶ DATOS | C3: =HYPERLINK("#SEGUIMIENTO!A1","▶ SEGUIMIENTO") -> ▶ SEGUIMIENTO | D3: =HYPERLINK("#CALCULOS!A1","▶ CALCULOS") -> ▶ CALCULOS | E3: =HYPERLINK("#RESULTADOS!A1","▶ RESULTADOS") -> ▶ RESULTADOS | F3: =HYPERLINK("#CURVAS!A1","● CURVAS") -> ● CURVAS | G3: =HYPERLINK("#FUENTES!A1","▶ FUENTES") -> ▶ FUENTES | H3: =HYPERLINK("#PRUEBAS!A1","▶ PRUEBAS") -> ▶ PRUEBAS | I3: =HYPERLINK("#CONFIG!A1","▶ CONFIG") -> ▶ CONFIG | J3: =HYPERLINK("#TABLAS!A1","▶ TABLAS") -> ▶ TABLAS | K3: =HYPERLINK("#CHANGELOG!A1","▶ CHANGELOG") -> ▶ CHANGELOG
A4: Los gráficos toman datos de T_SEGUIMIENTO. El canal de crecimiento y las alertas requieren los patrones OMS por sexo/edad, DESACTIVADOS hasta ingerir las tablas LMS oficiales (ver FUENTES). Por ahora se muestran tendencias crudas.

Sheet FUENTES
A1: NUTRIMETRÍA · NMX-14
A2: Trazabilidad de patrones OMS/MINSAL y ecuaciones · versión 2.0.1
A3: =HYPERLINK("#INICIO!A1","▶ INICIO") -> ▶ INICIO | B3: =HYPERLINK("#DATOS!A1","▶ DATOS") -> ▶ DATOS | C3: =HYPERLINK("#SEGUIMIENTO!A1","▶ SEGUIMIENTO") -> ▶ SEGUIMIENTO | D3: =HYPERLINK("#CALCULOS!A1","▶ CALCULOS") -> ▶ CALCULOS | E3: =HYPERLINK("#RESULTADOS!A1","▶ RESULTADOS") -> ▶ RESULTADOS | F3: =HYPERLINK("#CURVAS!A1","▶ CURVAS") -> ▶ CURVAS | G3: =HYPERLINK("#FUENTES!A1","● FUENTES") -> ● FUENTES | H3: =HYPERLINK("#PRUEBAS!A1","▶ PRUEBAS") -> ▶ PRUEBAS | I3: =HYPERLINK("#CONFIG!A1","▶ CONFIG") -> ▶ CONFIG | J3: =HYPERLINK("#TABLAS!A1","▶ TABLAS") -> ▶ TABLAS | K3: =HYPERLINK("#CHANGELOG!A1","▶ CHANGELOG") -> ▶ CHANGELOG
A5: Ecuación o dato | B5: Autor u organización | C5: Año | D5: Población | E5: Fórmula / valor | F5: Unidades | G5: Limitaciones | H5: DOI o fuente | I5: Fecha cotejo | J5: Licencia | K5: Nivel
A6: Estándares de crecimiento 0–5 a | B6: OMS — WHO Child Growth Standards | C6: 2006 | D6: MGRS, 8440 niños de 6 países | E6: LMS: L, M, S por sexo y mes/talla (P/E, P/T, longitud, PCe) | F6: kg; cm; adim. | G6: Estándar 0–60 m; requiere técnica correcta. | H6: who.int/childgrowth | I6: 2026-07-16 | J6: Tablas oficiales OMS de acceso público | K6: A
A7: Referencia 5–19 a | B7: OMS — Growth reference 2007 | C7: 2007 | D7: Reconstrucción NCHS/OMS | E7: LMS de IMC/edad y talla/edad 61–228 m | F7: adim. | G7: Para 5–19 años. | H7: who.int/growthref | I7: 2026-07-16 | J7: Tablas oficiales OMS de acceso público | K7: A
A8: Método LMS | B8: Cole TJ, Green PJ — Stat Med 11:1305-1319 | C8: 1992 | D8: Suavizado de centiles | E8: z = ((X/M)^L − 1)/(L·S) | F8: adim. | G8: Distribución Box-Cox normal. | H8: 10.1002/sim.4780111005 | I8: 2026-07-16 | J8: Artículo con derechos; solo la ecuación | K8: B
A9: Clasificación y flujograma | B9: MINSAL (Chile) — Norma de evaluación nutricional | C9: 2018 | D9: Población infantil chilena | E9: Cortes DE por indicador; indicador primario por edad | F9: z | G9: Cortes de tamizaje, no diagnósticos por sí solos. | H9: minsal.cl | I9: 2026-07-16 | J9: Documento oficial de acceso público | K9: A
A10: Perímetro de cintura | B10: MINSAL / referencia pediátrica | C10: 2018 | D10: Niñas y niños ≥5 años | E10: Cortes p75 / p90 por edad y sexo | F10: cm | G10: Complementa el diagnóstico; verificar tabla local. | H10: MINSAL · fuente exacta pendiente de cotejo | I10: 2026-07-16 | J10: Documento oficial de acceso público | K10: A
A11: TMB | B11: Schofield · FAO/OMS/UNU | C11: 1985 | D11: Metaanálisis por edad y sexo | E11: TMB = a·peso + b por banda | F11: kcal/día | G11: Estimación poblacional; ±SEE. | H11: FAO/WHO/UNU 1985 | I11: 2026-07-16 | J11: Documento oficial de acceso público | K11: A
A12: Proteína | B12: WHO/FAO/UNU 935 | C12: 2007 | D12: Ingesta segura por edad | E12: g/kg/día por banda etaria | F12: g/kg | G12: Valores de referencia poblacional. | H12: WHO TRS 935 | I12: 2026-07-16 | J12: Documento oficial de acceso público | K12: A
A13: Grasas | B13: FAO — Fats and fatty acids | C13: 2010 | D13: Recomendaciones por edad | E13: % del VCT por banda | F13: % | G13: Rangos; se usa el punto medio para CHO. | H13: FAO 2010 | I13: 2026-07-16 | J13: Documento oficial de acceso público | K13: A
A15: PENDIENTE DE VERIFICACIÓN: confirmar la edición vigente de la norma MINSAL y la fuente exacta de los cortes de cintura antes de un uso formal. Los datos OMS provienen de tablas oficiales; el método LMS es de nivel B.

Sheet PRUEBAS
A1: NUTRIMETRÍA · NMX-14
A2: Banco de verificación · versión 2.0.1 · recuento original + robustez
A3: =HYPERLINK("#INICIO!A1","▶ INICIO") -> ▶ INICIO | B3: =HYPERLINK("#DATOS!A1","▶ DATOS") -> ▶ DATOS | C3: =HYPERLINK("#SEGUIMIENTO!A1","▶ SEGUIMIENTO") -> ▶ SEGUIMIENTO | D3: =HYPERLINK("#CALCULOS!A1","▶ CALCULOS") -> ▶ CALCULOS | E3: =HYPERLINK("#RESULTADOS!A1","▶ RESULTADOS") -> ▶ RESULTADOS | F3: =HYPERLINK("#CURVAS!A1","▶ CURVAS") -> ▶ CURVAS | G3: =HYPERLINK("#FUENTES!A1","▶ FUENTES") -> ▶ FUENTES | H3: =HYPERLINK("#PRUEBAS!A1","● PRUEBAS") -> ● PRUEBAS | I3: =HYPERLINK("#CONFIG!A1","▶ CONFIG") -> ▶ CONFIG | J3: =HYPERLINK("#TABLAS!A1","▶ TABLAS") -> ▶ TABLAS | K3: =HYPERLINK("#CHANGELOG!A1","▶ CHANGELOG") -> ▶ CHANGELOG
A4: ◀ INICIO
A6: BLOQUE A · z PESO/TALLA (LMS con L,M,S oficiales OMS) · ±0,001
A7: ID | B7: Descripción | C7: Talla | D7: L | E7: M | F7: S | G7: Peso | H7: z obt | I7: z esp | J7: Est.
A8: A01 | B8: Niño 103 cm 16,5 kg | C8: 103 | D8: -0.3521 | E8: 16.2298 | F8: 0.08381 | G8: 16.5 | H8: =((G8/E8)^D8-1)/(F8*D8) -> 0.19643742 | I8: 0.196437 | J8: =IF(ABS(H8-I8)<=TOL_Z,"APROBADO","FALLIDO") -> APROBADO
A9: A02 | B9: Niño 90 cm 13 kg | C9: 90 | D9: -0.3521 | E9: 12.8864 | F9: 0.08032 | G9: 13 | H9: =((G9/E9)^D9-1)/(F9*D9) -> 0.10910506 | I9: 0.109105 | J9: =IF(ABS(H9-I9)<=TOL_Z,"APROBADO","FALLIDO") -> APROBADO
A10: A03 | B10: Niño 110 cm 20 kg | C10: 110 | D10: -0.3521 | E10: 18.5158 | F10: 0.088 | G10: 20 | H10: =((G10/E10)^D10-1)/(F10*D10) -> 0.86443789 | I10: 0.864438 | J10: =IF(ABS(H10-I10)<=TOL_Z,"APROBADO","FALLIDO") -> APROBADO
A11: A04 | B11: Niño 75 cm 9,5 kg | C11: 75 | D11: -0.3521 | E11: 9.5032 | F11: 0.08295 | G11: 9.5 | H11: =((G11/E11)^D11-1)/(F11*D11) -> -0.0040603418 | I11: -0.00406 | J11: =IF(ABS(H11-I11)<=TOL_Z,"APROBADO","FALLIDO") -> APROBADO
A12: A05 | B12: Niño 120 cm 25 kg | C12: 120 | D12: -0.3521 | E12: 22.353 | F12: 0.09424 | G12: 25 | H12: =((G12/E12)^D12-1)/(F12*D12) -> 1.1644624 | I12: 1.164462 | J12: =IF(ABS(H12-I12)<=TOL_Z,"APROBADO","FALLIDO") -> APROBADO
A14: BLOQUE B · z IMC/EDAD (≥61 m) · ±0,001
A15: ID | B15: Mes | C15: L | D15: M | E15: S | F15: IMC | G15: z obt | H15: z esp | I15: Est.
A16: B01 | B16: 72 | C16: -0.9921 | D16: 15.3062 | E16: 0.08682 | F16: 15 | G16: =((F16/D16)^C16-1)/(E16*C16) -> -0.23510365 | H16: -0.235104 | I16: =IF(ABS(G16-H16)<=TOL_Z,"APROBADO","FALLIDO") -> APROBADO
A17: B02 | B17: 120 | C17: -1.7407 | D17: 16.4433 | E17: 0.10566 | F17: 17 | G17: =((F17/D17)^C17-1)/(E17*C17) -> 0.3061591 | H17: 0.306159 | I17: =IF(ABS(G17-H17)<=TOL_Z,"APROBADO","FALLIDO") -> APROBADO
A18: B03 | B18: 180 | C18: -1.4961 | D18: 19.7744 | E18: 0.12412 | F18: 21 | G18: =((F18/D18)^C18-1)/(E18*C18) -> 0.46333024 | H18: 0.46333 | I18: =IF(ABS(G18-H18)<=TOL_Z,"APROBADO","FALLIDO") -> APROBADO
A19: B04 | B19: 61 | C19: -0.7387 | D19: 15.2641 | E19: 0.0839 | F19: 14 | G19: =((F19/D19)^C19-1)/(E19*C19) -> -1.0639592 | H19: -1.063959 | I19: =IF(ABS(G19-H19)<=TOL_Z,"APROBADO","FALLIDO") -> APROBADO
A20: B05 | B20: 228 | C20: -0.8419 | D20: 22.1883 | E20: 0.12948 | F20: 23 | G20: =((F20/D20)^C20-1)/(E20*C20) -> 0.27333277 | H20: 0.273333 | I20: =IF(ABS(G20-H20)<=TOL_Z,"APROBADO","FALLIDO") -> APROBADO
A22: BLOQUE C · z PESO/EDAD (0–12 m) y TALLA/EDAD (interpolación) · ±0,001
A23: ID | B23: Descripción | C23: p1 | D23: p2 | E23: p3 | F23: Medida | G23: Obtenido | H23: Esperado | I23: Est.
A24: C01 | B24: P/E niño 6m 8 kg | C24: 0.1257 | D24: 7.934 | E24: 0.10958 | F24: 8 | G24: =((F24/D24)^C24-1)/(E24*C24) -> 0.075639116 | H24: 0.075639 | I24: =IF(ABS(G24-H24)<=TOL_Z,"APROBADO","FALLIDO") -> APROBADO
A25: C02 | B25: P/E niño 6m 7 kg | C25: 0.1257 | D25: 7.934 | E25: 0.10958 | F25: 7 | G25: =((F25/D25)^C25-1)/(E25*C25) -> -1.1340245 | H25: -1.134025 | I25: =IF(ABS(G25-H25)<=TOL_Z,"APROBADO","FALLIDO") -> APROBADO
A26: C03 | B26: T/E niño 48m 103 cm | C26: 99.1 | D26: 103.3 | E26: 107.5 | F26: 103 | G26: =IF(F26>=D26,(F26-D26)/(E26-D26),(F26-D26)/(D26-C26)) -> -0.071428571 | H26: -0.071429 | I26: =IF(ABS(G26-H26)<=TOL_Z,"APROBADO","FALLIDO") -> APROBADO
A27: C04 | B27: T/E niño 48m 96 cm | C27: 99.1 | D27: 103.3 | E27: 107.5 | F27: 96 | G27: =IF(F27>=D27,(F27-D27)/(E27-D27),(F27-D27)/(D27-C27)) -> -1.7380952 | H27: -1.738095 | I27: =IF(ABS(G27-H27)<=TOL_Z,"APROBADO","FALLIDO") -> APROBADO
A29: BLOQUE D · TMB (Schofield) Y GET · ±0,5 kcal
A30: ID | B30: Sexo | C30: Años | D30: Peso | E30: a | F30: b | G30: TMB obt | H30: TMB esp | I30: Est. | J30: GET obt | K30: GET esp | L30: Est.
A31: D01 | B31: M | C31: 4 | D31: 16.5 | E31: 22.706 | F31: 504.3 | G31: =E31*D31+F31 -> 878.949 | H31: 878.949 | I31: =IF(ABS(G31-H31)<=TOL_K,"APROBADO","FALLIDO") -> APROBADO | J31: =G31*FA -> 1230.5286 | K31: 1230.5286 | L31: =IF(ABS(J31-K31)<=TOL_K,"APROBADO","FALLIDO") -> APROBADO
A32: D02 | B32: F | C32: 8 | D32: 25 | E32: 20.315 | F32: 485.9 | G32: =E32*D32+F32 -> 993.775 | H32: 993.775 | I32: =IF(ABS(G32-H32)<=TOL_K,"APROBADO","FALLIDO") -> APROBADO | J32: =G32*FA -> 1391.285 | K32: 1391.285 | L32: =IF(ABS(J32-K32)<=TOL_K,"APROBADO","FALLIDO") -> APROBADO
A33: D03 | B33: M | C33: 15 | D33: 55 | E33: 17.686 | F33: 658.2 | G33: =E33*D33+F33 -> 1630.93 | H33: 1630.93 | I33: =IF(ABS(G33-H33)<=TOL_K,"APROBADO","FALLIDO") -> APROBADO | J33: =G33*FA -> 2283.302 | K33: 2283.302 | L33: =IF(ABS(J33-K33)<=TOL_K,"APROBADO","FALLIDO") -> APROBADO
A34: D04 | B34: F | C34: 2 | D34: 12 | E34: 58.317 | F34: -31.1 | G34: =E34*D34+F34 -> 668.704 | H34: 668.704 | I34: =IF(ABS(G34-H34)<=TOL_K,"APROBADO","FALLIDO") -> APROBADO | J34: =G34*FA -> 936.1856 | K34: 936.1856 | L34: =IF(ABS(J34-K34)<=TOL_K,"APROBADO","FALLIDO") -> APROBADO
A35: D05 | B35: M | C35: 1 | D35: 10 | E35: 59.512 | F35: -30.4 | G35: =E35*D35+F35 -> 564.72 | H35: 564.72 | I35: =IF(ABS(G35-H35)<=TOL_K,"APROBADO","FALLIDO") -> APROBADO | J35: =G35*FA -> 790.608 | K35: 790.608 | L35: =IF(ABS(J35-K35)<=TOL_K,"APROBADO","FALLIDO") -> APROBADO
A37: BLOQUE E · VALIDACIONES
A38: ID | B38: Escenario | C38: Entrada | D38: Esperado | E38: Obtenido | F38: Est.
A39: E01 | B39: Peso negativo | C39: -5 | D39: ERROR: peso fuera de rango | E39: =IF(NOT(ISNUMBER(-5)),"ERROR: peso no numérico",IF(AND(-5>=1,-5<=150),"OK","ERROR: peso fuera de rango")) -> ERROR: peso fuera de rango | F39: =IF(E39=D39,"APROBADO","FALLIDO") -> APROBADO
A40: E02 | B40: Peso textual | C40: diez | D40: ERROR: peso no numérico | E40: =IF(NOT(ISNUMBER("diez")),"ERROR: peso no numérico",IF(AND("diez">=1,"diez"<=150),"OK","ERROR: peso fuera de rango")) -> ERROR: peso no numérico | F40: =IF(E40=D40,"APROBADO","FALLIDO") -> APROBADO
A41: E03 | B41: Talla imposible (300) | C41: 300 | D41: ERROR: talla fuera de rango | E41: =IF(NOT(ISNUMBER(300)),"ERROR: talla no numérica",IF(AND(300>=40,300<=210),"OK","ERROR: talla fuera de rango")) -> ERROR: talla fuera de rango | F41: =IF(E41=D41,"APROBADO","FALLIDO") -> APROBADO
A42: E04 | B42: Talla 103 válida | C42: 103 | D42: OK | E42: =IF(NOT(ISNUMBER(103)),"ERROR: talla no numérica",IF(AND(103>=40,103<=210),"OK","ERROR: talla fuera de rango")) -> OK | F42: =IF(E42=D42,"APROBADO","FALLIDO") -> APROBADO
A43: E05 | B43: Diag z=−2,3 → Desnutrición | C43: -2.3 | D43: Desnutrición | E43: =IF(-2.3<=-2,"Desnutrición",IF(-2.3<=-1,"Riesgo de desnutrir",IF(-2.3<1,"Normal",IF(-2.3<2,"Sobrepeso",IF(-2.3<3,"Obesidad","Obesidad severa"))))) -> Desnutrición | F43: =IF(E43=D43,"APROBADO","FALLIDO") -> APROBADO
A44: E06 | B44: Diag z=0,2 → Normal | C44: 0.2 | D44: Normal | E44: =IF(0.2<=-2,"Desnutrición",IF(0.2<=-1,"Riesgo de desnutrir",IF(0.2<1,"Normal",IF(0.2<2,"Sobrepeso",IF(0.2<3,"Obesidad","Obesidad severa"))))) -> Normal | F44: =IF(E44=D44,"APROBADO","FALLIDO") -> APROBADO
A45: E07 | B45: Diag z=2,5 → Obesidad | C45: 2.5 | D45: Obesidad | E45: =IF(2.5<=-2,"Desnutrición",IF(2.5<=-1,"Riesgo de desnutrir",IF(2.5<1,"Normal",IF(2.5<2,"Sobrepeso",IF(2.5<3,"Obesidad","Obesidad severa"))))) -> Obesidad | F45: =IF(E45=D45,"APROBADO","FALLIDO") -> APROBADO
...

Sheet CONFIG
A1: NUTRIMETRÍA · NMX-14
A2: Parámetros, cortes y coeficientes · versión 2.0.1
A3: =HYPERLINK("#INICIO!A1","▶ INICIO") -> ▶ INICIO | B3: =HYPERLINK("#DATOS!A1","▶ DATOS") -> ▶ DATOS | C3: =HYPERLINK("#SEGUIMIENTO!A1","▶ SEGUIMIENTO") -> ▶ SEGUIMIENTO | D3: =HYPERLINK("#CALCULOS!A1","▶ CALCULOS") -> ▶ CALCULOS | E3: =HYPERLINK("#RESULTADOS!A1","▶ RESULTADOS") -> ▶ RESULTADOS | F3: =HYPERLINK("#CURVAS!A1","▶ CURVAS") -> ▶ CURVAS | G3: =HYPERLINK("#FUENTES!A1","▶ FUENTES") -> ▶ FUENTES | H3: =HYPERLINK("#PRUEBAS!A1","▶ PRUEBAS") -> ▶ PRUEBAS | I3: =HYPERLINK("#CONFIG!A1","● CONFIG") -> ● CONFIG | J3: =HYPERLINK("#TABLAS!A1","▶ TABLAS") -> ▶ TABLAS | K3: =HYPERLINK("#CHANGELOG!A1","▶ CHANGELOG") -> ▶ CHANGELOG
A4: Todo umbral y coeficiente vive aquí; ninguna fórmula del libro trae una constante escrita a mano. Las celdas arena son editables. Los datos de referencia OMS están en la hoja TABLAS (no editar).
A6: C1 · PARÁMETROS, LÍMITES Y COEFICIENTES
A7: Parámetro | B7: Valor | C7: Unidad | D7: Tipo | E7: Nota / fuente
A8: Idioma | B8: Español (es-CL) | C8: — | D8: — | E8: Interfaz
A9: Versión de las fuentes | B9: 2026-07 · v1.0 | C9: — | D9: — | E9: OMS 2006/2007 · MINSAL 2018
A10: Peso mínimo plausible | B10: 1 | C10: kg | D10: IMPOSIBLE | E10: Guarda
A11: Peso máximo plausible | B11: 150 | C11: kg | D11: IMPOSIBLE | E11: Guarda
A12: Talla mínima plausible | B12: 40 | C12: cm | D12: IMPOSIBLE | E12: Guarda
A13: Talla máxima plausible | B13: 210 | C13: cm | D13: IMPOSIBLE | E13: Guarda
A14: Edad máxima (meses) | B14: 228 | C14: meses | D14: IMPOSIBLE | E14: 19 años (límite OMS)
A15: Semanas de gestación (a término) | B15: 40 | C15: sem | D15: Constante | E15: Para corregir edad en prematuros
A16: Corte edad · lactante menor | B16: 12 | C16: meses | D16: Corte | E16: <12 m: indicador P/E o P/T
A17: Corte edad · uso de IMC/edad | B17: 61 | C17: meses | D17: Corte | E17: ≥61 m: indicador IMC/edad
A18: Corte edad · perímetro cefálico | B18: 36 | C18: meses | D18: Corte | E18: PCe válido 0–36 m
A19: Corte edad · perímetro de cintura | B19: 5 | C19: años | D19: Corte | E19: Cintura válida ≥5 años
A20: z · desnutrición | B20: -2 | C20: z | D20: Corte | E20: ≤ −2 DE
A21: z · riesgo | B21: -1 | C21: z | D21: Corte | E21: ≤ −1 DE
... A27: Factor de actividad (GET = TMB × FA) | B27: 1.4 | C27: — | D27: Editable | E27: 1,4 leve · 1,6 moderada · 1,8 intensa
A29: C2 · SEXO
A30: Etiqueta | B30: Código interno
A31: Niño | B31: M
A32: Niña | B32: F
A34: C3 · LISTA SÍ / NO
A35: Sí
A36: No
A38: C4 · TMB · ECUACIONES FAO/OMS/UNU 1985 (Schofield) · TMB = a·kg + b
A39: Sexo | B39: Edad desde (años, ≥) | C39: Edad hasta (años, <) | D39: a | E39: b
A40: M | B40: 0 | C40: 3 | D40: 59.512 | E40: -30.4
A41: M | B41: 3 | C41: 10 | D41: 22.706 | E41: 504.3
A42: M | B42: 10 | C42: 18 | D42: 17.686 | E42: 658.2
A43: M | B43: 18 | C43: 99 | D43: 15.057 | E43: 692.2
A44: F | B44: 0 | C44: 3 | D44: 58.317 | E44: -31.1
A45: F | B45: 3 | C45: 10 | D45: 20.315 | E45: 485.9
A46: F | B46: 10 | C46: 18 | D46: 13.384 | E46: 692.6
A47: F | B47: 18 | C47: 99 | D47: 14.818 | E47: 486.6
A49: C5 · PROTEÍNA · INGESTA SEGURA WHO/FAO/UNU 2007 (g/kg/día)
A50: Edad desde (años, ≥) | B50: Edad hasta (años, <) | C50: g/kg/día | D50: Nota
...

Sheet TABLAS
A1: NUTRIMETRÍA · NMX-14
A2: Tablas de referencia OMS/MINSAL · NO EDITAR
A3: =HYPERLINK("#INICIO!A1","▶ INICIO") -> ▶ INICIO | B3: =HYPERLINK("#DATOS!A1","▶ DATOS") -> ▶ DATOS | C3: =HYPERLINK("#SEGUIMIENTO!A1","▶ SEGUIMIENTO") -> ▶ SEGUIMIENTO | D3: =HYPERLINK("#CALCULOS!A1","▶ CALCULOS") -> ▶ CALCULOS | E3: =HYPERLINK("#RESULTADOS!A1","▶ RESULTADOS") -> ▶ RESULTADOS | F3: =HYPERLINK("#CURVAS!A1","▶ CURVAS") -> ▶ CURVAS | G3: =HYPERLINK("#FUENTES!A1","▶ FUENTES") -> ▶ FUENTES | H3: =HYPERLINK("#PRUEBAS!A1","▶ PRUEBAS") -> ▶ PRUEBAS | I3: =HYPERLINK("#CONFIG!A1","▶ CONFIG") -> ▶ CONFIG | J3: =HYPERLINK("#TABLAS!A1","● TABLAS") -> ● TABLAS | K3: =HYPERLINK("#CHANGELOG!A1","▶ CHANGELOG") -> ▶ CHANGELOG
A4: Datos oficiales de la OMS (estándares 2006 / referencia 2007) y cortes MINSAL. LMS: v1=L, v2=M, v3=S. Líneas DE (T/E, PCe): v1=−2, v2=−1, v3=mediana, v4=+1, v5=+2. Cintura: v1=p75, v2=p90. La clave compuesta permite la búsqueda con COINCIDIR/INDICE.
A6: Tabla | B6: Sexo | C6: Clave | D6: v1 | E6: v2 | F6: v3 | G6: v4 | H6: v5 | I6: Clave compuesta
A7: IMC | B7: F | C7: 61 | D7: -0.8886 | E7: 15.2441 | F7: 0.09692 | I7: IMC-F-61
A8: IMC | B8: F | C8: 62 | D8: -0.9068 | E8: 15.2434 | F8: 0.09738 | I8: IMC-F-62
A9: IMC | B9: F | C9: 63 | D9: -0.9248 | E9: 15.2433 | F9: 0.09783 | I9: IMC-F-63
A10: IMC | B10: F | C10: 64 | D10: -0.9427 | E10: 15.2438 | F10: 0.09829 | I10: IMC-F-64
A11: IMC | B11: F | C11: 65 | D11: -0.9605 | E11: 15.2448 | F11: 0.09875 | I11: IMC-F-65
A12: IMC | B12: F | C12: 66 | D12: -0.978 | E12: 15.2464 | F12: 0.0992 | I12: IMC-F-66
A13: IMC | B13: F | C13: 67 | D13: -0.9954 | E13: 15.2487 | F13: 0.09966 | I13: IMC-F-67
A14: IMC | B14: F | C14: 68 | D14: -1.0126 | E14: 15.2516 | F14: 0.10012 | I14: IMC-F-68
A15: IMC | B15: F | C15: 69 | D15: -1.0296 | E15: 15.2551 | F15: 0.10058 | I15: IMC-F-69
A16: IMC | B16: F | C16: 70 | D16: -1.0464 | E16: 15.2592 | F16: 0.10104 | I16: IMC-F-70
A17: IMC | B17: F | C17: 71 | D17: -1.063 | E17: 15.2641 | F17: 0.10149 | I17: IMC-F-71
A18: IMC | B18: F | C18: 72 | D18: -1.0794 | E18: 15.2697 | F18: 0.10195 | I18: IMC-F-72
... A670: PT | B670: M | C670: 120 | D670: -0.3521 | E670: 22.353 | F670: 0.09424 | I670: PT-M-120
A671: TE | B671: F | C671: 0 | D671: 45.4 | E671: 47.3 | F671: 49.1 | G671: 51 | H671: 52.9 | I671: TE-F-0
A672: TE | B672: F | C672: 1 | D672: 49.8 | E672: 51.7 | F672: 53.7 | G672: 55.6 | H672: 57.6 | I672: TE-F-1
A673: TE | B673: F | C673: 2 | D673: 53 | E673: 55 | F673: 57.1 | G673: 59.1 | H673: 61.1 | I673: TE-F-2
A674: TE | B674: F | C674: 3 | D674: 55.6 | E674: 57.7 | F674: 59.8 | G674: 61.9 | H674: 64 | I674: TE-F-3
A675: TE | B675: F | C675: 4 | D675: 57.8 | E675: 59.9 | F675: 62.1 | G675: 64.3 | H675: 66.4 | I675: TE-F-4
A676: TE | B676: F | C676: 5 | D676: 59.6 | E676: 61.8 | F676: 64 | G676: 66.2 | H676: 68.5 | I676: TE-F-5
A677: TE | B677: F | C677: 6 | D677: 61.2 | E677: 63.5 | F677: 65.7 | G677: 68 | H677: 70.3 | I677: TE-F-6
A678: TE | B678: F | C678: 7 | D678: 62.7 | E678: 65 | F678: 67.3 | G678: 69.6 | H678: 71.9 | I678: TE-F-7
A679: TE | B679: F | C679: 8 | D679: 64 | E679: 66.4 | F679: 68.7 | G679: 71.1 | H679: 73.5 | I679: TE-F-8
A680: TE | B680: F | C680: 9 | D680: 65.3 | E680: 67.7 | F680: 70.1 | G680: 72.6 | H680: 75 | I680: TE-F-9
A681: TE | B681: F | C681: 10 | D681: 66.5 | E681: 69 | F681: 71.5 | G681: 73.9 | H681: 76.4 | I681: TE-F-10
A682: TE | B682: F | C682: 11 | D682: 67.7 | E682: 70.3 | F682: 72.8 | G682: 75.3 | H682: 77.8 | I682: TE-F-11
... A1202: PC | B1202: M | C1202: 36 | D1202: 46.6 | E1202: 48 | F1202: 49.5 | G1202: 50.9 | H1202: 52.3 | I1202: PC-M-36
A1203: CIN | B1203: F | C1203: 5 | D1203: 56.7 | E1203: 61.4 | I1203: CIN-F-5
A1204: CIN | B1204: F | C1204: 6 | D1204: 59.1 | E1204: 64.1 | I1204: CIN-F-6
A1205: CIN | B1205: F | C1205: 7 | D1205: 61.5 | E1205: 67.5 | I1205: CIN-F-7
A1206: CIN | B1206: F | C1206: 8 | D1206: 63.9 | E1206: 70.5 | I1206: CIN-F-8
A1207: CIN | B1207: F | C1207: 9 | D1207: 66.3 | E1207: 73.6 | I1207: CIN-F-9
A1208: CIN | B1208: F | C1208: 10 | D1208: 68.7 | E1208: 76.6 | I1208: CIN-F-10
A1209: CIN | B1209: F | C1209: 11 | D1209: 71.1 | E1209: 79.7 | I1209: CIN-F-11
A1210: CIN | B1210: F | C1210: 12 | D1210: 73.5 | E1210: 82.7 | I1210: CIN-F-12
A1211: CIN | B1211: F | C1211: 13 | D1211: 75.9 | E1211: 85.9 | I1211: CIN-F-13
...

Sheet CHANGELOG
A1: NUTRIMETRÍA · NMX-14
A2: Historial de versiones
A3: =HYPERLINK("#INICIO!A1","▶ INICIO") -> ▶ INICIO | B3: =HYPERLINK("#DATOS!A1","▶ DATOS") -> ▶ DATOS | C3: =HYPERLINK("#SEGUIMIENTO!A1","▶ SEGUIMIENTO") -> ▶ SEGUIMIENTO | D3: =HYPERLINK("#CALCULOS!A1","▶ CALCULOS") -> ▶ CALCULOS | E3: =HYPERLINK("#RESULTADOS!A1","▶ RESULTADOS") -> ▶ RESULTADOS | F3: =HYPERLINK("#CURVAS!A1","▶ CURVAS") -> ▶ CURVAS | G3: =HYPERLINK("#FUENTES!A1","▶ FUENTES") -> ▶ FUENTES | H3: =HYPERLINK("#PRUEBAS!A1","▶ PRUEBAS") -> ▶ PRUEBAS | I3: =HYPERLINK("#CONFIG!A1","▶ CONFIG") -> ▶ CONFIG | J3: =HYPERLINK("#TABLAS!A1","▶ TABLAS") -> ▶ TABLAS | K3: =HYPERLINK("#CHANGELOG!A1","● CHANGELOG") -> ● CHANGELOG
A5: Versión | B5: Fecha | C5: Cambio | F5: Motivo | H5: Responsable
A6: 1.0 | B6: 2026-07-14 | C6: Rediseño original a partir de una evaluación existente. Se reconstruyeron TODAS las fórmulas desde cero (INDICE/COINCIDIR en vez de XLOOKUP; guardas 'ND' en vez de IFERROR). Arquitectura completa con INICIO, FUENTES, PRUEBAS y CHANGELOG. | F6: Herramienta original y compatible con Excel 2021. | H6: Equipo Nutrimetría
A7: 1.0 | B7: 2026-07-14 | C7: Se completó el módulo de requerimientos (TMB Schofield, GET, proteína, lípidos y CHO) que en el archivo de origen estaba con marcadores de posición. | F7: Completar funcionalidad. | H7: Equipo Nutrimetría
A8: 1.0 | B8: 2026-07-14 | C8: Banco de pruebas con cotejo de z-scores, requerimientos, validaciones e integridad. | F8: Control de calidad. | H8: Equipo Nutrimetría
A9: 2.0 | B9: 2026-08-02 | C9: v2.0: navegacion HYPERLINK real en todas las hojas; nueva hoja SEGUIMIENTO (tabla expandible T_SEGUIMIENTO) y hoja CURVAS ligada a ella; percentiles desde z (NORMSDIST); identidad visual Nutrimetria, cuadricula oculta, paneles congelados y areas de impresion. Extensiones del motor (T/E por LMS, PCe z, P/E 0-60, IMC/E<61, P/L vs P/T por tecnica, clasificacion de cintura) DESACTIVADAS con 'ND: fuente pendiente de verificacion'. Sin inventar valores. Motor y datos v1.0 intactos. | F9: Auditor independiente (entorno sin Excel de escritorio) | H9: Equipo Nutrimetría
A10: 2.0.1 | B10: 2026-08-06 | C10: Robustez: guardas directas para peso, talla, fechas, sexo, edad gestacional, PCe y cintura; LMS con rama L=0; DATEDIF sustituido por cálculo equivalente de meses completos; 15 casos H-1:H-15 y regresión 39/39. | F10: Evitar errores o clasificaciones con entradas imposibles sin modificar tablas OMS ni parámetros L, M y S. | H10: Auditoría Nutrimetría

Sheet QA_REAL
A1: NUTRIMETRÍA · NMX-14 · QA MATEMÁTICO, FUNCIONAL Y DE ROBUSTEZ
A2: Versión 2.0.1 · base funcional v2.0 · evidencia QA independiente · recálculo real en Excel pendiente
A3: =HYPERLINK("#INICIO!A1","◀ INICIO") -> ◀ INICIO | B3: =HYPERLINK("#PRUEBAS!A1","▶ PRUEBAS") -> ▶ PRUEBAS
A5: Control | C5: Resultado
A6: Archivo funcional seleccionado | C6: NMX-14_Evaluacion_Nutricional_Pediatrica_v2_0(2).xlsx
A7: Archivo usado como evidencia | C7: NMX-14_QA_REAL(2).xlsx
A8: Versión de salida | C8: 2.0.1
A9: SHA-256 funcional | C9: cfed135fe4533e16eee18e1ddb8e8c0a0004050343027bd6be1b6a35929dfb55
A10: SHA-256 evidencia | C10: cb3a16c630232149c3e721d4478e1dd28a7fdd74c7367157d7faf1f0c8fda7e4
A11: Pruebas originales | C11: 39/39 APROBADAS
A12: Pruebas de robustez | C12: 15/15 APROBADAS ESTRUCTURALMENTE
A13: Microsoft Excel COM | C13: RECALCULO_REAL_NO_EJECUTADO
A15: Test_ID | B15: Escenario | C15: Entrada modificada | D15: Esperado independiente | E15: Gate | F15: IMC | G15: z integrado | H15: Percentil | I15: Estado cálculo | J15: Clasificación / PCe | K15: Estado estructural | L15: Estado Excel COM | M15: Fuente / evidencia | N15: Revisor
A16: H-1 | B16: Peso negativo | C16: B14=-5 | D16: Peso negativo → sin IMC, z, percentil ni clasificación | E16: NO | F16: ND | G16: ND | H16: ND | I16: DATO_INVALIDO · peso | J16: ND | K16: APROBADO_ESTRUCTURAL | L16: NO_EJECUTADO | M16: H-1: NMX-14_QA_REAL(2).xlsx; H-2:H-15: extensión de robustez documentada | N16: Nutrimetria · Labs
A17: H-2 | B17: Peso igual a cero | C17: B14=0 | D17: Peso 0 → sin IMC, z, percentil ni clasificación | E17: NO | F17: ND | G17: ND | H17: ND | I17: DATO_INVALIDO · peso | J17: ND | K17: APROBADO_ESTRUCTURAL | L17: NO_EJECUTADO | M17: H-1: NMX-14_QA_REAL(2).xlsx; H-2:H-15: extensión de robustez documentada | N17: Nutrimetria · Labs
A18: H-3 | B18: Peso vacío | C18: B14=None | D18: Peso vacío → sin IMC, z, percentil ni clasificación | E18: NO | F18: ND | G18: ND | H18: ND | I18: DATO_INVALIDO · peso | J18: ND | K18: APROBADO_ESTRUCTURAL | L18: NO_EJECUTADO | M18: H-1: NMX-14_QA_REAL(2).xlsx; H-2:H-15: extensión de robustez documentada | N18: Nutrimetria · Labs
A19: H-4 | B19: Peso como texto | C19: B14='diez' | D19: Peso textual → sin IMC, z, percentil ni clasificación | E19: NO | F19: ND | G19: ND | H19: ND | I19: DATO_INVALIDO · peso | J19: ND | K19: APROBADO_ESTRUCTURAL | L19: NO_EJECUTADO | M19: H-1: NMX-14_QA_REAL(2).xlsx; H-2:H-15: extensión de robustez documentada | N19: Nutrimetria · Labs
A20: H-5 | B20: Talla negativa | C20: B15=-10 | D20: Talla negativa → sin IMC, z, percentil ni clasificación | E20: NO | F20: ND | G20: ND | H20: ND | I20: DATO_INVALIDO · talla | J20: ND | K20: APROBADO_ESTRUCTURAL | L20: NO_EJECUTADO | M20: H-1: NMX-14_QA_REAL(2).xlsx; H-2:H-15: extensión de robustez documentada | N20: Nutrimetria · Labs
A21: H-6 | B21: Talla igual a cero | C21: B15=0 | D21: Talla 0 → sin IMC, z, percentil ni clasificación | E21: NO | F21: ND | G21: ND | H21: ND | I21: DATO_INVALIDO · talla | J21: ND | K21: APROBADO_ESTRUCTURAL | L21: NO_EJECUTADO | M21: H-1: NMX-14_QA_REAL(2).xlsx; H-2:H-15: extensión de robustez documentada | N21: Nutrimetria · Labs
A22: H-7 | B22: Talla vacía | C22: B15=None | D22: Talla vacía → sin IMC, z, percentil ni clasificación | E22: NO | F22: ND | G22: ND | H22: ND | I22: DATO_INVALIDO · talla | J22: ND | K22: APROBADO_ESTRUCTURAL | L22: NO_EJECUTADO | M22: H-1: NMX-14_QA_REAL(2).xlsx; H-2:H-15: extensión de robustez documentada | N22: Nutrimetria · Labs
A23: H-8 | B23: Sexo inválido | C23: B9='Otro' | D23: Sexo inválido → cálculo bloqueado | E23: NO | F23: ND | G23: ND | H23: ND | I23: DATO_INVALIDO · sexo | J23: ND | K23: APROBADO_ESTRUCTURAL | L23: NO_EJECUTADO | M23: H-1: NMX-14_QA_REAL(2).xlsx; H-2:H-15: extensión de robustez documentada | N23: Nutrimetria · Labs
A24: H-9 | B24: Fecha de nacimiento futura | C24: B10=47000; B11=46000 | D24: Nacimiento futuro → fechas inválidas | E24: NO | F24: ND | G24: ND | H24: ND | I24: DATO_INVALIDO · fechas | J24: ND | K24: APROBADO_ESTRUCTURAL | L24: NO_EJECUTADO | M24: H-1: NMX-14_QA_REAL(2).xlsx; H-2:H-15: extensión de robustez documentada | N24: Nutrimetria · Labs
A25: H-10 | B25: Edad fuera del rango | C25: B10=40000; B11=50000 | D25: Edad >228 meses → fuera de aplicabilidad | E25: NO | F25: ND | G25: ND | H25: ND | I25: FUERA_DE_APLICABILIDAD | J25: ND | K25: APROBADO_ESTRUCTURAL | L25: NO_EJECUTADO | M25: H-1: NMX-14_QA_REAL(2).xlsx; H-2:H-15: extensión de robustez documentada | N25: Nutrimetria · Labs
A26: H-11 | B26: Evaluación anterior al nacimiento | C26: B10=46204; B11=44743 | D26: Evaluación previa al nacimiento → fechas inválidas | E26: NO | F26: ND | G26: ND | H26: ND | I26: DATO_INVALIDO · fechas | J26: ND | K26: APROBADO_ESTRUCTURAL | L26: NO_EJECUTADO | M26: H-1: NMX-14_QA_REAL(2).xlsx; H-2:H-15: extensión de robustez documentada | N26: Nutrimetria · Labs
... A30: H-15 | B30: Caso válido después de uno inválido | C30: Restauración del caso válido | D30: Caso válido restaurado → cálculo habilitado y z numérico | E30: SÍ | F30: 15.552832500706948 | G30: 0.19643741528915706 | H30: 57.8 | I30: HABILITADO | J30: Normal | K30: APROBADO_ESTRUCTURAL | L30: NO_EJECUTADO | M30: H-1: NMX-14_QA_REAL(2).xlsx; H-2:H-15: extensión de robustez documentada | N30: Nutrimetria · Labs
A33: Resumen | B33: Resultado | C33: Criterio | D33: Estado
A34: Motor funcional seleccionado | B34: v2.0 de 11 hojas | C34: Producto operativo solicitado | D34: CONFIRMADO
A35: Regresión del banco original | B35: 39/39 | C35: Sin cambios en L, M, S ni TABLAS | D35: APROBADO_ESTRUCTURAL
A36: Robustez H-1 a H-15 | B36: 15/15 | C36: Sin z, percentil ni clasificación ante entradas imposibles | D36: APROBADO_ESTRUCTURAL
A37: Errores estructurales tras parche | B37: 0 | C37: Escaneo de fórmulas y resultados clave | D37: APROBADO_ESTRUCTURAL
A38: Cierre QA | B38: No | C38: Requiere Microsoft Excel COM y reapertura data_only=True | D38: QA_NO_CERRADO
