Workbook
Name a_Horas: ACTIVIDADES!$B$20
Name a_IndiceMET: ACTIVIDADES!$B$22
Name a_PAL: ACTIVIDADES!$B$27
Name a_SumaMETh: ACTIVIDADES!$B$21
Name a_TEE: ACTIVIDADES!$B$25
Name AJUSTE_MAX: CONFIG!$B$22
Name AMPL_MAX: CONFIG!$B$34
Name c_Energia: CALCULOS!$B$48
Name c_ETA: CALCULOS!$B$40
Name c_FA: CALCULOS!$B$13
Name c_GAF: CALCULOS!$B$38
Name c_Gate: CALCULOS!$B$33
Name c_GEB: CALCULOS!$B$37
Name c_GET: CALCULOS!$B$41
Name c_IMC: CALCULOS!$B$8
Name c_MLG: CALCULOS!$B$10
Name c_TallaM: CALCULOS!$B$7
Name COD_ACT: CONFIG!$A$131:$A$144
Name e_Ampl: ECUACIONES!$B$23
Name e_GEBsel: ECUACIONES!$B$28
Name EDAD_MAX: CONFIG!$B$12
Name EDAD_MIN: CONFIG!$B$11
Name EST_MAX: CONFIG!$B$16
Name EST_MIN: CONFIG!$B$15
Name EST_RA: CONFIG!$B$29
Name EST_RB: CONFIG!$B$28
Name ETA_DEF: CONFIG!$B$25
Name ETA_MAX: CONFIG!$B$21
Name FA_MAX: CONFIG!$B$20
Name FA_MIN: CONFIG!$B$19
Name FA_VAL: CONFIG!$B$51:$B$57
Name GRA_MIN: CONFIG!$B$33
Name GRASA_MAX: CONFIG!$B$18
Name GRASA_MIN: CONFIG!$B$17
Name HORAS_DIA: CONFIG!$B$23
Name IMC_RA: CONFIG!$B$31
Name IMC_RB: CONFIG!$B$30
Name in_Ajuste: DATOS!$B$16
Name in_Ecu: DATOS!$B$22
Name in_Edad: DATOS!$B$10
Name in_Est: DATOS!$B$12
Name in_FAcat: DATOS!$B$18
Name in_FAman: DATOS!$B$19
Name in_Fecha: DATOS!$B$7
Name in_Grasa: DATOS!$B$13
Name in_ID: DATOS!$B$6
Name in_Metodo: DATOS!$B$17
Name in_MLG: DATOS!$B$14
Name in_ModoETA: DATOS!$B$20
Name in_ModoGra: DATOS!$B$26
Name in_ModoPro: DATOS!$B$24
Name in_Motivo: DATOS!$B$23
Name in_Obj: DATOS!$B$15
Name in_Obs: DATOS!$B$28
Name in_Pac: DATOS!$B$8
Name in_Peso: DATOS!$B$11
Name in_pETA: DATOS!$B$21
Name in_Sexo: DATOS!$B$9
Name in_ValGra: DATOS!$B$27
Name in_ValPro: DATOS!$B$25

Sheet INICIO
A1: NUTRIMETRÍA · NMX-01
A2: Calculadora Energética · DEFINITIVO 2026 · NMX-PAL-2026-08-v1 · NMX-ACT-2024-v1
A4: Navegación — use las pestañas inferiores del libro
A5: =HYPERLINK("#DATOS!A1","▶ DATOS") -> ▶ DATOS | B5: =HYPERLINK("#ECUACIONES!A1","▶ ECUACIONES") -> ▶ ECUACIONES | D5: =HYPERLINK("#CALCULOS!A1","▶ CALCULOS") -> ▶ CALCULOS | F5: =HYPERLINK("#RESULTADOS!A1","▶ RESULTADOS") -> ▶ RESULTADOS | H5: =HYPERLINK("#ACTIVIDADES!A1","▶ ACTIVIDADES") -> ▶ ACTIVIDADES | J5: =HYPERLINK("#FUENTES!A1","▶ FUENTES") -> ▶ FUENTES | L5: =HYPERLINK("#PRUEBAS!A1","▶ PRUEBAS") -> ▶ PRUEBAS | N5: =HYPERLINK("#CONFIG!A1","▶ CONFIG") -> ▶ CONFIG | P5: =HYPERLINK("#CHANGELOG!A1","▶ CHANGELOG") -> ▶ CHANGELOG
A6: Ingresar datos | B6: Revisar motores | D6: Auditar operaciones | F6: Ver resumen | H6: Revisar PAL | J6: Consultar evidencia | L6: Ver QA | N6: Ajustes y límites | P6: Registro de versiones y cambios
A7: Código del producto | B7: NMX-01
A8: Versión | B8: DEFINITIVO 2026 · NMX-PAL-2026-08-v1 · NMX-ACT-2024-v1
A9: Fecha | B9: 46242
A10: Base | B10: v1.0 (2026-07-12), auditada contra el 'Dossier de verificación bibliográfica y metodológica'
A11: Formato | B11: .xlsx sin macros · Microsoft 365 (Windows) y Excel 2021
A12: Responsable | B12: Equipo Nutrimetría (completar por el titular)
A13: AVISO DE ALCANCE — LÉALO ANTES DE USAR EL LIBRO
A14: EXACTITUD MATEMÁTICA ≠ VALIDACIÓN CLÍNICA. Este libro cotejó sus coeficientes contra las fuentes documentadas en
A15: la hoja FUENTES. Eso NO significa que las ecuaciones estén validadas para su paciente concreto ni para población chilena.
A16: ESTE ARCHIVO NO ESTÁ VALIDADO CLÍNICAMENTE. La calorimetría indirecta sigue siendo la referencia de medición.
A17: APLICA A: personas ADULTAS (≥18 años) en condición estable. Módulo Compendium de actividad: desde 19 años.
A18: NO APLICA A: embarazo · lactancia · menores de edad · pacientes críticos o clínicamente inestables.
A19: PROPÓSITO Y ALCANCE
A20: Propósito | B20: Estimar gasto energético basal/de reposo y requerimiento energético diario mediante siete ecuaciones predictivas y un nivel de actividad física (PAL).
A21: Población | B21: Adultos ≥18 años en condición estable. Actividad física: 18 años = sin módulo Compendium; 19–59 = Adult Compendium 2024 (MET); ≥60 ambulante = Older Adult Compendium 2024 (MET60+); adultos usuarios de silla de ruedas = Wheelchair Compendium 2024 (METWC), con precaución etaria en ≥60.
A22: Uso | B22: Apoyo educativo y profesional. No sustituye calorimetría indirecta, evaluación clínica ni juicio del nutricionista.
A23: Compatibilidad | B23: Microsoft 365 y Excel 2021 para Windows. No utiliza VBA, complementos ni conexiones permanentes.
A24: Privacidad | B24: Los datos permanecen en el archivo local. El libro no transmite información.
A25: CÓMO SE MODELA EL GASTO (sin doble conteo) — confirmado por el dossier
A26: GEB = gasto energético basal, según la ecuación seleccionada.
A27: GAF = GEB × (Factor de actividad − 1). Se resta 1 para NO volver a contar el basal ya incluido en el PAL.
A28: ETA = 0 por defecto. FAO define PAL = gasto total 24 h / metabolismo basal 24 h: el efecto térmico YA está dentro.
A29: Si usted activa un ETA explícito sobre un PAL, el libro se lo permite pero ADVIERTE del doble conteo.
A30: GET = GEB + GAF + ETA ( = GEB × PAL cuando ETA = 0 ).
A31: Energía objetivo = GET × (1 + % de ajuste). Carbohidratos = por diferencia.
A32: Flujo de uso
A33: 1 | B33: Abra DATOS e ingrese sexo, edad, peso, estatura, porcentaje de grasa opcional, PAL y ecuación principal.
A34: 2 | B34: Revise RESULTADOS para la estimación principal y la comparación entre ecuaciones.
A35: 3 | B35: Use ECUACIONES y FUENTES para auditar fórmulas, poblaciones y limitaciones.
A36: 4 | B36: Consulte PRUEBAS para verificar casos sintéticos y controles manuales.
A37: 5 | B37: Interprete diferencias como incertidumbre predictiva; no como diagnóstico.
A38: MET → PAL: la conversión que la v1.1 hace explícita
A39: Un MET es un múltiplo del metabolismo en reposo ESTÁNDAR (≈1 kcal/kg/h), no del GEB de esta persona.
A40: Por eso Σ(MET×h)/24 es un ÍNDICE MET-h/día, y NO el PAL. La v1.0 los confundía. La v1.1 hace:
A41: 1) Σ(MET × horas) → índice MET-h/día (se muestra, pero no se usa como PAL)
...

Sheet DATOS
A1: DATOS · Variables ingresadas por el usuario
A2: =HYPERLINK("#INICIO!A1","◀ INICIO") -> ◀ INICIO | C2: =HYPERLINK("#RESULTADOS!A1","▶ RESULTADOS") -> ▶ RESULTADOS | E2: =HYPERLINK("#ACTIVIDADES!A1","▶ ACTIVIDADES") -> ▶ ACTIVIDADES
A3: LEYENDA · Celdas ARENA con texto AZUL = editables. Celdas grises = calculadas y protegidas. (opcional) = puede quedar vacía.
A4: ► Viene cargado un CASO DE EJEMPLO realista. Reemplace los valores por los de su paciente.
A5: Campo | B5: Valor | C5: Unidad | D5: Validación | E5: Ayuda | G5: MÓDULO ACTIVIDAD FÍSICA · NMX-ACT-2024-v1
A6: Identificador de la evaluación | B6: NMX-2026-0001 | C6: — | D6: Texto libre | E6: Código interno de la evaluación. | G6: Condición clínica | H6: Estable | I6: Debe estar estable; NMX-01 no aplica a pacientes críticos/inestables.
A7: Fecha | B7: 46215 | C7: fecha | D7: Fecha | E7: dd/mm/aaaa. | G7: Movilidad | H7: Usuario de silla de ruedas | I7: Seleccione silla de ruedas solo si corresponde al modo habitual de movilidad.
A8: Nombre o código del paciente | B8: PAC-0042 | C8: — | D8: Texto libre | E8: Prefiera un CÓDIGO si va a compartir el archivo. | G8: Estado del módulo | H8: =IF($H$10="BLOQUEADO_INESTABLE","BLOQUEADO · condición no estable",IF($H$10="FUERA_ALCANCE","FUERA DE ALCANCE",IF($H$10="COMPENDIUM_NO_DISPONIBLE_18","NMX-01 aplica; Compendium no disponible",IF(AND($H$10="WHEELCHAIR2024_METWC",in_Edad>=CONFIG!$B$154),"PRECAUCIÓN · METWC con evidencia etaria limitada","ACTIVO")))) -> ACTIVO | I8: Se determina por edad, condición clínica y movilidad.
A9: Sexo biológico | B9: Hombre | C9: — | D9: Lista: Hombre / Mujer | E9: LIMITACIÓN DEL MODELO: las 7 ecuaciones se derivaron por sexo biológico. Si no aplica, documéntelo en Observaciones. | G9: Fuente activa | H9: =IF($H$10="ADULT2024_MET","2024 Adult Compendium",IF($H$10="OLDER2024_MET60","2024 Older Adult Compendium",IF($H$10="WHEELCHAIR2024_METWC","2024 Wheelchair Compendium",IF($H$10="COMPENDIUM_NO_DISPONIBLE_18","No disponible para edad 18",IF($H$10="BLOQUEADO_INESTABLE","Bloqueado","Fuera de alcance"))))) -> 2024 Wheelchair Compendium | I9: Cambia automáticamente con la edad/movilidad.
A10: Edad | B10: 20 | C10: años | D10: ≥18 y ≤120 (IMPOSIBLE fuera de rango) | E10: Solo adultos. | G10: Motor actividad | H10: =IF($H$6<>"Estable","BLOQUEADO_INESTABLE",IF(NOT(ISNUMBER(in_Edad)),"FUERA_ALCANCE",IF(in_Edad<EDAD_MIN,"FUERA_ALCANCE",IF(in_Edad<CONFIG!$B$152,"COMPENDIUM_NO_DISPONIBLE_18",IF($H$7="Usuario de silla de ruedas","WHEELCHAIR2024_METWC",IF(in_Edad>=CONFIG!$B$154,"OLDER2024_MET60","ADULT2024_MET")))))) -> WHEELCHAIR2024_METWC | I10: Identificador auditable del motor activo.
A11: Peso | B11: 78 | C11: kg | D11: >0, entre PESO_MIN y PESO_MAX | E11: Balanza calibrada, ropa ligera, sin calzado.
A12: Estatura | B12: 180 | C12: cm | D12: >0, entre EST_MIN y EST_MAX | E12: Estadiómetro, plano de Frankfort.
A13: % de grasa corporal (opcional) | B13: 0.05 | C13: % | D13: Entre GRASA_MIN y GRASA_MAX | E13: Deje VACÍA si no la tiene.
A14: MLG medida (opcional) | B14: 62 | C14: kg | D14: Numérica y menor que el peso | E14: Si la ingresa, TIENE PRIORIDAD sobre el % de grasa. Sin % de grasa ni MLG, Cunningham 1980 y 1991 NO se calculan.
A15: Objetivo | B15: Aumento de peso | C15: — | D15: Lista (CONFIG C5) | E15: Descriptivo. El % real lo fija el campo siguiente.
A16: % de ajuste energético | B16: 0.05 | C16: % | D16: |%| ≤ AJUSTE_MAX | E16: NEGATIVO = déficit. POSITIVO = superávit. 0 = mantenimiento. Se aplica sobre el GET.
A17: Método de actividad | B17: Factor de actividad global | C17: — | D17: Lista (CONFIG C3) | E17: NMX-ACT-2024-v1: 'Cálculo por actividades' selecciona MET / MET60+ / METWC según edad y movilidad. El PAL se deriva solo cuando la conversión energética es aplicable.
A18: Factor de actividad global (catálogo) | B18: Moderado · PAL 1,80 | C18: — | D18: Lista (CONFIG C4) | E18: Seleccione según el patrón habitual global (trabajo/estudio, transporte, actividad física y descanso); no por una sola sesión ni solo por pasos.
A19: Factor de actividad manual (opcional) | C19: — | D19: Entre FA_MIN y FA_MAX | E19: Si lo escribe, SOBREESCRIBE al catálogo. Deje VACÍO para usar el catálogo.
A20: Tratamiento del efecto térmico (ETA) | B20: Incluido en el factor de actividad (recomendado) | C20: — | D20: Lista (CONFIG C6) | E20: Por defecto el ETA vale 0 porque el PAL ya lo contiene. Activarlo aparte lo duplicaría.
A21: % de efecto térmico | B21: 0.1 | C21: % | D21: Entre 0 y ETA_MAX | E21: Solo se usa si el modo de ETA es explícito.
A22: Ecuación seleccionada | B22: Cunningham (1991) · alias secundario: Katch–McArdle | C22: — | D22: Lista (CONFIG C11) · 7 opciones | E22: Las 7 ecuaciones se calculan igualmente. Esta define el GEB que alimenta el resto del libro.
A23: Motivo de selección | B23: Adulto sano sin composición corporal medida; Mifflin–St Jeor es la de mejor desempeño documentado en este perfil. | C23: — | D23: Texto OBLIGATORIO | E23: El libro advierte si lo deja vacío: una selección sin justificación no es auditable.
A24: Modo de distribución · PROTEÍNA | B24: g/kg de peso | C24: — | D24: Lista (CONFIG C7) | E24: '% de la energía' o 'g/kg de peso'.
A25: Valor de PROTEÍNA | B25: 1.5 | C25: % o g/kg | D25: ≥0 | E25: Se interpreta según el modo elegido arriba.
A26: Modo de distribución · GRASA | B26: % de la energía | C26: — | D26: Lista (CONFIG C7) | E26: '% de la energía' o 'g/kg de peso'.
A27: Valor de GRASA | B27: 0.2 | C27: % o g/kg | D27: ≥0 | E27: Se interpreta según el modo elegido arriba.
A28: Observaciones | C28: — | D28: Texto libre | E28: Contexto clínico, criterios adoptados, fuente de un MET personalizado, etc.
A30: ► Los CARBOHIDRATOS no se ingresan: se calculan POR DIFERENCIA, una vez fijadas la proteína y la grasa.
A31: ► % de ajuste sugerido para el objetivo elegido: | C31: =IF(COUNTIF(LISTA_OBJ,in_Obj)=1,INDEX(OBJ_PCT,MATCH(in_Obj,LISTA_OBJ,0)),"—") -> 0.1 | D31: (referencial; usted decide el % real en la fila 16)

Sheet ECUACIONES
A1: ECUACIONES · Gasto energético basal (7 ecuaciones)
A2: =HYPERLINK("#INICIO!A1","◀ INICIO") -> ◀ INICIO
A3: Cada ecuación se calcula si y solo si están presentes sus variables indispensables; si falta alguna, devuelve ND y explica por qué. La columna 'Fórmula publicada' es documental: el cálculo usa siempre los coeficientes de CONFIG (C8, C9 y C10), visibles en las columnas L a P. Esta hoja NO depende de la compuerta de CALCULOS: se resuelve antes, porque el PAL estimado de ACTIVIDADES necesita el GEB. GUARDAS ESPECÍFICAS POR ECUACIÓN (v1.1.1): la estatura solo se exige a Mifflin y a Harris–Benedict revisada, las únicas que la usan. La edad se exige a todas porque el alcance del producto es solo adultos. Ver CONFIG C11.
A5: COMPARACIÓN DE LAS 7 ECUACIONES
A6: ID | B6: Ecuación | C6: Fórmula publicada (hombre | mujer) | D6: Variables indispensables | E6: ¿Datos disponibles? | F6: GEB (kcal/día) | G6: Aplicabilidad por edad | H6: Dif. vs promedio (kcal) | I6: Dif. vs promedio (%) | J6: Dif. vs seleccionada (kcal) | K6: Dif. vs seleccionada (%) | L6: a | M6: b_peso | N6: b_estatura | O6: b_edad | P6: b_MLG
A7: =CONFIG!$A$120 -> E1 | B7: =CONFIG!$B$120 -> Mifflin–St Jeor (1990) | C7: 10·P + 6,25·T − 5·E + 5 | 10·P + 6,25·T − 5·E − 161 | D7: =CONFIG!$G$120 -> sexo, peso, estatura, edad | E7: =IF(OR(COUNTIF(SEXOS,in_Sexo)<>1,ISBLANK(in_Edad),NOT(ISNUMBER(in_Edad)),ISBLANK(in_Peso),NOT(ISNUMBER(in_Peso))),"NO: faltan sexo, edad o peso válidos",IF(OR(in_Edad<EDAD_MIN,in_Edad>EDAD_MAX),"NO: edad fuera del alcance adulto",IF(OR(in_Peso<=0,in_Peso<PESO_MIN,in_Peso>PESO_MAX),"NO: peso no válido",IF(AND(CONFIG!$F$120="SÍ",OR(ISBLANK(in_Est),NOT(ISNUMBER(in_Est)),in_Est<=0,in_Est<EST_MIN,in_Est>EST_MAX)),"NO: esta ecuación necesita la estatura",IF(AND(CONFIG!$E$120="SÍ",NOT(ISNUMBER(CALCULOS!$B$10))),"NO: falta la masa libre de grasa","SÍ"))))) -> SÍ | F7: =IF($E7<>"SÍ","ND",$L7+$M7*in_Peso+$N7*IF(CONFIG!$F$120="SÍ",in_Est,0)+$O7*in_Edad+$P7*IF(ISNUMBER(CALCULOS!$B$10),CALCULOS!$B$10,0)) -> 1810 | G7: =IF(OR(ISBLANK(in_Edad),NOT(ISNUMBER(in_Edad))),"",IF(OR(in_Edad<CONFIG!$C$120,in_Edad>CONFIG!$D$120),"⚠ Fuera del rango de derivación","Dentro del rango de derivación")) -> Dentro del rango de derivación | H7: =IF(OR(NOT(ISNUMBER($F7)),NOT(ISNUMBER($B$18))),"ND",$F7-$B$18) -> 9.8494286 | I7: =IF(OR(NOT(ISNUMBER($F7)),NOT(ISNUMBER($B$18)),$B$18=0),"ND",($F7-$B$18)/$B$18) -> 0.0054714471 | J7: =IF(OR(NOT(ISNUMBER($F7)),NOT(ISNUMBER($B$28))),"ND",$F7-$B$28) -> 100.8 | K7: =IF(OR(NOT(ISNUMBER($F7)),NOT(ISNUMBER($B$28)),$B$28=0),"ND",($F7-$B$28)/$B$28) -> 0.058974959 | L7: =IF($E7<>"SÍ",0,SUMIFS(CONFIG!$D$79:$D$88,CONFIG!$A$79:$A$88,$A7,CONFIG!$C$79:$C$88,in_Sexo)) -> 5 | M7: =IF($E7<>"SÍ",0,SUMIFS(CONFIG!$E$79:$E$88,CONFIG!$A$79:$A$88,$A7,CONFIG!$C$79:$C$88,in_Sexo)) -> 10 | N7: =IF($E7<>"SÍ",0,SUMIFS(CONFIG!$F$79:$F$88,CONFIG!$A$79:$A$88,$A7,CONFIG!$C$79:$C$88,in_Sexo)) -> 6.25 | O7: =IF($E7<>"SÍ",0,SUMIFS(CONFIG!$G$79:$G$88,CONFIG!$A$79:$A$88,$A7,CONFIG!$C$79:$C$88,in_Sexo)) -> -5 | P7: =IF($E7<>"SÍ",0,SUMIFS(CONFIG!$H$79:$H$88,CONFIG!$A$79:$A$88,$A7,CONFIG!$C$79:$C$88,in_Sexo)) -> 0
A8: =CONFIG!$A$121 -> E2 | B8: =CONFIG!$B$121 -> Harris–Benedict revisada · Roza & Shizgal (1984) | C8: 88,362 + 13,397·P + 4,799·T − 5,677·E | 447,593 + 9,247·P + 3,098·T − 4,330·E | D8: =CONFIG!$G$121 -> sexo, peso, estatura, edad | E8: =IF(OR(COUNTIF(SEXOS,in_Sexo)<>1,ISBLANK(in_Edad),NOT(ISNUMBER(in_Edad)),ISBLANK(in_Peso),NOT(ISNUMBER(in_Peso))),"NO: faltan sexo, edad o peso válidos",IF(OR(in_Edad<EDAD_MIN,in_Edad>EDAD_MAX),"NO: edad fuera del alcance adulto",IF(OR(in_Peso<=0,in_Peso<PESO_MIN,in_Peso>PESO_MAX),"NO: peso no válido",IF(AND(CONFIG!$F$121="SÍ",OR(ISBLANK(in_Est),NOT(ISNUMBER(in_Est)),in_Est<=0,in_Est<EST_MIN,in_Est>EST_MAX)),"NO: esta ecuación necesita la estatura",IF(AND(CONFIG!$E$121="SÍ",NOT(ISNUMBER(CALCULOS!$B$10))),"NO: falta la masa libre de grasa","SÍ"))))) -> SÍ | F8: =IF($E8<>"SÍ","ND",$L8+$M8*in_Peso+$N8*IF(CONFIG!$F$121="SÍ",in_Est,0)+$O8*in_Edad+$P8*IF(ISNUMBER(CALCULOS!$B$10),CALCULOS!$B$10,0)) -> 1883.608 | G8: =IF(OR(ISBLANK(in_Edad),NOT(ISNUMBER(in_Edad))),"",IF(OR(in_Edad<CONFIG!$C$121,in_Edad>CONFIG!$D$121),"⚠ Fuera del rango de derivación","Dentro del rango de derivación")) -> Dentro del rango de derivación | H8: =IF(OR(NOT(ISNUMBER($F8)),NOT(ISNUMBER($B$18))),"ND",$F8-$B$18) -> 83.457429 | I8: =IF(OR(NOT(ISNUMBER($F8)),NOT(ISNUMBER($B$18)),$B$18=0),"ND",($F8-$B$18)/$B$18) -> 0.04636136 | J8: =IF(OR(NOT(ISNUMBER($F8)),NOT(ISNUMBER($B$28))),"ND",$F8-$B$28) -> 174.408 | K8: =IF(OR(NOT(ISNUMBER($F8)),NOT(ISNUMBER($B$28)),$B$28=0),"ND",($F8-$B$28)/$B$28) -> 0.10204072 | L8: =IF($E8<>"SÍ",0,SUMIFS(CONFIG!$D$79:$D$88,CONFIG!$A$79:$A$88,$A8,CONFIG!$C$79:$C$88,in_Sexo)) -> 88.362 | M8: =IF($E8<>"SÍ",0,SUMIFS(CONFIG!$E$79:$E$88,CONFIG!$A$79:$A$88,$A8,CONFIG!$C$79:$C$88,in_Sexo)) -> 13.397 | N8: =IF($E8<>"SÍ",0,SUMIFS(CONFIG!$F$79:$F$88,CONFIG!$A$79:$A$88,$A8,CONFIG!$C$79:$C$88,in_Sexo)) -> 4.799 | O8: =IF($E8<>"SÍ",0,SUMIFS(CONFIG!$G$79:$G$88,CONFIG!$A$79:$A$88,$A8,CONFIG!$C$79:$C$88,in_Sexo)) -> -5.677 | P8: =IF($E8<>"SÍ",0,SUMIFS(CONFIG!$H$79:$H$88,CONFIG!$A$79:$A$88,$A8,CONFIG!$C$79:$C$88,in_Sexo)) -> 0
A9: =CONFIG!$A$122 -> E3 | B9: =CONFIG!$B$122 -> Owen (1986/1987) | C9: 879 + 10,2·P | 795 + 7,18·P | D9: =CONFIG!$G$122 -> sexo, peso | E9: =IF(OR(COUNTIF(SEXOS,in_Sexo)<>1,ISBLANK(in_Edad),NOT(ISNUMBER(in_Edad)),ISBLANK(in_Peso),NOT(ISNUMBER(in_Peso))),"NO: faltan sexo, edad o peso válidos",IF(OR(in_Edad<EDAD_MIN,in_Edad>EDAD_MAX),"NO: edad fuera del alcance adulto",IF(OR(in_Peso<=0,in_Peso<PESO_MIN,in_Peso>PESO_MAX),"NO: peso no válido",IF(AND(CONFIG!$F$122="SÍ",OR(ISBLANK(in_Est),NOT(ISNUMBER(in_Est)),in_Est<=0,in_Est<EST_MIN,in_Est>EST_MAX)),"NO: esta ecuación necesita la estatura",IF(AND(CONFIG!$E$122="SÍ",NOT(ISNUMBER(CALCULOS!$B$10))),"NO: falta la masa libre de grasa","SÍ"))))) -> SÍ | F9: =IF($E9<>"SÍ","ND",$L9+$M9*in_Peso+$N9*IF(CONFIG!$F$122="SÍ",in_Est,0)+$O9*in_Edad+$P9*IF(ISNUMBER(CALCULOS!$B$10),CALCULOS!$B$10,0)) -> 1674.6 | G9: =IF(OR(ISBLANK(in_Edad),NOT(ISNUMBER(in_Edad))),"",IF(OR(in_Edad<CONFIG!$C$122,in_Edad>CONFIG!$D$122),"⚠ Fuera del rango de derivación","Dentro del rango de derivación")) -> Dentro del rango de derivación | H9: =IF(OR(NOT(ISNUMBER($F9)),NOT(ISNUMBER($B$18))),"ND",$F9-$B$18) -> -125.55057 | I9: =IF(OR(NOT(ISNUMBER($F9)),NOT(ISNUMBER($B$18)),$B$18=0),"ND",($F9-$B$18)/$B$18) -> -0.069744483 | J9: =IF(OR(NOT(ISNUMBER($F9)),NOT(ISNUMBER($B$28))),"ND",$F9-$B$28) -> -34.6 | K9: =IF(OR(NOT(ISNUMBER($F9)),NOT(ISNUMBER($B$28)),$B$28=0),"ND",($F9-$B$28)/$B$28) -> -0.020243389 | L9: =IF($E9<>"SÍ",0,SUMIFS(CONFIG!$D$79:$D$88,CONFIG!$A$79:$A$88,$A9,CONFIG!$C$79:$C$88,in_Sexo)) -> 879 | M9: =IF($E9<>"SÍ",0,SUMIFS(CONFIG!$E$79:$E$88,CONFIG!$A$79:$A$88,$A9,CONFIG!$C$79:$C$88,in_Sexo)) -> 10.2 | N9: =IF($E9<>"SÍ",0,SUMIFS(CONFIG!$F$79:$F$88,CONFIG!$A$79:$A$88,$A9,CONFIG!$C$79:$C$88,in_Sexo)) -> 0 | O9: =IF($E9<>"SÍ",0,SUMIFS(CONFIG!$G$79:$G$88,CONFIG!$A$79:$A$88,$A9,CONFIG!$C$79:$C$88,in_Sexo)) -> 0 | P9: =IF($E9<>"SÍ",0,SUMIFS(CONFIG!$H$79:$H$88,CONFIG!$A$79:$A$88,$A9,CONFIG!$C$79:$C$88,in_Sexo)) -> 0
A10: =CONFIG!$A$123 -> E4 | B10: =CONFIG!$B$123 -> Cunningham (1980) | C10: 500 + 22·MLG (idéntica en ambos sexos) | D10: =CONFIG!$G$123 -> MLG | E10: =IF(OR(COUNTIF(SEXOS,in_Sexo)<>1,ISBLANK(in_Edad),NOT(ISNUMBER(in_Edad)),ISBLANK(in_Peso),NOT(ISNUMBER(in_Peso))),"NO: faltan sexo, edad o peso válidos",IF(OR(in_Edad<EDAD_MIN,in_Edad>EDAD_MAX),"NO: edad fuera del alcance adulto",IF(OR(in_Peso<=0,in_Peso<PESO_MIN,in_Peso>PESO_MAX),"NO: peso no válido",IF(AND(CONFIG!$F$123="SÍ",OR(ISBLANK(in_Est),NOT(ISNUMBER(in_Est)),in_Est<=0,in_Est<EST_MIN,in_Est>EST_MAX)),"NO: esta ecuación necesita la estatura",IF(AND(CONFIG!$E$123="SÍ",NOT(ISNUMBER(CALCULOS!$B$10))),"NO: falta la masa libre de grasa","SÍ"))))) -> SÍ | F10: =IF($E10<>"SÍ","ND",$L10+$M10*in_Peso+$N10*IF(CONFIG!$F$123="SÍ",in_Est,0)+$O10*in_Edad+$P10*IF(ISNUMBER(CALCULOS!$B$10),CALCULOS!$B$10,0)) -> 1864 | G10: =IF(OR(ISBLANK(in_Edad),NOT(ISNUMBER(in_Edad))),"",IF(OR(in_Edad<CONFIG!$C$123,in_Edad>CONFIG!$D$123),"⚠ Fuera del rango de derivación","Dentro del rango de derivación")) -> Dentro del rango de derivación | H10: =IF(OR(NOT(ISNUMBER($F10)),NOT(ISNUMBER($B$18))),"ND",$F10-$B$18) -> 63.849429 | I10: =IF(OR(NOT(ISNUMBER($F10)),NOT(ISNUMBER($B$18)),$B$18=0),"ND",($F10-$B$18)/$B$18) -> 0.035468938 | J10: =IF(OR(NOT(ISNUMBER($F10)),NOT(ISNUMBER($B$28))),"ND",$F10-$B$28) -> 154.8 | K10: =IF(OR(NOT(ISNUMBER($F10)),NOT(ISNUMBER($B$28)),$B$28=0),"ND",($F10-$B$28)/$B$28) -> 0.090568687 | L10: =IF($E10<>"SÍ",0,SUMIFS(CONFIG!$D$79:$D$88,CONFIG!$A$79:$A$88,$A10,CONFIG!$C$79:$C$88,in_Sexo)) -> 500 | M10: =IF($E10<>"SÍ",0,SUMIFS(CONFIG!$E$79:$E$88,CONFIG!$A$79:$A$88,$A10,CONFIG!$C$79:$C$88,in_Sexo)) -> 0 | N10: =IF($E10<>"SÍ",0,SUMIFS(CONFIG!$F$79:$F$88,CONFIG!$A$79:$A$88,$A10,CONFIG!$C$79:$C$88,in_Sexo)) -> 0 | O10: =IF($E10<>"SÍ",0,SUMIFS(CONFIG!$G$79:$G$88,CONFIG!$A$79:$A$88,$A10,CONFIG!$C$79:$C$88,in_Sexo)) -> 0 | P10: =IF($E10<>"SÍ",0,SUMIFS(CONFIG!$H$79:$H$88,CONFIG!$A$79:$A$88,$A10,CONFIG!$C$79:$C$88,in_Sexo)) -> 22
A11: =CONFIG!$A$124 -> E5 | B11: =CONFIG!$B$124 -> Cunningham (1991) · alias secundario: Katch–McArdle | C11: 370 + 21,6·FFM (idéntica en ambos sexos) · fuente primaria: Cunningham 1991 | D11: =CONFIG!$G$124 -> MLG (FFM) | E11: =IF(OR(COUNTIF(SEXOS,in_Sexo)<>1,ISBLANK(in_Edad),NOT(ISNUMBER(in_Edad)),ISBLANK(in_Peso),NOT(ISNUMBER(in_Peso))),"NO: faltan sexo, edad o peso válidos",IF(OR(in_Edad<EDAD_MIN,in_Edad>EDAD_MAX),"NO: edad fuera del alcance adulto",IF(OR(in_Peso<=0,in_Peso<PESO_MIN,in_Peso>PESO_MAX),"NO: peso no válido",IF(AND(CONFIG!$F$124="SÍ",OR(ISBLANK(in_Est),NOT(ISNUMBER(in_Est)),in_Est<=0,in_Est<EST_MIN,in_Est>EST_MAX)),"NO: esta ecuación necesita la estatura",IF(AND(CONFIG!$E$124="SÍ",NOT(ISNUMBER(CALCULOS!$B$10))),"NO: falta la masa libre de grasa","SÍ"))))) -> SÍ | F11: =IF($E11<>"SÍ","ND",$L11+$M11*in_Peso+$N11*IF(CONFIG!$F$124="SÍ",in_Est,0)+$O11*in_Edad+$P11*IF(ISNUMBER(CALCULOS!$B$10),CALCULOS!$B$10,0)) -> 1709.2 | G11: =IF(OR(ISBLANK(in_Edad),NOT(ISNUMBER(in_Edad))),"",IF(OR(in_Edad<CONFIG!$C$124,in_Edad>CONFIG!$D$124),"⚠ Fuera del rango de derivación","Dentro del rango de derivación")) -> Dentro del rango de derivación | H11: =IF(OR(NOT(ISNUMBER($F11)),NOT(ISNUMBER($B$18))),"ND",$F11-$B$18) -> -90.950571 | I11: =IF(OR(NOT(ISNUMBER($F11)),NOT(ISNUMBER($B$18)),$B$18=0),"ND",($F11-$B$18)/$B$18) -> -0.050523869 | J11: =IF(OR(NOT(ISNUMBER($F11)),NOT(ISNUMBER($B$28))),"ND",$F11-$B$28) -> 0 | K11: =IF(OR(NOT(ISNUMBER($F11)),NOT(ISNUMBER($B$28)),$B$28=0),"ND",($F11-$B$28)/$B$28) -> 0 | L11: =IF($E11<>"SÍ",0,SUMIFS(CONFIG!$D$79:$D$88,CONFIG!$A$79:$A$88,$A11,CONFIG!$C$79:$C$88,in_Sexo)) -> 370 | M11: =IF($E11<>"SÍ",0,SUMIFS(CONFIG!$E$79:$E$88,CONFIG!$A$79:$A$88,$A11,CONFIG!$C$79:$C$88,in_Sexo)) -> 0 | N11: =IF($E11<>"SÍ",0,SUMIFS(CONFIG!$F$79:$F$88,CONFIG!$A$79:$A$88,$A11,CONFIG!$C$79:$C$88,in_Sexo)) -> 0 | O11: =IF($E11<>"SÍ",0,SUMIFS(CONFIG!$G$79:$G$88,CONFIG!$A$79:$A$88,$A11,CONFIG!$C$79:$C$88,in_Sexo)) -> 0 | P11: =IF($E11<>"SÍ",0,SUMIFS(CONFIG!$H$79:$H$88,CONFIG!$A$79:$A$88,$A11,CONFIG!$C$79:$C$88,in_Sexo)) -> 21.6
A12: =CONFIG!$A$125 -> E6 | B12: =CONFIG!$B$125 -> Schofield (1985) adultos · tabla canónica | C12: Bandas 18–30 / 30–60 / ≥60 · GEB = a + b·P (tabla canónica, CONFIG C9) | D12: =CONFIG!$G$125 -> sexo, peso, banda etaria | E12: =IF(OR(COUNTIF(SEXOS,in_Sexo)<>1,ISBLANK(in_Edad),NOT(ISNUMBER(in_Edad)),ISBLANK(in_Peso),NOT(ISNUMBER(in_Peso))),"NO: faltan sexo, edad o peso válidos",IF(OR(in_Edad<EDAD_MIN,in_Edad>EDAD_MAX),"NO: edad fuera del alcance adulto",IF(OR(in_Peso<=0,in_Peso<PESO_MIN,in_Peso>PESO_MAX),"NO: peso no válido",IF(AND(CONFIG!$F$125="SÍ",OR(ISBLANK(in_Est),NOT(ISNUMBER(in_Est)),in_Est<=0,in_Est<EST_MIN,in_Est>EST_MAX)),"NO: esta ecuación necesita la estatura",IF(AND(CONFIG!$E$125="SÍ",NOT(ISNUMBER(CALCULOS!$B$10))),"NO: falta la masa libre de grasa","SÍ"))))) -> SÍ | F12: =IF($E12<>"SÍ","ND",$L12+$M12*in_Peso+$N12*IF(CONFIG!$F$125="SÍ",in_Est,0)+$O12*in_Edad+$P12*IF(ISNUMBER(CALCULOS!$B$10),CALCULOS!$B$10,0)) -> 1866.646 | G12: =IF(OR(ISBLANK(in_Edad),NOT(ISNUMBER(in_Edad))),"",IF(OR(in_Edad<CONFIG!$C$125,in_Edad>CONFIG!$D$125),"⚠ Fuera del rango de derivación","Dentro del rango de derivación")) -> Dentro del rango de derivación | H12: =IF(OR(NOT(ISNUMBER($F12)),NOT(ISNUMBER($B$18))),"ND",$F12-$B$18) -> 66.495429 | I12: =IF(OR(NOT(ISNUMBER($F12)),NOT(ISNUMBER($B$18)),$B$18=0),"ND",($F12-$B$18)/$B$18) -> 0.036938815 | J12: =IF(OR(NOT(ISNUMBER($F12)),NOT(ISNUMBER($B$28))),"ND",$F12-$B$28) -> 157.446 | K12: =IF(OR(NOT(ISNUMBER($F12)),NOT(ISNUMBER($B$28)),$B$28=0),"ND",($F12-$B$28)/$B$28) -> 0.09211678 | L12: =IF($E12<>"SÍ",0,SUMPRODUCT((CONFIG!$A$92:$A$97=in_Sexo)*(CONFIG!$B$92:$B$97<=in_Edad)*(CONFIG!$C$92:$C$97>in_Edad)*CONFIG!$E$92:$E$97)) -> 692.2 | M12: =IF($E12<>"SÍ",0,SUMPRODUCT((CONFIG!$A$92:$A$97=in_Sexo)*(CONFIG!$B$92:$B$97<=in_Edad)*(CONFIG!$C$92:$C$97>in_Edad)*CONFIG!$D$92:$D$97)) -> 15.057 | N12: 0 | O12: 0 | P12: 0
A13: =CONFIG!$A$126 -> E7 | B13: =CONFIG!$B$126 -> Henry / Oxford (2005) adultos · solo peso | C13: Bandas 18–30 / 30–60 / ≥60 · GEB = a + b·P (CONFIG C10) · NUEVO en v1.1 | D13: =CONFIG!$G$126 -> sexo, peso, banda etaria | E13: =IF(OR(COUNTIF(SEXOS,in_Sexo)<>1,ISBLANK(in_Edad),NOT(ISNUMBER(in_Edad)),ISBLANK(in_Peso),NOT(ISNUMBER(in_Peso))),"NO: faltan sexo, edad o peso válidos",IF(OR(in_Edad<EDAD_MIN,in_Edad>EDAD_MAX),"NO: edad fuera del alcance adulto",IF(OR(in_Peso<=0,in_Peso<PESO_MIN,in_Peso>PESO_MAX),"NO: peso no válido",IF(AND(CONFIG!$F$126="SÍ",OR(ISBLANK(in_Est),NOT(ISNUMBER(in_Est)),in_Est<=0,in_Est<EST_MIN,in_Est>EST_MAX)),"NO: esta ecuación necesita la estatura",IF(AND(CONFIG!$E$126="SÍ",NOT(ISNUMBER(CALCULOS!$B$10))),"NO: falta la masa libre de grasa","SÍ"))))) -> SÍ | F13: =IF($E13<>"SÍ","ND",$L13+$M13*in_Peso+$N13*IF(CONFIG!$F$126="SÍ",in_Est,0)+$O13*in_Edad+$P13*IF(ISNUMBER(CALCULOS!$B$10),CALCULOS!$B$10,0)) -> 1793 | G13: =IF(OR(ISBLANK(in_Edad),NOT(ISNUMBER(in_Edad))),"",IF(OR(in_Edad<CONFIG!$C$126,in_Edad>CONFIG!$D$126),"⚠ Fuera del rango de derivación","Dentro del rango de derivación")) -> Dentro del rango de derivación | H13: =IF(OR(NOT(ISNUMBER($F13)),NOT(ISNUMBER($B$18))),"ND",$F13-$B$18) -> -7.1505714 | I13: =IF(OR(NOT(ISNUMBER($F13)),NOT(ISNUMBER($B$18)),$B$18=0),"ND",($F13-$B$18)/$B$18) -> -0.0039722074 | J13: =IF(OR(NOT(ISNUMBER($F13)),NOT(ISNUMBER($B$28))),"ND",$F13-$B$28) -> 83.8 | K13: =IF(OR(NOT(ISNUMBER($F13)),NOT(ISNUMBER($B$28)),$B$28=0),"ND",($F13-$B$28)/$B$28) -> 0.049028785 | L13: =IF($E13<>"SÍ",0,SUMPRODUCT((CONFIG!$A$110:$A$115=in_Sexo)*(CONFIG!$B$110:$B$115<=in_Edad)*(CONFIG!$C$110:$C$115>in_Edad)*CONFIG!$E$110:$E$115)) -> 545 | M13: =IF($E13<>"SÍ",0,SUMPRODUCT((CONFIG!$A$110:$A$115=in_Sexo)*(CONFIG!$B$110:$B$115<=in_Edad)*(CONFIG!$C$110:$C$115>in_Edad)*CONFIG!$D$110:$D$115)) -> 16 | N13: 0 | O13: 0 | P13: 0
A15: ESTADÍSTICOS (las ecuaciones que devuelven ND quedan EXCLUIDAS)
A16: Estadístico | B16: Valor | C16: Unidad | D16: Nota
A17: Ecuaciones efectivamente calculadas (n) | B17: =COUNT($F$7:$F$13) -> 7 | C17: — | D17: COUNT ignora los ND: las no calculables quedan fuera de TODOS los estadísticos.
A18: Promedio | B18: =IF($B$17=0,"ND",AVERAGE($F$7:$F$13)) -> 1800.1506 | C18: kcal/día | D18: Media de las calculadas.
A19: Mediana | B19: =IF($B$17=0,"ND",MEDIAN($F$7:$F$13)) -> 1810 | C19: kcal/día | D19: Menos sensible a un valor extremo.
A20: Mínimo | B20: =IF($B$17=0,"ND",MIN($F$7:$F$13)) -> 1674.6 | C20: kcal/día
A21: Máximo | B21: =IF($B$17=0,"ND",MAX($F$7:$F$13)) -> 1883.608 | C21: kcal/día
A22: Rango (máximo − mínimo) | B22: =IF($B$17=0,"ND",$B$21-$B$20) -> 209.008 | C22: kcal/día | D22: Discrepancia entre ecuaciones.
A23: Amplitud relativa (rango / promedio) | B23: =IF(OR($B$17=0,$B$18=0),"ND",$B$22/$B$18) -> 0.11610584 | C23: % | D23: Si supera AMPL_MAX (CONFIG C1), el libro advierte de la dispersión.
A24: Estado de la dispersión | B24: =IF(NOT(ISNUMBER($B$23)),"ND",IF($B$23>AMPL_MAX,"⚠ Dispersión alta: la elección de la ecuación pesa mucho en el resultado.","OK: las ecuaciones concuerdan dentro del umbral configurado.")) -> OK: las ecuaciones concuerdan dentro del umbral configurado. | C24: —
A26: SELECCIÓN DE LA ECUACIÓN
A27: Elemento | B27: Valor | C27: Estado
A28: GEB de la ecuación seleccionada | B28: =IF(COUNTIF(LISTA_ECU,in_Ecu)<>1,"ND",INDEX($F$7:$F$13,MATCH(in_Ecu,$B$7:$B$13,0))) -> 1709.2 | C28: =in_Ecu -> Cunningham (1991) · alias secundario: Katch–McArdle
A29: Motivo de selección registrado | B29: =in_Motivo -> Adulto sano sin composición corporal medida; Mifflin–St Jeor es la de mejor desempeño documentado en este perfil. | C29: =IF(TRIM(in_Motivo)="","⚠ FALTA: registre el motivo en DATOS (fila 23). Una selección sin justificación no es auditable.","OK: motivo registrado") -> OK: motivo registrado
A30: Sugerencia automática del libro | B30: =IF(ISNUMBER(CALCULOS!$B$10),"Hay masa libre de grasa: Cunningham 1980 o Cunningham 1991 (alias Katch–McArdle) son defendibles, sobre todo con masa muscular alta. Mifflin–St Jeor y Henry siguen siendo opciones válidas.","Sin composición corporal: Mifflin–St Jeor (1990) y Henry/Oxford (2005) son las de mejor respaldo en adultos sanos.") -> Hay masa libre de grasa: Cunningham 1980 o Cunningham 1991 (alias Katch–McArdle) son defendibles, sobre todo con masa muscular alta. Mifflin–St Jeor y Henry siguen siendo opciones válidas. | C30: Sugerencia, NO imposición: la decisión y su motivo son suyos.
A31: Nivel de verificación de la ecuación seleccionada | B31: =IF(COUNTIF(LISTA_ECU,in_Ecu)<>1,"ND","Nivel "&INDEX(CONFIG!$H$120:$H$126,MATCH(in_Ecu,LISTA_ECU,0))&" · "&INDEX(CONFIG!$I$120:$I$126,MATCH(in_Ecu,LISTA_ECU,0))) -> Nivel B · Fuente primaria de 370+21,6·FFM: Cunningham 1991, DOI 10.1093/ajcn/54.6.963. El nombre 'Katch–McArdle' es un alias de nivel C | C31: A = fuente primaria cotejada · B = resumen primario o corroboración por pares · C = fuente secundaria

Sheet CALCULOS
A1: CÁLCULOS · Cadena auditable · DEFINITIVO 2026
A2: Sin constantes dentro de las fórmulas: todas provienen de CONFIG. Sin IFERROR: cada guarda es explícita y devuelve la causa. DATO IMPOSIBLE (bloquea) y DATO POCO FRECUENTE (solo advierte) son categorías separadas.
A3: =HYPERLINK("#INICIO!A1","◀ INICIO") -> ◀ INICIO
A5: 0 · CAPA BASE — se resuelve ANTES de la compuerta (el PAL por METs necesita el GEB)
A6: Variable | B6: Valor | C6: Unidad | D6: Fórmula / nota
A7: Estatura | B7: =IF(OR(ISBLANK(in_Est),NOT(ISNUMBER(in_Est)),in_Est<=0),"",in_Est/100) -> 1.8 | C7: m | D7: Estatura (cm) / 100
A8: IMC | B8: =IF(OR(NOT(ISNUMBER($B$7)),$B$7<=0,NOT(ISNUMBER(in_Peso)),in_Peso<=0),"",in_Peso/$B$7^2) -> 24.074074 | C8: kg/m² | D8: Peso / estatura². Guarda explícita contra la división por cero.
A9: % de grasa utilizado | B9: =IF(OR(NOT(ISNUMBER(in_Peso)),in_Peso<=0),"",IF(AND(NOT(ISBLANK(in_Grasa)),ISNUMBER(in_Grasa),in_Grasa>=GRASA_MIN,in_Grasa<=GRASA_MAX),in_Grasa,IF(AND(NOT(ISBLANK(in_MLG)),ISNUMBER(in_MLG),in_MLG>0,in_MLG<in_Peso),(in_Peso-in_MLG)/in_Peso,""))) -> 0.05 | C9: % | D9: Prioriza el % ingresado; si no, lo deriva de la MLG.
A10: Masa libre de grasa utilizada | B10: =IF(OR(NOT(ISNUMBER(in_Peso)),in_Peso<=0),"",IF(AND(NOT(ISBLANK(in_MLG)),ISNUMBER(in_MLG),in_MLG>0,in_MLG<in_Peso),in_MLG,IF(AND(NOT(ISBLANK(in_Grasa)),ISNUMBER(in_Grasa),in_Grasa>=GRASA_MIN,in_Grasa<=GRASA_MAX),in_Peso*(1-in_Grasa),""))) -> 62 | C10: kg | D10: La MLG MEDIDA tiene prioridad sobre la derivada del % de grasa. Alimenta a Cunningham 1980 y 1991.
A11: Masa grasa | B11: =IF(NOT(ISNUMBER($B$10)),"",in_Peso-$B$10) -> 16 | C11: kg | D11: Peso − MLG
A12: Origen de la MLG | B12: =IF(NOT(ISNUMBER($B$10)),"No disponible (Cunningham 1980 y 1991 no se calculan)",IF(AND(NOT(ISBLANK(in_MLG)),ISNUMBER(in_MLG),in_MLG>0,in_MLG<in_Peso),"Medida directamente","Derivada del % de grasa")) -> Medida directamente | C12: — | D12: Trazabilidad del dato.
A13: Factor de actividad efectivo (FA) | B13: =IF(in_Metodo=INDEX(LISTA_METODO,2),IF(ISNUMBER(ACTIVIDADES!$B$27),ACTIVIDADES!$B$27,""),IF(AND(NOT(ISBLANK(in_FAman)),ISNUMBER(in_FAman)),in_FAman,IF(COUNTIF(LISTA_FA,in_FAcat)=1,INDEX(FA_VAL,MATCH(in_FAcat,LISTA_FA,0)),""))) -> 1.8 | C13: — | D13: Prioridad: PAL derivado de ACTIVIDADES › factor manual › catálogo.
A14: Origen del factor | B14: =IF(in_Metodo=INDEX(LISTA_METODO,2),"PAL estimado desde ACTIVIDADES (TEE/GEB)",IF(AND(NOT(ISBLANK(in_FAman)),ISNUMBER(in_FAman)),"Factor manual de DATOS (sobreescribe el catálogo)","Catálogo CONFIG C4")) -> Catálogo CONFIG C4 | C14: — | D14: Trazabilidad de dónde salió el número.
A15: Horas registradas en ACTIVIDADES | B15: =ACTIVIDADES!$B$20 -> 24 | C15: h | D15: Debe ser 24 con el método por actividades.
A16: PAL estimado en ACTIVIDADES (TEE/GEB) | B16: =ACTIVIDADES!$B$27 -> NO CALCULADO | C16: — | D16: v1.1: ya NO es el promedio de METs. Ver hoja ACTIVIDADES.
A18: 1 · VALIDACIÓN — DATOS IMPOSIBLES (bloquean el cálculo)
A19: Verificación | B19: Estado | C19: Regla aplicada
A20: Sexo biológico | B20: =IF(COUNTIF(SEXOS,in_Sexo)=1,"OK","ERROR: seleccione Hombre o Mujer") -> OK | C20: Debe existir en el catálogo CONFIG C2.
A21: Edad adulta | B21: =IF(ISBLANK(in_Edad),"ERROR: vacío",IF(NOT(ISNUMBER(in_Edad)),"ERROR: no es numérico",IF(OR(in_Edad<EDAD_MIN,in_Edad>EDAD_MAX),"ERROR: edad fuera del alcance (solo adultos)","OK"))) -> OK | C21: Vacío → texto → rango [EDAD_MIN, EDAD_MAX].
A22: Peso mayor que cero | B22: =IF(ISBLANK(in_Peso),"ERROR: vacío",IF(NOT(ISNUMBER(in_Peso)),"ERROR: no es numérico",IF(in_Peso<=0,"ERROR: el peso debe ser mayor que cero",IF(OR(in_Peso<PESO_MIN,in_Peso>PESO_MAX),"ERROR: peso imposible en un adulto","OK")))) -> OK | C22: Bloquea vacíos, texto, cero y negativos.
A23: Estatura mayor que cero | B23: =IF(ISBLANK(in_Est),"ERROR: vacío",IF(NOT(ISNUMBER(in_Est)),"ERROR: no es numérico",IF(in_Est<=0,"ERROR: la estatura debe ser mayor que cero",IF(OR(in_Est<EST_MIN,in_Est>EST_MAX),"ERROR: estatura imposible","OK")))) -> OK | C23: Bloquea vacíos, texto, cero y negativos. Evita la división por cero del IMC.
A24: % de grasa (opcional) | B24: =IF(ISBLANK(in_Grasa),"NO INGRESADO (opcional)",IF(NOT(ISNUMBER(in_Grasa)),"ERROR: no es numérico",IF(OR(in_Grasa<GRASA_MIN,in_Grasa>GRASA_MAX),"ERROR: % de grasa imposible","OK"))) -> OK | C24: Opcional. Rango configurable.
A25: MLG menor que el peso (opcional) | B25: =IF(ISBLANK(in_MLG),"NO INGRESADA (opcional)",IF(NOT(ISNUMBER(in_MLG)),"ERROR: no es numérico",IF(NOT(ISNUMBER(in_Peso)),"NO APLICA",IF(in_MLG>=in_Peso,"ERROR: la MLG es mayor o igual al peso","OK")))) -> OK | C25: Imposibilidad fisiológica.
A26: Factor de actividad efectivo | B26: =IF(NOT(ISNUMBER($B$13)),IF(in_Metodo=INDEX(LISTA_METODO,2),"ERROR: el PAL por actividades exige 24 h registradas y un GEB calculable","ERROR: no se pudo determinar el factor de actividad"),IF(OR($B$13<FA_MIN,$B$13>FA_MAX),"ERROR: factor de actividad fuera de límites","OK")) -> OK | C26: Se valida el factor EFECTIVO, venga del catálogo, del campo manual o del PAL derivado.
A27: % de efecto térmico | B27: =IF(ISBLANK(in_pETA),"ERROR: vacío",IF(NOT(ISNUMBER(in_pETA)),"ERROR: no es numérico",IF(OR(in_pETA<0,in_pETA>ETA_MAX),"ERROR: % de efecto térmico fuera de rango","OK"))) -> OK | C27: Rango [0, ETA_MAX].
A28: % de ajuste energético | B28: =IF(ISBLANK(in_Ajuste),"ERROR: vacío",IF(NOT(ISNUMBER(in_Ajuste)),"ERROR: no es numérico",IF(ABS(in_Ajuste)>AJUSTE_MAX,"ERROR: ajuste fuera de rango","OK"))) -> OK | C28: |ajuste| ≤ AJUSTE_MAX.
A29: Registro de ACTIVIDADES = 24 h | B29: =IF(in_Metodo<>"Registro de actividades 24 h","NO APLICA · método global",IF(ABS(ACTIVIDADES!$B$20-HORAS_DIA)>0.001,"ERROR · registro de actividades ≠24 h",IF(COUNTIF(ACTIVIDADES!$H$7:$H$18,"REQUIERE REVALIDACIÓN")>0,"ERROR · hay actividades que requieren revalidación","OK"))) -> NO APLICA · método global | C29: Solo se exige con el método por actividades.
A30: Proteína no negativa | B30: =IF(ISBLANK(in_ValPro),"ERROR: vacío",IF(NOT(ISNUMBER(in_ValPro)),"ERROR: no es numérico",IF(in_ValPro<0,"ERROR: la proteína no puede ser negativa","OK"))) -> OK | C30: Se aplica en ambos modos.
A31: Grasa no negativa | B31: =IF(ISBLANK(in_ValGra),"ERROR: vacío",IF(NOT(ISNUMBER(in_ValGra)),"ERROR: no es numérico",IF(in_ValGra<0,"ERROR: la grasa no puede ser negativa","OK"))) -> OK | C31: Se aplica en ambos modos.
A32: % de proteína + % de grasa ≤ 100 % | B32: =IF(AND(in_ModoPro=INDEX(LISTA_MODO,1),in_ModoGra=INDEX(LISTA_MODO,1)),IF(ISNUMBER(in_ValPro)*ISNUMBER(in_ValGra)=0,"ERROR: valores no numéricos",IF(in_ValPro+in_ValGra>1,"ERROR: los % de proteína y grasa superan el 100 %","OK")),"NO APLICA (algún macro está en g/kg)") -> NO APLICA (algún macro está en g/kg) | C32: Con g/kg, el control equivalente es que los carbohidratos por diferencia no sean negativos (bloque 4).
A33: ¿CÁLCULO HABILITADO? | B33: =IF(SUMPRODUCT(--(LEFT($B$20:$B$32,5)="ERROR"))=0,"SÍ","NO") -> SÍ | C33: Compuerta única. Si es NO, todo lo que sigue devuelve vacío o 'ND', nunca un error de Excel.
A35: 2 · COMPONENTES DEL GASTO — GET = GEB + GAF + ETA
A36: Variable | B36: Valor | C36: Unidad | D36: Fórmula / nota
A37: GEB · gasto energético basal | B37: =IF($B$33<>"SÍ","",IF(ISNUMBER(ECUACIONES!$B$28),ECUACIONES!$B$28,"ND: la ecuación seleccionada no es calculable con los datos disponibles")) -> 1709.2 | C37: kcal/día | D37: Ecuación seleccionada en DATOS (hoja ECUACIONES).
A38: GAF · gasto por actividad física | B38: =IF(NOT(ISNUMBER($B$37)),"ND",$B$37*($B$13-1)) -> 1367.36 | C38: kcal/día | D38: GEB × (FA − 1). Se resta 1 para NO volver a contar el basal ya incluido en el factor.
A39: Modo de efecto térmico | B39: =in_ModoETA -> Incluido en el factor de actividad (recomendado) | C39: — | D39: Elegido en DATOS.
A40: ETA · efecto térmico de los alimentos | B40: =IF(NOT(ISNUMBER($B$38)),"ND",IF(in_ModoETA=INDEX(LISTA_ETA,1),0,IF(in_ModoETA=INDEX(LISTA_ETA,2),($B$37+$B$38)*in_pETA,IF(in_ModoETA=INDEX(LISTA_ETA,3),($B$37+$B$38)*in_pETA/(1-in_pETA),"ND")))) -> 0 | C40: kcal/día | D40: Modo 1: 0 (el PAL ya lo incluye). Modo 2: % de (GEB+GAF). Modo 3: se resuelve como % del GET.
A41: GET · gasto energético total | B41: =IF(OR(NOT(ISNUMBER($B$37)),NOT(ISNUMBER($B$38)),NOT(ISNUMBER($B$40))),"ND",$B$37+$B$38+$B$40) -> 3076.56 | C41: kcal/día | D41: Con ETA = 0 esto equivale exactamente a GEB × FA.
A42: Control de doble conteo | B42: =IF(in_ModoETA=INDEX(LISTA_ETA,1),"OK: el ETA está incluido en el factor de actividad; el libro lo fija en 0 y no lo suma dos veces.","⚠ ETA EXPLÍCITO SOBRE UN PAL: por definición de FAO, el PAL ya contiene el efecto térmico. Si su factor de actividad es un PAL, está contando el ETA DOS VECES. Actívelo solo si puede documentar que su factor lo EXCLUYE.") -> OK: el ETA está incluido en el factor de actividad; el libro lo fija en 0 y no lo suma dos veces.
A44: 3 · AJUSTE POR OBJETIVO Y ENERGÍA OBJETIVO
...

Sheet RESULTADOS
A1: RESULTADOS · Informe de la evaluación energética · DEFINITIVO 2026
A2: =HYPERLINK("#DATOS!A1","◀ DATOS") -> ◀ DATOS | C2: =HYPERLINK("#ECUACIONES!A1","▶ ECUACIONES") -> ▶ ECUACIONES
A4: IDENTIFICACIÓN
A5: Identificador de la evaluación | B5: =in_ID -> NMX-2026-0001
A6: Fecha | B6: =in_Fecha -> 46215
A7: Paciente | B7: =in_Pac -> PAC-0042
A8: Sexo · edad | B8: =IF(CALCULOS!$B$33<>"SÍ","ND",in_Sexo&" · "&ROUND(in_Edad,0)&" años") -> Hombre · 20 años
A9: Peso · estatura | B9: =IF(CALCULOS!$B$33<>"SÍ","ND",ROUND(in_Peso,1)&" kg · "&ROUND(in_Est,0)&" cm") -> 78 kg · 180 cm
A10: IMC | B10: =CALCULOS!$B$8 -> 24.074074 | C10: kg/m² | G10: kg/m²
A11: MLG utilizada · origen | B11: =IF(NOT(ISNUMBER(CALCULOS!$B$10)),"No disponible",ROUND(CALCULOS!$B$10,1)&" kg · "&CALCULOS!$B$12) -> 62 kg · Medida directamente
A12: Método de actividad · factor | B12: =in_Metodo&" · FA = "&IF(ISNUMBER(CALCULOS!$B$13),ROUND(CALCULOS!$B$13,3),"ND")&" ("&CALCULOS!$B$14&")" -> Factor de actividad global · FA = 1,8 (Catálogo CONFIG C4)
A13: Observaciones | B13: =IF(DATOS!$B$28="","—",DATOS!$B$28) -> —
A14: Nota técnica (QA v1.1.1): este bloque NO usa la función TEXT() con códigos de formato que contengan un punto decimal. En Excel en español el punto se interpreta como separador de millares y un factor de 1,55 se presentaría como 0,002. Se usa ROUND(), que respeta la configuración regional del usuario.
A15: DESGLOSE DEL GASTO Y ENERGÍA OBJETIVO
A16: Componente | B16: kcal/día | C16: % del GET | D16: Cómo se obtiene
A17: GEB · gasto energético basal | B17: =CALCULOS!$B$37 -> 1709.2 | C17: =IF(OR(NOT(ISNUMBER($B17)),NOT(ISNUMBER($B$20)),$B$20=0),"ND",$B17/$B$20) -> 0.55555556 | D17: Ecuación seleccionada
A18: GAF · gasto por actividad física | B18: =CALCULOS!$B$38 -> 1367.36 | C18: =IF(OR(NOT(ISNUMBER($B18)),NOT(ISNUMBER($B$20)),$B$20=0),"ND",$B18/$B$20) -> 0.44444444 | D18: GEB × (FA − 1)
A19: ETA · efecto térmico de los alimentos | B19: =CALCULOS!$B$40 -> 0 | C19: =IF(OR(NOT(ISNUMBER($B19)),NOT(ISNUMBER($B$20)),$B$20=0),"ND",$B19/$B$20) -> 0 | D19: 0 si el PAL ya lo incluye
A20: GET · gasto energético total | B20: =CALCULOS!$B$41 -> 3076.56 | C20: =IF(ISNUMBER($B$20),1,"ND") -> 1 | D20: GEB + GAF + ETA
A21: Ajuste por objetivo | B21: =CALCULOS!$B$47 -> 153.828 | C21: =in_Ajuste -> 0.05 | D21: GET × % de ajuste
A22: ENERGÍA OBJETIVO | B22: =CALCULOS!$B$48 -> 3230.388 | C22: ="—" -> — | D22: GET + ajuste
A23: Energía objetivo por kg | B23: =CALCULOS!$B$49 -> 41.415231 | C23: ="—" -> — | D23: Energía objetivo / peso
A24: =CALCULOS!$B$42 -> OK: el ETA está incluido en el factor de actividad; el libro lo fija en 0 y no lo suma dos veces.
A26: DISTRIBUCIÓN DE MACRONUTRIENTES
A27: Macronutriente | B27: g/día | C27: g/kg/día | D27: kcal/día | E27: % de la energía
A28: Proteína | B28: =CALCULOS!$D$53 -> 117 | C28: =CALCULOS!$E$53 -> 1.5 | D28: =CALCULOS!$F$53 -> 468 | E28: =CALCULOS!$G$53 -> 0.14487424
A29: Grasa | B29: =CALCULOS!$D$54 -> 72 | C29: =CALCULOS!$E$54 -> 0.92307692 | D29: =CALCULOS!$F$54 -> 648 | E29: =CALCULOS!$G$54 -> 0.2005951
A30: Carbohidratos (por diferencia) | B30: =CALCULOS!$D$55 -> 529 | C30: =CALCULOS!$E$55 -> 6.7820513 | D30: =CALCULOS!$F$55 -> 2116 | E30: =CALCULOS!$G$55 -> 0.65502967
A31: TOTAL | B31: =CALCULOS!$D$56 -> 718 | C31: =CALCULOS!$E$56 -> 9.2051282 | D31: =CALCULOS!$F$56 -> 3232 | E31: =CALCULOS!$G$56 -> 1.000499
A32: Comprobación · kcal de los macros − energía objetivo | B32: =CALCULOS!$B$62 -> 1.612 | C32: ="tolerancia: "&TEXT(TOL_KCAL,"0")&" kcal" -> tolerancia: 5 kcal | D32: =CALCULOS!$B$64 -> OK: las kcal de los macronutrientes cuadran con la energía objetivo dentro de la tolerancia.
A34: COMPARACIÓN DE LAS 7 ECUACIONES
A35: Ecuación | B35: GEB (kcal/día) | C35: Dif. vs promedio (kcal) | D35: Dif. vs promedio (%) | E35: Dif. vs seleccionada (kcal) | F35: Dif. vs seleccionada (%) | G35: ¿Datos disponibles?
A36: =ECUACIONES!$B$7 -> Mifflin–St Jeor (1990) | B36: =ECUACIONES!$F$7 -> 1810 | C36: =ECUACIONES!$H$7 -> 9.8494286 | D36: =ECUACIONES!$I$7 -> 0.0054714471 | E36: =ECUACIONES!$J$7 -> 100.8 | F36: =ECUACIONES!$K$7 -> 0.058974959 | G36: =ECUACIONES!$E$7 -> SÍ
A37: =ECUACIONES!$B$8 -> Harris–Benedict revisada · Roza & Shizgal (1984) | B37: =ECUACIONES!$F$8 -> 1883.608 | C37: =ECUACIONES!$H$8 -> 83.457429 | D37: =ECUACIONES!$I$8 -> 0.04636136 | E37: =ECUACIONES!$J$8 -> 174.408 | F37: =ECUACIONES!$K$8 -> 0.10204072 | G37: =ECUACIONES!$E$8 -> SÍ
A38: =ECUACIONES!$B$9 -> Owen (1986/1987) | B38: =ECUACIONES!$F$9 -> 1674.6 | C38: =ECUACIONES!$H$9 -> -125.55057 | D38: =ECUACIONES!$I$9 -> -0.069744483 | E38: =ECUACIONES!$J$9 -> -34.6 | F38: =ECUACIONES!$K$9 -> -0.020243389 | G38: =ECUACIONES!$E$9 -> SÍ
A39: =ECUACIONES!$B$10 -> Cunningham (1980) | B39: =ECUACIONES!$F$10 -> 1864 | C39: =ECUACIONES!$H$10 -> 63.849429 | D39: =ECUACIONES!$I$10 -> 0.035468938 | E39: =ECUACIONES!$J$10 -> 154.8 | F39: =ECUACIONES!$K$10 -> 0.090568687 | G39: =ECUACIONES!$E$10 -> SÍ
A40: =ECUACIONES!$B$11 -> Cunningham (1991) · alias secundario: Katch–McArdle | B40: =ECUACIONES!$F$11 -> 1709.2 | C40: =ECUACIONES!$H$11 -> -90.950571 | D40: =ECUACIONES!$I$11 -> -0.050523869 | E40: =ECUACIONES!$J$11 -> 0 | F40: =ECUACIONES!$K$11 -> 0 | G40: =ECUACIONES!$E$11 -> SÍ
A41: =ECUACIONES!$B$12 -> Schofield (1985) adultos · tabla canónica | B41: =ECUACIONES!$F$12 -> 1866.646 | C41: =ECUACIONES!$H$12 -> 66.495429 | D41: =ECUACIONES!$I$12 -> 0.036938815 | E41: =ECUACIONES!$J$12 -> 157.446 | F41: =ECUACIONES!$K$12 -> 0.09211678 | G41: =ECUACIONES!$E$12 -> SÍ
A42: =ECUACIONES!$B$13 -> Henry / Oxford (2005) adultos · solo peso | B42: =ECUACIONES!$F$13 -> 1793 | C42: =ECUACIONES!$H$13 -> -7.1505714 | D42: =ECUACIONES!$I$13 -> -0.0039722074 | E42: =ECUACIONES!$J$13 -> 83.8 | F42: =ECUACIONES!$K$13 -> 0.049028785 | G42: =ECUACIONES!$E$13 -> SÍ
A43: Ecuaciones calculadas (n) | B43: =ECUACIONES!$B$17 -> 7
...

Sheet ACTIVIDADES
A1: =IF(DATOS!$H$10="ADULT2024_MET","ACTIVIDADES · Adulto 19–59 años · MET · 2024 Adult Compendium",IF(DATOS!$H$10="OLDER2024_MET60","ACTIVIDADES · Adulto ≥60 años · MET60+ · 2024 Older Adult Compendium",IF(DATOS!$H$10="WHEELCHAIR2024_METWC","ACTIVIDADES · Usuario adulto de silla de ruedas · METWC · 2024 Wheelchair Compendium",IF(DATOS!$H$10="COMPENDIUM_NO_DISPONIBLE_18","ACTIVIDADES · Módulo Compendium no disponible para edad 18",IF(DATOS!$H$10="BLOQUEADO_INESTABLE","ACTIVIDADES · Módulo bloqueado · condición no estable","ACTIVIDADES · Fuera del alcance NMX-01"))))) -> ACTIVIDADES · Usuario adulto de silla de ruedas · METWC · 2024 Wheelchair Compendium
A2: =HYPERLINK("#DATOS!A1","◀ DATOS") -> ◀ DATOS
A3: =IF(DATOS!$H$10="BLOQUEADO_INESTABLE","MÓDULO BLOQUEADO: NMX-01 no aplica a pacientes críticos o clínicamente inestables.",IF(DATOS!$H$10="FUERA_ALCANCE","FUERA DEL ALCANCE DE NMX-01.",IF(DATOS!$H$10="COMPENDIUM_NO_DISPONIBLE_18","Edad 18: NMX-01 general aplica, pero este módulo no extrapola el Adult Compendium 2024. No se calcula PAL derivado del Compendium.",IF(COUNTIF($H$7:$H$18,"REQUIERE REVALIDACIÓN")>0,"CAMBIO DE POBLACIÓN O CATÁLOGO: revise las actividades marcadas REQUIERE REVALIDACIÓN antes de calcular TEE/PAL.",IF(AND(DATOS!$H$10="WHEELCHAIR2024_METWC",in_Edad>=CONFIG!$B$154),"PRECAUCIÓN: METWC es la referencia disponible para silla de ruedas; en ≥60 años la evidencia etaria es limitada y NMX-01 bloquea TEE/PAL automático.","Fuente 2024 activa y registro listo. MET/MET60+/METWC NO son intercambiables; el índice medio NO es el PAL."))))) -> CAMBIO DE POBLACIÓN O CATÁLOGO: revise las actividades marcadas REQUIERE REVALIDACIÓN antes de calcular TEE/PAL.
A4: Edad | B4: =in_Edad -> 20 | C4: Movilidad | D4: =DATOS!$H$7 -> Usuario de silla de ruedas | E4: Unidad activa | F4: =IF(DATOS!$H$10="ADULT2024_MET","MET",IF(DATOS!$H$10="OLDER2024_MET60","MET60+",IF(DATOS!$H$10="WHEELCHAIR2024_METWC","METWC","—"))) -> METWC | G4: =IF(DATOS!$H$10="ADULT2024_MET","✓ APLICABLE",IF(DATOS!$H$10="OLDER2024_MET60","✓ APLICABLE",IF(DATOS!$H$10="WHEELCHAIR2024_METWC",IF(in_Edad>=CONFIG!$B$154,"⚠ EVIDENCIA ETARIA LIMITADA","✓ APLICABLE"),IF(DATOS!$H$10="COMPENDIUM_NO_DISPONIBLE_18","⚠ NO DISPONIBLE","✕ BLOQUEADO")))) -> ✓ APLICABLE
A5: Fuente activa | B5: =IF(DATOS!$H$10="ADULT2024_MET","2024 Adult Compendium",IF(DATOS!$H$10="OLDER2024_MET60","2024 Older Adult Compendium",IF(DATOS!$H$10="WHEELCHAIR2024_METWC","2024 Wheelchair Compendium","—"))) -> 2024 Wheelchair Compendium | E5: Equiv. energético | F5: =IF(DATOS!$H$10="ADULT2024_MET",CONFIG!$B$149,IF(DATOS!$H$10="OLDER2024_MET60",CONFIG!$B$150,IF(DATOS!$H$10="WHEELCHAIR2024_METWC",CONFIG!$B$151,""))) -> 0.992 | G5: =IF(DATOS!$H$10="ADULT2024_MET","BASE_MET_ADULT_2024",IF(DATOS!$H$10="OLDER2024_MET60","BASE_MET_OLDER_2024",IF(DATOS!$H$10="WHEELCHAIR2024_METWC","BASE_MET_WHEELCHAIR_2024","—"))) -> BASE_MET_WHEELCHAIR_2024
A6: Nº | B6: Actividad (catálogo dinámico 2024) | C6: Código | D6: =$F$4 -> METWC | E6: Horas/día | F6: =IF($F$4="—","Unidad × h",$F$4&" × h") -> METWC × h | G6: Nota / justificación | H6: Estado
A7: 1 | B7: Dormir · [MET] | C7: 7030 | D7: 1 | E7: 8 | F7: =IF(AND(ISNUMBER($D7),ISNUMBER($E7)),$D7*$E7,0) -> 8 | H7: =IF(OR(DATOS!$H$10="FUERA_ALCANCE",DATOS!$H$10="BLOQUEADO_INESTABLE"),"FUERA DE ALCANCE",IF(DATOS!$H$10="COMPENDIUM_NO_DISPONIBLE_18","NO DISPONIBLE",IF(B7="","SIN ACTIVIDAD",IF(LEFT(B7,15)="(sin actividad)","SIN ACTIVIDAD",IF(OR(AND(DATOS!$H$10="ADULT2024_MET",NOT(ISNUMBER(FIND("[MET]",B7)))),AND(DATOS!$H$10="OLDER2024_MET60",NOT(ISNUMBER(FIND("[MET60+]",B7)))),AND(DATOS!$H$10="WHEELCHAIR2024_METWC",NOT(ISNUMBER(FIND("[METWC]",B7))))),"REQUIERE REVALIDACIÓN",IF(C7="","REQUIERE REVALIDACIÓN","OK")))))) -> REQUIERE REVALIDACIÓN
A8: 2 | B8: Trabajo sentado ligero · oficina / laboratorio / escritorio · [MET] | C8: 11580 | D8: 1.5 | E8: 7 | F8: =IF(AND(ISNUMBER($D8),ISNUMBER($E8)),$D8*$E8,0) -> 10.5 | H8: =IF(OR(DATOS!$H$10="FUERA_ALCANCE",DATOS!$H$10="BLOQUEADO_INESTABLE"),"FUERA DE ALCANCE",IF(DATOS!$H$10="COMPENDIUM_NO_DISPONIBLE_18","NO DISPONIBLE",IF(B8="","SIN ACTIVIDAD",IF(LEFT(B8,15)="(sin actividad)","SIN ACTIVIDAD",IF(OR(AND(DATOS!$H$10="ADULT2024_MET",NOT(ISNUMBER(FIND("[MET]",B8)))),AND(DATOS!$H$10="OLDER2024_MET60",NOT(ISNUMBER(FIND("[MET60+]",B8)))),AND(DATOS!$H$10="WHEELCHAIR2024_METWC",NOT(ISNUMBER(FIND("[METWC]",B8))))),"REQUIERE REVALIDACIÓN",IF(C8="","REQUIERE REVALIDACIÓN","OK")))))) -> REQUIERE REVALIDACIÓN
A9: 3 | B9: Estudiar sentado · lectura o escritura · esfuerzo ligero · [MET] | C9: 9060 | D9: 1.5 | E9: 3 | F9: =IF(AND(ISNUMBER($D9),ISNUMBER($E9)),$D9*$E9,0) -> 4.5 | H9: =IF(OR(DATOS!$H$10="FUERA_ALCANCE",DATOS!$H$10="BLOQUEADO_INESTABLE"),"FUERA DE ALCANCE",IF(DATOS!$H$10="COMPENDIUM_NO_DISPONIBLE_18","NO DISPONIBLE",IF(B9="","SIN ACTIVIDAD",IF(LEFT(B9,15)="(sin actividad)","SIN ACTIVIDAD",IF(OR(AND(DATOS!$H$10="ADULT2024_MET",NOT(ISNUMBER(FIND("[MET]",B9)))),AND(DATOS!$H$10="OLDER2024_MET60",NOT(ISNUMBER(FIND("[MET60+]",B9)))),AND(DATOS!$H$10="WHEELCHAIR2024_METWC",NOT(ISNUMBER(FIND("[METWC]",B9))))),"REQUIERE REVALIDACIÓN",IF(C9="","REQUIERE REVALIDACIÓN","OK")))))) -> REQUIERE REVALIDACIÓN
A10: 4 | B10: Caminar 4,5–5,5 km/h · moderado · [MET] | C10: 17190 | D10: 3.8 | E10: 2 | F10: =IF(AND(ISNUMBER($D10),ISNUMBER($E10)),$D10*$E10,0) -> 7.6 | H10: =IF(OR(DATOS!$H$10="FUERA_ALCANCE",DATOS!$H$10="BLOQUEADO_INESTABLE"),"FUERA DE ALCANCE",IF(DATOS!$H$10="COMPENDIUM_NO_DISPONIBLE_18","NO DISPONIBLE",IF(B10="","SIN ACTIVIDAD",IF(LEFT(B10,15)="(sin actividad)","SIN ACTIVIDAD",IF(OR(AND(DATOS!$H$10="ADULT2024_MET",NOT(ISNUMBER(FIND("[MET]",B10)))),AND(DATOS!$H$10="OLDER2024_MET60",NOT(ISNUMBER(FIND("[MET60+]",B10)))),AND(DATOS!$H$10="WHEELCHAIR2024_METWC",NOT(ISNUMBER(FIND("[METWC]",B10))))),"REQUIERE REVALIDACIÓN",IF(C10="","REQUIERE REVALIDACIÓN","OK")))))) -> REQUIERE REVALIDACIÓN
A11: 5 | B11: Cocina general · platos y limpieza · esfuerzo moderado · [MET] | C11: 5035 | D11: 3.3 | E11: 1.5 | F11: =IF(AND(ISNUMBER($D11),ISNUMBER($E11)),$D11*$E11,0) -> 4.95 | H11: =IF(OR(DATOS!$H$10="FUERA_ALCANCE",DATOS!$H$10="BLOQUEADO_INESTABLE"),"FUERA DE ALCANCE",IF(DATOS!$H$10="COMPENDIUM_NO_DISPONIBLE_18","NO DISPONIBLE",IF(B11="","SIN ACTIVIDAD",IF(LEFT(B11,15)="(sin actividad)","SIN ACTIVIDAD",IF(OR(AND(DATOS!$H$10="ADULT2024_MET",NOT(ISNUMBER(FIND("[MET]",B11)))),AND(DATOS!$H$10="OLDER2024_MET60",NOT(ISNUMBER(FIND("[MET60+]",B11)))),AND(DATOS!$H$10="WHEELCHAIR2024_METWC",NOT(ISNUMBER(FIND("[METWC]",B11))))),"REQUIERE REVALIDACIÓN",IF(C11="","REQUIERE REVALIDACIÓN","OK")))))) -> REQUIERE REVALIDACIÓN
A12: 6 | B12: Subir escaleras · ritmo lento · [MET] | C12: 17133 | D12: 4.5 | E12: 0.5 | F12: =IF(AND(ISNUMBER($D12),ISNUMBER($E12)),$D12*$E12,0) -> 2.25 | H12: =IF(OR(DATOS!$H$10="FUERA_ALCANCE",DATOS!$H$10="BLOQUEADO_INESTABLE"),"FUERA DE ALCANCE",IF(DATOS!$H$10="COMPENDIUM_NO_DISPONIBLE_18","NO DISPONIBLE",IF(B12="","SIN ACTIVIDAD",IF(LEFT(B12,15)="(sin actividad)","SIN ACTIVIDAD",IF(OR(AND(DATOS!$H$10="ADULT2024_MET",NOT(ISNUMBER(FIND("[MET]",B12)))),AND(DATOS!$H$10="OLDER2024_MET60",NOT(ISNUMBER(FIND("[MET60+]",B12)))),AND(DATOS!$H$10="WHEELCHAIR2024_METWC",NOT(ISNUMBER(FIND("[METWC]",B12))))),"REQUIERE REVALIDACIÓN",IF(C12="","REQUIERE REVALIDACIÓN","OK")))))) -> REQUIERE REVALIDACIÓN
A13: 7 | B13: Barrer garaje, acera o exterior de la casa · [MET] | C13: 5140 | D13: 3 | E13: 0.5 | F13: =IF(AND(ISNUMBER($D13),ISNUMBER($E13)),$D13*$E13,0) -> 1.5 | H13: =IF(OR(DATOS!$H$10="FUERA_ALCANCE",DATOS!$H$10="BLOQUEADO_INESTABLE"),"FUERA DE ALCANCE",IF(DATOS!$H$10="COMPENDIUM_NO_DISPONIBLE_18","NO DISPONIBLE",IF(B13="","SIN ACTIVIDAD",IF(LEFT(B13,15)="(sin actividad)","SIN ACTIVIDAD",IF(OR(AND(DATOS!$H$10="ADULT2024_MET",NOT(ISNUMBER(FIND("[MET]",B13)))),AND(DATOS!$H$10="OLDER2024_MET60",NOT(ISNUMBER(FIND("[MET60+]",B13)))),AND(DATOS!$H$10="WHEELCHAIR2024_METWC",NOT(ISNUMBER(FIND("[METWC]",B13))))),"REQUIERE REVALIDACIÓN",IF(C13="","REQUIERE REVALIDACIÓN","OK")))))) -> REQUIERE REVALIDACIÓN
A14: 8 | B14: Pesas · varios ejercicios · 8–15 repeticiones · [MET] | C14: 2054 | D14: 3.5 | E14: 1 | F14: =IF(AND(ISNUMBER($D14),ISNUMBER($E14)),$D14*$E14,0) -> 3.5 | H14: =IF(OR(DATOS!$H$10="FUERA_ALCANCE",DATOS!$H$10="BLOQUEADO_INESTABLE"),"FUERA DE ALCANCE",IF(DATOS!$H$10="COMPENDIUM_NO_DISPONIBLE_18","NO DISPONIBLE",IF(B14="","SIN ACTIVIDAD",IF(LEFT(B14,15)="(sin actividad)","SIN ACTIVIDAD",IF(OR(AND(DATOS!$H$10="ADULT2024_MET",NOT(ISNUMBER(FIND("[MET]",B14)))),AND(DATOS!$H$10="OLDER2024_MET60",NOT(ISNUMBER(FIND("[MET60+]",B14)))),AND(DATOS!$H$10="WHEELCHAIR2024_METWC",NOT(ISNUMBER(FIND("[METWC]",B14))))),"REQUIERE REVALIDACIÓN",IF(C14="","REQUIERE REVALIDACIÓN","OK")))))) -> REQUIERE REVALIDACIÓN
A15: 9 | B15: Ver televisión sentado · [MET] | C15: 7020 | D15: 1 | E15: 0.5 | F15: =IF(AND(ISNUMBER($D15),ISNUMBER($E15)),$D15*$E15,0) -> 0.5 | H15: =IF(OR(DATOS!$H$10="FUERA_ALCANCE",DATOS!$H$10="BLOQUEADO_INESTABLE"),"FUERA DE ALCANCE",IF(DATOS!$H$10="COMPENDIUM_NO_DISPONIBLE_18","NO DISPONIBLE",IF(B15="","SIN ACTIVIDAD",IF(LEFT(B15,15)="(sin actividad)","SIN ACTIVIDAD",IF(OR(AND(DATOS!$H$10="ADULT2024_MET",NOT(ISNUMBER(FIND("[MET]",B15)))),AND(DATOS!$H$10="OLDER2024_MET60",NOT(ISNUMBER(FIND("[MET60+]",B15)))),AND(DATOS!$H$10="WHEELCHAIR2024_METWC",NOT(ISNUMBER(FIND("[METWC]",B15))))),"REQUIERE REVALIDACIÓN",IF(C15="","REQUIERE REVALIDACIÓN","OK")))))) -> REQUIERE REVALIDACIÓN
A16: 10 | B16: (sin actividad) · [MET] | C16: 0 | D16: 0 | E16: 0 | F16: =IF(AND(ISNUMBER($D16),ISNUMBER($E16)),$D16*$E16,0) -> 0 | H16: =IF(OR(DATOS!$H$10="FUERA_ALCANCE",DATOS!$H$10="BLOQUEADO_INESTABLE"),"FUERA DE ALCANCE",IF(DATOS!$H$10="COMPENDIUM_NO_DISPONIBLE_18","NO DISPONIBLE",IF(B16="","SIN ACTIVIDAD",IF(LEFT(B16,15)="(sin actividad)","SIN ACTIVIDAD",IF(OR(AND(DATOS!$H$10="ADULT2024_MET",NOT(ISNUMBER(FIND("[MET]",B16)))),AND(DATOS!$H$10="OLDER2024_MET60",NOT(ISNUMBER(FIND("[MET60+]",B16)))),AND(DATOS!$H$10="WHEELCHAIR2024_METWC",NOT(ISNUMBER(FIND("[METWC]",B16))))),"REQUIERE REVALIDACIÓN",IF(C16="","REQUIERE REVALIDACIÓN","OK")))))) -> SIN ACTIVIDAD
A17: 11 | B17: (sin actividad) · [MET] | C17: 0 | D17: 0 | E17: 0 | F17: =IF(AND(ISNUMBER($D17),ISNUMBER($E17)),$D17*$E17,0) -> 0 | H17: =IF(OR(DATOS!$H$10="FUERA_ALCANCE",DATOS!$H$10="BLOQUEADO_INESTABLE"),"FUERA DE ALCANCE",IF(DATOS!$H$10="COMPENDIUM_NO_DISPONIBLE_18","NO DISPONIBLE",IF(B17="","SIN ACTIVIDAD",IF(LEFT(B17,15)="(sin actividad)","SIN ACTIVIDAD",IF(OR(AND(DATOS!$H$10="ADULT2024_MET",NOT(ISNUMBER(FIND("[MET]",B17)))),AND(DATOS!$H$10="OLDER2024_MET60",NOT(ISNUMBER(FIND("[MET60+]",B17)))),AND(DATOS!$H$10="WHEELCHAIR2024_METWC",NOT(ISNUMBER(FIND("[METWC]",B17))))),"REQUIERE REVALIDACIÓN",IF(C17="","REQUIERE REVALIDACIÓN","OK")))))) -> SIN ACTIVIDAD
A18: 12 | B18: (sin actividad) · [MET] | C18: 0 | D18: 0 | E18: 0 | F18: =IF(AND(ISNUMBER($D18),ISNUMBER($E18)),$D18*$E18,0) -> 0 | H18: =IF(OR(DATOS!$H$10="FUERA_ALCANCE",DATOS!$H$10="BLOQUEADO_INESTABLE"),"FUERA DE ALCANCE",IF(DATOS!$H$10="COMPENDIUM_NO_DISPONIBLE_18","NO DISPONIBLE",IF(B18="","SIN ACTIVIDAD",IF(LEFT(B18,15)="(sin actividad)","SIN ACTIVIDAD",IF(OR(AND(DATOS!$H$10="ADULT2024_MET",NOT(ISNUMBER(FIND("[MET]",B18)))),AND(DATOS!$H$10="OLDER2024_MET60",NOT(ISNUMBER(FIND("[MET60+]",B18)))),AND(DATOS!$H$10="WHEELCHAIR2024_METWC",NOT(ISNUMBER(FIND("[METWC]",B18))))),"REQUIERE REVALIDACIÓN",IF(C18="","REQUIERE REVALIDACIÓN","OK")))))) -> SIN ACTIVIDAD
A19: CONVERSIÓN 24 H · UNIDAD × H → ENERGÍA → PAL ESTIMADO
A20: 1 · Total de horas registradas | B20: =SUM($E$7:$E$18) -> 24 | C20: h | D20: =IF(ABS($B$20-HORAS_DIA)<0.001,"OK · Registro de 24 h completo",IF($B$20<HORAS_DIA,"INCOMPLETO · faltan "&TEXT(HORAS_DIA-$B$20,"0.00")&" h","ERROR · sobran "&TEXT($B$20-HORAS_DIA,"0.00")&" h")) -> OK · Registro de 24 h completo
A21: ="2 · Σ ("&$F$4&" × horas)" -> 2 · Σ (METWC × horas) | B21: =SUM($F$7:$F$18) -> 43.3 | C21: =IF($F$4="—","—",$F$4&"·h/día") -> METWC·h/día | D21: Suma bruta del registro activo.
A22: ="3 · Índice "&$F$4&" medio = Σ / 24 ◄ NO ES EL PAL" -> 3 · Índice METWC medio = Σ / 24 ◄ NO ES EL PAL | B22: =IF($B$20=0,"ND",$B$21/HORAS_DIA) -> 1.8041667 | C22: — | D22: Referencia descriptiva del costo relativo medio; NO se usa como PAL.
A23: 4 · Peso del paciente | B23: =IF(OR(ISBLANK(in_Peso),NOT(ISNUMBER(in_Peso)),in_Peso<=0),"ND",in_Peso) -> 78 | C23: kg | D23: Desde DATOS.
A24: ="5 · Equivalente energético de 1 "&$F$4 -> 5 · Equivalente energético de 1 METWC | B24: =$F$5 -> 0.992 | C24: kcal/kg/h | D24: =IF($F$4="MET","Adult Compendium 2024: 1,000 kcal/kg/h.",IF($F$4="MET60+","Older Adult 2024: 0,810 kcal/kg/h (basal 2,7 mL O2/kg/min).",IF($F$4="METWC","Wheelchair 2024: 0,992 kcal/kg/h.","No aplicable."))) -> Wheelchair 2024: 0,992 kcal/kg/h.
A25: 6 · TEE estimado = Σ(unidad×h) × Peso × equivalente | B25: =IF(ABS($B$20-HORAS_DIA)>0.001,"NO CALCULADO · registro ≠ 24 h",IF(COUNTIF($H$7:$H$18,"REQUIERE REVALIDACIÓN")>0,"NO CALCULADO · revalidar actividades",IF(OR(DATOS!$H$10="FUERA_ALCANCE",DATOS!$H$10="BLOQUEADO_INESTABLE",DATOS!$H$10="COMPENDIUM_NO_DISPONIBLE_18"),"NO CALCULADO · módulo no aplicable",IF(AND(DATOS!$H$10="WHEELCHAIR2024_METWC",in_Edad>=CONFIG!$B$154),"NO CALCULADO · METWC ≥60 con evidencia etaria limitada",IF(OR(NOT(ISNUMBER(in_Peso)),in_Peso<=0,NOT(ISNUMBER($F$5)),$F$5<=0),"NO CALCULADO · datos insuficientes",SUM($F$7:$F$18)*in_Peso*$F$5))))) -> NO CALCULADO · revalidar actividades | C25: kcal/día | D25: Estimación Compendium; no equivale a calorimetría indirecta. En silla de ruedas ≥60 se bloquea por evidencia etaria limitada.
A26: 7 · GEB de la ecuación seleccionada | B26: =IF(ISNUMBER(ECUACIONES!$B$28),ECUACIONES!$B$28,"ND") -> 1709.2 | C26: kcal/día | D26: Desde ECUACIONES.
A27: 8 · PAL ESTIMADO DERIVADO DE COMPENDIUM = TEE / GEB | B27: =IF(NOT(ISNUMBER($B$25)),"NO CALCULADO",IF(OR(NOT(ISNUMBER($B$26)),$B$26<=0),"NO CALCULADO",$B$25/$B$26)) -> NO CALCULADO | C27: — | D27: APROXIMACIÓN · NO MEDICIÓN. No presentar como PAL exacto ni clínicamente validado.
A29: Advertencia metodológica: MET, MET60+ y METWC tienen referencias de reposo diferentes y NO son intercambiables. El promedio de unidad×h NO es PAL. Si cambia la edad 59→60 o la movilidad, vuelva a seleccionar las actividades; las etiquetas incluyen la unidad para impedir una migración silenciosa.
A30: Fuentes 2024: Herrmann et al. Adult Compendium (19–59); Willis et al. Older Adult Compendium (≥60; MET60+); Conger et al. Wheelchair Compendium (METWC). Ver FUENTES y las hojas BASE_MET_* para códigos, valores y URLs oficiales.

Sheet FUENTES
A1: FUENTES · Trazabilidad y nivel de verificación · DEFINITIVO 2026 · NMX-ACT-2024-v1
A2: Fecha de cotejo: 2026-07-12, contra el 'Dossier de verificación bibliográfica y metodológica NMX-01 v1.1'. NIVEL A = publicación primaria con texto completo o documento institucional oficial · NIVEL B = resumen primario exacto y/o corroboración consistente en literatura revisada por pares · NIVEL C = depende de fuentes secundarias. EXACTITUD BIBLIOGRÁFICA ≠ VALIDACIÓN CLÍNICA.
A4: =HYPERLINK("#INICIO!A1","◀ INICIO") -> ◀ INICIO
