Workbook
Name CFG_ActivarActividad: CONFIG!$B$25
Name CFG_ActivarBioquimica: CONFIG!$B$23
Name CFG_ActivarComposicion: CONFIG!$B$28
Name CFG_ActivarFarmacos: CONFIG!$B$26
Name CFG_ActivarGraficos: CONFIG!$B$29
Name CFG_ActivarIdentificacionDirecta: CONFIG!$B$30
Name CFG_ActivarR24H: CONFIG!$B$24
Name CFG_ActivarSuplementos: CONFIG!$B$27
Name CFG_CaderaMax: CONFIG!$B$45
Name CFG_CaderaMin: CONFIG!$B$44
Name CFG_CinturaMax: CONFIG!$B$43
Name CFG_CinturaMin: CONFIG!$B$42
Name CFG_EdadMax: CONFIG!$B$37
Name CFG_EdadMin: CONFIG!$B$36
Name CFG_EstaturaMax: CONFIG!$B$41
Name CFG_EstaturaMin: CONFIG!$B$40
Name CFG_GrasaMax: CONFIG!$B$47
Name CFG_GrasaMin: CONFIG!$B$46
Name CFG_MaxGrafico: CONFIG!$B$49
Name CFG_PermitirFechasFuturas: CONFIG!$B$31
Name CFG_PesoMax: CONFIG!$B$39
Name CFG_PesoMin: CONFIG!$B$38
Name CFG_Tolerancia: CONFIG!$B$48
Name Lista_CategoriaAntecedente: CATALOGOS!$D$7:$D$27
Name Lista_CategoriaIntervencion: CATALOGOS!$K$7:$K$16
Name Lista_Confiabilidad: CATALOGOS!$P$7:$P$10
Name Lista_Consentimiento: CATALOGOS!$N$7:$N$10
Name Lista_EstadoBio: CATALOGOS!$T$7:$T$10
Name Lista_EstadoDiagnostico: CATALOGOS!$H$7:$H$11
Name Lista_EstadoObjetivo: CATALOGOS!$J$7:$J$11
Name Lista_EstadoPaciente: CATALOGOS!$A$7:$A$11
Name Lista_EstadoRegistro: CATALOGOS!$O$7:$O$12
Name Lista_EvaluationID: EVALUACION!$A$7:$A$36
Name Lista_FuenteDato: CATALOGOS!$M$7:$M$12
Name Lista_Intensidad: CATALOGOS!$Q$7:$Q$10
Name Lista_Modalidad: CATALOGOS!$C$7:$C$9
Name Lista_PatientID: PACIENTES!$A$7:$A$26
Name Lista_Presencia: CATALOGOS!$R$7:$R$10
Name Lista_Prioridad: CATALOGOS!$I$7:$I$10
Name Lista_SiNoNA: CATALOGOS!$U$7:$U$9
Name Lista_SistemaClinico: CATALOGOS!$E$7:$E$26
Name Lista_TiempoComida: CATALOGOS!$F$7:$F$14
Name Lista_TipoActividad: CATALOGOS!$G$7:$G$12
Name Lista_TipoDia: CATALOGOS!$S$7:$S$12
Name Lista_TipoEvaluacion: CATALOGOS!$B$7:$B$10
Name Lista_Unidad: CATALOGOS!$L$7:$L$24

Sheet INICIO
A1: Nutrimetría Excel Lab — NMX-03 · Historia Clínica Nutricional Completa
A2: ◀ INICIO | B2: RESUMEN | C2: CONFIG | D2: PRUEBAS
A3: PACIENTE FICTICIO PARA PRUEBA — NO UTILIZAR COMO REFERENCIA CLÍNICA · Elimine o reemplace todos los casos antes de uso real.
A5: Estado e inventario
A6: Código | B6: NMX-03 | F6: Información técnica y trazable.
A7: Versión | B7: 1.0.1-RC | F7: Información técnica y trazable.
A8: Estado | B8: CANDIDATO A PUBLICACIÓN — revisión clínica profesional declarada; requiere protocolo final en Excel 2021 y Microsoft 365 | F8: Información técnica y trazable.
A9: Pacientes | B9: =CALCULOS!B10 -> 5 | F9: Información técnica y trazable.
A10: Evaluaciones | B10: =CALCULOS!B11 -> 6 | F10: Información técnica y trazable.
A11: Última fecha | B11: =CALCULOS!B12 -> 46208 | F11: Información técnica y trazable.
A12: Pruebas | B12: =PRUEBAS!B99&" totales · "&PRUEBAS!B100&" aprobadas · "&PRUEBAS!B102&" pendientes" -> 90 totales · 88 aprobadas · 2 pendientes | F12: Información técnica y trazable.
A13: Compatibilidad | B13: Objetivo Excel 365 / Excel 2021 para Windows | F13: Información técnica y trazable.
A15: Objetivo, alcance y privacidad
A16: Registrar múltiples pacientes y evaluaciones longitudinales mediante PatientID y EvaluationID.
A17: Orientado a adultos en consulta nutricional ambulatoria; no pediatría, embarazo, UCI, nutrición enteral/parenteral, enfermedad renal avanzada, TCA ni deporte especializado.
A18: ▲ No emite diagnósticos médicos, no prescribe medicamentos ni decide tratamientos automáticamente.
A19: ▲ Use minimización de datos, identificadores internos, equipo protegido, copias de seguridad y medios de transferencia seguros.
A20: ▲ La protección de hojas evita cambios accidentales; no cifra datos ni impide accesos no autorizados.
A21: ▲ No use almacenamiento público ni envíe el archivo sin medidas de seguridad y autorización aplicables.
A23: Flujo de trabajo
A24: 1 · Registrar paciente en PACIENTES.
A25: 2 · Crear evaluación en EVALUACION.
A26: 3 · Completar ANTECEDENTES, ANTROPOMETRIA, BIOQUIMICA y CLINICA.
A27: 4 · Completar ALIMENTACION y ACTIVIDAD.
... A35: Navegación interna
A36: PACIENTES | D36: EVALUACION | G36: ANTECEDENTES | J36: ANTROPOMETRIA
A37: BIOQUIMICA | D37: CLINICA | G37: ALIMENTACION | J37: ACTIVIDAD
A38: FARMACOS | D38: DIAGNOSTICO | G38: OBJETIVOS | J38: INTERVENCION
A39: SEGUIMIENTO | D39: RESUMEN | G39: CALCULOS | J39: CATALOGOS
A40: PRUEBAS | D40: CONFIG | G40: FUENTES | J40: CHANGELOG
A41: AUDITORIA_COMERCIAL | D41: COMPATIBILIDAD
A42: Leyenda, respaldo y accesibilidad
A43: Tipo | B43: Muestra | C43: Significado
A44: Entrada editable | C44: Fondo ámbar
A45: Cálculo | C45: Fondo gris
A46: Dato ficticio | C46: Fondo lavanda
A47: Advertencia | C47: Texto ▲ + fondo amarillo
A48: Error | C48: Texto ✖ + fondo rojo
A50: Estado v1.0.1-RC: fórmulas ampliadas, navegación compatible, fechas y gráficos corregidos, validaciones reforzadas y barreras antiedición aplicadas. La protección nativa y la prueba física de Excel deben cerrarse antes de etiquetar la versión como definitiva.

Sheet PACIENTES
A1: PACIENTES · Maestro de identificación mínima y consentimiento
A2: ◀ INICIO | B2: RESUMEN | C2: CONFIG | D2: PRUEBAS
A3: PACIENTE FICTICIO PARA PRUEBA — NO UTILIZAR COMO REFERENCIA CLÍNICA · Todos los datos son sintéticos.
A5: T_PACIENTES
A6: PatientID | B6: Estado | C6: FechaRegistro | D6: Iniciales | E6: Nombre opcional | F6: Apellido opcional | G6: FechaNacimiento opcional | H6: Edad calculada | I6: Sexo registrado al nacer | J6: Género opcional | K6: Pronombres opcionales | L6: Teléfono opcional | M6: Correo opcional | N6: Ciudad o región opcional | O6: Ocupación | P6: Sistema previsión opcional | Q6: Contacto emergencia opcional | R6: Consentimiento datos | S6: Fecha consentimiento | T6: Versión consentimiento | U6: Profesional responsable | V6: FechaModificacion | W6: FuenteDato | X6: Observaciones | Y6: Control
A7: P-FICT-A | B7: Activo | C7: 46174 | D7: AFA | G7: 32975 | H7: =IF(ISNUMBER(G7),YEAR(TODAY())-YEAR(G7)-IF(DATE(YEAR(TODAY()),MONTH(G7),DAY(G7))>TODAY(),1,0),"") -> 36 | I7: Femenino | N7: Región ficticia | O7: Ocupación ficticia | R7: Sí | S7: 46174 | T7: CONS-1 | U7: PROF-DEMO | V7: 46216 | W7: Documentado | X7: PACIENTE FICTICIO PARA PRUEBA — NO UTILIZAR COMO REFERENCIA CLÍNICA | Y7: =IF(A7="","",IF(COUNTIF($A$7:$A$1006,A7)>1,"✖ PatientID duplicado",IF(AND(ISNUMBER(G7),G7>TODAY()),"✖ Fecha nacimiento futura",IF(AND(M7<>"",COUNTIF(M7,"?*@?*.?*")=0),"▲ Correo básico inválido",IF(COUNTIF(CATALOGOS!$A$7:$A$11,B7)=0,"✖ Estado no permitido",IF(AND(R7="Sí",NOT(ISNUMBER(S7))),"✖ Consentimiento Sí sin fecha",IF(AND(ISNUMBER(H7),OR(H7<CONFIG!$B$36,H7>CONFIG!$B$37)),"▲ Fuera de alcance adulto","✔ Correcto"))))))) -> ✔ Correcto
A8: P-FICT-B | B8: Activo | C8: 46143 | D8: BFB | G8: 31310 | H8: =IF(ISNUMBER(G8),YEAR(TODAY())-YEAR(G8)-IF(DATE(YEAR(TODAY()),MONTH(G8),DAY(G8))>TODAY(),1,0),"") -> 40 | I8: Masculino | N8: Región ficticia | O8: Ocupación ficticia | R8: Sí | S8: 46143 | T8: CONS-1 | U8: PROF-DEMO | V8: 46216 | W8: Documentado | X8: PACIENTE FICTICIO PARA PRUEBA — NO UTILIZAR COMO REFERENCIA CLÍNICA | Y8: =IF(A8="","",IF(COUNTIF($A$7:$A$1006,A8)>1,"✖ PatientID duplicado",IF(AND(ISNUMBER(G8),G8>TODAY()),"✖ Fecha nacimiento futura",IF(AND(M8<>"",COUNTIF(M8,"?*@?*.?*")=0),"▲ Correo básico inválido",IF(COUNTIF(CATALOGOS!$A$7:$A$11,B8)=0,"✖ Estado no permitido",IF(AND(R8="Sí",NOT(ISNUMBER(S8))),"✖ Consentimiento Sí sin fecha",IF(AND(ISNUMBER(H8),OR(H8<CONFIG!$B$36,H8>CONFIG!$B$37)),"▲ Fuera de alcance adulto","✔ Correcto"))))))) -> ✔ Correcto
A9: P-FICT-C | B9: Activo | C9: 46204 | D9: CFC | G9: 36535 | H9: =IF(ISNUMBER(G9),YEAR(TODAY())-YEAR(G9)-IF(DATE(YEAR(TODAY()),MONTH(G9),DAY(G9))>TODAY(),1,0),"") -> 26 | I9: No informado | N9: Región ficticia | O9: Ocupación ficticia | R9: Pendiente | T9: CONS-1 | U9: PROF-DEMO | V9: 46216 | W9: Informado por paciente | X9: PACIENTE FICTICIO PARA PRUEBA — NO UTILIZAR COMO REFERENCIA CLÍNICA | Y9: =IF(A9="","",IF(COUNTIF($A$7:$A$1006,A9)>1,"✖ PatientID duplicado",IF(AND(ISNUMBER(G9),G9>TODAY()),"✖ Fecha nacimiento futura",IF(AND(M9<>"",COUNTIF(M9,"?*@?*.?*")=0),"▲ Correo básico inválido",IF(COUNTIF(CATALOGOS!$A$7:$A$11,B9)=0,"✖ Estado no permitido",IF(AND(R9="Sí",NOT(ISNUMBER(S9))),"✖ Consentimiento Sí sin fecha",IF(AND(ISNUMBER(H9),OR(H9<CONFIG!$B$36,H9>CONFIG!$B$37)),"▲ Fuera de alcance adulto","✔ Correcto"))))))) -> ✔ Correcto
A10: P-FICT-D | B10: Activo | C10: 46183 | D10: DFD | G10: 28829 | H10: =IF(ISNUMBER(G10),YEAR(TODAY())-YEAR(G10)-IF(DATE(YEAR(TODAY()),MONTH(G10),DAY(G10))>TODAY(),1,0),"") -> 47 | I10: Femenino | N10: Región ficticia | O10: Ocupación ficticia | R10: Sí | S10: 46183 | T10: CONS-1 | U10: PROF-DEMO | V10: 46216 | W10: Documentado | X10: PACIENTE FICTICIO PARA PRUEBA — NO UTILIZAR COMO REFERENCIA CLÍNICA | Y10: =IF(A10="","",IF(COUNTIF($A$7:$A$1006,A10)>1,"✖ PatientID duplicado",IF(AND(ISNUMBER(G10),G10>TODAY()),"✖ Fecha nacimiento futura",IF(AND(M10<>"",COUNTIF(M10,"?*@?*.?*")=0),"▲ Correo básico inválido",IF(COUNTIF(CATALOGOS!$A$7:$A$11,B10)=0,"✖ Estado no permitido",IF(AND(R10="Sí",NOT(ISNUMBER(S10))),"✖ Consentimiento Sí sin fecha",IF(AND(ISNUMBER(H10),OR(H10<CONFIG!$B$36,H10>CONFIG!$B$37)),"▲ Fuera de alcance adulto","✔ Correcto"))))))) -> ✔ Correcto
A11: P-FICT-E | B11: Activo | C11: 46208 | D11: EFE | G11: 34887 | H11: =IF(ISNUMBER(G11),YEAR(TODAY())-YEAR(G11)-IF(DATE(YEAR(TODAY()),MONTH(G11),DAY(G11))>TODAY(),1,0),"") -> 31 | I11: Masculino | N11: Región ficticia | O11: Ocupación ficticia | R11: Revocado | S11: 46215 | T11: CONS-1 | U11: PROF-DEMO | V11: 46216 | W11: Documentado | X11: PACIENTE FICTICIO PARA PRUEBA — NO UTILIZAR COMO REFERENCIA CLÍNICA · Escenarios inválidos solo en PRUEBAS. | Y11: =IF(A11="","",IF(COUNTIF($A$7:$A$1006,A11)>1,"✖ PatientID duplicado",IF(AND(ISNUMBER(G11),G11>TODAY()),"✖ Fecha nacimiento futura",IF(AND(M11<>"",COUNTIF(M11,"?*@?*.?*")=0),"▲ Correo básico inválido",IF(COUNTIF(CATALOGOS!$A$7:$A$11,B11)=0,"✖ Estado no permitido",IF(AND(R11="Sí",NOT(ISNUMBER(S11))),"✖ Consentimiento Sí sin fecha",IF(AND(ISNUMBER(H11),OR(H11<CONFIG!$B$36,H11>CONFIG!$B$37)),"▲ Fuera de alcance adulto","✔ Correcto"))))))) -> ✔ Correcto
H12: =IF(ISNUMBER(G12),YEAR(TODAY())-YEAR(G12)-IF(DATE(YEAR(TODAY()),MONTH(G12),DAY(G12))>TODAY(),1,0),"") | Y12: =IF(A12="","",IF(COUNTIF($A$7:$A$26,A12)>1,"✖ PatientID duplicado",IF(AND(ISNUMBER(G12),G12>TODAY()),"✖ Fecha nacimiento futura",IF(AND(M12<>"",COUNTIF(M12,"?*@?*.?*")=0),"▲ Correo básico inválido",IF(COUNTIF(CATALOGOS!$A$7:$A$11,B12)=0,"✖ Estado no permitido",IF(AND(R12="Sí",NOT(ISNUMBER(S12))),"✖ Consentimiento Sí sin fecha",IF(AND(ISNUMBER(H12),OR(H12<CONFIG!$B$36,H12>CONFIG!$B$37)),"▲ Fuera de alcance adulto","✔ Correcto")))))))
H13: =IF(ISNUMBER(G13),YEAR(TODAY())-YEAR(G13)-IF(DATE(YEAR(TODAY()),MONTH(G13),DAY(G13))>TODAY(),1,0),"") | Y13: =IF(A13="","",IF(COUNTIF($A$7:$A$26,A13)>1,"✖ PatientID duplicado",IF(AND(ISNUMBER(G13),G13>TODAY()),"✖ Fecha nacimiento futura",IF(AND(M13<>"",COUNTIF(M13,"?*@?*.?*")=0),"▲ Correo básico inválido",IF(COUNTIF(CATALOGOS!$A$7:$A$11,B13)=0,"✖ Estado no permitido",IF(AND(R13="Sí",NOT(ISNUMBER(S13))),"✖ Consentimiento Sí sin fecha",IF(AND(ISNUMBER(H13),OR(H13<CONFIG!$B$36,H13>CONFIG!$B$37)),"▲ Fuera de alcance adulto","✔ Correcto")))))))
H14: =IF(ISNUMBER(G14),YEAR(TODAY())-YEAR(G14)-IF(DATE(YEAR(TODAY()),MONTH(G14),DAY(G14))>TODAY(),1,0),"") | Y14: =IF(A14="","",IF(COUNTIF($A$7:$A$26,A14)>1,"✖ PatientID duplicado",IF(AND(ISNUMBER(G14),G14>TODAY()),"✖ Fecha nacimiento futura",IF(AND(M14<>"",COUNTIF(M14,"?*@?*.?*")=0),"▲ Correo básico inválido",IF(COUNTIF(CATALOGOS!$A$7:$A$11,B14)=0,"✖ Estado no permitido",IF(AND(R14="Sí",NOT(ISNUMBER(S14))),"✖ Consentimiento Sí sin fecha",IF(AND(ISNUMBER(H14),OR(H14<CONFIG!$B$36,H14>CONFIG!$B$37)),"▲ Fuera de alcance adulto","✔ Correcto")))))))
H15: =IF(ISNUMBER(G15),YEAR(TODAY())-YEAR(G15)-IF(DATE(YEAR(TODAY()),MONTH(G15),DAY(G15))>TODAY(),1,0),"") | Y15: =IF(A15="","",IF(COUNTIF($A$7:$A$26,A15)>1,"✖ PatientID duplicado",IF(AND(ISNUMBER(G15),G15>TODAY()),"✖ Fecha nacimiento futura",IF(AND(M15<>"",COUNTIF(M15,"?*@?*.?*")=0),"▲ Correo básico inválido",IF(COUNTIF(CATALOGOS!$A$7:$A$11,B15)=0,"✖ Estado no permitido",IF(AND(R15="Sí",NOT(ISNUMBER(S15))),"✖ Consentimiento Sí sin fecha",IF(AND(ISNUMBER(H15),OR(H15<CONFIG!$B$36,H15>CONFIG!$B$37)),"▲ Fuera de alcance adulto","✔ Correcto")))))))
H16: =IF(ISNUMBER(G16),YEAR(TODAY())-YEAR(G16)-IF(DATE(YEAR(TODAY()),MONTH(G16),DAY(G16))>TODAY(),1,0),"") | Y16: =IF(A16="","",IF(COUNTIF($A$7:$A$26,A16)>1,"✖ PatientID duplicado",IF(AND(ISNUMBER(G16),G16>TODAY()),"✖ Fecha nacimiento futura",IF(AND(M16<>"",COUNTIF(M16,"?*@?*.?*")=0),"▲ Correo básico inválido",IF(COUNTIF(CATALOGOS!$A$7:$A$11,B16)=0,"✖ Estado no permitido",IF(AND(R16="Sí",NOT(ISNUMBER(S16))),"✖ Consentimiento Sí sin fecha",IF(AND(ISNUMBER(H16),OR(H16<CONFIG!$B$36,H16>CONFIG!$B$37)),"▲ Fuera de alcance adulto","✔ Correcto")))))))
H17: =IF(ISNUMBER(G17),YEAR(TODAY())-YEAR(G17)-IF(DATE(YEAR(TODAY()),MONTH(G17),DAY(G17))>TODAY(),1,0),"") | Y17: =IF(A17="","",IF(COUNTIF($A$7:$A$26,A17)>1,"✖ PatientID duplicado",IF(AND(ISNUMBER(G17),G17>TODAY()),"✖ Fecha nacimiento futura",IF(AND(M17<>"",COUNTIF(M17,"?*@?*.?*")=0),"▲ Correo básico inválido",IF(COUNTIF(CATALOGOS!$A$7:$A$11,B17)=0,"✖ Estado no permitido",IF(AND(R17="Sí",NOT(ISNUMBER(S17))),"✖ Consentimiento Sí sin fecha",IF(AND(ISNUMBER(H17),OR(H17<CONFIG!$B$36,H17>CONFIG!$B$37)),"▲ Fuera de alcance adulto","✔ Correcto")))))))
H18: =IF(ISNUMBER(G18),YEAR(TODAY())-YEAR(G18)-IF(DATE(YEAR(TODAY()),MONTH(G18),DAY(G18))>TODAY(),1,0),"") | Y18: =IF(A18="","",IF(COUNTIF($A$7:$A$26,A18)>1,"✖ PatientID duplicado",IF(AND(ISNUMBER(G18),G18>TODAY()),"✖ Fecha nacimiento futura",IF(AND(M18<>"",COUNTIF(M18,"?*@?*.?*")=0),"▲ Correo básico inválido",IF(COUNTIF(CATALOGOS!$A$7:$A$11,B18)=0,"✖ Estado no permitido",IF(AND(R18="Sí",NOT(ISNUMBER(S18))),"✖ Consentimiento Sí sin fecha",IF(AND(ISNUMBER(H18),OR(H18<CONFIG!$B$36,H18>CONFIG!$B$37)),"▲ Fuera de alcance adulto","✔ Correcto")))))))
H19: =IF(ISNUMBER(G19),YEAR(TODAY())-YEAR(G19)-IF(DATE(YEAR(TODAY()),MONTH(G19),DAY(G19))>TODAY(),1,0),"") | Y19: =IF(A19="","",IF(COUNTIF($A$7:$A$26,A19)>1,"✖ PatientID duplicado",IF(AND(ISNUMBER(G19),G19>TODAY()),"✖ Fecha nacimiento futura",IF(AND(M19<>"",COUNTIF(M19,"?*@?*.?*")=0),"▲ Correo básico inválido",IF(COUNTIF(CATALOGOS!$A$7:$A$11,B19)=0,"✖ Estado no permitido",IF(AND(R19="Sí",NOT(ISNUMBER(S19))),"✖ Consentimiento Sí sin fecha",IF(AND(ISNUMBER(H19),OR(H19<CONFIG!$B$36,H19>CONFIG!$B$37)),"▲ Fuera de alcance adulto","✔ Correcto")))))))
H20: =IF(ISNUMBER(G20),YEAR(TODAY())-YEAR(G20)-IF(DATE(YEAR(TODAY()),MONTH(G20),DAY(G20))>TODAY(),1,0),"") | Y20: =IF(A20="","",IF(COUNTIF($A$7:$A$26,A20)>1,"✖ PatientID duplicado",IF(AND(ISNUMBER(G20),G20>TODAY()),"✖ Fecha nacimiento futura",IF(AND(M20<>"",COUNTIF(M20,"?*@?*.?*")=0),"▲ Correo básico inválido",IF(COUNTIF(CATALOGOS!$A$7:$A$11,B20)=0,"✖ Estado no permitido",IF(AND(R20="Sí",NOT(ISNUMBER(S20))),"✖ Consentimiento Sí sin fecha",IF(AND(ISNUMBER(H20),OR(H20<CONFIG!$B$36,H20>CONFIG!$B$37)),"▲ Fuera de alcance adulto","✔ Correcto")))))))
H21: =IF(ISNUMBER(G21),YEAR(TODAY())-YEAR(G21)-IF(DATE(YEAR(TODAY()),MONTH(G21),DAY(G21))>TODAY(),1,0),"") | Y21: =IF(A21="","",IF(COUNTIF($A$7:$A$26,A21)>1,"✖ PatientID duplicado",IF(AND(ISNUMBER(G21),G21>TODAY()),"✖ Fecha nacimiento futura",IF(AND(M21<>"",COUNTIF(M21,"?*@?*.?*")=0),"▲ Correo básico inválido",IF(COUNTIF(CATALOGOS!$A$7:$A$11,B21)=0,"✖ Estado no permitido",IF(AND(R21="Sí",NOT(ISNUMBER(S21))),"✖ Consentimiento Sí sin fecha",IF(AND(ISNUMBER(H21),OR(H21<CONFIG!$B$36,H21>CONFIG!$B$37)),"▲ Fuera de alcance adulto","✔ Correcto")))))))
H22: =IF(ISNUMBER(G22),YEAR(TODAY())-YEAR(G22)-IF(DATE(YEAR(TODAY()),MONTH(G22),DAY(G22))>TODAY(),1,0),"") | Y22: =IF(A22="","",IF(COUNTIF($A$7:$A$26,A22)>1,"✖ PatientID duplicado",IF(AND(ISNUMBER(G22),G22>TODAY()),"✖ Fecha nacimiento futura",IF(AND(M22<>"",COUNTIF(M22,"?*@?*.?*")=0),"▲ Correo básico inválido",IF(COUNTIF(CATALOGOS!$A$7:$A$11,B22)=0,"✖ Estado no permitido",IF(AND(R22="Sí",NOT(ISNUMBER(S22))),"✖ Consentimiento Sí sin fecha",IF(AND(ISNUMBER(H22),OR(H22<CONFIG!$B$36,H22>CONFIG!$B$37)),"▲ Fuera de alcance adulto","✔ Correcto")))))))
H23: =IF(ISNUMBER(G23),YEAR(TODAY())-YEAR(G23)-IF(DATE(YEAR(TODAY()),MONTH(G23),DAY(G23))>TODAY(),1,0),"") | Y23: =IF(A23="","",IF(COUNTIF($A$7:$A$26,A23)>1,"✖ PatientID duplicado",IF(AND(ISNUMBER(G23),G23>TODAY()),"✖ Fecha nacimiento futura",IF(AND(M23<>"",COUNTIF(M23,"?*@?*.?*")=0),"▲ Correo básico inválido",IF(COUNTIF(CATALOGOS!$A$7:$A$11,B23)=0,"✖ Estado no permitido",IF(AND(R23="Sí",NOT(ISNUMBER(S23))),"✖ Consentimiento Sí sin fecha",IF(AND(ISNUMBER(H23),OR(H23<CONFIG!$B$36,H23>CONFIG!$B$37)),"▲ Fuera de alcance adulto","✔ Correcto")))))))
... H26: =IF(ISNUMBER(G26),YEAR(TODAY())-YEAR(G26)-IF(DATE(YEAR(TODAY()),MONTH(G26),DAY(G26))>TODAY(),1,0),"") | Y26: =IF(A26="","",IF(COUNTIF($A$7:$A$26,A26)>1,"✖ PatientID duplicado",IF(AND(ISNUMBER(G26),G26>TODAY()),"✖ Fecha nacimiento futura",IF(AND(M26<>"",COUNTIF(M26,"?*@?*.?*")=0),"▲ Correo básico inválido",IF(COUNTIF(CATALOGOS!$A$7:$A$11,B26)=0,"✖ Estado no permitido",IF(AND(R26="Sí",NOT(ISNUMBER(S26))),"✖ Consentimiento Sí sin fecha",IF(AND(ISNUMBER(H26),OR(H26<CONFIG!$B$36,H26>CONFIG!$B$37)),"▲ Fuera de alcance adulto","✔ Correcto")))))))

Sheet EVALUACION
A1: EVALUACIÓN · Maestro de atenciones y trazabilidad
A2: ◀ INICIO | B2: RESUMEN | C2: CONFIG | D2: PRUEBAS
A3: PACIENTE FICTICIO PARA PRUEBA — NO UTILIZAR COMO REFERENCIA CLÍNICA · Una evaluación corresponde a un único PatientID.
A5: T_EVALUACIONES
A6: EvaluationID | B6: PatientID | C6: Fecha | D6: Hora opcional | E6: Tipo evaluación | F6: Modalidad | G6: Motivo consulta | H6: Derivación | I6: Profesional | J6: Estado | K6: Duración aproximada min | L6: Prioridad clínica manual | M6: Fuente información | N6: Confiabilidad relato | O6: Acompañante opcional | P6: Observaciones | Q6: FechaRegistro | R6: FechaModificacion | S6: RangoPaciente | T6: ClavePacienteRango | U6: Control
A7: E-A-01 | B7: P-FICT-A | C7: 46174 | D7: 09:00 | E7: Inicial | F7: Presencial | G7: Evaluación inicial ficticia | H7: Sin derivación | I7: PROF-DEMO | J7: Revisado | K7: 60 | L7: Media | M7: Informado por paciente | N7: Alta | P7: PACIENTE FICTICIO PARA PRUEBA — NO UTILIZAR COMO REFERENCIA CLÍNICA | Q7: 46174 | R7: 46216 | S7: =IF(A7="","",COUNTIF($B$7:B7,B7)) -> 1 | T7: =IF(A7="","",B7&"|"&S7) -> P-FICT-A|1 | U7: =IF(A7="","",IF(COUNTIF($A$7:$A$3006,A7)>1,"✖ EvaluationID duplicado",IF(COUNTIF(PACIENTES!$A$7:$A$1006,B7)=0,"✖ PatientID inexistente",IF(AND(ISNUMBER(C7),C7>TODAY(),CONFIG!$B$31="No"),"✖ Fecha futura",IF(COUNTIF(CATALOGOS!$O$7:$O$12,J7)=0,"✖ Estado no permitido",IF(I7="","▲ Evaluación sin profesional","✔ Correcto")))))) -> ✔ Correcto
A8: E-B-01 | B8: P-FICT-B | C8: 46143 | D8: 10:00 | E8: Inicial | F8: Presencial | G8: Evaluación inicial ficticia | H8: Sin derivación | I8: PROF-DEMO | J8: Revisado | K8: 60 | L8: Media | M8: Informado por paciente | N8: Alta | P8: PACIENTE FICTICIO PARA PRUEBA — NO UTILIZAR COMO REFERENCIA CLÍNICA | Q8: 46143 | R8: 46216 | S8: =IF(A8="","",COUNTIF($B$7:B8,B8)) -> 1 | T8: =IF(A8="","",B8&"|"&S8) -> P-FICT-B|1 | U8: =IF(A8="","",IF(COUNTIF($A$7:$A$3006,A8)>1,"✖ EvaluationID duplicado",IF(COUNTIF(PACIENTES!$A$7:$A$1006,B8)=0,"✖ PatientID inexistente",IF(AND(ISNUMBER(C8),C8>TODAY(),CONFIG!$B$31="No"),"✖ Fecha futura",IF(COUNTIF(CATALOGOS!$O$7:$O$12,J8)=0,"✖ Estado no permitido",IF(I8="","▲ Evaluación sin profesional","✔ Correcto")))))) -> ✔ Correcto
A9: E-B-02 | B9: P-FICT-B | C9: 46204 | D9: 10:30 | E9: Control | F9: Remota | G9: Control longitudinal ficticio | H9: Sin derivación | I9: PROF-DEMO | J9: Completo | K9: 45 | L9: Media | M9: Informado por paciente | N9: Alta | P9: PACIENTE FICTICIO PARA PRUEBA — NO UTILIZAR COMO REFERENCIA CLÍNICA | Q9: 46204 | R9: 46216 | S9: =IF(A9="","",COUNTIF($B$7:B9,B9)) -> 2 | T9: =IF(A9="","",B9&"|"&S9) -> P-FICT-B|2 | U9: =IF(A9="","",IF(COUNTIF($A$7:$A$3006,A9)>1,"✖ EvaluationID duplicado",IF(COUNTIF(PACIENTES!$A$7:$A$1006,B9)=0,"✖ PatientID inexistente",IF(AND(ISNUMBER(C9),C9>TODAY(),CONFIG!$B$31="No"),"✖ Fecha futura",IF(COUNTIF(CATALOGOS!$O$7:$O$12,J9)=0,"✖ Estado no permitido",IF(I9="","▲ Evaluación sin profesional","✔ Correcto")))))) -> ✔ Correcto
A10: E-C-01 | B10: P-FICT-C | C10: 46205 | D10: 11:00 | E10: Inicial | F10: Presencial | G10: Evaluación incompleta ficticia | H10: Sin derivación | I10: PROF-DEMO | J10: Borrador | K10: 30 | L10: Baja | M10: Informado por paciente | N10: No evaluada | P10: PACIENTE FICTICIO PARA PRUEBA — NO UTILIZAR COMO REFERENCIA CLÍNICA | Q10: 46205 | R10: 46216 | S10: =IF(A10="","",COUNTIF($B$7:B10,B10)) -> 1 | T10: =IF(A10="","",B10&"|"&S10) -> P-FICT-C|1 | U10: =IF(A10="","",IF(COUNTIF($A$7:$A$3006,A10)>1,"✖ EvaluationID duplicado",IF(COUNTIF(PACIENTES!$A$7:$A$1006,B10)=0,"✖ PatientID inexistente",IF(AND(ISNUMBER(C10),C10>TODAY(),CONFIG!$B$31="No"),"✖ Fecha futura",IF(COUNTIF(CATALOGOS!$O$7:$O$12,J10)=0,"✖ Estado no permitido",IF(I10="","▲ Evaluación sin profesional","✔ Correcto")))))) -> ✔ Correcto
A11: E-D-01 | B11: P-FICT-D | C11: 46183 | D11: 12:00 | E11: Inicial | F11: Mixta | G11: Caso de advertencias ficticio | H11: Sin derivación | I11: PROF-DEMO | J11: Completo | K11: 60 | L11: Alta | M11: Documentado | N11: Media | P11: PACIENTE FICTICIO PARA PRUEBA — NO UTILIZAR COMO REFERENCIA CLÍNICA | Q11: 46183 | R11: 46216 | S11: =IF(A11="","",COUNTIF($B$7:B11,B11)) -> 1 | T11: =IF(A11="","",B11&"|"&S11) -> P-FICT-D|1 | U11: =IF(A11="","",IF(COUNTIF($A$7:$A$3006,A11)>1,"✖ EvaluationID duplicado",IF(COUNTIF(PACIENTES!$A$7:$A$1006,B11)=0,"✖ PatientID inexistente",IF(AND(ISNUMBER(C11),C11>TODAY(),CONFIG!$B$31="No"),"✖ Fecha futura",IF(COUNTIF(CATALOGOS!$O$7:$O$12,J11)=0,"✖ Estado no permitido",IF(I11="","▲ Evaluación sin profesional","✔ Correcto")))))) -> ✔ Correcto
A12: E-E-01 | B12: P-FICT-E | C12: 46208 | D12: 13:00 | E12: Inicial | F12: Presencial | G12: Caso de integridad ficticio | H12: Sin derivación | I12: PROF-DEMO | J12: Borrador | K12: 30 | L12: Media | M12: Documentado | N12: Media | P12: PACIENTE FICTICIO PARA PRUEBA — NO UTILIZAR COMO REFERENCIA CLÍNICA · Cruces inválidos solo en PRUEBAS. | Q12: 46208 | R12: 46216 | S12: =IF(A12="","",COUNTIF($B$7:B12,B12)) -> 1 | T12: =IF(A12="","",B12&"|"&S12) -> P-FICT-E|1 | U12: =IF(A12="","",IF(COUNTIF($A$7:$A$3006,A12)>1,"✖ EvaluationID duplicado",IF(COUNTIF(PACIENTES!$A$7:$A$1006,B12)=0,"✖ PatientID inexistente",IF(AND(ISNUMBER(C12),C12>TODAY(),CONFIG!$B$31="No"),"✖ Fecha futura",IF(COUNTIF(CATALOGOS!$O$7:$O$12,J12)=0,"✖ Estado no permitido",IF(I12="","▲ Evaluación sin profesional","✔ Correcto")))))) -> ✔ Correcto
S13: =IF(A13="","",COUNTIF($B$7:B13,B13)) | T13: =IF(A13="","",B13&"|"&S13) | U13: =IF(A13="","",IF(COUNTIF($A$7:$A$36,A13)>1,"✖ EvaluationID duplicado",IF(COUNTIF(PACIENTES!$A$7:$A$26,B13)=0,"✖ PatientID inexistente",IF(AND(ISNUMBER(C13),C13>TODAY(),CONFIG!$B$31="No"),"✖ Fecha futura",IF(COUNTIF(CATALOGOS!$O$7:$O$12,J13)=0,"✖ Estado no permitido",IF(I13="","▲ Evaluación sin profesional","✔ Correcto"))))))
S14: =IF(A14="","",COUNTIF($B$7:B14,B14)) | T14: =IF(A14="","",B14&"|"&S14) | U14: =IF(A14="","",IF(COUNTIF($A$7:$A$36,A14)>1,"✖ EvaluationID duplicado",IF(COUNTIF(PACIENTES!$A$7:$A$26,B14)=0,"✖ PatientID inexistente",IF(AND(ISNUMBER(C14),C14>TODAY(),CONFIG!$B$31="No"),"✖ Fecha futura",IF(COUNTIF(CATALOGOS!$O$7:$O$12,J14)=0,"✖ Estado no permitido",IF(I14="","▲ Evaluación sin profesional","✔ Correcto"))))))
S15: =IF(A15="","",COUNTIF($B$7:B15,B15)) | T15: =IF(A15="","",B15&"|"&S15) | U15: =IF(A15="","",IF(COUNTIF($A$7:$A$36,A15)>1,"✖ EvaluationID duplicado",IF(COUNTIF(PACIENTES!$A$7:$A$26,B15)=0,"✖ PatientID inexistente",IF(AND(ISNUMBER(C15),C15>TODAY(),CONFIG!$B$31="No"),"✖ Fecha futura",IF(COUNTIF(CATALOGOS!$O$7:$O$12,J15)=0,"✖ Estado no permitido",IF(I15="","▲ Evaluación sin profesional","✔ Correcto"))))))
S16: =IF(A16="","",COUNTIF($B$7:B16,B16)) | T16: =IF(A16="","",B16&"|"&S16) | U16: =IF(A16="","",IF(COUNTIF($A$7:$A$36,A16)>1,"✖ EvaluationID duplicado",IF(COUNTIF(PACIENTES!$A$7:$A$26,B16)=0,"✖ PatientID inexistente",IF(AND(ISNUMBER(C16),C16>TODAY(),CONFIG!$B$31="No"),"✖ Fecha futura",IF(COUNTIF(CATALOGOS!$O$7:$O$12,J16)=0,"✖ Estado no permitido",IF(I16="","▲ Evaluación sin profesional","✔ Correcto"))))))
S17: =IF(A17="","",COUNTIF($B$7:B17,B17)) | T17: =IF(A17="","",B17&"|"&S17) | U17: =IF(A17="","",IF(COUNTIF($A$7:$A$36,A17)>1,"✖ EvaluationID duplicado",IF(COUNTIF(PACIENTES!$A$7:$A$26,B17)=0,"✖ PatientID inexistente",IF(AND(ISNUMBER(C17),C17>TODAY(),CONFIG!$B$31="No"),"✖ Fecha futura",IF(COUNTIF(CATALOGOS!$O$7:$O$12,J17)=0,"✖ Estado no permitido",IF(I17="","▲ Evaluación sin profesional","✔ Correcto"))))))
S18: =IF(A18="","",COUNTIF($B$7:B18,B18)) | T18: =IF(A18="","",B18&"|"&S18) | U18: =IF(A18="","",IF(COUNTIF($A$7:$A$36,A18)>1,"✖ EvaluationID duplicado",IF(COUNTIF(PACIENTES!$A$7:$A$26,B18)=0,"✖ PatientID inexistente",IF(AND(ISNUMBER(C18),C18>TODAY(),CONFIG!$B$31="No"),"✖ Fecha futura",IF(COUNTIF(CATALOGOS!$O$7:$O$12,J18)=0,"✖ Estado no permitido",IF(I18="","▲ Evaluación sin profesional","✔ Correcto"))))))
S19: =IF(A19="","",COUNTIF($B$7:B19,B19)) | T19: =IF(A19="","",B19&"|"&S19) | U19: =IF(A19="","",IF(COUNTIF($A$7:$A$36,A19)>1,"✖ EvaluationID duplicado",IF(COUNTIF(PACIENTES!$A$7:$A$26,B19)=0,"✖ PatientID inexistente",IF(AND(ISNUMBER(C19),C19>TODAY(),CONFIG!$B$31="No"),"✖ Fecha futura",IF(COUNTIF(CATALOGOS!$O$7:$O$12,J19)=0,"✖ Estado no permitido",IF(I19="","▲ Evaluación sin profesional","✔ Correcto"))))))
S20: =IF(A20="","",COUNTIF($B$7:B20,B20)) | T20: =IF(A20="","",B20&"|"&S20) | U20: =IF(A20="","",IF(COUNTIF($A$7:$A$36,A20)>1,"✖ EvaluationID duplicado",IF(COUNTIF(PACIENTES!$A$7:$A$26,B20)=0,"✖ PatientID inexistente",IF(AND(ISNUMBER(C20),C20>TODAY(),CONFIG!$B$31="No"),"✖ Fecha futura",IF(COUNTIF(CATALOGOS!$O$7:$O$12,J20)=0,"✖ Estado no permitido",IF(I20="","▲ Evaluación sin profesional","✔ Correcto"))))))
S21: =IF(A21="","",COUNTIF($B$7:B21,B21)) | T21: =IF(A21="","",B21&"|"&S21) | U21: =IF(A21="","",IF(COUNTIF($A$7:$A$36,A21)>1,"✖ EvaluationID duplicado",IF(COUNTIF(PACIENTES!$A$7:$A$26,B21)=0,"✖ PatientID inexistente",IF(AND(ISNUMBER(C21),C21>TODAY(),CONFIG!$B$31="No"),"✖ Fecha futura",IF(COUNTIF(CATALOGOS!$O$7:$O$12,J21)=0,"✖ Estado no permitido",IF(I21="","▲ Evaluación sin profesional","✔ Correcto"))))))
S22: =IF(A22="","",COUNTIF($B$7:B22,B22)) | T22: =IF(A22="","",B22&"|"&S22) | U22: =IF(A22="","",IF(COUNTIF($A$7:$A$36,A22)>1,"✖ EvaluationID duplicado",IF(COUNTIF(PACIENTES!$A$7:$A$26,B22)=0,"✖ PatientID inexistente",IF(AND(ISNUMBER(C22),C22>TODAY(),CONFIG!$B$31="No"),"✖ Fecha futura",IF(COUNTIF(CATALOGOS!$O$7:$O$12,J22)=0,"✖ Estado no permitido",IF(I22="","▲ Evaluación sin profesional","✔ Correcto"))))))
S23: =IF(A23="","",COUNTIF($B$7:B23,B23)) | T23: =IF(A23="","",B23&"|"&S23) | U23: =IF(A23="","",IF(COUNTIF($A$7:$A$36,A23)>1,"✖ EvaluationID duplicado",IF(COUNTIF(PACIENTES!$A$7:$A$26,B23)=0,"✖ PatientID inexistente",IF(AND(ISNUMBER(C23),C23>TODAY(),CONFIG!$B$31="No"),"✖ Fecha futura",IF(COUNTIF(CATALOGOS!$O$7:$O$12,J23)=0,"✖ Estado no permitido",IF(I23="","▲ Evaluación sin profesional","✔ Correcto"))))))
S24: =IF(A24="","",COUNTIF($B$7:B24,B24)) | T24: =IF(A24="","",B24&"|"&S24) | U24: =IF(A24="","",IF(COUNTIF($A$7:$A$36,A24)>1,"✖ EvaluationID duplicado",IF(COUNTIF(PACIENTES!$A$7:$A$26,B24)=0,"✖ PatientID inexistente",IF(AND(ISNUMBER(C24),C24>TODAY(),CONFIG!$B$31="No"),"✖ Fecha futura",IF(COUNTIF(CATALOGOS!$O$7:$O$12,J24)=0,"✖ Estado no permitido",IF(I24="","▲ Evaluación sin profesional","✔ Correcto"))))))
... S36: =IF(A36="","",COUNTIF($B$7:B36,B36)) | T36: =IF(A36="","",B36&"|"&S36) | U36: =IF(A36="","",IF(COUNTIF($A$7:$A$36,A36)>1,"✖ EvaluationID duplicado",IF(COUNTIF(PACIENTES!$A$7:$A$26,B36)=0,"✖ PatientID inexistente",IF(AND(ISNUMBER(C36),C36>TODAY(),CONFIG!$B$31="No"),"✖ Fecha futura",IF(COUNTIF(CATALOGOS!$O$7:$O$12,J36)=0,"✖ Estado no permitido",IF(I36="","▲ Evaluación sin profesional","✔ Correcto"))))))

Sheet ANTECEDENTES
A1: ANTECEDENTES · Registros múltiples por evaluación
A2: ◀ INICIO | B2: RESUMEN | C2: CONFIG | D2: PRUEBAS
A3: PACIENTE FICTICIO PARA PRUEBA — NO UTILIZAR COMO REFERENCIA CLÍNICA · No convertir automáticamente un antecedente en diagnóstico.
A5: T_ANTECEDENTES
A6: EvaluationID | B6: PatientID | C6: Categoría | D6: Antecedente | E6: Estado | F6: Fecha inicio | G6: Fecha término | H6: Profesional diagnóstico opcional | I6: Tratamiento relacionado | J6: Relevancia nutricional manual | K6: FuenteDato | L6: FechaRegistro | M6: FechaModificacion | N6: Profesional | O6: Observaciones | P6: Control
A7: E-A-01 | B7: P-FICT-A | C7: Personales | D7: Antecedente ficticio A | E7: Activo | F7: 45292 | J7: Relevancia manual | K7: Documentado | L7: 46174 | M7: 46216 | N7: PROF-DEMO | O7: PACIENTE FICTICIO PARA PRUEBA — NO UTILIZAR COMO REFERENCIA CLÍNICA | P7: =IF(A7="","",IF(COUNTIF(EVALUACION!$A$7:$A$3006,A7)=0,"✖ EvaluationID inexistente",IF(COUNTIFS(EVALUACION!$A$7:$A$3006,A7,EVALUACION!$B$7:$B$3006,B7)=0,"✖ EvaluationID de otro paciente",IF(AND(ISNUMBER(F7),ISNUMBER(G7),G7<F7),"✖ Fecha término anterior","✔ Correcto")))) -> ✔ Correcto
A8: E-B-01 | B8: P-FICT-B | C8: Familiares | D8: Antecedente familiar ficticio | E8: Informado | J8: Relevancia manual | K8: Informado por paciente | L8: 46143 | M8: 46216 | N8: PROF-DEMO | O8: PACIENTE FICTICIO PARA PRUEBA — NO UTILIZAR COMO REFERENCIA CLÍNICA | P8: =IF(A8="","",IF(COUNTIF(EVALUACION!$A$7:$A$3006,A8)=0,"✖ EvaluationID inexistente",IF(COUNTIFS(EVALUACION!$A$7:$A$3006,A8,EVALUACION!$B$7:$B$3006,B8)=0,"✖ EvaluationID de otro paciente",IF(AND(ISNUMBER(F8),ISNUMBER(G8),G8<F8),"✖ Fecha término anterior","✔ Correcto")))) -> ✔ Correcto
A9: E-D-01 | B9: P-FICT-D | C9: Alergias | D9: Alergia ficticia no especificada | E9: Pendiente | J9: Revisar | K9: Informado por paciente | L9: 46183 | M9: 46216 | N9: PROF-DEMO | O9: PACIENTE FICTICIO PARA PRUEBA — NO UTILIZAR COMO REFERENCIA CLÍNICA | P9: =IF(A9="","",IF(COUNTIF(EVALUACION!$A$7:$A$3006,A9)=0,"✖ EvaluationID inexistente",IF(COUNTIFS(EVALUACION!$A$7:$A$3006,A9,EVALUACION!$B$7:$B$3006,B9)=0,"✖ EvaluationID de otro paciente",IF(AND(ISNUMBER(F9),ISNUMBER(G9),G9<F9),"✖ Fecha término anterior","✔ Correcto")))) -> ✔ Correcto
P10: =IF(A10="","",IF(COUNTIF(EVALUACION!$A$7:$A$36,A10)=0,"✖ EvaluationID inexistente",IF(COUNTIFS(EVALUACION!$A$7:$A$36,A10,EVALUACION!$B$7:$B$36,B10)=0,"✖ EvaluationID de otro paciente",IF(AND(ISNUMBER(F10),ISNUMBER(G10),G10<F10),"✖ Fecha término anterior","✔ Correcto"))))
P11: =IF(A11="","",IF(COUNTIF(EVALUACION!$A$7:$A$36,A11)=0,"✖ EvaluationID inexistente",IF(COUNTIFS(EVALUACION!$A$7:$A$36,A11,EVALUACION!$B$7:$B$36,B11)=0,"✖ EvaluationID de otro paciente",IF(AND(ISNUMBER(F11),ISNUMBER(G11),G11<F11),"✖ Fecha término anterior","✔ Correcto"))))
P12: =IF(A12="","",IF(COUNTIF(EVALUACION!$A$7:$A$36,A12)=0,"✖ EvaluationID inexistente",IF(COUNTIFS(EVALUACION!$A$7:$A$36,A12,EVALUACION!$B$7:$B$36,B12)=0,"✖ EvaluationID de otro paciente",IF(AND(ISNUMBER(F12),ISNUMBER(G12),G12<F12),"✖ Fecha término anterior","✔ Correcto"))))
P13: =IF(A13="","",IF(COUNTIF(EVALUACION!$A$7:$A$36,A13)=0,"✖ EvaluationID inexistente",IF(COUNTIFS(EVALUACION!$A$7:$A$36,A13,EVALUACION!$B$7:$B$36,B13)=0,"✖ EvaluationID de otro paciente",IF(AND(ISNUMBER(F13),ISNUMBER(G13),G13<F13),"✖ Fecha término anterior","✔ Correcto"))))
P14: =IF(A14="","",IF(COUNTIF(EVALUACION!$A$7:$A$36,A14)=0,"✖ EvaluationID inexistente",IF(COUNTIFS(EVALUACION!$A$7:$A$36,A14,EVALUACION!$B$7:$B$36,B14)=0,"✖ EvaluationID de otro paciente",IF(AND(ISNUMBER(F14),ISNUMBER(G14),G14<F14),"✖ Fecha término anterior","✔ Correcto"))))
P15: =IF(A15="","",IF(COUNTIF(EVALUACION!$A$7:$A$36,A15)=0,"✖ EvaluationID inexistente",IF(COUNTIFS(EVALUACION!$A$7:$A$36,A15,EVALUACION!$B$7:$B$36,B15)=0,"✖ EvaluationID de otro paciente",IF(AND(ISNUMBER(F15),ISNUMBER(G15),G15<F15),"✖ Fecha término anterior","✔ Correcto"))))
P16: =IF(A16="","",IF(COUNTIF(EVALUACION!$A$7:$A$36,A16)=0,"✖ EvaluationID inexistente",IF(COUNTIFS(EVALUACION!$A$7:$A$36,A16,EVALUACION!$B$7:$B$36,B16)=0,"✖ EvaluationID de otro paciente",IF(AND(ISNUMBER(F16),ISNUMBER(G16),G16<F16),"✖ Fecha término anterior","✔ Correcto"))))
P17: =IF(A17="","",IF(COUNTIF(EVALUACION!$A$7:$A$36,A17)=0,"✖ EvaluationID inexistente",IF(COUNTIFS(EVALUACION!$A$7:$A$36,A17,EVALUACION!$B$7:$B$36,B17)=0,"✖ EvaluationID de otro paciente",IF(AND(ISNUMBER(F17),ISNUMBER(G17),G17<F17),"✖ Fecha término anterior","✔ Correcto"))))
P18: =IF(A18="","",IF(COUNTIF(EVALUACION!$A$7:$A$36,A18)=0,"✖ EvaluationID inexistente",IF(COUNTIFS(EVALUACION!$A$7:$A$36,A18,EVALUACION!$B$7:$B$36,B18)=0,"✖ EvaluationID de otro paciente",IF(AND(ISNUMBER(F18),ISNUMBER(G18),G18<F18),"✖ Fecha término anterior","✔ Correcto"))))
P19: =IF(A19="","",IF(COUNTIF(EVALUACION!$A$7:$A$36,A19)=0,"✖ EvaluationID inexistente",IF(COUNTIFS(EVALUACION!$A$7:$A$36,A19,EVALUACION!$B$7:$B$36,B19)=0,"✖ EvaluationID de otro paciente",IF(AND(ISNUMBER(F19),ISNUMBER(G19),G19<F19),"✖ Fecha término anterior","✔ Correcto"))))
P20: =IF(A20="","",IF(COUNTIF(EVALUACION!$A$7:$A$36,A20)=0,"✖ EvaluationID inexistente",IF(COUNTIFS(EVALUACION!$A$7:$A$36,A20,EVALUACION!$B$7:$B$36,B20)=0,"✖ EvaluationID de otro paciente",IF(AND(ISNUMBER(F20),ISNUMBER(G20),G20<F20),"✖ Fecha término anterior","✔ Correcto"))))
P21: =IF(A21="","",IF(COUNTIF(EVALUACION!$A$7:$A$36,A21)=0,"✖ EvaluationID inexistente",IF(COUNTIFS(EVALUACION!$A$7:$A$36,A21,EVALUACION!$B$7:$B$36,B21)=0,"✖ EvaluationID de otro paciente",IF(AND(ISNUMBER(F21),ISNUMBER(G21),G21<F21),"✖ Fecha término anterior","✔ Correcto"))))
... P46: =IF(A46="","",IF(COUNTIF(EVALUACION!$A$7:$A$36,A46)=0,"✖ EvaluationID inexistente",IF(COUNTIFS(EVALUACION!$A$7:$A$36,A46,EVALUACION!$B$7:$B$36,B46)=0,"✖ EvaluationID de otro paciente",IF(AND(ISNUMBER(F46),ISNUMBER(G46),G46<F46),"✖ Fecha término anterior","✔ Correcto"))))

Sheet ANTROPOMETRIA
A1: ANTROPOMETRÍA · Mediciones, condiciones y cálculos auditables
A2: ◀ INICIO | B2: RESUMEN | C2: CONFIG | D2: PRUEBAS
A3: PACIENTE FICTICIO PARA PRUEBA — NO UTILIZAR COMO REFERENCIA CLÍNICA · IMC y composición corporal no constituyen evaluación completa.
A5: T_ANTROPOMETRIA
A6: EvaluationID | B6: PatientID | C6: Fecha | D6: Peso kg | E6: Estatura cm | F6: IMC | G6: Peso habitual kg | H6: Peso mínimo reciente kg | I6: Peso máximo reciente kg | J6: Cambio peso kg | K6: Cambio peso % | L6: Periodo cambio | M6: Intencionalidad cambio | N6: Cintura cm | O6: Cadera cm | P6: Brazo cm | Q6: Pantorrilla cm | R6: % grasa | S6: Masa grasa kg | T6: Masa libre grasa kg | U6: Fuente % grasa | V6: Cintura/estatura | W6: Cintura/cadera | X6: Calidad medición | Y6: Ayuno | Z6: Horario | AA6: Ropa | AB6: Retención líquidos | AC6: Edema | AD6: Dispositivo | AE6: Condiciones medición | AF6: Instrumento | AG6: Profesional | AH6: FuenteDato | AI6: Observaciones | AJ6: RangoPaciente | AK6: ClavePacienteRango | AL6: Control
A7: E-A-01 | B7: P-FICT-A | C7: 46174 | D7: 70 | E7: 165 | F7: =IF(AND(ISNUMBER(D7),ISNUMBER(E7),D7>0,E7>0),D7/((E7/100)^2),"") -> 25.711662 | G7: 72 | H7: 68 | I7: 75 | J7: =IF(AND(ISNUMBER(D7),ISNUMBER(G7)),D7-G7,"") -> -2 | K7: =IF(AND(ISNUMBER(D7),ISNUMBER(G7),G7<>0),(D7-G7)/G7,"") -> -0.027777778 | L7: 3 meses | M7: Intencional | N7: 82 | O7: 98 | P7: 29 | Q7: 36 | R7: 30 | S7: =IF(CONFIG!$B$28="No","",IF(AND(ISNUMBER(D7),ISNUMBER(R7),R7>=0,R7<=100,U7<>""),D7*R7/100,"")) -> 21 | T7: =IF(CONFIG!$B$28="No","",IF(AND(ISNUMBER(D7),ISNUMBER(S7)),D7-S7,"")) -> 49 | U7: BIA | V7: =IF(AND(ISNUMBER(N7),ISNUMBER(E7),E7>0),N7/E7,"") -> 0.4969697 | W7: =IF(AND(ISNUMBER(N7),ISNUMBER(O7),O7>0),N7/O7,"") -> 0.83673469 | X7: Adecuada | Y7: Sí | Z7: 09:00 | AA7: Ligera | AB7: No | AC7: No | AD7: BIA | AE7: Condición ficticia | AF7: Equipo ficticio | AG7: PROF-DEMO | AH7: Medido | AI7: PACIENTE FICTICIO PARA PRUEBA — NO UTILIZAR COMO REFERENCIA CLÍNICA | AJ7: =IF(A7="","",COUNTIF($B$7:B7,B7)) -> 1 | AK7: =IF(A7="","",B7&"|"&AJ7) -> P-FICT-A|1 | AL7: =IF(A7="","",IF(COUNTIFS(EVALUACION!$A$7:$A$3006,A7,EVALUACION!$B$7:$B$3006,B7)=0,"✖ Evaluación/paciente inconsistente",IF(OR(D7<0,E7<0,N7<0,O7<0),"✖ Valor negativo",IF(OR(AND(ISNUMBER(D7),OR(D7<CONFIG!$B$38,D7>CONFIG!$B$39)),AND(ISNUMBER(E7),OR(E7<CONFIG!$B$40,E7>CONFIG!$B$41))),"▲ Fuera de límite operativo",IF(AND(ISNUMBER(R7),OR(R7<0,R7>100)),"✖ % grasa fuera de 0–100",IF(AND(ISNUMBER(R7),U7=""),"▲ Falta fuente de % grasa",IF(E7="","▲ Estatura faltante",IF(AC7="Sí","▲ Edema registrado","✔ Correcto")))))))) -> ✔ Correcto
A8: E-B-01 | B8: P-FICT-B | C8: 46143 | D8: 90 | E8: 180 | F8: =IF(AND(ISNUMBER(D8),ISNUMBER(E8),D8>0,E8>0),D8/((E8/100)^2),"") -> 27.777778 | G8: 92 | H8: 88 | I8: 95 | J8: =IF(AND(ISNUMBER(D8),ISNUMBER(G8)),D8-G8,"") -> -2 | K8: =IF(AND(ISNUMBER(D8),ISNUMBER(G8),G8<>0),(D8-G8)/G8,"") -> -0.02173913 | L8: 2 meses | M8: No intencional | N8: 100 | O8: 105 | P8: 33 | Q8: 40 | R8: 25 | S8: =IF(CONFIG!$B$28="No","",IF(AND(ISNUMBER(D8),ISNUMBER(R8),R8>=0,R8<=100,U8<>""),D8*R8/100,"")) -> 22.5 | T8: =IF(CONFIG!$B$28="No","",IF(AND(ISNUMBER(D8),ISNUMBER(S8)),D8-S8,"")) -> 67.5 | U8: BIA | V8: =IF(AND(ISNUMBER(N8),ISNUMBER(E8),E8>0),N8/E8,"") -> 0.55555556 | W8: =IF(AND(ISNUMBER(N8),ISNUMBER(O8),O8>0),N8/O8,"") -> 0.95238095 | X8: Adecuada | Y8: Sí | Z8: 10:00 | AA8: Ligera | AB8: No | AC8: No | AD8: BIA | AE8: Condición ficticia | AF8: Equipo ficticio | AG8: PROF-DEMO | AH8: Medido | AI8: PACIENTE FICTICIO PARA PRUEBA — NO UTILIZAR COMO REFERENCIA CLÍNICA | AJ8: =IF(A8="","",COUNTIF($B$7:B8,B8)) -> 1 | AK8: =IF(A8="","",B8&"|"&AJ8) -> P-FICT-B|1 | AL8: =IF(A8="","",IF(COUNTIFS(EVALUACION!$A$7:$A$3006,A8,EVALUACION!$B$7:$B$3006,B8)=0,"✖ Evaluación/paciente inconsistente",IF(OR(D8<0,E8<0,N8<0,O8<0),"✖ Valor negativo",IF(OR(AND(ISNUMBER(D8),OR(D8<CONFIG!$B$38,D8>CONFIG!$B$39)),AND(ISNUMBER(E8),OR(E8<CONFIG!$B$40,E8>CONFIG!$B$41))),"▲ Fuera de límite operativo",IF(AND(ISNUMBER(R8),OR(R8<0,R8>100)),"✖ % grasa fuera de 0–100",IF(AND(ISNUMBER(R8),U8=""),"▲ Falta fuente de % grasa",IF(E8="","▲ Estatura faltante",IF(AC8="Sí","▲ Edema registrado","✔ Correcto")))))))) -> ✔ Correcto
A9: E-B-02 | B9: P-FICT-B | C9: 46204 | D9: 87 | E9: 180 | F9: =IF(AND(ISNUMBER(D9),ISNUMBER(E9),D9>0,E9>0),D9/((E9/100)^2),"") -> 26.851852 | G9: 92 | H9: 87 | I9: 95 | J9: =IF(AND(ISNUMBER(D9),ISNUMBER(G9)),D9-G9,"") -> -5 | K9: =IF(AND(ISNUMBER(D9),ISNUMBER(G9),G9<>0),(D9-G9)/G9,"") -> -0.054347826 | L9: 2 meses | M9: Acordado | N9: 96 | O9: 103 | P9: 32 | Q9: 39 | R9: 24 | S9: =IF(CONFIG!$B$28="No","",IF(AND(ISNUMBER(D9),ISNUMBER(R9),R9>=0,R9<=100,U9<>""),D9*R9/100,"")) -> 20.88 | T9: =IF(CONFIG!$B$28="No","",IF(AND(ISNUMBER(D9),ISNUMBER(S9)),D9-S9,"")) -> 66.12 | U9: BIA | V9: =IF(AND(ISNUMBER(N9),ISNUMBER(E9),E9>0),N9/E9,"") -> 0.53333333 | W9: =IF(AND(ISNUMBER(N9),ISNUMBER(O9),O9>0),N9/O9,"") -> 0.93203883 | X9: Adecuada | Y9: Sí | Z9: 10:30 | AA9: Ligera | AB9: No | AC9: No | AD9: BIA | AE9: Condición ficticia | AF9: Equipo ficticio | AG9: PROF-DEMO | AH9: Medido | AI9: PACIENTE FICTICIO PARA PRUEBA — NO UTILIZAR COMO REFERENCIA CLÍNICA | AJ9: =IF(A9="","",COUNTIF($B$7:B9,B9)) -> 2 | AK9: =IF(A9="","",B9&"|"&AJ9) -> P-FICT-B|2 | AL9: =IF(A9="","",IF(COUNTIFS(EVALUACION!$A$7:$A$3006,A9,EVALUACION!$B$7:$B$3006,B9)=0,"✖ Evaluación/paciente inconsistente",IF(OR(D9<0,E9<0,N9<0,O9<0),"✖ Valor negativo",IF(OR(AND(ISNUMBER(D9),OR(D9<CONFIG!$B$38,D9>CONFIG!$B$39)),AND(ISNUMBER(E9),OR(E9<CONFIG!$B$40,E9>CONFIG!$B$41))),"▲ Fuera de límite operativo",IF(AND(ISNUMBER(R9),OR(R9<0,R9>100)),"✖ % grasa fuera de 0–100",IF(AND(ISNUMBER(R9),U9=""),"▲ Falta fuente de % grasa",IF(E9="","▲ Estatura faltante",IF(AC9="Sí","▲ Edema registrado","✔ Correcto")))))))) -> ✔ Correcto
A10: E-C-01 | B10: P-FICT-C | C10: 46205 | D10: 65 | F10: =IF(AND(ISNUMBER(D10),ISNUMBER(E10),D10>0,E10>0),D10/((E10/100)^2),"") | G10: 65 | H10: 64 | I10: 66 | J10: =IF(AND(ISNUMBER(D10),ISNUMBER(G10)),D10-G10,"") -> 0 | K10: =IF(AND(ISNUMBER(D10),ISNUMBER(G10),G10<>0),(D10-G10)/G10,"") -> 0 | M10: No informado | S10: =IF(CONFIG!$B$28="No","",IF(AND(ISNUMBER(D10),ISNUMBER(R10),R10>=0,R10<=100,U10<>""),D10*R10/100,"")) | T10: =IF(CONFIG!$B$28="No","",IF(AND(ISNUMBER(D10),ISNUMBER(S10)),D10-S10,"")) | V10: =IF(AND(ISNUMBER(N10),ISNUMBER(E10),E10>0),N10/E10,"") | W10: =IF(AND(ISNUMBER(N10),ISNUMBER(O10),O10>0),N10/O10,"") | X10: Pendiente | Y10: No informado | Z10: 11:00 | AB10: No informado | AC10: No informado | AE10: Medición incompleta ficticia | AG10: PROF-DEMO | AH10: Informado por paciente | AI10: PACIENTE FICTICIO PARA PRUEBA — NO UTILIZAR COMO REFERENCIA CLÍNICA | AJ10: =IF(A10="","",COUNTIF($B$7:B10,B10)) -> 1 | AK10: =IF(A10="","",B10&"|"&AJ10) -> P-FICT-C|1 | AL10: =IF(A10="","",IF(COUNTIFS(EVALUACION!$A$7:$A$3006,A10,EVALUACION!$B$7:$B$3006,B10)=0,"✖ Evaluación/paciente inconsistente",IF(OR(D10<0,E10<0,N10<0,O10<0),"✖ Valor negativo",IF(OR(AND(ISNUMBER(D10),OR(D10<CONFIG!$B$38,D10>CONFIG!$B$39)),AND(ISNUMBER(E10),OR(E10<CONFIG!$B$40,E10>CONFIG!$B$41))),"▲ Fuera de límite operativo",IF(AND(ISNUMBER(R10),OR(R10<0,R10>100)),"✖ % grasa fuera de 0–100",IF(AND(ISNUMBER(R10),U10=""),"▲ Falta fuente de % grasa",IF(E10="","▲ Estatura faltante",IF(AC10="Sí","▲ Edema registrado","✔ Correcto")))))))) -> ▲ Estatura faltante
A11: E-D-01 | B11: P-FICT-D | C11: 46183 | D11: 78 | E11: 168 | F11: =IF(AND(ISNUMBER(D11),ISNUMBER(E11),D11>0,E11>0),D11/((E11/100)^2),"") -> 27.636054 | G11: 80 | H11: 76 | I11: 83 | J11: =IF(AND(ISNUMBER(D11),ISNUMBER(G11)),D11-G11,"") -> -2 | K11: =IF(AND(ISNUMBER(D11),ISNUMBER(G11),G11<>0),(D11-G11)/G11,"") -> -0.025 | L11: 1 mes | M11: No informado | N11: 94 | O11: 104 | P11: 31 | Q11: 38 | S11: =IF(CONFIG!$B$28="No","",IF(AND(ISNUMBER(D11),ISNUMBER(R11),R11>=0,R11<=100,U11<>""),D11*R11/100,"")) | T11: =IF(CONFIG!$B$28="No","",IF(AND(ISNUMBER(D11),ISNUMBER(S11)),D11-S11,"")) | V11: =IF(AND(ISNUMBER(N11),ISNUMBER(E11),E11>0),N11/E11,"") -> 0.55952381 | W11: =IF(AND(ISNUMBER(N11),ISNUMBER(O11),O11>0),N11/O11,"") -> 0.90384615 | X11: Adecuada | Y11: No informado | Z11: 12:00 | AA11: Ligera | AB11: Sí | AC11: Sí | AD11: Balanza | AE11: Condición ficticia con edema | AF11: Equipo ficticio | AG11: PROF-DEMO | AH11: Medido | AI11: PACIENTE FICTICIO PARA PRUEBA — NO UTILIZAR COMO REFERENCIA CLÍNICA | AJ11: =IF(A11="","",COUNTIF($B$7:B11,B11)) -> 1 | AK11: =IF(A11="","",B11&"|"&AJ11) -> P-FICT-D|1 | AL11: =IF(A11="","",IF(COUNTIFS(EVALUACION!$A$7:$A$3006,A11,EVALUACION!$B$7:$B$3006,B11)=0,"✖ Evaluación/paciente inconsistente",IF(OR(D11<0,E11<0,N11<0,O11<0),"✖ Valor negativo",IF(OR(AND(ISNUMBER(D11),OR(D11<CONFIG!$B$38,D11>CONFIG!$B$39)),AND(ISNUMBER(E11),OR(E11<CONFIG!$B$40,E11>CONFIG!$B$41))),"▲ Fuera de límite operativo",IF(AND(ISNUMBER(R11),OR(R11<0,R11>100)),"✖ % grasa fuera de 0–100",IF(AND(ISNUMBER(R11),U11=""),"▲ Falta fuente de % grasa",IF(E11="","▲ Estatura faltante",IF(AC11="Sí","▲ Edema registrado","✔ Correcto")))))))) -> ▲ Edema registrado
A12: E-E-01 | B12: P-FICT-E | C12: 46208 | D12: 82 | E12: 175 | F12: =IF(AND(ISNUMBER(D12),ISNUMBER(E12),D12>0,E12>0),D12/((E12/100)^2),"") -> 26.77551 | G12: 83 | H12: 80 | I12: 85 | J12: =IF(AND(ISNUMBER(D12),ISNUMBER(G12)),D12-G12,"") -> -1 | K12: =IF(AND(ISNUMBER(D12),ISNUMBER(G12),G12<>0),(D12-G12)/G12,"") -> -0.012048193 | L12: 1 mes | M12: No informado | N12: 90 | O12: 100 | P12: 32 | Q12: 39 | R12: 22 | S12: =IF(CONFIG!$B$28="No","",IF(AND(ISNUMBER(D12),ISNUMBER(R12),R12>=0,R12<=100,U12<>""),D12*R12/100,"")) -> 18.04 | T12: =IF(CONFIG!$B$28="No","",IF(AND(ISNUMBER(D12),ISNUMBER(S12)),D12-S12,"")) -> 63.96 | U12: Plicometría | V12: =IF(AND(ISNUMBER(N12),ISNUMBER(E12),E12>0),N12/E12,"") -> 0.51428571 | W12: =IF(AND(ISNUMBER(N12),ISNUMBER(O12),O12>0),N12/O12,"") -> 0.9 | X12: Adecuada | Y12: No | Z12: 13:00 | AA12: Ligera | AB12: No | AC12: No | AD12: Plicómetro | AE12: Condición ficticia | AF12: Equipo ficticio | AG12: PROF-DEMO | AH12: Medido | AI12: PACIENTE FICTICIO PARA PRUEBA — NO UTILIZAR COMO REFERENCIA CLÍNICA | AJ12: =IF(A12="","",COUNTIF($B$7:B12,B12)) -> 1 | AK12: =IF(A12="","",B12&"|"&AJ12) -> P-FICT-E|1 | AL12: =IF(A12="","",IF(COUNTIFS(EVALUACION!$A$7:$A$3006,A12,EVALUACION!$B$7:$B$3006,B12)=0,"✖ Evaluación/paciente inconsistente",IF(OR(D12<0,E12<0,N12<0,O12<0),"✖ Valor negativo",IF(OR(AND(ISNUMBER(D12),OR(D12<CONFIG!$B$38,D12>CONFIG!$B$39)),AND(ISNUMBER(E12),OR(E12<CONFIG!$B$40,E12>CONFIG!$B$41))),"▲ Fuera de límite operativo",IF(AND(ISNUMBER(R12),OR(R12<0,R12>100)),"✖ % grasa fuera de 0–100",IF(AND(ISNUMBER(R12),U12=""),"▲ Falta fuente de % grasa",IF(E12="","▲ Estatura faltante",IF(AC12="Sí","▲ Edema registrado","✔ Correcto")))))))) -> ✔ Correcto
F13: =IF(AND(ISNUMBER(D13),ISNUMBER(E13),D13>0,E13>0),D13/((E13/100)^2),"") | J13: =IF(AND(ISNUMBER(D13),ISNUMBER(G13)),D13-G13,"") | K13: =IF(AND(ISNUMBER(D13),ISNUMBER(G13),G13<>0),(D13-G13)/G13,"") | S13: =IF(CONFIG!$B$28="No","",IF(AND(ISNUMBER(D13),ISNUMBER(R13),R13>=0,R13<=100,U13<>""),D13*R13/100,"")) | T13: =IF(CONFIG!$B$28="No","",IF(AND(ISNUMBER(D13),ISNUMBER(S13)),D13-S13,"")) | V13: =IF(AND(ISNUMBER(N13),ISNUMBER(E13),E13>0),N13/E13,"") | W13: =IF(AND(ISNUMBER(N13),ISNUMBER(O13),O13>0),N13/O13,"") | AJ13: =IF(A13="","",COUNTIF($B$7:B13,B13)) | AK13: =IF(A13="","",B13&"|"&AJ13) | AL13: =IF(A13="","",IF(COUNTIFS(EVALUACION!$A$7:$A$36,A13,EVALUACION!$B$7:$B$36,B13)=0,"✖ Evaluación/paciente inconsistente",IF(OR(D13<0,E13<0,N13<0,O13<0),"✖ Valor negativo",IF(OR(AND(ISNUMBER(D13),OR(D13<CONFIG!$B$38,D13>CONFIG!$B$39)),AND(ISNUMBER(E13),OR(E13<CONFIG!$B$40,E13>CONFIG!$B$41))),"▲ Fuera de límite operativo",IF(AND(ISNUMBER(R13),OR(R13<0,R13>100)),"✖ % grasa fuera de 0–100",IF(AND(ISNUMBER(R13),U13=""),"▲ Falta fuente de % grasa",IF(E13="","▲ Estatura faltante",IF(AC13="Sí","▲ Edema registrado","✔ Correcto"))))))))
F14: =IF(AND(ISNUMBER(D14),ISNUMBER(E14),D14>0,E14>0),D14/((E14/100)^2),"") | J14: =IF(AND(ISNUMBER(D14),ISNUMBER(G14)),D14-G14,"") | K14: =IF(AND(ISNUMBER(D14),ISNUMBER(G14),G14<>0),(D14-G14)/G14,"") | S14: =IF(CONFIG!$B$28="No","",IF(AND(ISNUMBER(D14),ISNUMBER(R14),R14>=0,R14<=100,U14<>""),D14*R14/100,"")) | T14: =IF(CONFIG!$B$28="No","",IF(AND(ISNUMBER(D14),ISNUMBER(S14)),D14-S14,"")) | V14: =IF(AND(ISNUMBER(N14),ISNUMBER(E14),E14>0),N14/E14,"") | W14: =IF(AND(ISNUMBER(N14),ISNUMBER(O14),O14>0),N14/O14,"") | AJ14: =IF(A14="","",COUNTIF($B$7:B14,B14)) | AK14: =IF(A14="","",B14&"|"&AJ14) | AL14: =IF(A14="","",IF(COUNTIFS(EVALUACION!$A$7:$A$36,A14,EVALUACION!$B$7:$B$36,B14)=0,"✖ Evaluación/paciente inconsistente",IF(OR(D14<0,E14<0,N14<0,O14<0),"✖ Valor negativo",IF(OR(AND(ISNUMBER(D14),OR(D14<CONFIG!$B$38,D14>CONFIG!$B$39)),AND(ISNUMBER(E14),OR(E14<CONFIG!$B$40,E14>CONFIG!$B$41))),"▲ Fuera de límite operativo",IF(AND(ISNUMBER(R14),OR(R14<0,R14>100)),"✖ % grasa fuera de 0–100",IF(AND(ISNUMBER(R14),U14=""),"▲ Falta fuente de % grasa",IF(E14="","▲ Estatura faltante",IF(AC14="Sí","▲ Edema registrado","✔ Correcto"))))))))
F15: =IF(AND(ISNUMBER(D15),ISNUMBER(E15),D15>0,E15>0),D15/((E15/100)^2),"") | J15: =IF(AND(ISNUMBER(D15),ISNUMBER(G15)),D15-G15,"") | K15: =IF(AND(ISNUMBER(D15),ISNUMBER(G15),G15<>0),(D15-G15)/G15,"") | S15: =IF(CONFIG!$B$28="No","",IF(AND(ISNUMBER(D15),ISNUMBER(R15),R15>=0,R15<=100,U15<>""),D15*R15/100,"")) | T15: =IF(CONFIG!$B$28="No","",IF(AND(ISNUMBER(D15),ISNUMBER(S15)),D15-S15,"")) | V15: =IF(AND(ISNUMBER(N15),ISNUMBER(E15),E15>0),N15/E15,"") | W15: =IF(AND(ISNUMBER(N15),ISNUMBER(O15),O15>0),N15/O15,"") | AJ15: =IF(A15="","",COUNTIF($B$7:B15,B15)) | AK15: =IF(A15="","",B15&"|"&AJ15) | AL15: =IF(A15="","",IF(COUNTIFS(EVALUACION!$A$7:$A$36,A15,EVALUACION!$B$7:$B$36,B15)=0,"✖ Evaluación/paciente inconsistente",IF(OR(D15<0,E15<0,N15<0,O15<0),"✖ Valor negativo",IF(OR(AND(ISNUMBER(D15),OR(D15<CONFIG!$B$38,D15>CONFIG!$B$39)),AND(ISNUMBER(E15),OR(E15<CONFIG!$B$40,E15>CONFIG!$B$41))),"▲ Fuera de límite operativo",IF(AND(ISNUMBER(R15),OR(R15<0,R15>100)),"✖ % grasa fuera de 0–100",IF(AND(ISNUMBER(R15),U15=""),"▲ Falta fuente de % grasa",IF(E15="","▲ Estatura faltante",IF(AC15="Sí","▲ Edema registrado","✔ Correcto"))))))))
F16: =IF(AND(ISNUMBER(D16),ISNUMBER(E16),D16>0,E16>0),D16/((E16/100)^2),"") | J16: =IF(AND(ISNUMBER(D16),ISNUMBER(G16)),D16-G16,"") | K16: =IF(AND(ISNUMBER(D16),ISNUMBER(G16),G16<>0),(D16-G16)/G16,"") | S16: =IF(CONFIG!$B$28="No","",IF(AND(ISNUMBER(D16),ISNUMBER(R16),R16>=0,R16<=100,U16<>""),D16*R16/100,"")) | T16: =IF(CONFIG!$B$28="No","",IF(AND(ISNUMBER(D16),ISNUMBER(S16)),D16-S16,"")) | V16: =IF(AND(ISNUMBER(N16),ISNUMBER(E16),E16>0),N16/E16,"") | W16: =IF(AND(ISNUMBER(N16),ISNUMBER(O16),O16>0),N16/O16,"") | AJ16: =IF(A16="","",COUNTIF($B$7:B16,B16)) | AK16: =IF(A16="","",B16&"|"&AJ16) | AL16: =IF(A16="","",IF(COUNTIFS(EVALUACION!$A$7:$A$36,A16,EVALUACION!$B$7:$B$36,B16)=0,"✖ Evaluación/paciente inconsistente",IF(OR(D16<0,E16<0,N16<0,O16<0),"✖ Valor negativo",IF(OR(AND(ISNUMBER(D16),OR(D16<CONFIG!$B$38,D16>CONFIG!$B$39)),AND(ISNUMBER(E16),OR(E16<CONFIG!$B$40,E16>CONFIG!$B$41))),"▲ Fuera de límite operativo",IF(AND(ISNUMBER(R16),OR(R16<0,R16>100)),"✖ % grasa fuera de 0–100",IF(AND(ISNUMBER(R16),U16=""),"▲ Falta fuente de % grasa",IF(E16="","▲ Estatura faltante",IF(AC16="Sí","▲ Edema registrado","✔ Correcto"))))))))
F17: =IF(AND(ISNUMBER(D17),ISNUMBER(E17),D17>0,E17>0),D17/((E17/100)^2),"") | J17: =IF(AND(ISNUMBER(D17),ISNUMBER(G17)),D17-G17,"") | K17: =IF(AND(ISNUMBER(D17),ISNUMBER(G17),G17<>0),(D17-G17)/G17,"") | S17: =IF(CONFIG!$B$28="No","",IF(AND(ISNUMBER(D17),ISNUMBER(R17),R17>=0,R17<=100,U17<>""),D17*R17/100,"")) | T17: =IF(CONFIG!$B$28="No","",IF(AND(ISNUMBER(D17),ISNUMBER(S17)),D17-S17,"")) | V17: =IF(AND(ISNUMBER(N17),ISNUMBER(E17),E17>0),N17/E17,"") | W17: =IF(AND(ISNUMBER(N17),ISNUMBER(O17),O17>0),N17/O17,"") | AJ17: =IF(A17="","",COUNTIF($B$7:B17,B17)) | AK17: =IF(A17="","",B17&"|"&AJ17) | AL17: =IF(A17="","",IF(COUNTIFS(EVALUACION!$A$7:$A$36,A17,EVALUACION!$B$7:$B$36,B17)=0,"✖ Evaluación/paciente inconsistente",IF(OR(D17<0,E17<0,N17<0,O17<0),"✖ Valor negativo",IF(OR(AND(ISNUMBER(D17),OR(D17<CONFIG!$B$38,D17>CONFIG!$B$39)),AND(ISNUMBER(E17),OR(E17<CONFIG!$B$40,E17>CONFIG!$B$41))),"▲ Fuera de límite operativo",IF(AND(ISNUMBER(R17),OR(R17<0,R17>100)),"✖ % grasa fuera de 0–100",IF(AND(ISNUMBER(R17),U17=""),"▲ Falta fuente de % grasa",IF(E17="","▲ Estatura faltante",IF(AC17="Sí","▲ Edema registrado","✔ Correcto"))))))))
F18: =IF(AND(ISNUMBER(D18),ISNUMBER(E18),D18>0,E18>0),D18/((E18/100)^2),"") | J18: =IF(AND(ISNUMBER(D18),ISNUMBER(G18)),D18-G18,"") | K18: =IF(AND(ISNUMBER(D18),ISNUMBER(G18),G18<>0),(D18-G18)/G18,"") | S18: =IF(CONFIG!$B$28="No","",IF(AND(ISNUMBER(D18),ISNUMBER(R18),R18>=0,R18<=100,U18<>""),D18*R18/100,"")) | T18: =IF(CONFIG!$B$28="No","",IF(AND(ISNUMBER(D18),ISNUMBER(S18)),D18-S18,"")) | V18: =IF(AND(ISNUMBER(N18),ISNUMBER(E18),E18>0),N18/E18,"") | W18: =IF(AND(ISNUMBER(N18),ISNUMBER(O18),O18>0),N18/O18,"") | AJ18: =IF(A18="","",COUNTIF($B$7:B18,B18)) | AK18: =IF(A18="","",B18&"|"&AJ18) | AL18: =IF(A18="","",IF(COUNTIFS(EVALUACION!$A$7:$A$36,A18,EVALUACION!$B$7:$B$36,B18)=0,"✖ Evaluación/paciente inconsistente",IF(OR(D18<0,E18<0,N18<0,O18<0),"✖ Valor negativo",IF(OR(AND(ISNUMBER(D18),OR(D18<CONFIG!$B$38,D18>CONFIG!$B$39)),AND(ISNUMBER(E18),OR(E18<CONFIG!$B$40,E18>CONFIG!$B$41))),"▲ Fuera de límite operativo",IF(AND(ISNUMBER(R18),OR(R18<0,R18>100)),"✖ % grasa fuera de 0–100",IF(AND(ISNUMBER(R18),U18=""),"▲ Falta fuente de % grasa",IF(E18="","▲ Estatura faltante",IF(AC18="Sí","▲ Edema registrado","✔ Correcto"))))))))
F19: =IF(AND(ISNUMBER(D19),ISNUMBER(E19),D19>0,E19>0),D19/((E19/100)^2),"") | J19: =IF(AND(ISNUMBER(D19),ISNUMBER(G19)),D19-G19,"") | K19: =IF(AND(ISNUMBER(D19),ISNUMBER(G19),G19<>0),(D19-G19)/G19,"") | S19: =IF(CONFIG!$B$28="No","",IF(AND(ISNUMBER(D19),ISNUMBER(R19),R19>=0,R19<=100,U19<>""),D19*R19/100,"")) | T19: =IF(CONFIG!$B$28="No","",IF(AND(ISNUMBER(D19),ISNUMBER(S19)),D19-S19,"")) | V19: =IF(AND(ISNUMBER(N19),ISNUMBER(E19),E19>0),N19/E19,"") | W19: =IF(AND(ISNUMBER(N19),ISNUMBER(O19),O19>0),N19/O19,"") | AJ19: =IF(A19="","",COUNTIF($B$7:B19,B19)) | AK19: =IF(A19="","",B19&"|"&AJ19) | AL19: =IF(A19="","",IF(COUNTIFS(EVALUACION!$A$7:$A$36,A19,EVALUACION!$B$7:$B$36,B19)=0,"✖ Evaluación/paciente inconsistente",IF(OR(D19<0,E19<0,N19<0,O19<0),"✖ Valor negativo",IF(OR(AND(ISNUMBER(D19),OR(D19<CONFIG!$B$38,D19>CONFIG!$B$39)),AND(ISNUMBER(E19),OR(E19<CONFIG!$B$40,E19>CONFIG!$B$41))),"▲ Fuera de límite operativo",IF(AND(ISNUMBER(R19),OR(R19<0,R19>100)),"✖ % grasa fuera de 0–100",IF(AND(ISNUMBER(R19),U19=""),"▲ Falta fuente de % grasa",IF(E19="","▲ Estatura faltante",IF(AC19="Sí","▲ Edema registrado","✔ Correcto"))))))))
F20: =IF(AND(ISNUMBER(D20),ISNUMBER(E20),D20>0,E20>0),D20/((E20/100)^2),"") | J20: =IF(AND(ISNUMBER(D20),ISNUMBER(G20)),D20-G20,"") | K20: =IF(AND(ISNUMBER(D20),ISNUMBER(G20),G20<>0),(D20-G20)/G20,"") | S20: =IF(CONFIG!$B$28="No","",IF(AND(ISNUMBER(D20),ISNUMBER(R20),R20>=0,R20<=100,U20<>""),D20*R20/100,"")) | T20: =IF(CONFIG!$B$28="No","",IF(AND(ISNUMBER(D20),ISNUMBER(S20)),D20-S20,"")) | V20: =IF(AND(ISNUMBER(N20),ISNUMBER(E20),E20>0),N20/E20,"") | W20: =IF(AND(ISNUMBER(N20),ISNUMBER(O20),O20>0),N20/O20,"") | AJ20: =IF(A20="","",COUNTIF($B$7:B20,B20)) | AK20: =IF(A20="","",B20&"|"&AJ20) | AL20: =IF(A20="","",IF(COUNTIFS(EVALUACION!$A$7:$A$36,A20,EVALUACION!$B$7:$B$36,B20)=0,"✖ Evaluación/paciente inconsistente",IF(OR(D20<0,E20<0,N20<0,O20<0),"✖ Valor negativo",IF(OR(AND(ISNUMBER(D20),OR(D20<CONFIG!$B$38,D20>CONFIG!$B$39)),AND(ISNUMBER(E20),OR(E20<CONFIG!$B$40,E20>CONFIG!$B$41))),"▲ Fuera de límite operativo",IF(AND(ISNUMBER(R20),OR(R20<0,R20>100)),"✖ % grasa fuera de 0–100",IF(AND(ISNUMBER(R20),U20=""),"▲ Falta fuente de % grasa",IF(E20="","▲ Estatura faltante",IF(AC20="Sí","▲ Edema registrado","✔ Correcto"))))))))
F21: =IF(AND(ISNUMBER(D21),ISNUMBER(E21),D21>0,E21>0),D21/((E21/100)^2),"") | J21: =IF(AND(ISNUMBER(D21),ISNUMBER(G21)),D21-G21,"") | K21: =IF(AND(ISNUMBER(D21),ISNUMBER(G21),G21<>0),(D21-G21)/G21,"") | S21: =IF(CONFIG!$B$28="No","",IF(AND(ISNUMBER(D21),ISNUMBER(R21),R21>=0,R21<=100,U21<>""),D21*R21/100,"")) | T21: =IF(CONFIG!$B$28="No","",IF(AND(ISNUMBER(D21),ISNUMBER(S21)),D21-S21,"")) | V21: =IF(AND(ISNUMBER(N21),ISNUMBER(E21),E21>0),N21/E21,"") | W21: =IF(AND(ISNUMBER(N21),ISNUMBER(O21),O21>0),N21/O21,"") | AJ21: =IF(A21="","",COUNTIF($B$7:B21,B21)) | AK21: =IF(A21="","",B21&"|"&AJ21) | AL21: =IF(A21="","",IF(COUNTIFS(EVALUACION!$A$7:$A$36,A21,EVALUACION!$B$7:$B$36,B21)=0,"✖ Evaluación/paciente inconsistente",IF(OR(D21<0,E21<0,N21<0,O21<0),"✖ Valor negativo",IF(OR(AND(ISNUMBER(D21),OR(D21<CONFIG!$B$38,D21>CONFIG!$B$39)),AND(ISNUMBER(E21),OR(E21<CONFIG!$B$40,E21>CONFIG!$B$41))),"▲ Fuera de límite operativo",IF(AND(ISNUMBER(R21),OR(R21<0,R21>100)),"✖ % grasa fuera de 0–100",IF(AND(ISNUMBER(R21),U21=""),"▲ Falta fuente de % grasa",IF(E21="","▲ Estatura faltante",IF(AC21="Sí","▲ Edema registrado","✔ Correcto"))))))))
F22: =IF(AND(ISNUMBER(D22),ISNUMBER(E22),D22>0,E22>0),D22/((E22/100)^2),"") | J22: =IF(AND(ISNUMBER(D22),ISNUMBER(G22)),D22-G22,"") | K22: =IF(AND(ISNUMBER(D22),ISNUMBER(G22),G22<>0),(D22-G22)/G22,"") | S22: =IF(CONFIG!$B$28="No","",IF(AND(ISNUMBER(D22),ISNUMBER(R22),R22>=0,R22<=100,U22<>""),D22*R22/100,"")) | T22: =IF(CONFIG!$B$28="No","",IF(AND(ISNUMBER(D22),ISNUMBER(S22)),D22-S22,"")) | V22: =IF(AND(ISNUMBER(N22),ISNUMBER(E22),E22>0),N22/E22,"") | W22: =IF(AND(ISNUMBER(N22),ISNUMBER(O22),O22>0),N22/O22,"") | AJ22: =IF(A22="","",COUNTIF($B$7:B22,B22)) | AK22: =IF(A22="","",B22&"|"&AJ22) | AL22: =IF(A22="","",IF(COUNTIFS(EVALUACION!$A$7:$A$36,A22,EVALUACION!$B$7:$B$36,B22)=0,"✖ Evaluación/paciente inconsistente",IF(OR(D22<0,E22<0,N22<0,O22<0),"✖ Valor negativo",IF(OR(AND(ISNUMBER(D22),OR(D22<CONFIG!$B$38,D22>CONFIG!$B$39)),AND(ISNUMBER(E22),OR(E22<CONFIG!$B$40,E22>CONFIG!$B$41))),"▲ Fuera de límite operativo",IF(AND(ISNUMBER(R22),OR(R22<0,R22>100)),"✖ % grasa fuera de 0–100",IF(AND(ISNUMBER(R22),U22=""),"▲ Falta fuente de % grasa",IF(E22="","▲ Estatura faltante",IF(AC22="Sí","▲ Edema registrado","✔ Correcto"))))))))
F23: =IF(AND(ISNUMBER(D23),ISNUMBER(E23),D23>0,E23>0),D23/((E23/100)^2),"") | J23: =IF(AND(ISNUMBER(D23),ISNUMBER(G23)),D23-G23,"") | K23: =IF(AND(ISNUMBER(D23),ISNUMBER(G23),G23<>0),(D23-G23)/G23,"") | S23: =IF(CONFIG!$B$28="No","",IF(AND(ISNUMBER(D23),ISNUMBER(R23),R23>=0,R23<=100,U23<>""),D23*R23/100,"")) | T23: =IF(CONFIG!$B$28="No","",IF(AND(ISNUMBER(D23),ISNUMBER(S23)),D23-S23,"")) | V23: =IF(AND(ISNUMBER(N23),ISNUMBER(E23),E23>0),N23/E23,"") | W23: =IF(AND(ISNUMBER(N23),ISNUMBER(O23),O23>0),N23/O23,"") | AJ23: =IF(A23="","",COUNTIF($B$7:B23,B23)) | AK23: =IF(A23="","",B23&"|"&AJ23) | AL23: =IF(A23="","",IF(COUNTIFS(EVALUACION!$A$7:$A$36,A23,EVALUACION!$B$7:$B$36,B23)=0,"✖ Evaluación/paciente inconsistente",IF(OR(D23<0,E23<0,N23<0,O23<0),"✖ Valor negativo",IF(OR(AND(ISNUMBER(D23),OR(D23<CONFIG!$B$38,D23>CONFIG!$B$39)),AND(ISNUMBER(E23),OR(E23<CONFIG!$B$40,E23>CONFIG!$B$41))),"▲ Fuera de límite operativo",IF(AND(ISNUMBER(R23),OR(R23<0,R23>100)),"✖ % grasa fuera de 0–100",IF(AND(ISNUMBER(R23),U23=""),"▲ Falta fuente de % grasa",IF(E23="","▲ Estatura faltante",IF(AC23="Sí","▲ Edema registrado","✔ Correcto"))))))))
F24: =IF(AND(ISNUMBER(D24),ISNUMBER(E24),D24>0,E24>0),D24/((E24/100)^2),"") | J24: =IF(AND(ISNUMBER(D24),ISNUMBER(G24)),D24-G24,"") | K24: =IF(AND(ISNUMBER(D24),ISNUMBER(G24),G24<>0),(D24-G24)/G24,"") | S24: =IF(CONFIG!$B$28="No","",IF(AND(ISNUMBER(D24),ISNUMBER(R24),R24>=0,R24<=100,U24<>""),D24*R24/100,"")) | T24: =IF(CONFIG!$B$28="No","",IF(AND(ISNUMBER(D24),ISNUMBER(S24)),D24-S24,"")) | V24: =IF(AND(ISNUMBER(N24),ISNUMBER(E24),E24>0),N24/E24,"") | W24: =IF(AND(ISNUMBER(N24),ISNUMBER(O24),O24>0),N24/O24,"") | AJ24: =IF(A24="","",COUNTIF($B$7:B24,B24)) | AK24: =IF(A24="","",B24&"|"&AJ24) | AL24: =IF(A24="","",IF(COUNTIFS(EVALUACION!$A$7:$A$36,A24,EVALUACION!$B$7:$B$36,B24)=0,"✖ Evaluación/paciente inconsistente",IF(OR(D24<0,E24<0,N24<0,O24<0),"✖ Valor negativo",IF(OR(AND(ISNUMBER(D24),OR(D24<CONFIG!$B$38,D24>CONFIG!$B$39)),AND(ISNUMBER(E24),OR(E24<CONFIG!$B$40,E24>CONFIG!$B$41))),"▲ Fuera de límite operativo",IF(AND(ISNUMBER(R24),OR(R24<0,R24>100)),"✖ % grasa fuera de 0–100",IF(AND(ISNUMBER(R24),U24=""),"▲ Falta fuente de % grasa",IF(E24="","▲ Estatura faltante",IF(AC24="Sí","▲ Edema registrado","✔ Correcto"))))))))
... F36: =IF(AND(ISNUMBER(D36),ISNUMBER(E36),D36>0,E36>0),D36/((E36/100)^2),"") | J36: =IF(AND(ISNUMBER(D36),ISNUMBER(G36)),D36-G36,"") | K36: =IF(AND(ISNUMBER(D36),ISNUMBER(G36),G36<>0),(D36-G36)/G36,"") | S36: =IF(CONFIG!$B$28="No","",IF(AND(ISNUMBER(D36),ISNUMBER(R36),R36>=0,R36<=100,U36<>""),D36*R36/100,"")) | T36: =IF(CONFIG!$B$28="No","",IF(AND(ISNUMBER(D36),ISNUMBER(S36)),D36-S36,"")) | V36: =IF(AND(ISNUMBER(N36),ISNUMBER(E36),E36>0),N36/E36,"") | W36: =IF(AND(ISNUMBER(N36),ISNUMBER(O36),O36>0),N36/O36,"") | AJ36: =IF(A36="","",COUNTIF($B$7:B36,B36)) | AK36: =IF(A36="","",B36&"|"&AJ36) | AL36: =IF(A36="","",IF(COUNTIFS(EVALUACION!$A$7:$A$36,A36,EVALUACION!$B$7:$B$36,B36)=0,"✖ Evaluación/paciente inconsistente",IF(OR(D36<0,E36<0,N36<0,O36<0),"✖ Valor negativo",IF(OR(AND(ISNUMBER(D36),OR(D36<CONFIG!$B$38,D36>CONFIG!$B$39)),AND(ISNUMBER(E36),OR(E36<CONFIG!$B$40,E36>CONFIG!$B$41))),"▲ Fuera de límite operativo",IF(AND(ISNUMBER(R36),OR(R36<0,R36>100)),"✖ % grasa fuera de 0–100",IF(AND(ISNUMBER(R36),U36=""),"▲ Falta fuente de % grasa",IF(E36="","▲ Estatura faltante",IF(AC36="Sí","▲ Edema registrado","✔ Correcto"))))))))

Sheet BIOQUIMICA
A1: BIOQUÍMICA · Resultados con rangos ingresados y revisión profesional
A2: ◀ INICIO | B2: RESUMEN | C2: CONFIG | D2: PRUEBAS
A3: ▲ Los rangos dependen del laboratorio, método, unidad y población. No se generan diagnósticos.
A5: T_BIOQUIMICA
