Workbook
Name M12_AM_C1: M12_CONFIG!$B$49
Name M12_AM_C2: M12_CONFIG!$B$50
Name M12_AM_C3: M12_CONFIG!$B$51
Name M12_BRO_A: M12_CONFIG!$B$31
Name M12_BRO_B: M12_CONFIG!$B$32
Name M12_c_ampl: M12_CALCULOS!$B$30
Name M12_c_ClaseGrasa: M12_CALCULOS!$B$48
Name M12_c_ClaseIMC: M12_CALCULOS!$B$47
Name M12_c_Dens: M12_CALCULOS!$B$18
Name M12_c_DWc: M12_CALCULOS!$B$16
Name M12_c_DWm: M12_CALCULOS!$B$17
Name M12_c_estado: M12_CALCULOS!$B$31
Name M12_c_Gate: M12_CALCULOS!$B$13
Name M12_c_GrDeu: M12_CALCULOS!$B$21
Name M12_c_GrNavy: M12_CALCULOS!$B$20
Name M12_c_GrPli: M12_CALCULOS!$B$19
Name M12_c_GrRep: M12_CALCULOS!$B$24
Name M12_c_ICC: M12_CALCULOS!$B$40
Name M12_c_ICE: M12_CALCULOS!$B$41
Name M12_c_IMC: M12_CALCULOS!$B$9
Name M12_c_IMG: M12_CALCULOS!$B$36
Name M12_c_IMLG: M12_CALCULOS!$B$37
Name M12_c_max: M12_CALCULOS!$B$28
Name M12_c_MG: M12_CALCULOS!$B$34
Name M12_c_min: M12_CALCULOS!$B$27
Name M12_c_MLG: M12_CALCULOS!$B$35
Name M12_c_n: M12_CALCULOS!$B$25
Name M12_c_prom: M12_CALCULOS!$B$26
Name M12_c_rango: M12_CALCULOS!$B$29
Name M12_c_RiesgoCint: M12_CALCULOS!$B$42
Name M12_c_RiesgoICC: M12_CALCULOS!$B$43
Name M12_c_RiesgoICE: M12_CALCULOS!$B$44
Name M12_c_SumPli: M12_CALCULOS!$B$10
Name M12_c_TallaM: M12_CALCULOS!$B$8
Name M12_CAD_MAX: M12_CONFIG!$B$23
Name M12_CAD_MIN: M12_CONFIG!$B$22
Name M12_CIN_MAX: M12_CONFIG!$B$21
Name M12_CIN_MIN: M12_CONFIG!$B$20
Name M12_CINT_H: M12_CONFIG!$B$52
Name M12_CINT_M: M12_CONFIG!$B$53
Name M12_CUE_MAX: M12_CONFIG!$B$19
Name M12_CUE_MIN: M12_CONFIG!$B$18
Name M12_DEU_CONST: M12_CONFIG!$B$42
Name M12_DEU_EDAD: M12_CONFIG!$B$40
Name M12_DEU_IMC: M12_CONFIG!$B$39
Name M12_DEU_SEXO: M12_CONFIG!$B$41
Name M12_DISP_MAX: M12_CONFIG!$B$26
Name M12_EDAD_AM: M12_CONFIG!$B$48
Name M12_EDAD_MAX: M12_CONFIG!$B$11
Name M12_EDAD_MIN: M12_CONFIG!$B$10
Name M12_EST_MAX: M12_CONFIG!$B$15
Name M12_EST_MIN: M12_CONFIG!$B$14
Name M12_GRASA_MAX: M12_CONFIG!$B$25
Name M12_GRASA_MIN: M12_CONFIG!$B$24
Name M12_ICC_H: M12_CONFIG!$B$54
Name M12_ICC_M: M12_CONFIG!$B$55
Name M12_ICE_R: M12_CONFIG!$B$56
Name M12_IMC_C1: M12_CONFIG!$B$43
Name M12_IMC_C2: M12_CONFIG!$B$44
Name M12_IMC_C3: M12_CONFIG!$B$45

Sheet INICIO
A1: NUTRIMETRÍA · NMX-28 · PACK ANTROPOMETRÍA INTEGRADO
A2: Versión 2.1 · integración UDD separada · un solo archivo autónomo · alcance adulto
A4: Versión | B4: 2.1
A5: Componentes | B5: NMX-41 · NMX-36 · NMX-12 · NMX-16 · NMX-34 (educativo)
A6: Estado de validación | B6: NO REPRODUCIBLE: la afirmación 428/428 carece de 428 registros comprobables y no se aportaron los originales.
A7: Alcance | B7: Solo adultos (≥18 a). Sin extrapolación.
A8: Privacidad | B8: Use códigos; sin datos identificables.
A9: Aviso | B9: Exactitud matemática ≠ validación clínica. No es diagnóstico.
A10: ▶ AUDITORIA_INTEGRACION | B10: Matriz reproducible, fórmulas sin caché y limitaciones de la auditoría.
A11: Estado de auditoría | B11: 0 comparaciones original→integrado reproducibles; 192 comparaciones internas de módulos + 4 pruebas internas de integración documentadas.
A13: MÓDULOS Y NAVEGACIÓN
A14: =HYPERLINK("#DATOS!A1","▶ DATOS") -> ▶ DATOS
A15: =HYPERLINK("#MEDICIONES!A1","▶ MEDICIONES") -> ▶ MEDICIONES
A16: =HYPERLINK("#RESULTADOS!A1","▶ RESULTADOS") -> ▶ RESULTADOS
A17: =HYPERLINK("#SEGUIMIENTO!A1","▶ SEGUIMIENTO") -> ▶ SEGUIMIENTO
A18: =HYPERLINK("#CURVAS!A1","▶ CURVAS") -> ▶ CURVAS
A19: =HYPERLINK("#M41_INICIO!A1","▶ Control plicómetro (NMX-41)") -> ▶ Control plicómetro (NMX-41)
A20: =HYPERLINK("#M36_INICIO!A1","▶ Plicometría (NMX-36)") -> ▶ Plicometría (NMX-36)
A21: =HYPERLINK("#M12_INICIO!A1","▶ Composición (NMX-12)") -> ▶ Composición (NMX-12)
A22: =HYPERLINK("#M16_INICIO!A1","▶ Somatotipo (NMX-16)") -> ▶ Somatotipo (NMX-16)
A23: =HYPERLINK("#M34_INICIO!A1","▶ Edad metabólica ed. (NMX-34)") -> ▶ Edad metabólica ed. (NMX-34)
A24: =HYPERLINK("#MAPA_MODULOS!A1","▶ MAPA_MODULOS") -> ▶ MAPA_MODULOS
A25: =HYPERLINK("#FUENTES!A1","▶ FUENTES") -> ▶ FUENTES
A26: =HYPERLINK("#LICENCIAS!A1","▶ LICENCIAS") -> ▶ LICENCIAS
A27: =HYPERLINK("#PRUEBAS!A1","▶ PRUEBAS") -> ▶ PRUEBAS
A28: =HYPERLINK("#CHANGELOG!A1","▶ CHANGELOG") -> ▶ CHANGELOG
A32: PROTOCOLOS UDD · CAPA SEPARADA
A33: ▶ PROTOCOLOS_UDD | B33: Registro maestro de técnica, lado, posición, precisión, repeticiones, fuente y estado.
A34: ▶ COMPARADOR_PROTOCOLOS | B34: Selector UDD/ISAK con diferencias explícitas y sin mezcla metodológica.
A35: ▶ ECUACIONES_UDD | B35: Catálogo y calculadora documental separada de los motores originales.
A36: ▶ FUENTES_UDD | B36: Trazabilidad del Manual UDD, fuentes primarias, matrices y límites.
A37: ▶ PRUEBAS_UDD | B37: Pruebas funcionales, Open XML y regresión de motores.

Sheet DATOS
A1: NUTRIMETRÍA · NMX-28 · PACK ANTROPOMETRÍA INTEGRADO
A2: Fuente única de verdad · los módulos leen de aquí automáticamente
A4: LEYENDA · Celdas ARENA con texto AZUL = editables. Grises = calculadas/vinculadas. Solo adultos (≥18 a). Use CÓDIGOS, no datos identificables.
A6: Campo | B6: Valor
A7: ID de evaluación | B7: NMX-2026-0028
A8: Fecha | B8: 46236
A9: ID de persona | B9: PER-0007
A10: Sexo | B10: Hombre
A11: Edad (años) | B11: 34
A12: Peso (kg) | B12: 78.5
A13: Talla (cm) | B13: 176
A14: Evaluador | B14: EVAL-01
A15: Instrumento | B15: PLIC-01
A16: Método (informativo) | B16: cada módulo mantiene su propio selector
A17: Observaciones

Sheet MEDICIONES
A1: MEDICIONES ANTROPOMÉTRICAS
A2: Entrada única por sitio · fuera de tolerancia = advertencia, NO se promedia
A6: Sitio | B6: Med 1 | C6: Med 2 | D6: Med 3 | E6: Diferencia | F6: Tolerancia | G6: Promedio válido | H6: Unidad | I6: Evaluador | J6: Fecha | K6: Estado | L6: Observación
A7: Pectoral | B7: 8 | E7: =IF(COUNT(B7:D7)=0,"",MAX(B7:D7)-MIN(B7:D7)) -> 0 | F7: 5 | G7: =IF(COUNT(B7:D7)=0,"",IF((MAX(B7:D7)-MIN(B7:D7))<=F7,AVERAGE(B7:D7),"")) -> 8 | H7: mm | K7: =IF(COUNT(B7:D7)=0,"—",IF((MAX(B7:D7)-MIN(B7:D7))<=F7,"OK","FUERA DE TOLERANCIA")) -> OK
A8: Axilar medio | B8: 10 | E8: =IF(COUNT(B8:D8)=0,"",MAX(B8:D8)-MIN(B8:D8)) -> 0 | F8: 5 | G8: =IF(COUNT(B8:D8)=0,"",IF((MAX(B8:D8)-MIN(B8:D8))<=F8,AVERAGE(B8:D8),"")) -> 10 | H8: mm | K8: =IF(COUNT(B8:D8)=0,"—",IF((MAX(B8:D8)-MIN(B8:D8))<=F8,"OK","FUERA DE TOLERANCIA")) -> OK
A9: Tríceps | B9: 12 | E9: =IF(COUNT(B9:D9)=0,"",MAX(B9:D9)-MIN(B9:D9)) -> 0 | F9: 5 | G9: =IF(COUNT(B9:D9)=0,"",IF((MAX(B9:D9)-MIN(B9:D9))<=F9,AVERAGE(B9:D9),"")) -> 12 | H9: mm | K9: =IF(COUNT(B9:D9)=0,"—",IF((MAX(B9:D9)-MIN(B9:D9))<=F9,"OK","FUERA DE TOLERANCIA")) -> OK
A10: Subescapular | B10: 14 | E10: =IF(COUNT(B10:D10)=0,"",MAX(B10:D10)-MIN(B10:D10)) -> 0 | F10: 5 | G10: =IF(COUNT(B10:D10)=0,"",IF((MAX(B10:D10)-MIN(B10:D10))<=F10,AVERAGE(B10:D10),"")) -> 14 | H10: mm | K10: =IF(COUNT(B10:D10)=0,"—",IF((MAX(B10:D10)-MIN(B10:D10))<=F10,"OK","FUERA DE TOLERANCIA")) -> OK
A11: Bíceps | B11: 5 | E11: =IF(COUNT(B11:D11)=0,"",MAX(B11:D11)-MIN(B11:D11)) -> 0 | F11: 5 | G11: =IF(COUNT(B11:D11)=0,"",IF((MAX(B11:D11)-MIN(B11:D11))<=F11,AVERAGE(B11:D11),"")) -> 5 | H11: mm | K11: =IF(COUNT(B11:D11)=0,"—",IF((MAX(B11:D11)-MIN(B11:D11))<=F11,"OK","FUERA DE TOLERANCIA")) -> OK
A12: Suprailíaco | B12: 16 | E12: =IF(COUNT(B12:D12)=0,"",MAX(B12:D12)-MIN(B12:D12)) -> 0 | F12: 5 | G12: =IF(COUNT(B12:D12)=0,"",IF((MAX(B12:D12)-MIN(B12:D12))<=F12,AVERAGE(B12:D12),"")) -> 16 | H12: mm | K12: =IF(COUNT(B12:D12)=0,"—",IF((MAX(B12:D12)-MIN(B12:D12))<=F12,"OK","FUERA DE TOLERANCIA")) -> OK
A13: Abdominal | B13: 20 | E13: =IF(COUNT(B13:D13)=0,"",MAX(B13:D13)-MIN(B13:D13)) -> 0 | F13: 5 | G13: =IF(COUNT(B13:D13)=0,"",IF((MAX(B13:D13)-MIN(B13:D13))<=F13,AVERAGE(B13:D13),"")) -> 20 | H13: mm | K13: =IF(COUNT(B13:D13)=0,"—",IF((MAX(B13:D13)-MIN(B13:D13))<=F13,"OK","FUERA DE TOLERANCIA")) -> OK
A14: Muslo | B14: 12 | E14: =IF(COUNT(B14:D14)=0,"",MAX(B14:D14)-MIN(B14:D14)) -> 0 | F14: 5 | G14: =IF(COUNT(B14:D14)=0,"",IF((MAX(B14:D14)-MIN(B14:D14))<=F14,AVERAGE(B14:D14),"")) -> 12 | H14: mm | K14: =IF(COUNT(B14:D14)=0,"—",IF((MAX(B14:D14)-MIN(B14:D14))<=F14,"OK","FUERA DE TOLERANCIA")) -> OK
A15: Cuello | B15: 38 | E15: =IF(COUNT(B15:D15)=0,"",MAX(B15:D15)-MIN(B15:D15)) -> 0 | F15: 1 | G15: =IF(COUNT(B15:D15)=0,"",IF((MAX(B15:D15)-MIN(B15:D15))<=F15,AVERAGE(B15:D15),"")) -> 38 | H15: cm | K15: =IF(COUNT(B15:D15)=0,"—",IF((MAX(B15:D15)-MIN(B15:D15))<=F15,"OK","FUERA DE TOLERANCIA")) -> OK
A16: Cintura | B16: 85 | E16: =IF(COUNT(B16:D16)=0,"",MAX(B16:D16)-MIN(B16:D16)) -> 0 | F16: 1 | G16: =IF(COUNT(B16:D16)=0,"",IF((MAX(B16:D16)-MIN(B16:D16))<=F16,AVERAGE(B16:D16),"")) -> 85 | H16: cm | K16: =IF(COUNT(B16:D16)=0,"—",IF((MAX(B16:D16)-MIN(B16:D16))<=F16,"OK","FUERA DE TOLERANCIA")) -> OK
A17: Cadera | B17: 98 | E17: =IF(COUNT(B17:D17)=0,"",MAX(B17:D17)-MIN(B17:D17)) -> 0 | F17: 1 | G17: =IF(COUNT(B17:D17)=0,"",IF((MAX(B17:D17)-MIN(B17:D17))<=F17,AVERAGE(B17:D17),"")) -> 98 | H17: cm | K17: =IF(COUNT(B17:D17)=0,"—",IF((MAX(B17:D17)-MIN(B17:D17))<=F17,"OK","FUERA DE TOLERANCIA")) -> OK
A18: Brazo corregido | B18: 32 | E18: =IF(COUNT(B18:D18)=0,"",MAX(B18:D18)-MIN(B18:D18)) -> 0 | F18: 1 | G18: =IF(COUNT(B18:D18)=0,"",IF((MAX(B18:D18)-MIN(B18:D18))<=F18,AVERAGE(B18:D18),"")) -> 32 | H18: cm | K18: =IF(COUNT(B18:D18)=0,"—",IF((MAX(B18:D18)-MIN(B18:D18))<=F18,"OK","FUERA DE TOLERANCIA")) -> OK
... A22: Fémur (diámetro) | B22: 9 | E22: =IF(COUNT(B22:D22)=0,"",MAX(B22:D22)-MIN(B22:D22)) -> 0 | F22: 0.5 | G22: =IF(COUNT(B22:D22)=0,"",IF((MAX(B22:D22)-MIN(B22:D22))<=F22,AVERAGE(B22:D22),"")) -> 9 | H22: cm | K22: =IF(COUNT(B22:D22)=0,"—",IF((MAX(B22:D22)-MIN(B22:D22))<=F22,"OK","FUERA DE TOLERANCIA")) -> OK

Sheet SEGUIMIENTO
A1: SEGUIMIENTO LONGITUDINAL
A4: La tabla se expande al escribir; las curvas se actualizan solas
A6: Fecha | B6: Peso | C6: IMC | D6: Cintura | E6: ΣPliegues | F6: %Grasa | G6: MasaGrasa | H6: MasaLibre | I6: Somatotipo | J6: ETM | K6: Instrumento | L6: Evaluador
A7: 2026-08-02

Sheet CURVAS
A1: CURVAS DE TENDENCIA
A2: Se actualizan al agregar filas en SEGUIMIENTO

Sheet RESULTADOS
A1: RESULTADOS INTEGRADOS
A2: Referencias vivas a los módulos · exactitud matemática ≠ validación clínica
A6: Indicador | B6: Valor | C6: Procedencia
A7: IMC (kg/m²) | B7: =M12_c_IMC -> 25.3422 | C7: NMX-12
A8: Índice cintura/estatura | B8: =M12_c_ICE -> 0.48295455 | C8: NMX-12
A9: Riesgo cintura/estatura | B9: =M12_c_RiesgoICE -> Sin riesgo aumentado | C9: NMX-12
A10: Σ pliegues (7) | B10: =M36_c_Sum7 -> 92 | C10: NMX-36
A11: Densidad DW | B11: =M36_c_BDdw -> 1.0512379 | C11: NMX-36
A12: % grasa (método reportado) | B12: =M36_c_GrRep -> 0.13989155 | C12: NMX-36
A13: Masa grasa (kg) | B13: =M36_c_MG -> 10.981487 | C13: NMX-36
A14: Masa libre de grasa (kg) | B14: =M36_c_MLG -> 67.518513 | C14: NMX-36
A15: FMI | B15: =M36_c_IMG -> 3.5451597 | C15: NMX-36
A16: FFMI | B16: =M36_c_IMLG -> 21.797041 | C16: NMX-36
A17: Endomorfia | B17: =M16_c_Endo -> 4.146746 | C17: NMX-16
A18: Mesomorfia | B18: =M16_c_Meso -> 3.8497 | C18: NMX-16
A19: Ectomorfia | B19: =M16_c_Ecto -> 1.5084995 | C19: NMX-16
A20: Somatotipo | B20: =M16_c_Soma -> 04 - 04 - 02 | C20: NMX-16
A21: Somatocarta X | B21: =M16_c_SX -> -2.6382465 | C21: NMX-16
A22: Somatocarta Y | B22: =M16_c_SY -> 2.0441545 | C22: NMX-16
A23: ETM intraevaluador | B23: =M41_v_etm -> 0.29495762 | C23: NMX-41
A25: INDICADOR EDUCATIVO — NO DIAGNÓSTICO
A26: Edad metabólica: módulo NMX-34, EDUCATIVO y desactivado por defecto. No forma parte del diagnóstico antropométrico. No usar ante riesgo de TCA.
A27: =HYPERLINK("#M34_INICIO!A1","▶ Abrir módulo educativo (bajo su criterio)") -> ▶ Abrir módulo educativo (bajo su criterio)

Sheet M41_INICIO
A1: NUTRIMETRÍA · NMX-41
A2: Software acompañante para plicómetro · versión 1.0 · Fase 7 · especialidades y productos complementarios
A4: Navegación — use las pestañas inferiores del libro
A5: =HYPERLINK("#M41_DATOS!A1","▶ DATOS") -> ▶ DATOS | C5: =HYPERLINK("#M41_CALIBRACION!A1","▶ CALIBRACION") -> ▶ CALIBRACION | E5: =HYPERLINK("#M41_TECNICA!A1","▶ TECNICA") -> ▶ TECNICA | G5: =HYPERLINK("#M41_FIABILIDAD!A1","▶ FIABILIDAD") -> ▶ FIABILIDAD | I5: =HYPERLINK("#M41_SEGUIMIENTO!A1","▶ SEGUIMIENTO") -> ▶ SEGUIMIENTO | K5: =HYPERLINK("#M41_FUENTES!A1","▶ FUENTES") -> ▶ FUENTES | M5: =HYPERLINK("#M41_PRUEBAS!A1","▶ PRUEBAS") -> ▶ PRUEBAS | O5: =HYPERLINK("#M41_CONFIG!A1","▶ CONFIG") -> ▶ CONFIG
A6: Equipo y evaluador | C6: Control del instrumento | E6: Sitios y procedimiento | G6: Error técnico de medición | I6: ¿El cambio es real? | K6: Referencias y trazabilidad | M6: Control de calidad | O6: Constantes
A7: =HYPERLINK("#M41_CHANGELOG!A1","▶ CHANGELOG") -> ▶ CHANGELOG
A8: Historial
A10: Código del producto | C10: NMX-41
A11: Versión | C11: 1.0
A12: Fecha | C12: 2026-07-24
A13: Qué acompaña | C13: Cualquier plicómetro de uso profesional
A14: Complementos | C14: NMX-36 aplica ecuaciones de composición · NMX-20 integra pliegues y somatotipo
A15: Formato | C15: .xlsx sin macros · Microsoft 365 (Windows) y Excel 2021 · sin funciones matriciales
A16: Responsable | C16: Equipo Nutrimetría (completar por el titular)
A18: LA PREGUNTA QUE ESTE LIBRO RESPONDE
A19: Un pliegue bajó de dieciocho a diecisiete milímetros. ¿Cambió la persona o se equivocó quien midió? Sin conocer el error del evaluador esa pregunta no tiene respuesta, y se informan como cambios reales variaciones que son solo ruido del método.
A20: Este libro calcula el error propio de cada evaluador a partir de mediciones por duplicado, y con él establece cuánto debe cambiar un pliegue para que el cambio sea distinguible del error.
A21: También verifica el instrumento contra patrones de espesor conocido: un plicómetro descalibrado produce mediciones consistentes pero equivocadas, y ese error no se detecta repitiendo la medida.
A22: El seguimiento se hace sobre la SUMA de pliegues y no sobre pliegues aislados, porque al sumar varios sitios el error crece con la raíz del número de mediciones y la suma resulta proporcionalmente más sensible.
A24: AVISO DE ALCANCE — LÉALO ANTES DE USAR
A25: EXACTITUD MATEMÁTICA ≠ VALIDACIÓN CLÍNICA. Este archivo no está validado clínicamente y no constituye diagnóstico.
A26: Este libro NO estima densidad corporal, porcentaje de grasa ni somatotipo: se ocupa de la calidad de la medición previa. Para las ecuaciones de composición corporal use NMX-36 o NMX-20.
A27: El libro NO sustituye la formación práctica supervisada: describir la técnica no equivale a dominarla, y los criterios de error solo se alcanzan con entrenamiento.
A28: Los pliegues ESTIMAN el tejido adiposo subcutáneo. La referencia para composición corporal son la densitometría y el pesaje hidrostático.
A29: El error técnico es específico de cada evaluador, cada sitio anatómico y cada rango de espesor: no traslade el resultado de un sitio a otro ni de un evaluador a otro.
A30: Ninguna corrección posterior recupera mediciones tomadas con un instrumento descalibrado o con técnica deficiente.
A32: FLUJO DE USO
A33: 1 | C33: En DATOS registre el instrumento, su número de serie y el evaluador. Ambos deben quedar documentados en cada evaluación.
A34: 2 | C34: En CALIBRACIÓN verifique el plicómetro contra patrones de espesor conocido y complete la revisión mecánica. El libro emite un dictamen de aptitud.
A35: 3 | C35: Revise TÉCNICA antes de medir: secuencia, sitios anatómicos y condiciones que alteran el resultado.
A36: 4 | C36: En FIABILIDAD registre mediciones por duplicado en al menos diez personas para obtener su propio error técnico.
A37: 5 | C37: En SEGUIMIENTO compare dos evaluaciones: el libro indica si el cambio observado supera el error del método.
A38: 6 | C38: Verifique el instrumento cada seis meses y siempre después de una caída, y repita el cálculo de error cuando cambie de plicómetro.

Sheet M41_DATOS
A1: NUTRIMETRÍA · NMX-41
A2: Instrumento y evaluador
A4: =HYPERLINK("#M41_INICIO!A1","▶ VOLVER A INICIO") -> ▶ VOLVER A INICIO
A6: El plicómetro es un instrumento de medición: su resultado depende tanto del aparato como de quien lo usa. Este libro documenta ambos y cuantifica el error, para que usted sepa qué diferencias son reales y cuáles son ruido del método.
A10: IDENTIFICACIÓN DEL INSTRUMENTO
A11: Marca del plicómetro | C11: Harpenden
A12: Modelo | C12: —
A13: Número de serie | C13: — | L13: Permite trazar qué aparato tomó cada medición
A14: Fecha de adquisición | C14: 2024-03-15
A15: Presión declarada por el fabricante (g/mm²) | C15: 10 | L15: El estándar es 10 g/mm²
A16: Rango de medición (mm) | C16: 0 a 80
A17: Resolución de la escala (mm) | C17: 0.2 | L17: Cuánto vale la división más pequeña
A18: Fecha de la última verificación | C18: 2026-07-20
A19: Estado del instrumento | C19: Correcto
A21: EVALUADOR
A22: Nombre del evaluador | C22: Caso de ejemplo
A23: Nivel de acreditación | C23: En formación | L23: Condiciona el error esperable
A24: Fecha de la última evaluación de error | C24: 2026-07-20
A25: Número de mediciones realizadas en el último año | C25: 120
A26: ¿Midió siempre el mismo lado del cuerpo? | C26: Sí | L26: Por convención se mide el lado derecho
A27: Observaciones | C27: —
A29: Registre siempre QUIÉN midió y CON QUÉ aparato. Un cambio de evaluador o de instrumento entre dos evaluaciones introduce una fuente de variación que puede superar el cambio biológico que se busca detectar: en ese caso la comparación entre ambas mediciones deja de ser válida.

Sheet M41_CALIBRACION
A1: NUTRIMETRÍA · NMX-41
A2: Control del instrumento · verificación periódica
A4: =HYPERLINK("#M41_INICIO!A1","▶ VOLVER A INICIO") -> ▶ VOLVER A INICIO
A6: Un plicómetro descalibrado produce mediciones consistentes pero equivocadas: el error no se detecta repitiendo la medida, porque se repite igual. La única forma de detectarlo es verificar contra un patrón de espesor conocido y revisar la tensión del resorte.
A10: VERIFICACIÓN CONTRA PATRONES DE ESPESOR CONOCIDO
A11: Patrón | B11: Espesor real (mm) | C11: Lectura 1 | D11: Lectura 2 | E11: Lectura 3 | F11: Media | G11: Error (mm) | H11: Resultado
A12: Bloque patrón A | B12: 10 | C12: 10 | D12: 10.1 | E12: 10 | F12: =IF(COUNT(C12:E12)=0,"ND",AVERAGE(C12:E12)) -> 10.033333 | G12: =IF(OR(NOT(ISNUMBER(F12)),NOT(ISNUMBER(B12))),"ND",F12-B12) -> 0.033333333 | H12: =IF(NOT(ISNUMBER(G12)),"ND",IF(ABS(G12)<=M41_u_patron,"Dentro de tolerancia","FUERA DE TOLERANCIA: el instrumento requiere ajuste")) -> Dentro de tolerancia
A13: Bloque patrón B | B13: 20 | C13: 20 | D13: 20 | E13: 20.1 | F13: =IF(COUNT(C13:E13)=0,"ND",AVERAGE(C13:E13)) -> 20.033333 | G13: =IF(OR(NOT(ISNUMBER(F13)),NOT(ISNUMBER(B13))),"ND",F13-B13) -> 0.033333333 | H13: =IF(NOT(ISNUMBER(G13)),"ND",IF(ABS(G13)<=M41_u_patron,"Dentro de tolerancia","FUERA DE TOLERANCIA: el instrumento requiere ajuste")) -> Dentro de tolerancia
A14: Bloque patrón C | B14: 40 | C14: 40.2 | D14: 40.1 | E14: 40.2 | F14: =IF(COUNT(C14:E14)=0,"ND",AVERAGE(C14:E14)) -> 40.166667 | G14: =IF(OR(NOT(ISNUMBER(F14)),NOT(ISNUMBER(B14))),"ND",F14-B14) -> 0.16666667 | H14: =IF(NOT(ISNUMBER(G14)),"ND",IF(ABS(G14)<=M41_u_patron,"Dentro de tolerancia","FUERA DE TOLERANCIA: el instrumento requiere ajuste")) -> Dentro de tolerancia
A15: Bloque patrón D | B15: 60 | C15: 60.1 | D15: 60.2 | E15: 60.1 | F15: =IF(COUNT(C15:E15)=0,"ND",AVERAGE(C15:E15)) -> 60.133333 | G15: =IF(OR(NOT(ISNUMBER(F15)),NOT(ISNUMBER(B15))),"ND",F15-B15) -> 0.13333333 | H15: =IF(NOT(ISNUMBER(G15)),"ND",IF(ABS(G15)<=M41_u_patron,"Dentro de tolerancia","FUERA DE TOLERANCIA: el instrumento requiere ajuste")) -> Dentro de tolerancia
A16: Error medio del instrumento | G16: =IF(COUNT(G12:G15)=0,"ND",AVERAGE(G12:G15)) -> 0.091666667 | H16: =IF(NOT(ISNUMBER(G16)),"ND",IF(ABS(G16)<=M41_u_patron,"Instrumento apto para uso","Instrumento NO apto: derive a ajuste antes de seguir midiendo")) -> Instrumento apto para uso
A18: REVISIÓN MECÁNICA
A19: ¿La aguja marca cero con las ramas cerradas? | C19: Sí
A20: ¿Las ramas cierran de forma paralela? | C20: Sí
A21: ¿El resorte recupera su posición sin trabarse? | C21: Sí
A22: ¿Las superficies de contacto están limpias y sin desgaste? | C22: Sí
A23: ¿La escala se lee con nitidez? | C23: Sí
A24: ¿El instrumento ha sufrido caídas o golpes desde la última revisión? | C24: No
A26: Verificaciones conformes | C26: =COUNTIF(C19:C23,"Sí")+COUNTIF(C24,"No") -> 6 | L26: La última pregunta invierte el sentido: allí lo esperable es No
A27: Estado de la revisión mecánica | C27: =IF(C26=6,"Revisión mecánica conforme en los seis puntos.","REVISAR: "&(6-C26)&" punto(s) no conforme(s). Resuélvalos antes de usar el instrumento.") -> Revisión mecánica conforme en los seis puntos.
A28: DICTAMEN DEL INSTRUMENTO | C28: =IF(OR(NOT(ISNUMBER(G16)),NOT(ISNUMBER(C26))),"ND",IF(AND(ABS(G16)<=M41_u_patron,C26=6),"APTO PARA USO","NO APTO: corrija los hallazgos antes de continuar midiendo")) -> APTO PARA USO
A30: Verifique el instrumento al menos cada seis meses, y siempre después de una caída o de un periodo prolongado sin uso. Un plicómetro cuya lectura se desvía de forma constante introduce un sesgo sistemático: todas las mediciones quedan corridas en la misma dirección, algo que ningún cálculo posterior puede corregir si no se documentó.

Sheet M41_TECNICA
A1: NUTRIMETRÍA · NMX-41
A2: Procedimiento de medición · sitios y secuencia
A4: =HYPERLINK("#M41_INICIO!A1","▶ VOLVER A INICIO") -> ▶ VOLVER A INICIO
A6: SECUENCIA DE CADA MEDICIÓN
A7: 1 | C7: Marque el punto anatómico antes de tomar el pliegue: si se mide sin marcar, cada repetición cae en un lugar distinto y el error se dispara.
A8: 2 | C8: Tome el pliegue con los dedos pulgar e índice, a un centímetro del punto marcado, levantando piel y tejido subcutáneo sin incluir músculo.
A9: 3 | C9: Aplique las ramas del plicómetro perpendiculares al pliegue, sobre el punto marcado, manteniendo la toma con los dedos.
A10: 4 | C10: Espere dos segundos antes de leer: el tejido se comprime y la aguja se estabiliza. Leer antes sobreestima; esperar demasiado subestima.
A11: 5 | C11: Lea sin soltar el pliegue y registre de inmediato.
A12: 6 | C12: Mida todos los sitios en orden y recién entonces repita la serie completa: medir dos veces seguidas el mismo sitio subestima la segunda lectura por compresión del tejido.
A14: REFERENCIA DE SITIOS ANATÓMICOS
A15: Sitio | B15: Ubicación del punto | C15: Dirección del pliegue | D15: Posición de la persona
A16: =INDEX(M41_rng_sitios,1,1) -> Tríceps | B16: =INDEX(M41_rng_sitios,1,2) -> Punto medio entre acromion y olécranon, cara posterior del brazo | C16: =INDEX(M41_rng_sitios,1,3) -> Vertical | D16: =INDEX(M41_rng_sitios,1,4) -> De pie, brazo relajado
A17: =INDEX(M41_rng_sitios,2,1) -> Subescapular | B17: =INDEX(M41_rng_sitios,2,2) -> Dos centímetros por debajo del ángulo inferior de la escápula | C17: =INDEX(M41_rng_sitios,2,3) -> Oblicua, hacia abajo y afuera | D17: =INDEX(M41_rng_sitios,2,4) -> De pie, brazos a los lados
A18: =INDEX(M41_rng_sitios,3,1) -> Bíceps | B18: =INDEX(M41_rng_sitios,3,2) -> Punto medio del brazo, cara anterior, sobre el vientre del bíceps | C18: =INDEX(M41_rng_sitios,3,3) -> Vertical | D18: =INDEX(M41_rng_sitios,3,4) -> De pie, brazo relajado y supinado
A19: =INDEX(M41_rng_sitios,4,1) -> Suprailíaco | B19: =INDEX(M41_rng_sitios,4,2) -> Sobre la cresta ilíaca, en la línea axilar media | C19: =INDEX(M41_rng_sitios,4,3) -> Oblicua, siguiendo la cresta | D19: =INDEX(M41_rng_sitios,4,4) -> De pie, brazo separado
A20: =INDEX(M41_rng_sitios,5,1) -> Supraespinal | B20: =INDEX(M41_rng_sitios,5,2) -> Intersección de la línea axilar anterior con la cresta ilíaca | C20: =INDEX(M41_rng_sitios,5,3) -> Oblicua, hacia abajo y adentro | D20: =INDEX(M41_rng_sitios,5,4) -> De pie, brazo relajado
A21: =INDEX(M41_rng_sitios,6,1) -> Abdominal | B21: =INDEX(M41_rng_sitios,6,2) -> Cinco centímetros a la derecha del ombligo | C21: =INDEX(M41_rng_sitios,6,3) -> Vertical | D21: =INDEX(M41_rng_sitios,6,4) -> De pie, abdomen relajado
A22: =INDEX(M41_rng_sitios,7,1) -> Muslo anterior | B22: =INDEX(M41_rng_sitios,7,2) -> Punto medio entre pliegue inguinal y borde superior de la rótula | C22: =INDEX(M41_rng_sitios,7,3) -> Vertical | D22: =INDEX(M41_rng_sitios,7,4) -> Sentado, rodilla a noventa grados
A23: =INDEX(M41_rng_sitios,8,1) -> Pantorrilla medial | B23: =INDEX(M41_rng_sitios,8,2) -> Cara medial, en el perímetro máximo | C23: =INDEX(M41_rng_sitios,8,3) -> Vertical | D23: =INDEX(M41_rng_sitios,8,4) -> Sentado o de pie con la pierna apoyada
A25: CONDICIONES QUE ALTERAN LA MEDICIÓN
A26: Ejercicio reciente | B26: La redistribución de líquido tras el ejercicio modifica el espesor del pliegue: mida antes de entrenar o varias horas después.
A27: Estado de hidratación | B27: La deshidratación y la retención de líquido cambian el resultado sin que haya cambiado la grasa corporal.
A28: Momento del ciclo menstrual | B28: La retención de líquido puede alterar las mediciones: registre en qué fase se midió y procure repetir en la misma.
A29: Temperatura ambiente | B29: El frío contrae los tejidos y dificulta tomar el pliegue de forma reproducible.
A30: Cambio de evaluador | B30: Es la principal fuente de variación entre dos evaluaciones. Si cambia el evaluador, la comparación pierde validez salvo que se conozca el error entre ambos.
A31: Cambio de instrumento | B31: Dos plicómetros de marcas distintas pueden diferir de forma sistemática: no compare mediciones tomadas con aparatos diferentes.
A33: Estandarizar las condiciones importa tanto como la técnica. Una medición tomada en condiciones distintas a la anterior no es comparable, aunque la técnica haya sido impecable en ambas.

Sheet M41_SEGUIMIENTO
A1: NUTRIMETRÍA · NMX-41
A2: ¿El cambio observado es real o es error de medición?
A4: =HYPERLINK("#M41_INICIO!A1","▶ VOLVER A INICIO") -> ▶ VOLVER A INICIO
A6: Esta es la pregunta que un plicómetro debe poder responder y que casi ningún software responde. Un pliegue que baja de 18 a 17 milímetros puede reflejar un cambio real o simplemente el error de quien mide. Aquí se compara el cambio observado con el error propio del evaluador.
A10: COMPARACIÓN ENTRE DOS EVALUACIONES
A11: Sitio | B11: Evaluación inicial (mm) | C11: Evaluación de control (mm) | D11: Cambio (mm) | E11: Cambio mínimo detectable | F11: ¿Distinguible del error?
A12: Tríceps | B12: 12.4 | C12: 11 | D12: =IF(OR(NOT(ISNUMBER(B12)),NOT(ISNUMBER(C12))),"",C12-B12) -> -1.4 | E12: =IF(NOT(ISNUMBER(D12)),"",M41_v_mdc) -> 0.81758082 | F12: =IF(NOT(ISNUMBER(D12)),"",IF(ABS(D12)>M41_v_mdc,"Sí · el cambio supera el error","No · queda dentro del error de medición")) -> Sí · el cambio supera el error
A13: Subescapular | B13: 14 | C13: 12.8 | D13: =IF(OR(NOT(ISNUMBER(B13)),NOT(ISNUMBER(C13))),"",C13-B13) -> -1.2 | E13: =IF(NOT(ISNUMBER(D13)),"",M41_v_mdc) -> 0.81758082 | F13: =IF(NOT(ISNUMBER(D13)),"",IF(ABS(D13)>M41_v_mdc,"Sí · el cambio supera el error","No · queda dentro del error de medición")) -> Sí · el cambio supera el error
A14: Bíceps | B14: 6 | C14: 5.6 | D14: =IF(OR(NOT(ISNUMBER(B14)),NOT(ISNUMBER(C14))),"",C14-B14) -> -0.4 | E14: =IF(NOT(ISNUMBER(D14)),"",M41_v_mdc) -> 0.81758082 | F14: =IF(NOT(ISNUMBER(D14)),"",IF(ABS(D14)>M41_v_mdc,"Sí · el cambio supera el error","No · queda dentro del error de medición")) -> No · queda dentro del error de medición
A15: Suprailíaco | B15: 16 | C15: 14.2 | D15: =IF(OR(NOT(ISNUMBER(B15)),NOT(ISNUMBER(C15))),"",C15-B15) -> -1.8 | E15: =IF(NOT(ISNUMBER(D15)),"",M41_v_mdc) -> 0.81758082 | F15: =IF(NOT(ISNUMBER(D15)),"",IF(ABS(D15)>M41_v_mdc,"Sí · el cambio supera el error","No · queda dentro del error de medición")) -> Sí · el cambio supera el error
A16: Abdominal | B16: 18 | C16: 16.2 | D16: =IF(OR(NOT(ISNUMBER(B16)),NOT(ISNUMBER(C16))),"",C16-B16) -> -1.8 | E16: =IF(NOT(ISNUMBER(D16)),"",M41_v_mdc) -> 0.81758082 | F16: =IF(NOT(ISNUMBER(D16)),"",IF(ABS(D16)>M41_v_mdc,"Sí · el cambio supera el error","No · queda dentro del error de medición")) -> Sí · el cambio supera el error
A17: Muslo anterior | B17: 10.2 | C17: 9.4 | D17: =IF(OR(NOT(ISNUMBER(B17)),NOT(ISNUMBER(C17))),"",C17-B17) -> -0.8 | E17: =IF(NOT(ISNUMBER(D17)),"",M41_v_mdc) -> 0.81758082 | F17: =IF(NOT(ISNUMBER(D17)),"",IF(ABS(D17)>M41_v_mdc,"Sí · el cambio supera el error","No · queda dentro del error de medición")) -> No · queda dentro del error de medición
D18: =IF(OR(NOT(ISNUMBER(B18)),NOT(ISNUMBER(C18))),"",C18-B18) | E18: =IF(NOT(ISNUMBER(D18)),"",M41_v_mdc) | F18: =IF(NOT(ISNUMBER(D18)),"",IF(ABS(D18)>M41_v_mdc,"Sí · el cambio supera el error","No · queda dentro del error de medición"))
D19: =IF(OR(NOT(ISNUMBER(B19)),NOT(ISNUMBER(C19))),"",C19-B19) | E19: =IF(NOT(ISNUMBER(D19)),"",M41_v_mdc) | F19: =IF(NOT(ISNUMBER(D19)),"",IF(ABS(D19)>M41_v_mdc,"Sí · el cambio supera el error","No · queda dentro del error de medición"))
A20: SUMA DE PLIEGUES | B20: =SUM(B12:B19) -> 76.6 | C20: =SUM(C12:C19) -> 69.2 | D20: =IF(OR(NOT(ISNUMBER(B20)),NOT(ISNUMBER(C20))),"",C20-B20) -> -7.4 | E20: =IF(COUNT(D12:D19)=0,"ND",M41_k_z*SQRT(2)*M41_v_etm*SQRT(COUNT(D12:D19))) -> 2.0026558 | F20: =IF(OR(NOT(ISNUMBER(D20)),NOT(ISNUMBER(E20))),"ND",IF(ABS(D20)>E20,"Sí · el cambio de la suma supera el error","No · queda dentro del error de medición")) -> Sí · el cambio de la suma supera el error
A22: POR QUÉ LA SUMA ES MÁS SENSIBLE QUE UN PLIEGUE AISLADO
A23: Error de un pliegue individual (mm) | C23: =M41_v_etm -> 0.29495762
A24: Número de pliegues sumados | C24: =COUNT(D12:D19) -> 6
A25: Error de la suma (mm) | C25: =IF(OR(NOT(ISNUMBER(M41_v_etm)),NOT(ISNUMBER(C24))),"ND",M41_v_etm*SQRT(C24)) -> 0.72249567 | L25: El error crece con la raíz del número de pliegues, no de forma proporcional
A26: Cambio relativo mínimo detectable en la suma | C26: =IF(OR(NOT(ISNUMBER(E20)),NOT(ISNUMBER(B20)),B20=0),"ND",E20/B20) -> 0.026144332
A27: Qué significa | C27: =IF(OR(NOT(ISNUMBER(E20)),NOT(ISNUMBER(M41_v_mdc))),"ND","Cada pliegue por separado necesita cambiar más de "&TEXT(M41_v_mdc,"0.00")&" mm para ser distinguible del error. La suma de "&TEXT(C24,"0")&" pliegues necesita cambiar más de "&TEXT(E20,"0.00")&" mm, que representa una proporción MENOR del total: por eso el seguimiento se hace sobre la suma y no sobre pliegues aislados.") -> Cada pliegue por separado necesita cambiar más de 001 mm para ser distinguible del error. La suma de 6 pliegues necesita cambiar más de 002 mm, que representa una proporción MENOR del total: por eso el seguimiento se hace sobre la suma y no sobre pliegues aislados.
A29: CONDICIONES DE COMPARABILIDAD
A30: ¿Midió el mismo evaluador ambas veces? | C30: Sí
A31: ¿Usó el mismo plicómetro? | C31: Sí
A32: ¿Se respetaron condiciones similares de hidratación y horario? | C32: Sí
A33: ¿El instrumento estaba verificado en ambas ocasiones? | C33: Sí
A34: Validez de la comparación | C34: =IF(COUNTIF(C30:C33,"Sí")=4,"Las cuatro condiciones se cumplen: la comparación entre ambas evaluaciones es válida.","ATENCIÓN: "&(4-COUNTIF(C30:C33,"Sí"))&" condición(es) no se cumple(n). El cambio observado puede deberse a esa diferencia y no a un cambio real de la persona.") -> Las cuatro condiciones se cumplen: la comparación entre ambas evaluaciones es válida.
A36: CONCLUSIÓN DEL SEGUIMIENTO | C36: =IF(OR(NOT(ISNUMBER(D20)),NOT(ISNUMBER(E20))),"ND: faltan datos",IF(COUNTIF(C30:C33,"Sí")<4,"No concluyente: primero resuelva las condiciones de comparabilidad.",IF(ABS(D20)>E20,"Cambio DISTINGUIBLE del error de medición: la suma de pliegues varió "&TEXT(D20,"+0.0;-0.0")&" mm, por sobre el umbral de "&TEXT(E20,"0.00")&" mm.","Cambio NO distinguible del error: la variación de "&TEXT(D20,"+0.0;-0.0")&" mm queda dentro del margen del método. No informe un cambio como si fuera real."))) -> Cambio DISTINGUIBLE del error de medición: la suma de pliegues varió -07 mm, por sobre el umbral de 002 mm.
A38: Sitio | B38: Cambio (mm)
A39: =A12 -> Tríceps | B39: =D12 -> -1.4
A40: =A13 -> Subescapular | B40: =D13 -> -1.2
A41: =A14 -> Bíceps | B41: =D14 -> -0.4
A42: =A15 -> Suprailíaco | B42: =D15 -> -1.8
A43: =A16 -> Abdominal | B43: =D16 -> -1.8
A44: =A17 -> Muslo anterior | B44: =D17 -> -0.8
A46: Informar un cambio que no supera el error de medición es un error frecuente y evitable. Si la variación queda dentro del margen del método, la respuesta correcta es que no se puede afirmar que haya cambiado, no que se mantuvo igual: ambas cosas son distintas.

Sheet M41_FIABILIDAD
A1: NUTRIMETRÍA · NMX-41
A2: Error técnico de medición · cuánto se equivoca este evaluador
A4: =HYPERLINK("#M41_INICIO!A1","▶ VOLVER A INICIO") -> ▶ VOLVER A INICIO
A6: Para conocer su propio error, mida el mismo pliegue DOS veces en al menos diez personas distintas, completando la serie de sitios entre ambas repeticiones. No mida dos veces seguidas el mismo sitio: la compresión del tejido hace que la segunda lectura sea menor y el error calculado saldría falsamente bajo.
A11: MEDICIONES POR DUPLICADO
A12: Nº | B12: Sujeto | C12: Sitio medido | D12: Medida 1 (mm) | E12: Medida 2 (mm) | F12: Media | G12: Diferencia | H12: Diferencia² | I12: Control
A13: 1 | B13: Sujeto 1 | C13: Tríceps | D13: 12.4 | E13: 12.1 | F13: =IF(OR(NOT(ISNUMBER(D13)),NOT(ISNUMBER(E13))),"",(D13+E13)/2) -> 12.25 | G13: =IF(OR(NOT(ISNUMBER(D13)),NOT(ISNUMBER(E13))),"",D13-E13) -> 0.3 | H13: =IF(NOT(ISNUMBER(G13)),"",G13^2) -> 0.09 | I13: =IF(OR(NOT(ISNUMBER(G13)),NOT(ISNUMBER(F13)),F13=0),"",IF(ABS(G13)/F13>M41_u_dif,"REVISAR: las dos medidas difieren más del 5%","OK")) -> OK
A14: 2 | B14: Sujeto 2 | C14: Tríceps | D14: 18.6 | E14: 18.9 | F14: =IF(OR(NOT(ISNUMBER(D14)),NOT(ISNUMBER(E14))),"",(D14+E14)/2) -> 18.75 | G14: =IF(OR(NOT(ISNUMBER(D14)),NOT(ISNUMBER(E14))),"",D14-E14) -> -0.3 | H14: =IF(NOT(ISNUMBER(G14)),"",G14^2) -> 0.09 | I14: =IF(OR(NOT(ISNUMBER(G14)),NOT(ISNUMBER(F14)),F14=0),"",IF(ABS(G14)/F14>M41_u_dif,"REVISAR: las dos medidas difieren más del 5%","OK")) -> OK
A15: 3 | B15: Sujeto 3 | C15: Tríceps | D15: 9.2 | E15: 9.5 | F15: =IF(OR(NOT(ISNUMBER(D15)),NOT(ISNUMBER(E15))),"",(D15+E15)/2) -> 9.35 | G15: =IF(OR(NOT(ISNUMBER(D15)),NOT(ISNUMBER(E15))),"",D15-E15) -> -0.3 | H15: =IF(NOT(ISNUMBER(G15)),"",G15^2) -> 0.09 | I15: =IF(OR(NOT(ISNUMBER(G15)),NOT(ISNUMBER(F15)),F15=0),"",IF(ABS(G15)/F15>M41_u_dif,"REVISAR: las dos medidas difieren más del 5%","OK")) -> OK
A16: 4 | B16: Sujeto 4 | C16: Tríceps | D16: 24.8 | E16: 24.2 | F16: =IF(OR(NOT(ISNUMBER(D16)),NOT(ISNUMBER(E16))),"",(D16+E16)/2) -> 24.5 | G16: =IF(OR(NOT(ISNUMBER(D16)),NOT(ISNUMBER(E16))),"",D16-E16) -> 0.6 | H16: =IF(NOT(ISNUMBER(G16)),"",G16^2) -> 0.36 | I16: =IF(OR(NOT(ISNUMBER(G16)),NOT(ISNUMBER(F16)),F16=0),"",IF(ABS(G16)/F16>M41_u_dif,"REVISAR: las dos medidas difieren más del 5%","OK")) -> OK
A17: 5 | B17: Sujeto 5 | C17: Tríceps | D17: 15 | E17: 15.4 | F17: =IF(OR(NOT(ISNUMBER(D17)),NOT(ISNUMBER(E17))),"",(D17+E17)/2) -> 15.2 | G17: =IF(OR(NOT(ISNUMBER(D17)),NOT(ISNUMBER(E17))),"",D17-E17) -> -0.4 | H17: =IF(NOT(ISNUMBER(G17)),"",G17^2) -> 0.16 | I17: =IF(OR(NOT(ISNUMBER(G17)),NOT(ISNUMBER(F17)),F17=0),"",IF(ABS(G17)/F17>M41_u_dif,"REVISAR: las dos medidas difieren más del 5%","OK")) -> OK
A18: 6 | B18: Sujeto 6 | C18: Tríceps | D18: 21.3 | E18: 21 | F18: =IF(OR(NOT(ISNUMBER(D18)),NOT(ISNUMBER(E18))),"",(D18+E18)/2) -> 21.15 | G18: =IF(OR(NOT(ISNUMBER(D18)),NOT(ISNUMBER(E18))),"",D18-E18) -> 0.3 | H18: =IF(NOT(ISNUMBER(G18)),"",G18^2) -> 0.09 | I18: =IF(OR(NOT(ISNUMBER(G18)),NOT(ISNUMBER(F18)),F18=0),"",IF(ABS(G18)/F18>M41_u_dif,"REVISAR: las dos medidas difieren más del 5%","OK")) -> OK
A19: 7 | B19: Sujeto 7 | C19: Tríceps | D19: 11.7 | E19: 11.4 | F19: =IF(OR(NOT(ISNUMBER(D19)),NOT(ISNUMBER(E19))),"",(D19+E19)/2) -> 11.55 | G19: =IF(OR(NOT(ISNUMBER(D19)),NOT(ISNUMBER(E19))),"",D19-E19) -> 0.3 | H19: =IF(NOT(ISNUMBER(G19)),"",G19^2) -> 0.09 | I19: =IF(OR(NOT(ISNUMBER(G19)),NOT(ISNUMBER(F19)),F19=0),"",IF(ABS(G19)/F19>M41_u_dif,"REVISAR: las dos medidas difieren más del 5%","OK")) -> OK
A20: 8 | B20: Sujeto 8 | C20: Tríceps | D20: 17.4 | E20: 17.9 | F20: =IF(OR(NOT(ISNUMBER(D20)),NOT(ISNUMBER(E20))),"",(D20+E20)/2) -> 17.65 | G20: =IF(OR(NOT(ISNUMBER(D20)),NOT(ISNUMBER(E20))),"",D20-E20) -> -0.5 | H20: =IF(NOT(ISNUMBER(G20)),"",G20^2) -> 0.25 | I20: =IF(OR(NOT(ISNUMBER(G20)),NOT(ISNUMBER(F20)),F20=0),"",IF(ABS(G20)/F20>M41_u_dif,"REVISAR: las dos medidas difieren más del 5%","OK")) -> OK
A21: 9 | B21: Sujeto 9 | C21: Tríceps | D21: 28.2 | E21: 27.6 | F21: =IF(OR(NOT(ISNUMBER(D21)),NOT(ISNUMBER(E21))),"",(D21+E21)/2) -> 27.9 | G21: =IF(OR(NOT(ISNUMBER(D21)),NOT(ISNUMBER(E21))),"",D21-E21) -> 0.6 | H21: =IF(NOT(ISNUMBER(G21)),"",G21^2) -> 0.36 | I21: =IF(OR(NOT(ISNUMBER(G21)),NOT(ISNUMBER(F21)),F21=0),"",IF(ABS(G21)/F21>M41_u_dif,"REVISAR: las dos medidas difieren más del 5%","OK")) -> OK
A22: 10 | B22: Sujeto 10 | C22: Tríceps | D22: 13.9 | E22: 14.3 | F22: =IF(OR(NOT(ISNUMBER(D22)),NOT(ISNUMBER(E22))),"",(D22+E22)/2) -> 14.1 | G22: =IF(OR(NOT(ISNUMBER(D22)),NOT(ISNUMBER(E22))),"",D22-E22) -> -0.4 | H22: =IF(NOT(ISNUMBER(G22)),"",G22^2) -> 0.16 | I22: =IF(OR(NOT(ISNUMBER(G22)),NOT(ISNUMBER(F22)),F22=0),"",IF(ABS(G22)/F22>M41_u_dif,"REVISAR: las dos medidas difieren más del 5%","OK")) -> OK
A23: 11 | F23: =IF(OR(NOT(ISNUMBER(D23)),NOT(ISNUMBER(E23))),"",(D23+E23)/2) | G23: =IF(OR(NOT(ISNUMBER(D23)),NOT(ISNUMBER(E23))),"",D23-E23) | H23: =IF(NOT(ISNUMBER(G23)),"",G23^2) | I23: =IF(OR(NOT(ISNUMBER(G23)),NOT(ISNUMBER(F23)),F23=0),"",IF(ABS(G23)/F23>M41_u_dif,"REVISAR: las dos medidas difieren más del 5%","OK"))
A24: 12 | F24: =IF(OR(NOT(ISNUMBER(D24)),NOT(ISNUMBER(E24))),"",(D24+E24)/2) | G24: =IF(OR(NOT(ISNUMBER(D24)),NOT(ISNUMBER(E24))),"",D24-E24) | H24: =IF(NOT(ISNUMBER(G24)),"",G24^2) | I24: =IF(OR(NOT(ISNUMBER(G24)),NOT(ISNUMBER(F24)),F24=0),"",IF(ABS(G24)/F24>M41_u_dif,"REVISAR: las dos medidas difieren más del 5%","OK"))
A25: 13 | F25: =IF(OR(NOT(ISNUMBER(D25)),NOT(ISNUMBER(E25))),"",(D25+E25)/2) | G25: =IF(OR(NOT(ISNUMBER(D25)),NOT(ISNUMBER(E25))),"",D25-E25) | H25: =IF(NOT(ISNUMBER(G25)),"",G25^2) | I25: =IF(OR(NOT(ISNUMBER(G25)),NOT(ISNUMBER(F25)),F25=0),"",IF(ABS(G25)/F25>M41_u_dif,"REVISAR: las dos medidas difieren más del 5%","OK"))
A26: 14 | F26: =IF(OR(NOT(ISNUMBER(D26)),NOT(ISNUMBER(E26))),"",(D26+E26)/2) | G26: =IF(OR(NOT(ISNUMBER(D26)),NOT(ISNUMBER(E26))),"",D26-E26) | H26: =IF(NOT(ISNUMBER(G26)),"",G26^2) | I26: =IF(OR(NOT(ISNUMBER(G26)),NOT(ISNUMBER(F26)),F26=0),"",IF(ABS(G26)/F26>M41_u_dif,"REVISAR: las dos medidas difieren más del 5%","OK"))
A27: 15 | F27: =IF(OR(NOT(ISNUMBER(D27)),NOT(ISNUMBER(E27))),"",(D27+E27)/2) | G27: =IF(OR(NOT(ISNUMBER(D27)),NOT(ISNUMBER(E27))),"",D27-E27) | H27: =IF(NOT(ISNUMBER(G27)),"",G27^2) | I27: =IF(OR(NOT(ISNUMBER(G27)),NOT(ISNUMBER(F27)),F27=0),"",IF(ABS(G27)/F27>M41_u_dif,"REVISAR: las dos medidas difieren más del 5%","OK"))
A28: 16 | F28: =IF(OR(NOT(ISNUMBER(D28)),NOT(ISNUMBER(E28))),"",(D28+E28)/2) | G28: =IF(OR(NOT(ISNUMBER(D28)),NOT(ISNUMBER(E28))),"",D28-E28) | H28: =IF(NOT(ISNUMBER(G28)),"",G28^2) | I28: =IF(OR(NOT(ISNUMBER(G28)),NOT(ISNUMBER(F28)),F28=0),"",IF(ABS(G28)/F28>M41_u_dif,"REVISAR: las dos medidas difieren más del 5%","OK"))
A29: 17 | F29: =IF(OR(NOT(ISNUMBER(D29)),NOT(ISNUMBER(E29))),"",(D29+E29)/2) | G29: =IF(OR(NOT(ISNUMBER(D29)),NOT(ISNUMBER(E29))),"",D29-E29) | H29: =IF(NOT(ISNUMBER(G29)),"",G29^2) | I29: =IF(OR(NOT(ISNUMBER(G29)),NOT(ISNUMBER(F29)),F29=0),"",IF(ABS(G29)/F29>M41_u_dif,"REVISAR: las dos medidas difieren más del 5%","OK"))
A30: 18 | F30: =IF(OR(NOT(ISNUMBER(D30)),NOT(ISNUMBER(E30))),"",(D30+E30)/2) | G30: =IF(OR(NOT(ISNUMBER(D30)),NOT(ISNUMBER(E30))),"",D30-E30) | H30: =IF(NOT(ISNUMBER(G30)),"",G30^2) | I30: =IF(OR(NOT(ISNUMBER(G30)),NOT(ISNUMBER(F30)),F30=0),"",IF(ABS(G30)/F30>M41_u_dif,"REVISAR: las dos medidas difieren más del 5%","OK"))
A31: 19 | F31: =IF(OR(NOT(ISNUMBER(D31)),NOT(ISNUMBER(E31))),"",(D31+E31)/2) | G31: =IF(OR(NOT(ISNUMBER(D31)),NOT(ISNUMBER(E31))),"",D31-E31) | H31: =IF(NOT(ISNUMBER(G31)),"",G31^2) | I31: =IF(OR(NOT(ISNUMBER(G31)),NOT(ISNUMBER(F31)),F31=0),"",IF(ABS(G31)/F31>M41_u_dif,"REVISAR: las dos medidas difieren más del 5%","OK"))
A32: 20 | F32: =IF(OR(NOT(ISNUMBER(D32)),NOT(ISNUMBER(E32))),"",(D32+E32)/2) | G32: =IF(OR(NOT(ISNUMBER(D32)),NOT(ISNUMBER(E32))),"",D32-E32) | H32: =IF(NOT(ISNUMBER(G32)),"",G32^2) | I32: =IF(OR(NOT(ISNUMBER(G32)),NOT(ISNUMBER(F32)),F32=0),"",IF(ABS(G32)/F32>M41_u_dif,"REVISAR: las dos medidas difieren más del 5%","OK"))
A33: TOTALES | F33: =IF(COUNT(F13:F32)=0,"ND",AVERAGE(F13:F32)) -> 17.24 | G33: =COUNT(G13:G32) -> 10 | H33: =SUM(H13:H32) -> 1.74 | I33: =COUNTIF(I13:I32,"REVISAR*")&" con diferencia sobre el 5%" -> 0 con diferencia sobre el 5%
A35: CÁLCULO DEL ERROR TÉCNICO DE MEDICIÓN
A36: Número de pares medidos | C36: =G33 -> 10
A37: Suma de las diferencias al cuadrado | C37: =H33 -> 1.74
A38: Media general de las mediciones (mm) | C38: =F33 -> 17.24
A39: ERROR TÉCNICO DE MEDICIÓN (mm) | C39: =IF(OR(NOT(ISNUMBER(C36)),C36=0,NOT(ISNUMBER(C37))),"ND: faltan mediciones",SQRT(C37/(2*C36))) -> 0.29495762 | L39: Raíz de la suma de diferencias al cuadrado dividida por dos veces n
A40: ERROR RELATIVO (%) | C40: =IF(OR(NOT(ISNUMBER(C39)),NOT(ISNUMBER(C38)),C38=0),"ND",C39/C38) -> 0.017108911
A41: Desviación estándar entre sujetos (mm) | C41: =IF(COUNT(F13:F32)<2,"ND",STDEV(F13:F32)) -> 5.9407164
A42: Coeficiente de fiabilidad | C42: =IF(OR(NOT(ISNUMBER(C39)),NOT(ISNUMBER(C41)),C41=0),"ND",1-(C39^2/C41^2)) -> 0.99753486 | L42: Proporción de la variación observada que NO se explica por error de medición
A44: LECTURA DE LA FIABILIDAD
A45: Error relativo frente al criterio | C45: =IF(NOT(ISNUMBER(C40)),"ND",IF(C40<=M41_u_intra,"El error relativo de "&TEXT(C40,"0.00%")&" cumple el criterio para un mismo evaluador, que es de "&TEXT(M41_u_intra,"0%")&".",IF(C40<=M41_u_inter,"El error relativo de "&TEXT(C40,"0.00%")&" supera el criterio para un mismo evaluador pero se mantiene bajo el criterio entre evaluadores. Conviene entrenar la técnica antes de usar estas mediciones para seguimiento fino.","El error relativo de "&TEXT(C40,"0.00%")&" SUPERA ambos criterios. Las mediciones no son suficientemente reproducibles: revise la técnica con supervisión antes de continuar."))) -> El error relativo de 002% cumple el criterio para un mismo evaluador, que es de 5%.
A46: Coeficiente de fiabilidad frente al criterio | C46: =IF(NOT(ISNUMBER(C42)),"ND",IF(C42>=M41_u_R,"La fiabilidad de "&TEXT(C42,"0.000")&" alcanza el mínimo de "&TEXT(M41_u_R,"0.00")&": la variación observada entre sujetos se debe mayormente a diferencias reales y no al error del método.","La fiabilidad de "&TEXT(C42,"0.000")&" queda bajo el mínimo: una parte importante de lo que usted observa es error de medición, no diferencia real.")) -> La fiabilidad de 0.001 alcanza el mínimo de 001: la variación observada entre sujetos se debe mayormente a diferencias reales y no al error del método.
A47: Pares con diferencia sobre el cinco por ciento | C47: =COUNTIF(I13:I32,"REVISAR*") -> 0 | L47: Cada uno merece revisión: suelen indicar un punto anatómico mal marcado
A49: CAMBIO MÍNIMO DETECTABLE
...

Sheet M41_FUENTES
A1: NUTRIMETRÍA · NMX-41
A2: Referencias, fórmulas y trazabilidad
A4: =HYPERLINK("#M41_INICIO!A1","▶ VOLVER A INICIO") -> ▶ VOLVER A INICIO
A6: MÉTODOS Y REFERENCIAS
A7: Elemento | B7: Detalle
A8: Protocolo de medición | B8: Sitios anatómicos, dirección del pliegue y posición corporal siguen el protocolo de la Sociedad Internacional para el Avance de la Cineantropometría, de uso extendido en evaluación antropométrica. Este libro describe el procedimiento pero NO sustituye la formación práctica supervisada, que es la única vía para alcanzar los criterios de error exigidos.
A9: Error técnico de medición | B9: Se calcula como la raíz cuadrada de la suma de las diferencias al cuadrado entre mediciones duplicadas, dividida por dos veces el número de pares. Es la medida clásica de error de medición en antropometría y se expresa en las mismas unidades que la variable, en este caso milímetros.
A10: Error relativo | B10: Es el error técnico expresado como porcentaje de la media de las mediciones. Permite comparar el desempeño entre sitios de distinto espesor: un error de medio milímetro pesa mucho más en un pliegue de seis milímetros que en uno de treinta.
A11: Criterios de aceptación | B11: Los límites de cinco por ciento para un mismo evaluador y siete coma cinco por ciento entre evaluadores corresponden a los criterios de acreditación antropométrica de uso internacional para pliegues cutáneos. Son editables en CONFIG.
A12: Coeficiente de fiabilidad | B12: Se obtiene restando de uno el cociente entre el cuadrado del error técnico y el cuadrado de la desviación estándar entre sujetos. Expresa qué proporción de la variación observada corresponde a diferencias reales y no a error de medición. El mínimo habitual es 0,95.
A13: Cambio mínimo detectable | B13: Se calcula multiplicando el error técnico por la raíz de dos y por el valor de la distribución normal para el nivel de confianza elegido, 1,96 para el noventa y cinco por ciento. Un cambio menor que ese valor no puede distinguirse del error del método.
A14: Error de una suma de pliegues | B14: Al sumar varios pliegues los errores independientes se combinan según la raíz del número de sitios, no de forma proporcional. Por eso el cambio mínimo detectable de una suma representa una proporción menor del total que el de un pliegue aislado, y el seguimiento resulta más sensible sobre la suma.
A15: Presión del instrumento | B15: Los plicómetros de uso profesional están construidos para ejercer una presión constante de diez gramos por milímetro cuadrado sobre las superficies de contacto, con independencia de la apertura de las ramas. Esa presión constante es lo que hace comparable la medición: un instrumento con el resorte alterado deja de cumplirla.
A16: Verificación con patrones | B16: La comprobación contra bloques de espesor conocido detecta desviaciones sistemáticas del instrumento, que no se revelan repitiendo mediciones sobre personas porque se repiten de forma idéntica. Ninguna corrección estadística posterior puede recuperar mediciones tomadas con un instrumento descalibrado si esa desviación no fue documentada.
A17: Qué NO hace este libro | B17: No estima densidad corporal, porcentaje de grasa ni somatotipo: para eso están los módulos específicos de la colección. No reemplaza la formación práctica ni la acreditación del evaluador. No corrige mediciones mal tomadas. No está validado clínicamente.
A18: Relación con otros módulos | B18: NMX-36 aplica ecuaciones de composición corporal a partir de pliegues. NMX-20 integra pliegues, somatotipo y recordatorio en un formulario único. Este módulo se ocupa de lo previo: que el instrumento esté verificado y que el error del evaluador sea conocido.

Sheet M41_PRUEBAS
A1: NUTRIMETRÍA · NMX-41
A2: Control de calidad del motor de cálculo
A4: =HYPERLINK("#M41_INICIO!A1","▶ VOLVER A INICIO") -> ▶ VOLVER A INICIO
A6: Los valores esperados se calcularon de forma independiente del motor del libro (verificación externa).
A8: Bloque | B8: Descripción de la prueba | C8: Obtenido | D8: Esperado | E8: Estado
A9: A | B9: Media del primer par (12,4 y 12,1) | C9: =M41_FIABILIDAD!F13 -> 12.25 | D9: 12.25 | E9: =IF(AND(ISNUMBER(C9),ISNUMBER(D9)),IF(ABS(C9-D9)<=0.001,"APROBADO","REVISAR"),IF(EXACT(C9&"",D9&""),"APROBADO","REVISAR")) -> APROBADO
A10: A | B10: Diferencia del primer par | C10: =M41_FIABILIDAD!G13 -> 0.3 | D10: 0.3 | E10: =IF(AND(ISNUMBER(C10),ISNUMBER(D10)),IF(ABS(C10-D10)<=0.001,"APROBADO","REVISAR"),IF(EXACT(C10&"",D10&""),"APROBADO","REVISAR")) -> APROBADO
A11: A | B11: Diferencia al cuadrado del primer par | C11: =M41_FIABILIDAD!H13 -> 0.09 | D11: 0.09 | E11: =IF(AND(ISNUMBER(C11),ISNUMBER(D11)),IF(ABS(C11-D11)<=0.001,"APROBADO","REVISAR"),IF(EXACT(C11&"",D11&""),"APROBADO","REVISAR")) -> APROBADO
A12: A | B12: Número de pares medidos | C12: =M41_FIABILIDAD!C36 -> 10 | D12: 10 | E12: =IF(AND(ISNUMBER(C12),ISNUMBER(D12)),IF(ABS(C12-D12)<=0.001,"APROBADO","REVISAR"),IF(EXACT(C12&"",D12&""),"APROBADO","REVISAR")) -> APROBADO
A13: A | B13: Suma de las diferencias al cuadrado | C13: =M41_FIABILIDAD!C37 -> 1.74 | D13: 1.74 | E13: =IF(AND(ISNUMBER(C13),ISNUMBER(D13)),IF(ABS(C13-D13)<=0.001,"APROBADO","REVISAR"),IF(EXACT(C13&"",D13&""),"APROBADO","REVISAR")) -> APROBADO
A14: A | B14: Media general de las mediciones | C14: =M41_FIABILIDAD!C38 -> 17.24 | D14: 17.24 | E14: =IF(AND(ISNUMBER(C14),ISNUMBER(D14)),IF(ABS(C14-D14)<=0.001,"APROBADO","REVISAR"),IF(EXACT(C14&"",D14&""),"APROBADO","REVISAR")) -> APROBADO
A15: B | B15: ERROR TÉCNICO DE MEDICIÓN | C15: =M41_FIABILIDAD!C39 -> 0.29495762 | D15: 0.29495762 | E15: =IF(AND(ISNUMBER(C15),ISNUMBER(D15)),IF(ABS(C15-D15)<=0.001,"APROBADO","REVISAR"),IF(EXACT(C15&"",D15&""),"APROBADO","REVISAR")) -> APROBADO
A16: B | B16: Error relativo | C16: =M41_FIABILIDAD!C40 -> 0.017108911 | D16: 0.017108911 | E16: =IF(AND(ISNUMBER(C16),ISNUMBER(D16)),IF(ABS(C16-D16)<=0.001,"APROBADO","REVISAR"),IF(EXACT(C16&"",D16&""),"APROBADO","REVISAR")) -> APROBADO
A17: B | B17: Desviación estándar entre sujetos | C17: =M41_FIABILIDAD!C41 -> 5.9407164 | D17: 5.9407164 | E17: =IF(AND(ISNUMBER(C17),ISNUMBER(D17)),IF(ABS(C17-D17)<=0.001,"APROBADO","REVISAR"),IF(EXACT(C17&"",D17&""),"APROBADO","REVISAR")) -> APROBADO
A18: B | B18: Coeficiente de fiabilidad | C18: =M41_FIABILIDAD!C42 -> 0.99753486 | D18: 0.99753486 | E18: =IF(AND(ISNUMBER(C18),ISNUMBER(D18)),IF(ABS(C18-D18)<=0.001,"APROBADO","REVISAR"),IF(EXACT(C18&"",D18&""),"APROBADO","REVISAR")) -> APROBADO
A19: C | B19: El error relativo cumple el criterio de un mismo evaluador | C19: =IF(M41_FIABILIDAD!C40<=M41_u_intra,"CUMPLE","NO CUMPLE") -> CUMPLE | D19: CUMPLE | E19: =IF(AND(ISNUMBER(C19),ISNUMBER(D19)),IF(ABS(C19-D19)<=0.001,"APROBADO","REVISAR"),IF(EXACT(C19&"",D19&""),"APROBADO","REVISAR")) -> APROBADO
A20: C | B20: La fiabilidad alcanza el mínimo exigido | C20: =IF(M41_FIABILIDAD!C42>=M41_u_R,"ALCANZA","NO ALCANZA") -> ALCANZA | D20: ALCANZA | E20: =IF(AND(ISNUMBER(C20),ISNUMBER(D20)),IF(ABS(C20-D20)<=0.001,"APROBADO","REVISAR"),IF(EXACT(C20&"",D20&""),"APROBADO","REVISAR")) -> APROBADO
A21: C | B21: Ningún par supera el 5% de diferencia entre medidas | C21: =COUNTIF(M41_FIABILIDAD!I13:I32,"REVISAR*") -> 0 | D21: 0 | E21: =IF(AND(ISNUMBER(C21),ISNUMBER(D21)),IF(ABS(C21-D21)<=0.001,"APROBADO","REVISAR"),IF(EXACT(C21&"",D21&""),"APROBADO","REVISAR")) -> APROBADO
A22: D | B22: Cambio mínimo detectable en un pliegue | C22: =M41_FIABILIDAD!C50 -> 0.81758082 | D22: 0.81758082 | E22: =IF(AND(ISNUMBER(C22),ISNUMBER(D22)),IF(ABS(C22-D22)<=0.001,"APROBADO","REVISAR"),IF(EXACT(C22&"",D22&""),"APROBADO","REVISAR")) -> APROBADO
A23: D | B23: Error de la suma de 6 pliegues | C23: =M41_SEGUIMIENTO!C25 -> 0.72249567 | D23: 0.72249568 | E23: =IF(AND(ISNUMBER(C23),ISNUMBER(D23)),IF(ABS(C23-D23)<=0.001,"APROBADO","REVISAR"),IF(EXACT(C23&"",D23&""),"APROBADO","REVISAR")) -> APROBADO
A24: D | B24: Cambio mínimo detectable de la suma | C24: =M41_SEGUIMIENTO!E20 -> 2.0026558 | D24: 2.0026558 | E24: =IF(AND(ISNUMBER(C24),ISNUMBER(D24)),IF(ABS(C24-D24)<=0.001,"APROBADO","REVISAR"),IF(EXACT(C24&"",D24&""),"APROBADO","REVISAR")) -> APROBADO
A25: D | B25: El error de la suma es menor que 6 veces el individual | C25: =IF(M41_SEGUIMIENTO!C25<6*M41_FIABILIDAD!C39,"MENOR","MAYOR") -> MENOR | D25: MENOR | E25: =IF(AND(ISNUMBER(C25),ISNUMBER(D25)),IF(ABS(C25-D25)<=0.001,"APROBADO","REVISAR"),IF(EXACT(C25&"",D25&""),"APROBADO","REVISAR")) -> APROBADO
A26: E | B26: Suma inicial de los 6 pliegues | C26: =M41_SEGUIMIENTO!B20 -> 76.6 | D26: 76.6 | E26: =IF(AND(ISNUMBER(C26),ISNUMBER(D26)),IF(ABS(C26-D26)<=0.001,"APROBADO","REVISAR"),IF(EXACT(C26&"",D26&""),"APROBADO","REVISAR")) -> APROBADO
A27: E | B27: Suma de control | C27: =M41_SEGUIMIENTO!C20 -> 69.2 | D27: 69.2 | E27: =IF(AND(ISNUMBER(C27),ISNUMBER(D27)),IF(ABS(C27-D27)<=0.001,"APROBADO","REVISAR"),IF(EXACT(C27&"",D27&""),"APROBADO","REVISAR")) -> APROBADO
A28: E | B28: Cambio de la suma | C28: =M41_SEGUIMIENTO!D20 -> -7.4 | D28: -7.4 | E28: =IF(AND(ISNUMBER(C28),ISNUMBER(D28)),IF(ABS(C28-D28)<=0.001,"APROBADO","REVISAR"),IF(EXACT(C28&"",D28&""),"APROBADO","REVISAR")) -> APROBADO
A29: E | B29: El cambio de la suma supera el umbral | C29: =IF(ABS(M41_SEGUIMIENTO!D20)>M41_SEGUIMIENTO!E20,"SUPERA","NO SUPERA") -> SUPERA | D29: SUPERA | E29: =IF(AND(ISNUMBER(C29),ISNUMBER(D29)),IF(ABS(C29-D29)<=0.001,"APROBADO","REVISAR"),IF(EXACT(C29&"",D29&""),"APROBADO","REVISAR")) -> APROBADO
A30: E | B30: Cambio del bíceps (de 6,0 a 5,6) | C30: =M41_SEGUIMIENTO!D14 -> -0.4 | D30: -0.4 | E30: =IF(AND(ISNUMBER(C30),ISNUMBER(D30)),IF(ABS(C30-D30)<=0.001,"APROBADO","REVISAR"),IF(EXACT(C30&"",D30&""),"APROBADO","REVISAR")) -> APROBADO
A31: E | B31: Ese cambio individual NO es distinguible del error | C31: =IF(ABS(M41_SEGUIMIENTO!D14)>M41_v_mdc,"DISTINGUIBLE","NO DISTINGUIBLE") -> NO DISTINGUIBLE | D31: NO DISTINGUIBLE | E31: =IF(AND(ISNUMBER(C31),ISNUMBER(D31)),IF(ABS(C31-D31)<=0.001,"APROBADO","REVISAR"),IF(EXACT(C31&"",D31&""),"APROBADO","REVISAR")) -> APROBADO
A32: E | B32: Cambio del suprailíaco (de 16,0 a 14,2) | C32: =M41_SEGUIMIENTO!D15 -> -1.8 | D32: -1.8 | E32: =IF(AND(ISNUMBER(C32),ISNUMBER(D32)),IF(ABS(C32-D32)<=0.001,"APROBADO","REVISAR"),IF(EXACT(C32&"",D32&""),"APROBADO","REVISAR")) -> APROBADO
A33: E | B33: Ese cambio individual SÍ es distinguible | C33: =IF(ABS(M41_SEGUIMIENTO!D15)>M41_v_mdc,"DISTINGUIBLE","NO DISTINGUIBLE") -> DISTINGUIBLE | D33: DISTINGUIBLE | E33: =IF(AND(ISNUMBER(C33),ISNUMBER(D33)),IF(ABS(C33-D33)<=0.001,"APROBADO","REVISAR"),IF(EXACT(C33&"",D33&""),"APROBADO","REVISAR")) -> APROBADO
A34: F | B34: Error medio del instrumento en la verificación | C34: =M41_CALIBRACION!G16 -> 0.091666667 | D34: 0.091666667 | E34: =IF(AND(ISNUMBER(C34),ISNUMBER(D34)),IF(ABS(C34-D34)<=0.001,"APROBADO","REVISAR"),IF(EXACT(C34&"",D34&""),"APROBADO","REVISAR")) -> APROBADO
A35: F | B35: La verificación queda dentro de tolerancia | C35: =IF(ABS(M41_CALIBRACION!G16)<=M41_u_patron,"DENTRO","FUERA") -> DENTRO | D35: DENTRO | E35: =IF(AND(ISNUMBER(C35),ISNUMBER(D35)),IF(ABS(C35-D35)<=0.001,"APROBADO","REVISAR"),IF(EXACT(C35&"",D35&""),"APROBADO","REVISAR")) -> APROBADO
A36: F | B36: Puntos conformes de la revisión mecánica | C36: =M41_CALIBRACION!C26 -> 6 | D36: 6 | E36: =IF(AND(ISNUMBER(C36),ISNUMBER(D36)),IF(ABS(C36-D36)<=0.001,"APROBADO","REVISAR"),IF(EXACT(C36&"",D36&""),"APROBADO","REVISAR")) -> APROBADO
A37: F | B37: Dictamen del instrumento | C37: =M41_CALIBRACION!C28 -> APTO PARA USO | D37: APTO PARA USO | E37: =IF(AND(ISNUMBER(C37),ISNUMBER(D37)),IF(ABS(C37-D37)<=0.001,"APROBADO","REVISAR"),IF(EXACT(C37&"",D37&""),"APROBADO","REVISAR")) -> APROBADO
A38: G | B38: Un valor ausente NO se interpreta como cero | C38: =IF(ISNUMBER(""),"NUMERO","ND") -> ND | D38: ND | E38: =IF(AND(ISNUMBER(C38),ISNUMBER(D38)),IF(ABS(C38-D38)<=0.001,"APROBADO","REVISAR"),IF(EXACT(C38&"",D38&""),"APROBADO","REVISAR")) -> APROBADO
A40: RESUMEN | B40: Pruebas aprobadas | C40: =COUNTIF(E9:E38,"APROBADO") -> 30 | D40: =COUNTA(E9:E38) -> 30 | E40: =IF(C40=D40,"TODAS APROBADAS","HAY PRUEBAS POR REVISAR") -> TODAS APROBADAS

Sheet M41_CONFIG
A1: NUTRIMETRÍA · NMX-41
A2: Configuración · umbrales de calidad de la medición
A4: =HYPERLINK("#M41_INICIO!A1","▶ VOLVER A INICIO") -> ▶ VOLVER A INICIO
A6: UMBRALES DE ERROR TÉCNICO DE MEDICIÓN
A7: Error relativo aceptable · un mismo evaluador | D7: % | E7: 0.05
A8: Error relativo aceptable · entre evaluadores | D8: % | E8: 0.075
A9: Coeficiente de fiabilidad mínimo aceptable | D9: R | E9: 0.95
A10: Nivel de confianza para el cambio mínimo detectable | D10: z | E10: 1.96
A11: Presión estándar del plicómetro | D11: g/mm² | E11: 10
A12: Tolerancia aceptada en la verificación con patrón | D12: mm | E12: 0.2
A13: Diferencia máxima entre dos medidas del mismo pliegue | D13: % | E13: 0.05
A14: Número mínimo de sujetos para estimar el error | D14: sujetos | E14: 10
A15: Tolerancia de las pruebas | D15: ± | E15: 0.0001
A16: Los límites de cinco y siete coma cinco por ciento corresponden a los criterios de acreditación de la Sociedad Internacional para el Avance de la Cineantropometría para medidas de pliegues. Son exigentes y se alcanzan con entrenamiento: un evaluador sin práctica supervisada rara vez los cumple al inicio.
A20: SITIOS ANATÓMICOS DE REFERENCIA
A21: Sitio | B21: Ubicación del punto | C21: Dirección del pliegue | D21: Posición de la persona
A22: Tríceps | B22: Punto medio entre acromion y olécranon, cara posterior del brazo | C22: Vertical | D22: De pie, brazo relajado
A23: Subescapular | B23: Dos centímetros por debajo del ángulo inferior de la escápula | C23: Oblicua, hacia abajo y afuera | D23: De pie, brazos a los lados
A24: Bíceps | B24: Punto medio del brazo, cara anterior, sobre el vientre del bíceps | C24: Vertical | D24: De pie, brazo relajado y supinado
A25: Suprailíaco | B25: Sobre la cresta ilíaca, en la línea axilar media | C25: Oblicua, siguiendo la cresta | D25: De pie, brazo separado
A26: Supraespinal | B26: Intersección de la línea axilar anterior con la cresta ilíaca | C26: Oblicua, hacia abajo y adentro | D26: De pie, brazo relajado
A27: Abdominal | B27: Cinco centímetros a la derecha del ombligo | C27: Vertical | D27: De pie, abdomen relajado
A28: Muslo anterior | B28: Punto medio entre pliegue inguinal y borde superior de la rótula | C28: Vertical | D28: Sentado, rodilla a noventa grados
A29: Pantorrilla medial | B29: Cara medial, en el perímetro máximo | C29: Vertical | D29: Sentado o de pie con la pierna apoyada
A31: LISTAS
A32: MARCA | B32: SI | C32: ESTADO | D32: NIVEL
A33: Harpenden | B33: Sí | C33: Correcto | D33: En formación
A34: Holtain | B34: No | C34: Requiere ajuste | D34: Acreditado nivel 1
A35: Lange | C35: Fuera de servicio | D35: Acreditado nivel 2
A36: Slim Guide | D36: Acreditado nivel 3 o superior
A37: Otro

Sheet M41_CHANGELOG
A1: NUTRIMETRÍA · NMX-41
A2: Historial de versiones
A4: =HYPERLINK("#M41_INICIO!A1","▶ VOLVER A INICIO") -> ▶ VOLVER A INICIO
A6: Versión | B6: Fecha | C6: Cambio
A7: 1.0 | B7: 2026-07-24 | C7: Versión inicial de NMX-41: software acompañante para plicómetro, centrado en la calidad del instrumento y del evaluador. | J7: Fase 7 · Especialidades y productos complementarios.
A8: 1.0 | B8: 2026-07-24 | C8: Hoja de verificación del instrumento contra patrones de espesor conocido, con dictamen de aptitud. | J8: Una desviación sistemática del plicómetro no se detecta repitiendo mediciones: se repite igual.
A9: 1.0 | B9: 2026-07-24 | C9: Cálculo del error técnico de medición, error relativo y coeficiente de fiabilidad a partir de mediciones por duplicado. | J9: Permite que cada evaluador conozca su propio error en lugar de suponerlo.
A10: 1.0 | B10: 2026-07-24 | C10: Cambio mínimo detectable por pliegue y para la suma de pliegues. | J10: Responde la pregunta central de quien usa plicómetro: si el cambio observado es real o es ruido del método.
A11: 1.0 | B11: 2026-07-24 | C11: Se explicita que el error de una suma crece con la raíz del número de pliegues. | J11: Fundamenta por qué el seguimiento se hace sobre la suma y no sobre pliegues aislados.
A12: 1.0 | B12: 2026-07-24 | C12: Lista de condiciones de comparabilidad que invalidan la comparación si no se cumplen. | J12: Un cambio de evaluador o de instrumento puede superar el cambio biológico que se busca detectar.
A13: 1.0 | B13: 2026-07-24 | C13: Advertencia sobre no medir dos veces seguidas el mismo sitio. | J13: La compresión del tejido subestima la segunda lectura y el error calculado saldría falsamente bajo.
A14: 1.0 | B14: 2026-07-24 | C14: Diseño visual, barra de navegación y enlaces de retorno replicados de NMX-10 aprobado. | J14: Unificar la identidad de la colección.
A15: 1.0.1 | B15: 2026-08-01 | C15: Actualizado el valor esperado de la prueba F (error medio del instrumento) de 0,1 al valor preciso 0,091666667, en linea con la alta precision del resto de las pruebas. 30 pruebas aprobadas.

Sheet M36_INICIO
A1: NUTRIMETRÍA · NMX-36
A2: Calculadora especializada de plicometría · versión 1.0
A4: Navegación — use las pestañas inferiores del libro
