Workbook
Name k_max: CONFIG!$E$12
Name k_mediana: CONFIG!$E$10
Name k_min: CONFIG!$E$11
Name k_tol: CONFIG!$E$14
Name lst_ambito: CONFIG!$D$22:$D$26
Name lst_dificultad: CONFIG!$J$22:$J$24
Name lst_marca: CONFIG!$A$22:$A$23
Name lst_momento: CONFIG!$G$22:$G$27
Name lst_si: CONFIG!$M$22:$M$23
Name u_alta: CONFIG!$E$7
Name u_maxHab: CONFIG!$E$13
Name u_media: CONFIG!$E$8
Name u_seguidos: CONFIG!$E$9
Name v_dias: DATOS!$C$10

Sheet INICIO
A1: NUTRIMETRÍA · NMX-24
A2: Seguimiento mensual de hábitos · versión 1.0 · Fase 6 · planificación
A4: Navegación — use las pestañas inferiores del libro
A5: =HYPERLINK("#DATOS!A1","▶ DATOS") -> ▶ DATOS | C5: =HYPERLINK("#HABITOS!A1","▶ HABITOS") -> ▶ HABITOS | E5: =HYPERLINK("#REGISTRO!A1","▶ REGISTRO") -> ▶ REGISTRO | G5: =HYPERLINK("#ANALISIS!A1","▶ ANALISIS") -> ▶ ANALISIS | I5: =HYPERLINK("#PANEL!A1","▶ PANEL") -> ▶ PANEL | K5: =HYPERLINK("#FUENTES!A1","▶ FUENTES") -> ▶ FUENTES | M5: =HYPERLINK("#PRUEBAS!A1","▶ PRUEBAS") -> ▶ PRUEBAS | O5: =HYPERLINK("#CONFIG!A1","▶ CONFIG") -> ▶ CONFIG
A6: Persona y mes | C6: Qué se va a seguir | E6: Calendario del mes | G6: Adherencia y patrones | I6: Tablero visual | K6: Evidencia y trazabilidad | M6: Control de calidad | O6: Constantes
A7: =HYPERLINK("#CHANGELOG!A1","▶ CHANGELOG") -> ▶ CHANGELOG
A8: Historial
A10: Código del producto | C10: NMX-24
A11: Versión | C11: 1.0
A12: Fecha | C12: 2026-07-23
A13: Base de evidencia | C13: Lally y cols., European Journal of Social Psychology, 2010
A14: Formato | C14: .xlsx sin macros · Microsoft 365 (Windows) y Excel 2021 · sin funciones matriciales
A15: Responsable | C15: Equipo Nutrimetría (completar por el titular)
A17: CÓMO ESTÁ PENSADO ESTE SEGUIMIENTO
A18: Fallar un día NO rompe el proceso. La investigación muestra que omitir una oportunidad aislada no altera la trayectoria hacia la automaticidad. Por eso este libro registra la racha pero NO la usa como criterio.
A19: La señal que sí importa son DOS DÍAS SEGUIDOS sin cumplir: ahí se empieza a consolidar la no ejecución.
A20: Una celda vacía significa que no hubo oportunidad y no cuenta en contra. Un día de viaje o de enfermedad no es un incumplimiento.
A21: Un mes no forma un hábito: la mediana observada es de 66 días, con un rango de 18 a 254. Este registro acompaña el proceso, no lo certifica.
A23: AVISO DE ALCANCE — LÉALO ANTES DE USAR
A24: EXACTITUD MATEMÁTICA ≠ VALIDACIÓN CLÍNICA. Este archivo no está validado clínicamente y no constituye diagnóstico ni tratamiento.
A25: PRECAUCIÓN: el registro diario de conductas alimentarias puede intensificar la preocupación por la comida y el pensamiento de todo o nada en personas con trastorno de la conducta alimentaria o alto riesgo. Evalúe antes de indicarlo.
A26: NUNCA incluya el peso corporal como hábito de registro diario.
A27: Los umbrales de 80% y 60% son convenciones de lectura editables, sin significado clínico por sí mismas.
A28: Este libro mide CONDUCTAS, no automaticidad: no puede declarar que un hábito se formó.
A29: Los resultados describen conductas en un contexto y no califican a la persona. Una adherencia baja informa que el hábito no calzaba con la vida real de ese mes.
A31: FLUJO DE USO
A32: 1 | C32: En DATOS registre a la persona, el mes y los acuerdos, incluido qué hacer ante un día fallido.
A33: 2 | C33: En HÁBITOS defina dos o tres conductas observables, cada una anclada a una señal concreta del día.
A34: 3 | C34: Entregue el REGISTRO: se marca 1 si cumplió, 0 si no, y se deja vacío si no hubo oportunidad.
A35: 4 | C35: El registro se hace cada noche, en menos de un minuto: si toma más, el propio registro se abandona.
A36: 5 | C36: En ANÁLISIS revise la adherencia de cada hábito y la recomendación de conducta que entrega el libro.
A37: 6 | C37: En PANEL vea el mes de un vistazo antes de la conversación de control.
A38: 7 | C38: Cierre con los acuerdos del mes siguiente: qué sigue, qué se retira y qué obstáculo concreto se resuelve.

Sheet DATOS
A1: NUTRIMETRÍA · NMX-24
A2: Persona, mes de seguimiento y acuerdos
A4: =HYPERLINK("#INICIO!A1","▶ VOLVER A INICIO") -> ▶ VOLVER A INICIO
A6: IDENTIFICACIÓN
A7: Nombre o identificador | C7: Caso de ejemplo
A8: Edad (años) | C8: 34
A9: Mes de seguimiento | C9: Julio 2026
A10: Días que tiene el mes | C10: 31 | L10: Ajuste a 28, 29, 30 o 31
A11: Fecha de inicio | C11: 2026-07-01
A12: Profesional que acompaña | C12: —
A13: Fecha de la revisión | C13: 2026-08-01
A15: ACUERDOS DE ESTE MES
A16: Objetivo del mes | C16: Sostener una rutina de comidas más ordenada.
A17: ¿Los hábitos los eligió la persona? | C17: Sí | L17: Un hábito impuesto rara vez se sostiene
A18: ¿Se acordó qué hacer ante un día fallido? | C18: Sí | L18: Clave: retomar al día siguiente, sin compensar
A19: Qué se hará si falla un día | C19: Retomar al día siguiente. No se compensa ni se castiga.
A20: Cómo y cuándo se registrará | C20: Cada noche, antes de dormir, en menos de un minuto.
A21: Con quién se revisará | C21: En el control del 1 de agosto.
A23: EXPECTATIVA REALISTA
A24: Días de este mes | C24: =C10 -> 31
A25: Días de referencia para consolidar un hábito | C25: =k_mediana -> 66 | L25: Mediana observada en investigación sobre formación de hábitos
A26: Rango observado | C26: =k_min&" a "&k_max&" días" -> 18 a 254 días | L26: La variación entre personas y conductas es muy amplia
A27: Lectura | C27: =IF(NOT(ISNUMBER(C10)),"ND",IF(C10<k_mediana,"Un mes NO alcanza para consolidar un hábito: la mediana observada es de "&k_mediana&" días. Este registro sirve para acompañar el proceso y detectar qué se atraviesa, no para declarar un hábito formado.","El periodo cubre la mediana de referencia, pero la consolidación sigue siendo individual.")) -> Un mes NO alcanza para consolidar un hábito: la mediana observada es de 66 días. Este registro sirve para acompañar el proceso y detectar qué se atraviesa, no para declarar un hábito formado.
A29: Un mes de registro no forma un hábito y este libro no debe presentarse como si lo hiciera. Su utilidad real es otra: mostrar cuáles conductas se sostienen solas, cuáles necesitan apoyo y qué circunstancias las interrumpen. Esa información sirve para ajustar el plan, no para calificar a la persona.

Sheet HABITOS
A1: NUTRIMETRÍA · NMX-24
A2: Definición de los hábitos a seguir
A4: =HYPERLINK("#INICIO!A1","▶ VOLVER A INICIO") -> ▶ VOLVER A INICIO
A6: Un hábito bien definido es OBSERVABLE y de respuesta binaria: al final del día se puede responder sí o no sin discutir. 'Comer mejor' no sirve; 'incluir verduras en almuerzo y cena' sí. Ancle cada uno a una señal concreta del día: es lo que hace que la conducta se dispare sola.
A10: HÁBITOS DEL MES
A11: Nº | B11: Hábito (redacción observable) | C11: Ámbito | D11: Señal que lo dispara | E11: Momento del día | F11: Dificultad | G11: ¿Lo eligió la persona? | H11: Por qué importa para su plan
A12: 1 | B12: Desayunar dentro de la primera hora | C12: Alimentación | D12: Apagar el despertador | E12: Al despertar | F12: Media | G12: Sí | H12: Ordena el resto del día y evita llegar con hambre extrema al almuerzo.
A13: 2 | B13: Incluir verduras en almuerzo y cena | C13: Alimentación | D13: Servirse el plato | E13: Mediodía | F13: Fácil | G13: Sí | H13: Aporte de fibra y micronutrientes; también sacia.
A14: 3 | B14: Beber al menos 6 vasos de agua | C14: Alimentación | D14: Cada vez que se sienta a trabajar | E14: Sin hora fija | F14: Fácil | G14: No | H14: Hidratación y menos confusión entre sed y hambre.
A15: 4 | B15: Comer una comida sin pantallas | C15: Conciencia | D15: Sentarse a la mesa | E15: Mediodía | F15: Exigente | G15: Sí | H15: Permite percibir señales de saciedad.
A16: 5 | B16: Llevar colación planificada | C16: Organización | D16: Preparar el bolso | E16: Antes del desayuno | F16: Media | G16: Sí | H16: Evita el picoteo no planificado de la tarde.
A17: 6 | B17: Caminar 30 minutos | C17: Movimiento | D17: Terminar la jornada | E17: Tarde | F17: Media | G17: Sí | H17: Actividad sostenible y realista para su rutina.
A18: 7 | B18: Acostarse antes de las 23:30 | C18: Descanso | D18: Terminar de ordenar la cocina | E18: Antes de dormir | F18: Exigente | G18: Sí | H18: El sueño insuficiente altera el apetito al día siguiente.
A19: 8 | B19: Dejar lista la comida del día siguiente | C19: Organización | D19: Después de cenar | E19: Antes de dormir | F19: Exigente | G19: Sí | H19: Reduce decisiones en el momento de mayor cansancio.
A20: 9 | B20: Anotar cómo me sentí al comer | C20: Conciencia | D20: Terminar de comer | E20: Sin hora fija | F20: Media | G20: Sí | H20: Identifica el contexto emocional de las ingestas.
A21: 10 | B21: Comer sentado a la mesa | C21: Conciencia | D21: Servirse el plato | E21: Sin hora fija | F21: Fácil | G21: Sí | H21: Estructura las comidas y evita comer de pie o caminando.
A23: CONTROL DEL DISEÑO
A24: Hábitos definidos | C24: =COUNTIF(B12:B21,"?*") -> 10
A25: Hábitos elegidos por la persona | C25: =COUNTIF(G12:G21,"Sí") -> 9
A26: Hábitos calificados como exigentes | C26: =COUNTIF(F12:F21,"Exigente") -> 3
A27: Lectura del diseño | C27: =IF(C24=0,"Aún no se han definido hábitos.",IF(C24>u_maxHab,"Son "&C24&" hábitos: MÁS de los "&u_maxHab&" recomendados a la vez. Seguir demasiadas conductas al mismo tiempo reduce la probabilidad de sostener cualquiera. Priorice dos o tres.",IF(C26>2,"Hay más de dos hábitos exigentes: considere dejar solo uno exigente y acompañarlo de otros fáciles.","El número y la dificultad de los hábitos son razonables para un mes."))) -> Son 10 hábitos: MÁS de los 5 recomendados a la vez. Seguir demasiadas conductas al mismo tiempo reduce la probabilidad de sostener cualquiera. Priorice dos o tres.
A29: Este ejemplo trae diez hábitos para mostrar el funcionamiento completo del registro, y por eso el propio libro lo marca como demasiados. En la práctica, dos o tres conductas bien elegidas rinden más que diez mal sostenidas: borre las que no correspondan antes de entregarlo.

Sheet REGISTRO
A1: NUTRIMETRÍA · NMX-24
A2: Calendario del mes · marque 1 si cumplió, 0 si no, y deje vacío si no hubo oportunidad
A4: =HYPERLINK("#INICIO!A1","▶ VOLVER A INICIO") -> ▶ VOLVER A INICIO
A6: Registre cada noche, en menos de un minuto. Una celda VACÍA significa que ese día no hubo oportunidad (viaje, enfermedad, el día no aplicaba) y NO cuenta en contra. Un cero significa que hubo ocasión y no se cumplió: también es información útil, no una falta.
A10: REGISTRO DIARIO
A11: Nº | B11: Hábito | C11: 1 | D11: 2 | E11: 3 | F11: 4 | G11: 5 | H11: 6 | I11: 7 | J11: 8 | K11: 9 | L11: 10 | M11: 11 | N11: 12 | O11: 13 | P11: 14 | Q11: 15 | R11: 16 | S11: 17 | T11: 18 | U11: 19 | V11: 20 | W11: 21 | X11: 22 | Y11: 23 | Z11: 24 | AA11: 25 | AB11: 26 | AC11: 27 | AD11: 28 | AE11: 29 | AF11: 30 | AG11: 31 | AH11: Cumplidos | AI11: Oportunidades | AJ11: Adherencia | AK11: Racha actual | AL11: Racha máxima | AM11: Máx. días seguidos sin cumplir | AN11: Señal
A12: 1 | B12: =IF(HABITOS!B12="","",HABITOS!B12) -> Desayunar dentro de la primera hora | C12: 1 | D12: 1 | E12: 1 | F12: 1 | G12: 1 | H12: 0 | I12: 0 | J12: 1 | K12: 1 | L12: 1 | M12: 1 | N12: 1 | O12: 0 | P12: 1 | Q12: 1 | R12: 1 | S12: 1 | T12: 1 | U12: 1 | V12: 0 | W12: 1 | X12: 1 | Y12: 1 | Z12: 1 | AA12: 1 | AB12: 1 | AC12: 0 | AD12: 1 | AE12: 1 | AF12: 1 | AG12: 1 | AH12: =IF($B12="","",COUNTIF(C12:AG12,1)) -> 26 | AI12: =IF($B12="","",COUNT(C12:AG12)) -> 31 | AJ12: =IF($B12="","",IF(AI12=0,"Sin oportunidades registradas",AH12/AI12)) -> 0.83870968 | AK12: =IF($B12="","",AG27) -> 4 | AL12: =IF($B12="","",MAX(C27:AG27)) -> 6 | AM12: =IF($B12="","",MAX(C40:AG40)) -> 2 | AN12: =IF($B12="","",IF(AM12>=u_seguidos,"Revisar: hubo "&AM12&" días seguidos sin cumplir","Sin interrupciones seguidas")) -> Revisar: hubo 2 días seguidos sin cumplir
A13: 2 | B13: =IF(HABITOS!B13="","",HABITOS!B13) -> Incluir verduras en almuerzo y cena | C13: 1 | D13: 1 | E13: 1 | F13: 0 | G13: 1 | H13: 1 | I13: 1 | J13: 1 | K13: 1 | L13: 1 | M13: 0 | N13: 1 | O13: 1 | P13: 1 | Q13: 1 | R13: 1 | S13: 1 | T13: 0 | U13: 1 | V13: 1 | W13: 1 | X13: 1 | Y13: 1 | Z13: 1 | AA13: 0 | AB13: 1 | AC13: 1 | AD13: 1 | AE13: 1 | AF13: 1 | AG13: 1 | AH13: =IF($B13="","",COUNTIF(C13:AG13,1)) -> 27 | AI13: =IF($B13="","",COUNT(C13:AG13)) -> 31 | AJ13: =IF($B13="","",IF(AI13=0,"Sin oportunidades registradas",AH13/AI13)) -> 0.87096774 | AK13: =IF($B13="","",AG28) -> 6 | AL13: =IF($B13="","",MAX(C28:AG28)) -> 6 | AM13: =IF($B13="","",MAX(C41:AG41)) -> 1 | AN13: =IF($B13="","",IF(AM13>=u_seguidos,"Revisar: hubo "&AM13&" días seguidos sin cumplir","Sin interrupciones seguidas")) -> Sin interrupciones seguidas
A14: 3 | B14: =IF(HABITOS!B14="","",HABITOS!B14) -> Beber al menos 6 vasos de agua | C14: 1 | D14: 1 | E14: 0 | F14: 1 | G14: 1 | H14: 1 | I14: 1 | J14: 1 | K14: 1 | L14: 0 | M14: 1 | N14: 1 | O14: 1 | P14: 1 | Q14: 1 | R14: 1 | S14: 0 | T14: 1 | U14: 1 | V14: 1 | W14: 1 | X14: 1 | Y14: 1 | Z14: 0 | AA14: 1 | AB14: 1 | AC14: 1 | AD14: 1 | AE14: 1 | AF14: 1 | AG14: 0 | AH14: =IF($B14="","",COUNTIF(C14:AG14,1)) -> 26 | AI14: =IF($B14="","",COUNT(C14:AG14)) -> 31 | AJ14: =IF($B14="","",IF(AI14=0,"Sin oportunidades registradas",AH14/AI14)) -> 0.83870968 | AK14: =IF($B14="","",AG29) -> 0 | AL14: =IF($B14="","",MAX(C29:AG29)) -> 6 | AM14: =IF($B14="","",MAX(C42:AG42)) -> 1 | AN14: =IF($B14="","",IF(AM14>=u_seguidos,"Revisar: hubo "&AM14&" días seguidos sin cumplir","Sin interrupciones seguidas")) -> Sin interrupciones seguidas
A15: 4 | B15: =IF(HABITOS!B15="","",HABITOS!B15) -> Comer una comida sin pantallas | C15: 1 | D15: 0 | E15: 1 | F15: 1 | G15: 0 | H15: 1 | I15: 1 | J15: 1 | K15: 0 | L15: 1 | M15: 1 | N15: 1 | O15: 1 | P15: 1 | Q15: 1 | R15: 0 | S15: 1 | T15: 1 | U15: 0 | V15: 1 | W15: 1 | X15: 1 | Y15: 0 | Z15: 1 | AA15: 1 | AB15: 0 | AC15: 1 | AD15: 1 | AE15: 1 | AF15: 0 | AG15: 1 | AH15: =IF($B15="","",COUNTIF(C15:AG15,1)) -> 23 | AI15: =IF($B15="","",COUNT(C15:AG15)) -> 31 | AJ15: =IF($B15="","",IF(AI15=0,"Sin oportunidades registradas",AH15/AI15)) -> 0.74193548 | AK15: =IF($B15="","",AG30) -> 1 | AL15: =IF($B15="","",MAX(C30:AG30)) -> 6 | AM15: =IF($B15="","",MAX(C43:AG43)) -> 1 | AN15: =IF($B15="","",IF(AM15>=u_seguidos,"Revisar: hubo "&AM15&" días seguidos sin cumplir","Sin interrupciones seguidas")) -> Sin interrupciones seguidas
A16: 5 | B16: =IF(HABITOS!B16="","",HABITOS!B16) -> Llevar colación planificada | C16: 0 | D16: 1 | E16: 1 | F16: 1 | G16: 1 | H16: 1 | I16: 1 | J16: 0 | K16: 1 | L16: 1 | M16: 1 | N16: 1 | O16: 1 | P16: 1 | Q16: 0 | R16: 1 | S16: 1 | T16: 1 | U16: 1 | V16: 1 | W16: 1 | X16: 0 | Y16: 1 | Z16: 1 | AA16: 1 | AB16: 1 | AC16: 1 | AD16: 1 | AE16: 0 | AF16: 1 | AG16: 1 | AH16: =IF($B16="","",COUNTIF(C16:AG16,1)) -> 26 | AI16: =IF($B16="","",COUNT(C16:AG16)) -> 31 | AJ16: =IF($B16="","",IF(AI16=0,"Sin oportunidades registradas",AH16/AI16)) -> 0.83870968 | AK16: =IF($B16="","",AG31) -> 2 | AL16: =IF($B16="","",MAX(C31:AG31)) -> 6 | AM16: =IF($B16="","",MAX(C44:AG44)) -> 1 | AN16: =IF($B16="","",IF(AM16>=u_seguidos,"Revisar: hubo "&AM16&" días seguidos sin cumplir","Sin interrupciones seguidas")) -> Sin interrupciones seguidas
A17: 6 | B17: =IF(HABITOS!B17="","",HABITOS!B17) -> Caminar 30 minutos | C17: 1 | D17: 1 | E17: 1 | F17: 1 | G17: 1 | H17: 0 | I17: 0 | J17: 1 | K17: 1 | L17: 1 | M17: 1 | N17: 1 | O17: 0 | P17: 0 | Q17: 1 | R17: 1 | S17: 1 | T17: 1 | U17: 1 | V17: 0 | W17: 0 | X17: 1 | Y17: 1 | Z17: 1 | AA17: 1 | AB17: 1 | AC17: 0 | AD17: 0 | AE17: 1 | AF17: 1 | AG17: 1 | AH17: =IF($B17="","",COUNTIF(C17:AG17,1)) -> 23 | AI17: =IF($B17="","",COUNT(C17:AG17)) -> 31 | AJ17: =IF($B17="","",IF(AI17=0,"Sin oportunidades registradas",AH17/AI17)) -> 0.74193548 | AK17: =IF($B17="","",AG32) -> 3 | AL17: =IF($B17="","",MAX(C32:AG32)) -> 5 | AM17: =IF($B17="","",MAX(C45:AG45)) -> 2 | AN17: =IF($B17="","",IF(AM17>=u_seguidos,"Revisar: hubo "&AM17&" días seguidos sin cumplir","Sin interrupciones seguidas")) -> Revisar: hubo 2 días seguidos sin cumplir
A18: 7 | B18: =IF(HABITOS!B18="","",HABITOS!B18) -> Acostarse antes de las 23:30 | C18: 1 | D18: 1 | E18: 1 | F18: 1 | G18: 0 | H18: 0 | I18: 1 | J18: 1 | K18: 1 | L18: 1 | M18: 1 | N18: 1 | O18: 0 | P18: 1 | Q18: 1 | R18: 1 | S18: 1 | T18: 1 | U18: 0 | V18: 0 | W18: 1 | X18: 1 | Y18: 1 | Z18: 1 | AA18: 1 | AB18: 0 | AC18: 0 | AD18: 1 | AE18: 1 | AF18: 1 | AG18: 1 | AH18: =IF($B18="","",COUNTIF(C18:AG18,1)) -> 24 | AI18: =IF($B18="","",COUNT(C18:AG18)) -> 31 | AJ18: =IF($B18="","",IF(AI18=0,"Sin oportunidades registradas",AH18/AI18)) -> 0.77419355 | AK18: =IF($B18="","",AG33) -> 4 | AL18: =IF($B18="","",MAX(C33:AG33)) -> 6 | AM18: =IF($B18="","",MAX(C46:AG46)) -> 2 | AN18: =IF($B18="","",IF(AM18>=u_seguidos,"Revisar: hubo "&AM18&" días seguidos sin cumplir","Sin interrupciones seguidas")) -> Revisar: hubo 2 días seguidos sin cumplir
A19: 8 | B19: =IF(HABITOS!B19="","",HABITOS!B19) -> Dejar lista la comida del día siguiente | C19: 1 | D19: 0 | E19: 0 | F19: 0 | G19: 1 | H19: 1 | I19: 1 | J19: 1 | K19: 0 | L19: 0 | M19: 0 | N19: 1 | O19: 1 | P19: 1 | Q19: 1 | R19: 0 | S19: 0 | T19: 0 | U19: 1 | V19: 1 | W19: 1 | X19: 1 | Y19: 0 | Z19: 0 | AA19: 0 | AB19: 1 | AC19: 1 | AD19: 1 | AE19: 1 | AF19: 0 | AG19: 0 | AH19: =IF($B19="","",COUNTIF(C19:AG19,1)) -> 17 | AI19: =IF($B19="","",COUNT(C19:AG19)) -> 31 | AJ19: =IF($B19="","",IF(AI19=0,"Sin oportunidades registradas",AH19/AI19)) -> 0.5483871 | AK19: =IF($B19="","",AG34) -> 0 | AL19: =IF($B19="","",MAX(C34:AG34)) -> 4 | AM19: =IF($B19="","",MAX(C47:AG47)) -> 3 | AN19: =IF($B19="","",IF(AM19>=u_seguidos,"Revisar: hubo "&AM19&" días seguidos sin cumplir","Sin interrupciones seguidas")) -> Revisar: hubo 3 días seguidos sin cumplir
A20: 9 | B20: =IF(HABITOS!B20="","",HABITOS!B20) -> Anotar cómo me sentí al comer | C20: 0 | D20: 0 | E20: 0 | F20: 1 | G20: 1 | H20: 1 | I20: 1 | J20: 1 | K20: 1 | L20: 1 | M20: 1 | N20: 1 | O20: 1 | P20: 1 | Q20: 0 | R20: 0 | S20: 0 | T20: 1 | U20: 1 | V20: 1 | W20: 1 | X20: 1 | Y20: 1 | Z20: 1 | AA20: 1 | AB20: 1 | AC20: 1 | AD20: 1 | AE20: 0 | AF20: 0 | AG20: 0 | AH20: =IF($B20="","",COUNTIF(C20:AG20,1)) -> 22 | AI20: =IF($B20="","",COUNT(C20:AG20)) -> 31 | AJ20: =IF($B20="","",IF(AI20=0,"Sin oportunidades registradas",AH20/AI20)) -> 0.70967742 | AK20: =IF($B20="","",AG35) -> 0 | AL20: =IF($B20="","",MAX(C35:AG35)) -> 11 | AM20: =IF($B20="","",MAX(C48:AG48)) -> 3 | AN20: =IF($B20="","",IF(AM20>=u_seguidos,"Revisar: hubo "&AM20&" días seguidos sin cumplir","Sin interrupciones seguidas")) -> Revisar: hubo 3 días seguidos sin cumplir
A21: 10 | B21: =IF(HABITOS!B21="","",HABITOS!B21) -> Comer sentado a la mesa | C21: 1 | D21: 1 | E21: 1 | F21: 1 | G21: 1 | H21: 1 | I21: 0 | J21: 1 | K21: 1 | L21: 1 | M21: 1 | N21: 1 | O21: 1 | P21: 0 | Q21: 1 | R21: 1 | S21: 1 | T21: 1 | U21: 1 | V21: 1 | W21: 0 | X21: 1 | Y21: 1 | Z21: 1 | AA21: 1 | AB21: 1 | AC21: 1 | AD21: 0 | AE21: 1 | AF21: 1 | AG21: 1 | AH21: =IF($B21="","",COUNTIF(C21:AG21,1)) -> 27 | AI21: =IF($B21="","",COUNT(C21:AG21)) -> 31 | AJ21: =IF($B21="","",IF(AI21=0,"Sin oportunidades registradas",AH21/AI21)) -> 0.87096774 | AK21: =IF($B21="","",AG36) -> 3 | AL21: =IF($B21="","",MAX(C36:AG36)) -> 6 | AM21: =IF($B21="","",MAX(C49:AG49)) -> 1 | AN21: =IF($B21="","",IF(AM21>=u_seguidos,"Revisar: hubo "&AM21&" días seguidos sin cumplir","Sin interrupciones seguidas")) -> Sin interrupciones seguidas
B22: CUMPLIDOS DEL DÍA | C22: =IF(COUNT(C12:C21)=0,"",COUNTIF(C12:C21,1)) -> 8 | D22: =IF(COUNT(D12:D21)=0,"",COUNTIF(D12:D21,1)) -> 7 | E22: =IF(COUNT(E12:E21)=0,"",COUNTIF(E12:E21,1)) -> 7 | F22: =IF(COUNT(F12:F21)=0,"",COUNTIF(F12:F21,1)) -> 8 | G22: =IF(COUNT(G12:G21)=0,"",COUNTIF(G12:G21,1)) -> 8 | H22: =IF(COUNT(H12:H21)=0,"",COUNTIF(H12:H21,1)) -> 7 | I22: =IF(COUNT(I12:I21)=0,"",COUNTIF(I12:I21,1)) -> 7 | J22: =IF(COUNT(J12:J21)=0,"",COUNTIF(J12:J21,1)) -> 9 | ... AG22: =IF(COUNT(AG12:AG21)=0,"",COUNTIF(AG12:AG21,1)) -> 7 | AH22: =SUM(AH12:AH21) -> 241 | AI22: =SUM(AI12:AI21) -> 310 | AJ22: =IF(AI22=0,"ND",AH22/AI22) -> 0.77741935
B23: OPORTUNIDADES DEL DÍA | C23: =IF(COUNT(C12:C21)=0,"",COUNT(C12:C21)) -> 10 | D23: =IF(COUNT(D12:D21)=0,"",COUNT(D12:D21)) -> 10 | E23: =IF(COUNT(E12:E21)=0,"",COUNT(E12:E21)) -> 10 | F23: =IF(COUNT(F12:F21)=0,"",COUNT(F12:F21)) -> 10 | G23: =IF(COUNT(G12:G21)=0,"",COUNT(G12:G21)) -> 10 | H23: =IF(COUNT(H12:H21)=0,"",COUNT(H12:H21)) -> 10 | I23: =IF(COUNT(I12:I21)=0,"",COUNT(I12:I21)) -> 10 | J23: =IF(COUNT(J12:J21)=0,"",COUNT(J12:J21)) -> 10 | ... AG23: =IF(COUNT(AG12:AG21)=0,"",COUNT(AG12:AG21)) -> 10
A25: BLOQUE AUXILIAR · racha de cumplimiento acumulada por día (no escribir)
B26: Cada celda cuenta cuántos días seguidos lleva cumpliendo hasta ese día. Un día sin oportunidad MANTIENE la racha, no la corta.
B27: =$B$12 -> Desayunar dentro de la primera hora | C27: =IF($B27="","",IF(C12="",0,IF(C12=1,0+1,0))) -> 1 | D27: =IF($B27="","",IF(D12="",C27,IF(D12=1,C27+1,0))) -> 2 | E27: =IF($B27="","",IF(E12="",D27,IF(E12=1,D27+1,0))) -> 3 | F27: =IF($B27="","",IF(F12="",E27,IF(F12=1,E27+1,0))) -> 4 | G27: =IF($B27="","",IF(G12="",F27,IF(G12=1,F27+1,0))) -> 5 | H27: =IF($B27="","",IF(H12="",G27,IF(H12=1,G27+1,0))) -> 0 | I27: =IF($B27="","",IF(I12="",H27,IF(I12=1,H27+1,0))) -> 0 | J27: =IF($B27="","",IF(J12="",I27,IF(J12=1,I27+1,0))) -> 1 | K27: =IF($B27="","",IF(K12="",J27,IF(K12=1,J27+1,0))) -> 2 | ... AG27: =IF($B27="","",IF(AG12="",AF27,IF(AG12=1,AF27+1,0))) -> 4
B28: =$B$13 -> Incluir verduras en almuerzo y cena | C28: =IF($B28="","",IF(C13="",0,IF(C13=1,0+1,0))) -> 1 | D28: =IF($B28="","",IF(D13="",C28,IF(D13=1,C28+1,0))) -> 2 | E28: =IF($B28="","",IF(E13="",D28,IF(E13=1,D28+1,0))) -> 3 | F28: =IF($B28="","",IF(F13="",E28,IF(F13=1,E28+1,0))) -> 0 | G28: =IF($B28="","",IF(G13="",F28,IF(G13=1,F28+1,0))) -> 1 | H28: =IF($B28="","",IF(H13="",G28,IF(H13=1,G28+1,0))) -> 2 | I28: =IF($B28="","",IF(I13="",H28,IF(I13=1,H28+1,0))) -> 3 | J28: =IF($B28="","",IF(J13="",I28,IF(J13=1,I28+1,0))) -> 4 | K28: =IF($B28="","",IF(K13="",J28,IF(K13=1,J28+1,0))) -> 5 | ... AG28: =IF($B28="","",IF(AG13="",AF28,IF(AG13=1,AF28+1,0))) -> 6
B29: =$B$14 -> Beber al menos 6 vasos de agua | C29: =IF($B29="","",IF(C14="",0,IF(C14=1,0+1,0))) -> 1 | D29: =IF($B29="","",IF(D14="",C29,IF(D14=1,C29+1,0))) -> 2 | E29: =IF($B29="","",IF(E14="",D29,IF(E14=1,D29+1,0))) -> 0 | F29: =IF($B29="","",IF(F14="",E29,IF(F14=1,E29+1,0))) -> 1 | G29: =IF($B29="","",IF(G14="",F29,IF(G14=1,F29+1,0))) -> 2 | H29: =IF($B29="","",IF(H14="",G29,IF(H14=1,G29+1,0))) -> 3 | I29: =IF($B29="","",IF(I14="",H29,IF(I14=1,H29+1,0))) -> 4 | J29: =IF($B29="","",IF(J14="",I29,IF(J14=1,I29+1,0))) -> 5 | K29: =IF($B29="","",IF(K14="",J29,IF(K14=1,J29+1,0))) -> 6 | ... AG29: =IF($B29="","",IF(AG14="",AF29,IF(AG14=1,AF29+1,0))) -> 0
B30: =$B$15 -> Comer una comida sin pantallas | C30: =IF($B30="","",IF(C15="",0,IF(C15=1,0+1,0))) -> 1 | D30: =IF($B30="","",IF(D15="",C30,IF(D15=1,C30+1,0))) -> 0 | E30: =IF($B30="","",IF(E15="",D30,IF(E15=1,D30+1,0))) -> 1 | F30: =IF($B30="","",IF(F15="",E30,IF(F15=1,E30+1,0))) -> 2 | G30: =IF($B30="","",IF(G15="",F30,IF(G15=1,F30+1,0))) -> 0 | H30: =IF($B30="","",IF(H15="",G30,IF(H15=1,G30+1,0))) -> 1 | I30: =IF($B30="","",IF(I15="",H30,IF(I15=1,H30+1,0))) -> 2 | J30: =IF($B30="","",IF(J15="",I30,IF(J15=1,I30+1,0))) -> 3 | K30: =IF($B30="","",IF(K15="",J30,IF(K15=1,J30+1,0))) -> 0 | ... AG30: =IF($B30="","",IF(AG15="",AF30,IF(AG15=1,AF30+1,0))) -> 1
B31: =$B$16 -> Llevar colación planificada | C31: =IF($B31="","",IF(C16="",0,IF(C16=1,0+1,0))) -> 0 | D31: =IF($B31="","",IF(D16="",C31,IF(D16=1,C31+1,0))) -> 1 | E31: =IF($B31="","",IF(E16="",D31,IF(E16=1,D31+1,0))) -> 2 | F31: =IF($B31="","",IF(F16="",E31,IF(F16=1,E31+1,0))) -> 3 | G31: =IF($B31="","",IF(G16="",F31,IF(G16=1,F31+1,0))) -> 4 | H31: =IF($B31="","",IF(H16="",G31,IF(H16=1,G31+1,0))) -> 5 | I31: =IF($B31="","",IF(I16="",H31,IF(I16=1,H31+1,0))) -> 6 | J31: =IF($B31="","",IF(J16="",I31,IF(J16=1,I31+1,0))) -> 0 | K31: =IF($B31="","",IF(K16="",J31,IF(K16=1,J31+1,0))) -> 1 | ... AG31: =IF($B31="","",IF(AG16="",AF31,IF(AG16=1,AF31+1,0))) -> 2
B32: =$B$17 -> Caminar 30 minutos | C32: =IF($B32="","",IF(C17="",0,IF(C17=1,0+1,0))) -> 1 | D32: =IF($B32="","",IF(D17="",C32,IF(D17=1,C32+1,0))) -> 2 | E32: =IF($B32="","",IF(E17="",D32,IF(E17=1,D32+1,0))) -> 3 | F32: =IF($B32="","",IF(F17="",E32,IF(F17=1,E32+1,0))) -> 4 | G32: =IF($B32="","",IF(G17="",F32,IF(G17=1,F32+1,0))) -> 5 | H32: =IF($B32="","",IF(H17="",G32,IF(H17=1,G32+1,0))) -> 0 | I32: =IF($B32="","",IF(I17="",H32,IF(I17=1,H32+1,0))) -> 0 | J32: =IF($B32="","",IF(J17="",I32,IF(J17=1,I32+1,0))) -> 1 | K32: =IF($B32="","",IF(K17="",J32,IF(K17=1,J32+1,0))) -> 2 | ... AG32: =IF($B32="","",IF(AG17="",AF32,IF(AG17=1,AF32+1,0))) -> 3
B33: =$B$18 -> Acostarse antes de las 23:30 | C33: =IF($B33="","",IF(C18="",0,IF(C18=1,0+1,0))) -> 1 | D33: =IF($B33="","",IF(D18="",C33,IF(D18=1,C33+1,0))) -> 2 | E33: =IF($B33="","",IF(E18="",D33,IF(E18=1,D33+1,0))) -> 3 | F33: =IF($B33="","",IF(F18="",E33,IF(F18=1,E33+1,0))) -> 4 | G33: =IF($B33="","",IF(G18="",F33,IF(G18=1,F33+1,0))) -> 0 | H33: =IF($B33="","",IF(H18="",G33,IF(H18=1,G33+1,0))) -> 0 | I33: =IF($B33="","",IF(I18="",H33,IF(I18=1,H33+1,0))) -> 1 | J33: =IF($B33="","",IF(J18="",I33,IF(J18=1,I33+1,0))) -> 2 | K33: =IF($B33="","",IF(K18="",J33,IF(K18=1,J33+1,0))) -> 3 | ... AG33: =IF($B33="","",IF(AG18="",AF33,IF(AG18=1,AF33+1,0))) -> 4
B34: =$B$19 -> Dejar lista la comida del día siguiente | C34: =IF($B34="","",IF(C19="",0,IF(C19=1,0+1,0))) -> 1 | D34: =IF($B34="","",IF(D19="",C34,IF(D19=1,C34+1,0))) -> 0 | E34: =IF($B34="","",IF(E19="",D34,IF(E19=1,D34+1,0))) -> 0 | F34: =IF($B34="","",IF(F19="",E34,IF(F19=1,E34+1,0))) -> 0 | G34: =IF($B34="","",IF(G19="",F34,IF(G19=1,F34+1,0))) -> 1 | H34: =IF($B34="","",IF(H19="",G34,IF(H19=1,G34+1,0))) -> 2 | I34: =IF($B34="","",IF(I19="",H34,IF(I19=1,H34+1,0))) -> 3 | J34: =IF($B34="","",IF(J19="",I34,IF(J19=1,I34+1,0))) -> 4 | K34: =IF($B34="","",IF(K19="",J34,IF(K19=1,J34+1,0))) -> 0 | ... AG34: =IF($B34="","",IF(AG19="",AF34,IF(AG19=1,AF34+1,0))) -> 0
B35: =$B$20 -> Anotar cómo me sentí al comer | C35: =IF($B35="","",IF(C20="",0,IF(C20=1,0+1,0))) -> 0 | D35: =IF($B35="","",IF(D20="",C35,IF(D20=1,C35+1,0))) -> 0 | E35: =IF($B35="","",IF(E20="",D35,IF(E20=1,D35+1,0))) -> 0 | F35: =IF($B35="","",IF(F20="",E35,IF(F20=1,E35+1,0))) -> 1 | G35: =IF($B35="","",IF(G20="",F35,IF(G20=1,F35+1,0))) -> 2 | H35: =IF($B35="","",IF(H20="",G35,IF(H20=1,G35+1,0))) -> 3 | I35: =IF($B35="","",IF(I20="",H35,IF(I20=1,H35+1,0))) -> 4 | J35: =IF($B35="","",IF(J20="",I35,IF(J20=1,I35+1,0))) -> 5 | K35: =IF($B35="","",IF(K20="",J35,IF(K20=1,J35+1,0))) -> 6 | ... AG35: =IF($B35="","",IF(AG20="",AF35,IF(AG20=1,AF35+1,0))) -> 0
B36: =$B$21 -> Comer sentado a la mesa | C36: =IF($B36="","",IF(C21="",0,IF(C21=1,0+1,0))) -> 1 | D36: =IF($B36="","",IF(D21="",C36,IF(D21=1,C36+1,0))) -> 2 | E36: =IF($B36="","",IF(E21="",D36,IF(E21=1,D36+1,0))) -> 3 | F36: =IF($B36="","",IF(F21="",E36,IF(F21=1,E36+1,0))) -> 4 | G36: =IF($B36="","",IF(G21="",F36,IF(G21=1,F36+1,0))) -> 5 | H36: =IF($B36="","",IF(H21="",G36,IF(H21=1,G36+1,0))) -> 6 | I36: =IF($B36="","",IF(I21="",H36,IF(I21=1,H36+1,0))) -> 0 | J36: =IF($B36="","",IF(J21="",I36,IF(J21=1,I36+1,0))) -> 1 | K36: =IF($B36="","",IF(K21="",J36,IF(K21=1,J36+1,0))) -> 2 | ... AG36: =IF($B36="","",IF(AG21="",AF36,IF(AG21=1,AF36+1,0))) -> 3
A38: BLOQUE AUXILIAR · días seguidos SIN cumplir (no escribir)
B39: Cuenta cuántos días seguidos lleva sin cumplir. Es la señal que la evidencia identifica como relevante.
B40: =$B$12 -> Desayunar dentro de la primera hora | C40: =IF($B40="","",IF(C12="",0,IF(C12=0,0+1,0))) -> 0 | D40: =IF($B40="","",IF(D12="",C40,IF(D12=0,C40+1,0))) -> 0 | E40: =IF($B40="","",IF(E12="",D40,IF(E12=0,D40+1,0))) -> 0 | F40: =IF($B40="","",IF(F12="",E40,IF(F12=0,E40+1,0))) -> 0 | G40: =IF($B40="","",IF(G12="",F40,IF(G12=0,F40+1,0))) -> 0 | H40: =IF($B40="","",IF(H12="",G40,IF(H12=0,G40+1,0))) -> 1 | I40: =IF($B40="","",IF(I12="",H40,IF(I12=0,H40+1,0))) -> 2 | J40: =IF($B40="","",IF(J12="",I40,IF(J12=0,I40+1,0))) -> 0 | K40: =IF($B40="","",IF(K12="",J40,IF(K12=0,J40+1,0))) -> 0 | ... AG40: =IF($B40="","",IF(AG12="",AF40,IF(AG12=0,AF40+1,0))) -> 0
B41: =$B$13 -> Incluir verduras en almuerzo y cena | C41: =IF($B41="","",IF(C13="",0,IF(C13=0,0+1,0))) -> 0 | D41: =IF($B41="","",IF(D13="",C41,IF(D13=0,C41+1,0))) -> 0 | E41: =IF($B41="","",IF(E13="",D41,IF(E13=0,D41+1,0))) -> 0 | F41: =IF($B41="","",IF(F13="",E41,IF(F13=0,E41+1,0))) -> 1 | G41: =IF($B41="","",IF(G13="",F41,IF(G13=0,F41+1,0))) -> 0 | H41: =IF($B41="","",IF(H13="",G41,IF(H13=0,G41+1,0))) -> 0 | I41: =IF($B41="","",IF(I13="",H41,IF(I13=0,H41+1,0))) -> 0 | J41: =IF($B41="","",IF(J13="",I41,IF(J13=0,I41+1,0))) -> 0 | K41: =IF($B41="","",IF(K13="",J41,IF(K13=0,J41+1,0))) -> 0 | ... AG41: =IF($B41="","",IF(AG13="",AF41,IF(AG13=0,AF41+1,0))) -> 0
B42: =$B$14 -> Beber al menos 6 vasos de agua | C42: =IF($B42="","",IF(C14="",0,IF(C14=0,0+1,0))) -> 0 | D42: =IF($B42="","",IF(D14="",C42,IF(D14=0,C42+1,0))) -> 0 | E42: =IF($B42="","",IF(E14="",D42,IF(E14=0,D42+1,0))) -> 1 | F42: =IF($B42="","",IF(F14="",E42,IF(F14=0,E42+1,0))) -> 0 | G42: =IF($B42="","",IF(G14="",F42,IF(G14=0,F42+1,0))) -> 0 | H42: =IF($B42="","",IF(H14="",G42,IF(H14=0,G42+1,0))) -> 0 | I42: =IF($B42="","",IF(I14="",H42,IF(I14=0,H42+1,0))) -> 0 | J42: =IF($B42="","",IF(J14="",I42,IF(J14=0,I42+1,0))) -> 0 | K42: =IF($B42="","",IF(K14="",J42,IF(K14=0,J42+1,0))) -> 0 | ... AG42: =IF($B42="","",IF(AG14="",AF42,IF(AG14=0,AF42+1,0))) -> 1
B43: =$B$15 -> Comer una comida sin pantallas | C43: =IF($B43="","",IF(C15="",0,IF(C15=0,0+1,0))) -> 0 | D43: =IF($B43="","",IF(D15="",C43,IF(D15=0,C43+1,0))) -> 1 | E43: =IF($B43="","",IF(E15="",D43,IF(E15=0,D43+1,0))) -> 0 | F43: =IF($B43="","",IF(F15="",E43,IF(F15=0,E43+1,0))) -> 0 | G43: =IF($B43="","",IF(G15="",F43,IF(G15=0,F43+1,0))) -> 1 | H43: =IF($B43="","",IF(H15="",G43,IF(H15=0,G43+1,0))) -> 0 | I43: =IF($B43="","",IF(I15="",H43,IF(I15=0,H43+1,0))) -> 0 | J43: =IF($B43="","",IF(J15="",I43,IF(J15=0,I43+1,0))) -> 0 | K43: =IF($B43="","",IF(K15="",J43,IF(K15=0,J43+1,0))) -> 1 | ... AG43: =IF($B43="","",IF(AG15="",AF43,IF(AG15=0,AF43+1,0))) -> 0
B44: =$B$16 -> Llevar colación planificada | C44: =IF($B44="","",IF(C16="",0,IF(C16=0,0+1,0))) -> 1 | D44: =IF($B44="","",IF(D16="",C44,IF(D16=0,C44+1,0))) -> 0 | E44: =IF($B44="","",IF(E16="",D44,IF(E16=0,D44+1,0))) -> 0 | F44: =IF($B44="","",IF(F16="",E44,IF(F16=0,E44+1,0))) -> 0 | G44: =IF($B44="","",IF(G16="",F44,IF(G16=0,F44+1,0))) -> 0 | H44: =IF($B44="","",IF(H16="",G44,IF(H16=0,G44+1,0))) -> 0 | I44: =IF($B44="","",IF(I16="",H44,IF(I16=0,H44+1,0))) -> 0 | J44: =IF($B44="","",IF(J16="",I44,IF(J16=0,I44+1,0))) -> 1 | K44: =IF($B44="","",IF(K16="",J44,IF(K16=0,J44+1,0))) -> 0 | ... AG44: =IF($B44="","",IF(AG16="",AF44,IF(AG16=0,AF44+1,0))) -> 0
B45: =$B$17 -> Caminar 30 minutos | C45: =IF($B45="","",IF(C17="",0,IF(C17=0,0+1,0))) -> 0 | D45: =IF($B45="","",IF(D17="",C45,IF(D17=0,C45+1,0))) -> 0 | E45: =IF($B45="","",IF(E17="",D45,IF(E17=0,D45+1,0))) -> 0 | F45: =IF($B45="","",IF(F17="",E45,IF(F17=0,E45+1,0))) -> 0 | G45: =IF($B45="","",IF(G17="",F45,IF(G17=0,F45+1,0))) -> 0 | H45: =IF($B45="","",IF(H17="",G45,IF(H17=0,G45+1,0))) -> 1 | I45: =IF($B45="","",IF(I17="",H45,IF(I17=0,H45+1,0))) -> 2 | J45: =IF($B45="","",IF(J17="",I45,IF(J17=0,I45+1,0))) -> 0 | K45: =IF($B45="","",IF(K17="",J45,IF(K17=0,J45+1,0))) -> 0 | ... AG45: =IF($B45="","",IF(AG17="",AF45,IF(AG17=0,AF45+1,0))) -> 0
B46: =$B$18 -> Acostarse antes de las 23:30 | C46: =IF($B46="","",IF(C18="",0,IF(C18=0,0+1,0))) -> 0 | D46: =IF($B46="","",IF(D18="",C46,IF(D18=0,C46+1,0))) -> 0 | E46: =IF($B46="","",IF(E18="",D46,IF(E18=0,D46+1,0))) -> 0 | F46: =IF($B46="","",IF(F18="",E46,IF(F18=0,E46+1,0))) -> 0 | G46: =IF($B46="","",IF(G18="",F46,IF(G18=0,F46+1,0))) -> 1 | H46: =IF($B46="","",IF(H18="",G46,IF(H18=0,G46+1,0))) -> 2 | I46: =IF($B46="","",IF(I18="",H46,IF(I18=0,H46+1,0))) -> 0 | J46: =IF($B46="","",IF(J18="",I46,IF(J18=0,I46+1,0))) -> 0 | K46: =IF($B46="","",IF(K18="",J46,IF(K18=0,J46+1,0))) -> 0 | ... AG46: =IF($B46="","",IF(AG18="",AF46,IF(AG18=0,AF46+1,0))) -> 0
B47: =$B$19 -> Dejar lista la comida del día siguiente | C47: =IF($B47="","",IF(C19="",0,IF(C19=0,0+1,0))) -> 0 | D47: =IF($B47="","",IF(D19="",C47,IF(D19=0,C47+1,0))) -> 1 | E47: =IF($B47="","",IF(E19="",D47,IF(E19=0,D47+1,0))) -> 2 | F47: =IF($B47="","",IF(F19="",E47,IF(F19=0,E47+1,0))) -> 3 | G47: =IF($B47="","",IF(G19="",F47,IF(G19=0,F47+1,0))) -> 0 | H47: =IF($B47="","",IF(H19="",G47,IF(H19=0,G47+1,0))) -> 0 | I47: =IF($B47="","",IF(I19="",H47,IF(I19=0,H47+1,0))) -> 0 | J47: =IF($B47="","",IF(J19="",I47,IF(J19=0,I47+1,0))) -> 0 | K47: =IF($B47="","",IF(K19="",J47,IF(K19=0,J47+1,0))) -> 1 | ... AG47: =IF($B47="","",IF(AG19="",AF47,IF(AG19=0,AF47+1,0))) -> 2
...

Sheet ANALISIS
A1: NUTRIMETRÍA · NMX-24
A2: Adherencia, patrones y lectura del mes
A4: =HYPERLINK("#INICIO!A1","▶ VOLVER A INICIO") -> ▶ VOLVER A INICIO
A6: RESULTADO POR HÁBITO
A7: Hábito | B7: Cumplidos | C7: Oportunidades | D7: Adherencia | E7: Nivel | F7: Racha máxima | G7: Máx. días seguidos sin cumplir | H7: Qué hacer con este hábito
A8: =REGISTRO!B12 -> Desayunar dentro de la primera hora | B8: =REGISTRO!AH12 -> 26 | C8: =REGISTRO!AI12 -> 31 | D8: =REGISTRO!AJ12 -> 0.83870968 | E8: =IF(NOT(ISNUMBER(D8)),"ND",IF(D8>=u_alta,"Sostenido",IF(D8>=u_media,"Intermitente","Con dificultad"))) -> Sostenido | F8: =REGISTRO!AL12 -> 6 | G8: =REGISTRO!AM12 -> 2 | H8: =IF(NOT(ISNUMBER(D8)),"ND",IF(AND(D8>=u_alta,G8<u_seguidos),"Se está sosteniendo solo: puede dejar de registrarse.",IF(D8>=u_alta,"Se cumple casi siempre, pero hubo interrupciones seguidas: revise qué las causó.",IF(D8>=u_media,"Se cumple a ratos: revise si la señal que lo dispara es clara y está a la vista.","Cuesta sostenerlo: probablemente sea demasiado exigente. Divídalo en algo más pequeño o déjelo para otro mes.")))) -> Se cumple casi siempre, pero hubo interrupciones seguidas: revise qué las causó.
A9: =REGISTRO!B13 -> Incluir verduras en almuerzo y cena | B9: =REGISTRO!AH13 -> 27 | C9: =REGISTRO!AI13 -> 31 | D9: =REGISTRO!AJ13 -> 0.87096774 | E9: =IF(NOT(ISNUMBER(D9)),"ND",IF(D9>=u_alta,"Sostenido",IF(D9>=u_media,"Intermitente","Con dificultad"))) -> Sostenido | F9: =REGISTRO!AL13 -> 6 | G9: =REGISTRO!AM13 -> 1 | H9: =IF(NOT(ISNUMBER(D9)),"ND",IF(AND(D9>=u_alta,G9<u_seguidos),"Se está sosteniendo solo: puede dejar de registrarse.",IF(D9>=u_alta,"Se cumple casi siempre, pero hubo interrupciones seguidas: revise qué las causó.",IF(D9>=u_media,"Se cumple a ratos: revise si la señal que lo dispara es clara y está a la vista.","Cuesta sostenerlo: probablemente sea demasiado exigente. Divídalo en algo más pequeño o déjelo para otro mes.")))) -> Se está sosteniendo solo: puede dejar de registrarse.
A10: =REGISTRO!B14 -> Beber al menos 6 vasos de agua | B10: =REGISTRO!AH14 -> 26 | C10: =REGISTRO!AI14 -> 31 | D10: =REGISTRO!AJ14 -> 0.83870968 | E10: =IF(NOT(ISNUMBER(D10)),"ND",IF(D10>=u_alta,"Sostenido",IF(D10>=u_media,"Intermitente","Con dificultad"))) -> Sostenido | F10: =REGISTRO!AL14 -> 6 | G10: =REGISTRO!AM14 -> 1 | H10: =IF(NOT(ISNUMBER(D10)),"ND",IF(AND(D10>=u_alta,G10<u_seguidos),"Se está sosteniendo solo: puede dejar de registrarse.",IF(D10>=u_alta,"Se cumple casi siempre, pero hubo interrupciones seguidas: revise qué las causó.",IF(D10>=u_media,"Se cumple a ratos: revise si la señal que lo dispara es clara y está a la vista.","Cuesta sostenerlo: probablemente sea demasiado exigente. Divídalo en algo más pequeño o déjelo para otro mes.")))) -> Se está sosteniendo solo: puede dejar de registrarse.
A11: =REGISTRO!B15 -> Comer una comida sin pantallas | B11: =REGISTRO!AH15 -> 23 | C11: =REGISTRO!AI15 -> 31 | D11: =REGISTRO!AJ15 -> 0.74193548 | E11: =IF(NOT(ISNUMBER(D11)),"ND",IF(D11>=u_alta,"Sostenido",IF(D11>=u_media,"Intermitente","Con dificultad"))) -> Intermitente | F11: =REGISTRO!AL15 -> 6 | G11: =REGISTRO!AM15 -> 1 | H11: =IF(NOT(ISNUMBER(D11)),"ND",IF(AND(D11>=u_alta,G11<u_seguidos),"Se está sosteniendo solo: puede dejar de registrarse.",IF(D11>=u_alta,"Se cumple casi siempre, pero hubo interrupciones seguidas: revise qué las causó.",IF(D11>=u_media,"Se cumple a ratos: revise si la señal que lo dispara es clara y está a la vista.","Cuesta sostenerlo: probablemente sea demasiado exigente. Divídalo en algo más pequeño o déjelo para otro mes.")))) -> Se cumple a ratos: revise si la señal que lo dispara es clara y está a la vista.
A12: =REGISTRO!B16 -> Llevar colación planificada | B12: =REGISTRO!AH16 -> 26 | C12: =REGISTRO!AI16 -> 31 | D12: =REGISTRO!AJ16 -> 0.83870968 | E12: =IF(NOT(ISNUMBER(D12)),"ND",IF(D12>=u_alta,"Sostenido",IF(D12>=u_media,"Intermitente","Con dificultad"))) -> Sostenido | F12: =REGISTRO!AL16 -> 6 | G12: =REGISTRO!AM16 -> 1 | H12: =IF(NOT(ISNUMBER(D12)),"ND",IF(AND(D12>=u_alta,G12<u_seguidos),"Se está sosteniendo solo: puede dejar de registrarse.",IF(D12>=u_alta,"Se cumple casi siempre, pero hubo interrupciones seguidas: revise qué las causó.",IF(D12>=u_media,"Se cumple a ratos: revise si la señal que lo dispara es clara y está a la vista.","Cuesta sostenerlo: probablemente sea demasiado exigente. Divídalo en algo más pequeño o déjelo para otro mes.")))) -> Se está sosteniendo solo: puede dejar de registrarse.
A13: =REGISTRO!B17 -> Caminar 30 minutos | B13: =REGISTRO!AH17 -> 23 | C13: =REGISTRO!AI17 -> 31 | D13: =REGISTRO!AJ17 -> 0.74193548 | E13: =IF(NOT(ISNUMBER(D13)),"ND",IF(D13>=u_alta,"Sostenido",IF(D13>=u_media,"Intermitente","Con dificultad"))) -> Intermitente | F13: =REGISTRO!AL17 -> 5 | G13: =REGISTRO!AM17 -> 2 | H13: =IF(NOT(ISNUMBER(D13)),"ND",IF(AND(D13>=u_alta,G13<u_seguidos),"Se está sosteniendo solo: puede dejar de registrarse.",IF(D13>=u_alta,"Se cumple casi siempre, pero hubo interrupciones seguidas: revise qué las causó.",IF(D13>=u_media,"Se cumple a ratos: revise si la señal que lo dispara es clara y está a la vista.","Cuesta sostenerlo: probablemente sea demasiado exigente. Divídalo en algo más pequeño o déjelo para otro mes.")))) -> Se cumple a ratos: revise si la señal que lo dispara es clara y está a la vista.
A14: =REGISTRO!B18 -> Acostarse antes de las 23:30 | B14: =REGISTRO!AH18 -> 24 | C14: =REGISTRO!AI18 -> 31 | D14: =REGISTRO!AJ18 -> 0.77419355 | E14: =IF(NOT(ISNUMBER(D14)),"ND",IF(D14>=u_alta,"Sostenido",IF(D14>=u_media,"Intermitente","Con dificultad"))) -> Intermitente | F14: =REGISTRO!AL18 -> 6 | G14: =REGISTRO!AM18 -> 2 | H14: =IF(NOT(ISNUMBER(D14)),"ND",IF(AND(D14>=u_alta,G14<u_seguidos),"Se está sosteniendo solo: puede dejar de registrarse.",IF(D14>=u_alta,"Se cumple casi siempre, pero hubo interrupciones seguidas: revise qué las causó.",IF(D14>=u_media,"Se cumple a ratos: revise si la señal que lo dispara es clara y está a la vista.","Cuesta sostenerlo: probablemente sea demasiado exigente. Divídalo en algo más pequeño o déjelo para otro mes.")))) -> Se cumple a ratos: revise si la señal que lo dispara es clara y está a la vista.
A15: =REGISTRO!B19 -> Dejar lista la comida del día siguiente | B15: =REGISTRO!AH19 -> 17 | C15: =REGISTRO!AI19 -> 31 | D15: =REGISTRO!AJ19 -> 0.5483871 | E15: =IF(NOT(ISNUMBER(D15)),"ND",IF(D15>=u_alta,"Sostenido",IF(D15>=u_media,"Intermitente","Con dificultad"))) -> Con dificultad | F15: =REGISTRO!AL19 -> 4 | G15: =REGISTRO!AM19 -> 3 | H15: =IF(NOT(ISNUMBER(D15)),"ND",IF(AND(D15>=u_alta,G15<u_seguidos),"Se está sosteniendo solo: puede dejar de registrarse.",IF(D15>=u_alta,"Se cumple casi siempre, pero hubo interrupciones seguidas: revise qué las causó.",IF(D15>=u_media,"Se cumple a ratos: revise si la señal que lo dispara es clara y está a la vista.","Cuesta sostenerlo: probablemente sea demasiado exigente. Divídalo en algo más pequeño o déjelo para otro mes.")))) -> Cuesta sostenerlo: probablemente sea demasiado exigente. Divídalo en algo más pequeño o déjelo para otro mes.
A16: =REGISTRO!B20 -> Anotar cómo me sentí al comer | B16: =REGISTRO!AH20 -> 22 | C16: =REGISTRO!AI20 -> 31 | D16: =REGISTRO!AJ20 -> 0.70967742 | E16: =IF(NOT(ISNUMBER(D16)),"ND",IF(D16>=u_alta,"Sostenido",IF(D16>=u_media,"Intermitente","Con dificultad"))) -> Intermitente | F16: =REGISTRO!AL20 -> 11 | G16: =REGISTRO!AM20 -> 3 | H16: =IF(NOT(ISNUMBER(D16)),"ND",IF(AND(D16>=u_alta,G16<u_seguidos),"Se está sosteniendo solo: puede dejar de registrarse.",IF(D16>=u_alta,"Se cumple casi siempre, pero hubo interrupciones seguidas: revise qué las causó.",IF(D16>=u_media,"Se cumple a ratos: revise si la señal que lo dispara es clara y está a la vista.","Cuesta sostenerlo: probablemente sea demasiado exigente. Divídalo en algo más pequeño o déjelo para otro mes.")))) -> Se cumple a ratos: revise si la señal que lo dispara es clara y está a la vista.
A17: =REGISTRO!B21 -> Comer sentado a la mesa | B17: =REGISTRO!AH21 -> 27 | C17: =REGISTRO!AI21 -> 31 | D17: =REGISTRO!AJ21 -> 0.87096774 | E17: =IF(NOT(ISNUMBER(D17)),"ND",IF(D17>=u_alta,"Sostenido",IF(D17>=u_media,"Intermitente","Con dificultad"))) -> Sostenido | F17: =REGISTRO!AL21 -> 6 | G17: =REGISTRO!AM21 -> 1 | H17: =IF(NOT(ISNUMBER(D17)),"ND",IF(AND(D17>=u_alta,G17<u_seguidos),"Se está sosteniendo solo: puede dejar de registrarse.",IF(D17>=u_alta,"Se cumple casi siempre, pero hubo interrupciones seguidas: revise qué las causó.",IF(D17>=u_media,"Se cumple a ratos: revise si la señal que lo dispara es clara y está a la vista.","Cuesta sostenerlo: probablemente sea demasiado exigente. Divídalo en algo más pequeño o déjelo para otro mes.")))) -> Se está sosteniendo solo: puede dejar de registrarse.
A18: GLOBAL DEL MES | B18: =SUM(B8:B17) -> 241 | C18: =SUM(C8:C17) -> 310 | D18: =IF(C18=0,"ND",B18/C18) -> 0.77741935
A20: PATRONES DEL MES
A21: Hábitos sostenidos | C21: =COUNTIF(E8:E17,"Sostenido") -> 5
A22: Hábitos intermitentes | C22: =COUNTIF(E8:E17,"Intermitente") -> 4
A23: Hábitos con dificultad | C23: =COUNTIF(E8:E17,"Con dificultad") -> 1
A24: Hábitos con dos o más días seguidos sin cumplir | C24: =COUNTIF(G8:G17,">="&u_seguidos) -> 5
A25: Hábito de mayor adherencia | C25: =IF(COUNT(D8:D17)=0,"ND",INDEX(A8:A17,MATCH(MAX(D8:D17),D8:D17,0))) -> Incluir verduras en almuerzo y cena
A26: Hábito de menor adherencia | C26: =IF(COUNT(D8:D17)=0,"ND",INDEX(A8:A17,MATCH(MIN(D8:D17),D8:D17,0))) -> Dejar lista la comida del día siguiente
A27: Mejor día del mes (hábitos cumplidos) | C27: =MAX(REGISTRO!C22:AG22) -> 10
A28: Día más bajo del mes | C28: =MIN(REGISTRO!C22:AG22) -> 7
A29: Promedio de hábitos cumplidos por día | C29: =IF(COUNT(REGISTRO!C22:AG22)=0,"ND",AVERAGE(REGISTRO!C22:AG22)) -> 7.7741935
A31: LECTURA DEL MES
A32: Adherencia global | C32: =IF(NOT(ISNUMBER(D18)),"ND",IF(D18>=u_alta,"La mayoría de los hábitos se sostuvo la mayor parte del mes.",IF(D18>=u_media,"El cumplimiento fue parcial: hay conductas que se sostienen y otras que no.","El cumplimiento fue bajo. Antes de insistir, revise si los hábitos elegidos eran realistas para este mes."))) -> El cumplimiento fue parcial: hay conductas que se sostienen y otras que no.
A33: Dónde poner el foco | C33: =IF(C23=0,"Ningún hábito quedó en dificultad: puede incorporar uno nuevo el próximo mes.","Hay "&C23&" hábito(s) con dificultad. Conviene retirarlos o hacerlos más pequeños antes de agregar cualquier conducta nueva.") -> Hay 1 hábito(s) con dificultad. Conviene retirarlos o hacerlos más pequeños antes de agregar cualquier conducta nueva.
A34: Interrupciones seguidas | C34: =IF(C24=0,"No hubo interrupciones de dos días seguidos.","En "&C24&" hábito(s) hubo dos o más días seguidos sin cumplir. Esa es la señal a conversar: no el día aislado, sino qué ocurrió para que se encadenaran.") -> En 5 hábito(s) hubo dos o más días seguidos sin cumplir. Esa es la señal a conversar: no el día aislado, sino qué ocurrió para que se encadenaran.
A36: ACUERDOS PARA EL MES SIGUIENTE
A37: Qué hábitos continúan | C37: —
A38: Qué hábitos se retiran o se hacen más pequeños | C38: —
A39: Qué hábito nuevo se incorpora, si corresponde | C39: —
A40: Qué obstáculo concreto se va a resolver | C40: —
A41: Fecha de la próxima revisión | C41: —
A43: Este análisis describe CONDUCTAS, no a la persona. Una adherencia baja informa que el hábito elegido no calzaba con la vida real de ese mes, no que la persona haya fallado. La conducta profesional ante un mes bajo es simplificar el objetivo, no exigir más constancia.

Sheet PANEL
A1: NUTRIMETRÍA · NMX-24
A2: Tablero del mes · lectura de un vistazo
A4: =HYPERLINK("#INICIO!A1","▶ VOLVER A INICIO") -> ▶ VOLVER A INICIO
A6: INDICADORES DEL MES
A7: ADHERENCIA GLOBAL | D7: HÁBITOS SOSTENIDOS | G7: HÁBITOS CON DIFICULTAD | J7: CON DOS DÍAS SEGUIDOS | M7: PROMEDIO POR DÍA
A8: =ANALISIS!D18 -> 0.77741935 | D8: =ANALISIS!C21 -> 5 | G8: =ANALISIS!C23 -> 1 | J8: =ANALISIS!C24 -> 5 | M8: =ANALISIS!C29 -> 7.7741935
A10: del total de oportunidades | D10: con 80% o más | G10: bajo el 60% | J10: hábitos con la señal | M10: hábitos cumplidos al día
A12: ADHERENCIA POR HÁBITO
A13: Hábito | B13: Adherencia
A14: =ANALISIS!A8 -> Desayunar dentro de la primera hora | B14: =ANALISIS!D8 -> 0.83870968
A15: =ANALISIS!A9 -> Incluir verduras en almuerzo y cena | B15: =ANALISIS!D9 -> 0.87096774
A16: =ANALISIS!A10 -> Beber al menos 6 vasos de agua | B16: =ANALISIS!D10 -> 0.83870968
A17: =ANALISIS!A11 -> Comer una comida sin pantallas | B17: =ANALISIS!D11 -> 0.74193548
A18: =ANALISIS!A12 -> Llevar colación planificada | B18: =ANALISIS!D12 -> 0.83870968
A19: =ANALISIS!A13 -> Caminar 30 minutos | B19: =ANALISIS!D13 -> 0.74193548
A20: =ANALISIS!A14 -> Acostarse antes de las 23:30 | B20: =ANALISIS!D14 -> 0.77419355
A21: =ANALISIS!A15 -> Dejar lista la comida del día siguiente | B21: =ANALISIS!D15 -> 0.5483871
A22: =ANALISIS!A16 -> Anotar cómo me sentí al comer | B22: =ANALISIS!D16 -> 0.70967742
A23: =ANALISIS!A17 -> Comer sentado a la mesa | B23: =ANALISIS!D17 -> 0.87096774
A25: CUMPLIMIENTO DÍA A DÍA
A26: Día | B26: Hábitos cumplidos
A27: 1 | B27: =REGISTRO!C22 -> 8
A28: 2 | B28: =REGISTRO!D22 -> 7
A29: 3 | B29: =REGISTRO!E22 -> 7
A30: 4 | B30: =REGISTRO!F22 -> 8
A31: 5 | B31: =REGISTRO!G22 -> 8
A32: 6 | B32: =REGISTRO!H22 -> 7
A33: 7 | B33: =REGISTRO!I22 -> 7
A34: 8 | B34: =REGISTRO!J22 -> 9
A35: 9 | B35: =REGISTRO!K22 -> 8
A36: 10 | B36: =REGISTRO!L22 -> 8
A37: 11 | B37: =REGISTRO!M22 -> 8
A38: 12 | B38: =REGISTRO!N22 -> 10
A39: 13 | B39: =REGISTRO!O22 -> 7
A40: 14 | B40: =REGISTRO!P22 -> 8
A41: 15 | B41: =REGISTRO!Q22 -> 8
A42: 16 | B42: =REGISTRO!R22 -> 7
A43: 17 | B43: =REGISTRO!S22 -> 7
A44: 18 | B44: =REGISTRO!T22 -> 8
A45: 19 | B45: =REGISTRO!U22 -> 8
...

Sheet FUENTES
A1: NUTRIMETRÍA · NMX-24
A2: Evidencia sobre formación de hábitos y trazabilidad
A4: =HYPERLINK("#INICIO!A1","▶ VOLVER A INICIO") -> ▶ VOLVER A INICIO
A6: BASE DE EVIDENCIA
A7: Elemento | B7: Referencia y alcance
A8: Cuánto demora consolidarse un hábito | B8: Lally P, van Jaarsveld CHM, Potts HWW, Wardle J. «How are habits formed: modelling habit formation in the real world». European Journal of Social Psychology, 2010; 40(6): 998-1009. Siguieron a 96 personas durante 12 semanas: la MEDIANA para alcanzar automaticidad fue de 66 días, con un rango observado de 18 a 254 días. Un mes de registro no basta para dar por formado un hábito.
A9: El mito de los 21 días | B9: La cifra de 21 días no proviene de investigación sobre hábitos: se originó en una observación de Maxwell Maltz (1960) sobre pacientes de cirugía plástica adaptándose a su nueva imagen. No debe usarse como meta ni como promesa a la persona.
A10: Fallar un día NO rompe el proceso | B10: En los datos de Lally, omitir una sola oportunidad no afectó de forma significativa la trayectoria hacia la automaticidad. Este es el fundamento del diseño de este libro: se registra la racha, pero NO se la usa como criterio, porque la lógica de racha castiga un fallo aislado que la evidencia muestra inocuo.
A11: Qué sí es señal | B11: Lo relevante es la interrupción SOSTENIDA. La regla práctica derivada de esa literatura es no fallar dos días seguidos, porque la repetición de la no ejecución también se consolida. Por eso el indicador central de este libro es el máximo de días seguidos sin cumplir y no la racha.
A12: Automaticidad frente a racha | B12: Un hábito está formado cuando la conducta ocurre sin decisión consciente, no cuando se acumulan N días seguidos. Dos personas con la misma racha pueden tener grados de automaticidad muy distintos. La racha es una medida de conteo, no de consolidación.
A13: Límite del enfoque de hábitos | B13: La misma literatura advierte que las conductas simples y acotadas en contextos estables (beber agua, tomar una fruta) son buenas candidatas a volverse automáticas, mientras que conductas complejas como «alimentarse bien» o «entrenar de forma constante» siguen requiriendo decisión consciente. Redacte hábitos simples y observables.
A14: Número de hábitos simultáneos | B14: El límite precargado de cinco hábitos a la vez es una convención de trabajo editable, orientada a no dispersar el esfuerzo. No proviene de un punto de corte experimental.
A15: Umbrales de adherencia | B15: Los cortes de 80% y 60% son convenciones de lectura EDITABLES en CONFIG, útiles para conversar sobre el mes. No son puntos de corte validados ni tienen significado clínico por sí mismos.
A16: Precaución clínica | B16: El registro diario de conductas alimentarias puede intensificar la preocupación por la comida y el pensamiento de todo o nada en personas con trastorno de la conducta alimentaria o alto riesgo. Evalúe antes de indicarlo y considere una versión sin cuantificación. Nunca incluya el peso corporal como hábito de registro diario.
A17: Qué NO hace este libro | B17: No mide automaticidad, que requiere un instrumento propio; no diagnostica; no evalúa la ingesta; no reemplaza el acompañamiento profesional; no está validado clínicamente.

Sheet PRUEBAS
A1: NUTRIMETRÍA · NMX-24
A2: Control de calidad del motor de cálculo
A4: =HYPERLINK("#INICIO!A1","▶ VOLVER A INICIO") -> ▶ VOLVER A INICIO
A6: Los valores esperados se calcularon de forma independiente del motor del libro (verificación externa).
A8: Bloque | B8: Descripción de la prueba | C8: Obtenido | D8: Esperado | E8: Estado
A9: A | B9: Hábito 1 · días cumplidos | C9: =REGISTRO!AH12 -> 26 | D9: 26 | E9: =IF(AND(ISNUMBER(C9),ISNUMBER(D9)),IF(ABS(C9-D9)<=0.001,"APROBADO","REVISAR"),IF(EXACT(C9&"",D9&""),"APROBADO","REVISAR")) -> APROBADO
A10: A | B10: Hábito 1 · oportunidades registradas | C10: =REGISTRO!AI12 -> 31 | D10: 31 | E10: =IF(AND(ISNUMBER(C10),ISNUMBER(D10)),IF(ABS(C10-D10)<=0.001,"APROBADO","REVISAR"),IF(EXACT(C10&"",D10&""),"APROBADO","REVISAR")) -> APROBADO
A11: A | B11: Hábito 1 · adherencia | C11: =REGISTRO!AJ12 -> 0.83870968 | D11: 0.83870968 | E11: =IF(AND(ISNUMBER(C11),ISNUMBER(D11)),IF(ABS(C11-D11)<=0.001,"APROBADO","REVISAR"),IF(EXACT(C11&"",D11&""),"APROBADO","REVISAR")) -> APROBADO
A12: A | B12: Hábito 2 · días cumplidos | C12: =REGISTRO!AH13 -> 27 | D12: 27 | E12: =IF(AND(ISNUMBER(C12),ISNUMBER(D12)),IF(ABS(C12-D12)<=0.001,"APROBADO","REVISAR"),IF(EXACT(C12&"",D12&""),"APROBADO","REVISAR")) -> APROBADO
A13: A | B13: Hábito 8 · días cumplidos (el más bajo) | C13: =REGISTRO!AH19 -> 17 | D13: 17 | E13: =IF(AND(ISNUMBER(C13),ISNUMBER(D13)),IF(ABS(C13-D13)<=0.001,"APROBADO","REVISAR"),IF(EXACT(C13&"",D13&""),"APROBADO","REVISAR")) -> APROBADO
A14: A | B14: Hábito 8 · adherencia | C14: =REGISTRO!AJ19 -> 0.5483871 | D14: 0.5483871 | E14: =IF(AND(ISNUMBER(C14),ISNUMBER(D14)),IF(ABS(C14-D14)<=0.001,"APROBADO","REVISAR"),IF(EXACT(C14&"",D14&""),"APROBADO","REVISAR")) -> APROBADO
A15: B | B15: Hábito 1 · racha máxima | C15: =REGISTRO!AL12 -> 6 | D15: 6 | E15: =IF(AND(ISNUMBER(C15),ISNUMBER(D15)),IF(ABS(C15-D15)<=0.001,"APROBADO","REVISAR"),IF(EXACT(C15&"",D15&""),"APROBADO","REVISAR")) -> APROBADO
A16: B | B16: Hábito 9 · racha máxima (la más larga) | C16: =REGISTRO!AL20 -> 11 | D16: 11 | E16: =IF(AND(ISNUMBER(C16),ISNUMBER(D16)),IF(ABS(C16-D16)<=0.001,"APROBADO","REVISAR"),IF(EXACT(C16&"",D16&""),"APROBADO","REVISAR")) -> APROBADO
A17: B | B17: Hábito 4 · racha máxima (la más corta) | C17: =REGISTRO!AL15 -> 6 | D17: 6 | E17: =IF(AND(ISNUMBER(C17),ISNUMBER(D17)),IF(ABS(C17-D17)<=0.001,"APROBADO","REVISAR"),IF(EXACT(C17&"",D17&""),"APROBADO","REVISAR")) -> APROBADO
A18: C | B18: Hábito 1 · máximo de días seguidos sin cumplir | C18: =REGISTRO!AM12 -> 2 | D18: 2 | E18: =IF(AND(ISNUMBER(C18),ISNUMBER(D18)),IF(ABS(C18-D18)<=0.001,"APROBADO","REVISAR"),IF(EXACT(C18&"",D18&""),"APROBADO","REVISAR")) -> APROBADO
A19: C | B19: Hábito 8 · máximo de días seguidos sin cumplir | C19: =REGISTRO!AM19 -> 3 | D19: 3 | E19: =IF(AND(ISNUMBER(C19),ISNUMBER(D19)),IF(ABS(C19-D19)<=0.001,"APROBADO","REVISAR"),IF(EXACT(C19&"",D19&""),"APROBADO","REVISAR")) -> APROBADO
A20: C | B20: Hábito 2 · máximo de días seguidos sin cumplir | C20: =REGISTRO!AM13 -> 1 | D20: 1 | E20: =IF(AND(ISNUMBER(C20),ISNUMBER(D20)),IF(ABS(C20-D20)<=0.001,"APROBADO","REVISAR"),IF(EXACT(C20&"",D20&""),"APROBADO","REVISAR")) -> APROBADO
A21: C | B21: Hábitos con dos o más días seguidos sin cumplir | C21: =ANALISIS!C24 -> 5 | D21: 5 | E21: =IF(AND(ISNUMBER(C21),ISNUMBER(D21)),IF(ABS(C21-D21)<=0.001,"APROBADO","REVISAR"),IF(EXACT(C21&"",D21&""),"APROBADO","REVISAR")) -> APROBADO
A22: D | B22: Cumplimientos totales del mes | C22: =ANALISIS!B18 -> 241 | D22: 241 | E22: =IF(AND(ISNUMBER(C22),ISNUMBER(D22)),IF(ABS(C22-D22)<=0.001,"APROBADO","REVISAR"),IF(EXACT(C22&"",D22&""),"APROBADO","REVISAR")) -> APROBADO
A23: D | B23: Oportunidades totales del mes | C23: =ANALISIS!C18 -> 310 | D23: 310 | E23: =IF(AND(ISNUMBER(C23),ISNUMBER(D23)),IF(ABS(C23-D23)<=0.001,"APROBADO","REVISAR"),IF(EXACT(C23&"",D23&""),"APROBADO","REVISAR")) -> APROBADO
A24: D | B24: ADHERENCIA GLOBAL | C24: =ANALISIS!D18 -> 0.77741935 | D24: 0.77741936 | E24: =IF(AND(ISNUMBER(C24),ISNUMBER(D24)),IF(ABS(C24-D24)<=0.001,"APROBADO","REVISAR"),IF(EXACT(C24&"",D24&""),"APROBADO","REVISAR")) -> APROBADO
A25: D | B25: Promedio de hábitos cumplidos por día | C25: =ANALISIS!C29 -> 7.7741935 | D25: 7.7741935 | E25: =IF(AND(ISNUMBER(C25),ISNUMBER(D25)),IF(ABS(C25-D25)<=0.001,"APROBADO","REVISAR"),IF(EXACT(C25&"",D25&""),"APROBADO","REVISAR")) -> APROBADO
A26: E | B26: Cumplidos del día 1 | C26: =REGISTRO!C22 -> 8 | D26: 8 | E26: =IF(AND(ISNUMBER(C26),ISNUMBER(D26)),IF(ABS(C26-D26)<=0.001,"APROBADO","REVISAR"),IF(EXACT(C26&"",D26&""),"APROBADO","REVISAR")) -> APROBADO
A27: E | B27: Cumplidos del día 15 | C27: =REGISTRO!Q22 -> 8 | D27: 8 | E27: =IF(AND(ISNUMBER(C27),ISNUMBER(D27)),IF(ABS(C27-D27)<=0.001,"APROBADO","REVISAR"),IF(EXACT(C27&"",D27&""),"APROBADO","REVISAR")) -> APROBADO
A28: E | B28: Cumplidos del día 31 | C28: =REGISTRO!AG22 -> 7 | D28: 7 | E28: =IF(AND(ISNUMBER(C28),ISNUMBER(D28)),IF(ABS(C28-D28)<=0.001,"APROBADO","REVISAR"),IF(EXACT(C28&"",D28&""),"APROBADO","REVISAR")) -> APROBADO
A29: E | B29: Mejor día del mes | C29: =ANALISIS!C27 -> 10 | D29: 10 | E29: =IF(AND(ISNUMBER(C29),ISNUMBER(D29)),IF(ABS(C29-D29)<=0.001,"APROBADO","REVISAR"),IF(EXACT(C29&"",D29&""),"APROBADO","REVISAR")) -> APROBADO
A30: E | B30: Día más bajo del mes | C30: =ANALISIS!C28 -> 7 | D30: 7 | E30: =IF(AND(ISNUMBER(C30),ISNUMBER(D30)),IF(ABS(C30-D30)<=0.001,"APROBADO","REVISAR"),IF(EXACT(C30&"",D30&""),"APROBADO","REVISAR")) -> APROBADO
A31: F | B31: Hábitos sostenidos (80% o más) | C31: =ANALISIS!C21 -> 5 | D31: 5 | E31: =IF(AND(ISNUMBER(C31),ISNUMBER(D31)),IF(ABS(C31-D31)<=0.001,"APROBADO","REVISAR"),IF(EXACT(C31&"",D31&""),"APROBADO","REVISAR")) -> APROBADO
A32: F | B32: Hábitos con dificultad (bajo 60%) | C32: =ANALISIS!C23 -> 1 | D32: 1 | E32: =IF(AND(ISNUMBER(C32),ISNUMBER(D32)),IF(ABS(C32-D32)<=0.001,"APROBADO","REVISAR"),IF(EXACT(C32&"",D32&""),"APROBADO","REVISAR")) -> APROBADO
A33: F | B33: Nivel asignado al hábito 8 | C33: =ANALISIS!E15 -> Con dificultad | D33: Con dificultad | E33: =IF(AND(ISNUMBER(C33),ISNUMBER(D33)),IF(ABS(C33-D33)<=0.001,"APROBADO","REVISAR"),IF(EXACT(C33&"",D33&""),"APROBADO","REVISAR")) -> APROBADO
A34: F | B34: Nivel asignado al hábito 2 | C34: =ANALISIS!E9 -> Sostenido | D34: Sostenido | E34: =IF(AND(ISNUMBER(C34),ISNUMBER(D34)),IF(ABS(C34-D34)<=0.001,"APROBADO","REVISAR"),IF(EXACT(C34&"",D34&""),"APROBADO","REVISAR")) -> APROBADO
A35: G | B35: El libro advierte que hay demasiados hábitos | C35: =IF(ISNUMBER(SEARCH("MÁS de los",HABITOS!C27)),"ADVIERTE","NO ADVIERTE") -> ADVIERTE | D35: ADVIERTE | E35: =IF(AND(ISNUMBER(C35),ISNUMBER(D35)),IF(ABS(C35-D35)<=0.001,"APROBADO","REVISAR"),IF(EXACT(C35&"",D35&""),"APROBADO","REVISAR")) -> APROBADO
A36: G | B36: Un mes no alcanza para consolidar un hábito | C36: =IF(ISNUMBER(SEARCH("NO alcanza",DATOS!C27)),"ADVIERTE","NO ADVIERTE") -> ADVIERTE | D36: ADVIERTE | E36: =IF(AND(ISNUMBER(C36),ISNUMBER(D36)),IF(ABS(C36-D36)<=0.001,"APROBADO","REVISAR"),IF(EXACT(C36&"",D36&""),"APROBADO","REVISAR")) -> APROBADO
A37: H | B37: Una celda vacía NO se cuenta como incumplimiento | C37: =IF(COUNT(REGISTRO!C12:AG12)=COUNTA(REGISTRO!C12:AG12),"COHERENTE","REVISAR") -> COHERENTE | D37: COHERENTE | E37: =IF(AND(ISNUMBER(C37),ISNUMBER(D37)),IF(ABS(C37-D37)<=0.001,"APROBADO","REVISAR"),IF(EXACT(C37&"",D37&""),"APROBADO","REVISAR")) -> APROBADO
A39: RESUMEN | B39: Pruebas aprobadas | C39: =COUNTIF(E9:E37,"APROBADO") -> 29 | D39: =COUNTA(E9:E37) -> 29 | E39: =IF(C39=D39,"TODAS APROBADAS","HAY PRUEBAS POR REVISAR") -> TODAS APROBADAS

Sheet CONFIG
A1: NUTRIMETRÍA · NMX-24
A2: Configuración · umbrales y listas del seguimiento
A4: =HYPERLINK("#INICIO!A1","▶ VOLVER A INICIO") -> ▶ VOLVER A INICIO
A6: UMBRALES DE LECTURA
A7: Adherencia alta · desde | D7: % | E7: 0.8
A8: Adherencia intermedia · desde | D8: % | E8: 0.6
A9: Días seguidos sin cumplir que activan la señal | D9: días | E9: 2
A10: Días de referencia para consolidar un hábito (mediana) | D10: días | E10: 66
A11: Rango inferior observado para consolidar | D11: días | E11: 18
A12: Rango superior observado para consolidar | D12: días | E12: 254
A13: Número máximo de hábitos a seguir a la vez | D13: hábitos | E13: 5
A14: Tolerancia de las pruebas | D14: ± | E14: 0.0001
A15: La señal que importa NO es la racha rota sino DOS DÍAS SEGUIDOS sin cumplir. La evidencia muestra que fallar un día aislado no altera la trayectoria de consolidación; lo que la altera es abandonar después del fallo. Por eso este libro mide días seguidos sin cumplir y no castiga el corte de una racha.
A20: LISTAS DESPLEGABLES
A21: MARCA | D21: AMBITO | G21: MOMENTO | J21: DIFICULTAD | M21: SI
A22: 1 | D22: Alimentación | G22: Al despertar | J22: Fácil | M22: Sí
A23: 0 | D23: Movimiento | G23: Antes del desayuno | J23: Media | M23: No
D24: Descanso | G24: Mediodía | J24: Exigente
D25: Organización | G25: Tarde
D26: Conciencia | G26: Antes de dormir
G27: Sin hora fija
A29: SIGNIFICADO DE CADA MARCA DEL CALENDARIO
A30: 1 | B30: Cumplió el hábito ese día
A31: 0 | B31: No lo cumplió, habiendo tenido la oportunidad
A32: (celda vacía) | B32: No hubo oportunidad: viaje, enfermedad, el día no aplicaba. NO cuenta en contra.
A33: Distinguir la celda vacía del cero es deliberado: un día sin oportunidad no es un incumplimiento. La adherencia se calcula sobre los días en que efectivamente hubo ocasión de cumplir, no sobre los 31 días del mes.

Sheet CHANGELOG
A1: NUTRIMETRÍA · NMX-24
A2: Historial de versiones
A4: =HYPERLINK("#INICIO!A1","▶ VOLVER A INICIO") -> ▶ VOLVER A INICIO
A6: Versión | B6: Fecha | C6: Cambio
A7: 1.0 | B7: 2026-07-23 | C7: Versión inicial de NMX-24: seguimiento mensual de hábitos con calendario de 31 días, análisis de adherencia por conducta y tablero visual. | J7: Fase 6 · Planificación.
A8: 1.0 | B8: 2026-07-23 | C8: El indicador central NO es la racha sino el máximo de días seguidos sin cumplir. | J8: La evidencia muestra que fallar un día aislado no altera la trayectoria de consolidación; lo que la altera es encadenar ausencias.
